Workbook
Name zsupermetrics_9i4W4hgd80uRpQLMeX0eRnESN8gjyv: Formula!$H$13:$H$14
Name zsupermetrics_ru0GDtbZzDLHQOQtJJ6K08MvUDyyp7: Formula!$G$4:$G$5
Name zsupermetrics_lx4cNai7gT6tH4j08ZRkI21Qlpjioi: Formula!$G$4:$H$5
Name zsupermetrics_refreshAll: SupermetricsQueries!$H$5
Name zsupermetrics_8xojRjNDjo2jWHGDWjFEhflhyIq3Hq: Sales!$K$7:$K$8
Name zsupermetrics_n3GtLgiKpTmd2pYmQNMuq6TPD0qE0b: Formula!$G$4:$G$5
Name zsupermetrics_OI1SHh9RTAzpmZ8JDWgszLojYv8Hv4: Formula!$F$4:$G$5
Name zsupermetrics_refreshAllSilent: SupermetricsQueries!$H$6
Name zsupermetrics_qWp7V908pNEYMtfv8QZvSTeDnBAHOU: Formula!$G$5:$H$6
Name zsupermetrics_forceRefresh: SupermetricsQueries!$H$4
Name zsupermetrics_HgZqhorObHOtZHuyJjpmyYaEPoYntx: Formula!$G$4:$G$5
Name zsupermetrics_YsFuuYtr8vOdNXCCPiFJIO38NP4b2T: Formula!$G$4:$H$5
Name zsupermetrics_DQl8lUbpTRu3fayaJJi7lVfOGKjNU4: Formula!$F$3:$F$4
Name zsupermetrics_4VkB7ij7WO0JjKBEgvjB2GHjSy2Egm: Formula!$G$4:$H$5

Sheet Sales
A1: Date | B1: 44409 | C1: 44410 | D1: 44411 | E1: 44412 | F1: 44413 | G1: 44414 | H1: 44415 | I1: 44416 | J1: 44417 | K1: 44418 | L1: 44419 | M1: 44420 | N1: 44421 | O1: 44422 | P1: 44423 | Q1: 44424 | R1: 44425 | S1: 44426 | T1: 44427 | U1: 44428 | V1: 44429 | W1: 44430 | X1: 44431 | Y1: 44432 | Z1: 44433 | AA1: 44434 | AB1: 44435 | AC1: 44436 | AD1: 44437 | AE1: 44438 | AF1: 44439
B2: SUN | C2: MON | D2: TUE | E2: WED | F2: THU | G2: FRI | H2: SAT | I2: SUN | J2: SUN | K2: MON | L2: TUE | M2: WED | N2: THU | O2: FRI | P2: SAT | Q2: SUN | R2: SUN | S2: MON | T2: TUE | U2: WED | V2: THU | W2: FRI | X2: SAT | Y2: SUN | Z2: SUN | AA2: MON | AB2: TUE | AC2: WED | AD2: THU | AE2: FRI | AF2: SAT
A4: Notes | C4: IGG News
A6: Indiegogo | B6: 2266 | C6: 2648 | D6: 2495 | E6: 2799 | F6: 1116 | G6: 3895 | H6: 4143 | I6: 2736 | J6: 4076 | K6: 1709 | L6: 1854 | M6: 2039 | N6: 540 | O6: 1307 | P6: 873 | Q6: 2022 | R6: 220 | S6: 0 | T6: 1005 | U6: 1589 | V6: 0 | W6: 196 | X6: 473 | Y6: 206 | Z6: 760 | AA6: 1701 | AB6: 616 | AC6: 202 | AD6: 856 | AE6: 255 | AF6: 0
A7: Shopify | B7: 17191 | C7: 10945 | D7: 10375 | E7: 12387 | F7: 8501 | G7: 10197 | H7: 7967 | I7: 9485 | J7: 5519 | K7: 7115 | L7: 7120 | M7: 7058 | N7: 6625 | O7: 5426 | P7: 9198 | Q7: 6919 | R7: 6277 | S7: 7468 | T7: 3393 | U7: 7464 | V7: 9654 | W7: 10780 | X7: 7230 | Y7: 7202 | Z7: 7176 | AA7: 7842 | AB7: 8645 | AC7: 7834 | AD7: 8270 | AE7: 7236 | AF7: 4910
A8: Total Revenue | B8: =SUM(B6:B7) -> 19457 | C8: =SUM(C6:C7) -> 13593 | D8: =SUM(D6:D7) -> 12870 | E8: =SUM(E6:E7) -> 15186 | F8: =SUM(F6:F7) -> 9617 | G8: =SUM(G6:G7) -> 14092 | H8: =SUM(H6:H7) -> 12110 | I8: =SUM(I6:I7) -> 12221 | ... AF8: =SUM(AF6:AF7) -> 4910
A9: Orders | B9: 69 | C9: 49 | D9: 47 | E9: 63 | F9: 38 | G9: 55 | H9: 50 | I9: 45 | J9: 41 | K9: 32 | L9: 36 | M9: 35 | N9: 26 | O9: 25 | P9: 35 | Q9: 33 | R9: 25 | S9: 29 | T9: 17 | U9: 37 | V9: 35 | W9: 39 | X9: 26 | Y9: 27 | Z9: 30 | AA9: 39 | AB9: 37 | AC9: 29 | AD9: 36 | AE9: 31 | AF9: 20
A11: FB - US & CA | B11: 3930.46 | C11: 3116.25 | D11: 4066.75 | E11: 4115.87 | F11: 4080 | G11: 4553.98 | H11: 3638.76 | I11: 2978.91 | J11: 2898.89 | K11: 2430.05 | L11: 1974.56 | M11: 1277.33 | N11: 1284.07 | O11: 1417.81 | P11: 1372.36 | Q11: 1598.13 | R11: 1708.5 | S11: 2011.99 | T11: 2358.06 | U11: 2655.29 | V11: 2445.38 | W11: 2479.78 | X11: 2415.26 | Y11: 2974.25 | Z11: 3427.93 | AA11: 3142.54 | AB11: 3011.57 | AC11: 2736.01 | AD11: 2617.35 | AE11: 1022.26
A12: FB - Internal Paid | B12: 2866.63 | C12: 2613.94 | D12: 1723.09 | E12: 1391.28 | F12: 2513.78 | G12: 993.3 | J12: 510.92 | K12: 1118.55 | L12: 955.94 | M12: 1142.12 | N12: 1148.12 | O12: 756.12 | P12: 618.09 | Q12: 405.44 | R12: 322.56 | S12: 585.53 | T12: 417.34
A13: Pinterest | B13: 394.63 | C13: 0.47
A14: TikTok | K14: 109.41 | L14: 117.42 | M14: 116.94 | N14: 229.85 | O14: 235.79 | P14: 235.53 | Q14: 188.02 | R14: 117.23 | S14: 114.32 | T14: 67.48
A15: Google - WW | B15: 391.27 | C15: 326.3 | D15: 284.92 | E15: 284.52 | F15: 331.33 | G15: 265.73 | H15: 256.41 | I15: 220.36 | J15: 303.02 | K15: 299.55 | L15: 344.3 | M15: 331.49 | N15: 350.49 | O15: 350.97 | P15: 367.91 | Q15: 396.35 | R15: 373.47 | S15: 245.73 | T15: 281.21 | U15: 344.54 | V15: 477.52 | W15: 518.9 | X15: 608.15 | Y15: 604.94 | Z15: 407.15 | AA15: 95.57 | AB15: 88.52 | AC15: 88.89 | AD15: 58.21 | AE15: 69.66 | AF15: 57.4
A16: Bing - WW | B16: 9.97 | C16: 7.86 | D16: 6.82 | E16: 8.42 | F16: 7.1 | G16: 8.47 | H16: 9.09 | I16: 6.88 | J16: 16.04 | K16: 4.33 | L16: 4.59 | M16: 7.93 | N16: 8.48 | O16: 7.06 | P16: 8.45 | Q16: 8.38 | R16: 12.1 | S16: 12.04 | T16: 10.02 | U16: 6.18 | V16: 4.43 | W16: 5.62 | X16: 1.55 | Y16: 8.63 | Z16: 13.425 | AA16: 10.95 | AB16: 5.34 | AC16: 3.61 | AD16: 3.49 | AE16: 6.64 | AF16: 10.14
A17: Total Spend | B17: =SUM(B11:B16) -> 7592.96 | C17: =SUM(C11:C16) -> 6064.82 | D17: =SUM(D11:D16) -> 6081.58 | E17: =SUM(E11:E16) -> 5800.09 | F17: =SUM(F11:F16) -> 6932.21 | G17: =SUM(G11:G16) -> 5821.48 | H17: =SUM(H11:H16) -> 3904.26 | I17: =SUM(I11:I16) -> 3206.15 | ... AF17: =SUM(AF11:AF16) -> 67.54
A19: ROAS | B19: =B8/B17 -> 2.5625053 | C19: =C8/C17 -> 2.2412866 | D19: =D8/D17 -> 2.1162264 | E19: =E8/E17 -> 2.6182352 | F19: =F8/F17 -> 1.3872921 | G19: =G8/G17 -> 2.4206903 | H19: =H8/H17 -> 3.1017402 | I19: =I8/I17 -> 3.8117368 | ... AF19: =AF8/AF17 -> 72.697661
A20: CAC | B20: =B17/B9 -> 110.0429 | C20: =C17/C9 -> 123.77184 | D20: =D17/D9 -> 129.39532 | E20: =E17/E9 -> 92.064921 | F20: =F17/F9 -> 182.42658 | G20: =G17/G9 -> 105.84509 | H20: =H17/H9 -> 78.0852 | I20: =I17/I9 -> 71.247778 | ... AF20: =AF17/AF9 -> 3.377
A21: CR | B21: 0.0077 | C21: 0.0065 | D21: 0.0066 | E21: 0.008 | F21: 0.0029 | G21: 0.0054 | H21: 0.0088 | I21: 0.0088 | J21: 0.0055 | K21: 0.0056 | L21: 0.0067 | M21: 0.006 | N21: 0.0046 | O21: 0.0056 | P21: 0.0091 | Q21: 0.0089 | R21: 0.0073 | S21: 0.0078 | T21: 0.0033 | U21: 0.0094 | V21: 0.0107 | W21: 0.0109 | X21: 0.0069 | Y21: 0.007 | Z21: 0.0066 | AA21: 0.0095 | AB21: 0.0112 | AC21: 0.0103 | AD21: 0.012 | AE21: 0.0167 | AF21: 0.016
A22: AOV | B22: =B8/B9 -> 281.98551 | C22: =C8/C9 -> 277.40816 | D22: =D8/D9 -> 273.82979 | E22: =E8/E9 -> 241.04762 | F22: =F8/F9 -> 253.07895 | G22: =G8/G9 -> 256.21818 | H22: =H8/H9 -> 242.2 | I22: =I8/I9 -> 271.57778 | ... AF22: =AF8/AF9 -> 245.5
A24: Post-purchase Survey
A25: Facebook / Instagram | B25: 0.6923 | C25: 0.8 | D25: 0.76 | E25: 0.7813 | F25: 0.7647 | G25: 0.6154 | H25: 0.45 | I25: 0.7368 | J25: 0.6 | K25: 0.7143 | L25: 0.5625 | M25: 0.4667 | N25: 0.6923 | O25: 0.6364 | P25: 0.5625 | Q25: 0.7143 | R25: 0.9231 | S25: 0.8125 | T25: 0.8571 | U25: 0.6111 | V25: 0.8571 | W25: 0.6429 | X25: 0.7333 | Y25: 0.7059 | Z25: 0.5263 | AA25: 0.7333 | AB25: 0.7778 | AC25: 0.6667 | AD25: 0.75 | AE25: 0.5833 | AF25: 0.4545
A26: Friends / Family | B26: 0.1282 | C26: 0.15 | D26: 0.16 | E26: 0.1875 | F26: 0 | G26: 0.1538 | H26: 0.3 | I26: 0.2105 | J26: 0.3333 | K26: 0.2143 | L26: 0.3125 | M26: 0.4667 | N26: 0.2308 | O26: 0.1818 | P26: 0.1875 | Q26: 0.2143 | R26: 0 | S26: 0.125 | T26: 0.1429 | U26: 0.3333 | V26: 0.0952 | W26: 0.1786 | X26: 0.0667 | Y26: 0.1176 | Z26: 0.4211 | AA26: 0.2 | AB26: 0.0556 | AC26: 0.1905 | AD26: 0.1 | AE26: 0.25 | AF26: 0.3636
A27: Google, Yahoo, Bing | B27: 0.1282 | C27: 0 | D27: 0 | E27: 0.0313 | F27: 0.1176 | G27: 0.0769 | H27: 0.1 | I27: 0.0526 | J27: 0.0667 | K27: 0 | L27: 0.0625 | M27: 0 | N27: 0 | O27: 0 | P27: 0 | Q27: 0 | R27: 0.0769 | S27: 0 | T27: 0 | U27: 0 | V27: 0.0476 | W27: 0.1071 | X27: 0.1333 | Y27: 0.0588 | Z27: 0 | AA27: 0 | AB27: 0.0556 | AC27: 0.0952 | AD27: 0.15 | AE27: 0 | AF27: 0
A28: Pinterest | B28: 0 | C28: 0 | D28: 0.04 | E28: 0 | F28: 0 | G28: 0 | H28: 0.05 | I28: 0 | J28: 0 | K28: 0 | L28: 0 | M28: 0 | N28: 0 | O28: 0 | P28: 0 | Q28: 0 | R28: 0 | S28: 0 | T28: 0 | U28: 0 | V28: 0 | W28: 0 | X28: 0 | Y28: 0 | Z28: 0 | AA28: 0 | AB28: 0 | AC28: 0.0476 | AD28: 0 | AE28: 0 | AF28: 0
A29: TikTok | B29: 0 | C29: 0 | D29: 0 | E29: 0 | F29: 0 | G29: 0 | H29: 0 | I29: 0 | J29: 0 | K29: 0.0714 | L29: 0 | M29: 0.0667 | N29: 0 | O29: 0.1818 | P29: 0.1875 | Q29: 0.0714 | R29: 0 | S29: 0.0625 | T29: 0 | U29: 0 | V29: 0 | W29: 0 | X29: 0 | Y29: 0 | Z29: 0 | AA29: 0 | AB29: 0 | AC29: 0 | AD29: 0 | AE29: 0 | AF29: 0
A30: TV / Radio | B30: 0 | C30: 0 | D30: 0 | E30: 0 | F30: 0.0588 | G30: 0.0769 | H30: 0.05 | I30: 0 | J30: 0 | K30: 0 | L30: 0 | M30: 0 | N30: 0 | O30: 0 | P30: 0 | Q30: 0 | R30: 0 | S30: 0 | T30: 0 | U30: 0 | V30: 0 | W30: 0.0357 | X30: 0.0667 | Y30: 0 | Z30: 0 | AA30: 0 | AB30: 0.0556 | AC30: 0 | AD30: 0 | AE30: 0.0833 | AF30: 0.0909
A31: Blog / Article | B31: 0.0513 | C31: 0.05 | D31: 0.04 | E31: 0 | F31: 0.0588 | G31: 0.0769 | H31: 0.05 | I31: 0 | J31: 0 | K31: 0 | L31: 0.0625 | M31: 0 | N31: 0.0769 | O31: 0 | P31: 0.0625 | Q31: 0 | R31: 0 | S31: 0 | T31: 0 | U31: 0.0556 | V31: 0 | W31: 0.0357 | X31: 0 | Y31: 0.1176 | Z31: 0.0526 | AA31: 0.0667 | AB31: 0.0556 | AC31: 0 | AD31: 0 | AE31: 0.0833 | AF31: 0.0909
B33: 44409
A34: Revenue | B34: =SUM(B8:AF8) -> 298006
A35: Spend | B35: =SUM(B17:AF17) -> 111419.01
A36: ROAS | B36: =B34/B35 -> 2.6746424
A37: CAC | B37: =SUM(B17:AF17)/SUM(B9:AF9) -> 98.08011
A38: CR | B38: =AVERAGE(B21:AF21) -> 0.0081387097
A39: AOV | B39: =AVERAGE(B22:AF22) -> 262.76923
A40: Orders | B40: =SUM(B9:AF9) -> 1136

Sheet Attribution
B1: 44409 | C1: 44410 | D1: 44411 | E1: 44412 | F1: 44413 | G1: 44414 | H1: 44415 | I1: 44416 | J1: 44417 | K1: 44418 | L1: 44419 | M1: 44420 | N1: 44421 | O1: 44422 | P1: 44423 | Q1: 44424 | R1: 44425 | S1: 44426 | T1: 44427 | U1: 44428 | V1: 44429 | W1: 44430 | X1: 44431 | Y1: 44432 | Z1: 44433 | AA1: 44434 | AB1: 44435 | AC1: 44436 | AD1: 44437 | AE1: 44438 | AF1: 44439
B2: SUN | C2: MON | D2: TUE | E2: WED | F2: THU | G2: FRI | H2: SAT | I2: SUN | J2: SUN | K2: MON | L2: TUE | M2: WED | N2: THU | O2: FRI | P2: SAT | Q2: SUN | R2: SUN | S2: MON | T2: TUE | U2: WED | V2: THU | W2: FRI | X2: SAT | Y2: SUN | Z2: SUN | AA2: MON | AB2: TUE | AC2: WED | AD2: THU | AE2: FRI | AF2: SAT
A3: FB Orders (Shopify + IGG) | B3: 33 | C3: 24 | D3: 23 | E3: 29 | F3: 19 | G3: 17 | H3: 17 | I3: 14 | J3: 13 | K3: 10 | L3: 3 | M3: 6 | N3: 10 | O3: 8 | P3: 11 | Q3: 9 | R3: 5 | S3: 7 | T3: 4 | U3: 11 | V3: 11 | W3: 15 | X3: 10 | Y3: 5 | Z3: 15 | AA3: 13 | AB3: 10 | AC3: 14 | AD3: 10 | AE3: 2 | AF3: 7
A4: All Orders (Shopify + IGG) | B4: =Sales!B9 -> 69 | C4: =Sales!C9 -> 49 | D4: =Sales!D9 -> 47 | E4: =Sales!E9 -> 63 | F4: =Sales!F9 -> 38 | G4: =Sales!G9 -> 55 | H4: =Sales!H9 -> 50 | I4: =Sales!I9 -> 45 | ... AF4: =Sales!AF9 -> 20
A5: % Attributed to FB (Ads Manager) | B5: =B3/B4 -> 0.47826087 | C5: =C3/C4 -> 0.48979592 | D5: =D3/D4 -> 0.4893617 | E5: =E3/E4 -> 0.46031746 | F5: =F3/F4 -> 0.5 | G5: =G3/G4 -> 0.30909091 | H5: =H3/H4 -> 0.34 | I5: =I3/I4 -> 0.31111111 | ... AF5: =AF3/AF4 -> 0.35
A7: Attribution
A9: Notes
A11: FB Orders (Shopify) | B11: 20 | C11: 16 | D11: 12 | E11: 13 | F11: 12 | G11: 11 | H11: 2 | I11: 8 | J11: 9 | K11: 8 | L11: 2 | M11: 3 | N11: 7 | O11: 7 | P11: 9 | Q11: 6 | R11: 4 | S11: 5 | T11: 3 | U11: 4 | V11: 10 | W11: 12 | X11: 9 | Y11: 5 | Z11: 13 | AA11: 7 | AB11: 7 | AC11: 12 | AD11: 6 | AE11: 1 | AF11: 0
A13: GA (UTM: fb-paid) Orders (Shopify) | B13: 24 | C13: 10 | D13: 15 | E13: 13 | F13: 10 | G13: 8 | H13: 5 | I13: 5 | J13: 5 | K13: 2 | L13: 5 | M13: 4 | N13: 5 | O13: 4 | P13: 7 | Q13: 4 | R13: 5 | S13: 6 | T13: 3 | U13: 7 | V13: 10 | W13: 10 | X13: 9 | Y13: 6 | Z13: 8 | AA13: 9 | AB13: 7 | AC13: 6 | AD13: 4 | AE13: 1 | AF13: 2
A14: % difference | B14: =B13/B11 -> 1.2 | C14: =C13/C11 -> 0.625 | D14: =D13/D11 -> 1.25 | E14: =E13/E11 -> 1 | F14: =F13/F11 -> 0.83333333 | G14: =G13/G11 -> 0.72727273 | H14: =H13/H11 -> 2.5 | I14: =I13/I11 -> 0.625 | ... AF14: =AF13/AF11 -> #DIV/0!
A16: Social Orders (Shopify) | B16: 22 | C16: 11 | D16: 15 | E16: 14 | F16: 10 | G16: 9 | H16: 4 | I16: 6 | J16: 4 | K16: 2 | L16: 8 | M16: 3 | N16: 6 | O16: 5 | P16: 10 | Q16: 3 | R16: 8 | S16: 6 | T16: 4 | U16: 9 | V16: 14 | W16: 8 | X16: 9 | Y16: 9 | Z16: 7 | AA16: 11 | AB16: 14 | AC16: 9 | AD16: 10 | AE16: 6 | AF16: 0
A17: % difference | B17: =B16/B11 -> 1.1 | C17: =C16/C11 -> 0.6875 | D17: =D16/D11 -> 1.25 | E17: =E16/E11 -> 1.0769231 | F17: =F16/F11 -> 0.83333333 | G17: =G16/G11 -> 0.81818182 | H17: =H16/H11 -> 2 | I17: =I16/I11 -> 0.75 | ... AF17: =AF16/AF11 -> #DIV/0!
A19: PP Survey (FB) Orders | B19: 27 | C19: 16 | D19: 19 | E19: 25 | F19: 13 | G19: 16 | H19: 9 | I19: 14 | J19: 9 | K19: 10 | L19: 9 | M19: 7 | N19: 9 | O19: 7 | P19: 9 | Q19: 10 | R19: 12 | S19: 13 | T19: 6 | U19: 11 | V19: 18 | W19: 18 | X19: 11 | Y19: 12 | Z19: 10 | AA19: 11 | AB19: 14 | AC19: 14 | AD19: 15 | AE19: 7 | AF19: 5
A20: PP Survey (FB) Orders Modeled #1 | B20: =(1-B22)*B19+B19 -> 35.3079 | C20: =(1-C22)*C19+C19 -> 19.2 | D20: =(1-D22)*D19+D19 -> 23.56 | E20: =(1-E22)*E19+E19 -> 30.4675 | F20: =(1-F22)*F19+F19 -> 16.0589 | G20: =(1-G22)*G19+G19 -> 22.1536 | H20: =(1-H22)*H19+H19 -> 13.95 | I20: =(1-I22)*I19+I19 -> 17.6848 | ... AF20: =(1-AF22)*AF19+AF19 -> 7.7275
A21: PP Survey (FB) Orders Modeled #2 | B21: =(1-B33)*B20+B20 -> 41.960113 | C21: =(1-C33)*C20+C20 -> 24.685714 | D21: =(1-D33)*D20+D20 -> 29.575319 | E21: =(1-E33)*E20+E20 -> 38.688889 | F21: =(1-F33)*F20+F20 -> 18.594516 | G21: =(1-G33)*G20+G20 -> 29.403869 | H21: =(1-H33)*H20+H20 -> 19.251 | I21: =(1-I33)*I20+I20 -> 27.902684 | ... AF21: =(1-AF33)*AF20+AF20 -> 8.50025
A22: Response Rate | B22: 0.6923 | C22: 0.8 | D22: 0.76 | E22: 0.7813 | F22: 0.7647 | G22: 0.6154 | H22: 0.45 | I22: 0.7368 | J22: 0.6 | K22: 0.7143 | L22: 0.5625 | M22: 0.4667 | N22: 0.6923 | O22: 0.6364 | P22: 0.5625 | Q22: 0.7143 | R22: 0.9231 | S22: 0.8125 | T22: 0.8571 | U22: 0.6111 | V22: 0.8571 | W22: 0.6429 | X22: 0.7333 | Y22: 0.7059 | Z22: 0.5263 | AA22: 0.7333 | AB22: 0.7778 | AC22: 0.6667 | AD22: 0.75 | AE22: 0.5833 | AF22: 0.4545
A23: % difference | B23: =B21/B11 -> 2.0980057 | C23: =C21/C11 -> 1.5428571 | D23: =D21/D11 -> 2.4646099 | E23: =E21/E11 -> 2.9760684 | F23: =F21/F11 -> 1.549543 | G23: =G21/G11 -> 2.673079 | H23: =H21/H11 -> 9.6255 | I23: =I21/I11 -> 3.4878356 | ... AF23: =AF21/AF11 -> #DIV/0!
A27: Shopify (All) | B27: =Sales!B9 -> 69 | C27: =Sales!C9 -> 49 | D27: =Sales!D9 -> 47 | E27: =Sales!E9 -> 63 | F27: =Sales!F9 -> 38 | G27: =Sales!G9 -> 55 | H27: =Sales!H9 -> 50 | I27: =Sales!I9 -> 45 | ... AF27: =Sales!AF9 -> 20
A29: GA (Shopify) | B29: 54 | C29: 37 | D29: 34 | E29: 47 | F29: 33 | G29: 38 | H29: 29 | I29: 31 | J29: 22 | K29: 23 | L29: 27 | M29: 23 | N29: 19 | O29: 19 | P29: 30 | Q29: 21 | R29: 23 | S29: 27 | T29: 11 | U29: 28 | V29: 35 | W29: 39 | X29: 23 | Y29: 25 | Z29: 26 | AA29: 30 | AB29: 31 | AC29: 26 | AD29: 29 | AE29: 28 | AF29: 19
A30: % difference | B30: =B29/B27 -> 0.7826087 | C30: =C29/C27 -> 0.75510204 | D30: =D29/D27 -> 0.72340426 | E30: =E29/E27 -> 0.74603175 | F30: =F29/F27 -> 0.86842105 | G30: =G29/G27 -> 0.69090909 | H30: =H29/H27 -> 0.58 | I30: =I29/I27 -> 0.68888889 | ... AF30: =AF29/AF27 -> 0.95
A32: PP Survey (All) Orders Views | B32: 56 | C32: 35 | D32: 35 | E32: 46 | F32: 32 | G32: 37 | H32: 31 | I32: 19 | J32: 23 | K32: 23 | L32: 29 | M32: 26 | N32: 23 | O32: 20 | P32: 31 | Q32: 26 | R32: 21 | S32: 29 | T32: 13 | U32: 29 | V32: 34 | W32: 38 | X32: 24 | Y32: 25 | Z32: 27 | AA32: 32 | AB32: 33 | AC32: 28 | AD32: 32 | AE32: 25 | AF32: 18
A33: % difference | B33: =B32/B27 -> 0.8115942 | C33: =C32/C27 -> 0.71428571 | D33: =D32/D27 -> 0.74468085 | E33: =E32/E27 -> 0.73015873 | F33: =F32/F27 -> 0.84210526 | G33: =G32/G27 -> 0.67272727 | H33: =H32/H27 -> 0.62 | I33: =I32/I27 -> 0.42222222 | ... AF33: =AF32/AF27 -> 0.9

Sheet Detailed Report
A1: MESEC | B1: 44409 | C1: 44410 | D1: 44411 | E1: 44412 | F1: 44413 | G1: 44414 | H1: 44415 | I1: 44416 | J1: 44417 | K1: 44418 | L1: 44419 | M1: 44420 | N1: 44421 | O1: 44422 | P1: 44423 | Q1: 44424 | R1: 44425 | S1: 44426 | T1: 44427 | U1: 44428 | V1: 44429 | W1: 44430 | X1: 44431 | Y1: 44432 | Z1: 44433 | AA1: 44434 | AB1: 44435 | AC1: 44436 | AD1: 44437 | AE1: 44438 | AF1: 44439 | AG1: Skupaj
A2: DAN | B2: NED | C2: PON | D2: TOR | E2: SRE | F2: ČET | G2: PET | H2: SOB | I2: NED | J2: PON | K2: TOR | L2: SRE | M2: ČET | N2: PET | O2: SOB | P2: NED | Q2: PON | R2: TOR | S2: SRE | T2: ČET | U2: PET | V2: SOB | W2: NED | X2: PON | Y2: TOR | Z2: SRE | AA2: ČET | AB2: PET | AC2: SOB | AD2: NED | AE2: PON | AF2: TOR
A3: KOMENTAR
A4: Transakcije
A5: Google (MuteSIX) | B5: 8 | C5: 6 | D5: 7 | E5: 9 | F5: 5 | G5: 13 | H5: 7 | I5: 9 | J5: 6 | K5: 6 | L5: 7 | M5: 6 | N5: 3 | O5: 2 | P5: 9 | Q5: 4 | R5: 6 | S5: 8 | T5: 1 | U5: 7 | V5: 5 | W5: 13 | X5: 9 | Y5: 6 | Z5: 3 | AA5: 4 | AB5: 4 | AC5: 5 | AD5: 5 | AE5: 10 | AF5: 5 | AG5: =SUM(B5:AF5) -> 198
A6: FB (IGG Digital Team) | AG6: =SUM(B6:AF6) -> 0
A7: FB (Backerkit) | AG7: =SUM(B7:AF7) -> 0
A8: FB (Internal Paid) | B8: 7 | C8: 7 | D8: 4 | E8: 7 | F8: 9 | G8: 2 | H8: 2 | I8: 0 | J8: 2 | K8: 3 | L8: 0 | M8: 2 | N8: 1 | O8: 4 | P8: 1 | Q8: 1 | R8: 1 | S8: 0 | T8: 0 | AG8: =SUM(B8:AF8) -> 53
A9: FB (US & CA) | B9: 26 | C9: 17 | D9: 19 | E9: 22 | F9: 10 | G9: 15 | H9: 15 | I9: 14 | J9: 11 | K9: 7 | L9: 3 | M9: 4 | N9: 9 | O9: 4 | P9: 10 | Q9: 8 | R9: 4 | S9: 7 | T9: 4 | U9: 11 | V9: 11 | W9: 15 | X9: 10 | Y9: 5 | Z9: 15 | AA9: 13 | AB9: 10 | AC9: 14 | AD9: 10 | AE9: 2 | AF9: 7 | AG9: =SUM(B9:AF9) -> 332
A10: FB (EU & UK) | AG10: =SUM(B10:AF10) -> 0
A11: Bing Microsoft | B11: 0 | C11: 1 | D11: 0 | E11: 1 | F11: 0 | G11: 0 | H11: 1 | I11: 0 | J11: 0 | K11: 0 | L11: 0 | M11: 1 | N11: 0 | O11: 1 | P11: 0 | Q11: 0 | R11: 0 | S11: 0 | T11: 0 | U11: 0 | V11: 1 | W11: 1 | X11: 0 | Y11: 1 | Z11: 0 | AA11: 1 | AB11: 1 | AC11: 1 | AD11: 0 | AE11: 1 | AF11: 1 | AG11: =SUM(B11:AF11) -> 13
A12: Pinterest | B12: 0 | AG12: =SUM(B12:AF12) -> 0
A13: TikTok | K13: 1 | L13: 0 | M13: 1 | N13: 0 | O13: 1 | P13: 2 | Q13: 0 | R13: 0 | S13: 0 | T13: 0 | AG13: =SUM(B13:AF13) -> 5
A14: Skupaj | B14: =SUM(B5:B13) -> 41 | C14: =SUM(C5:C13) -> 31 | D14: =SUM(D5:D13) -> 30 | E14: =SUM(E5:E13) -> 39 | F14: =SUM(F5:F13) -> 24 | G14: =SUM(G5:G13) -> 30 | H14: =SUM(H5:H13) -> 25 | I14: =SUM(I5:I13) -> 23 | ... AF14: =SUM(AF5:AF13) -> 13 | AG14: =SUM(B14:AF14) -> 601
A16: Prihodek
A17: Google (MuteSIX) | B17: 2834 | C17: 1309 | D17: 1582 | E17: 2564 | F17: 1416 | G17: 3294 | H17: 1645 | I17: 2211 | J17: 1250 | K17: 2089 | L17: 1416 | M17: 1718 | N17: 970 | O17: 666 | P17: 3024 | Q17: 1141 | R17: 1365 | S17: 1921 | T17: 387 | U17: 1509 | V17: 1501 | W17: 3525 | X17: 2792 | Y17: 1683 | Z17: 673 | AA17: 972 | AB17: 1092 | AC17: 1705 | AD17: 1265 | AE17: 2482 | AF17: 1172 | AG17: =SUM(B17:AF17) -> 53173
A18: FB (IGG Digital Team) | AG18: =SUM(B18:AF18) -> 0
A19: FB (Backerkit) | AG19: =SUM(B19:AF19) -> 0
A20: FB (Internal Paid) | B20: 2472.68 | C20: 956.71 | D20: 1086.31 | E20: 1552.65 | F20: 1426.62 | G20: 588.14 | H20: 575.8 | I20: 0 | J20: 453.46 | K20: 483.16 | L20: 0 | M20: 572.9 | N20: 15.09 | O20: 842.87 | P20: 203.17 | Q20: 99.57 | R20: 290.56 | S20: 0 | T20: 0 | AG20: =SUM(B20:AF20) -> 11619.69
A21: FB (US & CA) | B21: 6489.65 | C21: 4350.01 | D21: 6708.73 | E21: 5122.95 | F21: 2834.61 | G21: 3712.09 | H21: 3527.9 | I21: 3503.42 | J21: 2629.74 | K21: 1755.34 | L21: 651.16 | M21: 885.46 | N21: 2718.54 | O21: 1114.88 | P21: 2140.95 | Q21: 2182.34 | R21: 1090.37 | S21: 1727.32 | T21: 858.89 | U21: 2953.11 | V21: 2453.53 | W21: 2482.4 | X21: 2413.99 | Y21: 1563.61 | Z21: 466.42 | AA21: 3241.53 | AB21: 3470.82 | AC21: 2461.53 | AD21: 3479.22 | AE21: 4959.81 | AF21: 1107.64 | AG21: =SUM(B21:AF21) -> 85057.96
A22: FB (EU & UK) | AG22: =SUM(B22:AF22) -> 0
A23: Microsoft | B23: 0 | C23: 236 | D23: 0 | E23: 206 | F23: 0 | G23: 0 | H23: 206 | I23: 0 | J23: 0 | K23: 0 | L23: 0 | M23: 206 | N23: 0 | O23: 265 | P23: 0 | Q23: 0 | R23: 0 | S23: 0 | T23: 0 | U23: 0 | V23: 265 | W23: 206 | X23: 0 | Y23: 206 | Z23: 0 | AA23: 379 | AB23: 71 | AC23: 206 | AD23: 0 | AE23: 206 | AF23: 224 | AG23: =SUM(B23:AF23) -> 2882
A24: Pinterest | B24: 0 | C24: 0 | AG24: =SUM(B24:AF24) -> 0
A25: TikTok | K25: 188.91 | L25: 0 | M25: 188.93 | N25: 0 | O25: 248.37 | P25: 527.36 | Q25: 0 | R25: 0 | S25: 0 | T25: 0 | AG25: =SUM(B25:AF25) -> 1153.57
A26: Skupaj | B26: =SUM(B17:B25) -> 11796.33 | C26: =SUM(C17:C25) -> 6851.72 | D26: =SUM(D17:D25) -> 9377.04 | E26: =SUM(E17:E25) -> 9445.6 | F26: =SUM(F17:F25) -> 5677.23 | G26: =SUM(G17:G25) -> 7594.23 | H26: =SUM(H17:H25) -> 5954.7 | I26: =SUM(I17:I25) -> 5714.42 | ... AF26: =SUM(AF17:AF25) -> 2503.64 | AG26: =SUM(B26:AF26) -> 153886.22
A28: Odhodek
A29: Google Spend (MuteSIX) | B29: 390.94 | C29: 326.11 | D29: 284.79 | E29: 284.43 | F29: 331.33 | G29: 265.55 | H29: 256.29 | I29: 220.36 | J29: 303.02 | K29: 299.55 | L29: 344.3 | M29: 331.49 | N29: 350.49 | O29: 350.97 | P29: 367.91 | Q29: 396.35 | R29: 373.47 | S29: 245.6 | T29: 281.21 | U29: 344.54 | V29: 477.52 | W29: 518.9 | X29: 608.15 | Y29: 604.88 | Z29: 407.07 | AA29: 95.57 | AB29: 88.52 | AC29: 88.89 | AD29: 58.21 | AE29: 69.66 | AF29: 57.4 | AG29: =SUM(B29:AF29) -> 9423.47
A30: Provizija 15% Spend (MuteSIX) / $3,500 | B30: =B29*0.15 -> 58.641 | C30: =C29*0.15 -> 48.9165 | D30: =D29*0.15 -> 42.7185 | E30: =E29*0.15 -> 42.6645 | F30: =F29*0.15 -> 49.6995 | G30: =G29*0.15 -> 39.8325 | H30: =H29*0.15 -> 38.4435 | I30: =I29*0.15 -> 33.054 | ... Z30: =Z29*0.15 -> 61.0605 | AG30: =SUM(B30:AF30) -> 1344.783
A31: FB Spend (IGG Digital Team) | AG31: =SUM(B31:AF31) -> 0
A32: Provizija 13% Purchase (IGG Digital Team) | AG32: =SUM(B32:AF32) -> 0
A33: FB Spend (Backerkit) | AG33: =SUM(B33:AF33) -> 0
A34: Provizija 15% Purchase (Backerkit) | B34: =B19*0.15 -> 0 | C34: =C19*0.15 -> 0 | D34: =D19*0.15 -> 0 | E34: =E19*0.15 -> 0 | F34: =F19*0.15 -> 0 | G34: =G19*0.15 -> 0 | H34: =H19*0.15 -> 0 | I34: =I19*0.15 -> 0 | ... AF34: =AF19*0.15 -> 0 | AG34: =SUM(B34:AF34) -> 0
A35: FB Spend (Internal Paid) | B35: 2859.39 | C35: 2602.89 | D35: 1719.9 | E35: 1389.34 | F35: 2513 | G35: 992.98 | H35: 0 | I35: 0 | J35: 510.92 | K35: 1121.16 | L35: 955.94 | M35: 1142.12 | N35: 1148.12 | O35: 756.12 | P35: 618.09 | Q35: 405.44 | R35: 322.56 | S35: 585.53 | T35: 417.34 | AG35: =SUM(B35:AF35) -> 20060.84
A36: FB Spend (US & CA) | B36: 3913.6 | C36: 3098.93 | D36: 4048.11 | E36: 4104.28 | F36: 4072.73 | G36: 4553.36 | H36: 3637.62 | I36: 2979.08 | J36: 2898.89 | K36: 2852.24 | L36: 1974.56 | M36: 1277.33 | N36: 1284.07 | O36: 1417.81 | P36: 1372.36 | Q36: 1598.13 | R36: 1708.5 | S36: 2011.99 | T36: 2358.06 | U36: 2655.29 | V36: 2445.38 | W36: 2479.78 | X36: 2415.26 | Y36: 2937.83 | Z36: 3377.03 | AA36: 3096.26 | AB36: 2959.2 | AC36: 2686.35 | AD36: 2570.63 | AE36: 1001.56 | AF36: 0 | AG36: =SUM(B36:AF36) -> 79786.22
A37: Microsoft Spend | B37: 9.97 | C37: 7.86 | D37: 6.82 | E37: 8.42 | F37: 7.1 | G37: 8.47 | H37: 9.09 | I37: 6.88 | J37: 16.04 | K37: 4.33 | L37: 4.59 | M37: 7.93 | N37: 8.48 | O37: 7.06 | P37: 8.45 | Q37: 8.38 | R37: 12.1 | S37: 12.04 | T37: 10.02 | U37: 6.18 | V37: 4.43 | W37: 5.62 | X37: 1.55 | Y37: 8.63 | Z37: 13.25 | AA37: 10.95 | AB37: 5.34 | AC37: 3.61 | AD37: 3.49 | AE37: 6.64 | AF37: 9.32 | AG37: =SUM(B37:AF37) -> 243.04
A38: Pinterest Spend | B38: 394.63 | C38: 0.47 | AG38: =SUM(B38:AF38) -> 395.1
A39: TikTok Spend | K39: 109.41 | L39: 117.42 | M39: 116.94 | N39: 229.85 | O39: 235.79 | P39: 235.53 | Q39: 188.02 | R39: 117.23 | S39: 114.32 | T39: 67.48 | AG39: =SUM(B39:AF39) -> 1531.99
A40: FB Spend (EU & UK) | AG40: =SUM(B40:AF40) -> 0
A41: Platform Fee (6,90%) | AG41: =SUM(B41:AF41) -> 0
A42: Processing Fee (2,6%) | B42: =B26*0.026 -> 306.70458 | C42: =C26*0.026 -> 178.14472 | D42: =D26*0.026 -> 243.80304 | E42: =E26*0.026 -> 245.5856 | F42: =F26*0.026 -> 147.60798 | G42: =G26*0.026 -> 197.44998 | H42: =H26*0.026 -> 154.8222 | I42: =I26*0.026 -> 148.57492 | ... AF42: =AF26*0.026 -> 65.09464 | AG42: =SUM(B42:AF42) -> 4001.0417
...

Sheet Refunds
A1: Date | B1: Order ID | C1: Name | D1: Email | E1: Value | F1: Reason | G1: Platform
A2: 44235 | B2: #8892 | C2: Kolbi Olson | D2: kolbileigh@gmail.com | E2: 381 | F2: Doesn't want BB anymore | G2: Shopify | H2: Reason | I2: Number
A3: 44235 | B3: #7444 | C3: Janice Forry | D3: jforry34@gmail.com | E3: 59 | F3: Partial refund - duplicate add-on | G3: Shopify | H3: Delivery Date | I3: 13 | J3: =I3/I9 -> 0.31707317
A4: 44235 | B4: #14221 | C4: Benno Lamboy | D4: si3ygryzzg@privaterelay.appleid.com | E4: 178 | F4: Cannot afford it anymore | G4: Kickstarter | H4: Cannot Afford it Anymore | I4: 7 | J4: =I4/I9 -> 0.17073171
A5: 44235 | B5: #9924 | C5: Elizabeth McGauley | D5: beth@mcgauley.com | E5: 369 | F5: Cannot afford it anymore | G5: Shopify | H5: Moving | I5: 1 | J5: =I5/I9 -> 0.024390244
A6: 44294 | B6: #9203 | C6: Chris Jacona | D6: zoggsbar@aol.com | E6: 265 | F6: Delivery date | G6: Shopify | H6: Refund and order another Bundle | I6: 0 | J6: =I6/I9 -> 0
A7: 44294 | B7: #4376 | C7: Harrison Bade | D7: artifactsinmotion@icloud.com | E7: 224 | F7: Doesn't want BB anymore | G7: Shopify | H7: Unknown | I7: 7 | J7: =I7/I9 -> 0.17073171
A8: 44294 | B8: #10344 | C8: Maureen Sellers | D8: Maureensel@aol.com | E8: 206 | F8: Doesn't want BB anymore | G8: Shopify | H8: Other | I8: 13 | J8: =I8/I9 -> 0.31707317
A9: 44294 | B9: #10281 | C9: Lydia Haren | D9: lydiaharen@bellsouth.net | E9: 369 | F9: Delivery date | G9: Shopify | H9: All | I9: =SUM(I3:I8) -> 41
A10: 44294 | B10: #10624 | C10: Laura Hird | D10: misty15@hotmail.co.uk | E10: 202 | F10: Delivery date | G10: Shopify
A11: 44324 | B11: #10247 | C11: Stephanie Pelletier | D11: stephtier@icloud.com | E11: 414 | F11: Delivery date | G11: Shopify | H11: All Orders | I11: =Sales!B40 -> 1136
A12: 44324 | B12: #1116 | C12: Jens Hubert | D12: tryllekunstner@yahoo.dk | E12: 202 | F12: Duplicate order | G12: Indiegogo
A13: 44355 | B13: #10726 | C13: Hendrik Narius | D13: h-narius@t-online.de | E13: 261 | F13: Doesn't want BB anymore | G13: Shopify | H13: Refund % | I13: =I9/I11 -> 0.036091549
A14: 44324 | B14: #10712 | C14: Rebecca Wilson | D14: rwilson423@gmail.com | E14: 255 | F14: Cannot afford it anymore | G14: Shopify
A15: 44355 | B15: #2717 | C15: Susan Wilson | D15: classicduo@msn.com | E15: 191 | F15: Cannot afford it anymore | G15: Shopify
A16: 44447 | B16: #2473 | C16: Geoffrey Rugh | D16: geoffreyrugh@gmail.com | E16: 218 | F16: Doesn't want BB anymore | G16: Indiegogo
A17: 44477 | B17: #10851 | C17: Simon Lamb | D17: simon@houseofnarcisse.com | E17: 224 | F17: Delivery date | G17: Shopify
A18: 44477 | B18: #8397 | C18: Beulah Prosser | D18: tannybogus@hotmail.com | E18: 206 | F18: Doesn't want BB anymore | G18: Shopify
A19: 44477 | B19: #10170 | C19: Chelsea Fluker | D19: megaboygamer@yahoo.com | E19: 206 | F19: Cannot afford it anymore | G19: Shopify
A20: 44477 | B20: #31 | C20: Wallner Matthias | D20: maiseb77@gmail.com | E20: 265 | F20: Delivery date | G20: Indiegogo
A21: 44508 | B21: #8714 | C21: Ginni Rosenfeld | D21: drgin64@gmail.com | E21: 487 | F21: Delivery date | G21: Shopify
A22: 44538 | B22: #1677 | C22: Virginia Haley | D22: haleyv@charter.net | E22: 206 | F22: Delivery date | G22: Shopify
A23: 16/8/2021 | B23: #10916 | C23: Eileen Avera | D23: eileen.avera@gmail.com | E23: 206 | F23: Gift recepient already pre-ordered | G23: Shopify
A24: 16/8/2021 | B24: #10957 | C24: Jason Linder | D24: jlinder@gmail.com | E24: 206 | F24: Delivery date | G24: Shopify
A25: 17/8/2021 | B25: #10780 | C25: Josef Breitenfellner | D25: breitenfellner.josef@gmail.com | E25: 261 | F25: Delivery date | G25: Shopify
A26: 17/8/2021 | B26: #10866 | C26: Matthew Peacock | D26: mattapeacock@me.com | E26: 206 | F26: Waiting for response | G26: Shopify
A27: 17/8/2022 | B27: #10974 | C27: Travis Mock | D27: tomock@gmail.com | E27: 189 | F27: Delivery date | G27: Shopify
A28: 17/8/2023 | B28: #9690 | C28: Daniel Aprile | D28: danaprile@gmail.com | E28: 206 | F28: Doesn't want BB anymore | G28: Indiegogo
A29: 17/8/2024 | B29: #3555 | C29: Nathan Reif | D29: snnation@gmail.com | E29: 206 | F29: Doesn't want BB anymore | G29: Indiegogo
A30: 18/8/2021 | B30: #9288 | C30: Steven Hummel | D30: steven.hummel@aol.com | E30: 206 | F30: Waiting for response | G30: Indiegogo
A31: 18/8/2021 | B31: #3603 | C31: Lee Holden | D31: lee@kettlecup.co.uk | E31: 261 | F31: Doesn't want BB anymore | G31: Indiegogo
A32: 19/8/2021 | B32: #7864 | C32: Rylan Morabito | D32: rylanexplores@gmail.com | E32: 209 | F32: Waiting for response | G32: Shopify
A33: 23/8/2021 | B33: #11150 | C33: Frances Fortune | D33: ffffortune1@gmail.com | E33: 206 | F33: Waiting for response | G33: Shopify
A34: 23/8/2021 | B34: #10698 | C34: Donna Stevenson | D34: donnastevenson8@msn.com | E34: 464 | F34: Delivery date | G34: Shopify
... A43: 31/8/2021 | B43: #11439 | C43: Kevin C. Wiman | D43: kevin.wiman@gmail.com | E43: 283 | F43: Waiting for response | G43: Shopify

Sheet Formula
A1: Conversion Rate | G1: AOV
C2: CR | D2: Orders | E2: Weighted average | I2: AOV | J2: Orders | K2: Weighted average
A3: 44409 | B3: Shopify | C3: 0.0069 | D3: 59 | E3: =IFERROR(__xludf.DUMMYFUNCTION("AVERAGE.WEIGHTED(C3:C4,D3:D4)"),0.007668115942028986) -> 0.0076681159 | G3: 44409 | H3: Shopify | I3: 291.37 | J3: 59 | K3: =IFERROR(__xludf.DUMMYFUNCTION("AVERAGE.WEIGHTED(I3:I4,J3:J4)"),281.98304347826087) -> 281.98304
B4: IGG | C4: 0.0122 | D4: 10 | H4: IGG | I4: 226.6 | J4: 10
A5: 44410 | B5: Shopify | C5: 0.0052 | D5: 38 | E5: =IFERROR(__xludf.DUMMYFUNCTION("AVERAGE.WEIGHTED(C5:C6,D5:D6)"),0.0064795918367346935) -> 0.0064795918 | G5: 44410 | H5: Shopify | I5: 288.03 | J5: 38 | K5: =IFERROR(__xludf.DUMMYFUNCTION("AVERAGE.WEIGHTED(I5:I6,J5:J6)"),277.4116326530612) -> 277.41163
B6: IGG | C6: 0.0109 | D6: 11 | H6: IGG | I6: 240.73 | J6: 11
A7: 44411 | B7: Shopify | C7: 0.0059 | D7: 37 | E7: =IFERROR(__xludf.DUMMYFUNCTION("AVERAGE.WEIGHTED(C7:C8,D7:D8)"),0.006580851063829787) -> 0.0065808511 | G7: 44411 | H7: Shopify | I7: 280.41 | J7: 37 | K7: =IFERROR(__xludf.DUMMYFUNCTION("AVERAGE.WEIGHTED(I7:I8,J7:J8)"),273.8334042553192) -> 273.8334
B8: IGG | C8: 0.0091 | D8: 10 | H8: IGG | I8: 249.5 | J8: 10
A9: 44412 | B9: Shopify | C9: 0.0072 | D9: 50 | E9: =IFERROR(__xludf.DUMMYFUNCTION("AVERAGE.WEIGHTED(C9:C10,D9:D10)"),0.007963492063492063) -> 0.0079634921 | G9: 44412 | H9: Shopify | I9: 247.74 | J9: 50 | K9: =IFERROR(__xludf.DUMMYFUNCTION("AVERAGE.WEIGHTED(I9:I10,J9:J10)"),241.04809523809524) -> 241.0481
B10: IGG | C10: 0.0109 | D10: 13 | H10: IGG | I10: 215.31 | J10: 13
A11: 44413 | B11: Shopify | C11: 0.0029 | D11: 33 | E11: =IFERROR(__xludf.DUMMYFUNCTION("AVERAGE.WEIGHTED(C11:C12,D11:D12)"),0.0028736842105263156) -> 0.0028736842 | G11: 44413 | H11: Shopify | I11: 257.61 | J11: 33 | K11: =IFERROR(__xludf.DUMMYFUNCTION("AVERAGE.WEIGHTED(I11:I12,J11:J12)"),253.08236842105265) -> 253.08237
B12: IGG | C12: 0.0027 | D12: 5 | H12: IGG | I12: 223.2 | J12: 5
A13: 44414 | B13: Shopify | C13: 0.0045 | D13: 39 | E13: =IFERROR(__xludf.DUMMYFUNCTION("AVERAGE.WEIGHTED(C13:C14,D13:D14)"),0.005401818181818181) -> 0.0054018182 | G13: 44414 | H13: Shopify | I13: 261.46 | J13: 39 | K13: =IFERROR(__xludf.DUMMYFUNCTION("AVERAGE.WEIGHTED(I13:I14,J13:J14)"),256.2178181818182) -> 256.21782
B14: IGG | C14: 0.0076 | D14: 16 | H14: IGG | I14: 243.44 | J14: 16
A15: 44415 | B15: Shopify | C15: 0.0068 | D15: 31 | E15: =IFERROR(__xludf.DUMMYFUNCTION("AVERAGE.WEIGHTED(C15:C16,D15:D16)"),0.008775999999999999) -> 0.008776 | G15: 44415 | H15: Shopify | I15: 257 | J15: 31 | K15: =IFERROR(__xludf.DUMMYFUNCTION("AVERAGE.WEIGHTED(I15:I16,J15:J16)"),242.199) -> 242.199
B16: IGG | C16: 0.012 | D16: 19 | H16: IGG | I16: 218.05 | J16: 19
A17: 44416 | B17: Shopify | C17: 0.009 | D17: 34 | E17: =IFERROR(__xludf.DUMMYFUNCTION("AVERAGE.WEIGHTED(C17:C18,D17:D18)"),0.00878) -> 0.00878 | G17: 44416 | H17: Shopify | I17: 278.97 | J17: 34 | K17: =IFERROR(__xludf.DUMMYFUNCTION("AVERAGE.WEIGHTED(I17:I18,J17:J18)"),271.57800000000003) -> 271.578
B18: IGG | C18: 0.0081 | D18: 11 | H18: IGG | I18: 248.73 | J18: 11
A19: 44417 | B19: Shopify | C19: 0.0055 | D19: 25 | E19: =IFERROR(__xludf.DUMMYFUNCTION("AVERAGE.WEIGHTED(C19:C20,D19:D20)"),0.005539024390243902) -> 0.0055390244 | G19: 44417 | H19: Shopify | I19: 220.76 | J19: 25 | K19: =IFERROR(__xludf.DUMMYFUNCTION("AVERAGE.WEIGHTED(I19:I20,J19:J20)"),234.02439024390245) -> 234.02439
B20: IGG | C20: 0.0056 | D20: 16 | H20: IGG | I20: 254.75 | J20: 16
A21: 44418 | B21: Shopify | C21: 0.0066 | D21: 25 | E21: =IFERROR(__xludf.DUMMYFUNCTION("AVERAGE.WEIGHTED(C21:C22,D21:D22)"),0.005571875) -> 0.005571875 | G21: 44418 | H21: Shopify | I21: 284.6 | J21: 25 | K21: =IFERROR(__xludf.DUMMYFUNCTION("AVERAGE.WEIGHTED(I21:I22,J21:J22)"),275.749375) -> 275.74937
B22: IGG | C22: 0.0019 | D22: 7 | H22: IGG | I22: 244.14 | J22: 7
A23: 44419 | B23: Shopify | C23: 0.0076 | D23: 29 | E23: =IFERROR(__xludf.DUMMYFUNCTION("AVERAGE.WEIGHTED(C23:C24,D23:D24)"),0.006744444444444444) -> 0.0067444444 | G23: 44419 | H23: Shopify | I23: 245.52 | J23: 29 | K23: =IFERROR(__xludf.DUMMYFUNCTION("AVERAGE.WEIGHTED(I23:I24,J23:J24)"),249.28055555555557) -> 249.28056
B24: IGG | C24: 0.0032 | D24: 7 | H24: IGG | I24: 264.86 | J24: 7
A25: 44420 | B25: Shopify | C25: 0.0062 | D25: 27 | E25: =IFERROR(__xludf.DUMMYFUNCTION("AVERAGE.WEIGHTED(C25:C26,D25:D26)"),0.005971428571428571) -> 0.0059714286 | G25: 44420 | H25: Shopify | I25: 261.41 | J25: 27 | K25: =IFERROR(__xludf.DUMMYFUNCTION("AVERAGE.WEIGHTED(I25:I26,J25:J26)"),259.9174285714286) -> 259.91743
B26: IGG | C26: 0.0052 | D26: 8 | H26: IGG | I26: 254.88 | J26: 8
A27: 44421 | B27: Shopify | C27: 0.0049 | D27: 24 | E27: =IFERROR(__xludf.DUMMYFUNCTION("AVERAGE.WEIGHTED(C27:C28,D27:D28)"),0.004623076923076923) -> 0.0046230769 | G27: 44421 | H27: Shopify | I27: 276.04 | J27: 24 | K27: =IFERROR(__xludf.DUMMYFUNCTION("AVERAGE.WEIGHTED(I27:I28,J27:J28)"),275.5753846153846) -> 275.57538
B28: IGG | C28: 0.0013 | D28: 2 | H28: IGG | I28: 270 | J28: 2
A29: 44422 | B29: Shopify | C29: 0.0062 | D29: 20 | E29: =IFERROR(__xludf.DUMMYFUNCTION("AVERAGE.WEIGHTED(C29:C30,D29:D30)"),0.00558) -> 0.00558 | G29: 44422 | H29: Shopify | I29: 271.3 | J29: 20 | K29: =IFERROR(__xludf.DUMMYFUNCTION("AVERAGE.WEIGHTED(I29:I30,J29:J30)"),269.32) -> 269.32
B30: IGG | C30: 0.0031 | D30: 5 | H30: IGG | I30: 261.4 | J30: 5
A31: 44423 | B31: Shopify | C31: 0.01 | D31: 31 | E31: =IFERROR(__xludf.DUMMYFUNCTION("AVERAGE.WEIGHTED(C31:C32,D31:D32)"),0.00910857142857143) -> 0.0091085714 | G31: 44423 | H31: Shopify | I31: 296.71 | J31: 31 | K31: =IFERROR(__xludf.DUMMYFUNCTION("AVERAGE.WEIGHTED(I31:I32,J31:J32)"),287.74314285714286) -> 287.74314
B32: IGG | C32: 0.0022 | D32: 4 | H32: IGG | I32: 218.25 | J32: 4
A33: 44424 | B33: Shopify | C33: 0.01 | D33: 27 | E33: =IFERROR(__xludf.DUMMYFUNCTION("AVERAGE.WEIGHTED(C33:C34,D33:D34)"),0.00890909090909091) -> 0.0089090909 | G33: 44424 | H33: Shopify | I33: 256.26 | J33: 27 | K33: =IFERROR(__xludf.DUMMYFUNCTION("AVERAGE.WEIGHTED(I33:I34,J33:J34)"),270.94) -> 270.94
B34: IGG | C34: 0.004 | D34: 6 | H34: IGG | I34: 337 | J34: 6
A35: 44425 | B35: Shopify | C35: 0.0076 | D35: 24 | E35: =IFERROR(__xludf.DUMMYFUNCTION("AVERAGE.WEIGHTED(C35:C36,D35:D36)"),0.007332) -> 0.007332 | G35: 44425 | H35: Shopify | I35: 261.54 | J35: 24 | K35: =IFERROR(__xludf.DUMMYFUNCTION("AVERAGE.WEIGHTED(I35:I36,J35:J36)"),259.8784) -> 259.8784
B36: IGG | C36: 0.0009 | D36: 1 | H36: IGG | I36: 220 | J36: 1
A37: 44426 | B37: Shopify | C37: 0.0078 | D37: 29 | E37: =IFERROR(__xludf.DUMMYFUNCTION("AVERAGE.WEIGHTED(C37:C38,D37:D38)"),0.0078) -> 0.0078 | G37: 44426 | H37: Shopify | I37: 257.52 | J37: 29 | K37: =IFERROR(__xludf.DUMMYFUNCTION("AVERAGE.WEIGHTED(I37:I38,J37:J38)"),257.52) -> 257.52
B38: IGG | C38: 0 | D38: 0 | H38: IGG | I38: 0 | J38: 0
A39: 44427 | B39: Shopify | C39: 0.003 | D39: 13 | E39: =IFERROR(__xludf.DUMMYFUNCTION("AVERAGE.WEIGHTED(C39:C40,D39:D40)"),0.003258823529411765) -> 0.0032588235 | G39: 44427 | H39: Shopify | I39: 261 | J39: 13 | K39: =IFERROR(__xludf.DUMMYFUNCTION("AVERAGE.WEIGHTED(I39:I40,J39:J40)"),258.70588235294116) -> 258.70588
B40: IGG | C40: 0.0041 | D40: 4 | H40: IGG | I40: 251.25 | J40: 4
...

Sheet SupermetricsQueries
A1: Supermetrics Queries
A3: All the queries created by Supermetrics are stored here, each in its own row.
H4: 16340380
A5: On this sheet you can:
A6: 1. Modify the parameters of a query. Any changes will be visible when you run a refresh.
A8: 2. Remove a query by deleting its row | H8: Europe/Paris
A10: 3. Add new queries: type a range address and query parameters, leave the query ID empty. The query will be added when you run a refresh. (Of course, it's much easier to use the sidebar to add new queries.)
A13: Queries are stored with the authentication of the original user that created the query. If you want to transfer a query to the currently active Google Sheets user, delete its query ID from column A and run a refresh. For complete instructions on transferring queries, see https://support.supermetrics.com/support/solutions/articles/19000050074-how-can-i-transfer-queries-from-one-user-to-another-
A16: Don't delete or rename this sheet. If you delete or rename it, your existing queries can no longer be refreshed. Hiding the sheet is OK. Also, don't delete any rows above row 21.
A19: Query ID | D19: Sheet name | E19: Range address | G19: Created | H19: Updated | I19: Last status | J19: Last refresh ID | K19: Results contain sampled data | L19: Execution time (sec) | M19: Object type | N19: Linked chart ID | O19: Data source | Q19: Date range type | R19: Start date | S19: End date | T19: Compare to | U19: Comparison value type | W19: Accounts/views | X19: Metrics | Y19: Dimensions | Z19: Pivot dimensions | AA19: Filters | AB19: Segment ID | AC19: Sort | AD19: Max rows | AE19: Max pivot categories | AF19: Special settings | AG19: Other parameters | AJ19: Result type | AK19: Language/country | AL19: Translate to | AN19: SQL | AO19: Database name | AP19: Range address (static) | AQ19: Report type | AT19: Highlight with colour | AU19: Refresh with user account | AV19: Returned data
A20: paramsID | C20: ssID | D20: sheetName | E20: rangeAddress | G20: created | H20: updated | I20: lastStatus | J20: lastqueryID | K20: sampled | L20: runtime_sec | M20: objType | N20: linkedChartID | O20: dataSource | Q20: dateRangeType | R20: startDateString | S20: endDateString | T20: comp | U20: cvt | W20: profiles | X20: metrics | Y20: dimensions | Z20: sd | AA20: filterArr | AB20: segment | AC20: sort | AD20: maxResults | AE20: maxCategories | AF20: specialSettings | AG20: otherParams | AJ20: sds_result_type | AK20: sds_lang | AL20: sds_tolang | AN20: sql | AO20: db_name | AP20: rangeAddressStatic | AQ20: rt | AR20: scopeMZ | AS20: sortMZ | AT20: condform | AU20: authUser | AV20: metaDataToUser
A21: 9i4W4hgd80uRpQLMeX0eRnESN8gjyv | D21: =IFERROR(__xludf.DUMMYFUNCTION("ARRAY_CONSTRAIN(split(CELL(""ADDRESS"",zsupermetrics_9i4W4hgd80uRpQLMeX0eRnESN8gjyv),""!""),1,1)"),"Formula") -> Formula | E21: =CELL("ADDRESS",zsupermetrics_9i4W4hgd80uRpQLMeX0eRnESN8gjyv)&":"&address(row(zsupermetrics_9i4W4hgd80uRpQLMeX0eRnESN8gjyv)+rows(zsupermetrics_9i4W4hgd80uRpQLMeX0eRnESN8gjyv)-1,column(zsupermetrics_9i4W4hgd80uRpQLMeX0eRnESN8gjyv)+COLUMNS(zsupermetrics_9i4W4hgd80uRpQLMeX0eRnESN8gjyv)-1) -> Formula!$H$13:$H$14 | G21: 44481.52 | H21: 44481.521 | I21: Created successfully | K21: FALSE | L21: 1 | M21: TABLE | O21: SHP | Q21: today | W21: ["gid://shopify/Shop/55807180983`Bird Buddy"] | X21: ["total_sales"] | Y21: [] | Z21: [] | AA21: [{"field":"order_utm_name","operator":"=@","value":"US","combineToPrev":";"}] | AB21: [] | AD21: 1000 | AE21: 10 | AF21: [] | AG21: {} | AP21: Formula'!H12:H13 | AU21: gid://shopify/Shop/55807180983
A22: DQl8lUbpTRu3fayaJJi7lVfOGKjNU4 | D22: =IFERROR(__xludf.DUMMYFUNCTION("ARRAY_CONSTRAIN(split(CELL(""ADDRESS"",zsupermetrics_DQl8lUbpTRu3fayaJJi7lVfOGKjNU4),""!""),1,1)"),"Formula") -> Formula | E22: =CELL("ADDRESS",zsupermetrics_DQl8lUbpTRu3fayaJJi7lVfOGKjNU4)&":"&address(row(zsupermetrics_DQl8lUbpTRu3fayaJJi7lVfOGKjNU4)+rows(zsupermetrics_DQl8lUbpTRu3fayaJJi7lVfOGKjNU4)-1,column(zsupermetrics_DQl8lUbpTRu3fayaJJi7lVfOGKjNU4)+COLUMNS(zsupermetrics_DQl8lUbpTRu3fayaJJi7lVfOGKjNU4)-1) -> Formula!$F$3:$F$4 | G22: 44481.567 | I22: Created successfully | K22: FALSE | L22: 4 | M22: TABLE | O22: SHP | Q22: yesterday | W22: ["gid://shopify/Shop/55807180983`Bird Buddy"] | X22: ["total_sales"] | Y22: [] | Z22: [] | AA22: [] | AB22: [] | AF22: [] | AG22: {} | AP22: Formula'!F2:F3 | AU22: gid://shopify/Shop/55807180983
A23: n3GtLgiKpTmd2pYmQNMuq6TPD0qE0b | D23: =IFERROR(__xludf.DUMMYFUNCTION("ARRAY_CONSTRAIN(split(CELL(""ADDRESS"",zsupermetrics_n3GtLgiKpTmd2pYmQNMuq6TPD0qE0b),""!""),1,1)"),"Formula") -> Formula | E23: =CELL("ADDRESS",zsupermetrics_n3GtLgiKpTmd2pYmQNMuq6TPD0qE0b)&":"&address(row(zsupermetrics_n3GtLgiKpTmd2pYmQNMuq6TPD0qE0b)+rows(zsupermetrics_n3GtLgiKpTmd2pYmQNMuq6TPD0qE0b)-1,column(zsupermetrics_n3GtLgiKpTmd2pYmQNMuq6TPD0qE0b)+COLUMNS(zsupermetrics_n3GtLgiKpTmd2pYmQNMuq6TPD0qE0b)-1) -> Formula!$G$4:$G$5 | G23: 44481.599 | I23: Created successfully | K23: FALSE | L23: 5 | M23: TABLE | O23: SHP | Q23: yesterday | W23: ["gid://shopify/Shop/55807180983`Bird Buddy"] | X23: ["total_sales"] | Y23: [] | Z23: [] | AA23: [] | AB23: [] | AF23: [] | AG23: {} | AP23: Formula'!G3:G4 | AU23: gid://shopify/Shop/55807180983
A24: qWp7V908pNEYMtfv8QZvSTeDnBAHOU | D24: =IFERROR(__xludf.DUMMYFUNCTION("ARRAY_CONSTRAIN(split(CELL(""ADDRESS"",zsupermetrics_qWp7V908pNEYMtfv8QZvSTeDnBAHOU),""!""),1,1)"),"Formula") -> Formula | E24: =CELL("ADDRESS",zsupermetrics_qWp7V908pNEYMtfv8QZvSTeDnBAHOU)&":"&address(row(zsupermetrics_qWp7V908pNEYMtfv8QZvSTeDnBAHOU)+rows(zsupermetrics_qWp7V908pNEYMtfv8QZvSTeDnBAHOU)-1,column(zsupermetrics_qWp7V908pNEYMtfv8QZvSTeDnBAHOU)+COLUMNS(zsupermetrics_qWp7V908pNEYMtfv8QZvSTeDnBAHOU)-1) -> Formula!$G$5:$H$6 | G24: 44481.601 | H24: 44481.56 | I24: Refreshed successfully | J24: 1634037959028 | K24: FALSE | M24: TABLE | O24: SHP | Q24: yesterday | W24: ["gid://shopify/Shop/55807180983`Bird Buddy"] | X24: ["total_sales"] | Y24: [] | Z24: [] | AA24: [] | AB24: [] | AF24: ["APPEND_RESULTS"] | AG24: {} | AP24: Formula'!G4:H5 | AU24: gid://shopify/Shop/55807180983
A25: lx4cNai7gT6tH4j08ZRkI21Qlpjioi | D25: =IFERROR(__xludf.DUMMYFUNCTION("ARRAY_CONSTRAIN(split(CELL(""ADDRESS"",zsupermetrics_lx4cNai7gT6tH4j08ZRkI21Qlpjioi),""!""),1,1)"),"Formula") -> Formula | E25: =CELL("ADDRESS",zsupermetrics_lx4cNai7gT6tH4j08ZRkI21Qlpjioi)&":"&address(row(zsupermetrics_lx4cNai7gT6tH4j08ZRkI21Qlpjioi)+rows(zsupermetrics_lx4cNai7gT6tH4j08ZRkI21Qlpjioi)-1,column(zsupermetrics_lx4cNai7gT6tH4j08ZRkI21Qlpjioi)+COLUMNS(zsupermetrics_lx4cNai7gT6tH4j08ZRkI21Qlpjioi)-1) -> Formula!$G$4:$H$5 | G25: 44481.617 | I25: Created successfully | K25: FALSE | L25: 0 | M25: TABLE | O25: SHP | Q25: yesterday | W25: ["gid://shopify/Shop/55807180983`Bird Buddy"] | X25: ["total_sales"] | Y25: [] | Z25: [] | AA25: [] | AB25: [] | AF25: ["APPEND_RESULTS"] | AG25: {} | AP25: Formula'!G3:H4 | AU25: gid://shopify/Shop/55807180983
A26: 4VkB7ij7WO0JjKBEgvjB2GHjSy2Egm | D26: =IFERROR(__xludf.DUMMYFUNCTION("ARRAY_CONSTRAIN(split(CELL(""ADDRESS"",zsupermetrics_4VkB7ij7WO0JjKBEgvjB2GHjSy2Egm),""!""),1,1)"),"Formula") -> Formula | E26: =CELL("ADDRESS",zsupermetrics_4VkB7ij7WO0JjKBEgvjB2GHjSy2Egm)&":"&address(row(zsupermetrics_4VkB7ij7WO0JjKBEgvjB2GHjSy2Egm)+rows(zsupermetrics_4VkB7ij7WO0JjKBEgvjB2GHjSy2Egm)-1,column(zsupermetrics_4VkB7ij7WO0JjKBEgvjB2GHjSy2Egm)+COLUMNS(zsupermetrics_4VkB7ij7WO0JjKBEgvjB2GHjSy2Egm)-1) -> Formula!$G$4:$H$5 | G26: 44481.617 | I26: Created successfully | K26: FALSE | L26: 9 | M26: TABLE | O26: SHP | Q26: today | W26: ["gid://shopify/Shop/55807180983`Bird Buddy"] | X26: ["total_sales"] | Y26: [] | Z26: [] | AA26: [] | AB26: [] | AF26: ["APPEND_RESULTS"] | AG26: {} | AP26: Formula'!G3:H4 | AU26: gid://shopify/Shop/55807180983
A27: HgZqhorObHOtZHuyJjpmyYaEPoYntx | D27: =IFERROR(__xludf.DUMMYFUNCTION("ARRAY_CONSTRAIN(split(CELL(""ADDRESS"",zsupermetrics_HgZqhorObHOtZHuyJjpmyYaEPoYntx),""!""),1,1)"),"Formula") -> Formula | E27: =CELL("ADDRESS",zsupermetrics_HgZqhorObHOtZHuyJjpmyYaEPoYntx)&":"&address(row(zsupermetrics_HgZqhorObHOtZHuyJjpmyYaEPoYntx)+rows(zsupermetrics_HgZqhorObHOtZHuyJjpmyYaEPoYntx)-1,column(zsupermetrics_HgZqhorObHOtZHuyJjpmyYaEPoYntx)+COLUMNS(zsupermetrics_HgZqhorObHOtZHuyJjpmyYaEPoYntx)-1) -> Formula!$G$4:$G$5 | G27: 44481.619 | I27: Created successfully | K27: FALSE | L27: 5 | M27: TABLE | O27: SHP | Q27: yesterday | W27: ["gid://shopify/Shop/55807180983`Bird Buddy"] | X27: ["total_sales"] | Y27: [] | Z27: [] | AA27: [] | AB27: [] | AF27: [] | AG27: {} | AP27: Formula'!G3:G4 | AU27: gid://shopify/Shop/55807180983
A28: ru0GDtbZzDLHQOQtJJ6K08MvUDyyp7 | D28: =IFERROR(__xludf.DUMMYFUNCTION("ARRAY_CONSTRAIN(split(CELL(""ADDRESS"",zsupermetrics_ru0GDtbZzDLHQOQtJJ6K08MvUDyyp7),""!""),1,1)"),"Formula") -> Formula | E28: =CELL("ADDRESS",zsupermetrics_ru0GDtbZzDLHQOQtJJ6K08MvUDyyp7)&":"&address(row(zsupermetrics_ru0GDtbZzDLHQOQtJJ6K08MvUDyyp7)+rows(zsupermetrics_ru0GDtbZzDLHQOQtJJ6K08MvUDyyp7)-1,column(zsupermetrics_ru0GDtbZzDLHQOQtJJ6K08MvUDyyp7)+COLUMNS(zsupermetrics_ru0GDtbZzDLHQOQtJJ6K08MvUDyyp7)-1) -> Formula!$G$4:$G$5 | G28: 44481.62 | I28: Created successfully | K28: FALSE | L28: 0 | M28: TABLE | O28: SHP | Q28: yesterday | W28: ["gid://shopify/Shop/55807180983`Bird Buddy"] | X28: ["total_sales"] | Y28: [] | Z28: [] | AA28: [] | AB28: [] | AF28: [] | AG28: {} | AP28: Formula'!G3:G4 | AU28: gid://shopify/Shop/55807180983
A29: YsFuuYtr8vOdNXCCPiFJIO38NP4b2T | D29: =IFERROR(__xludf.DUMMYFUNCTION("ARRAY_CONSTRAIN(split(CELL(""ADDRESS"",zsupermetrics_YsFuuYtr8vOdNXCCPiFJIO38NP4b2T),""!""),1,1)"),"Formula") -> Formula | E29: =CELL("ADDRESS",zsupermetrics_YsFuuYtr8vOdNXCCPiFJIO38NP4b2T)&":"&address(row(zsupermetrics_YsFuuYtr8vOdNXCCPiFJIO38NP4b2T)+rows(zsupermetrics_YsFuuYtr8vOdNXCCPiFJIO38NP4b2T)-1,column(zsupermetrics_YsFuuYtr8vOdNXCCPiFJIO38NP4b2T)+COLUMNS(zsupermetrics_YsFuuYtr8vOdNXCCPiFJIO38NP4b2T)-1) -> Formula!$G$4:$H$5 | G29: 44481.62 | I29: Created successfully | K29: FALSE | L29: 0 | M29: TABLE | O29: SHP | Q29: yesterday | W29: ["gid://shopify/Shop/55807180983`Bird Buddy"] | X29: ["total_sales"] | Y29: [] | Z29: [] | AA29: [] | AB29: [] | AF29: ["APPEND_RESULTS"] | AG29: {} | AP29: Formula'!G3:H4 | AU29: gid://shopify/Shop/55807180983
A30: OI1SHh9RTAzpmZ8JDWgszLojYv8Hv4 | D30: =IFERROR(__xludf.DUMMYFUNCTION("ARRAY_CONSTRAIN(split(CELL(""ADDRESS"",zsupermetrics_OI1SHh9RTAzpmZ8JDWgszLojYv8Hv4),""!""),1,1)"),"Formula") -> Formula | E30: =CELL("ADDRESS",zsupermetrics_OI1SHh9RTAzpmZ8JDWgszLojYv8Hv4)&":"&address(row(zsupermetrics_OI1SHh9RTAzpmZ8JDWgszLojYv8Hv4)+rows(zsupermetrics_OI1SHh9RTAzpmZ8JDWgszLojYv8Hv4)-1,column(zsupermetrics_OI1SHh9RTAzpmZ8JDWgszLojYv8Hv4)+COLUMNS(zsupermetrics_OI1SHh9RTAzpmZ8JDWgszLojYv8Hv4)-1) -> Formula!$F$4:$G$5 | G30: 44482.395 | I30: Created successfully | K30: FALSE | L30: 4 | M30: TABLE | O30: SHP | Q30: yesterday | W30: ["gid://shopify/Shop/55807180983`Bird Buddy"] | X30: ["total_sales"] | Y30: [] | Z30: [] | AA30: [] | AB30: [] | AF30: ["APPEND_RESULTS"] | AG30: {} | AP30: Formula'!F3:G4 | AU30: gid://shopify/Shop/55807180983
