Workbook
Name zsupermetrics_9i4W4hgd80uRpQLMeX0eRnESN8gjyv: Formula!$H$12
Name zsupermetrics_ru0GDtbZzDLHQOQtJJ6K08MvUDyyp7: Formula!$G$3:$G$4
Name zsupermetrics_lx4cNai7gT6tH4j08ZRkI21Qlpjioi: Formula!$G$3:$H$12
Name zsupermetrics_refreshAll: SupermetricsQueries!$H$5
Name zsupermetrics_8xojRjNDjo2jWHGDWjFEhflhyIq3Hq: Sales!$K$7:$K$8
Name zsupermetrics_n3GtLgiKpTmd2pYmQNMuq6TPD0qE0b: Formula!$G$3:$G$4
Name zsupermetrics_refreshAllSilent: SupermetricsQueries!$H$6
Name zsupermetrics_BioPyGBzcBsy60UCQmPcTuFReEmghI: Formula!$G$1:$G$2
Name zsupermetrics_qWp7V908pNEYMtfv8QZvSTeDnBAHOU: Formula!$G$4:$H$12
Name zsupermetrics_Mgms9p0QzysYvrIhnsKACeVBVxfIEO: Formula!$F$1:$F$2
Name zsupermetrics_forceRefresh: SupermetricsQueries!$H$4
Name zsupermetrics_HgZqhorObHOtZHuyJjpmyYaEPoYntx: Formula!$G$3:$G$4
Name zsupermetrics_NugLlrQxlKiqhxQae8EFpITBm1pLCj: Formula!$G$5:$H$12
Name zsupermetrics_xwoIpANxRm908eDp5oKTwQpEI8gvD4: Formula!$F$1
Name zsupermetrics_wbYMmT0YL9bAN0yhimW0ziPFnia9Dx: Formula!$F$1:$F$2
Name zsupermetrics_YsFuuYtr8vOdNXCCPiFJIO38NP4b2T: Formula!$G$3:$H$12
Name zsupermetrics_iNpyVy90bWCI0yUaFQpxOtzWMa6sW4: Formula!$F$1:$F$2
Name zsupermetrics_DQl8lUbpTRu3fayaJJi7lVfOGKjNU4: Formula!$F$2:$F$3
Name zsupermetrics_4VkB7ij7WO0JjKBEgvjB2GHjSy2Egm: Formula!$G$3:$H$9

Sheet Sales
A1: 3 | B1: 44470 | C1: 44471 | D1: 44472 | E1: 44473 | F1: 44474 | G1: 44475 | H1: 44476 | I1: 44477 | J1: 44478 | K1: 44479 | L1: 44480 | M1: 44481 | N1: 44482 | O1: 44483 | P1: 44484 | Q1: 44485 | R1: 44486 | S1: 44487 | T1: 44488 | U1: 44489 | V1: 44490 | W1: 44491 | X1: 44492 | Y1: 44493 | Z1: 44494 | AA1: 44495 | AB1: 44496 | AC1: 44497 | AD1: 44498 | AE1: 44499 | AF1: 44500
B2: FRI | C2: SAT | D2: SUN | E2: MON | F2: TUE | G2: WED | H2: THU | I2: FRI | J2: SAT | K2: SUN | L2: MON | M2: TUE | N2: WED | O2: THU | P2: FRI | Q2: SAT | R2: SUN | S2: MON | T2: TUE | U2: WED | V2: THU | W2: FRI | X2: SAT | Y2: SUN | Z2: MON | AA2: TUE | AB2: WED | AC2: THU | AD2: FRI | AE2: SAT | AF2: SUN
A4: Notes | H4: Product Price Up | J4: CBS Broadcast | N4: IGG Over | T4: Shipping Price Up, Special Offer from March to April | AC4: Halloween Offer
A6: Indiegogo | B6: 0 | C6: 0 | D6: 202 | E6: 0 | F6: 202 | G6: 511 | H6: 0 | I6: 0 | J6: 1266 | K6: 0 | L6: 1513 | M6: 563 | N6: 0 | O6: 774
A7: Shopify | B7: 7630 | C7: 11329 | D7: 12479 | E7: 8050 | F7: 8353 | G7: 5696 | H7: 5140 | I7: 5585 | J7: 92219 | K7: 24793 | L7: 14104 | M7: 9503 | N7: 7614 | O7: 8202 | P7: 6635 | Q7: 14130 | R7: 11060 | S7: 8197 | T7: 7684 | U7: 5998 | V7: 7969 | W7: 9244 | X7: 8367 | Y7: 9031 | Z7: 9037 | AA7: 5927 | AB7: 7247 | AC7: 7071 | AD7: 9772 | AE7: 10906 | AF7: 10568
A8: Total Revenue | B8: =SUM(B6:B7) -> 7630 | C8: =SUM(C6:C7) -> 11329 | D8: =SUM(D6:D7) -> 12681 | E8: =SUM(E6:E7) -> 8050 | F8: =SUM(F6:F7) -> 8555 | G8: =SUM(G6:G7) -> 6207 | H8: =SUM(H6:H7) -> 5140 | I8: =SUM(I6:I7) -> 5585 | ... AF8: =SUM(AF6:AF7) -> 10568
A9: Orders | B9: 31 | C9: 45 | D9: 52 | E9: 29 | F9: 33 | G9: 22 | H9: 22 | I9: 23 | J9: 334 | K9: 89 | L9: 51 | M9: 36 | N9: 27 | O9: 31 | P9: 25 | Q9: 49 | R9: 44 | S9: 33 | T9: 31 | U9: 21 | V9: 30 | W9: 37 | X9: 28 | Y9: 36 | Z9: 34 | AA9: 23 | AB9: 28 | AC9: 26 | AD9: 39 | AE9: 43 | AF9: 43
A11: FB - US & CA | B11: =Formula!D3 -> 1344.0734 | C11: =Formula!D4 -> 1965.4285 | D11: =Formula!D5 -> 2328.9972 | E11: =Formula!D6 -> 1715.8457 | F11: =Formula!D7 -> 2093.2718 | G11: =Formula!D8 -> 1532.2383 | H11: =Formula!D9 -> 1179.481 | I11: =Formula!D10 -> 1484.3779 | J11: =Formula!D11 -> 1742.1874 | K11: =Formula!D12 -> 1694.5231 | L11: =Formula!D13 -> 1601.1214 | M11: =Formula!D14 -> 1952.1596 | N11: =Formula!D15 -> 1738.0568 | O11: =Formula!D16 -> 1714.8534 | P11: =Formula!D17 -> 1749.7103 | Q11: =Formula!D18 -> 2207.0154 | R11: =Formula!D19 -> 2327.9588 | S11: =Formula!D20 -> 2171.5239 | T11: =Formula!D21 -> 1639.6821 | U11: =Formula!D22 -> 1921.5372 | V11: =Formula!D23 -> 1941.5445 | W11: =Formula!D24 -> 3286.2986 | X11: =Formula!D25 -> 1942.779 | Y11: =Formula!D26 -> 2092.4872 | Z11: =Formula!D27 -> 2065.4647 | AA11: =Formula!D28 -> 1721.0841 | AB11: =Formula!D29 -> 1605.3444 | AC11: =Formula!D30 -> 1712.4881 | AD11: =Formula!D31 -> 2588.3067 | AE11: =Formula!D32 -> 3725.8232 | AF11: =Formula!D33 -> 3391.3539
A12: Google - WW | B12: 41.01 | C12: 65.55 | D12: 54.81 | E12: 46.74 | F12: 154.83 | G12: 167.87 | H12: 124.85 | I12: 186.66 | J12: 2187.48 | K12: 1020.78 | L12: 451.7 | M12: 223.39 | N12: 259.05 | O12: 198.01 | P12: 206.53 | Q12: 330.57 | R12: 467.23 | S12: 195.86 | T12: 179.37 | U12: 218.64 | V12: 182.78 | W12: 182.62 | X12: 185.5 | Y12: 183.33 | Z12: 134.14 | AA12: 128.61 | AB12: 112.6 | AC12: 123.69 | AD12: 111.63 | AE12: 140.2 | AF12: 149.52
A13: Bing - WW | B13: 8.73 | C13: 1.75 | D13: 7.81 | E13: 10.56 | F13: 6.83 | G13: 5.35 | H13: 5.09 | I13: 17.35 | J13: 252.07 | K13: 69.6 | L13: 40.79 | M13: 21.82 | N13: 11.82 | O13: 7.92 | P13: 8.01 | Q13: 8.08 | R13: 15.47 | S13: 10.62 | T13: 8.18 | U13: 5.53 | V13: 9.54 | W13: 9.48 | X13: 7.71 | Y13: 12.34 | Z13: 8.62 | AA13: 10.63 | AB13: 3.53 | AC13: 6.12 | AD13: 9.11 | AE13: 11.04 | AF13: 7.25
A14: Total Spend | B14: =SUM(B11:B13) -> 1393.8134 | C14: =SUM(C11:C13) -> 2032.7285 | D14: =SUM(D11:D13) -> 2391.6172 | E14: =SUM(E11:E13) -> 1773.1457 | F14: =SUM(F11:F13) -> 2254.9318 | G14: =SUM(G11:G13) -> 1705.4583 | H14: =SUM(H11:H13) -> 1309.421 | I14: =SUM(I11:I13) -> 1688.3879 | ... AF14: =SUM(AF11:AF13) -> 3548.1239
A16: ROAS | B16: =B8/B14 -> 5.4741905 | C16: =C8/C14 -> 5.5732971 | D16: =D8/D14 -> 5.3022699 | E16: =E8/E14 -> 4.539954 | F16: =F8/F14 -> 3.7939063 | G16: =G8/G14 -> 3.6394908 | H16: =H8/H14 -> 3.9253992 | I16: =I8/I14 -> 3.3078892 | ... AF16: =AF8/AF14 -> 2.9784755
A17: CAC | B17: =B14/B9 -> 44.961722 | C17: =C14/C9 -> 45.171745 | D17: =D14/D9 -> 45.992639 | E17: =E14/E9 -> 61.142956 | F17: =F14/F9 -> 68.331266 | G17: =G14/G9 -> 77.520834 | H17: =H14/H9 -> 59.519134 | I17: =I14/I9 -> 73.408169 | ... AF17: =AF14/AF9 -> 82.514509
A18: CR | B18: 0.011 | C18: 0.0118 | D18: 0.0112 | E18: 0.008 | F18: 0.0084 | G18: 0.0068 | H18: 0.009 | I18: 0.0083 | J18: 0.0232 | K18: 0.0137 | L18: 0.0118 | M18: 0.0088 | N18: 0.0083 | O18: 0.0097 | P18: 0.0074 | Q18: 0.0135 | R18: 0.0122 | S18: 0.0099 | T18: 0.0102 | U18: 0.0078 | V18: 0.0115 | W18: 0.0105 | X18: 0.011 | Y18: 0.0123 | Z18: 0.0126 | AA18: 0.0099 | AB18: 0.0128 | AC18: 0.01 | AD18: 0.013 | AE18: 0.0111 | AF18: 0.0125
A19: AOV | B19: =B8/B9 -> 246.12903 | C19: =C8/C9 -> 251.75556 | D19: =D8/D9 -> 243.86538 | E19: =E8/E9 -> 277.58621 | F19: =F8/F9 -> 259.24242 | G19: =G8/G9 -> 282.13636 | H19: =H8/H9 -> 233.63636 | I19: =I8/I9 -> 242.82609 | ... AF19: =AF8/AF9 -> 245.76744
A21: Post-purchase Survey
A22: Facebook / Instagram | B22: 0.85 | C22: 0.7241 | D22: 0.7 | E22: 0.8 | F22: 0.6471 | G22: 0.75 | H22: 0.8571 | I22: 0.5714 | J22: 0.0656 | K22: 0.2414 | L22: 0.2581 | M22: 0.2778 | N22: 0.5263 | O22: 0.5 | P22: 0.5 | Q22: 0.4211 | R22: 0.4643 | S22: 0.4286 | T22: 0.7059 | U22: 0.875 | V22: 0.6154 | W22: 0.5909 | X22: 0.3571 | Y22: 0.7391 | Z22: 0.6429 | AA22: 0.2727 | AB22: 0.6154 | AC22: 0.8333 | AD22: 0.8421 | AE22: 0.5714 | AF22: 0.9167
A23: Friends / Family | B23: 0.1 | C23: 0.1379 | D23: 0.1667 | E23: 0.0667 | F23: 0.1765 | G23: 0.125 | H23: 0.0714 | I23: 0.1429 | J23: 0.0123 | K23: 0.0172 | L23: 0.1613 | M23: 0.1111 | N23: 0.1053 | O23: 0 | P23: 0.4 | Q23: 0 | R23: 0.0714 | S23: 0 | T23: 0.1765 | U23: 0 | V23: 0.1538 | W23: 0.0909 | X23: 0.2143 | Y23: 0.087 | Z23: 0.2143 | AA23: 0.3636 | AB23: 0.1538 | AC23: 0.1667 | AD23: 0.0526 | AE23: 0.1905 | AF23: 0.0833
A24: Google, Yahoo, Bing | B24: 0 | C24: 0 | D24: 0.0667 | E24: 0.1333 | F24: 0.0588 | G24: 0 | H24: 0 | I24: 0.1429 | J24: 0.0164 | K24: 0.0172 | L24: 0.0645 | M24: 0.0556 | N24: 0.0526 | O24: 0.0833 | P24: 0 | Q24: 0 | R24: 0.0357 | S24: 0.2143 | T24: 0 | U24: 0.125 | V24: 0.1538 | W24: 0.0455 | X24: 0.0714 | Y24: 0.0435 | Z24: 0 | AA24: 0.2727 | AB24: 0.1538 | AC24: 0 | AD24: 0 | AE24: 0.0952 | AF24: 0
A25: Pinterest | B25: 0 | C25: 0 | D25: 0 | E25: 0 | F25: 0 | G25: 0 | H25: 0 | I25: 0 | J25: 0 | K25: 0 | L25: 0 | M25: 0 | N25: 0 | O25: 0 | P25: 0 | Q25: 0 | R25: 0 | S25: 0 | T25: 0 | U25: 0 | V25: 0 | W25: 0 | X25: 0 | Y25: 0 | Z25: 0 | AA25: 0 | AB25: 0 | AC25: 0 | AD25: 0.0526 | AE25: 0.0476 | AF25: 0
A26: TikTok | B26: 0 | C26: 0 | D26: 0.0333 | E26: 0 | F26: 0 | G26: 0 | H26: 0 | I26: 0 | J26: 0 | K26: 0 | L26: 0 | M26: 0 | N26: 0 | O26: 0 | P26: 0 | Q26: 0.0526 | R26: 0.0357 | S26: 0 | T26: 0 | U26: 0 | V26: 0 | W26: 0 | X26: 0.0714 | Y26: 0 | Z26: 0 | AA26: 0 | AB26: 0 | AC26: 0 | AD26: 0 | AE26: 0 | AF26: 0
A27: TV / Radio | B27: 0 | C27: 0.069 | D27: 0 | E27: 0 | F27: 0 | G27: 0 | H27: 0 | I27: 0 | J27: 0.8975 | K27: 0.7241 | L27: 0.4839 | M27: 0.5 | N27: 0.3158 | O27: 0.3333 | P27: 0.1 | Q27: 0.5263 | R27: 0.3214 | S27: 0.2143 | T27: 0.1176 | U27: 0 | V27: 0 | W27: 0.1364 | X27: 0.2857 | Y27: 0.1304 | Z27: 0.0714 | AA27: 0.0909 | AB27: 0.0769 | AC27: 0 | AD27: 0.0526 | AE27: 0.0476 | AF27: 0
A28: Blog / Article | B28: 0.05 | C28: 0.069 | D28: 0.0333 | E28: 0 | F28: 0.1176 | G28: 0.125 | H28: 0.0714 | I28: 0.1429 | J28: 0.0082 | K28: 0 | L28: 0.0323 | M28: 0.0556 | N28: 0 | O28: 0.0833 | P28: 0 | Q28: 0 | R28: 0.0714 | S28: 0.1429 | T28: 0 | U28: 0 | V28: 0.0769 | W28: 0.1364 | X28: 0 | Y28: 0 | Z28: 0.0714 | AA28: 0 | AB28: 0 | AC28: 0 | AD28: 0 | AE28: 0.0476 | AF28: 0
B30: 44470
A31: Revenue | B31: =SUM(B8:AF8) -> 374571
A32: Spend | B32: =SUM(B14:AF14) -> 71211.318
A33: ROAS | B33: =B31/B32 -> 5.2599926
A34: CAC | B34: =SUM(B14:AF14)/SUM(B9:AF9) -> 51.047539
A35: CR | B35: =AVERAGE(B18:AF18) -> 0.010909677
A36: AOV | B36: =B31/B37 -> 268.50968
A37: Orders | B37: =SUM(B9:AF9) -> 1395

Sheet Attribution
B1: 44470 | C1: 44471 | D1: 44472 | E1: 44473 | F1: 44474 | G1: 44475 | H1: 44476 | I1: 44477 | J1: 44478 | K1: 44479 | L1: 44480 | M1: 44481 | N1: 44482 | O1: 44483 | P1: 44484 | Q1: 44485 | R1: 44486 | S1: 44487 | T1: 44488 | U1: 44489 | V1: 44490 | W1: 44491 | X1: 44492 | Y1: 44493 | Z1: 44494 | AA1: 44495 | AB1: 44496 | AC1: 44497 | AD1: 44498 | AE1: 44499 | AF1: 44500
B2: FRI | C2: SAT | D2: SUN | E2: MON | F2: TUE | G2: WED | H2: THU | I2: FRI | J2: SAT | K2: SUN | L2: MON | M2: TUE | N2: WED | O2: THU | P2: FRI | Q2: SAT | R2: SUN | S2: MON | T2: TUE | U2: WED | V2: THU | W2: FRI | X2: SAT | Y2: SUN | Z2: MON | AA2: TUE | AB2: WED | AC2: THU | AD2: FRI | AE2: SAT | AF2: SUN
A3: FB Orders (Shopify + IGG) | B3: 18 | C3: 19 | D3: 19 | E3: 8 | F3: 9 | G3: 4 | H3: 9 | I3: 4 | J3: 10 | K3: 9 | L3: 13 | M3: 12 | N3: 2 | O3: 1 | P3: 8 | Q3: 6 | R3: 17 | S3: 15 | T3: 12 | U3: 5
A4: All Orders (Shopify + IGG) | B4: =B31 -> 31 | C4: =C31 -> 45 | D4: =D31 -> 52 | E4: =E31 -> 29 | F4: =F31 -> 33 | G4: =G31 -> 22 | H4: =H31 -> 22 | I4: =I31 -> 23 | ... T4: =T31 -> 31 | U4: 21 | V4: =V31 -> 30 | W4: =W31 -> 37 | X4: =X31 -> 28 | Y4: =Y31 -> 36 | Z4: =Z31 -> 34 | AA4: =AA31 -> 23 | AB4: =AB31 -> 28 | AC4: =AC31 -> 26 | ... AF4: =AF31 -> 43
A5: % Attributed to FB (Ads Manager) | B5: =B3/B4 -> 0.58064516 | C5: =C3/C4 -> 0.42222222 | D5: =D3/D4 -> 0.36538462 | E5: =E3/E4 -> 0.27586207 | F5: =F3/F4 -> 0.27272727 | G5: =G3/G4 -> 0.18181818 | H5: =H3/H4 -> 0.40909091 | I5: =I3/I4 -> 0.17391304 | ... U5: =U3/U4 -> 0.23809524
A7: Attribution
A9: Notes | B9: Counting MUA Purchases | P9: Uploading offline conversions
H10: Price Up | J10: CBS | N10: IGG Over
A12: FB Orders (Shopify) | B12: =B3 -> 18 | C12: =C3 -> 19 | D12: =D3 -> 19 | E12: =E3 -> 8 | F12: =F3 -> 9 | G12: =G3 -> 4 | H12: =H3 -> 9 | I12: =I3 -> 4 | J12: 10 | K12: 9 | L12: 13 | M12: 12 | N12: 2 | O12: 1 | P12: 8 | Q12: 6 | R12: 17 | S12: 15 | T12: 12 | U12: 5
A14: FB Offline Conversions (Shopify | P14: 3 | Q14: 12 | R14: 14 | S14: 10 | T14: 10 | U14: 11
A15: % difference | P15: =P14/P12 -> 0.375 | Q15: =Q14/Q12 -> 2 | R15: =R14/R12 -> 0.82352941 | S15: =S14/S12 -> 0.66666667 | T15: =T14/T12 -> 0.83333333 | U15: =U14/U12 -> 2.2
A17: GA (UTM: fb-paid) Orders (Shopify) | B17: 18 | C17: 19 | D17: 19 | E17: 8 | F17: 9 | G17: 4 | H17: 9 | I17: 5 | J17: 8 | K17: 14 | L17: 6 | M17: 4 | N17: 8 | O17: 4 | P17: 9 | Q17: 16 | R17: 11 | S17: 9 | T17: 9 | U17: 11
A18: % difference | B18: =B17/B12 -> 1 | C18: =C17/C12 -> 1 | D18: =D17/D12 -> 1 | E18: =E17/E12 -> 1 | F18: =F17/F12 -> 1 | G18: =G17/G12 -> 1 | H18: =H17/H12 -> 1 | I18: =I17/I12 -> 1.25 | ... AF18: =AF17/AF12 -> #DIV/0!
A20: Social Orders (Shopify) | B20: 10 | C20: 10 | D20: 17 | E20: 0 | F20: 2 | G20: 4 | H20: 10 | I20: 6 | J20: 15 | K20: 16 | L20: 7 | M20: 4 | N20: 1 | O20: 2 | P20: 3 | Q20: 5 | R20: 12 | S20: 6 | T20: 3 | U20: 4
A21: % difference | B21: =B20/B12 -> 0.55555556 | C21: =C20/C12 -> 0.52631579 | D21: =D20/D12 -> 0.89473684 | E21: =E20/E12 -> 0 | F21: =F20/F12 -> 0.22222222 | G21: =G20/G12 -> 1 | H21: =H20/H12 -> 1.1111111 | I21: =I20/I12 -> 1.5 | ... AF21: =AF20/AF12 -> #DIV/0!
A23: PP Survey (FB) Orders | B23: 17 | C23: 21 | D23: 21 | E23: 12 | F23: 11 | G23: 12 | H23: 12 | I23: 4 | J23: 16 | K23: 14 | L23: 8 | M23: 5 | N23: 10 | O23: 6 | P23: 5 | Q23: 9 | R23: 13 | S23: 6 | T23: 12 | U23: 7
A24: PP Survey (FB) Orders Modeled #1 | B24: =(1-B26)*B23+B23 -> 23.0316 | C24: =(1-C26)*C23+C23 -> 28.1589 | D24: =(1-D26)*D23+D23 -> 29.8851 | E24: =(1-E26)*E23+E23 -> 17.5716 | F24: =(1-F26)*F23+F23 -> 15.5518 | G24: =(1-G26)*G23+G23 -> 14.8572 | H24: =(1-H26)*H23+H23 -> 15.6 | I24: =(1-I26)*I23+I23 -> 6.7828 | ... AF24: =(1-AF26)*AF23+AF23 -> 0
A25: PP Survey (FB) Orders Modeled #2 | B25: =(1-B37)*B24+B24 -> 23.0316 | C25: =(1-C37)*C24+C24 -> 28.784653 | D25: =(1-D37)*D24+D24 -> 29.8851 | E25: =(1-E37)*E24+E24 -> 18.177517 | F25: =(1-F37)*F24+F24 -> 17.436867 | G25: =(1-G37)*G24+G24 -> 15.532527 | H25: =(1-H37)*H24+H24 -> 17.018182 | I25: =(1-I37)*I24+I24 -> 6.7828 | ... AF25: =(1-AF37)*AF24+AF24 -> 0
A26: Response Rate | B26: 0.6452 | C26: 0.6591 | D26: 0.5769 | E26: 0.5357 | F26: 0.5862 | G26: 0.7619 | H26: 0.7 | I26: 0.3043 | J26: 0.7578 | K26: 0.6824 | L26: 0.6458 | M26: 0.5455 | N26: 0.7037 | O26: 0.5 | P26: 0.5 | Q26: 0.45 | R26: 0.4643 | S26: 0.4286 | T26: 0.7059 | U26: 0.875
A27: % difference | B27: =B25/B12 -> 1.2795333 | C27: =C25/C12 -> 1.5149818 | D27: =D25/D12 -> 1.5729 | E27: =E25/E12 -> 2.2721897 | F27: =F25/F12 -> 1.9374296 | G27: =G25/G12 -> 3.8831318 | H27: =H25/H12 -> 1.8909091 | I27: =I25/I12 -> 1.6957 | ... AF27: =AF25/AF12 -> #DIV/0!
A31: Shopify (All) | B31: =Sales!B9 -> 31 | C31: =Sales!C9 -> 45 | D31: =Sales!D9 -> 52 | E31: =Sales!E9 -> 29 | F31: =Sales!F9 -> 33 | G31: =Sales!G9 -> 22 | H31: =Sales!H9 -> 22 | I31: =Sales!I9 -> 23 | ... T31: =Sales!T9 -> 31 | U31: 21 | V31: =Sales!V9 -> 30 | W31: =Sales!W9 -> 37 | X31: =Sales!X9 -> 28 | Y31: =Sales!Y9 -> 36 | Z31: =Sales!Z9 -> 34 | AA31: =Sales!AA9 -> 23 | AB31: =Sales!AB9 -> 28 | AC31: =Sales!AC9 -> 26 | ... AF31: =Sales!AF9 -> 43
A33: GA (Shopify) | B33: 32 | C33: 43 | D33: 49 | E33: 28 | F33: 30 | G33: 20 | H33: 22 | I33: 23 | J33: 310 | K33: 77 | L33: 50 | M33: 31 | N33: 27 | O33: 28 | P33: 25 | Q33: 44 | R33: 41 | S33: 32 | T33: 30 | U33: 19
A34: % difference | B34: =B33/B31 -> 1.0322581 | C34: =C33/C31 -> 0.95555556 | D34: =D33/D31 -> 0.94230769 | E34: =E33/E31 -> 0.96551724 | F34: =F33/F31 -> 0.90909091 | G34: =G33/G31 -> 0.90909091 | H34: =H33/H31 -> 1 | I34: =I33/I31 -> 1 | ... AF34: =AF33/AF31 -> 0
A36: PP Survey (All) Order Views | B36: 31 | C36: 44 | D36: 52 | E36: 28 | F36: 29 | G36: 21 | H36: 20 | I36: 23 | J36: 322 | K36: 85 | L36: 48 | M36: 33 | N36: 27 | O36: 29 | P36: 25 | Q36: 48 | R36: 44 | S36: 29 | T36: 28 | U36: 20
A37: % difference | B37: =B36/B31 -> 1 | C37: =C36/C31 -> 0.97777778 | D37: =D36/D31 -> 1 | E37: =E36/E31 -> 0.96551724 | F37: =F36/F31 -> 0.87878788 | G37: =G36/G31 -> 0.95454545 | H37: =H36/H31 -> 0.90909091 | I37: =I36/I31 -> 1 | ... AF37: =AF36/AF31 -> 0

Sheet Detailed Report
A1: MESEC | B1: 44470 | C1: 44471 | D1: 44472 | E1: 44473 | F1: 44474 | G1: 44475 | H1: 44476 | I1: 44477 | J1: 44478 | K1: 44479 | L1: 44480 | M1: 44481 | N1: 44482 | O1: 44483 | P1: 44484 | Q1: 44485 | R1: 44486 | S1: 44487 | T1: 44488 | U1: 44489 | V1: 44490 | W1: 44491 | X1: 44492 | Y1: 44493 | Z1: 44494 | AA1: 44495 | AB1: 44496 | AC1: 44497 | AD1: 44498 | AE1: 44499 | AF1: 44500 | AG1: Skupaj
A2: DAN | B2: PET | C2: SOB | D2: NED | E2: PON | F2: TOR | G2: SRE | H2: ČET | I2: PET | J2: SOB | K2: NED | L2: PON | M2: TOR | N2: SRE | O2: ČET | P2: PET | Q2: SOB | R2: NED | S2: PON | T2: TOR | U2: SRE | V2: ČET | W2: PET | X2: SOB | Y2: NED | Z2: PON | AA2: TOR | AB2: SRE | AC2: ČET | AD2: PET | AE2: SOB | AF2: NED
A3: KOMENTAR
A4: Transakcije
A5: Google (Internal) | B5: 2 | C5: 11 | D5: 11 | E5: 4 | F5: 10 | G5: 5 | H5: 2 | I5: 9 | J5: 27 | K5: 31 | L5: 23 | M5: 9 | N5: 8 | O5: 6 | P5: 2 | Q5: 15 | R5: 12 | S5: 11 | T5: 3 | U5: 3 | V5: 8 | W5: 9 | X5: 10 | Y5: 9 | Z5: 9 | AA5: 7 | AB5: 5 | AC5: 2 | AD5: 8 | AE5: 7 | AF5: 5 | AG5: =SUM(B5:AF5) -> 283
A6: FB (IGG Digital Team) | AG6: =SUM(B6:AE6) -> 0
A7: FB (Backerkit) | AG7: =SUM(B7:AE7) -> 0
A8: FB (Internal Paid) | AG8: =SUM(B8:AE8) -> 0
A9: FB (US & CA) | B9: 18 | C9: 19 | D9: 19 | E9: 8 | F9: 9 | G9: 4 | H9: 9 | I9: 4 | J9: 10 | K9: 9 | L9: 13 | M9: 12 | N9: 2 | O9: 1 | P9: 8 | Q9: 6 | R9: 17 | S9: 15 | T9: 12 | U9: 5 | V9: 16 | W9: 13 | X9: 11 | Y9: 9 | Z9: 7 | AA9: 7 | AB9: 8 | AC9: 4 | AD9: 12 | AE9: 18 | AF9: 15 | AG9: =SUM(B9:AF9) -> 320
A10: FB (EU & UK) | AG10: =SUM(B10:AE10) -> 0
A11: Bing Microsoft | B11: 1 | C11: 0 | D11: 1 | E11: 0 | F11: 0 | G11: 0 | H11: 0 | I11: 0 | J11: 36 | K11: 5 | L11: 0 | M11: 0 | N11: 1 | O11: 1 | P11: 0 | Q11: 1 | R11: 0 | S11: 1 | T11: 0 | U11: 0 | V11: 0 | W11: 2 | X11: 0 | Y11: 0 | Z11: 0 | AA11: 1 | AB11: 0 | AC11: 0 | AD11: 1 | AE11: 0 | AF11: 2 | AG11: =SUM(B11:AF11) -> 53
A12: Pinterest | AG12: =SUM(B12:AE12) -> 0
A13: TikTok | AG13: =SUM(B13:AE13) -> 0
A14: Skupaj | B14: =SUM(B5:B13) -> 21 | C14: =SUM(C5:C13) -> 30 | D14: =SUM(D5:D13) -> 31 | E14: =SUM(E5:E13) -> 12 | F14: =SUM(F5:F13) -> 19 | G14: =SUM(G5:G13) -> 9 | H14: =SUM(H5:H13) -> 11 | I14: =SUM(I5:I13) -> 13 | ... AF14: =SUM(AF5:AF13) -> 22 | AG14: =SUM(B14:AE14) -> 634
A16: Prihodek
A17: Google (Internal) | B17: 412 | C17: 2509 | D17: 2800 | E17: 1480 | F17: 2788 | G17: 1298 | H17: 481 | I17: 2271 | J17: 7102 | K17: 8189 | L17: 6056 | M17: 2429 | N17: 1983 | O17: 1472 | P17: 635 | Q17: 4082 | R17: 2929 | S17: 2685 | T17: 802 | U17: 937 | V17: 1871 | W17: 2149 | X17: 2701 | Y17: 2536 | Z17: 2504 | AA17: 1758 | AB17: 1220 | AC17: 438 | AD17: 2027 | AE17: 1686 | AF17: 1257 | AG17: =SUM(B17:AF17) -> 73487
A18: FB (IGG Digital Team) | AG18: =SUM(B18:AE18) -> 0
A19: FB (Backerkit) | AG19: =SUM(B19:AE19) -> 0
A20: FB (Internal Paid) | AG20: =SUM(B20:AE20) -> 0
A21: FB (US & CA) | B21: 4739 | C21: 5207 | D21: 4697 | E21: 1977 | F21: 2286 | G21: 996 | H21: 2074 | I21: 1095.66 | J21: 2426.99 | K21: 2179.99 | L21: 3751.64 | M21: 2910.29 | N21: 602.54 | O21: 212.8 | P21: 3672.05 | Q21: 1852.13 | R21: 3699.9 | S21: 3650.84 | T21: 2732.72 | U21: 1134.57 | V21: 5569.17 | W21: 3236.06 | X21: 2862.2 | Y21: 2074.1 | Z21: 1459.6 | AA21: 1681.58 | AB21: 2436.9 | AC21: 926.25 | AD21: 3040.55 | AE21: 4239.43 | AF21: 3740.25 | AG21: =SUM(B21:AF21) -> 83164.21
A22: FB (EU & UK) | AG22: =SUM(B22:AE22) -> 0
A23: Microsoft | B23: 206 | C23: 0 | D23: 224 | E23: 0 | F23: 0 | G23: 0 | H23: 0 | I23: 0 | J23: 10135 | K23: 1375 | L23: 0 | M23: 0 | N23: 216 | O23: 216 | P23: 0 | Q23: 287 | R23: 0 | S23: 275 | T23: 0 | U23: 0 | V23: 0 | W23: 497 | X23: 0 | Y23: 0 | Z23: 0 | AA23: 219 | AB23: 0 | AC23: 0 | AD23: 263 | AE23: 0 | AF23: 479 | AG23: =SUM(B23:AF23) -> 14392
A24: Pinterest | AG24: =SUM(B24:AE24) -> 0
A25: TikTok | AG25: =SUM(B25:AE25) -> 0
A26: Skupaj | B26: =SUM(B17:B25) -> 5357 | C26: =SUM(C17:C25) -> 7716 | D26: =SUM(D17:D25) -> 7721 | E26: =SUM(E17:E25) -> 3457 | F26: =SUM(F17:F25) -> 5074 | G26: =SUM(G17:G25) -> 2294 | H26: =SUM(H17:H25) -> 2555 | I26: =SUM(I17:I25) -> 3366.66 | ... AF26: =SUM(AF17:AF25) -> 5476.25 | AG26: =SUM(B26:AE26) -> 165566.96
A28: Odhodek
A29: Google Spend (Internal) | B29: 41.01 | C29: 65.55 | D29: 54.81 | E29: 46.74 | F29: 154.83 | G29: 167.87 | H29: 124.85 | I29: 186.66 | J29: 2187.48 | K29: 1020.78 | L29: 451.7 | M29: 223.39 | N29: 259.05 | O29: 198.01 | P29: 206.53 | Q29: 330.57 | R29: 467.23 | S29: 195.86 | T29: 179.37 | U29: 218.64 | V29: =Sales!V12 -> 182.78 | W29: =Sales!W12 -> 182.62 | X29: =Sales!X12 -> 185.5 | Y29: =Sales!Y12 -> 183.33 | Z29: =Sales!Z12 -> 134.14 | AA29: =Sales!AA12 -> 128.61 | AB29: =Sales!AB12 -> 112.6 | AC29: =Sales!AC12 -> 123.69 | ... AF29: =Sales!AF12 -> 149.52 | AG29: =SUM(B29:AE29) -> 8266.03
A30: Provizija 15% Spend (MuteSIX) / $3,500 | AG30: =SUM(B30:AE30) -> 0
A31: FB Spend (IGG Digital Team) | AG31: =SUM(B31:AE31) -> 0
A32: Provizija 13% Purchase (IGG Digital Team) | AG32: =SUM(B32:AE32) -> 0
A33: FB Spend (Backerkit) | AG33: =SUM(B33:AE33) -> 0
A34: Provizija 15% Purchase (Backerkit) | AG34: =SUM(B34:AE34) -> 0
A35: FB Spend (Internal Paid) | AG35: =SUM(B35:AE35) -> 0
A36: FB Spend (US & CA) | B36: 1347.74 | C36: 1974.88 | D36: 2341.3 | E36: 1722.07 | F36: 2098.14 | G36: 1534.35 | H36: 1179.45 | I36: 1487.15 | J36: 1747.78 | K36: 1696.28 | L36: 1604.65 | M36: 1967.38 | N36: 1748.89 | O36: 1722.92 | P36: 1757.94 | Q36: 2217.5 | R36: 2337.64 | S36: 2188.64 | T36: 1651.01 | U36: 1938.13 | V36: =Formula!D23 -> 1941.5445 | W36: =Formula!D24 -> 3286.2986 | X36: =Formula!D25 -> 1942.779 | Y36: =Formula!D26 -> 2092.4872 | Z36: =Formula!D27 -> 2065.4647 | AA36: =Formula!D28 -> 1721.0841 | AB36: =Formula!D29 -> 1605.3444 | AC36: =Formula!D30 -> 1712.4881 | AD36: =Formula!D31 -> 2588.3067 | AE36: =Formula!D32 -> 3725.8232 | AF36: =Formula!D33 -> 3391.3539 | AG36: =SUM(B36:AE36) -> 58945.46
A37: Microsoft Spend | B37: 8.73 | C37: 1.75 | D37: 7.81 | E37: 10.56 | F37: 6.83 | G37: 5.35 | H37: 5.09 | I37: 17.35 | J37: 252.07 | K37: 69.6 | L37: 40.79 | M37: 21.82 | N37: 11.82 | O37: 7.92 | P37: 8.01 | Q37: 8.08 | R37: 15.47 | S37: 10.62 | T37: 8.18 | U37: 5.53 | V37: =Sales!V13 -> 9.54 | W37: =Sales!W13 -> 9.48 | X37: =Sales!X13 -> 7.71 | Y37: =Sales!Y13 -> 12.34 | Z37: =Sales!Z13 -> 8.62 | AA37: =Sales!AA13 -> 10.63 | AB37: =Sales!AB13 -> 3.53 | AC37: =Sales!AC13 -> 6.12 | ... AF37: =Sales!AF13 -> 7.25 | AG37: =SUM(B37:AE37) -> 611.5
A38: Pinterest Spend | AG38: =SUM(B38:AE38) -> 0
A39: TikTok Spend | AG39: =SUM(B39:AE39) -> 0
A40: FB Spend (EU & UK) | AG40: =SUM(B40:AE40) -> 0
A41: Platform Fee (6,90%) | AG41: =SUM(B41:AE41) -> 0
A42: Processing Fee (2,6%) | B42: =B26*0.026 -> 139.282 | C42: =C26*0.026 -> 200.616 | D42: =D26*0.026 -> 200.746 | E42: =E26*0.026 -> 89.882 | F42: =F26*0.026 -> 131.924 | G42: =G26*0.026 -> 59.644 | H42: =H26*0.026 -> 66.43 | I42: =I26*0.026 -> 87.53316 | ... AF42: =AF26*0.026 -> 142.3825 | AG42: =SUM(B42:AE42) -> 4304.741
...

Sheet Refunds
A1: Date | B1: Date of purchase | C1: Order ID | D1: Name | E1: Email | F1: Value | G1: Reason | H1: Platform | I1: Reason | J1: Number
A2: 44326 | B2: 44354 | C2: #6121 | D2: AJ Kratt | E2: ajkratt@icloud.com | F2: 369 | G2: Delivery date | H2: Shopify | I2: Delivery Date | J2: 50 | K2: =J2/J8 -> 0.67567568
A3: 44357 | B3: 17/6/2021 | C3: #3795 | D3: Marisol Plazas | E3: marisolcplazas@gmail.com | F3: 295 | G3: Cannot afford it anymore | H3: Shopify | I3: Cannot Afford it Anymore | J3: 7 | K3: =J3/J8 -> 0.094594595
A4: 44357 | B4: 18/7/2021 | C4: #7605 | D4: Ciera Dillard | E4: dillardeevee@gmail.com | F4: 265 | G4: Delivery date | H4: Shopify | I4: Moving | J4: 2 | K4: =J4/J8 -> 0.027027027
A5: 44418 | B5: 19/5/2021 | C5: #1464 | D5: Laurence Humphreys-Davies | E5: laurence@humphreysdavies.co.uk | F5: 220 | G5: Delivery date | H5: Shopify | I5: Refund and order another Bundle | J5: 0 | K5: =J5/J8 -> 0
A6: 44418 | B6: 44445 | C6: #2942 | D6: Laramee John | E6: johnlaramee@me.com | F6: 582 | G6: Unknown | H6: Shopify | I6: Unknown | J6: 7 | K6: =J6/J8 -> 0.094594595
A7: 44510 | B7: 44356 | C7: #11544 | D7: Donna Christensen | E7: dnattyr@gmail.com | F7: 265 | G7: Unknown | H7: Shopify | I7: Other | J7: 8 | K7: =J7/J8 -> 0.10810811
A8: 44510 | B8: 44449 | C8: #12132 | D8: Nicklas Ansman Giertz | E8: nicklas@ansman.se | F8: 216 | G8: Other | H8: Shopify | I8: All | J8: =SUM(J2:J7) -> 74
A9: 44510 | B9: 44414 | C9: #2922 | D9: Aiden Beard | E9: canaidenb@gmail.com | F9: 283 | G9: Cannot afford it anymore | H9: Shopify
A10: 44510 | B10: 44449 | C10: #12240 | D10: Patricia Osterhouse | E10: trisho831@gmail.com | F10: 216 | G10: Other | H10: Shopify | I10: All Orders | J10: =Sales!B37 -> 1395
A11: 44510 | B11: 14/6/2021 | C11: #7011 | D11: Rachel Shelton | E11: racheldshelton@yahoo.com | F11: 224 | G11: Unknown | H11: Shopify
A12: 44510 | B12: 18/7/2021 | C12: #7788 | D12: Cynthia Bannon | E12: cindy@salomonrealty.com | F12: 206 | G12: Delivery date | H12: Shopify | I12: Refund % | J12: =J8/J10 -> 0.053046595
A13: 44510 | B13: 20/6/2021 | C13: #4340 | D13: Carol Mecham | E13: cnmmecham@gmail.com | F13: 398 | G13: Cannot afford it anymore | H13: Shopify
A14: 44510 | B14: 44204 | C14: #10529 | D14: Martin Tödtling | E14: martin@xn--tdtling-90a.com | F14: 279 | G14: Other | H14: Shopify
A15: 44510 | B15: 44449 | C15: #12355 | D15: Becky Fenwick | E15: rgfenstick@gmail.com | F15: 234 | G15: Cannot afford it anymore | H15: Shopify
A16: 44540 | B16: 23/5/2021 | C16: #12294 | D16: Donna Goodwin | E16: donnacgoodwin1@gmail.com | F16: 263 | G16: Delivery date | H16: Indiegogo | I16: 44136 | J16: 2
A17: 44540 | B17: 44449 | C17: #12259 | D17: Gregg Mitchell | E17: greggmitch1@att.net | F17: 275 | G17: Delivery date | H17: Shopify | I17: Januar | J17: 1
A18: 13/10/2021 | B18: 22/6/2021 | C18: #4671 | D18: Belinda Moisan | E18: bsmoisan@gmail.com | F18: 265 | G18: Delivery date | H18: Shopify | I18: Februar | J18: 1
A19: 13/10/2021 | B19: 18/11/2020 | C19: #820 | D19: Kieran Bohan | E19: kieran.bohan@yahoo.co.uk | F19: 108 | G19: Delivery date | H19: Kickstarter | I19: Marec | J19: 2
A20: 13/10/2021 | B20: 44449 | C20: #12258 | D20: Alisa Ruot | E20: rosieruot@gmail.com | F20: 287 | G20: Unknown | H20: Shopify | I20: April | J20: 1
A21: 14/10/2021 | B21: 23/5/2021 | C21: #1614 | D21: Jody Thoennes | E21: jody.thoennes@gmail.com | F21: 523 | G21: Cannot afford it anymore | H21: Shopify | I21: Maj | J21: 11
A22: 14/10/2021 | B22: 44352 | C22: #10357 | D22: Brandy Reed | E22: brandynicole7399@yahoo.com | F22: 224 | G22: Delivery date | H22: Indiegogo | I22: Junij | J22: 13
A23: 14/10/2021 | B23: 44449 | C23: #12324 | D23: Heidi K Hohmann | E23: heidik520@gmail.com | F23: 275 | G23: Cannot afford it anymore | H23: Shopify | I23: Julij | J23: 23
A24: 15/10/2021 | B24: 24/7/2021 | C24: #9061 | D24: Laura McKnight | E24: lkmck07@gmail.com | F24: 265 | G24: Moving | H24: Shopify | I24: Avgust | J24: 1
A25: 18/10/2021 | B25: 13/10/2021 | C25: #12662 | D25: Marian Williams | E25: mwilliams2529@cfl.rr.com | F25: 305 | G25: Delivery date | H25: Shopify | I25: September | J25: 2
A26: 18/10/2021 | B26: 44295 | C26: #11516 | D26: Julia Kiwitter | E26: julia@julia-kiwitter.de | F26: 210 | G26: Delivery date | H26: Shopify | I26: Oktober | J26: 14
A27: 18/10/2021 | B27: 17/7/2021 | C27: #7507 | D27: Traci Waiss | E27: hospicern35@gmail.com | F27: 206 | G27: Cannot afford it anymore | H27: Shopify | K27: =sum(J16:J26) -> 71
A28: 18/10/2021 | B28: 18/7/2021 | C28: #7564 | D28: Blair Davis | E28: baydavis1@gmail.com | F28: 191 | G28: Delivery date | H28: Shopify
A29: 18/10/2021 | B29: 26/6/2021 | C29: #5004 | D29: Daniel Oikari | E29: daniel@planetpromo.se | F29: 436 | G29: Delivery date | H29: Shopify
A30: 18/10/2021 | B30: 13/7/2021 | C30: #6914 | D30: Michael Noonan | E30: mjnoonan2@gmail.com | F30: 265 | G30: Delivery date | H30: Shopify
A31: 18/10/2021 | B31: 16/10/2021 | C31: #12743 | D31: barbara glasser | E31: barbglasser@yahoo.com | F31: 311 | G31: Other | H31: Shopify
A32: 19/10/2021 | B32: 44265 | C32: #11993 | D32: Dan Hentschke | E32: bblackhu@gmail.com | F32: 265 | G32: Delivery date | H32: Shopify
A33: 19/10/2021 | B33: 16/7/2021 | C33: #7352 | D33: Kelly Tanner | E33: momoftwo2021@yahoo.com | F33: 265 | G33: Delivery date | H33: Shopify
A34: 19/10/2021 | B34: 44444 | C34: #10824 | D34: Dan Bullerman | E34: dlbuller@mtu.edu | F34: 283 | G34: Delivery date | H34: Indiegogo
A35: 20/10/2021 | B35: 44350 | C35: #3466 | D35: Brian McCarty | E35: bkmccarty@gmail.com | F35: 285 | G35: Delivery date | H35: Indiegogo
A36: 20/10/2021 | B36: 44472 | C36: #3901 | D36: Katherine Scott | E36: 17kascott@gmail.com | F36: 206 | G36: Other | H36: Indiegogo
A37: 20/10/2021 | B37: 27/7/2021 | C37: #9925 | D37: Laura Allen | E37: allen3841@gmail.com | F37: 265 | G37: Other | H37: Shopify
A38: 21/10/2021 | B38: 23/11/2020 | C38: #5392 | D38: Jody Sataloff | E38: jsataloff@gmail.com | F38: 143 | G38: Delivery date | H38: Kickstarter
A39: 21/10/2021 | B39: 44409 | C39: #18603 | D39: Cheryl Hanes | E39: cheryl@idri.net | F39: 183 | G39: Moving | H39: Kickstarter
A40: 22/10/2021 | B40: 44262 | C40: #5780 | D40: Joel Sthilaire | E40: joelst40@gmail.com | F40: 250 | G40: Delivery date | H40: Shopify
...

Sheet Formula
C1: FB - US and CA | F1: Error: You need to reauthenticate the Shopify account used in the query and run it again: https://supermetrics.link/reauth
C2: EUR | D2: USD
A3: 44470 | C3: 1164.89 | D3: =IFERROR(__xludf.DUMMYFUNCTION("GOOGLEFINANCE(""CURRENCY:EURUSD"")*C3"),1344.0733797999999) -> 1344.0734
A4: 44471 | C4: 1703.41 | D4: =IFERROR(__xludf.DUMMYFUNCTION("GOOGLEFINANCE(""CURRENCY:EURUSD"")*C4"),1965.4285261999999) -> 1965.4285
A5: 44472 | C5: 2018.51 | D5: =IFERROR(__xludf.DUMMYFUNCTION("GOOGLEFINANCE(""CURRENCY:EURUSD"")*C5"),2328.9972081999995) -> 2328.9972
A6: 44473 | C6: 1487.1 | D6: =IFERROR(__xludf.DUMMYFUNCTION("GOOGLEFINANCE(""CURRENCY:EURUSD"")*C6"),1715.8457219999996) -> 1715.8457
A7: 44474 | C7: 1814.21 | D7: =IFERROR(__xludf.DUMMYFUNCTION("GOOGLEFINANCE(""CURRENCY:EURUSD"")*C7"),2093.2717822) -> 2093.2718
A8: 44475 | C8: 1327.97 | D8: =IFERROR(__xludf.DUMMYFUNCTION("GOOGLEFINANCE(""CURRENCY:EURUSD"")*C8"),1532.2383453999998) -> 1532.2383
A9: 44476 | C9: 1022.24 | D9: =IFERROR(__xludf.DUMMYFUNCTION("GOOGLEFINANCE(""CURRENCY:EURUSD"")*C9"),1179.4809567999998) -> 1179.481
A10: 44477 | C10: 1286.49 | D10: =IFERROR(__xludf.DUMMYFUNCTION("GOOGLEFINANCE(""CURRENCY:EURUSD"")*C10"),1484.3778917999998) -> 1484.3779
A11: 44478 | C11: 1509.93 | D11: =IFERROR(__xludf.DUMMYFUNCTION("GOOGLEFINANCE(""CURRENCY:EURUSD"")*C11"),1742.1874325999997) -> 1742.1874
A12: 44479 | C12: 1468.62 | D12: =IFERROR(__xludf.DUMMYFUNCTION("GOOGLEFINANCE(""CURRENCY:EURUSD"")*C12"),1694.5231283999997) -> 1694.5231
A13: 44480 | C13: 1387.67 | D13: =IFERROR(__xludf.DUMMYFUNCTION("GOOGLEFINANCE(""CURRENCY:EURUSD"")*C13"),1601.1213994) -> 1601.1214
A14: 44481 | C14: 1691.91 | D14: =IFERROR(__xludf.DUMMYFUNCTION("GOOGLEFINANCE(""CURRENCY:EURUSD"")*C14"),1952.1595962) -> 1952.1596
A15: 44482 | C15: 1506.35 | D15: =IFERROR(__xludf.DUMMYFUNCTION("GOOGLEFINANCE(""CURRENCY:EURUSD"")*C15"),1738.0567569999996) -> 1738.0568
A16: 44483 | C16: 1486.24 | D16: =IFERROR(__xludf.DUMMYFUNCTION("GOOGLEFINANCE(""CURRENCY:EURUSD"")*C16"),1714.8534367999998) -> 1714.8534
A17: 44484 | C17: 1516.45 | D17: =IFERROR(__xludf.DUMMYFUNCTION("GOOGLEFINANCE(""CURRENCY:EURUSD"")*C17"),1749.7103389999997) -> 1749.7103
A18: 44485 | C18: 1912.79 | D18: =IFERROR(__xludf.DUMMYFUNCTION("GOOGLEFINANCE(""CURRENCY:EURUSD"")*C18"),2207.0153577999995) -> 2207.0154
A19: 44486 | C19: 2017.61 | D19: =IFERROR(__xludf.DUMMYFUNCTION("GOOGLEFINANCE(""CURRENCY:EURUSD"")*C19"),2327.9587701999994) -> 2327.9588
A20: 44487 | C20: 1882.03 | D20: =IFERROR(__xludf.DUMMYFUNCTION("GOOGLEFINANCE(""CURRENCY:EURUSD"")*C20"),2171.5238545999996) -> 2171.5239
A21: 44488 | C21: 1421.09 | D21: =IFERROR(__xludf.DUMMYFUNCTION("GOOGLEFINANCE(""CURRENCY:EURUSD"")*C21"),1639.6820637999997) -> 1639.6821
A22: 44489 | C22: 1665.37 | D22: =IFERROR(__xludf.DUMMYFUNCTION("GOOGLEFINANCE(""CURRENCY:EURUSD"")*C22"),1921.5372133999997) -> 1921.5372
A23: 44490 | C23: 1682.71 | D23: =IFERROR(__xludf.DUMMYFUNCTION("GOOGLEFINANCE(""CURRENCY:EURUSD"")*C23"),1941.5444521999998) -> 1941.5445
A24: 44491 | C24: 2848.19 | D24: =IFERROR(__xludf.DUMMYFUNCTION("GOOGLEFINANCE(""CURRENCY:EURUSD"")*C24"),3286.2985857999997) -> 3286.2986
A25: 44492 | C25: 1683.78 | D25: =IFERROR(__xludf.DUMMYFUNCTION("GOOGLEFINANCE(""CURRENCY:EURUSD"")*C25"),1942.7790395999998) -> 1942.779
A26: 44493 | C26: 1813.53 | D26: =IFERROR(__xludf.DUMMYFUNCTION("GOOGLEFINANCE(""CURRENCY:EURUSD"")*C26"),2092.4871845999996) -> 2092.4872
A27: 44494 | C27: 1790.11 | D27: =IFERROR(__xludf.DUMMYFUNCTION("GOOGLEFINANCE(""CURRENCY:EURUSD"")*C27"),2065.4647201999996) -> 2065.4647
A28: 44495 | C28: 1491.64 | D28: =IFERROR(__xludf.DUMMYFUNCTION("GOOGLEFINANCE(""CURRENCY:EURUSD"")*C28"),1721.0840647999999) -> 1721.0841
A29: 44496 | C29: 1391.33 | D29: =IFERROR(__xludf.DUMMYFUNCTION("GOOGLEFINANCE(""CURRENCY:EURUSD"")*C29"),1605.3443805999998) -> 1605.3444
A30: 44497 | C30: 1484.19 | D30: =IFERROR(__xludf.DUMMYFUNCTION("GOOGLEFINANCE(""CURRENCY:EURUSD"")*C30"),1712.4881057999999) -> 1712.4881
A31: 44498 | C31: 2243.25 | D31: =IFERROR(__xludf.DUMMYFUNCTION("GOOGLEFINANCE(""CURRENCY:EURUSD"")*C31"),2588.3067149999997) -> 2588.3067
A32: 44499 | C32: 3229.12 | D32: =IFERROR(__xludf.DUMMYFUNCTION("GOOGLEFINANCE(""CURRENCY:EURUSD"")*C32"),3725.8232383999994) -> 3725.8232
A33: 44500 | C33: 2939.24 | D33: =IFERROR(__xludf.DUMMYFUNCTION("GOOGLEFINANCE(""CURRENCY:EURUSD"")*C33"),3391.3538967999993) -> 3391.3539

Sheet SupermetricsQueries
A1: Supermetrics Queries
A3: All the queries created by Supermetrics are stored here, each in its own row.
H4: 16987982
A5: On this sheet you can:
A6: 1. Modify the parameters of a query. Any changes will be visible when you run a refresh.
A8: 2. Remove a query by deleting its row | H8: Europe/Paris
A10: 3. Add new queries: type a range address and query parameters, leave the query ID empty. The query will be added when you run a refresh. (Of course, it's much easier to use the sidebar to add new queries.)
A13: Queries are stored with the authentication of the original user that created the query. If you want to transfer a query to the currently active Google Sheets user, delete its query ID from column A and run a refresh. For complete instructions on transferring queries, see https://support.supermetrics.com/support/solutions/articles/19000050074-how-can-i-transfer-queries-from-one-user-to-another-
A16: Don't delete or rename this sheet. If you delete or rename it, your existing queries can no longer be refreshed. Hiding the sheet is OK. Also, don't delete any rows above row 21.
A19: Query ID | D19: Sheet name | E19: Range address | G19: Created | H19: Updated | I19: Last status | J19: Last refresh ID | K19: Results contain sampled data | L19: Execution time (sec) | M19: Object type | N19: Linked chart ID | O19: Data source | Q19: Date range type | R19: Start date | S19: End date | T19: Compare to | U19: Comparison value type | W19: Accounts/views | X19: Metrics | Y19: Dimensions | Z19: Pivot dimensions | AA19: Filters | AB19: Segment ID | AC19: Sort | AD19: Max rows | AE19: Max pivot categories | AF19: Special settings | AG19: Other parameters | AJ19: Result type | AK19: Language/country | AL19: Translate to | AN19: SQL | AO19: Database name | AP19: Range address (static) | AQ19: Report type | AT19: Highlight with colour | AU19: Refresh with user account | AV19: Returned data | AW19: Refresh button number
A20: paramsID | C20: ssID | D20: sheetName | E20: rangeAddress | G20: created | H20: updated | I20: lastStatus | J20: lastqueryID | K20: sampled | L20: runtime_sec | M20: objType | N20: linkedChartID | O20: dataSource | Q20: dateRangeType | R20: startDateString | S20: endDateString | T20: comp | U20: cvt | W20: profiles | X20: metrics | Y20: dimensions | Z20: sd | AA20: filterArr | AB20: segment | AC20: sort | AD20: maxResults | AE20: maxCategories | AF20: specialSettings | AG20: otherParams | AJ20: sds_result_type | AK20: sds_lang | AL20: sds_tolang | AN20: sql | AO20: db_name | AP20: rangeAddressStatic | AQ20: rt | AR20: scopeMZ | AS20: sortMZ | AT20: condform | AU20: authUser | AV20: metaDataToUser | AW20: refreshButtonNumber
A21: xwoIpANxRm908eDp5oKTwQpEI8gvD4 | D21: =IFERROR(__xludf.DUMMYFUNCTION("ARRAY_CONSTRAIN(split(CELL(""ADDRESS"",zsupermetrics_xwoIpANxRm908eDp5oKTwQpEI8gvD4),""!""),1,1)"),"Formula") -> Formula | E21: =CELL("ADDRESS",zsupermetrics_xwoIpANxRm908eDp5oKTwQpEI8gvD4)&":"&address(row(zsupermetrics_xwoIpANxRm908eDp5oKTwQpEI8gvD4)+rows(zsupermetrics_xwoIpANxRm908eDp5oKTwQpEI8gvD4)-1,column(zsupermetrics_xwoIpANxRm908eDp5oKTwQpEI8gvD4)+COLUMNS(zsupermetrics_xwoIpANxRm908eDp5oKTwQpEI8gvD4)-1) -> Formula!$F$1:$F$1 | G21: 44494.462 | H21: 45231.058 | I21: Error: You need to reauthenticate the Shopify account used in the query and run it again: https://supermetrics.link/reauth | J21: 1698798163807 | K21: FALSE | L21: 1 | M21: TABLE | O21: SHP | Q21: yesterday | W21: ["gid://shopify/Shop/55807180983`Bird Buddy"] | X21: ["total_sales"] | Y21: [] | Z21: [] | AA21: [] | AB21: [] | AF21: [] | AG21: {} | AP21: Formula'!F1 | AU21: gid://shopify/Shop/55807180983
