Workbook
Name zsupermetrics_ru0GDtbZzDLHQOQtJJ6K08MvUDyyp7: #REF!
Name zsupermetrics_DQl8lUbpTRu3fayaJJi7lVfOGKjNU4: 'Data - P&L'!$A$3:$A$4
Name zsupermetrics_BioPyGBzcBsy60UCQmPcTuFReEmghI: 'Data - P&L'!$B$2:$B$3
Name zsupermetrics_refreshAll: SupermetricsQueries!$H$5
Name zsupermetrics_n3GtLgiKpTmd2pYmQNMuq6TPD0qE0b: #REF!
Name zsupermetrics_refreshAllSilent: SupermetricsQueries!$H$6
Name zsupermetrics_Mgms9p0QzysYvrIhnsKACeVBVxfIEO: #REF!
Name zsupermetrics_Mgms9p0QzysYvrIhnsKACeVBVxfIEO: 'Data - P&L'!$A$2:$A$3
Name zsupermetrics_forceRefresh: SupermetricsQueries!$H$4
Name zsupermetrics_wbYMmT0YL9bAN0yhimW0ziPFnia9Dx: #REF!
Name zsupermetrics_iNpyVy90bWCI0yUaFQpxOtzWMa6sW4: #REF!
Name zsupermetrics_xwoIpANxRm908eDp5oKTwQpEI8gvD4: #REF!
Name zsupermetrics_n3GtLgiKpTmd2pYmQNMuq6TPD0qE0b: 'Data - P&L'!$B$4:$B$5
Name rdataslayer_42b112e4e4be4305bb4c1be75e2dd549: 'Data - P&L'!$B$2:$C$3
Name zsupermetrics_9i4W4hgd80uRpQLMeX0eRnESN8gjyv: #REF!
Name zsupermetrics_5bmwtOpHUbSYmDMeuCPkrxaojTprPP: #REF!
Name rdataslayer_3753ddf3234e496aa261974a0222e193: 'Data - P&L'!$H$2:$I$2
Name zsupermetrics_SGBxROnInO9rFyh3H7j2Lldx0Bdc5v: #REF!
Name zsupermetrics_pxuhRTEmIU93xSgKclyxajD0fCZ6rF: #REF!
Name zsupermetrics_ru0GDtbZzDLHQOQtJJ6K08MvUDyyp7: 'Data - P&L'!$B$4:$B$5
Name zsupermetrics_qWp7V908pNEYMtfv8QZvSTeDnBAHOU: 'Data - P&L'!$B$5:$C$13
Name rdataslayer_4a0f150f4f2f4e4f85c890c75b7a1fa4: #REF!
Name zsupermetrics_8xojRjNDjo2jWHGDWjFEhflhyIq3Hq: #REF!
Name zsupermetrics_HgZqhorObHOtZHuyJjpmyYaEPoYntx: #REF!
Name zsupermetrics_YsFuuYtr8vOdNXCCPiFJIO38NP4b2T: #REF!
Name zsupermetrics_DQl8lUbpTRu3fayaJJi7lVfOGKjNU4: #REF!
Name zsupermetrics_YVuzfmsfdurz7Ldl84Rfns8oka6LsS: #REF!
Name zsupermetrics_4VkB7ij7WO0JjKBEgvjB2GHjSy2Egm: #REF!
Name zsupermetrics_9i4W4hgd80uRpQLMeX0eRnESN8gjyv: 'Data - P&L'!$C$13
Name zsupermetrics_lx4cNai7gT6tH4j08ZRkI21Qlpjioi: #REF!
Name rdataslayer_d70e473bcafe40a3aa834ce157fb2ba3: #REF!
Name zsupermetrics_NugLlrQxlKiqhxQae8EFpITBm1pLCj: 'Data - P&L'!$B$6:$C$13
Name zsupermetrics_8xojRjNDjo2jWHGDWjFEhflhyIq3Hq: Summary!$K$9:$K$33
Name zsupermetrics_FEamnpN5FsVYF0RtUTXAwunZ388Tkc: Forecast!$A$113:$C$141
Name rdataslayer_3753ddf3234e496aa261974a0222e193: #REF!
Name zsupermetrics_iNpyVy90bWCI0yUaFQpxOtzWMa6sW4: 'Data - P&L'!$A$2:$A$3
Name rdataslayer_4a0f150f4f2f4e4f85c890c75b7a1fa4: 'Data - P&L'!$D$2:$E$3
Name zsupermetrics_BioPyGBzcBsy60UCQmPcTuFReEmghI: #REF!
Name zsupermetrics_qWp7V908pNEYMtfv8QZvSTeDnBAHOU: #REF!
Name zsupermetrics_wbYMmT0YL9bAN0yhimW0ziPFnia9Dx: 'Data - P&L'!$A$2:$A$3
Name zsupermetrics_4VkB7ij7WO0JjKBEgvjB2GHjSy2Egm: 'Data - P&L'!$B$4:$C$10
Name zsupermetrics_lx4cNai7gT6tH4j08ZRkI21Qlpjioi: 'Data - P&L'!$B$4:$C$13
Name rdataslayer_42b112e4e4be4305bb4c1be75e2dd549: #REF!
Name rdataslayer_adf57e64065742daa5b4161161b1c3ca: #REF!
Name rdataslayer_adf57e64065742daa5b4161161b1c3ca: 'Data - P&L'!$B$4:$D$5
Name zsupermetrics_NugLlrQxlKiqhxQae8EFpITBm1pLCj: #REF!
Name zsupermetrics_xwoIpANxRm908eDp5oKTwQpEI8gvD4: #REF!
Name zsupermetrics_YsFuuYtr8vOdNXCCPiFJIO38NP4b2T: 'Data - P&L'!$B$4:$C$13
Name rdataslayer_d70e473bcafe40a3aa834ce157fb2ba3: 'Data - P&L'!$C$8:$D$9
Name zsupermetrics_HgZqhorObHOtZHuyJjpmyYaEPoYntx: 'Data - P&L'!$B$4:$B$5

Sheet Data_forecast_2024
B1: 45627 | C1: 45628 | D1: 45629 | E1: 45630 | F1: 45631 | G1: 45632 | H1: 45633 | I1: 45634 | J1: 45635 | K1: 45636 | L1: 45637 | M1: 45638 | N1: 45639 | O1: 45640 | P1: 45641 | Q1: 45642 | R1: 45643 | S1: 45644 | T1: 45645 | U1: 45646 | V1: 45647 | W1: 45648 | X1: 45649 | Y1: 45650 | Z1: 45651 | AA1: 45652 | AB1: 45653 | AC1: 45654 | AD1: 45655 | AE1: 45656 | AF1: 45657
A2: Quantities | B2: ='DTC - P&L'!B65+'AMAZON - P&L'!B36+'WALMART - P&L'!B19+'Digital Marketplaces - P&L'!B17+'Digital Marketplaces - P&L'!B129+'Digital Marketplaces - P&L'!B239+'COSTCO - P&L'!B19 -> 124 | C2: ='DTC - P&L'!C65+'AMAZON - P&L'!C36+'WALMART - P&L'!C19+'Digital Marketplaces - P&L'!C17+'Digital Marketplaces - P&L'!C129+'Digital Marketplaces - P&L'!C239+'COSTCO - P&L'!C19 -> 145 | D2: ='DTC - P&L'!D65+'AMAZON - P&L'!D36+'WALMART - P&L'!D19+'Digital Marketplaces - P&L'!D17+'Digital Marketplaces - P&L'!D129+'Digital Marketplaces - P&L'!D239+'COSTCO - P&L'!D19 -> 129 | E2: ='DTC - P&L'!E65+'AMAZON - P&L'!E36+'WALMART - P&L'!E19+'Digital Marketplaces - P&L'!E17+'Digital Marketplaces - P&L'!E129+'Digital Marketplaces - P&L'!E239+'COSTCO - P&L'!E19 -> 151 | F2: ='DTC - P&L'!F65+'AMAZON - P&L'!F36+'WALMART - P&L'!F19+'Digital Marketplaces - P&L'!F17+'Digital Marketplaces - P&L'!F129+'Digital Marketplaces - P&L'!F239+'COSTCO - P&L'!F19 -> 155 | G2: ='DTC - P&L'!G65+'AMAZON - P&L'!G36+'WALMART - P&L'!G19+'Digital Marketplaces - P&L'!G17+'Digital Marketplaces - P&L'!G129+'Digital Marketplaces - P&L'!G239+'COSTCO - P&L'!G19 -> 141 | H2: ='DTC - P&L'!H65+'AMAZON - P&L'!H36+'WALMART - P&L'!H19+'Digital Marketplaces - P&L'!H17+'Digital Marketplaces - P&L'!H129+'Digital Marketplaces - P&L'!H239+'COSTCO - P&L'!H19 -> 142 | I2: ='DTC - P&L'!I65+'AMAZON - P&L'!I36+'WALMART - P&L'!I19+'Digital Marketplaces - P&L'!I17+'Digital Marketplaces - P&L'!I129+'Digital Marketplaces - P&L'!I239+'COSTCO - P&L'!I19 -> 166 | ... AF2: ='DTC - P&L'!AF65+'AMAZON - P&L'!AF36+'WALMART - P&L'!AF19+'Digital Marketplaces - P&L'!AF17+'Digital Marketplaces - P&L'!AF129+'Digital Marketplaces - P&L'!AF239+'COSTCO - P&L'!AF19 -> 211
A3: Sales | B3: =Summary!B33+Summary!B79+Summary!B71+Summary!B45 -> 347569.25 | C3: =Summary!C33+Summary!C79+Summary!C71+Summary!C45 -> 318732.08 | D3: =Summary!D33+Summary!D79+Summary!D71+Summary!D45 -> 274274.49 | E3: =Summary!E33+Summary!E79+Summary!E71+Summary!E45 -> 221829.02 | F3: =Summary!F33+Summary!F79+Summary!F71+Summary!F45 -> 218022.8 | G3: =Summary!G33+Summary!G79+Summary!G71+Summary!G45 -> 172617.41 | H3: =Summary!H33+Summary!H79+Summary!H71+Summary!H45 -> 169640 | I3: =Summary!I33+Summary!I79+Summary!I71+Summary!I45 -> 176385.71 | ... AF3: =Summary!AF33+Summary!AF79+Summary!AF71+Summary!AF45 -> 77205.522

Sheet WALMART_Data_forecast_2024
B1: 45597 | C1: 45598 | D1: 45599 | E1: 45600 | F1: 45601 | G1: 45602 | H1: 45603 | I1: 45604 | J1: 45605 | K1: 45606 | L1: 45607 | M1: 45608 | N1: 45609 | O1: 45610 | P1: 45611 | Q1: 45612 | R1: 45613 | S1: 45614 | T1: 45615 | U1: 45616 | V1: 45617 | W1: 45618 | X1: 45619 | Y1: 45620 | Z1: 45621 | AA1: 45622 | AB1: 45623 | AC1: 45624 | AD1: 45625 | AE1: 45626
A2: Quantities | B2: ='WALMART - P&L'!B19 -> 0 | C2: ='WALMART - P&L'!C19 -> 2 | D2: ='WALMART - P&L'!D19 -> 1 | E2: ='WALMART - P&L'!E19 -> 0 | F2: ='WALMART - P&L'!F19 -> 0 | G2: ='WALMART - P&L'!G19 -> 1 | H2: ='WALMART - P&L'!H19 -> 1 | I2: ='WALMART - P&L'!I19 -> 0 | ... AF2: ='WALMART - P&L'!AF19 -> 0
A3: Sales | B3: =Summary!B53 -> 62.63 | C3: =Summary!C53 -> 635.17 | D3: =Summary!D53 -> 271.93 | E3: =Summary!E53 -> 0 | F3: =Summary!F53 -> 0 | G3: =Summary!G53 -> 382.97 | H3: =Summary!H53 -> 336.83 | I3: =Summary!I53 -> 31.39 | ... AF3: =Summary!AF53 -> 31.32

Sheet COSTCO_Data_forecast_2024
B1: 45627 | C1: 45628 | D1: 45629 | E1: 45630 | F1: 45631 | G1: 45632 | H1: 45633 | I1: 45634 | J1: 45635 | K1: 45636 | L1: 45637 | M1: 45638 | N1: 45639 | O1: 45640 | P1: 45641 | Q1: 45642 | R1: 45643 | S1: 45644 | T1: 45645 | U1: 45646 | V1: 45647 | W1: 45648 | X1: 45649 | Y1: 45650 | Z1: 45651 | AA1: 45652 | AB1: 45653 | AC1: 45654 | AD1: 45655 | AE1: 45656 | AF1: 45657
A2: Quantities | B2: ='COSTCO - P&L'!B19 -> 0 | C2: ='COSTCO - P&L'!C19 -> 0 | D2: ='COSTCO - P&L'!D19 -> 0 | E2: ='COSTCO - P&L'!E19 -> 0 | F2: ='COSTCO - P&L'!F19 -> 0 | G2: ='COSTCO - P&L'!G19 -> 0 | H2: ='COSTCO - P&L'!H19 -> 0 | I2: ='COSTCO - P&L'!I19 -> 0 | ... AF2: ='COSTCO - P&L'!AF19 -> 4
A3: Sales | B3: =Summary!B45 -> 0 | C3: =Summary!C45 -> 0 | D3: =Summary!D45 -> 0 | E3: =Summary!E45 -> 0 | F3: =Summary!F45 -> 0 | G3: =Summary!G45 -> 0 | H3: =Summary!H45 -> 0 | I3: =Summary!I45 -> 0 | ... AF3: =Summary!AF45 -> 1188.7255

Sheet DM_Data_forecast_2024
B1: 45627 | C1: 45628 | D1: 45629 | E1: 45630 | F1: 45631 | G1: 45632 | H1: 45633 | I1: 45634 | J1: 45635 | K1: 45636 | L1: 45637 | M1: 45638 | N1: 45639 | O1: 45640 | P1: 45641 | Q1: 45642 | R1: 45643 | S1: 45644 | T1: 45645 | U1: 45646 | V1: 45647 | W1: 45648 | X1: 45649 | Y1: 45650 | Z1: 45651 | AA1: 45652 | AB1: 45653 | AC1: 45654 | AD1: 45655 | AE1: 45656 | AF1: 45657
A2: Quantities | B2: ='Digital Marketplaces - P&L'!B17+'Digital Marketplaces - P&L'!B129+'Digital Marketplaces - P&L'!B239 -> 0 | C2: ='Digital Marketplaces - P&L'!C17+'Digital Marketplaces - P&L'!C129+'Digital Marketplaces - P&L'!C239 -> 0 | D2: ='Digital Marketplaces - P&L'!D17+'Digital Marketplaces - P&L'!D129+'Digital Marketplaces - P&L'!D239 -> 0 | E2: ='Digital Marketplaces - P&L'!E17+'Digital Marketplaces - P&L'!E129+'Digital Marketplaces - P&L'!E239 -> 0 | F2: ='Digital Marketplaces - P&L'!F17+'Digital Marketplaces - P&L'!F129+'Digital Marketplaces - P&L'!F239 -> 0 | G2: ='Digital Marketplaces - P&L'!G17+'Digital Marketplaces - P&L'!G129+'Digital Marketplaces - P&L'!G239 -> 0 | H2: ='Digital Marketplaces - P&L'!H17+'Digital Marketplaces - P&L'!H129+'Digital Marketplaces - P&L'!H239 -> 0 | I2: ='Digital Marketplaces - P&L'!I17+'Digital Marketplaces - P&L'!I129+'Digital Marketplaces - P&L'!I239 -> 0 | ... AF2: ='Digital Marketplaces - P&L'!AF17+'Digital Marketplaces - P&L'!AF129+'Digital Marketplaces - P&L'!AF239 -> 1
A3: Sales | B3: =Summary!B71 -> 0 | C3: =Summary!C71 -> 0 | D3: =Summary!D71 -> 0 | E3: =Summary!E71 -> 0 | F3: =Summary!F71 -> 0 | G3: =Summary!G71 -> 0 | H3: =Summary!H71 -> 0 | I3: =Summary!I71 -> 0 | ... AF3: =Summary!AF71 -> 254.72539

Sheet AMAZON_Data_forecast_2024
B1: 45597 | C1: 45598 | D1: 45599 | E1: 45600 | F1: 45601 | G1: 45602 | H1: 45603 | I1: 45604 | J1: 45605 | K1: 45606 | L1: 45607 | M1: 45608 | N1: 45609 | O1: 45610 | P1: 45611 | Q1: 45612 | R1: 45613 | S1: 45614 | T1: 45615 | U1: 45616 | V1: 45617 | W1: 45618 | X1: 45619 | Y1: 45620 | Z1: 45621 | AA1: 45622 | AB1: 45623 | AC1: 45624 | AD1: 45625 | AE1: 45626
A2: Quantities | B2: ='AMAZON - P&L'!B36 -> 64 | C2: ='AMAZON - P&L'!C36 -> 90 | D2: ='AMAZON - P&L'!D36 -> 73 | E2: ='AMAZON - P&L'!E36 -> 84 | F2: ='AMAZON - P&L'!F36 -> 86 | G2: ='AMAZON - P&L'!G36 -> 77 | H2: ='AMAZON - P&L'!H36 -> 72 | I2: ='AMAZON - P&L'!I36 -> 92 | ... AE2: ='AMAZON - P&L'!AE36 -> 61
A3: Sales | B3: =Summary!B27 -> 20026.6 | C3: =Summary!C27 -> 28799.1 | D3: =Summary!D27 -> 23958 | E3: =Summary!E27 -> 28901.2 | F3: =Summary!F27 -> 29312.82 | G3: =Summary!G27 -> 25501.91 | H3: =Summary!H27 -> 23405.2 | I3: =Summary!I27 -> 29757.41 | ... AF3: =Summary!AF27 -> 23985.36

Sheet DTC_Data_forecast_2024
B1: 45627 | C1: 45628 | D1: 45629 | E1: 45630 | F1: 45631 | G1: 45632 | H1: 45633 | I1: 45634 | J1: 45635 | K1: 45636 | L1: 45637 | M1: 45638 | N1: 45639 | O1: 45640 | P1: 45641 | Q1: 45642 | R1: 45643 | S1: 45644 | T1: 45645 | U1: 45646 | V1: 45647 | W1: 45648 | X1: 45649 | Y1: 45650 | Z1: 45651 | AA1: 45652 | AB1: 45653 | AC1: 45654 | AD1: 45655 | AE1: 45656 | AF1: 45657
A2: Quantities | B2: ='DTC - P&L'!B65 -> 60 | C2: ='DTC - P&L'!C65 -> 53 | D2: ='DTC - P&L'!D65 -> 55 | E2: ='DTC - P&L'!E65 -> 67 | F2: ='DTC - P&L'!F65 -> 69 | G2: ='DTC - P&L'!G65 -> 63 | H2: ='DTC - P&L'!H65 -> 69 | I2: ='DTC - P&L'!I65 -> 74 | ... AF2: ='DTC - P&L'!AF65 -> 127
A3: Sales | B3: =Summary!B9 -> 138390.47 | C3: =Summary!C9 -> 151225.52 | D3: =Summary!D9 -> 151451.22 | E3: =Summary!E9 -> 99608.559 | F3: =Summary!F9 -> 103556.73 | G3: =Summary!G9 -> 90242.155 | H3: =Summary!H9 -> 90339.034 | I3: =Summary!I9 -> 88015.047 | ... AF3: =Summary!AF9 -> 40433.49

Sheet Summary
B1: 45658 | C1: 45659 | D1: 45660 | E1: 45661 | F1: 45662 | G1: 45663 | H1: 45664 | I1: 45665 | J1: 45666 | K1: 45667 | L1: 45668 | M1: 45669 | N1: 45670 | O1: 45671 | P1: 45672 | Q1: 45673 | R1: 45674 | S1: 45675 | T1: 45676 | U1: 45677 | V1: 45678 | W1: 45679 | X1: 45680 | Y1: 45681 | Z1: 45682 | AA1: 45683 | AB1: 45684 | AC1: 45685 | AD1: 45686 | AE1: 45687 | AF1: 45688
B2: WED | C2: THU | D2: FRI | E2: SAT | F2: SUN | G2: MON | H2: TUE | I2: WED | J2: THU | K2: FRI | L2: SAT | M2: SUN | N2: MON | O2: TUE | P2: WED | Q2: THU | R2: FRI | S2: SAT | T2: SUN | U2: MON | V2: TUE | W2: WED | X2: THU | Y2: FRI | Z2: SAT | AA2: SUN | AB2: MON | AC2: TUE | AD2: WED | AE2: THU | AF2: FRI
A3: Notes | D3: SBF PRO In Stock (/Storefront/US) | I3: Added Add-on Amazon videos on PDPs (US/EU) | O3: VAT # in EU receipt emails | P3: redirect EU users to .eu site and vice versa | Q3: AvaTax Plugin disabled | R3: Shipping to Canada enabled (US) | W3: PayPal Plugin Updated | X3: Weekend Sale Up to 25% OFF | Y3: 3in1 Limited time offer removal (/Cart) | AB3: Winter Sale Up to 30% OFF | AF3: Valentine's Sale
D4: Family Premium Switch functionality EU | O4: WOO - Card functionality - switch order of cards and variations | R4: SKU3 V2 Discount -13% (Weekend Offer) | U4: SKU3 V2 Discount -13% (Winter Sale) | AB4: SKU3 V1 OOS (US)
A9: DTC Revenue | B9: =SUM(B10,B17,B24) -> 138390.47 | C9: =SUM(C10,C17,C24) -> 151225.52 | D9: =SUM(D10,D17,D24) -> 151451.22 | E9: =SUM(E10,E17,E24) -> 99608.559 | F9: =SUM(F10,F17,F24) -> 103556.73 | G9: =SUM(G10,G17,G24) -> 90242.155 | H9: =SUM(H10,H17,H24) -> 90339.034 | I9: =SUM(I10,I17,I24) -> 88015.047 | ... AF9: =SUM(AF10,AF17,AF24) -> 40433.49
A10: - DTC Revenue US&CA | B10: =sum(B11:B16) -> 32513.25 | C10: =sum(C11:C16) -> 27793.37 | D10: =sum(D11:D16) -> 28794.1 | E10: =sum(E11:E16) -> 32011.86 | F10: =sum(F11:F16) -> 33804.54 | G10: =sum(G11:G16) -> 25939.48 | H10: =sum(H11:H16) -> 26740.41 | I10: =sum(I11:I16) -> 28657.92 | ... AF10: =sum(AF11:AF16) -> 35862.51
A11: - Hardware | B11: 12382.12 | C11: 11605 | D11: 12358.05 | E11: 17039.5 | F11: 16960.2 | G11: 14331.3 | H11: 15021 | I11: 17465.6 | J11: 15843.6 | K11: 15047.7 | L11: 25198.6 | M11: 21421.2 | N11: 13093.4 | O11: 15569 | P11: 11748.6 | Q11: 9660.4 | R11: 14207.3 | S11: 20091.2 | T11: 18290.8 | U11: 17758.2 | V11: 19615.8 | W11: 19700.65 | X11: 26633.35 | Y11: 24376.1 | Z11: 23492.55 | AA11: 29612 | AB11: 24275.15 | AC11: 30845.5 | AD11: 26298.85 | AE11: 29790.65 | AF11: 26643.65
A12: - Add-ons | B12: 11484.08 | C12: 8466.2 | D12: 8023.15 | E12: 7842.2 | F12: 9018.4 | G12: 5711.4 | H12: 5676 | I12: 5167.6 | J12: 6817.4 | K12: 6827.9 | L12: 5878.7 | M12: 8233.4 | N12: 4279.4 | O12: 5128.8 | P12: 2789 | Q12: 3011.45 | R12: 3294.1 | S12: 5084.2 | T12: 5376.3 | U12: 3963.2 | V12: 3463.4 | W12: 4752.1 | X12: 6272.2 | Y12: 7388 | Z12: 8210.3 | AA12: 9821.9 | AB12: 5451 | AC12: 4807.1 | AD12: 4501 | AE12: 3853.8 | AF12: 3031
A13: - Merch | B13: 0 | C13: 0 | D13: 0 | E13: 0 | F13: 0 | G13: 0 | H13: 0 | I13: 0 | J13: 0 | K13: 39.99 | L13: 0 | M13: 0 | N13: 39.99 | O13: 0 | P13: 0 | Q13: 0 | R13: 0 | S13: 39.99 | T13: 109.96 | U13: 0 | V13: 0 | W13: 0 | X13: 29.99 | Y13: 39.99 | Z13: 0 | AA13: 0 | AB13: 0 | AC13: 0 | AD13: 0 | AE13: 0 | AF13: 0
A14: - Seeds | B14: 657 | C14: 454.4 | D14: 756.5 | E14: 596.9 | F14: 586.1 | G14: 335.6 | H14: 409.5 | I14: 331.8 | J14: 766.4 | K14: 549.2 | L14: 564.2 | M14: 497.5 | N14: 285.2 | O14: 499.3 | P14: 646.1 | Q14: 589 | R14: 606 | S14: 566.3 | T14: 336.9 | U14: 340.9 | V14: 505.3 | W14: 269.1 | X14: 330 | Y14: 421.5 | Z14: 501.5 | AA14: 466.6 | AB14: 508.1 | AC14: 316.9 | AD14: 440.6 | AE14: 354.9 | AF14: 432.6
A15: - Taxes | B15: 4928.35 | C15: 4728.89 | D15: 5167.52 | E15: 3607.16 | F15: 3951.86 | G15: 3241.54 | H15: 3330.51 | I15: 3154.94 | J15: 3108.9 | K15: 2659.86 | L15: 2968.59 | M15: 3272.94 | N15: 2470.75 | O15: 3150.53 | P15: 2324.83 | Q15: 2192.58 | R15: 2529.88 | S15: 2944.25 | T15: 3115.64 | U15: 2330.51 | V15: 2248.45 | W15: 2185.37 | X15: 2894.57 | Y15: 2533.08 | Z15: 2792.62 | AA15: 3116.51 | AB15: 2429.6 | AC15: 2855.81 | AD15: 2474.51 | AE15: 2606.27 | AF15: 2286.52
A16: - Shipping | B16: 3061.7 | C16: 2538.88 | D16: 2488.88 | E16: 2926.1 | F16: 3287.98 | G16: 2319.64 | H16: 2303.4 | I16: 2537.98 | J16: 2571.22 | K16: 2510.46 | L16: 3062.42 | M16: 3165.2 | N16: 1911.06 | O16: 2320.46 | P16: 1561.36 | Q16: 1493.84 | R16: 1946.7 | S16: 2842.96 | T16: 2637.68 | U16: 2448.57 | V16: 2457.38 | W16: 2668.85 | X16: 3572.8 | Y16: 3348.64 | Z16: 3455.88 | AA16: 4327.47 | AB16: 3476.34 | AC16: 4229.42 | AD16: 3662.69 | AE16: 3989.72 | AF16: 3468.74
A17: - DTC Revenue EU | B17: =SUM(B18:B23) -> 2141.9635 | C17: =SUM(C18:C23) -> 1323.3695 | D17: =SUM(D18:D23) -> 1988.7311 | E17: =SUM(E18:E23) -> 1192.1166 | F17: =SUM(F18:F23) -> 1205.1182 | G17: =SUM(G18:G23) -> 3051.0134 | H17: =SUM(H18:H23) -> 3347.4632 | I17: =SUM(I18:I23) -> 2946.463 | ... AF17: =SUM(AF18:AF23) -> 1516.1459
A18: - Hardware | B18: ='DTC EU - P&L'!B15*B$121 -> 975.37473 | C18: ='DTC EU - P&L'!C15*C$121 -> 257.94352 | D18: ='DTC EU - P&L'!D15*D$121 -> 715.93122 | E18: ='DTC EU - P&L'!E15*E$121 -> 462.44835 | F18: ='DTC EU - P&L'!F15*F$121 -> 511.41654 | G18: ='DTC EU - P&L'!G15*G$121 -> 1724.0245 | H18: ='DTC EU - P&L'!H15*H$121 -> 2031.272 | I18: ='DTC EU - P&L'!I15*I$121 -> 1662.4814 | ... AF18: ='DTC EU - P&L'!AF15*AF$121 -> 799.06035
A19: - Add-ons | B19: ='DTC EU - P&L'!B16*B$121 -> 50.171297 | C19: ='DTC EU - P&L'!C16*C$121 -> 155.47857 | D19: ='DTC EU - P&L'!D16*D$121 -> 316.19686 | E19: ='DTC EU - P&L'!E16*E$121 -> 230.62614 | F19: ='DTC EU - P&L'!F16*F$121 -> 0 | G19: ='DTC EU - P&L'!G16*G$121 -> 157.97735 | H19: ='DTC EU - P&L'!H16*H$121 -> 140.83356 | I19: ='DTC EU - P&L'!I16*I$121 -> 92.089542 | ... AF19: ='DTC EU - P&L'!AF16*AF$121 -> 268.08524
A20: - Merch | B20: ='DTC EU - P&L'!B17*B$121 -> 0 | C20: ='DTC EU - P&L'!C17*C$121 -> 0 | D20: ='DTC EU - P&L'!D17*D$121 -> 0 | E20: ='DTC EU - P&L'!E17*E$121 -> 0 | F20: ='DTC EU - P&L'!F17*F$121 -> 0 | G20: ='DTC EU - P&L'!G17*G$121 -> 0 | H20: ='DTC EU - P&L'!H17*H$121 -> 0 | I20: ='DTC EU - P&L'!I17*I$121 -> 0 | ... AF20: ='DTC EU - P&L'!AF17*AF$121 -> 0
A21: - Seeds | B21: ='DTC EU - P&L'!B18*B$121 -> 0 | C21: ='DTC EU - P&L'!C18*C$121 -> 0 | D21: ='DTC EU - P&L'!D18*D$121 -> 0 | E21: ='DTC EU - P&L'!E18*E$121 -> 0 | F21: ='DTC EU - P&L'!F18*F$121 -> 0 | G21: ='DTC EU - P&L'!G18*G$121 -> 0 | H21: ='DTC EU - P&L'!H18*H$121 -> 0 | I21: ='DTC EU - P&L'!I18*I$121 -> 0 | ... AF21: ='DTC EU - P&L'!AF18*AF$121 -> 0
A22: - Taxes | B22: ='DTC EU - P&L'!B20*B$121 -> 1002.5565 | C22: ='DTC EU - P&L'!C20*C$121 -> 853.48444 | D22: ='DTC EU - P&L'!D20*D$121 -> 827.70299 | E22: ='DTC EU - P&L'!E20*E$121 -> 406.24309 | F22: ='DTC EU - P&L'!F20*F$121 -> 642.17669 | G22: ='DTC EU - P&L'!G20*G$121 -> 1002.8836 | H22: ='DTC EU - P&L'!H20*H$121 -> 921.92969 | I22: ='DTC EU - P&L'!I20*I$121 -> 1001.0276 | ... AF22: ='DTC EU - P&L'!AF20*AF$121 -> 277.89526
A23: - Shipping | B23: ='DTC EU - P&L'!B21*B$121 -> 113.861 | C23: ='DTC EU - P&L'!C21*C$121 -> 56.463 | D23: ='DTC EU - P&L'!D21*D$121 -> 128.9 | E23: ='DTC EU - P&L'!E21*E$121 -> 92.799 | F23: ='DTC EU - P&L'!F21*F$121 -> 51.525 | G23: ='DTC EU - P&L'!G21*G$121 -> 166.128 | H23: ='DTC EU - P&L'!H21*H$121 -> 253.428 | I23: ='DTC EU - P&L'!I21*I$121 -> 190.8645 | ... AF23: ='DTC EU - P&L'!AF21*AF$121 -> 171.105
A24: - Yearly Premium Subscription | B24: =sum(B25:B26) -> 103735.26 | C24: =sum(C25:C26) -> 122108.78 | D24: =sum(D25:D26) -> 120668.38 | E24: =sum(E25:E26) -> 66404.582 | F24: =sum(F25:F26) -> 68547.074 | G24: =sum(G25:G26) -> 61251.662 | H24: =sum(H25:H26) -> 60251.16 | I24: =sum(I25:I26) -> 56410.664 | ... AF24: =sum(AF25:AF26) -> 3054.8346
A25: - Yearly Premium Subscription US&CA | B25: 100033.13 | C25: 118465.39 | D25: 117907.14 | E25: 65256.05 | F25: 66072.06 | G25: 58560.98 | H25: 58317.96 | I25: 53727.14 | J25: 54178.9 | K25: 41571.93 | L25: 36487.14 | M25: 44013.65 | N25: 51106.81 | O25: 59033.86 | P25: 48894.56 | Q25: 45313.83 | R25: 38832.72 | S25: 33186.35 | T25: 39257.71 | U25: 26192.68 | V25: 14413.74 | W25: 9013.77 | X25: 7115.38 | Y25: 8639.03 | Z25: 13258.44 | AA25: 5567.19 | AB25: 4499.49 | AC25: 2689.69 | AD25: 2535.45 | AE25: 2376.81 | AF25: 2977.07
A26: - Yearly Premium Subscription EU | B26: ='DTC EU - P&L'!B19*B$121 -> 3702.1283 | C26: ='DTC EU - P&L'!C19*C$121 -> 3643.3931 | D26: ='DTC EU - P&L'!D19*D$121 -> 2761.2442 | E26: ='DTC EU - P&L'!E19*E$121 -> 1148.532 | F26: ='DTC EU - P&L'!F19*F$121 -> 2475.0137 | G26: ='DTC EU - P&L'!G19*G$121 -> 2690.6818 | H26: ='DTC EU - P&L'!H19*H$121 -> 1933.2005 | I26: ='DTC EU - P&L'!I19*I$121 -> 2683.5239 | ... AF26: ='DTC EU - P&L'!AF19*AF$121 -> 77.76463
A27: Amazon Revenue | B27: =B28+B29+B30+B31+B32 -> 20026.6 | C27: =C28+C29+C30+C31+C32 -> 28799.1 | D27: =D28+D29+D30+D31+D32 -> 23958 | E27: =E28+E29+E30+E31+E32 -> 28901.2 | F27: =F28+F29+F30+F31+F32 -> 29312.82 | G27: =G28+G29+G30+G31+G32 -> 25501.91 | H27: =H28+H29+H30+H31+H32 -> 23405.2 | I27: =I28+I29+I30+I31+I32 -> 29757.41 | ... AF27: =AF28+AF29+AF30+AF31+AF32 -> 23985.36
A28: - Hardware | B28: 16658.38 | C28: 25109.18 | D28: 20102.12 | E28: 23515.24 | F28: 24193.24 | G28: 21565.68 | H28: 19505.8 | I28: 25763.36 | J28: 23692.88 | K28: 21093.8 | L28: 28339.16 | M28: 26259.68 | N28: 19194.12 | O28: 17921.5 | P28: 14673.5 | Q28: 16446.8 | R28: 16779.62 | S28: 17801.8 | T28: 18526.12 | U28: 16525.36 | V28: 15597.6 | W28: 20251.58 | X28: 21065.76 | Y28: 19099.52 | Z28: 26332.28 | AA28: 24356.52 | AB28: 15515.9 | AC28: 18065.38 | AD28: 15675.9 | AE28: 15016.14 | AF28: 19312.9
A29: - Add-ons | B29: 2039 | C29: 1737.3 | D29: 2205.78 | E29: 3405.26 | F29: 3165.26 | G29: 2260.2 | H29: 2355.66 | I29: 2145.84 | J29: 1430.02 | K29: 3003.28 | L29: 3697.26 | M29: 5641.26 | N29: 3363.66 | O29: 4035.66 | P29: 3239.48 | Q29: 3437.9 | R29: 3682.84 | S29: 4599.84 | T29: 4585.14 | U29: 3954.16 | V29: 2494.6 | W29: 2898.78 | X29: 1692.54 | Y29: 1894.2 | Z29: 1776.32 | AA29: 2344.56 | AB29: 2034.22 | AC29: 2820.1 | AD29: 2042 | AE29: 2263.12 | AF29: 3106.88
A30: - Tax | B30: 1328.82 | C30: 1939.15 | D30: 1627.42 | E30: 1940.02 | F30: 1939.6 | G30: 1638.52 | H30: 1533.51 | I30: 1826.25 | J30: 1687.66 | K30: 1593.8 | L30: 2131.74 | M30: 2157.87 | N30: 1623.16 | O30: 1551.46 | P30: 1265.16 | Q30: 1313.16 | R30: 1415.97 | S30: 1612.58 | T30: 1638.57 | U30: 1360.17 | V30: 1174.01 | W30: 1532.1 | X30: 1561.91 | Y30: 1392.98 | Z30: 1959.39 | AA30: 1797.54 | AB30: 1216.92 | AC30: 1404.38 | AD30: 1280.3 | AE30: 1171.66 | AF30: 1559.59
A31: - Shipping | B31: 0.25 | C31: 12.47 | D31: 17.85 | E31: 31.02 | F31: 5.06 | G31: 28.02 | H31: 0.4 | I31: 7.47 | J31: 0.66 | K31: 4.92 | L31: 0.88 | M31: 17.6 | N31: 0.16 | O31: 7.4 | P31: 25.38 | Q31: 23.13 | R31: 9.82 | S31: 46.82 | T31: 18.62 | U31: 2.7 | V31: 3.79 | W31: 1.49 | X31: 31.69 | Y31: 12.82 | Z31: 22.47 | AA31: 7.99 | AB31: 8.24 | AC31: 7.49 | AD31: 1.25 | AE31: 0.75 | AF31: 1.25
A32: - Gift Wrap | B32: 0.15 | C32: 1 | D32: 4.83 | E32: 9.66 | F32: 9.66 | G32: 9.49 | H32: 9.83 | I32: 14.49 | J32: 14.11 | K32: 21.95 | L32: 6.36 | M32: 5.98 | N32: 4.83 | O32: 22.44 | P32: 4.98 | Q32: 0.85 | R32: 0.83 | S32: 27.79 | T32: 9.32 | U32: 5.66 | V32: 10.68 | W32: 18.72 | X32: 13.77 | Y32: 5.09 | Z32: 27.84 | AA32: 5.09 | AB32: 9.73 | AC32: 22.75 | AD32: 5.24 | AE32: 0.45 | AF32: 4.74
A33: Total Revenue | B33: =SUM(B9+B27) -> 158417.07 | C33: =SUM(C9+C27) -> 180024.62 | D33: =SUM(D9+D27) -> 175409.22 | E33: =SUM(E9+E27) -> 128509.76 | F33: =SUM(F9+F27) -> 132869.55 | G33: =SUM(G9+G27) -> 115744.07 | H33: =SUM(H9+H27) -> 113744.23 | I33: =SUM(I9+I27) -> 117772.46 | ... AF33: =SUM(AF9+AF27) -> 64418.85
A35: B2B Revenue
A36: RETAIL Revenue
A37: Best Buy | B37: =iferror(sum(B38:B40),"") -> 910.67059 | C37: =iferror(sum(C38:C40),"") -> 1799.0624 | D37: =iferror(sum(D38:D40),"") -> 2687.4542 | E37: =iferror(sum(E38:E40),"") -> 0 | F37: =iferror(sum(F38:F40),"") -> 0 | G37: =iferror(sum(G38:G40),"") -> 2665.1754 | H37: =iferror(sum(H38:H40),"") -> 2961.306 | I37: =iferror(sum(I38:I40),"") -> 1776.7836 | ... AF37: =iferror(sum(AF38:AF40),"") -> 0
A38: - Hardware | B38: 857.99 | C38: 1694.99 | D38: 2531.99 | E38: 0 | F38: 0 | G38: 2511 | H38: 2790 | I38: 1674 | J38: 1395 | K38: 1415.99 | L38: 837 | M38: 0 | N38: 279 | O38: 837 | P38: 2531.99 | Q38: 1694.99 | R38: 279 | S38: 279 | T38: 0 | U38: 558 | V38: 0 | W38: 837 | X38: 1395 | Y38: 558 | Z38: 558 | AA38: 0 | AB38: 837 | AC38: 558 | AD38: 837 | AE38: 279 | AF38: 0
A39: - Tax | B39: =B38*'Data - P&L'!$U$3 -> 52.680586 | C39: =C38*'Data - P&L'!$U$3 -> 104.07239 | D39: =D38*'Data - P&L'!$U$3 -> 155.46419 | E39: =E38*'Data - P&L'!$U$3 -> 0 | F39: =F38*'Data - P&L'!$U$3 -> 0 | G39: =G38*'Data - P&L'!$U$3 -> 154.1754 | H39: =H38*'Data - P&L'!$U$3 -> 171.306 | I39: =I38*'Data - P&L'!$U$3 -> 102.7836 | ... AF39: =AF38*'Data - P&L'!$U$3 -> 0
A40: - Shipping
A41: Target | B41: =sum(B42:B44) -> 4887.747 | C41: =sum(C42:C44) -> 4781.607 | D41: =sum(D42:D44) -> 3887.9082 | E41: =sum(E42:E44) -> 7842.6846 | F41: =sum(F42:F44) -> 4855.905 | G41: =sum(G42:G44) -> 3156.6036 | H41: =sum(H42:H44) -> 4675.467 | I41: =sum(I42:I44) -> 4370.8452 | ... AF41: =sum(AF42:AF44) -> 2908.236
A42: - Hardware | B42: 4605 | C42: 4505 | D42: 3663 | E42: 7389 | F42: 4575 | G42: 2974 | H42: 4405 | I42: 4118 | J42: 4635 | K42: 3906 | L42: 6774 | M42: 2995 | N42: 3529 | O42: 2169 | P42: 4077 | Q42: 1763 | R42: 2815 | S42: 4743 | T42: 2597 | U42: 1929 | V42: 1622 | W42: 280 | X42: 1376 | Y42: 1330 | Z42: 2936 | AA42: 2384 | AB42: 1072 | AC42: 714 | AD42: 1202 | AE42: 520 | AF42: 2740
A43: - Tax | B43: =B42*'Data - P&L'!$U$3 -> 282.747 | C43: =C42*'Data - P&L'!$U$3 -> 276.607 | D43: =D42*'Data - P&L'!$U$3 -> 224.9082 | E43: =E42*'Data - P&L'!$U$3 -> 453.6846 | F43: =F42*'Data - P&L'!$U$3 -> 280.905 | G43: =G42*'Data - P&L'!$U$3 -> 182.6036 | H43: =H42*'Data - P&L'!$U$3 -> 270.467 | I43: =I42*'Data - P&L'!$U$3 -> 252.8452 | ... AF43: =AF42*'Data - P&L'!$U$3 -> 168.236
A44: - Shipping
A45: Costco | B45: =SUM(B46:B48) -> 0 | C45: =SUM(C46:C48) -> 0 | D45: =SUM(D46:D48) -> 0 | E45: =SUM(E46:E48) -> 0 | F45: =SUM(F46:F48) -> 0 | G45: =SUM(G46:G48) -> 0 | H45: =SUM(H46:H48) -> 0 | I45: =SUM(I46:I48) -> 0 | ... AF45: =SUM(AF46:AF48) -> 1188.7255
...

Sheet DTC - P&L
A1: JANUARY | B1: 45658 | C1: 45659 | D1: 45660 | E1: 45661 | F1: 45662 | G1: 45663 | H1: 45664 | I1: 45665 | J1: 45666 | K1: 45667 | L1: 45668 | M1: 45669 | N1: 45670 | O1: 45671 | P1: 45672 | Q1: 45673 | R1: 45674 | S1: 45675 | T1: 45676 | U1: 45677 | V1: 45678 | W1: 45679 | X1: 45680 | Y1: 45681 | Z1: 45682 | AA1: 45683 | AB1: 45684 | AC1: 45685 | AD1: 45686 | AE1: 45687 | AF1: 45688
A2: DAY | B2: WED | C2: THU | D2: FRI | E2: SAT | F2: SUN | G2: MON | H2: TUE | I2: WED | J2: THU | K2: FRI | L2: SAT | M2: SUN | N2: MON | O2: TUE | P2: WED | Q2: THU | R2: FRI | S2: SAT | T2: SUN | U2: MON | V2: TUE | W2: WED | X2: THU | Y2: FRI | Z2: SAT | AA2: SUN | AB2: MON | AC2: TUE | AD2: WED | AE2: THU | AF2: FRI
A3: COMMENT
A4: Orders
A5: Meta | B5: 265 | C5: 288 | D5: 261 | E5: 149 | F5: 199 | G5: 149 | H5: 116 | I5: 122 | J5: 114 | K5: 108 | L5: 75 | M5: 114 | N5: 130 | O5: 145 | P5: 126 | Q5: 63 | R5: 76 | S5: 83 | T5: 140 | U5: 136 | V5: 92 | W5: 79 | X5: 100 | Y5: 106 | Z5: 126 | AA5: 134 | AB5: 61 | AC5: 97 | AD5: 26 | AE5: 110 | AF5: 78 | AG5: =SUM(B5:AF5) -> 3868
A6: Google | B6: 89 | C6: 76 | D6: 68 | E6: 62 | F6: 76 | G6: 58 | H6: 49 | I6: 54 | J6: 58 | K6: 56 | L6: 56 | M6: 70 | N6: 38 | O6: 52 | P6: 29 | Q6: 35 | R6: 39 | S6: 50 | T6: 53 | U6: 32 | V6: 47 | W6: 54 | X6: 59 | Y6: 53 | Z6: 68 | AA6: 77 | AB6: 59 | AC6: 57 | AD6: 48 | AE6: 48 | AF6: 58 | AG6: =SUM(B6:AF6) -> 1728
A7: TikTok | B7: 0 | C7: 0 | D7: 0 | E7: 0 | F7: 0 | G7: 0 | H7: 0 | I7: 0 | J7: 0 | K7: 0 | L7: 0 | M7: 0 | N7: 0 | O7: 0 | P7: 0 | Q7: 0 | R7: 0 | S7: 0 | T7: 0 | U7: 0 | V7: 0 | W7: 0 | X7: 0 | Y7: 0 | Z7: 0 | AA7: 0 | AB7: 0 | AC7: 0 | AD7: 0 | AE7: 0 | AF7: 0 | AG7: =SUM(B7:AF7) -> 0
A8: Bing | B8: 14 | C8: 12 | D8: 18 | E8: 18 | F8: 34 | G8: 10 | H8: 12 | I8: 8 | J8: 28 | K8: 16 | L8: 26 | M8: 16 | N8: 12 | O8: 18 | P8: 10 | Q8: 10 | R8: 8 | S8: 18 | T8: 6 | U8: 10 | V8: 8 | W8: 2 | X8: 12 | Y8: 18 | Z8: 20 | AA8: 22 | AB8: 24 | AC8: 22 | AD8: 8 | AE8: 20 | AF8: 18 | AG8: =SUM(B8:AF8) -> 478
A9: Email | B9: 0 | C9: 1 | D9: 0 | E9: 0 | F9: 0 | G9: 0 | H9: 0 | I9: 0 | J9: 0 | K9: 0 | L9: 0 | M9: 0 | N9: 0 | O9: 0 | P9: 0 | Q9: 0 | R9: 0 | S9: 0 | T9: 0 | U9: 0 | V9: 0 | W9: 0 | X9: 0 | Y9: 0 | Z9: 0 | AA9: 0 | AB9: 0 | AC9: 0 | AD9: 0 | AE9: 0 | AF9: 0 | AG9: =SUM(B9:AF9) -> 1
A10: Nextdoor | B10: - | C10: - | D10: - | E10: - | F10: - | G10: - | H10: - | I10: - | J10: - | K10: - | L10: - | M10: - | N10: - | O10: - | P10: - | Q10: - | R10: - | S10: - | T10: - | U10: - | V10: - | W10: - | X10: - | Y10: - | Z10: - | AA10: - | AB10: - | AC10: - | AD10: - | AE10: - | AF10: - | AG10: =SUM(B10:AF10) -> 0
A11: Affiliates (Refersion) | B11: - | C11: - | D11: - | E11: - | F11: - | G11: - | H11: - | I11: - | J11: - | K11: - | L11: - | M11: - | N11: - | O11: - | P11: - | Q11: - | R11: - | S11: - | T11: - | U11: - | V11: - | W11: - | X11: - | Y11: - | Z11: - | AA11: - | AB11: - | AC11: - | AD11: - | AE11: - | AF11: - | AG11: =SUM(B11:AF11) -> 0
A12: All | B12: =SUM(B5:B11) -> 368 | C12: =SUM(C5:C11) -> 377 | D12: =SUM(D5:D11) -> 347 | E12: =SUM(E5:E11) -> 229 | F12: =SUM(F5:F11) -> 309 | G12: =SUM(G5:G11) -> 217 | H12: =SUM(H5:H11) -> 177 | I12: =SUM(I5:I11) -> 184 | ... AF12: =SUM(AF5:AF11) -> 154 | AG12: =SUM(B12:AF12) -> 6075
A14: Revenue | B14: 24151.74 | C14: 25955.47 | D14: 25319.02 | E14: 14224.63 | F14: 19860.05 | G14: 15692.06 | H14: 11951.66 | I14: 12862.92 | J14: 11618.75 | K14: 11146.34 | L14: 8520.56 | M14: 14015.63 | N14: 13865.49 | O14: 14099.99 | P14: 12808.42 | Q14: 6710.56 | R14: 10173.04 | S14: 10870.09 | T14: 17827.86 | U14: 15012.41 | V14: 13250.44 | W14: 12235.65 | X14: 18145.52 | Y14: 21256.28 | Z14: 21105.78 | AA14: 25560.15 | AB14: 11697.2 | AC14: 20252.82 | AD14: 5772.79 | AE14: 25336.04 | AF14: 16132.94
A15: Meta | B15: =B14*Summary!B121 -> 24999.466 | C15: =C14*Summary!C121 -> 26645.886 | D15: =D14*Summary!D121 -> 26108.973 | E15: =E14*Summary!E121 -> 14667.016 | F15: =F14*Summary!F121 -> 20465.782 | G15: =G14*Summary!G121 -> 16293.066 | H15: =H14*Summary!H121 -> 12362.797 | I15: =I14*Summary!I121 -> 13270.675 | ... AF15: =AF14*Summary!AF121 -> 16729.859 | AG15: =SUM(B15:AF15) -> 504957.64
A16: Google | B16: 10827.24 | C16: 12049.75 | D16: 9180.54 | E16: 8951.08 | F16: 12049.75 | G16: 9872.94 | H16: 7522.21 | I16: 11202.75 | J16: 10186.53 | K16: 9906.13 | L16: 13712.91 | M16: 13635.17 | N16: 6524.74 | O16: 10388.91 | P16: 6395.6 | Q16: 5748.06 | R16: 7677.03 | S16: 10739.94 | T16: 11907.65 | U16: 7155.26 | V16: 10141.65 | W16: 14230.8 | X16: 15392.32 | Y16: 12961.39 | Z16: 15375.1 | AA16: 15147.65 | AB16: 11275.41 | AC16: 12318.62 | AD16: 10566.51 | AE16: 10566.51 | AF16: 12724.01 | AG16: =SUM(B16:AF16) -> 336334.16
A17: TikTok | B17: 0 | C17: 0 | D17: 0 | E17: 0 | F17: 0 | G17: 0 | H17: 0 | I17: 0 | J17: 0 | K17: 0 | L17: 0 | M17: 0 | N17: 0 | O17: 0 | P17: 0 | Q17: 0 | R17: 0 | S17: 0 | T17: 0 | U17: 0 | V17: 0 | W17: 0 | X17: 0 | Y17: 0 | Z17: 0 | AA17: 0 | AB17: 0 | AC17: 0 | AD17: 0 | AE17: 0 | AF17: 0 | AG17: =SUM(B17:AF17) -> 0
A18: Bing | B18: 1757 | C18: 1506 | D18: 2259 | E18: 2259 | F18: 4267 | G18: 1255 | H18: 1506 | I18: 1004 | J18: 3514 | K18: 2008 | L18: 3263 | M18: 2008 | N18: 1506 | O18: 2259 | P18: 1255 | Q18: 1255 | R18: 1004 | S18: 2259 | T18: 753 | U18: 1255 | V18: 1004 | W18: 251 | X18: 1506 | Y18: 2259 | Z18: 2510 | AA18: 2761 | AB18: 3012 | AC18: 2761 | AD18: 1004 | AE18: 2510 | AF18: 2259 | AG18: =SUM(B18:AF18) -> 59989
A19: Email | B19: 0 | C19: 41.08 | D19: 0 | E19: 0 | F19: 0 | G19: 0 | H19: 0 | I19: 0 | J19: 0 | K19: 0 | L19: 0 | M19: 0 | N19: 0 | O19: 0 | P19: 0 | Q19: 0 | R19: 0 | S19: 0 | T19: 0 | U19: 0 | V19: 0 | W19: 0 | X19: 0 | Y19: 0 | Z19: 0 | AA19: 0 | AB19: 0 | AC19: 0 | AD19: 0 | AE19: 0 | AF19: 0 | AG19: =SUM(B19:AF19) -> 41.08
A20: Nextdoor | B20: - | C20: - | D20: - | E20: - | F20: - | G20: - | H20: - | I20: - | J20: - | K20: - | L20: - | M20: - | N20: - | O20: - | P20: - | Q20: - | R20: - | S20: - | T20: - | U20: - | V20: - | W20: - | X20: - | Y20: - | Z20: - | AA20: - | AB20: - | AC20: - | AD20: - | AE20: - | AF20: -
A21: Affiliates (Refersion) | B21: - | C21: - | D21: - | E21: - | F21: - | G21: - | H21: - | I21: - | J21: - | K21: - | L21: - | M21: - | N21: - | O21: - | P21: - | Q21: - | R21: - | S21: - | T21: - | U21: - | V21: - | W21: - | X21: - | Y21: - | Z21: - | AA21: - | AB21: - | AC21: - | AD21: - | AE21: - | AF21: -
A22: All | B22: =SUM(B15:B21) -> 37583.706 | C22: =SUM(C15:C21) -> 40242.715 | D22: =SUM(D15:D21) -> 37548.513 | E22: =SUM(E15:E21) -> 25877.096 | F22: =SUM(F15:F21) -> 36782.532 | G22: =SUM(G15:G21) -> 27421.006 | H22: =SUM(H15:H21) -> 21391.007 | I22: =SUM(I15:I21) -> 25477.425 | ... AF22: =SUM(AF15:AF21) -> 31712.869 | AG22: =SUM(B22:AF22) -> 901321.88
A24: Media Cost
A25: Meta | B25: =Summary!B122 -> 4984.317 | C25: =Summary!C122 -> 5399.0434 | D25: =Summary!D122 -> 3918.065 | E25: =Summary!E122 -> 4578.5789 | F25: =Summary!F122 -> 5201.3869 | G25: =Summary!G122 -> 5126.9904 | H25: =Summary!H122 -> 5048.4409 | I25: =Summary!I122 -> 4964.7674 | ... AF25: =Summary!AF122 -> 18145.063 | AG25: =SUM(B25:AF25) -> 467833.8
A26: Google | B26: =Summary!B125 -> 3103.99 | C26: =Summary!C125 -> 2165.06 | D26: =Summary!D125 -> 2128.43 | E26: =Summary!E125 -> 2232.05 | F26: =Summary!F125 -> 2200.78 | G26: =Summary!G125 -> 1922.34 | H26: =Summary!H125 -> 2967.68 | I26: =Summary!I125 -> 4036.71 | ... AF26: =Summary!AF125 -> 2301.88 | AG26: =SUM(B26:AF26) -> 70865.77
A27: TikTok | B27: =Summary!B129 -> 0 | C27: =Summary!C129 -> 0 | D27: =Summary!D129 -> 0 | E27: =Summary!E129 -> 0 | F27: =Summary!F129 -> 0 | G27: =Summary!G129 -> 0 | H27: =Summary!H129 -> 0 | I27: =Summary!I129 -> 0 | ... AF27: =Summary!AF129 -> 0 | AG27: =SUM(B27:AF27) -> 0
A28: Bing | B28: =Summary!B128 -> 166.94 | C28: =Summary!C128 -> 194.55 | D28: =Summary!D128 -> 172.16 | E28: =Summary!E128 -> 183.21 | F28: =Summary!F128 -> 210.95 | G28: =Summary!G128 -> 220.19 | H28: =Summary!H128 -> 327.79 | I28: =Summary!I128 -> 331.77 | ... AF28: =Summary!AF128 -> 155.29 | AG28: =SUM(B28:AF28) -> 6300.77
A29: Nextdoor | B29: - | C29: - | D29: - | E29: - | F29: - | G29: - | H29: - | I29: - | J29: - | K29: - | L29: - | M29: - | N29: - | O29: - | P29: - | Q29: - | R29: - | S29: - | T29: - | U29: - | V29: - | W29: - | X29: - | Y29: - | Z29: - | AA29: - | AB29: - | AC29: - | AD29: - | AE29: - | AF29: - | AG29: =SUM(B29:AF29) -> 0
A30: Affiliate Fee (20%) | B30: - | C30: - | D30: - | E30: - | F30: - | G30: - | H30: - | I30: - | J30: - | K30: - | L30: - | M30: - | N30: - | O30: - | P30: - | Q30: - | R30: - | S30: - | T30: - | U30: - | V30: - | W30: - | X30: - | Y30: - | Z30: - | AA30: - | AB30: - | AC30: - | AD30: - | AE30: - | AF30: - | AG30: =SUM(B30:AF30) -> 0
A31: All | B31: =SUM(B25:B30) -> 8255.247 | C31: =SUM(C25:C30) -> 7758.6534 | D31: =SUM(D25:D30) -> 6218.655 | E31: =SUM(E25:E30) -> 6993.8389 | F31: =SUM(F25:F30) -> 7613.1169 | G31: =SUM(G25:G30) -> 7269.5204 | H31: =SUM(H25:H30) -> 8343.9109 | I31: =SUM(I25:I30) -> 9333.2474 | ... AF31: =SUM(AF25:AF30) -> 20602.233 | AG31: =SUM(B31:AF31) -> 545000.34
A36: Revenue
A37: Revenue Woocommerce (Platform) | B37: =Summary!B9 -> 138390.47 | C37: =Summary!C9 -> 151225.52 | D37: =Summary!D9 -> 151451.22 | E37: =Summary!E9 -> 99608.559 | F37: =Summary!F9 -> 103556.73 | G37: =Summary!G9 -> 90242.155 | H37: =Summary!H9 -> 90339.034 | I37: =Summary!I9 -> 88015.047 | ... AF37: =Summary!AF9 -> 40433.49 | AG37: =SUM(B37:AF37) -> 2320738.1
A38: Revenue w/o renewals | B38: ='DTC US&CA - P&L'!B6+'DTC EU - P&L'!B6 -> 30858.567 | C38: ='DTC US&CA - P&L'!C6+'DTC EU - P&L'!C6 -> 25074.981 | D38: ='DTC US&CA - P&L'!D6+'DTC EU - P&L'!D6 -> 26768.824 | E38: ='DTC US&CA - P&L'!E6+'DTC EU - P&L'!E6 -> 31316.638 | F38: ='DTC US&CA - P&L'!F6+'DTC EU - P&L'!F6 -> 32512.392 | G38: ='DTC US&CA - P&L'!G6+'DTC EU - P&L'!G6 -> 26553.964 | H38: ='DTC US&CA - P&L'!H6+'DTC EU - P&L'!H6 -> 27574.692 | I38: ='DTC US&CA - P&L'!I6+'DTC EU - P&L'!I6 -> 29490.513 | ... AF38: ='DTC US&CA - P&L'!AF6+'DTC EU - P&L'!AF6 -> 36952.031 | AG38: =SUM(B38:AF38) -> 999031.54
A39: SUM | B39: =SUM(B37) -> 138390.47 | C39: =SUM(C37) -> 151225.52 | D39: =SUM(D37) -> 151451.22 | E39: =SUM(E37) -> 99608.559 | F39: =SUM(F37) -> 103556.73 | G39: =SUM(G37) -> 90242.155 | H39: =SUM(H37) -> 90339.034 | I39: =SUM(I37) -> 88015.047 | ... AF39: =SUM(AF37) -> 40433.49 | AG39: =SUM(B39:AF39) -> 2320738.1
A41: Orders
A42: Orders Woocommerce (Platform) | B42: =Summary!B82 -> 1432 | C42: =Summary!C82 -> 1599 | D42: =Summary!D82 -> 1585 | E42: =Summary!E82 -> 972 | F42: =Summary!F82 -> 1040 | G42: =Summary!G82 -> 868 | H42: =Summary!H82 -> 855 | I42: =Summary!I82 -> 808 | ... AF42: =Summary!AF82 -> 213 | AG42: =SUM(B42:AF42) -> 20147
A43: Orders w/o renewals | B43: ='DTC US&CA - P&L'!B11+'DTC EU - P&L'!B11 -> 256 | C43: ='DTC US&CA - P&L'!C11+'DTC EU - P&L'!C11 -> 215 | D43: ='DTC US&CA - P&L'!D11+'DTC EU - P&L'!D11 -> 217 | E43: ='DTC US&CA - P&L'!E11+'DTC EU - P&L'!E11 -> 224 | F43: ='DTC US&CA - P&L'!F11+'DTC EU - P&L'!F11 -> 264 | G43: ='DTC US&CA - P&L'!G11+'DTC EU - P&L'!G11 -> 171 | H43: ='DTC US&CA - P&L'!H11+'DTC EU - P&L'!H11 -> 169 | I43: ='DTC US&CA - P&L'!I11+'DTC EU - P&L'!I11 -> 166 | ... AF43: ='DTC US&CA - P&L'!AF11+'DTC EU - P&L'!AF11 -> 168 | AG43: =SUM(B43:AF43) -> 5600
A44: SUM | B44: =SUM(B42) -> 1432 | C44: =SUM(C42) -> 1599 | D44: =SUM(D42) -> 1585 | E44: =SUM(E42) -> 972 | F44: =SUM(F42) -> 1040 | G44: =SUM(G42) -> 868 | H44: =SUM(H42) -> 855 | I44: =SUM(I42) -> 808 | ... AF44: =SUM(AF42) -> 213 | AG44: =SUM(B44:AF44) -> 20147
A46: Breakdown
A47: - Hardware | B47: =Summary!B11+Summary!B18 -> 13357.495 | C47: =Summary!C11+Summary!C18 -> 11862.944 | D47: =Summary!D11+Summary!D18 -> 13073.981 | E47: =Summary!E11+Summary!E18 -> 17501.948 | F47: =Summary!F11+Summary!F18 -> 17471.617 | G47: =Summary!G11+Summary!G18 -> 16055.324 | H47: =Summary!H11+Summary!H18 -> 17052.272 | I47: =Summary!I11+Summary!I18 -> 19128.081 | ... AF47: =Summary!AF11+Summary!AF18 -> 27442.71 | AG47: =SUM(B47:AF47) -> 634926.61
A48: - Add-ons | B48: =Summary!B12+Summary!B19 -> 11534.251 | C48: =Summary!C12+Summary!C19 -> 8621.6786 | D48: =Summary!D12+Summary!D19 -> 8339.3469 | E48: =Summary!E12+Summary!E19 -> 8072.8261 | F48: =Summary!F12+Summary!F19 -> 9018.4 | G48: =Summary!G12+Summary!G19 -> 5869.3773 | H48: =Summary!H12+Summary!H19 -> 5816.8336 | I48: =Summary!I12+Summary!I19 -> 5259.6895 | ... AF48: =Summary!AF12+Summary!AF19 -> 3299.0852 | AG48: =SUM(B48:AF48) -> 190893.33
...

Sheet DTC US&CA - P&L
A1: JANUARY | B1: 45658 | C1: 45659 | D1: 45660 | E1: 45661 | F1: 45662 | G1: 45663 | H1: 45664 | I1: 45665 | J1: 45666 | K1: 45667 | L1: 45668 | M1: 45669 | N1: 45670 | O1: 45671 | P1: 45672 | Q1: 45673 | R1: 45674 | S1: 45675 | T1: 45676 | U1: 45677 | V1: 45678 | W1: 45679 | X1: 45680 | Y1: 45681 | Z1: 45682 | AA1: 45683 | AB1: 45684 | AC1: 45685 | AD1: 45686 | AE1: 45687 | AF1: 45688
A2: DAY | B2: WED | C2: THU | D2: FRI | E2: SAT | F2: SUN | G2: MON | H2: TUE | I2: WED | J2: THU | K2: FRI | L2: SAT | M2: SUN | N2: MON | O2: TUE | P2: WED | Q2: THU | R2: FRI | S2: SAT | T2: SUN | U2: MON | V2: TUE | W2: WED | X2: THU | Y2: FRI | Z2: SAT | AA2: SUN | AB2: MON | AC2: TUE | AD2: WED | AE2: THU | AF2: FRI
A4: Revenue
A5: Revenue Woocommerce (Platform) | B5: =Summary!B10+Summary!B25 -> 132546.38 | C5: =Summary!C10+Summary!C25 -> 146258.76 | D5: =Summary!D10+Summary!D25 -> 146701.24 | E5: =Summary!E10+Summary!E25 -> 97267.91 | F5: =Summary!F10+Summary!F25 -> 99876.6 | G5: =Summary!G10+Summary!G25 -> 84500.46 | H5: =Summary!H10+Summary!H25 -> 85058.37 | I5: =Summary!I10+Summary!I25 -> 82385.06 | ... AF5: =Summary!AF10+Summary!AF25 -> 38839.58 | AG5: =SUM(B5:AF5) -> 2206917.3
A6: Revenue w/o renewals | B6: 29485.61 | C6: 24511.84 | D6: 25173.96 | E6: 30367.82 | F6: 31799.77 | G6: 24082.55 | H6: 24621.17 | I6: 27110.02 | J6: 27116.1 | K6: 26159.97 | L6: 36501.67 | M6: 35241.49 | N6: 20682.52 | O6: 24504.2 | P6: 17303.63 | Q6: 15406.99 | R6: 21226.42 | S6: 30312.73 | T6: 28726.92 | U6: 25841.5 | V6: 27741.67 | W6: 29196.67 | X6: 39397.46 | Y6: 37662 | Z6: 37828.24 | AA6: 47102.89 | AB6: 35699.31 | AC6: 42729.55 | AD6: 37147.37 | AE6: 40358.76 | AF6: 35451.44 | AG6: =SUM(B6:AF6) -> 936492.24
A7: SUM | B7: =SUM(B5) -> 132546.38 | C7: =SUM(C5) -> 146258.76 | D7: =SUM(D5) -> 146701.24 | E7: =SUM(E5) -> 97267.91 | F7: =SUM(F5) -> 99876.6 | G7: =SUM(G5) -> 84500.46 | H7: =SUM(H5) -> 85058.37 | I7: =SUM(I5) -> 82385.06 | ... AF7: =SUM(AF5) -> 38839.58 | AG7: =SUM(B7:AF7) -> 2206917.3
A9: Orders
A10: Orders Woocommerce (Platform) | B10: =Summary!B83 -> 1379 | C10: =Summary!C83 -> 1547 | D10: =Summary!D83 -> 1538 | E10: =Summary!E83 -> 953 | F10: =Summary!F83 -> 1005 | G10: =Summary!G83 -> 825 | H10: =Summary!H83 -> 820 | I10: =Summary!I83 -> 766 | ... AF10: =Summary!AF83 -> 203 | AG10: =SUM(B10:AF10) -> 19333
A11: Orders w/o renewals | B11: 251 | C11: 211 | D11: 205 | E11: 218 | F11: 261 | G11: 163 | H11: 158 | I11: 159 | J11: 174 | K11: 200 | L11: 171 | M11: 206 | N11: 123 | O11: 145 | P11: 92 | Q11: 101 | R11: 118 | S11: 158 | T11: 158 | U11: 136 | V11: 136 | W11: 142 | X11: 175 | Y11: 162 | Z11: 183 | AA11: 232 | AB11: 173 | AC11: 202 | AD11: 178 | AE11: 184 | AF11: 159 | AG11: =SUM(B11:AF11) -> 5334
A12: SUM | B12: =SUM(B10) -> 1379 | C12: =SUM(C10) -> 1547 | D12: =SUM(D10) -> 1538 | E12: =SUM(E10) -> 953 | F12: =SUM(F10) -> 1005 | G12: =SUM(G10) -> 825 | H12: =SUM(H10) -> 820 | I12: =SUM(I10) -> 766 | ... AF12: =SUM(AF10) -> 203 | AG12: =SUM(B12:AF12) -> 19333
A14: Breakdown
A15: - Hardware | B15: =Summary!B11 -> 12382.12 | C15: =Summary!C11 -> 11605 | D15: =Summary!D11 -> 12358.05 | E15: =Summary!E11 -> 17039.5 | F15: =Summary!F11 -> 16960.2 | G15: =Summary!G11 -> 14331.3 | H15: =Summary!H11 -> 15021 | I15: =Summary!I11 -> 17465.6 | ... AF15: =Summary!AF11 -> 26643.65 | AG15: =SUM(B15:AF15) -> 596377.02
A16: - Add-ons | B16: =Summary!B12 -> 11484.08 | C16: =Summary!C12 -> 8466.2 | D16: =Summary!D12 -> 8023.15 | E16: =Summary!E12 -> 7842.2 | F16: =Summary!F12 -> 9018.4 | G16: =Summary!G12 -> 5711.4 | H16: =Summary!H12 -> 5676 | I16: =Summary!I12 -> 5167.6 | ... AF16: =Summary!AF12 -> 3031 | AG16: =SUM(B16:AF16) -> 183624.68
A17: - Merch | B17: =Summary!B13 -> 0 | C17: =Summary!C13 -> 0 | D17: =Summary!D13 -> 0 | E17: =Summary!E13 -> 0 | F17: =Summary!F13 -> 0 | G17: =Summary!G13 -> 0 | H17: =Summary!H13 -> 0 | I17: =Summary!I13 -> 0 | ... AF17: =Summary!AF13 -> 0 | AG17: =SUM(B17:AF17) -> 299.91
A18: - Seeds | B18: =Summary!B14 -> 657 | C18: =Summary!C14 -> 454.4 | D18: =Summary!D14 -> 756.5 | E18: =Summary!E14 -> 596.9 | F18: =Summary!F14 -> 586.1 | G18: =Summary!G14 -> 335.6 | H18: =Summary!H14 -> 409.5 | I18: =Summary!I14 -> 331.8 | ... AF18: =Summary!AF14 -> 432.6 | AG18: =SUM(B18:AF18) -> 14921.9
A19: - Yearly Pro Subscription | B19: =Summary!B25 -> 100033.13 | C19: =Summary!C25 -> 118465.39 | D19: =Summary!D25 -> 117907.14 | E19: =Summary!E25 -> 65256.05 | F19: =Summary!F25 -> 66072.06 | G19: =Summary!G25 -> 58560.98 | H19: =Summary!H25 -> 58317.96 | I19: =Summary!I25 -> 53727.14 | ... AF19: =Summary!AF25 -> 2977.07 | AG19: =SUM(B19:AF19) -> 1229496.1
A20: - Taxes | B20: =Summary!B15 -> 4928.35 | C20: =Summary!C15 -> 4728.89 | D20: =Summary!D15 -> 5167.52 | E20: =Summary!E15 -> 3607.16 | F20: =Summary!F15 -> 3951.86 | G20: =Summary!G15 -> 3241.54 | H20: =Summary!H15 -> 3330.51 | I20: =Summary!I15 -> 3154.94 | ... AF20: =Summary!AF15 -> 2286.52 | AG20: =SUM(B20:AF20) -> 93603.34
A21: - Shipping | B21: =Summary!B16 -> 3061.7 | C21: =Summary!C16 -> 2538.88 | D21: =Summary!D16 -> 2488.88 | E21: =Summary!E16 -> 2926.1 | F21: =Summary!F16 -> 3287.98 | G21: =Summary!G16 -> 2319.64 | H21: =Summary!H16 -> 2303.4 | I21: =Summary!I16 -> 2537.98 | ... AF21: =Summary!AF16 -> 3468.74 | AG21: =SUM(B21:AF21) -> 88594.42
A22: SUM | B22: =SUM(B15:B21) -> 132546.38 | C22: =SUM(C15:C21) -> 146258.76 | D22: =SUM(D15:D21) -> 146701.24 | E22: =SUM(E15:E21) -> 97267.91 | F22: =SUM(F15:F21) -> 99876.6 | G22: =SUM(G15:G21) -> 84500.46 | H22: =SUM(H15:H21) -> 85058.37 | I22: =SUM(I15:I21) -> 82385.06 | ... AF22: =SUM(AF15:AF21) -> 38839.58 | AG22: =SUM(B22:AF22) -> 2206917.3
A24: Units Sold (Gross)
A25: SKU 1 - Blue | B25: 48 | C25: 44 | D25: 34 | E25: 19 | F25: 23 | G25: 18 | H25: 21 | I25: 21 | J25: 29 | K25: 23 | L25: 22 | M25: 17 | N25: 11 | O25: 10 | P25: 10 | Q25: 6 | R25: 6 | S25: 6 | T25: 5 | U25: 5 | V25: 4 | W25: 10 | X25: 6 | Y25: 4 | Z25: 0 | AA25: 8 | AB25: 12 | AC25: 21 | AD25: 15 | AE25: 16 | AF25: 12 | AG25: =SUM(B25:AF25) -> 486
A26: SKU 2 - Yellow | B26: 0 | C26: 0 | D26: 0 | E26: 0 | F26: 0 | G26: 0 | H26: 0 | I26: 0 | J26: 0 | K26: 0 | L26: 0 | M26: 0 | N26: 0 | O26: 0 | P26: 0 | Q26: 0 | R26: 0 | S26: 0 | T26: 0 | U26: 0 | V26: 0 | W26: 0 | X26: 0 | Y26: 0 | Z26: 0 | AA26: 0 | AB26: 0 | AC26: 0 | AD26: 0 | AE26: 0 | AF26: 0 | AG26: =SUM(B26:AF26) -> 0
A27: SKU 3 - Blue w/ Solar | B27: 0 | C27: 0 | D27: 0 | E27: 0 | F27: 0 | G27: 0 | H27: 0 | I27: 0 | J27: 0 | K27: 0 | L27: 0 | M27: 0 | N27: 5 | O27: 7 | P27: 5 | Q27: 6 | R27: 3 | S27: 3 | T27: 8 | U27: 4 | V27: 4 | W27: 7 | X27: 21 | Y27: 12 | Z27: 25 | AA27: 18 | AB27: 18 | AC27: 0 | AD27: 0 | AE27: 0 | AF27: 0 | AG27: =SUM(B27:AF27) -> 146
A28: SKU 4 - Yellow w/ Solar | B28: 7 | C28: 8 | D28: 7 | E28: 12 | F28: 9 | G28: 6 | H28: 4 | I28: 4 | J28: 6 | K28: 8 | L28: 9 | M28: 11 | N28: 4 | O28: 9 | P28: 8 | Q28: 4 | R28: 2 | S28: 3 | T28: 2 | U28: 2 | V28: 5 | W28: 9 | X28: 11 | Y28: 14 | Z28: 7 | AA28: 9 | AB28: 16 | AC28: 38 | AD28: 28 | AE28: 41 | AF28: 31 | AG28: =SUM(B28:AF28) -> 334
A29: SKU 1 - Blue PRO | B29: 0 | C29: 0 | D29: 1 | E29: 3 | F29: 11 | G29: 7 | H29: 13 | I29: 9 | J29: 5 | K29: 6 | L29: 6 | M29: 9 | N29: 5 | O29: 6 | P29: 3 | Q29: 4 | R29: 2 | S29: 2 | T29: 4 | U29: 3 | V29: 3 | W29: 5 | X29: 8 | Y29: 9 | Z29: 9 | AA29: 15 | AB29: 8 | AC29: 18 | AD29: 10 | AE29: 18 | AF29: 19 | AG29: =SUM(B29:AF29) -> 221
A30: SKU 2 - Yellow PRO | B30: 0 | C30: 0 | D30: 0 | E30: 0 | F30: 0 | G30: 0 | H30: 0 | I30: 0 | J30: 0 | K30: 0 | L30: 0 | M30: 0 | N30: 0 | O30: 0 | P30: 0 | Q30: 0 | R30: 0 | S30: 0 | T30: 0 | U30: 0 | V30: 0 | W30: 0 | X30: 0 | Y30: 0 | Z30: 0 | AA30: 0 | AB30: 0 | AC30: 0 | AD30: 0 | AE30: 0 | AF30: 0 | AG30: =SUM(B30:AF30) -> 0
A31: SKU 3 - Blue w/ Solar PRO | B31: 1 | C31: 0 | D31: 10 | E31: 31 | F31: 24 | G31: 25 | H31: 22 | I31: 33 | J31: 23 | K31: 22 | L31: 56 | M31: 43 | N31: 24 | O31: 27 | P31: 18 | Q31: 16 | R31: 42 | S31: 66 | T31: 53 | U31: 57 | V31: 61 | W31: 51 | X31: 69 | Y31: 67 | Z31: 63 | AA31: 80 | AB31: 57 | AC31: 66 | AD31: 66 | AE31: 63 | AF31: 60 | AG31: =SUM(B31:AF31) -> 1296
A32: SKU 4 - Yellow w/ Solar PRO | B32: 0 | C32: 0 | D32: 0 | E32: 0 | F32: 0 | G32: 0 | H32: 0 | I32: 0 | J32: 0 | K32: 0 | L32: 0 | M32: 0 | N32: 0 | O32: 0 | P32: 0 | Q32: 0 | R32: 0 | S32: 0 | T32: 0 | U32: 0 | V32: 0 | W32: 0 | X32: 0 | Y32: 0 | Z32: 0 | AA32: 0 | AB32: 0 | AC32: 0 | AD32: 0 | AE32: 0 | AF32: 0 | AG32: =SUM(B32:AF32) -> 0
A33: SUM (SKU 1 - SKU 4) | B33: =SUM(B25:B32) -> 56 | C33: =SUM(C25:C32) -> 52 | D33: =SUM(D25:D32) -> 52 | E33: =SUM(E25:E32) -> 65 | F33: =SUM(F25:F32) -> 67 | G33: =SUM(G25:G32) -> 56 | H33: =SUM(H25:H32) -> 60 | I33: =SUM(I25:I32) -> 67 | ... AF33: =SUM(AF25:AF32) -> 122 | AG33: =SUM(B33:AF33) -> 2483
A35: SKU 5 - HBF | B35: 0 | C35: 0 | D35: 0 | E35: 0 | F35: 0 | G35: 0 | H35: 0 | I35: 0 | J35: 0 | K35: 0 | L35: 0 | M35: 0 | N35: 0 | O35: 0 | P35: 0 | Q35: 0 | R35: 0 | S35: 0 | T35: 0 | U35: 0 | V35: 0 | W35: 0 | X35: 0 | Y35: 0 | Z35: 0 | AA35: 0 | AB35: 0 | AC35: 0 | AD35: 0 | AE35: 0 | AF35: 0 | AG35: =SUM(B35:AF35) -> 0
A36: SKU 6 - HBF w/ Solar | B36: 0 | C36: 0 | D36: 0 | E36: 0 | F36: 0 | G36: 0 | H36: 0 | I36: 0 | J36: 0 | K36: 0 | L36: 0 | M36: 0 | N36: 0 | O36: 0 | P36: 0 | Q36: 0 | R36: 0 | S36: 0 | T36: 0 | U36: 0 | V36: 0 | W36: 0 | X36: 0 | Y36: 0 | Z36: 0 | AA36: 0 | AB36: 0 | AC36: 0 | AD36: 0 | AE36: 0 | AF36: 0 | AG36: =SUM(B36:AF36) -> 0
A37: SUM (SKU 5 - SKU 6) | B37: =SUM(B35:B36) -> 0 | C37: =SUM(C35:C36) -> 0 | D37: =SUM(D35:D36) -> 0 | E37: =SUM(E35:E36) -> 0 | F37: =SUM(F35:F36) -> 0 | G37: =SUM(G35:G36) -> 0 | H37: =SUM(H35:H36) -> 0 | I37: =SUM(I35:I36) -> 0 | ... AF37: =SUM(AF35:AF36) -> 0 | AG37: =SUM(B37:AF37) -> 0
A39: Wall Mount | B39: 23 | C39: 31 | D39: 17 | E39: 26 | F39: 31 | G39: 12 | H39: 12 | I39: 12 | J39: 16 | K39: 17 | L39: 13 | M39: 21 | N39: 14 | O39: 17 | P39: 9 | Q39: 7 | R39: 6 | S39: 14 | T39: 16 | U39: 11 | V39: 11 | W39: 21 | X39: 45 | Y39: 47 | Z39: 44 | AA39: 51 | AB39: 22 | AC39: 18 | AD39: 16 | AE39: 15 | AF39: 13 | AG39: =SUM(B39:AF39) -> 628
A40: Suet Ball Holder | B40: 20 | C40: 18 | D40: 14 | E40: 19 | F40: 23 | G40: 11 | H40: 16 | I40: 19 | J40: 12 | K40: 20 | L40: 10 | M40: 19 | N40: 14 | O40: 9 | P40: 5 | Q40: 13 | R40: 8 | S40: 21 | T40: 12 | U40: 26 | V40: 11 | W40: 15 | X40: 68 | Y40: 89 | Z40: 84 | AA40: 111 | AB40: 86 | AC40: 112 | AD40: 95 | AE40: 105 | AF40: 85 | AG40: =SUM(B40:AF40) -> 1170
A41: 3-in-1 Nutrition Set - Blue | B41: 19 | C41: 5 | D41: 12 | E41: 21 | F41: 19 | G41: 7 | H41: 14 | I41: 7 | J41: 17 | K41: 12 | L41: 16 | M41: 19 | N41: 10 | O41: 17 | P41: 7 | Q41: 4 | R41: 5 | S41: 12 | T41: 10 | U41: 16 | V41: 3 | W41: 19 | X41: 40 | Y41: 45 | Z41: 45 | AA41: 51 | AB41: 21 | AC41: 14 | AD41: 10 | AE41: 9 | AF41: 3 | AG41: =SUM(B41:AF41) -> 509
A42: 3-in-1 Nutrition Set - Yellow | B42: 2 | C42: 1 | D42: 1 | E42: 8 | F42: 4 | G42: 2 | H42: 0 | I42: 1 | J42: 0 | K42: 3 | L42: 0 | M42: 4 | N42: 2 | O42: 2 | P42: 3 | Q42: 1 | R42: 2 | S42: 1 | T42: 2 | U42: 2 | V42: 3 | W42: 5 | X42: 5 | Y42: 1 | Z42: 5 | AA42: 5 | AB42: 3 | AC42: 2 | AD42: 2 | AE42: 3 | AF42: 3 | AG42: =SUM(B42:AF42) -> 78
A43: Solar Roof Single - Blue | B43: 91 | C43: 71 | D43: 56 | E43: 36 | F43: 54 | G43: 43 | H43: 30 | I43: 29 | J43: 47 | K43: 34 | L43: 35 | M43: 49 | N43: 25 | O43: 29 | P43: 15 | Q43: 17 | R43: 19 | S43: 22 | T43: 23 | U43: 11 | V43: 15 | W43: 15 | X43: 7 | Y43: 13 | Z43: 21 | AA43: 21 | AB43: 19 | AC43: 26 | AD43: 26 | AE43: 19 | AF43: 17 | AG43: =SUM(B43:AF43) -> 935
A44: Solar Roof Single - Yellow | B44: 2 | C44: 1 | D44: 1 | E44: 4 | F44: 0 | G44: 1 | H44: 1 | I44: 0 | J44: 0 | K44: 1 | L44: 3 | M44: 2 | N44: 0 | O44: 0 | P44: 1 | Q44: 1 | R44: 2 | S44: 1 | T44: 2 | U44: 0 | V44: 1 | W44: 1 | X44: 2 | Y44: 1 | Z44: 2 | AA44: 2 | AB44: 2 | AC44: 2 | AD44: 2 | AE44: 1 | AF44: 0 | AG44: =SUM(B44:AF44) -> 39
A45: Perch Extender - Blue | B45: 93 | C45: 70 | D45: 80 | E45: 81 | F45: 102 | G45: 59 | H45: 63 | I45: 69 | J45: 73 | K45: 70 | L45: 50 | M45: 77 | N45: 48 | O45: 51 | P45: 27 | Q45: 37 | R45: 30 | S45: 50 | T45: 57 | U45: 52 | V45: 34 | W45: 54 | X45: 73 | Y45: 77 | Z45: 96 | AA45: 113 | AB45: 58 | AC45: 36 | AD45: 54 | AE45: 33 | AF45: 33 | AG45: =SUM(B45:AF45) -> 1900
A46: Perch Extender - Yellow | B46: 16 | C46: 10 | D46: 13 | E46: 17 | F46: 10 | G46: 6 | H46: 8 | I46: 9 | J46: 6 | K46: 14 | L46: 11 | M46: 19 | N46: 7 | O46: 10 | P46: 8 | Q46: 7 | R46: 7 | S46: 11 | T46: 9 | U46: 3 | V46: 9 | W46: 10 | X46: 8 | Y46: 8 | Z46: 7 | AA46: 12 | AB46: 6 | AC46: 13 | AD46: 5 | AE46: 11 | AF46: 10 | AG46: =SUM(B46:AF46) -> 300
...

Sheet DTC EU - P&L
A1: JANUARY | B1: 45658 | C1: 45659 | D1: 45660 | E1: 45661 | F1: 45662 | G1: 45663 | H1: 45664 | I1: 45665 | J1: 45666 | K1: 45667 | L1: 45668 | M1: 45669 | N1: 45670 | O1: 45671 | P1: 45672 | Q1: 45673 | R1: 45674 | S1: 45675 | T1: 45676 | U1: 45677 | V1: 45678 | W1: 45679 | X1: 45680 | Y1: 45681 | Z1: 45682 | AA1: 45683 | AB1: 45684 | AC1: 45685 | AD1: 45686 | AE1: 45687 | AF1: 45688
A2: DAY | B2: WED | C2: THU | D2: FRI | E2: SAT | F2: SUN | G2: MON | H2: TUE | I2: WED | J2: THU | K2: FRI | L2: SAT | M2: SUN | N2: MON | O2: TUE | P2: WED | Q2: THU | R2: FRI | S2: SAT | T2: SUN | U2: MON | V2: TUE | W2: WED | X2: THU | Y2: FRI | Z2: SAT | AA2: SUN | AB2: MON | AC2: TUE | AD2: WED | AE2: THU | AF2: FRI
A4: Revenue
A5: Revenue Woocommerce (Platform) | B5: =Summary!B17+Summary!B26 -> 5844.0918 | C5: =Summary!C17+Summary!C26 -> 4966.7627 | D5: =Summary!D17+Summary!D26 -> 4749.9753 | E5: =Summary!E17+Summary!E26 -> 2340.6486 | F5: =Summary!F17+Summary!F26 -> 3680.1319 | G5: =Summary!G17+Summary!G26 -> 5741.6952 | H5: =Summary!H17+Summary!H26 -> 5280.6637 | I5: =Summary!I17+Summary!I26 -> 5629.9869 | ... AF5: =Summary!AF17+Summary!AF26 -> 1593.9105 | AG5: =SUM(B5:AF5) -> 113820.79
A6: Revenue w/o renewals | B6: =B8*Summary!B121 -> 1372.9566 | C6: =C8*Summary!C121 -> 563.14143 | D6: =D8*Summary!D121 -> 1594.8642 | E6: =E8*Summary!E121 -> 948.81822 | F6: =F8*Summary!F121 -> 712.62167 | G6: =G8*Summary!G121 -> 2471.4136 | H6: =H8*Summary!H121 -> 2953.5223 | I6: =I8*Summary!I121 -> 2380.493 | ... AF6: =AF8*Summary!AF121 -> 1500.5909
A7: SUM | B7: =SUM(B5) -> 5844.0918 | C7: =SUM(C5) -> 4966.7627 | D7: =SUM(D5) -> 4749.9753 | E7: =SUM(E5) -> 2340.6486 | F7: =SUM(F5) -> 3680.1319 | G7: =SUM(G5) -> 5741.6952 | H7: =SUM(H5) -> 5280.6637 | I7: =SUM(I5) -> 5629.9869 | ... AF7: =SUM(AF5) -> 1593.9105 | AG7: =SUM(B7:AF7) -> 113820.79
A8: Revenue w/o renewals EURO | B8: 1326.4 | C8: 548.55 | D8: 1546.61 | E8: 920.2 | F8: 691.53 | G8: 2380.25 | H8: 2855.3 | I8: 2307.35 | J8: 2743.4 | K8: 908.85 | L8: 1536.2 | M8: 1489.8 | N8: 1376.6 | O8: 2920.75 | P8: 772.9 | Q8: 429.25 | R8: 1655.7 | S8: 2853.16 | T8: 6758.4 | U8: 369.9 | V8: 1183.1 | W8: 1417.13 | X8: 1344.51 | Y8: 1625.13 | Z8: 3130.65 | AA8: 4870.33 | AB8: 3693.08 | AC8: 1327.15 | AD8: 2004.65 | AE8: 1930.35 | AF8: 1447.05
A9: Orders
A10: Orders Woocommerce (Platform) | B10: =Summary!B89 -> 53 | C10: =Summary!C89 -> 52 | D10: =Summary!D89 -> 47 | E10: =Summary!E89 -> 19 | F10: =Summary!F89 -> 35 | G10: =Summary!G89 -> 43 | H10: =Summary!H89 -> 35 | I10: =Summary!I89 -> 42 | ... AF10: =Summary!AF89 -> 10 | AG10: =SUM(B10:AF10) -> 814
A11: Orders w/o renewals | B11: 5 | C11: 4 | D11: 12 | E11: 6 | F11: 3 | G11: 8 | H11: 11 | I11: 7 | J11: 11 | K11: 4 | L11: 5 | M11: 7 | N11: 6 | O11: 5 | P11: 5 | Q11: 3 | R11: 7 | S11: 16 | T11: 28 | U11: 2 | V11: 7 | W11: 6 | X11: 7 | Y11: 7 | Z11: 9 | AA11: 23 | AB11: 16 | AC11: 7 | AD11: 8 | AE11: 12 | AF11: 9
A12: SUM | B12: =SUM(B10) -> 53 | C12: =SUM(C10) -> 52 | D12: =SUM(D10) -> 47 | E12: =SUM(E10) -> 19 | F12: =SUM(F10) -> 35 | G12: =SUM(G10) -> 43 | H12: =SUM(H10) -> 35 | I12: =SUM(I10) -> 42 | ... AF12: =SUM(AF10) -> 10 | AG12: =SUM(B12:AF12) -> 814
A14: Breakdown
A15: - Hardware | B15: 942.3 | C15: 251.26 | D15: 694.27 | E15: 448.5 | F15: 496.28 | G15: 1660.43 | H15: 1963.72 | I15: 1611.4 | J15: 1772.83 | K15: 643.09 | L15: 1098.4 | M15: 976.38 | N15: 881.33 | O15: 2186.04 | P15: 388.62 | Q15: 197.52 | R15: 1077.99 | S15: 1712.77 | T15: 4299.41 | U15: 249.17 | V15: 626.01 | W15: 802.22 | X15: 757.6 | Y15: 1075.03 | Z15: 1879.64 | AA15: 2682.89 | AB15: 2201.77 | AC15: 800.25 | AD15: 1052.11 | AE15: 1020.23 | AF15: 770.55 | AG15: =SUM(B15:AF15) -> 37220.01
A16: - Add-ons | B16: 48.47 | C16: 151.45 | D16: 306.63 | E16: 223.67 | F16: 0 | G16: 152.15 | H16: 136.15 | I16: 89.26 | J16: 256.75 | K16: 23.97 | L16: 48.33 | M16: 111.19 | N16: 127.19 | O16: 15.7 | P16: 162.83 | Q16: 113.33 | R16: 135.02 | S16: 347.25 | T16: 701.97 | U16: 24.37 | V16: 217.86 | W16: 241.52 | X16: 229.89 | Y16: 118.3 | Z16: 441.35 | AA16: 898.8 | AB16: 479.15 | AC16: 155.59 | AD16: 420.83 | AE16: 367.12 | AF16: 258.52 | AG16: =SUM(B16:AF16) -> 7004.61
A17: - Merch | B17: 0 | C17: 0 | D17: 0 | E17: 0 | F17: 0 | G17: 0 | H17: 0 | I17: 0 | J17: 0 | K17: 0 | L17: 0 | M17: 0 | N17: 0 | O17: 0 | P17: 0 | Q17: 0 | R17: 0 | S17: 0 | T17: 0 | U17: 0 | V17: 0 | W17: 0 | X17: 0 | Y17: 0 | Z17: 0 | AA17: 0 | AB17: 0 | AC17: 0 | AD17: 0 | AE17: 0 | AF17: 0 | AG17: =SUM(B17:AF17) -> 0
A18: - Seeds | B18: 0 | C18: 0 | D18: 0 | E18: 0 | F18: 0 | G18: 0 | H18: 0 | I18: 0 | J18: 0 | K18: 0 | L18: 0 | M18: 0 | N18: 0 | O18: 0 | P18: 0 | Q18: 0 | R18: 0 | S18: 0 | T18: 0 | U18: 0 | V18: 0 | W18: 0 | X18: 0 | Y18: 0 | Z18: 0 | AA18: 0 | AB18: 0 | AC18: 0 | AD18: 0 | AE18: 0 | AF18: 0 | AG18: =SUM(B18:AF18) -> 0
A19: - Yearly Pro Subscription | B19: 3576.59 | C19: 3548.99 | D19: 2677.7 | E19: 1113.89 | F19: 2401.76 | G19: 2591.43 | H19: 1868.91 | I19: 2601.07 | J19: 2748.67 | K19: 2074.76 | L19: 2303.65 | M19: 2156.51 | N19: 1793.99 | O19: 2227.15 | P19: 1185.84 | Q19: 1045.62 | R19: 1412.17 | S19: 698.12 | T19: 523.12 | U19: 373.14 | V19: 331.31 | W19: 596.88 | X19: 371.9 | Y19: 147.53 | Z19: 0 | AA19: 327.36 | AB19: 149.38 | AC19: 0 | AD19: 224.4 | AE19: 226.27 | AF19: 74.99 | AG19: =SUM(B19:AF19) -> 41373.1
A20: - Taxes | B20: 968.56 | C20: 831.37 | D20: 802.66 | E20: 393.99 | F20: 623.17 | G20: 965.89 | H20: 891.27 | I20: 970.27 | J20: 1064.78 | K20: 601.75 | L20: 750.51 | M20: 725.43 | N20: 613.85 | O20: 966.56 | P20: 395.45 | Q20: 287.64 | R20: 595.33 | S20: 634.93 | T20: 1268.83 | U20: 138.17 | V20: 262.88 | W20: 376.43 | X20: 305.07 | Y20: 304.25 | Z20: 549.66 | AA20: 891.24 | AB20: 702.76 | AC20: 226.31 | AD20: 392.28 | AE20: 376.7 | AF20: 267.98 | AG20: =SUM(B20:AF20) -> 19145.97
A21: - Shipping | B21: 110 | C21: 55 | D21: 125 | E21: 90 | F21: 50 | G21: 160 | H21: 245 | I21: 185 | J21: 230 | K21: 85 | L21: 125 | M21: 130 | N21: 120 | O21: 225 | P21: 80 | Q21: 45 | R21: 145 | S21: 270 | T21: 595 | U21: 35 | V21: 105 | W21: 120 | X21: 130 | Y21: 160 | Z21: 260 | AA21: 430 | AB21: 340 | AC21: 145 | AD21: 185 | AE21: 210 | AF21: 165 | AG21: =SUM(B21:AF21) -> 5355
A22: SUM | B22: =SUM(B15:B21) -> 5645.92 | C22: =SUM(C15:C21) -> 4838.07 | D22: =SUM(D15:D21) -> 4606.26 | E22: =SUM(E15:E21) -> 2270.05 | F22: =SUM(F15:F21) -> 3571.21 | G22: =SUM(G15:G21) -> 5529.9 | H22: =SUM(H15:H21) -> 5105.05 | I22: =SUM(I15:I21) -> 5457 | ... AF22: =SUM(AF15:AF21) -> 1537.04 | AG22: =SUM(B22:AF22) -> 110098.69
A24: Units Sold (Gross)
A25: SKU 1 - Blue | B25: 0 | C25: 0 | D25: 0 | E25: 0 | F25: 0 | G25: 0 | H25: 0 | I25: 0 | J25: 0 | K25: 0 | L25: 0 | M25: 0 | N25: 0 | O25: 0 | P25: 0 | Q25: 0 | R25: 0 | S25: 0 | T25: 3 | U25: 0 | V25: 0 | W25: 0 | X25: 0 | Y25: 0 | Z25: 0 | AA25: 0 | AB25: 0 | AC25: 1 | AD25: 4 | AE25: 2 | AF25: 2 | AG25: =SUM(B25:AF25) -> 12
A26: SKU 2 - Yellow | B26: 0 | C26: 0 | D26: 0 | E26: 0 | F26: 0 | G26: 0 | H26: 0 | I26: 0 | J26: 0 | K26: 0 | L26: 0 | M26: 0 | N26: 0 | O26: 0 | P26: 0 | Q26: 0 | R26: 0 | S26: 0 | T26: 0 | U26: 0 | V26: 0 | W26: 0 | X26: 0 | Y26: 0 | Z26: 0 | AA26: 0 | AB26: 0 | AC26: 0 | AD26: 0 | AE26: 0 | AF26: 0 | AG26: =SUM(B26:AF26) -> 0
A27: SKU 3 - Blue w/ Solar | B27: 0 | C27: 0 | D27: 0 | E27: 0 | F27: 0 | G27: 0 | H27: 0 | I27: 0 | J27: 0 | K27: 0 | L27: 0 | M27: 0 | N27: 0 | O27: 0 | P27: 0 | Q27: 0 | R27: 0 | S27: 0 | T27: 0 | U27: 0 | V27: 0 | W27: 0 | X27: 0 | Y27: 0 | Z27: 0 | AA27: 0 | AB27: 0 | AC27: 0 | AD27: 0 | AE27: 0 | AF27: 0 | AG27: =SUM(B27:AF27) -> 0
A28: SKU 4 - Yellow w/ Solar | B28: 0 | C28: 0 | D28: 0 | E28: 0 | F28: 0 | G28: 0 | H28: 0 | I28: 0 | J28: 0 | K28: 0 | L28: 0 | M28: 0 | N28: 0 | O28: 0 | P28: 0 | Q28: 0 | R28: 0 | S28: 0 | T28: 0 | U28: 0 | V28: 0 | W28: 0 | X28: 0 | Y28: 0 | Z28: 0 | AA28: 0 | AB28: 0 | AC28: 0 | AD28: 0 | AE28: 0 | AF28: 0 | AG28: =SUM(B28:AF28) -> 0
A29: SKU 1 - Blue PRO | B29: 1 | C29: 0 | D29: 1 | E29: 0 | F29: 0 | G29: 0 | H29: 5 | I29: 2 | J29: 4 | K29: 2 | L29: 2 | M29: 0 | N29: 2 | O29: 1 | P29: 2 | Q29: 1 | R29: 1 | S29: 0 | T29: 1 | U29: 0 | V29: 1 | W29: 0 | X29: 1 | Y29: 2 | Z29: 2 | AA29: 0 | AB29: 5 | AC29: 4 | AD29: 3 | AE29: 2 | AF29: 3 | AG29: =SUM(B29:AF29) -> 48
A30: SKU 2 - Yellow PRO | B30: 0 | C30: 0 | D30: 0 | E30: 0 | F30: 0 | G30: 0 | H30: 0 | I30: 0 | J30: 0 | K30: 0 | L30: 0 | M30: 0 | N30: 0 | O30: 0 | P30: 0 | Q30: 0 | R30: 0 | S30: 0 | T30: 0 | U30: 0 | V30: 0 | W30: 0 | X30: 0 | Y30: 0 | Z30: 0 | AA30: 0 | AB30: 0 | AC30: 0 | AD30: 0 | AE30: 0 | AF30: 0 | AG30: =SUM(B30:AF30) -> 0
