Workbook
Name zsupermetrics_ru0GDtbZzDLHQOQtJJ6K08MvUDyyp7: #REF!
Name zsupermetrics_DQl8lUbpTRu3fayaJJi7lVfOGKjNU4: 'Data - P&L'!$A$3:$A$4
Name zsupermetrics_BioPyGBzcBsy60UCQmPcTuFReEmghI: 'Data - P&L'!$B$2:$B$3
Name zsupermetrics_refreshAll: SupermetricsQueries!$H$5
Name zsupermetrics_n3GtLgiKpTmd2pYmQNMuq6TPD0qE0b: #REF!
Name zsupermetrics_refreshAllSilent: SupermetricsQueries!$H$6
Name zsupermetrics_Mgms9p0QzysYvrIhnsKACeVBVxfIEO: #REF!
Name zsupermetrics_Mgms9p0QzysYvrIhnsKACeVBVxfIEO: 'Data - P&L'!$A$2:$A$3
Name zsupermetrics_forceRefresh: SupermetricsQueries!$H$4
Name zsupermetrics_wbYMmT0YL9bAN0yhimW0ziPFnia9Dx: #REF!
Name zsupermetrics_iNpyVy90bWCI0yUaFQpxOtzWMa6sW4: #REF!
Name zsupermetrics_xwoIpANxRm908eDp5oKTwQpEI8gvD4: #REF!
Name zsupermetrics_n3GtLgiKpTmd2pYmQNMuq6TPD0qE0b: 'Data - P&L'!$B$4:$B$5
Name rdataslayer_42b112e4e4be4305bb4c1be75e2dd549: 'Data - P&L'!$B$2:$C$3
Name zsupermetrics_9i4W4hgd80uRpQLMeX0eRnESN8gjyv: #REF!
Name zsupermetrics_5bmwtOpHUbSYmDMeuCPkrxaojTprPP: #REF!
Name rdataslayer_3753ddf3234e496aa261974a0222e193: 'Data - P&L'!$H$2:$I$2
Name zsupermetrics_SGBxROnInO9rFyh3H7j2Lldx0Bdc5v: #REF!
Name zsupermetrics_pxuhRTEmIU93xSgKclyxajD0fCZ6rF: #REF!
Name zsupermetrics_ru0GDtbZzDLHQOQtJJ6K08MvUDyyp7: 'Data - P&L'!$B$4:$B$5
Name zsupermetrics_qWp7V908pNEYMtfv8QZvSTeDnBAHOU: 'Data - P&L'!$B$5:$C$13
Name rdataslayer_4a0f150f4f2f4e4f85c890c75b7a1fa4: #REF!
Name zsupermetrics_8xojRjNDjo2jWHGDWjFEhflhyIq3Hq: #REF!
Name zsupermetrics_HgZqhorObHOtZHuyJjpmyYaEPoYntx: #REF!
Name zsupermetrics_YsFuuYtr8vOdNXCCPiFJIO38NP4b2T: #REF!
Name zsupermetrics_DQl8lUbpTRu3fayaJJi7lVfOGKjNU4: #REF!
Name zsupermetrics_YVuzfmsfdurz7Ldl84Rfns8oka6LsS: #REF!
Name zsupermetrics_4VkB7ij7WO0JjKBEgvjB2GHjSy2Egm: #REF!
Name zsupermetrics_9i4W4hgd80uRpQLMeX0eRnESN8gjyv: 'Data - P&L'!$C$13
Name zsupermetrics_lx4cNai7gT6tH4j08ZRkI21Qlpjioi: #REF!
Name rdataslayer_d70e473bcafe40a3aa834ce157fb2ba3: #REF!
Name zsupermetrics_NugLlrQxlKiqhxQae8EFpITBm1pLCj: 'Data - P&L'!$B$6:$C$13
Name zsupermetrics_8xojRjNDjo2jWHGDWjFEhflhyIq3Hq: Summary!$K$12:$K$47
Name zsupermetrics_FEamnpN5FsVYF0RtUTXAwunZ388Tkc: Forecast!$A$113:$C$141
Name rdataslayer_3753ddf3234e496aa261974a0222e193: #REF!
Name zsupermetrics_iNpyVy90bWCI0yUaFQpxOtzWMa6sW4: 'Data - P&L'!$A$2:$A$3
Name rdataslayer_4a0f150f4f2f4e4f85c890c75b7a1fa4: 'Data - P&L'!$D$2:$E$3
Name zsupermetrics_BioPyGBzcBsy60UCQmPcTuFReEmghI: #REF!
Name zsupermetrics_qWp7V908pNEYMtfv8QZvSTeDnBAHOU: #REF!
Name zsupermetrics_wbYMmT0YL9bAN0yhimW0ziPFnia9Dx: 'Data - P&L'!$A$2:$A$3
Name zsupermetrics_4VkB7ij7WO0JjKBEgvjB2GHjSy2Egm: 'Data - P&L'!$B$4:$C$10
Name zsupermetrics_lx4cNai7gT6tH4j08ZRkI21Qlpjioi: 'Data - P&L'!$B$4:$C$13
Name rdataslayer_42b112e4e4be4305bb4c1be75e2dd549: #REF!
Name rdataslayer_adf57e64065742daa5b4161161b1c3ca: #REF!
Name rdataslayer_adf57e64065742daa5b4161161b1c3ca: 'Data - P&L'!$B$4:$D$5
Name zsupermetrics_NugLlrQxlKiqhxQae8EFpITBm1pLCj: #REF!
Name zsupermetrics_xwoIpANxRm908eDp5oKTwQpEI8gvD4: #REF!
Name zsupermetrics_YsFuuYtr8vOdNXCCPiFJIO38NP4b2T: 'Data - P&L'!$B$4:$C$13
Name rdataslayer_d70e473bcafe40a3aa834ce157fb2ba3: 'Data - P&L'!$C$8:$D$9
Name zsupermetrics_HgZqhorObHOtZHuyJjpmyYaEPoYntx: 'Data - P&L'!$B$4:$B$5

Sheet Data_forecast_2024
B1: 45809 | C1: 45810 | D1: 45811 | E1: 45812 | F1: 45813 | G1: 45814 | H1: 45815 | I1: 45816 | J1: 45817 | K1: 45818 | L1: 45819 | M1: 45820 | N1: 45821 | O1: 45822 | P1: 45823 | Q1: 45824 | R1: 45825 | S1: 45826 | T1: 45827 | U1: 45828 | V1: 45829 | W1: 45830 | X1: 45831 | Y1: 45832 | Z1: 45833 | AA1: 45834 | AB1: 45835 | AC1: 45836 | AD1: 45837 | AE1: 45838 | AF1: 45839
A2: Quantities | B2: ='DTC - P&L'!B66+'AMAZON US&CA - P&L'!B36+'WALMART - P&L'!B23+'Digital Marketplaces - P&L'!B17+'Digital Marketplaces - P&L'!B129+'Digital Marketplaces - P&L'!B243+'COSTCO - P&L'!B19 -> 38 | C2: ='DTC - P&L'!C66+'AMAZON US&CA - P&L'!C36+'WALMART - P&L'!C23+'Digital Marketplaces - P&L'!C17+'Digital Marketplaces - P&L'!C129+'Digital Marketplaces - P&L'!C243+'COSTCO - P&L'!C19 -> 40 | D2: ='DTC - P&L'!D66+'AMAZON US&CA - P&L'!D36+'WALMART - P&L'!D23+'Digital Marketplaces - P&L'!D17+'Digital Marketplaces - P&L'!D129+'Digital Marketplaces - P&L'!D243+'COSTCO - P&L'!D19 -> 41 | E2: ='DTC - P&L'!E66+'AMAZON US&CA - P&L'!E36+'WALMART - P&L'!E23+'Digital Marketplaces - P&L'!E17+'Digital Marketplaces - P&L'!E129+'Digital Marketplaces - P&L'!E243+'COSTCO - P&L'!E19 -> 32 | F2: ='DTC - P&L'!F66+'AMAZON US&CA - P&L'!F36+'WALMART - P&L'!F23+'Digital Marketplaces - P&L'!F17+'Digital Marketplaces - P&L'!F129+'Digital Marketplaces - P&L'!F243+'COSTCO - P&L'!F19 -> 36 | G2: ='DTC - P&L'!G66+'AMAZON US&CA - P&L'!G36+'WALMART - P&L'!G23+'Digital Marketplaces - P&L'!G17+'Digital Marketplaces - P&L'!G129+'Digital Marketplaces - P&L'!G243+'COSTCO - P&L'!G19 -> 37 | H2: ='DTC - P&L'!H66+'AMAZON US&CA - P&L'!H36+'WALMART - P&L'!H23+'Digital Marketplaces - P&L'!H17+'Digital Marketplaces - P&L'!H129+'Digital Marketplaces - P&L'!H243+'COSTCO - P&L'!H19 -> 161 | I2: ='DTC - P&L'!I66+'AMAZON US&CA - P&L'!I36+'WALMART - P&L'!I23+'Digital Marketplaces - P&L'!I17+'Digital Marketplaces - P&L'!I129+'Digital Marketplaces - P&L'!I243+'COSTCO - P&L'!I19 -> 189 | ... AF2: ='DTC - P&L'!AF66+'AMAZON US&CA - P&L'!AF36+'WALMART - P&L'!AF23+'Digital Marketplaces - P&L'!AF17+'Digital Marketplaces - P&L'!AF129+'Digital Marketplaces - P&L'!AF243+'COSTCO - P&L'!AF19 -> 52
A3: Sales | B3: =Summary!B47+Summary!B93+Summary!B85+Summary!B59 -> 31136.706 | C3: =Summary!C47+Summary!C93+Summary!C85+Summary!C59 -> 30219.791 | D3: =Summary!D47+Summary!D93+Summary!D85+Summary!D59 -> 23249.623 | E3: =Summary!E47+Summary!E93+Summary!E85+Summary!E59 -> 21309.283 | F3: =Summary!F47+Summary!F93+Summary!F85+Summary!F59 -> 24536.862 | G3: =Summary!G47+Summary!G93+Summary!G85+Summary!G59 -> 19523.24 | H3: =Summary!H47+Summary!H93+Summary!H85+Summary!H59 -> 55470.515 | I3: =Summary!I47+Summary!I93+Summary!I85+Summary!I59 -> 60647.394 | ... AF3: =Summary!AF47+Summary!AF93+Summary!AF85+Summary!AF59 -> 24620.701

Sheet WALMART_Data_forecast_2024
B1: 45809 | C1: 45810 | D1: 45811 | E1: 45812 | F1: 45813 | G1: 45814 | H1: 45815 | I1: 45816 | J1: 45817 | K1: 45818 | L1: 45819 | M1: 45820 | N1: 45821 | O1: 45822 | P1: 45823 | Q1: 45824 | R1: 45825 | S1: 45826 | T1: 45827 | U1: 45828 | V1: 45829 | W1: 45830 | X1: 45831 | Y1: 45832 | Z1: 45833 | AA1: 45834 | AB1: 45835 | AC1: 45836 | AD1: 45837 | AE1: 45838 | AF1: 45839
A2: Quantities | B2: ='WALMART - P&L'!B23 -> 0 | C2: ='WALMART - P&L'!C23 -> 1 | D2: ='WALMART - P&L'!D23 -> 0 | E2: ='WALMART - P&L'!E23 -> 0 | F2: ='WALMART - P&L'!F23 -> 0 | G2: ='WALMART - P&L'!G23 -> 0 | H2: ='WALMART - P&L'!H23 -> 0 | I2: ='WALMART - P&L'!I23 -> 0 | ... AF2: ='WALMART - P&L'!AF23 -> 1
A3: Sales | B3: =Summary!B67 -> 0 | C3: =Summary!C67 -> 350.96 | D3: =Summary!D67 -> 0 | E3: =Summary!E67 -> 0 | F3: =Summary!F67 -> 0 | G3: =Summary!G67 -> 0 | H3: =Summary!H67 -> 31.03 | I3: =Summary!I67 -> 0 | ... AF3: =Summary!AF67 -> 321.43

Sheet COSTCO_Data_forecast_2024
B1: 45809 | C1: 45749 | D1: 45750 | E1: 45751 | F1: 45752 | G1: 45753 | H1: 45754 | I1: 45755 | J1: 45756 | K1: 45757 | L1: 45758 | M1: 45759 | N1: 45760 | O1: 45761 | P1: 45762 | Q1: 45763 | R1: 45764 | S1: 45765 | T1: 45766 | U1: 45767 | V1: 45768 | W1: 45769 | X1: 45770 | Y1: 45771 | Z1: 45772 | AA1: 45773 | AB1: 45774 | AC1: 45775 | AD1: 45776 | AE1: 45777 | AF1: 45778
A2: Quantities | B2: ='COSTCO - P&L'!B19 -> 0 | C2: ='COSTCO - P&L'!C19 -> 0 | D2: ='COSTCO - P&L'!D19 -> 0 | E2: ='COSTCO - P&L'!E19 -> 0 | F2: ='COSTCO - P&L'!F19 -> 0 | G2: ='COSTCO - P&L'!G19 -> 0 | H2: ='COSTCO - P&L'!H19 -> 0 | I2: ='COSTCO - P&L'!I19 -> 0 | ... AF2: ='COSTCO - P&L'!AF19 -> 0
A3: Sales | B3: =Summary!B59 -> 0 | C3: =Summary!C59 -> 0 | D3: =Summary!D59 -> 0 | E3: =Summary!E59 -> 0 | F3: =Summary!F59 -> 0 | G3: =Summary!G59 -> 0 | H3: =Summary!H59 -> 0 | I3: =Summary!I59 -> 0 | ... AF3: =Summary!AF59 -> 0

Sheet DM_Data_forecast_2024
B1: 45809 | C1: 45810 | D1: 45811 | E1: 45812 | F1: 45813 | G1: 45814 | H1: 45815 | I1: 45816 | J1: 45817 | K1: 45818 | L1: 45819 | M1: 45820 | N1: 45821 | O1: 45822 | P1: 45823 | Q1: 45824 | R1: 45825 | S1: 45826 | T1: 45827 | U1: 45828 | V1: 45829 | W1: 45830 | X1: 45831 | Y1: 45832 | Z1: 45833 | AA1: 45834 | AB1: 45835 | AC1: 45836 | AD1: 45837 | AE1: 45838 | AF1: 45839
A2: Quantities | B2: ='Digital Marketplaces - P&L'!B17+'Digital Marketplaces - P&L'!B129+'Digital Marketplaces - P&L'!B243 -> 0 | C2: ='Digital Marketplaces - P&L'!C17+'Digital Marketplaces - P&L'!C129+'Digital Marketplaces - P&L'!C243 -> 0 | D2: ='Digital Marketplaces - P&L'!D17+'Digital Marketplaces - P&L'!D129+'Digital Marketplaces - P&L'!D243 -> 0 | E2: ='Digital Marketplaces - P&L'!E17+'Digital Marketplaces - P&L'!E129+'Digital Marketplaces - P&L'!E243 -> 0 | F2: ='Digital Marketplaces - P&L'!F17+'Digital Marketplaces - P&L'!F129+'Digital Marketplaces - P&L'!F243 -> 0 | G2: ='Digital Marketplaces - P&L'!G17+'Digital Marketplaces - P&L'!G129+'Digital Marketplaces - P&L'!G243 -> 0 | H2: ='Digital Marketplaces - P&L'!H17+'Digital Marketplaces - P&L'!H129+'Digital Marketplaces - P&L'!H243 -> 0 | I2: ='Digital Marketplaces - P&L'!I17+'Digital Marketplaces - P&L'!I129+'Digital Marketplaces - P&L'!I243 -> 0 | ... AF2: ='Digital Marketplaces - P&L'!AF17+'Digital Marketplaces - P&L'!AF129+'Digital Marketplaces - P&L'!AF243 -> 0
A3: Sales | B3: =Summary!B85 -> 0 | C3: =Summary!C85 -> 0 | D3: =Summary!D85 -> 0 | E3: =Summary!E85 -> 0 | F3: =Summary!F85 -> 0 | G3: =Summary!G85 -> 0 | H3: =Summary!H85 -> 0 | I3: =Summary!I85 -> 0 | ... AF3: =Summary!AF85 -> 0

Sheet AMAZON_Data_Forecast
A1: US | B1: 45809 | C1: 45810 | D1: 45811 | E1: 45812 | F1: 45813 | G1: 45814 | H1: 45815 | I1: 45816 | J1: 45817 | K1: 45818 | L1: 45819 | M1: 45820 | N1: 45821 | O1: 45822 | P1: 45823 | Q1: 45824 | R1: 45825 | S1: 45826 | T1: 45827 | U1: 45828 | V1: 45829 | W1: 45830 | X1: 45831 | Y1: 45832 | Z1: 45833 | AA1: 45834 | AB1: 45835 | AC1: 45836 | AD1: 45837 | AE1: 45838 | AF1: 45839
A2: Quantities | B2: ='AMAZON US&CA - P&L'!B36+'AMAZON US&CA - P&L'!B40 -> 15 | C2: ='AMAZON US&CA - P&L'!C36+'AMAZON US&CA - P&L'!C40 -> 28 | D2: ='AMAZON US&CA - P&L'!D36+'AMAZON US&CA - P&L'!D40 -> 20 | E2: ='AMAZON US&CA - P&L'!E36+'AMAZON US&CA - P&L'!E40 -> 22 | F2: ='AMAZON US&CA - P&L'!F36+'AMAZON US&CA - P&L'!F40 -> 24 | G2: ='AMAZON US&CA - P&L'!G36+'AMAZON US&CA - P&L'!G40 -> 16 | H2: ='AMAZON US&CA - P&L'!H36+'AMAZON US&CA - P&L'!H40 -> 169 | I2: ='AMAZON US&CA - P&L'!I36+'AMAZON US&CA - P&L'!I40 -> 197 | ... AF2: ='AMAZON US&CA - P&L'!AF36+'AMAZON US&CA - P&L'!AF40 -> 18
A3: Sales | B3: =Summary!B32 -> 4277.26 | C3: =Summary!C32 -> 8057.58 | D3: =Summary!D32 -> 5661.28 | E3: =Summary!E32 -> 6498.59 | F3: =Summary!F32 -> 7048.66 | G3: =Summary!G32 -> 4593.61 | H3: =Summary!H32 -> 41026.28 | I3: =Summary!I32 -> 46178.59 | ... AF3: =Summary!AF32 -> 5819.91
A5: UK
A6: Quantities | B6: ='AMAZON UK, FR, GER - P&L'!B37 -> 0 | C6: ='AMAZON UK, FR, GER - P&L'!C37 -> 0 | D6: ='AMAZON UK, FR, GER - P&L'!D37 -> 0 | E6: ='AMAZON UK, FR, GER - P&L'!E37 -> 2 | F6: ='AMAZON UK, FR, GER - P&L'!F37 -> 0 | G6: ='AMAZON UK, FR, GER - P&L'!G37 -> 0 | H6: ='AMAZON UK, FR, GER - P&L'!H37 -> 0 | I6: ='AMAZON UK, FR, GER - P&L'!I37 -> 0 | ... AF6: ='AMAZON UK, FR, GER - P&L'!AF37 -> 0
A7: Sales | B7: =Summary!B39 -> 136.8 | C7: =Summary!C39 -> 104.88 | D7: =Summary!D39 -> 0 | E7: =Summary!E39 -> 767.29 | F7: =Summary!F39 -> 0 | G7: =Summary!G39 -> 0 | H7: =Summary!H39 -> 45.41 | I7: =Summary!I39 -> 0 | ... AF7: =Summary!AF39 -> 44.5
A9: FR
A10: Quantities | B10: ='AMAZON UK, FR, GER - P&L'!B223 -> 1 | C10: ='AMAZON UK, FR, GER - P&L'!C223 -> 1 | D10: ='AMAZON UK, FR, GER - P&L'!D223 -> 0 | E10: ='AMAZON UK, FR, GER - P&L'!E223 -> 0 | F10: ='AMAZON UK, FR, GER - P&L'!F223 -> 1 | G10: ='AMAZON UK, FR, GER - P&L'!G223 -> 0 | H10: ='AMAZON UK, FR, GER - P&L'!H223 -> 1 | I10: ='AMAZON UK, FR, GER - P&L'!I223 -> 0 | ... AF10: ='AMAZON UK, FR, GER - P&L'!AF223 -> 0
A11: Sales | B11: =Summary!B40 -> 365.55 | C11: =Summary!C40 -> 474.15 | D11: =Summary!D40 -> 40.32 | E11: =Summary!E40 -> 0 | F11: =Summary!F40 -> 381.38 | G11: =Summary!G40 -> 0 | H11: =Summary!H40 -> 383.6 | I11: =Summary!I40 -> 0 | ... AF11: =Summary!AF40 -> 0
A13: GR
A14: Quantities | B14: ='AMAZON UK, FR, GER - P&L'!B409 -> 0 | C14: ='AMAZON UK, FR, GER - P&L'!C409 -> 0 | D14: ='AMAZON UK, FR, GER - P&L'!D409 -> 1 | E14: ='AMAZON UK, FR, GER - P&L'!E409 -> 0 | F14: ='AMAZON UK, FR, GER - P&L'!F409 -> 0 | G14: ='AMAZON UK, FR, GER - P&L'!G409 -> 0 | H14: ='AMAZON UK, FR, GER - P&L'!H409 -> 4 | I14: ='AMAZON UK, FR, GER - P&L'!I409 -> 5 | ... AF14: ='AMAZON UK, FR, GER - P&L'!AF409 -> 0
A15: Sales | B15: =Summary!B41 -> 0 | C15: =Summary!C41 -> 0 | D15: =Summary!D41 -> 379.95 | E15: =Summary!E41 -> 0 | F15: =Summary!F41 -> 0 | G15: =Summary!G41 -> 0 | H15: =Summary!H41 -> 1363.72 | I15: =Summary!I41 -> 1697.58 | ... AF15: =Summary!AF41 -> 0
A17: Spent US | B17: =Summary!B152 -> 2516.45 | C17: =Summary!C152 -> 2084.29 | D17: =Summary!D152 -> 2139.06 | E17: =Summary!E152 -> 2187.44 | F17: =Summary!F152 -> 2242.09 | G17: =Summary!G152 -> 2170.97 | H17: =Summary!H152 -> 8267.02 | I17: =Summary!I152 -> 10880.35 | ... AF17: =Summary!AF152 -> 2618.32
A18: Spent UK | B18: =Summary!B154 -> 103.91 | C18: =Summary!C154 -> 59.24 | D18: =Summary!D154 -> 36.87 | E18: =Summary!E154 -> 34.24 | F18: =Summary!F154 -> 38.27 | G18: =Summary!G154 -> 36.68 | H18: =Summary!H154 -> 49.12 | I18: =Summary!I154 -> 26.91 | ... AF18: =Summary!AF154 -> 87.24
A19: Spent FR | B19: =Summary!B155 -> 57.2 | C19: =Summary!C155 -> 93.11 | D19: =Summary!D155 -> 88.68 | E19: =Summary!E155 -> 132.88 | F19: =Summary!F155 -> 133.27 | G19: =Summary!G155 -> 101.41 | H19: =Summary!H155 -> 106.09 | I19: =Summary!I155 -> 92.64 | ... AF19: =Summary!AF155 -> 90.11
A20: Spent GR | B20: =Summary!B156 -> 50.34 | C20: =Summary!C156 -> 27.94 | D20: =Summary!D156 -> 93.51 | E20: =Summary!E156 -> 41.32 | F20: =Summary!F156 -> 85.55 | G20: =Summary!G156 -> 32.88 | H20: =Summary!H156 -> 87.81 | I20: =Summary!I156 -> 58.8 | ... AF20: =Summary!AF156 -> 105.97

Sheet DTC_Data_Forecast
B1: 45809 | C1: 45810 | D1: 45811 | E1: 45812 | F1: 45813 | G1: 45814 | H1: 45815 | I1: 45816 | J1: 45817 | K1: 45818 | L1: 45819 | M1: 45820 | N1: 45821 | O1: 45822 | P1: 45823 | Q1: 45824 | R1: 45825 | S1: 45826 | T1: 45827 | U1: 45828 | V1: 45829 | W1: 45830 | X1: 45831 | Y1: 45832 | Z1: 45833 | AA1: 45834 | AB1: 45835 | AC1: 45836 | AD1: 45837 | AE1: 45838 | AF1: 45839
A2: Quantities | B2: ='DTC - P&L'!B66 -> 24 | C2: ='DTC - P&L'!C66 -> 16 | D2: ='DTC - P&L'!D66 -> 25 | E2: ='DTC - P&L'!E66 -> 14 | F2: ='DTC - P&L'!F66 -> 24 | G2: ='DTC - P&L'!G66 -> 23 | H2: ='DTC - P&L'!H66 -> 15 | I2: ='DTC - P&L'!I66 -> 17 | ... AF2: ='DTC - P&L'!AF66 -> 34
A3: Sales | B3: =Summary!B12-Summary!B28 -> 8605.7804 | C3: =Summary!C12-Summary!C28 -> 7879.3831 | D3: =Summary!D12-Summary!D28 -> 10324.478 | E3: =Summary!E12-Summary!E28 -> 6222.0866 | F3: =Summary!F12-Summary!F28 -> 8526.0997 | G3: =Summary!G12-Summary!G28 -> 8264.87 | H3: =Summary!H12-Summary!H28 -> 5625.3745 | I3: =Summary!I12-Summary!I28 -> 6852.3095 | ... AF3: =Summary!AF12-Summary!AF28 -> 12980.27
A5: DTC US
A6: Quantities | B6: ='DTC US&CA - P&L'!B34 -> 22 | C6: ='DTC US&CA - P&L'!C34 -> 14 | D6: ='DTC US&CA - P&L'!D34 -> 24 | E6: ='DTC US&CA - P&L'!E34 -> 13 | F6: ='DTC US&CA - P&L'!F34 -> 21 | G6: ='DTC US&CA - P&L'!G34 -> 23 | H6: ='DTC US&CA - P&L'!H34 -> 14 | I6: ='DTC US&CA - P&L'!I34 -> 14 | ... AF6: ='DTC US&CA - P&L'!AF34 -> 32
A7: Sales | B7: =Summary!B13 -> 7970.72 | C7: =Summary!C13 -> 7200.56 | D7: =Summary!D13 -> 9890.75 | E7: =Summary!E13 -> 5880.1 | F7: =Summary!F13 -> 7497.64 | G7: =Summary!G13 -> 8264.87 | H7: =Summary!H13 -> 5198.91 | I7: =Summary!I13 -> 5730.87 | ... AF7: =Summary!AF13 -> 12054.38
A9: DTC EU
A10: Quantities | B10: ='DTC EU - P&L'!B33 -> 2 | C10: ='DTC EU - P&L'!C33 -> 2 | D10: ='DTC EU - P&L'!D33 -> 1 | E10: ='DTC EU - P&L'!E33 -> 1 | F10: ='DTC EU - P&L'!F33 -> 3 | G10: ='DTC EU - P&L'!G33 -> 0 | H10: ='DTC EU - P&L'!H33 -> 1 | I10: ='DTC EU - P&L'!I33 -> 3 | ... AF10: ='DTC EU - P&L'!AF33 -> 2
A11: Sales | B11: =Summary!B21 -> 635.06036 | C11: =Summary!C21 -> 678.82308 | D11: =Summary!D21 -> 433.72771 | E11: =Summary!E21 -> 341.98663 | F11: =Summary!F21 -> 1028.4597 | G11: =Summary!G21 -> 0 | H11: =Summary!H21 -> 426.4645 | I11: =Summary!I21 -> 1121.4395 | ... AF11: =Summary!AF21 -> 925.89039
A14: Spent US | B14: =Summary!B145+Summary!B148+Summary!B150+Summary!B151 -> 3918.03 | C14: =Summary!C145+Summary!C148+Summary!C150+Summary!C151 -> 3419.1 | D14: =Summary!D145+Summary!D148+Summary!D150+Summary!D151 -> 2727.21 | E14: =Summary!E145+Summary!E148+Summary!E150+Summary!E151 -> 2505.73 | F14: =Summary!F145+Summary!F148+Summary!F150+Summary!F151 -> 3418.96 | G14: =Summary!G145+Summary!G148+Summary!G150+Summary!G151 -> 3974.08 | H14: =Summary!H145+Summary!H148+Summary!H150+Summary!H151 -> 2858.83 | I14: =Summary!I145+Summary!I148+Summary!I150+Summary!I151 -> 1161.27 | ... AF14: =Summary!AF145+Summary!AF148+Summary!AF150+Summary!AF151 -> 8523.6
A15: Spent EU | B15: =Summary!B165 -> 0 | C15: =Summary!C165 -> 0 | D15: =Summary!D165 -> 0 | E15: =Summary!E165 -> 0 | F15: =Summary!F165 -> 0 | G15: =Summary!G165 -> 0 | H15: =Summary!H165 -> 0.95 | I15: =Summary!I165 -> 0 | ... AF15: =Summary!AF165 -> 1.14
A17: DTC US
A18: Quantities | B18: ='DTC US&CA - P&L'!B34+'DTC US&CA - P&L'!B38 -> 24 | C18: ='DTC US&CA - P&L'!C34+'DTC US&CA - P&L'!C38 -> 22 | D18: ='DTC US&CA - P&L'!D34+'DTC US&CA - P&L'!D38 -> 29 | E18: ='DTC US&CA - P&L'!E34+'DTC US&CA - P&L'!E38 -> 17 | F18: ='DTC US&CA - P&L'!F34+'DTC US&CA - P&L'!F38 -> 23 | G18: ='DTC US&CA - P&L'!G34+'DTC US&CA - P&L'!G38 -> 27 | H18: ='DTC US&CA - P&L'!H34+'DTC US&CA - P&L'!H38 -> 16 | I18: ='DTC US&CA - P&L'!I34+'DTC US&CA - P&L'!I38 -> 17 | ... AF18: ='DTC US&CA - P&L'!AF34+'DTC US&CA - P&L'!AF38 -> 38
A19: Sales w/o renewals | B19: =Summary!B13 -> 7970.72 | C19: =Summary!C13 -> 7200.56 | D19: =Summary!D13 -> 9890.75 | E19: =Summary!E13 -> 5880.1 | F19: =Summary!F13 -> 7497.64 | G19: =Summary!G13 -> 8264.87 | H19: =Summary!H13 -> 5198.91 | I19: =Summary!I13 -> 5730.87 | ... AF19: =Summary!AF13 -> 12054.38
A20: Sales with renewals | B20: =Summary!B13+Summary!B29 -> 11810.27 | C20: =Summary!C13+Summary!C29 -> 9270.32 | D20: =Summary!D13+Summary!D29 -> 12350.47 | E20: =Summary!E13+Summary!E29 -> 7559.91 | F20: =Summary!F13+Summary!F29 -> 9177.45 | G20: =Summary!G13+Summary!G29 -> 9644.71 | H20: =Summary!H13+Summary!H29 -> 6788.64 | I20: =Summary!I13+Summary!I29 -> 7380.68 | ... AF20: =Summary!AF13+Summary!AF29 -> 13753.17

Sheet Summary
B1: 45931 | C1: 45932 | D1: 45933 | E1: 45934 | F1: 45935 | G1: 45936 | H1: 45937 | I1: 45938 | J1: 45939 | K1: 45940 | L1: 45941 | M1: 45942 | N1: 45943 | O1: 45944 | P1: 45945 | Q1: 45946 | R1: 45947 | S1: 45948 | T1: 45949 | U1: 45950 | V1: 45951 | W1: 45952 | X1: 45953 | Y1: 45954 | Z1: 45955 | AA1: 45956 | AB1: 45957 | AC1: 45958 | AD1: 45959 | AE1: 45960 | AF1: 45961
B2: WED | C2: THU | D2: FRI | E2: SAT | F2: SUN | G2: MON | H2: TUE | I2: WED | J2: THU | K2: FRI | L2: SAT | M2: SUN | N2: MON | O2: TUE | P2: WED | Q2: THU | R2: FRI | S2: SAT | T2: SUN | U2: MON | V2: TUE | W2: WED | X2: THU | Y2: FRI | Z2: SAT | AA2: SUN | AB2: MON | AC2: TUE | AD2: WED | AE2: THU | AF2: FRI
A3: Notes | B3: Halloween Sale | H3: PRIME DAY AMZ | N3: Halloween Sale | X3: Halloween Sale
B4: Halloween Sale New MT Pricing and theme change | D4: Duplicate site with MAP pricing for Tom (Meta ads) (DTC US) | G4: Climate Badge Aquired for: HBF Pro feeders (AMZ US) | I4: Membership page removed (because of FPM Price test) DTC US | J4: Lifetime Warranty A/B test LIVE | K4: Make Add-on widgets clickable (DTC/Cart US/EU) | O4: Woo account transfer Flowout --> Birdbuddy | P4: Membership Page US/EU | Remove Unlimited Storage Information | Q4: BFCM Special lander deployed on production (LP Pricing) | W4: Remove Nature Cam Pro from DTC US/EU | X4: Remove Nature Cam Pro from DTC US/EU | Y4: Birdbuddy Seeds as Add-on: Buddy Bites 20 lbs RRP: $59 LP: $39 Discount: 34% (DTC US/Storefront/add-ons) | AB4: Warranty A/B Pricing Test Active $19.99 vs $39.99 | AC4: Add-on cart A/B test 3 Revenue Goal added(DTC US) | AD4: ApplePay & Google Pay Work on Thank You Page Upsell | AE4: Giftbag Test stopped and deployed on production. 1x SBF in the cart gets a gift bag offer $19.99 at checkout (DTC US/Checkout)
B5: FPM Thank You Page A/B test OFF (DTC US) | D5: Giftwrap Test Convert Recalibration | G5: 'Shipping in October'' and pre-order post-purchase emails removed from: HBF Pro HBF, Pro Solar, Nature Station | I5: BB2 PDP - Shipping info removed | K5: Bird Bath Card live (DTC/Shop US) | P5: Webflow monthly plan enabled ($29/month) for Christmas Advertorial Page | W5: Warranty Test on TYP finished. Lifestyle was set as default DTC US/EU | X5: Add-on cart A/B test 3 (DTC US) | AC5: Convert - Staging tests turned off while tests are running on production (duplicate | AE5: Amazon QR code test stopped. Only SBF will be offered (DTC US)
B6: Add-on Cart A/B test OFF (DTC US) | D6: BB2 Help Page redirect | G6: BB naming updated DTC US | K6: Change CTA buttons on: Buy Now (DTC/pdp's US/EU) | P6: Ultimate Guide Page US/EU - New edits were published | W6: FPM Price set to $98.99 (DTC US/EU) | X6: Remove Audobon mentions/widgets from D2C and Woo emails | AC6: Checkout & Thank You Page Optimization DONE (DTC US/EU) | AE6: Add-on Pop-up A/B test stopped (DTC US/cart)
B7: FPM Pricing Test ON (DTC US /cart) | G7: Woo email naming updated | X7: Holiday Bundle BBS4073AAA Live SKU3 V2 - $399 $239 Family Premium - $98.99 $69.99 Gift Bag - $19.90 FREE ———————————————————————— SUBTOTAL: $517.89 $308.99 Discount: $209 OFF | AE7: New MAPtest2 - updated MAP prices and query string ?MAPtest --> ?MAPtest2
B8: WOO - Order cancelation reason added for CE | AE8: Wall mount OOS (DTC US)
B9: FPM opt-in not included if NS is in the cart (DTC US) | AE9: CA Cookie Banner Implementation (DTC US)
B10: Snapchat Plugin - Active (DTC US)
A12: DTC Revenue | B12: =SUM(B13,B21,B28) -> 12539.758 | C12: =SUM(C13,C21,C28) -> 9949.1431 | D12: =SUM(D13,D21,D28) -> 12784.198 | E12: =SUM(E13,E21,E28) -> 7901.8966 | F12: =SUM(F13,F21,F28) -> 10290.26 | G12: =SUM(G13,G21,G28) -> 9644.71 | H12: =SUM(H13,H21,H28) -> 7215.1045 | I12: =SUM(I13,I21,I28) -> 8589.3703 | ... AF12: =SUM(AF13,AF21,AF28) -> 14679.06
A13: - DTC Revenue US&CA | B13: =sum(B14:B20) -> 7970.72 | C13: =sum(C14:C20) -> 7200.56 | D13: =sum(D14:D20) -> 9890.75 | E13: =sum(E14:E20) -> 5880.1 | F13: =sum(F14:F20) -> 7497.64 | G13: =sum(G14:G20) -> 8264.87 | H13: =sum(H14:H20) -> 5198.91 | I13: =sum(I14:I20) -> 5730.87 | ... AF13: =sum(AF14:AF20) -> 12054.38
A14: - Hardware | B14: 5646 | C14: 5118 | D14: 7031 | E14: 3935.3 | F14: 5527 | G14: 5734.2 | H14: 3674 | I14: 4053 | J14: 6009.2 | K14: 6195 | L14: 4730.99 | M14: 7470.52 | N14: 6464 | O14: 6623 | P14: 5155.65 | Q14: 6155 | R14: 7753.5 | S14: 7258.2 | T14: 9006.33 | U14: 9515.98 | V14: 7888.15 | W14: 14770.3 | X14: 9848.99 | Y14: 8726.28 | Z14: 11457.08 | AA14: 10880.99 | AB14: 10246.99 | AC14: 10195.44 | AD14: 8793.49 | AE14: 7129.18 | AF14: 9072
A15: - Add-ons | B15: 569 | C15: 637 | D15: 820 | E15: 334 | F15: 273 | G15: 715 | H15: 386 | I15: 412 | J15: 723 | K15: 251 | L15: 757 | M15: 954.67 | N15: 706 | O15: 328 | P15: 1280.67 | Q15: 209 | R15: 1070.8 | S15: 868 | T15: 1079.67 | U15: 540 | V15: 1173.6 | W15: 1244.67 | X15: 1054 | Y15: 623.9 | Z15: 1219.5 | AA15: 731 | AB15: 580 | AC15: 332.5 | AD15: 423 | AE15: 273 | AF15: 371
A16: - Merch | B16: 0 | C16: 0 | D16: 0 | E16: 0 | F16: 0 | G16: 0 | H16: 0 | I16: 0 | J16: 0 | K16: 0 | L16: 0 | M16: 0 | N16: 0 | O16: 0 | P16: 0 | Q16: 0 | R16: 0 | S16: 0 | T16: 0 | U16: 0 | V16: 0 | W16: 0 | X16: 0 | Y16: 0 | Z16: 0 | AA16: 0 | AB16: 0 | AC16: 0 | AD16: 0 | AE16: 0 | AF16: 0
A17: - Seeds | B17: 236.2 | C17: 169.5 | D17: 345.9 | E17: 435.7 | F17: 323.9 | G17: 242 | H17: 257.9 | I17: 216.4 | J17: 388.9 | K17: 133.6 | L17: 408.7 | M17: 269.1 | N17: 89.7 | O17: 116.6 | P17: 289.1 | Q17: 244.2 | R17: 119.6 | S17: 119.6 | T17: 229.3 | U17: 179.4 | V17: 216.4 | W17: 89.7 | X17: 186.5 | Y17: 338.65 | Z17: 425.4 | AA17: 456.1 | AB17: 341.2 | AC17: 380.5 | AD17: 207.7 | AE17: 146.9 | AF17: 367.1
A18: - Taxes | B18: 707.8 | C18: 497.34 | D18: 697.65 | E18: 476.16 | F18: 519.22 | G18: 635.71 | H18: 318.27 | I18: 431.09 | J18: 540.24 | K18: 591.25 | L18: 448.45 | M18: 728.76 | N18: 689.27 | O18: 617.91 | P18: 615.41 | Q18: 597.45 | R18: 817.77 | S18: 722.35 | T18: 713.49 | U18: 826.71 | V18: 833.65 | W18: 1236.14 | X18: 966.48 | Y18: 778.49 | Z18: 1078.69 | AA18: 1041.19 | AB18: 969.49 | AC18: 867.46 | AD18: 739.31 | AE18: 1377.52 | AF18: 799.56
A19: - Shipping | B19: 702.42 | C19: 629.62 | D19: 842.2 | E19: 534.31 | F19: 655.62 | G19: 803.76 | H19: 508.04 | I19: 523.98 | J19: 701.5 | K19: 697.74 | L19: 589.8 | M19: 943.21 | N19: 773.38 | O19: 754.38 | P19: 639.62 | Q19: 678.93 | R19: 976.2 | S19: 868.14 | T19: 1097.72 | U19: 1056.79 | V19: 998.1 | W19: 1683.88 | X19: 1225.33 | Y19: 1050.19 | Z19: 1398.47 | AA19: 1202.3 | AB19: 1165.42 | AC19: 1145.42 | AD19: 1012.32 | AE19: 796.37 | AF19: 1046.72
A20: - Gift Bag | B20: 109.3 | C20: 149.1 | D20: 154 | E20: 164.63 | F20: 198.9 | G20: 134.2 | H20: 54.7 | I20: 94.4 | J20: 44.7 | K20: 189 | L20: 89.4 | M20: 188.9 | N20: 89.5 | O20: 59.7 | P20: 86.07 | Q20: 149.2 | R20: 208.8 | S20: 154.1 | T20: 223.8 | U20: 174.1 | V20: 159.2 | W20: 238.8 | X20: 79.6 | Y20: 79.6 | Z20: 113.43 | AA20: 159.2 | AB20: 79.6 | AC20: 89.5 | AD20: 169.1 | AE20: 218.9 | AF20: 398
A21: - DTC Revenue EU | B21: =SUM(B22:B27) -> 635.06036 | C21: =SUM(C22:C27) -> 678.82308 | D21: =SUM(D22:D27) -> 433.72771 | E21: =SUM(E22:E27) -> 341.98663 | F21: =SUM(F22:F27) -> 1028.4597 | G21: =SUM(G22:G27) -> 0 | H21: =SUM(H22:H27) -> 426.4645 | I21: =SUM(I22:I27) -> 1121.4395 | ... AF21: =SUM(AF22:AF27) -> 925.89039
A22: - Hardware | B22: ='DTC EU - P&L'!B15*B$143 -> 500.58844 | C22: ='DTC EU - P&L'!C15*C$143 -> 447.52517 | D22: ='DTC EU - P&L'!D15*D$143 -> 259.95479 | E22: ='DTC EU - P&L'!E15*E$143 -> 196.25936 | F22: ='DTC EU - P&L'!F15*F$143 -> 682.58555 | G22: ='DTC EU - P&L'!G15*G$143 -> 0 | H22: ='DTC EU - P&L'!H15*H$143 -> 245.52462 | I22: ='DTC EU - P&L'!I15*I$143 -> 650.17543 | ... AF22: ='DTC EU - P&L'!AF15*AF$143 -> 501.02776
A23: - Add-ons | B23: ='DTC EU - P&L'!B16*B$143 -> 24.651033 | C23: ='DTC EU - P&L'!C16*C$143 -> 47.649454 | D23: ='DTC EU - P&L'!D16*D$143 -> 66.958586 | E23: ='DTC EU - P&L'!E16*E$143 -> 37.831574 | F23: ='DTC EU - P&L'!F16*F$143 -> 37.763891 | G23: ='DTC EU - P&L'!G16*G$143 -> 0 | H23: ='DTC EU - P&L'!H16*H$143 -> 61.59978 | I23: ='DTC EU - P&L'!I16*I$143 -> 166.10126 | ... AF23: ='DTC EU - P&L'!AF16*AF$143 -> 173.13001
A24: - Merch | B24: ='DTC EU - P&L'!B17*B$143 -> 0 | C24: ='DTC EU - P&L'!C17*C$143 -> 0 | D24: ='DTC EU - P&L'!D17*D$143 -> 0 | E24: ='DTC EU - P&L'!E17*E$143 -> 0 | F24: ='DTC EU - P&L'!F17*F$143 -> 0 | G24: ='DTC EU - P&L'!G17*G$143 -> 0 | H24: ='DTC EU - P&L'!H17*H$143 -> 0 | I24: ='DTC EU - P&L'!I17*I$143 -> 0 | ... AF24: ='DTC EU - P&L'!AF17*AF$143 -> 0
A25: - Seeds | B25: ='DTC EU - P&L'!B18*B$143 -> 0 | C25: ='DTC EU - P&L'!C18*C$143 -> 0 | D25: ='DTC EU - P&L'!D18*D$143 -> 0 | E25: ='DTC EU - P&L'!E18*E$143 -> 0 | F25: ='DTC EU - P&L'!F18*F$143 -> 0 | G25: ='DTC EU - P&L'!G18*G$143 -> 0 | H25: ='DTC EU - P&L'!H18*H$143 -> 0 | I25: ='DTC EU - P&L'!I18*I$143 -> 0 | ... AF25: ='DTC EU - P&L'!AF18*AF$143 -> 0
A26: - Taxes | B26: ='DTC EU - P&L'!B20*B$143 -> 80.48838 | C26: ='DTC EU - P&L'!C20*C$143 -> 125.05345 | D26: ='DTC EU - P&L'!D20*D$143 -> 65.713828 | E26: ='DTC EU - P&L'!E20*E$143 -> 66.812696 | F26: ='DTC EU - P&L'!F20*F$143 -> 220.23273 | G26: ='DTC EU - P&L'!G20*G$143 -> 0 | H26: ='DTC EU - P&L'!H20*H$143 -> 78.5301 | I26: ='DTC EU - P&L'!I20*I$143 -> 206.26528 | ... AF26: ='DTC EU - P&L'!AF20*AF$143 -> 158.87662
A27: - Shipping | B27: ='DTC EU - P&L'!B21*B$143 -> 29.3325 | C27: ='DTC EU - P&L'!C21*C$143 -> 58.595 | D27: ='DTC EU - P&L'!D21*D$143 -> 41.1005 | E27: ='DTC EU - P&L'!E21*E$143 -> 41.083 | F27: ='DTC EU - P&L'!F21*F$143 -> 87.8775 | G27: ='DTC EU - P&L'!G21*G$143 -> 0 | H27: ='DTC EU - P&L'!H21*H$143 -> 40.81 | I27: ='DTC EU - P&L'!I21*I$143 -> 98.8975 | ... AF27: ='DTC EU - P&L'!AF21*AF$143 -> 92.856
A28: - Yearly Premium Subscription | B28: =sum(B29:B30) -> 3933.9772 | C28: =sum(C29:C30) -> 2069.76 | D28: =sum(D29:D30) -> 2459.72 | E28: =sum(E29:E30) -> 1679.81 | F28: =sum(F29:F30) -> 1764.1607 | G28: =sum(G29:G30) -> 1379.84 | H28: =sum(H29:H30) -> 1589.73 | I28: =sum(I29:I30) -> 1737.0609 | ... AF28: =sum(AF29:AF30) -> 1698.79
A29: - Yearly Premium Subscription US&CA | B29: 3839.55 | C29: 2069.76 | D29: 2459.72 | E29: 1679.81 | F29: 1679.81 | G29: 1379.84 | H29: 1589.73 | I29: 1649.81 | J29: 1619.82 | K29: 1409.84 | L29: 959.89 | M29: 2159.75 | N29: 1529.8 | O29: 1799.78 | P29: 1649.72 | Q29: 2459.72 | R29: 2549.61 | S29: 2759.69 | T29: 1349.84 | U29: 1529.81 | V29: 1289.85 | W29: 2369.72 | X29: 1739.79 | Y29: 2308.72 | Z29: 1809.77 | AA29: 3108.62 | AB29: 2988.63 | AC29: 2999.64 | AD29: 1178.86 | AE29: 25149.39 | AF29: 1698.79
A30: - Yearly Premium Subscription EU | B30: ='DTC EU - P&L'!B19*B$143 -> 94.427184 | C30: ='DTC EU - P&L'!C19*C$143 -> 0 | D30: ='DTC EU - P&L'!D19*D$143 -> 0 | E30: ='DTC EU - P&L'!E19*E$143 -> 0 | F30: ='DTC EU - P&L'!F19*F$143 -> 84.350683 | G30: ='DTC EU - P&L'!G19*G$143 -> 0 | H30: ='DTC EU - P&L'!H19*H$143 -> 0 | I30: ='DTC EU - P&L'!I19*I$143 -> 87.250865 | ... AF30: ='DTC EU - P&L'!AF19*AF$143 -> 0
A31: Amazon Revenue | B31: =sum(B32,B38) -> 4779.61 | C31: =sum(C32,C38) -> 8636.61 | D31: =sum(D32,D38) -> 6081.55 | E31: =sum(E32,E38) -> 7265.88 | F31: =sum(F32,F38) -> 7430.04 | G31: =sum(G32,G38) -> 4593.61 | H31: =sum(H32,H38) -> 42819.01 | I31: =sum(I32,I38) -> 47876.17 | ... AF31: =sum(AF32,AF38) -> 5864.41
A32: Amazon Revenue US | B32: =B33+B34+B35+B36+B37 -> 4277.26 | C32: =C33+C34+C35+C36+C37 -> 8057.58 | D32: =D33+D34+D35+D36+D37 -> 5661.28 | E32: =E33+E34+E35+E36+E37 -> 6498.59 | F32: =F33+F34+F35+F36+F37 -> 7048.66 | G32: =G33+G34+G35+G36+G37 -> 4593.61 | H32: =H33+H34+H35+H36+H37 -> 41026.28 | I32: =I33+I34+I35+I36+I37 -> 46178.59 | ... AF32: =AF33+AF34+AF35+AF36+AF37 -> 5819.91
A33: - Hardware | B33: 3885 | C33: 7382 | D33: 5230 | E33: 5848 | F33: 6456 | G33: 4134 | H33: 37960.25 | I33: 42698 | J33: 24350.65 | K33: 5718 | L33: 7820 | M33: 5210 | N33: 5230 | O33: 5031 | P33: 1614 | Q33: 2053 | R33: 4624 | S33: 6219 | T33: 3189 | U33: 5023 | V33: 4126 | W33: 4903 | X33: 7853 | Y33: 7343.04 | Z33: 7355 | AA33: 4365 | AB33: 5322 | AC33: 7415 | AD33: 3827 | AE33: 6478 | AF33: 5322
A34: - Add-ons | B34: 116 | C34: 165 | D34: 68 | E34: 185 | F34: 116 | G34: 136 | H34: 262 | I34: 427 | J34: 223 | K34: 136 | L34: 213 | M34: 87 | N34: 58 | O34: 107 | P34: 87 | Q34: 97 | R34: 58 | S34: 97 | T34: 87 | U34: 126 | V34: 126 | W34: 39 | X34: 146 | Y34: 68 | Z34: 291 | AA34: 204 | AB34: 136 | AC34: 68 | AD34: 68 | AE34: 155 | AF34: 97
A35: - Tax | B35: 259.98 | C35: 506.09 | D35: 358.79 | E35: 458.68 | F35: 476.66 | G35: 319.12 | H35: 2777.09 | I35: 3037.62 | J35: 1711.31 | K35: 414.1 | L35: 602.38 | M35: 392.54 | N35: 383.55 | O35: 352.09 | P35: 94.23 | Q35: 136.91 | R35: 324.96 | S35: 463.7 | T35: 217.07 | U35: 396.78 | V35: 314.57 | W35: 338.82 | X35: 587.73 | Y35: 501.74 | Z35: 571.7 | AA35: 276.61 | AB35: 421.8 | AC35: 525.4 | AD35: 298.31 | AE35: 421.08 | AF35: 400.91
A36: - Shipping | B36: 11.79 | C36: 0 | D36: 0 | E36: 6.91 | F36: 0 | G36: 0 | H36: 8.98 | I36: 6.99 | J36: 0 | K36: 0 | L36: 0 | M36: 0 | N36: 10.7 | O36: 0 | P36: 0 | Q36: 0 | R36: 0 | S36: 0 | T36: 0 | U36: 0 | V36: 0 | W36: 6.99 | X36: 0 | Y36: 0 | Z36: 0 | AA36: 13.98 | AB36: 11.42 | AC36: 0 | AD36: 0 | AE36: 0 | AF36: 0
A37: - Gift Wrap | B37: 4.49 | C37: 4.49 | D37: 4.49 | E37: 0 | F37: 0 | G37: 4.49 | H37: 17.96 | I37: 8.98 | J37: 4.49 | K37: 13.47 | L37: 8.98 | M37: 4.49 | N37: 0 | O37: 8.98 | P37: 0 | Q37: 0 | R37: 8.98 | S37: 8.98 | T37: 0 | U37: 0 | V37: 0 | W37: 0 | X37: 13.47 | Y37: 8.98 | Z37: 4.49 | AA37: 4.49 | AB37: 4.49 | AC37: 0 | AD37: 0 | AE37: 0 | AF37: 0
A38: Amazon Revenue EU | B38: ='AMAZON EU - P&L'!B32 -> 502.35 | C38: ='AMAZON EU - P&L'!C32 -> 579.03 | D38: ='AMAZON EU - P&L'!D32 -> 420.27 | E38: ='AMAZON EU - P&L'!E32 -> 767.29 | F38: ='AMAZON EU - P&L'!F32 -> 381.38 | G38: ='AMAZON EU - P&L'!G32 -> 0 | H38: ='AMAZON EU - P&L'!H32 -> 1792.73 | I38: ='AMAZON EU - P&L'!I32 -> 1697.58 | ... AF38: ='AMAZON EU - P&L'!AF32 -> 44.5
A39: Amazon Revenue UK | B39: ='AMAZON UK, FR, GER - P&L'!B26 -> 136.8 | C39: ='AMAZON UK, FR, GER - P&L'!C26 -> 104.88 | D39: ='AMAZON UK, FR, GER - P&L'!D26 -> 0 | E39: ='AMAZON UK, FR, GER - P&L'!E26 -> 767.29 | F39: ='AMAZON UK, FR, GER - P&L'!F26 -> 0 | G39: ='AMAZON UK, FR, GER - P&L'!G26 -> 0 | H39: ='AMAZON UK, FR, GER - P&L'!H26 -> 45.41 | I39: ='AMAZON UK, FR, GER - P&L'!I26 -> 0 | ... AF39: ='AMAZON UK, FR, GER - P&L'!AF26 -> 44.5
A40: Amazon Revenue FR | B40: ='AMAZON UK, FR, GER - P&L'!B212 -> 365.55 | C40: ='AMAZON UK, FR, GER - P&L'!C212 -> 474.15 | D40: ='AMAZON UK, FR, GER - P&L'!D212 -> 40.32 | E40: ='AMAZON UK, FR, GER - P&L'!E212 -> 0 | F40: ='AMAZON UK, FR, GER - P&L'!F212 -> 381.38 | G40: ='AMAZON UK, FR, GER - P&L'!G212 -> 0 | H40: ='AMAZON UK, FR, GER - P&L'!H212 -> 383.6 | I40: ='AMAZON UK, FR, GER - P&L'!I212 -> 0 | ... AF40: ='AMAZON UK, FR, GER - P&L'!AF212 -> 0
A41: Amazon Revenue GER | B41: ='AMAZON UK, FR, GER - P&L'!B398 -> 0 | C41: ='AMAZON UK, FR, GER - P&L'!C398 -> 0 | D41: ='AMAZON UK, FR, GER - P&L'!D398 -> 379.95 | E41: ='AMAZON UK, FR, GER - P&L'!E398 -> 0 | F41: ='AMAZON UK, FR, GER - P&L'!F398 -> 0 | G41: ='AMAZON UK, FR, GER - P&L'!G398 -> 0 | H41: ='AMAZON UK, FR, GER - P&L'!H398 -> 1363.72 | I41: ='AMAZON UK, FR, GER - P&L'!I398 -> 1697.58 | ... AF41: ='AMAZON UK, FR, GER - P&L'!AF398 -> 0
...

Sheet Chewy P&L
A1: OCTOBER | B1: 45931 | C1: 45932 | D1: 45933 | E1: 45934 | F1: 45935 | G1: 45936 | H1: 45937 | I1: 45938 | J1: 45939 | K1: 45940 | L1: 45941 | M1: 45942 | N1: 45943 | O1: 45944 | P1: 45945 | Q1: 45946 | R1: 45947 | S1: 45948 | T1: 45949 | U1: 45950 | V1: 45951 | W1: 45952 | X1: 45953 | Y1: 45954 | Z1: 45955 | AA1: 45956 | AB1: 45957 | AC1: 45958 | AD1: 45959 | AE1: 45960 | AF1: 45961
A2: DAY | B2: WED | C2: THU | D2: FRI | E2: SAT | F2: SUN | G2: MON | H2: TUE | I2: WED | J2: THU | K2: FRI | L2: SAT | M2: SUN | N2: MON | O2: TUE | P2: WED | Q2: THU | R2: FRI | S2: SAT | T2: SUN | U2: MON | V2: TUE | W2: WED | X2: THU | Y2: FRI | Z2: SAT | AA2: SUN | AB2: MON | AC2: TUE | AD2: WED | AE2: THU | AF2: FRI | AG2: SUM
A3: Orders | B3: =Summary!B127 -> 3 | C3: =Summary!C127 -> 0 | D3: =Summary!D127 -> 0 | E3: =Summary!E127 -> 2 | F3: =Summary!F127 -> 1 | G3: =Summary!G127 -> 0 | H3: =Summary!H127 -> 2 | I3: =Summary!I127 -> 4 | ... AF3: =Summary!AF127 -> 2 | AG3: =SUM(B3:AF3) -> 35
A4: Revenue | B4: =Summary!B63 -> 92.3418 | C4: =Summary!C63 -> 0 | D4: =Summary!D63 -> 0 | E4: =Summary!E63 -> 316.2972 | F4: =Summary!F63 -> 30.7806 | G4: =Summary!G63 -> 0 | H4: =Summary!H63 -> 228.201 | I4: =Summary!I63 -> 690.01614 | ... AF4: =Summary!AF63 -> 348.38332 | AG4: =SUM(B4:AF4) -> 5873.5647
A5: - Hardware | B5: =Summary!B64 -> 87 | C5: =Summary!C64 -> 0 | D5: =Summary!D64 -> 0 | E5: =Summary!E64 -> 298 | F5: =Summary!F64 -> 29 | G5: =Summary!G64 -> 0 | H5: =Summary!H64 -> 215 | I5: =Summary!I64 -> 650.1 | ... AF5: =Summary!AF64 -> 328.23 | AG5: =SUM(B5:AF5) -> 5533.79
A6: - Tax | B6: =Summary!B65 -> 5.3418 | C6: =Summary!C65 -> 0 | D6: =Summary!D65 -> 0 | E6: =Summary!E65 -> 18.2972 | F6: =Summary!F65 -> 1.7806 | G6: =Summary!G65 -> 0 | H6: =Summary!H65 -> 13.201 | I6: =Summary!I65 -> 39.91614 | ... AF6: =Summary!AF65 -> 20.153322 | AG6: =SUM(B6:AF6) -> 339.77471
A7: - Shipping | B7: =Summary!B66 | C7: =Summary!C66 | D7: =Summary!D66 | E7: =Summary!E66 | F7: =Summary!F66 | G7: =Summary!G66 | H7: =Summary!H66 | I7: =Summary!I66 | ... AF7: =Summary!AF66 | AG7: =SUM(B7:AF7) -> 0
A9: FROM ADS MANAGER
A10: - Sales | B10: 0 | C10: 0 | D10: 0 | E10: 0 | F10: 0 | G10: 0 | H10: 0 | I10: 0 | J10: 0 | K10: 0 | L10: 0 | M10: 0 | N10: 0 | O10: 0 | P10: 0 | Q10: 0 | R10: 0 | S10: 0 | T10: 0 | U10: 0 | V10: 0 | W10: 0 | X10: 0 | Y10: 0 | Z10: 0 | AA10: 0 | AB10: 0 | AC10: 0 | AD10: 0 | AE10: 0 | AF10: 0 | AG10: =SUM(B10:AF10) -> 0
A11: - Orders | B11: 0 | C11: 0 | D11: 0 | E11: 0 | F11: 0 | G11: 0 | H11: 0 | I11: 0 | J11: 0 | K11: 0 | L11: 0 | M11: 0 | N11: 0 | O11: 0 | P11: 0 | Q11: 0 | R11: 0 | S11: 0 | T11: 0 | U11: 0 | V11: 0 | W11: 0 | X11: 0 | Y11: 0 | Z11: 0 | AA11: 0 | AB11: 0 | AC11: 0 | AD11: 0 | AE11: 0 | AF11: 0 | AG11: =SUM(B11:AF11) -> 0
A12: - Spend | B12: =Summary!B159 -> 0 | C12: =Summary!C159 -> 0 | D12: =Summary!D159 -> 0 | E12: =Summary!E159 -> 0 | F12: =Summary!F159 -> 0 | G12: =Summary!G159 -> 0 | H12: =Summary!H159 -> 0 | I12: =Summary!I159 -> 0 | ... AF12: =Summary!AF159 -> 0 | AG12: =SUM(B12:AF12) -> 0
A14: Units Sold | B14: =B24+B28 -> 0 | C14: =C24+C28 -> 0 | D14: =D24+D28 -> 0 | E14: =E24+E28 -> 1 | F14: =F24+F28 -> 0 | G14: =G24+G28 -> 0 | H14: =H24+H28 -> 1 | I14: =I24+I28 -> 3 | ... AG14: =AG24+AG28 -> 20
A15: SKU 1 - Blue | B15: 0 | C15: 0 | D15: 0 | E15: 0 | F15: 0 | G15: 0 | H15: 0 | I15: 0 | J15: 0 | K15: 0 | L15: 0 | M15: 0 | N15: 0 | O15: 0 | P15: 0 | Q15: 0 | R15: 0 | S15: 0 | T15: 0 | U15: 0 | V15: 0 | W15: 0 | X15: 0 | Y15: 0 | Z15: 0 | AA15: 0 | AB15: 0 | AC15: 0 | AD15: 0 | AE15: 0 | AF15: 0 | AG15: =sum(B15:AF15) -> 0
A16: SKU 2 - Yellow | B16: 0 | C16: 0 | D16: 0 | E16: 0 | F16: 0 | G16: 0 | H16: 0 | I16: 0 | J16: 0 | K16: 0 | L16: 0 | M16: 0 | N16: 0 | O16: 0 | P16: 0 | Q16: 0 | R16: 0 | S16: 0 | T16: 0 | U16: 0 | V16: 0 | W16: 0 | X16: 0 | Y16: 0 | Z16: 0 | AA16: 0 | AB16: 0 | AC16: 0 | AD16: 0 | AE16: 0 | AF16: 0 | AG16: =sum(B16:AF16) -> 0
A17: SKU 3 - Blue w/ Solar | B17: 0 | C17: 0 | D17: 0 | E17: 0 | F17: 0 | G17: 0 | H17: 0 | I17: 0 | J17: 0 | K17: 0 | L17: 0 | M17: 0 | N17: 0 | O17: 0 | P17: 0 | Q17: 0 | R17: 0 | S17: 0 | T17: 0 | U17: 0 | V17: 0 | W17: 0 | X17: 0 | Y17: 0 | Z17: 0 | AA17: 0 | AB17: 0 | AC17: 0 | AD17: 0 | AE17: 0 | AF17: 0 | AG17: =sum(B17:AF17) -> 0
A18: SKU 4 - Yellow w/ Solar | B18: 0 | C18: 0 | D18: 0 | E18: 0 | F18: 0 | G18: 0 | H18: 0 | I18: 0 | J18: 0 | K18: 0 | L18: 0 | M18: 0 | N18: 0 | O18: 0 | P18: 0 | Q18: 0 | R18: 0 | S18: 0 | T18: 0 | U18: 0 | V18: 0 | W18: 0 | X18: 0 | Y18: 0 | Z18: 0 | AA18: 0 | AB18: 0 | AC18: 0 | AD18: 0 | AE18: 0 | AF18: 0 | AG18: =sum(B18:AF18) -> 0
A19: SKU 1 - Blue PRO | B19: 0 | C19: 0 | D19: 0 | E19: 0 | F19: 0 | G19: 0 | H19: 1 | I19: 1 | J19: 2 | K19: 0 | L19: 2 | M19: 0 | N19: 1 | O19: 0 | P19: 0 | Q19: 0 | R19: 0 | S19: 0 | T19: 0 | U19: 0 | V19: 0 | W19: 0 | X19: 0 | Y19: 0 | Z19: 0 | AA19: 0 | AB19: 0 | AC19: 0 | AD19: 0 | AE19: 0 | AF19: 0 | AG19: =sum(B19:AF19) -> 7
A20: SKU 2 - Yellow PRO | B20: 0 | C20: 0 | D20: 0 | E20: 0 | F20: 0 | G20: 0 | H20: 0 | I20: 0 | J20: 0 | K20: 0 | L20: 0 | M20: 0 | N20: 0 | O20: 0 | P20: 0 | Q20: 0 | R20: 0 | S20: 0 | T20: 0 | U20: 0 | V20: 0 | W20: 0 | X20: 0 | Y20: 0 | Z20: 0 | AA20: 0 | AB20: 0 | AC20: 0 | AD20: 0 | AE20: 0 | AF20: 0 | AG20: =sum(B20:AF20) -> 0
A21: SKU 3 - Blue w/ Solar PRO | B21: 0 | C21: 0 | D21: 0 | E21: 1 | F21: 0 | G21: 0 | H21: 0 | I21: 2 | J21: 0 | K21: 0 | L21: 0 | M21: 0 | N21: 0 | O21: 1 | P21: 0 | Q21: 0 | R21: 1 | S21: 0 | T21: 0 | U21: 0 | V21: 0 | W21: 0 | X21: 0 | Y21: 0 | Z21: 0 | AA21: 0 | AB21: 0 | AC21: 0 | AD21: 0 | AE21: 0 | AF21: 0 | AG21: =sum(B21:AF21) -> 5
A22: SKU 4 - Yellow w/ Solar PRO | B22: 0 | C22: 0 | D22: 0 | E22: 0 | F22: 0 | G22: 0 | H22: 0 | I22: 0 | J22: 0 | K22: 0 | L22: 0 | M22: 0 | N22: 0 | O22: 0 | P22: 0 | Q22: 0 | R22: 0 | S22: 0 | T22: 0 | U22: 0 | V22: 0 | W22: 0 | X22: 0 | Y22: 0 | Z22: 0 | AA22: 0 | AB22: 0 | AC22: 0 | AD22: 0 | AE22: 0 | AF22: 0 | AG22: =sum(B22:AF22) -> 0
A23: BBS4052RAA | B23: 0 | C23: 0 | D23: 0 | E23: 0 | F23: 0 | G23: 0 | H23: 0 | I23: 0 | J23: 0 | K23: 0 | L23: 1 | M23: 0 | N23: 0 | O23: 0 | P23: 1 | Q23: 1 | R23: 1 | S23: 0 | T23: 0 | U23: 0 | V23: 0 | W23: 0 | X23: 0 | Y23: 1 | Z23: 1 | AA23: 0 | AB23: 0 | AC23: 0 | AD23: 0 | AE23: 1 | AF23: 1 | AG23: =sum(B23:AF23) -> 8
A24: SUM (SKU 1 - SKU 4) | B24: =sum(B15:B23) -> 0 | C24: =sum(C15:C23) -> 0 | D24: =sum(D15:D23) -> 0 | E24: =sum(E15:E23) -> 1 | F24: =sum(F15:F23) -> 0 | G24: =sum(G15:G23) -> 0 | H24: =sum(H15:H23) -> 1 | I24: =sum(I15:I23) -> 3 | ... AF24: =sum(AF15:AF23) -> 1 | AG24: =sum(B24:AF24) -> 20
A26: SKU 5 - HBF | B26: 0 | C26: 0 | D26: 0 | E26: 0 | F26: 0 | G26: 0 | H26: 0 | I26: 0 | J26: 0 | K26: 0 | L26: 0 | M26: 0 | N26: 0 | O26: 0 | P26: 0 | Q26: 0 | R26: 0 | S26: 0 | T26: 0 | U26: 0 | V26: 0 | W26: 0 | X26: 0 | Y26: 0 | Z26: 0 | AA26: 0 | AB26: 0 | AC26: 0 | AD26: 0 | AE26: 0 | AF26: 0 | AG26: =sum(B26:AF26) -> 0
A27: SKU 6 - HBF w/ Solar | B27: 0 | C27: 0 | D27: 0 | E27: 0 | F27: 0 | G27: 0 | H27: 0 | I27: 0 | J27: 0 | K27: 0 | L27: 0 | M27: 0 | N27: 0 | O27: 0 | P27: 0 | Q27: 0 | R27: 0 | S27: 0 | T27: 0 | U27: 0 | V27: 0 | W27: 0 | X27: 0 | Y27: 0 | Z27: 0 | AA27: 0 | AB27: 0 | AC27: 0 | AD27: 0 | AE27: 0 | AF27: 0 | AG27: =sum(B27:AF27) -> 0
A28: SUM (SKU 5 - SKU 6) | B28: =SUM(B26:B27) -> 0 | C28: =SUM(C26:C27) -> 0 | D28: =SUM(D26:D27) -> 0 | E28: =SUM(E26:E27) -> 0 | F28: =SUM(F26:F27) -> 0 | G28: =SUM(G26:G27) -> 0 | H28: =SUM(H26:H27) -> 0 | I28: =SUM(I26:I27) -> 0 | ... AF28: =SUM(AF26:AF27) -> 0 | AG28: =sum(B28:AF28) -> 0
A30: Wall Mount | B30: 0 | C30: 0 | D30: 0 | E30: 0 | F30: 0 | G30: 0 | H30: 0 | I30: 0 | J30: 0 | K30: 0 | L30: 0 | M30: 0 | N30: 0 | O30: 0 | P30: 0 | Q30: 0 | R30: 0 | S30: 0 | T30: 0 | U30: 0 | V30: 0 | W30: 0 | X30: 0 | Y30: 0 | Z30: 0 | AA30: 0 | AB30: 0 | AC30: 0 | AD30: 0 | AE30: 0 | AF30: 0 | AG30: =sum(B30:AF30) -> 0
A31: Suet Ball Holder | B31: 0 | C31: 0 | D31: 0 | E31: 0 | F31: 0 | G31: 0 | H31: 0 | I31: 0 | J31: 0 | K31: 0 | L31: 0 | M31: 0 | N31: 0 | O31: 0 | P31: 0 | Q31: 0 | R31: 0 | S31: 0 | T31: 0 | U31: 0 | V31: 0 | W31: 0 | X31: 0 | Y31: 0 | Z31: 0 | AA31: 0 | AB31: 0 | AC31: 0 | AD31: 0 | AE31: 0 | AF31: 0 | AG31: =sum(B31:AF31) -> 0
A32: 3-in-1 Nutrition Set - Blue | B32: 0 | C32: 0 | D32: 0 | E32: 0 | F32: 0 | G32: 0 | H32: 0 | I32: 0 | J32: 0 | K32: 0 | L32: 0 | M32: 0 | N32: 0 | O32: 0 | P32: 0 | Q32: 0 | R32: 0 | S32: 0 | T32: 0 | U32: 0 | V32: 0 | W32: 0 | X32: 0 | Y32: 0 | Z32: 0 | AA32: 0 | AB32: 0 | AC32: 0 | AD32: 0 | AE32: 0 | AF32: 0 | AG32: =sum(B32:AF32) -> 0
A33: 3-in-1 Nutrition Set - Yellow | B33: 0 | C33: 0 | D33: 0 | E33: 0 | F33: 0 | G33: 0 | H33: 0 | I33: 0 | J33: 0 | K33: 0 | L33: 0 | M33: 0 | N33: 0 | O33: 0 | P33: 0 | Q33: 0 | R33: 0 | S33: 0 | T33: 0 | U33: 0 | V33: 0 | W33: 0 | X33: 0 | Y33: 0 | Z33: 0 | AA33: 0 | AB33: 0 | AC33: 0 | AD33: 0 | AE33: 0 | AF33: 0 | AG33: =sum(B33:AF33) -> 0
A34: Solar Roof Single - Blue | B34: 0 | C34: 0 | D34: 0 | E34: 0 | F34: 0 | G34: 0 | H34: 0 | I34: 0 | J34: 0 | K34: 0 | L34: 0 | M34: 0 | N34: 0 | O34: 0 | P34: 0 | Q34: 0 | R34: 0 | S34: 0 | T34: 0 | U34: 0 | V34: 0 | W34: 0 | X34: 0 | Y34: 0 | Z34: 0 | AA34: 0 | AB34: 0 | AC34: 0 | AD34: 0 | AE34: 0 | AF34: 0 | AG34: =sum(B34:AF34) -> 0
A35: Solar Roof Single - Yellow | B35: 0 | C35: 0 | D35: 0 | E35: 0 | F35: 0 | G35: 0 | H35: 0 | I35: 0 | J35: 0 | K35: 0 | L35: 0 | M35: 0 | N35: 0 | O35: 0 | P35: 0 | Q35: 0 | R35: 0 | S35: 0 | T35: 0 | U35: 0 | V35: 0 | W35: 0 | X35: 0 | Y35: 0 | Z35: 0 | AA35: 0 | AB35: 0 | AC35: 0 | AD35: 0 | AE35: 0 | AF35: 0 | AG35: =sum(B35:AF35) -> 0
A36: Perch Extender - Blue | B36: 3 | C36: 0 | D36: 0 | E36: 1 | F36: 1 | G36: 0 | H36: 1 | I36: 1 | J36: 0 | K36: 1 | L36: 1 | M36: 1 | N36: 0 | O36: 0 | P36: 0 | Q36: 0 | R36: 0 | S36: 0 | T36: 0 | U36: 2 | V36: 0 | W36: 0 | X36: 0 | Y36: 0 | Z36: 0 | AA36: 0 | AB36: 0 | AC36: 0 | AD36: 1 | AE36: 1 | AF36: 1 | AG36: =sum(B36:AF36) -> 15
A37: Perch Extender - Yellow | B37: 0 | C37: 0 | D37: 0 | E37: 0 | F37: 0 | G37: 0 | H37: 0 | I37: 0 | J37: 0 | K37: 0 | L37: 0 | M37: 0 | N37: 0 | O37: 0 | P37: 0 | Q37: 0 | R37: 0 | S37: 0 | T37: 0 | U37: 0 | V37: 0 | W37: 0 | X37: 0 | Y37: 0 | Z37: 0 | AA37: 0 | AB37: 0 | AC37: 0 | AD37: 0 | AE37: 0 | AF37: 0 | AG37: =sum(B37:AF37) -> 0
A38: Solar Roof (HBF) | B38: 0 | C38: 0 | D38: 0 | E38: 0 | F38: 0 | G38: 0 | H38: 0 | I38: 0 | J38: 0 | K38: 0 | L38: 0 | M38: 0 | N38: 0 | O38: 0 | P38: 0 | Q38: 0 | R38: 0 | S38: 0 | T38: 0 | U38: 0 | V38: 0 | W38: 0 | X38: 0 | Y38: 0 | Z38: 0 | AA38: 0 | AB38: 0 | AC38: 0 | AD38: 0 | AE38: 0 | AF38: 0 | AG38: =sum(B38:AF38) -> 0
A39: Housing - only (HBF) | B39: 0 | C39: 0 | D39: 0 | E39: 0 | F39: 0 | G39: 0 | H39: 0 | I39: 0 | J39: 0 | K39: 0 | L39: 0 | M39: 0 | N39: 0 | O39: 0 | P39: 0 | Q39: 0 | R39: 0 | S39: 0 | T39: 0 | U39: 0 | V39: 0 | W39: 0 | X39: 0 | Y39: 0 | Z39: 0 | AA39: 0 | AB39: 0 | AC39: 0 | AD39: 0 | AE39: 0 | AF39: 0 | AG39: =sum(B39:AF39) -> 0
A40: Nature Cam PRO | B40: 0 | C40: 0 | D40: 0 | E40: 0 | F40: 0 | G40: 0 | H40: 0 | I40: 0 | J40: 0 | K40: 0 | L40: 0 | M40: 0 | N40: 0 | O40: 0 | P40: 0 | Q40: 0 | R40: 0 | S40: 0 | T40: 0 | U40: 0 | V40: 0 | W40: 0 | X40: 0 | Y40: 0 | Z40: 0 | AA40: 0 | AB40: 0 | AC40: 0 | AD40: 0 | AE40: 0 | AF40: 0 | AG40: =sum(B40:AF40) -> 0
A41: SUM (Add-ons) | B41: =sum(B30:B40) -> 3 | C41: =sum(C30:C40) -> 0 | D41: =sum(D30:D40) -> 0 | E41: =sum(E30:E40) -> 1 | F41: =sum(F30:F40) -> 1 | G41: =sum(G30:G40) -> 0 | H41: =sum(H30:H40) -> 1 | I41: =sum(I30:I40) -> 1 | ... AF41: =sum(AF30:AF40) -> 1 | AG41: =sum(B41:AF41) -> 15

Sheet DTC - P&L
A1: OCTOBER | B1: 45931 | C1: 45932 | D1: 45933 | E1: 45934 | F1: 45935 | G1: 45936 | H1: 45937 | I1: 45938 | J1: 45939 | K1: 45940 | L1: 45941 | M1: 45942 | N1: 45943 | O1: 45944 | P1: 45945 | Q1: 45946 | R1: 45947 | S1: 45948 | T1: 45949 | U1: 45950 | V1: 45951 | W1: 45952 | X1: 45953 | Y1: 45954 | Z1: 45955 | AA1: 45956 | AB1: 45957 | AC1: 45958 | AD1: 45959 | AE1: 45960 | AF1: 45961
A2: DAY | B2: WED | C2: THU | D2: FRI | E2: SAT | F2: SUN | G2: MON | H2: TUE | I2: WED | J2: THU | K2: FRI | L2: SAT | M2: SUN | N2: MON | O2: TUE | P2: WED | Q2: THU | R2: FRI | S2: SAT | T2: SUN | U2: MON | V2: TUE | W2: WED | X2: THU | Y2: FRI | Z2: SAT | AA2: SUN | AB2: MON | AC2: TUE | AD2: WED | AE2: THU | AF2: FRI
A3: COMMENT
A4: Orders
A5: Meta | B5: 9 | C5: 16 | D5: 10 | E5: 4 | F5: 8 | G5: 6 | H5: 6 | I5: 4 | J5: 5 | K5: 2 | L5: 7 | M5: 11 | N5: 8 | O5: 10 | P5: 10 | Q5: 7 | R5: 17 | S5: 16 | T5: 16 | U5: 8 | V5: 10 | W5: 13 | X5: 16 | Y5: 16 | Z5: 24 | AA5: 20 | AB5: 15 | AC5: 15 | AD5: 13 | AE5: 14 | AF5: 18 | AG5: =SUM(B5:AF5) -> 354
A6: Google | B6: 7 | C6: 6 | D6: 22 | E6: 11 | F6: 7 | G6: 13 | H6: 6 | I6: 10 | J6: 5 | K6: 8 | L6: 9 | M6: 11 | N6: 14 | O6: 6 | P6: 5 | Q6: 9 | R6: 14 | S6: 12 | T6: 19 | U6: 17 | V6: 16 | W6: 18 | X6: 12 | Y6: 10 | Z6: 16 | AA6: 21 | AB6: 12 | AC6: 15 | AD6: 12 | AE6: 14 | AF6: 18 | AG6: =SUM(B6:AF6) -> 375
A7: TikTok | B7: 0 | C7: 0 | D7: 0 | E7: 0 | F7: 0 | G7: 0 | H7: 0 | I7: 0 | J7: 0 | K7: 0 | L7: 0 | M7: 0 | N7: 0 | O7: 0 | P7: 0 | Q7: 0 | R7: 0 | S7: 0 | T7: 0 | U7: 0 | V7: 0 | W7: 0 | X7: 0 | Y7: 0 | Z7: 0 | AA7: 0 | AB7: 0 | AC7: 0 | AD7: 0 | AE7: 0 | AF7: 0 | AG7: =SUM(B7:AF7) -> 0
A8: Bing | B8: 0 | C8: 4 | D8: 2 | E8: 2 | F8: 6 | G8: 4 | H8: 0 | I8: 2 | J8: 4 | K8: 2 | L8: 2 | M8: 2 | N8: 2 | O8: 2 | P8: 2 | Q8: 2 | R8: 2 | S8: 0 | T8: 14 | U8: 2 | V8: 2 | W8: 6 | X8: 2 | Y8: 8 | Z8: 6 | AA8: 2 | AB8: 4 | AC8: 2 | AD8: 2 | AE8: 4 | AF8: 4 | AG8: =SUM(B8:AF8) -> 98
A9: Email | B9: 0 | C9: 0 | D9: 0 | E9: 0 | F9: 0 | G9: 0 | H9: 0 | I9: 0 | J9: 0 | K9: 0 | L9: 0 | M9: 0 | N9: 0 | O9: 0 | P9: 0 | Q9: 0 | R9: 0 | S9: 0 | T9: 0 | U9: 0 | V9: 0 | W9: 0 | X9: 0 | Y9: 0 | Z9: 0 | AA9: 0 | AB9: 0 | AC9: 0 | AD9: 0 | AE9: 0 | AF9: 0 | AG9: =SUM(B9:AF9) -> 0
A10: Nextdoor | B10: - | C10: - | D10: - | E10: - | F10: - | G10: - | H10: - | I10: - | J10: - | K10: - | L10: - | M10: - | N10: - | O10: - | P10: - | Q10: - | R10: - | S10: - | T10: - | U10: - | V10: - | W10: - | X10: - | Y10: - | Z10: - | AA10: - | AB10: - | AC10: - | AD10: - | AE10: - | AF10: - | AG10: =SUM(B10:AF10) -> 0
A11: Affiliates (Refersion) | B11: - | C11: - | D11: - | E11: - | F11: - | G11: - | H11: - | I11: - | J11: - | K11: - | L11: - | M11: - | N11: - | O11: - | P11: - | Q11: - | R11: - | S11: - | T11: - | U11: - | V11: - | W11: - | X11: - | Y11: - | Z11: - | AA11: - | AB11: - | AC11: - | AD11: - | AE11: - | AF11: - | AG11: =SUM(B11:AF11) -> 0
A12: All | B12: =SUM(B5:B11) -> 16 | C12: =SUM(C5:C11) -> 26 | D12: =SUM(D5:D11) -> 34 | E12: =SUM(E5:E11) -> 17 | F12: =SUM(F5:F11) -> 21 | G12: =SUM(G5:G11) -> 23 | H12: =SUM(H5:H11) -> 12 | I12: =SUM(I5:I11) -> 16 | ... AF12: =SUM(AF5:AF11) -> 40 | AG12: =SUM(B12:AF12) -> 827
A14: Revenue
A15: Meta | B15: 2592.57 | C15: 2662.87 | D15: 2214.87 | E15: 787.71 | F15: 1918.17 | G15: 1221.27 | H15: 1126.82 | I15: 643.75 | J15: 609.51 | K15: 386.8 | L15: 1318.69 | M15: 2579.83 | N15: 1800.47 | O15: 6322.72 | P15: 6322.72 | Q15: 2167.7 | R15: 4279.44 | S15: 3550.78 | T15: 4840.69 | U15: 3091.32 | V15: 3206.49 | W15: 7543.93 | X15: 5346.76 | Y15: 5450.48 | Z15: 7903.75 | AA15: 6443.44 | AB15: 4586.19 | AC15: 4877.24 | AD15: 4944.58 | AE15: 4467.99 | AF15: 5054.63 | AG15: =SUM(B15:AF15) -> 110264.18
A16: Google | B16: 1445.92 | C16: 1171.36 | D16: 5187.83 | E16: 3219.02 | F16: 1871.47 | G16: 2620.66 | H16: 1929.79 | I16: 2295.87 | J16: 1795.91 | K16: 2398.03 | L16: 2902.92 | M16: 2540.72 | N16: 4093.2 | O16: 1456.6 | P16: 1240.88 | Q16: 3008.8 | R16: 4251.42 | S16: 3287.28 | T16: 4062.02 | U16: 4889.86 | V16: 3774.98 | W16: 5883.2 | X16: 3108.53 | Y16: 3754.96 | Z16: 3362.87 | AA16: 5829.58 | AB16: 2966.91 | AC16: 4841.91 | AD16: 3454.43 | AE16: 4164.09 | AF16: 4592.14 | AG16: =SUM(B16:AF16) -> 101403.16
A17: TikTok | B17: 0 | C17: 0 | D17: 0 | E17: 0 | F17: 0 | G17: 0 | H17: 0 | I17: 0 | J17: 0 | K17: 0 | L17: 0 | M17: 0 | N17: 0 | O17: 0 | P17: 0 | Q17: 0 | R17: 0 | S17: 0 | T17: 0 | U17: 0 | V17: 0 | W17: 0 | X17: 0 | Y17: 0 | Z17: 0 | AA17: 0 | AB17: 0 | AC17: 0 | AD17: 0 | AE17: 0 | AF17: 0 | AG17: =SUM(B17:AF17) -> 0
A18: Bing | B18: 0 | C18: 502 | D18: 251 | E18: 251 | F18: 753 | G18: 502 | H18: 0 | I18: 251 | J18: 502 | K18: 251 | L18: 251 | M18: 251 | N18: 251 | O18: 251 | P18: 251 | Q18: 251 | R18: 251 | S18: 0 | T18: 1757 | U18: 251 | V18: 251 | W18: 753 | X18: 251 | Y18: 1004 | Z18: 753 | AA18: 251 | AB18: 502 | AC18: 251 | AD18: 251 | AE18: 502 | AF18: 502 | AG18: =SUM(B18:AF18) -> 12299
A19: Email | B19: 0 | C19: 0 | D19: 0 | E19: 0 | F19: 0 | G19: 0 | H19: 0 | I19: 0 | J19: 0 | K19: 0 | L19: 0 | M19: 0 | N19: 0 | O19: 0 | P19: 0 | Q19: 0 | R19: 0 | S19: 0 | T19: 0 | U19: 0 | V19: 0 | W19: 0 | X19: 0 | Y19: 0 | Z19: 0 | AA19: 0 | AB19: 0 | AC19: 0 | AD19: 0 | AE19: 0 | AF19: 0 | AG19: =SUM(B19:AF19) -> 0
A20: Nextdoor | B20: - | C20: - | D20: - | E20: - | F20: - | G20: - | H20: - | I20: - | J20: - | K20: - | L20: - | M20: - | N20: - | O20: - | P20: - | Q20: - | R20: - | S20: - | T20: - | U20: - | V20: - | W20: - | X20: - | Y20: - | Z20: - | AA20: - | AB20: - | AC20: - | AD20: - | AE20: - | AF20: -
A21: Affiliates (Refersion) | B21: - | C21: - | D21: - | E21: - | F21: - | G21: - | H21: - | I21: - | J21: - | K21: - | L21: - | M21: - | N21: - | O21: - | P21: - | Q21: - | R21: - | S21: - | T21: - | U21: - | V21: - | W21: - | X21: - | Y21: - | Z21: - | AA21: - | AB21: - | AC21: - | AD21: - | AE21: - | AF21: -
A22: All | B22: =SUM(B15:B21) -> 4038.49 | C22: =SUM(C15:C21) -> 4336.23 | D22: =SUM(D15:D21) -> 7653.7 | E22: =SUM(E15:E21) -> 4257.73 | F22: =SUM(F15:F21) -> 4542.64 | G22: =SUM(G15:G21) -> 4343.93 | H22: =SUM(H15:H21) -> 3056.61 | I22: =SUM(I15:I21) -> 3190.62 | ... AF22: =SUM(AF15:AF21) -> 10148.77 | AG22: =SUM(B22:AF22) -> 223966.34
A24: Media Cost
A25: Meta | B25: =Summary!B144 -> 3578.17 | C25: =Summary!C144 -> 2319.61 | D25: =Summary!D144 -> 1579.22 | E25: =Summary!E144 -> 1331.36 | F25: =Summary!F144 -> 2034.93 | G25: =Summary!G144 -> 2639.58 | H25: =Summary!H144 -> 1643.5 | I25: =Summary!I144 -> 200.94 | ... AF25: =Summary!AF144 -> 7337.42 | AG25: =SUM(B25:AF25) -> 105997.18
A26: Google | B26: =Summary!B147 -> 263.84 | C26: =Summary!C147 -> 226.3 | D26: =Summary!D147 -> 282.72 | E26: =Summary!E147 -> 342.99 | F26: =Summary!F147 -> 552.67 | G26: =Summary!G147 -> 482.37 | H26: =Summary!H147 -> 443.73 | I26: =Summary!I147 -> 466.66 | ... AF26: =Summary!AF147 -> 863.56 | AG26: =SUM(B26:AF26) -> 22602.7
A27: TikTok | B27: =Summary!B151 -> 0 | C27: =Summary!C151 -> 799.88 | D27: =Summary!D151 -> 799.64 | E27: =Summary!E151 -> 769.64 | F27: =Summary!F151 -> 799.48 | G27: =Summary!G151 -> 799.84 | H27: =Summary!H151 -> 727.33 | I27: =Summary!I151 -> 452.81 | ... AF27: =Summary!AF151 -> 219.95 | AG27: =SUM(B27:AF27) -> 11680.77
A28: Bing | B28: =Summary!B150 -> 76.02 | C28: =Summary!C150 -> 73.31 | D28: =Summary!D150 -> 65.63 | E28: =Summary!E150 -> 61.74 | F28: =Summary!F150 -> 31.88 | G28: =Summary!G150 -> 52.29 | H28: =Summary!H150 -> 45.22 | I28: =Summary!I150 -> 40.86 | ... AF28: =Summary!AF150 -> 103.81 | AG28: =SUM(B28:AF28) -> 1716.13
A29: Nextdoor | B29: - | C29: - | D29: - | E29: - | F29: - | G29: - | H29: - | I29: - | J29: - | K29: - | L29: - | M29: - | N29: - | O29: - | P29: - | Q29: - | R29: - | S29: - | T29: - | U29: - | V29: - | W29: - | X29: - | Y29: - | Z29: - | AA29: - | AB29: - | AC29: - | AD29: - | AE29: - | AF29: - | AG29: =SUM(B29:AF29) -> 0
A30: Affiliate Fee (20%) | B30: - | C30: - | D30: - | E30: - | F30: - | G30: - | H30: - | I30: - | J30: - | K30: - | L30: - | M30: - | N30: - | O30: - | P30: - | Q30: - | R30: - | S30: - | T30: - | U30: - | V30: - | W30: - | X30: - | Y30: - | Z30: - | AA30: - | AB30: - | AC30: - | AD30: - | AE30: - | AF30: - | AG30: =SUM(B30:AF30) -> 0
A31: All | B31: =SUM(B25:B30) -> 3918.03 | C31: =SUM(C25:C30) -> 3419.1 | D31: =SUM(D25:D30) -> 2727.21 | E31: =SUM(E25:E30) -> 2505.73 | F31: =SUM(F25:F30) -> 3418.96 | G31: =SUM(G25:G30) -> 3974.08 | H31: =SUM(H25:H30) -> 2859.78 | I31: =SUM(I25:I30) -> 1161.27 | ... AF31: =SUM(AF25:AF30) -> 8524.74 | AG31: =SUM(B31:AF31) -> 141996.78
A36: Revenue
A37: Revenue Woocommerce (Platform) | B37: =Summary!B12 -> 12539.758 | C37: =Summary!C12 -> 9949.1431 | D37: =Summary!D12 -> 12784.198 | E37: =Summary!E12 -> 7901.8966 | F37: =Summary!F12 -> 10290.26 | G37: =Summary!G12 -> 9644.71 | H37: =Summary!H12 -> 7215.1045 | I37: =Summary!I12 -> 8589.3703 | ... AF37: =Summary!AF12 -> 14679.06 | AG37: =SUM(B37:AF37) -> 423370.67
A38: Revenue w/o renewals | B38: ='DTC US&CA - P&L'!B6+'DTC EU - P&L'!B6 -> 8185.9226 | C38: ='DTC US&CA - P&L'!C6+'DTC EU - P&L'!C6 -> 7613.7131 | D38: ='DTC US&CA - P&L'!D6+'DTC EU - P&L'!D6 -> 9894.2777 | E38: ='DTC US&CA - P&L'!E6+'DTC EU - P&L'!E6 -> 5661.0966 | F38: ='DTC US&CA - P&L'!F6+'DTC EU - P&L'!F6 -> 8120.4091 | G38: ='DTC US&CA - P&L'!G6+'DTC EU - P&L'!G6 -> 7937.85 | H38: ='DTC US&CA - P&L'!H6+'DTC EU - P&L'!H6 -> 5296.1145 | I38: ='DTC US&CA - P&L'!I6+'DTC EU - P&L'!I6 -> 6538.317 | ... AF38: ='DTC US&CA - P&L'!AF6+'DTC EU - P&L'!AF6 -> 13108.17 | AG38: =SUM(B38:AF38) -> 331588.16
A39: SUM | B39: =SUM(B37) -> 12539.758 | C39: =SUM(C37) -> 9949.1431 | D39: =SUM(D37) -> 12784.198 | E39: =SUM(E37) -> 7901.8966 | F39: =SUM(F37) -> 10290.26 | G39: =SUM(G37) -> 9644.71 | H39: =SUM(H37) -> 7215.1045 | I39: =SUM(I37) -> 8589.3703 | ... AF39: =SUM(AF37) -> 14679.06 | AG39: =SUM(B39:AF39) -> 423370.67
A41: Orders
A42: Orders Woocommerce (Platform) | B42: =Summary!B96 -> 91 | C42: =Summary!C96 -> 59 | D42: =Summary!D96 -> 79 | E42: =Summary!E96 -> 59 | F42: =Summary!F96 -> 71 | G42: =Summary!G96 -> 63 | H42: =Summary!H96 -> 58 | I42: =Summary!I96 -> 58 | ... AF42: =Summary!AF96 -> 72 | AG42: =SUM(B42:AF42) -> 2414
A43: Orders w/o renewals | B43: ='DTC US&CA - P&L'!B11+'DTC EU - P&L'!B11 -> 37 | C43: ='DTC US&CA - P&L'!C11+'DTC EU - P&L'!C11 -> 30 | D43: ='DTC US&CA - P&L'!D11+'DTC EU - P&L'!D11 -> 40 | E43: ='DTC US&CA - P&L'!E11+'DTC EU - P&L'!E11 -> 28 | F43: ='DTC US&CA - P&L'!F11+'DTC EU - P&L'!F11 -> 40 | G43: ='DTC US&CA - P&L'!G11+'DTC EU - P&L'!G11 -> 39 | H43: ='DTC US&CA - P&L'!H11+'DTC EU - P&L'!H11 -> 31 | I43: ='DTC US&CA - P&L'!I11+'DTC EU - P&L'!I11 -> 32 | ... AF43: ='DTC US&CA - P&L'!AF11+'DTC EU - P&L'!AF11 -> 49 | AG43: =SUM(B43:AF43) -> 1276
A44: SUM | B44: =SUM(B42) -> 91 | C44: =SUM(C42) -> 59 | D44: =SUM(D42) -> 79 | E44: =SUM(E42) -> 59 | F44: =SUM(F42) -> 71 | G44: =SUM(G42) -> 63 | H44: =SUM(H42) -> 58 | I44: =SUM(I42) -> 58 | ... AF44: =SUM(AF42) -> 72 | AG44: =SUM(B44:AF44) -> 2414
A46: Breakdown
A47: - Hardware | B47: =Summary!B14+Summary!B22 -> 6146.5884 | C47: =Summary!C14+Summary!C22 -> 5565.5252 | D47: =Summary!D14+Summary!D22 -> 7290.9548 | E47: =Summary!E14+Summary!E22 -> 4131.5594 | F47: =Summary!F14+Summary!F22 -> 6209.5856 | G47: =Summary!G14+Summary!G22 -> 5734.2 | H47: =Summary!H14+Summary!H22 -> 3919.5246 | I47: =Summary!I14+Summary!I22 -> 4703.1754 | ... AF47: =Summary!AF14+Summary!AF22 -> 9573.0278 | AG47: =SUM(B47:AF47) -> 245439.36
A48: - Add-ons | B48: =Summary!B15+Summary!B23 -> 593.65103 | C48: =Summary!C15+Summary!C23 -> 684.64945 | D48: =Summary!D15+Summary!D23 -> 886.95859 | E48: =Summary!E15+Summary!E23 -> 371.83157 | F48: =Summary!F15+Summary!F23 -> 310.76389 | G48: =Summary!G15+Summary!G23 -> 715 | H48: =Summary!H15+Summary!H23 -> 447.59978 | I48: =Summary!I15+Summary!I23 -> 578.10126 | ... AF48: =Summary!AF15+Summary!AF23 -> 544.13001 | AG48: =SUM(B48:AF48) -> 23254.95
...

Sheet DTC US&CA - P&L
A1: OCTOBER | B1: 45931 | C1: 45932 | D1: 45933 | E1: 45934 | F1: 45935 | G1: 45936 | H1: 45937 | I1: 45938 | J1: 45939 | K1: 45940 | L1: 45941 | M1: 45942 | N1: 45943 | O1: 45944 | P1: 45945 | Q1: 45946 | R1: 45947 | S1: 45948 | T1: 45949 | U1: 45950 | V1: 45951 | W1: 45952 | X1: 45953 | Y1: 45954 | Z1: 45955 | AA1: 45956 | AB1: 45957 | AC1: 45958 | AD1: 45959 | AE1: 45960 | AF1: 45961
A2: DAY | B2: WED | C2: THU | D2: FRI | E2: SAT | F2: SUN | G2: MON | H2: TUE | I2: WED | J2: THU | K2: FRI | L2: SAT | M2: SUN | N2: MON | O2: TUE | P2: WED | Q2: THU | R2: FRI | S2: SAT | T2: SUN | U2: MON | V2: TUE | W2: WED | X2: THU | Y2: FRI | Z2: SAT | AA2: SUN | AB2: MON | AC2: TUE | AD2: WED | AE2: THU | AF2: FRI
A4: Revenue
A5: Revenue Woocommerce (Platform) | B5: =Summary!B13+Summary!B29 -> 11810.27 | C5: =Summary!C13+Summary!C29 -> 9270.32 | D5: =Summary!D13+Summary!D29 -> 12350.47 | E5: =Summary!E13+Summary!E29 -> 7559.91 | F5: =Summary!F13+Summary!F29 -> 9177.45 | G5: =Summary!G13+Summary!G29 -> 9644.71 | H5: =Summary!H13+Summary!H29 -> 6788.64 | I5: =Summary!I13+Summary!I29 -> 7380.68 | ... AF5: =Summary!AF13+Summary!AF29 -> 13753.17 | AG5: =SUM(B5:AF5) -> 400826.86
A6: Revenue w/o renewals | B6: 7572.58 | C6: 6934.89 | D6: 9460.55 | E6: 5319.11 | F6: 7113.04 | G6: 7937.85 | H6: 4869.65 | I6: 5434.33 | J6: 7945.11 | K6: 7864.73 | L6: 6567.7 | M6: 10196.91 | N6: 8642.88 | O6: 8326.78 | P6: 7689.26 | Q6: 7701.48 | R6: 10722.35 | S6: 9781.04 | T6: 12050.47 | U6: 12055.28 | V6: 10994.88 | W6: 19089.76 | X6: 13315.44 | Y6: 11738.42 | Z6: 16158.39 | AA6: 14565.3 | AB6: 13820.06 | AC6: 13207.82 | AD6: 11386.73 | AE6: 9630.31 | AF6: 12182.28
A7: SUM | B7: =SUM(B5) -> 11810.27 | C7: =SUM(C5) -> 9270.32 | D7: =SUM(D5) -> 12350.47 | E7: =SUM(E5) -> 7559.91 | F7: =SUM(F5) -> 9177.45 | G7: =SUM(G5) -> 9644.71 | H7: =SUM(H5) -> 6788.64 | I7: =SUM(I5) -> 7380.68 | ... AF7: =SUM(AF5) -> 13753.17 | AG7: =SUM(B7:AF7) -> 400826.86
A9: Orders
A10: Orders Woocommerce (Platform) | B10: =Summary!B97 -> 88 | C10: =Summary!C97 -> 57 | D10: =Summary!D97 -> 77 | E10: =Summary!E97 -> 57 | F10: =Summary!F97 -> 67 | G10: =Summary!G97 -> 63 | H10: =Summary!H97 -> 56 | I10: =Summary!I97 -> 53 | ... AF10: =Summary!AF97 -> 67 | AG10: =SUM(B10:AF10) -> 2319
