Workbook
Name zsupermetrics_ru0GDtbZzDLHQOQtJJ6K08MvUDyyp7: #REF!
Name zsupermetrics_DQl8lUbpTRu3fayaJJi7lVfOGKjNU4: 'Data - P&L'!$A$3:$A$4
Name zsupermetrics_BioPyGBzcBsy60UCQmPcTuFReEmghI: 'Data - P&L'!$B$2:$B$3
Name zsupermetrics_refreshAll: SupermetricsQueries!$H$5
Name zsupermetrics_n3GtLgiKpTmd2pYmQNMuq6TPD0qE0b: #REF!
Name zsupermetrics_refreshAllSilent: SupermetricsQueries!$H$6
Name zsupermetrics_Mgms9p0QzysYvrIhnsKACeVBVxfIEO: #REF!
Name zsupermetrics_Mgms9p0QzysYvrIhnsKACeVBVxfIEO: 'Data - P&L'!$A$2:$A$3
Name zsupermetrics_forceRefresh: SupermetricsQueries!$H$4
Name zsupermetrics_wbYMmT0YL9bAN0yhimW0ziPFnia9Dx: #REF!
Name zsupermetrics_iNpyVy90bWCI0yUaFQpxOtzWMa6sW4: #REF!
Name zsupermetrics_xwoIpANxRm908eDp5oKTwQpEI8gvD4: #REF!
Name zsupermetrics_n3GtLgiKpTmd2pYmQNMuq6TPD0qE0b: 'Data - P&L'!$B$4:$B$5
Name rdataslayer_42b112e4e4be4305bb4c1be75e2dd549: 'Data - P&L'!$B$2:$C$3
Name zsupermetrics_9i4W4hgd80uRpQLMeX0eRnESN8gjyv: #REF!
Name zsupermetrics_5bmwtOpHUbSYmDMeuCPkrxaojTprPP: #REF!
Name rdataslayer_3753ddf3234e496aa261974a0222e193: 'Data - P&L'!$H$2:$I$2
Name zsupermetrics_SGBxROnInO9rFyh3H7j2Lldx0Bdc5v: #REF!
Name zsupermetrics_pxuhRTEmIU93xSgKclyxajD0fCZ6rF: #REF!
Name zsupermetrics_ru0GDtbZzDLHQOQtJJ6K08MvUDyyp7: 'Data - P&L'!$B$4:$B$5
Name zsupermetrics_qWp7V908pNEYMtfv8QZvSTeDnBAHOU: 'Data - P&L'!$B$5:$C$13
Name rdataslayer_4a0f150f4f2f4e4f85c890c75b7a1fa4: #REF!
Name zsupermetrics_8xojRjNDjo2jWHGDWjFEhflhyIq3Hq: #REF!
Name zsupermetrics_HgZqhorObHOtZHuyJjpmyYaEPoYntx: #REF!
Name zsupermetrics_YsFuuYtr8vOdNXCCPiFJIO38NP4b2T: #REF!
Name zsupermetrics_DQl8lUbpTRu3fayaJJi7lVfOGKjNU4: #REF!
Name zsupermetrics_YVuzfmsfdurz7Ldl84Rfns8oka6LsS: #REF!
Name zsupermetrics_4VkB7ij7WO0JjKBEgvjB2GHjSy2Egm: #REF!
Name zsupermetrics_9i4W4hgd80uRpQLMeX0eRnESN8gjyv: 'Data - P&L'!$C$13
Name zsupermetrics_lx4cNai7gT6tH4j08ZRkI21Qlpjioi: #REF!
Name rdataslayer_d70e473bcafe40a3aa834ce157fb2ba3: #REF!
Name zsupermetrics_NugLlrQxlKiqhxQae8EFpITBm1pLCj: 'Data - P&L'!$B$6:$C$13
Name zsupermetrics_8xojRjNDjo2jWHGDWjFEhflhyIq3Hq: Summary!$K$12:$K$48
Name zsupermetrics_FEamnpN5FsVYF0RtUTXAwunZ388Tkc: Forecast!$A$113:$C$141
Name rdataslayer_3753ddf3234e496aa261974a0222e193: #REF!
Name zsupermetrics_iNpyVy90bWCI0yUaFQpxOtzWMa6sW4: 'Data - P&L'!$A$2:$A$3
Name rdataslayer_4a0f150f4f2f4e4f85c890c75b7a1fa4: 'Data - P&L'!$D$2:$E$3
Name zsupermetrics_BioPyGBzcBsy60UCQmPcTuFReEmghI: #REF!
Name zsupermetrics_qWp7V908pNEYMtfv8QZvSTeDnBAHOU: #REF!
Name zsupermetrics_wbYMmT0YL9bAN0yhimW0ziPFnia9Dx: 'Data - P&L'!$A$2:$A$3
Name zsupermetrics_4VkB7ij7WO0JjKBEgvjB2GHjSy2Egm: 'Data - P&L'!$B$4:$C$10
Name zsupermetrics_lx4cNai7gT6tH4j08ZRkI21Qlpjioi: 'Data - P&L'!$B$4:$C$13
Name rdataslayer_42b112e4e4be4305bb4c1be75e2dd549: #REF!
Name rdataslayer_adf57e64065742daa5b4161161b1c3ca: #REF!
Name rdataslayer_adf57e64065742daa5b4161161b1c3ca: 'Data - P&L'!$B$4:$D$5
Name zsupermetrics_NugLlrQxlKiqhxQae8EFpITBm1pLCj: #REF!
Name zsupermetrics_xwoIpANxRm908eDp5oKTwQpEI8gvD4: #REF!
Name zsupermetrics_YsFuuYtr8vOdNXCCPiFJIO38NP4b2T: 'Data - P&L'!$B$4:$C$13
Name rdataslayer_d70e473bcafe40a3aa834ce157fb2ba3: 'Data - P&L'!$C$8:$D$9
Name zsupermetrics_HgZqhorObHOtZHuyJjpmyYaEPoYntx: 'Data - P&L'!$B$4:$B$5

Sheet Data_forecast_2024
B1: 45809 | C1: 45810 | D1: 45811 | E1: 45812 | F1: 45813 | G1: 45814 | H1: 45815 | I1: 45816 | J1: 45817 | K1: 45818 | L1: 45819 | M1: 45820 | N1: 45821 | O1: 45822 | P1: 45823 | Q1: 45824 | R1: 45825 | S1: 45826 | T1: 45827 | U1: 45828 | V1: 45829 | W1: 45830 | X1: 45831 | Y1: 45832 | Z1: 45833 | AA1: 45834 | AB1: 45835 | AC1: 45836 | AD1: 45837 | AE1: 45838 | AF1: 45839
A2: Quantities | B2: ='DTC - P&L'!B59+'AMAZON US&CA - P&L'!B38+'WALMART - P&L'!B25+#REF!+#REF!+'Digital Marketplaces - P&L'!B21+'COSTCO - P&L'!B19 -> #REF! | C2: ='DTC - P&L'!C59+'AMAZON US&CA - P&L'!C38+'WALMART - P&L'!C25+#REF!+#REF!+'Digital Marketplaces - P&L'!C21+'COSTCO - P&L'!C19 -> #REF! | D2: ='DTC - P&L'!D59+'AMAZON US&CA - P&L'!D38+'WALMART - P&L'!D25+#REF!+#REF!+'Digital Marketplaces - P&L'!D21+'COSTCO - P&L'!D19 -> #REF! | E2: ='DTC - P&L'!E59+'AMAZON US&CA - P&L'!E38+'WALMART - P&L'!E25+#REF!+#REF!+'Digital Marketplaces - P&L'!E21+'COSTCO - P&L'!E19 -> #REF! | F2: ='DTC - P&L'!F59+'AMAZON US&CA - P&L'!F38+'WALMART - P&L'!F25+#REF!+#REF!+'Digital Marketplaces - P&L'!F21+'COSTCO - P&L'!F19 -> #REF! | G2: ='DTC - P&L'!G59+'AMAZON US&CA - P&L'!G38+'WALMART - P&L'!G25+#REF!+#REF!+'Digital Marketplaces - P&L'!G21+'COSTCO - P&L'!G19 -> #REF! | H2: ='DTC - P&L'!H59+'AMAZON US&CA - P&L'!H38+'WALMART - P&L'!H25+#REF!+#REF!+'Digital Marketplaces - P&L'!H21+'COSTCO - P&L'!H19 -> #REF! | I2: ='DTC - P&L'!I59+'AMAZON US&CA - P&L'!I38+'WALMART - P&L'!I25+#REF!+#REF!+'Digital Marketplaces - P&L'!I21+'COSTCO - P&L'!I19 -> #REF! | ... AF2: ='DTC - P&L'!AF59+'AMAZON US&CA - P&L'!AF38+'WALMART - P&L'!AF25+#REF!+#REF!+'Digital Marketplaces - P&L'!AF21+'COSTCO - P&L'!AF19 -> #REF!
A3: Sales | B3: =Summary!B48+Summary!B86+Summary!B78+Summary!B60 -> 146142.12 | C3: =Summary!C48+Summary!C86+Summary!C78+Summary!C60 -> 258926.64 | D3: =Summary!D48+Summary!D86+Summary!D78+Summary!D60 -> 311083.39 | E3: =Summary!E48+Summary!E86+Summary!E78+Summary!E60 -> 290191.27 | F3: =Summary!F48+Summary!F86+Summary!F78+Summary!F60 -> 246664.67 | G3: =Summary!G48+Summary!G86+Summary!G78+Summary!G60 -> 195495.82 | H3: =Summary!H48+Summary!H86+Summary!H78+Summary!H60 -> 156845.36 | I3: =Summary!I48+Summary!I86+Summary!I78+Summary!I60 -> 132492.52 | ... AF3: =Summary!AF48+Summary!AF86+Summary!AF78+Summary!AF60 -> 94639.443

Sheet WALMART_Data_forecast_2024
B1: 45809 | C1: 45810 | D1: 45811 | E1: 45812 | F1: 45813 | G1: 45814 | H1: 45815 | I1: 45816 | J1: 45817 | K1: 45818 | L1: 45819 | M1: 45820 | N1: 45821 | O1: 45822 | P1: 45823 | Q1: 45824 | R1: 45825 | S1: 45826 | T1: 45827 | U1: 45828 | V1: 45829 | W1: 45830 | X1: 45831 | Y1: 45832 | Z1: 45833 | AA1: 45834 | AB1: 45835 | AC1: 45836 | AD1: 45837 | AE1: 45838 | AF1: 45839
A2: Quantities | B2: ='WALMART - P&L'!B25 | C2: ='WALMART - P&L'!C25 | D2: ='WALMART - P&L'!D25 | E2: ='WALMART - P&L'!E25 | F2: ='WALMART - P&L'!F25 | G2: ='WALMART - P&L'!G25 | H2: ='WALMART - P&L'!H25 | I2: ='WALMART - P&L'!I25 | ... AF2: ='WALMART - P&L'!AF25
A3: Sales | B3: =Summary!B68 -> 1187.59 | C3: =Summary!C68 -> 1218.97 | D3: =Summary!D68 -> 1927.97 | E3: =Summary!E68 -> 2718.28 | F3: =Summary!F68 -> 1100.4 | G3: =Summary!G68 -> 669.03 | H3: =Summary!H68 -> 339.18 | I3: =Summary!I68 -> 0 | ... AF3: =Summary!AF68 -> 38.96

Sheet COSTCO_Data_forecast_2024
B1: 45809 | C1: 45749 | D1: 45750 | E1: 45751 | F1: 45752 | G1: 45753 | H1: 45754 | I1: 45755 | J1: 45756 | K1: 45757 | L1: 45758 | M1: 45759 | N1: 45760 | O1: 45761 | P1: 45762 | Q1: 45763 | R1: 45764 | S1: 45765 | T1: 45766 | U1: 45767 | V1: 45768 | W1: 45769 | X1: 45770 | Y1: 45771 | Z1: 45772 | AA1: 45773 | AB1: 45774 | AC1: 45775 | AD1: 45776 | AE1: 45777 | AF1: 45778
A2: Quantities | B2: ='COSTCO - P&L'!B19 -> #REF! | C2: ='COSTCO - P&L'!C19 -> #REF! | D2: ='COSTCO - P&L'!D19 -> #REF! | E2: ='COSTCO - P&L'!E19 -> #REF! | F2: ='COSTCO - P&L'!F19 -> #REF! | G2: ='COSTCO - P&L'!G19 -> #REF! | H2: ='COSTCO - P&L'!H19 -> #REF! | I2: ='COSTCO - P&L'!I19 -> #REF! | ... AF2: ='COSTCO - P&L'!AF19 -> #REF!
A3: Sales | B3: =Summary!B60 -> 0 | C3: =Summary!C60 -> 0 | D3: =Summary!D60 -> 0 | E3: =Summary!E60 -> 0 | F3: =Summary!F60 -> 0 | G3: =Summary!G60 -> 0 | H3: =Summary!H60 -> 0 | I3: =Summary!I60 -> 0 | ... AF3: =Summary!AF60 -> 0

Sheet DM_Data_forecast_2024
B1: 45809 | C1: 45810 | D1: 45811 | E1: 45812 | F1: 45813 | G1: 45814 | H1: 45815 | I1: 45816 | J1: 45817 | K1: 45818 | L1: 45819 | M1: 45820 | N1: 45821 | O1: 45822 | P1: 45823 | Q1: 45824 | R1: 45825 | S1: 45826 | T1: 45827 | U1: 45828 | V1: 45829 | W1: 45830 | X1: 45831 | Y1: 45832 | Z1: 45833 | AA1: 45834 | AB1: 45835 | AC1: 45836 | AD1: 45837 | AE1: 45838 | AF1: 45839
A2: Quantities | B2: =#REF!+#REF!+'Digital Marketplaces - P&L'!B21 -> #REF! | C2: =#REF!+#REF!+'Digital Marketplaces - P&L'!C21 -> #REF! | D2: =#REF!+#REF!+'Digital Marketplaces - P&L'!D21 -> #REF! | E2: =#REF!+#REF!+'Digital Marketplaces - P&L'!E21 -> #REF! | F2: =#REF!+#REF!+'Digital Marketplaces - P&L'!F21 -> #REF! | G2: =#REF!+#REF!+'Digital Marketplaces - P&L'!G21 -> #REF! | H2: =#REF!+#REF!+'Digital Marketplaces - P&L'!H21 -> #REF! | I2: =#REF!+#REF!+'Digital Marketplaces - P&L'!I21 -> #REF! | ... AF2: =#REF!+#REF!+'Digital Marketplaces - P&L'!AF21 -> #REF!
A3: Sales | B3: =Summary!B78 -> 0 | C3: =Summary!C78 -> 0 | D3: =Summary!D78 -> 0 | E3: =Summary!E78 -> 0 | F3: =Summary!F78 -> 0 | G3: =Summary!G78 -> 0 | H3: =Summary!H78 -> 0 | I3: =Summary!I78 -> 0 | ... AF3: =Summary!AF78 -> 0

Sheet AMAZON_Data_Forecast
A1: US | B1: 45809 | C1: 45810 | D1: 45811 | E1: 45812 | F1: 45813 | G1: 45814 | H1: 45815 | I1: 45816 | J1: 45817 | K1: 45818 | L1: 45819 | M1: 45820 | N1: 45821 | O1: 45822 | P1: 45823 | Q1: 45824 | R1: 45825 | S1: 45826 | T1: 45827 | U1: 45828 | V1: 45829 | W1: 45830 | X1: 45831 | Y1: 45832 | Z1: 45833 | AA1: 45834 | AB1: 45835 | AC1: 45836 | AD1: 45837 | AE1: 45838 | AF1: 45839
A2: Quantities | B2: ='AMAZON US&CA - P&L'!B38+'AMAZON US&CA - P&L'!B64 -> 0 | C2: ='AMAZON US&CA - P&L'!C38+'AMAZON US&CA - P&L'!C64 -> 0 | D2: ='AMAZON US&CA - P&L'!D38+'AMAZON US&CA - P&L'!D64 -> 0 | E2: ='AMAZON US&CA - P&L'!E38+'AMAZON US&CA - P&L'!E64 -> 0 | F2: ='AMAZON US&CA - P&L'!F38+'AMAZON US&CA - P&L'!F64 -> 0 | G2: ='AMAZON US&CA - P&L'!G38+'AMAZON US&CA - P&L'!G64 -> 0 | H2: ='AMAZON US&CA - P&L'!H38+'AMAZON US&CA - P&L'!H64 -> 0 | I2: ='AMAZON US&CA - P&L'!I38+'AMAZON US&CA - P&L'!I64 -> 0 | ... AF2: ='AMAZON US&CA - P&L'!AF38+'AMAZON US&CA - P&L'!AF64 -> 0
A3: Sales | B3: =Summary!B33 -> 41264.95 | C3: =Summary!C33 -> 59108.3 | D3: =Summary!D33 -> 106923.09 | E3: =Summary!E33 -> 100980.97 | F3: =Summary!F33 -> 90308.03 | G3: =Summary!G33 -> 64294.29 | H3: =Summary!H33 -> 59341.85 | I3: =Summary!I33 -> 38530.94 | ... AF3: =Summary!AF33 -> 18005.48
A5: UK
A6: Quantities | B6: ='AMAZON UK, FR, GER - P&L'!B37 | C6: ='AMAZON UK, FR, GER - P&L'!C37 | D6: ='AMAZON UK, FR, GER - P&L'!D37 | E6: ='AMAZON UK, FR, GER - P&L'!E37 | F6: ='AMAZON UK, FR, GER - P&L'!F37 | G6: ='AMAZON UK, FR, GER - P&L'!G37 | H6: ='AMAZON UK, FR, GER - P&L'!H37 | I6: ='AMAZON UK, FR, GER - P&L'!I37 | ... AF6: ='AMAZON UK, FR, GER - P&L'!AF37
A7: Sales | B7: =Summary!B40 -> 45.94 | C7: =Summary!C40 -> 0 | D7: =Summary!D40 -> 45.97 | E7: =Summary!E40 -> 0 | F7: =Summary!F40 -> 0 | G7: =Summary!G40 -> 45.99 | H7: =Summary!H40 -> 0 | I7: =Summary!I40 -> 0 | ... AF7: =Summary!AF40 -> 45.51
A9: FR
A10: Quantities | B10: ='AMAZON UK, FR, GER - P&L'!B313 | C10: ='AMAZON UK, FR, GER - P&L'!C313 | D10: ='AMAZON UK, FR, GER - P&L'!D313 | E10: ='AMAZON UK, FR, GER - P&L'!E313 | F10: ='AMAZON UK, FR, GER - P&L'!F313 | G10: ='AMAZON UK, FR, GER - P&L'!G313 | H10: ='AMAZON UK, FR, GER - P&L'!H313 | I10: ='AMAZON UK, FR, GER - P&L'!I313 | ... AF10: ='AMAZON UK, FR, GER - P&L'!AF313
A11: Sales | B11: =Summary!B41 -> 0 | C11: =Summary!C41 -> 0 | D11: =Summary!D41 -> 0 | E11: =Summary!E41 -> 39.55 | F11: =Summary!F41 -> 32.88 | G11: =Summary!G41 -> 0 | H11: =Summary!H41 -> 0 | I11: =Summary!I41 -> 0 | ... AF11: =Summary!AF41 -> 238.57
A13: GR
A14: Quantities | B14: ='AMAZON UK, FR, GER - P&L'!B589 | C14: ='AMAZON UK, FR, GER - P&L'!C589 | D14: ='AMAZON UK, FR, GER - P&L'!D589 | E14: ='AMAZON UK, FR, GER - P&L'!E589 | F14: ='AMAZON UK, FR, GER - P&L'!F589 | G14: ='AMAZON UK, FR, GER - P&L'!G589 | H14: ='AMAZON UK, FR, GER - P&L'!H589 | I14: ='AMAZON UK, FR, GER - P&L'!I589 | ... AF14: ='AMAZON UK, FR, GER - P&L'!AF589
A15: Sales | B15: =Summary!B42 -> 0 | C15: =Summary!C42 -> 0 | D15: =Summary!D42 -> 28.6 | E15: =Summary!E42 -> 0 | F15: =Summary!F42 -> 232.93 | G15: =Summary!G42 -> 0 | H15: =Summary!H42 -> 473.42 | I15: =Summary!I42 -> 240.08 | ... AF15: =Summary!AF42 -> 271.13
A17: Spent US | B17: =Summary!B143 -> 2300.7 | C17: =Summary!C143 -> 2354.42 | D17: =Summary!D143 -> 2354.52 | E17: =Summary!E143 -> 7873.04 | F17: =Summary!F143 -> 6577.65 | G17: =Summary!G143 -> 2322.01 | H17: =Summary!H143 -> 2339.76 | I17: =Summary!I143 -> 2097.77 | ... AF17: =Summary!AF143 -> 1435
A18: Spent UK | B18: =Summary!B145 -> 0 | C18: =Summary!C145 -> 0 | D18: =Summary!D145 -> 0 | E18: =Summary!E145 -> 0 | F18: =Summary!F145 -> 0 | G18: =Summary!G145 -> 0 | H18: =Summary!H145 -> 0 | I18: =Summary!I145 -> 0 | ... AF18: =Summary!AF145 -> 0
A19: Spent FR | B19: =Summary!B146 -> 6.25 | C19: =Summary!C146 -> 19.46 | D19: =Summary!D146 -> 16.34 | E19: =Summary!E146 -> 2.74 | F19: =Summary!F146 -> 4.92 | G19: =Summary!G146 -> 10.67 | H19: =Summary!H146 -> 1.53 | I19: =Summary!I146 -> 7.79 | ... AF19: =Summary!AF146 -> 0
A20: Spent GR | B20: =Summary!B147 -> 31.45 | C20: =Summary!C147 -> 42.96 | D20: =Summary!D147 -> 42.18 | E20: =Summary!E147 -> 26.3 | F20: =Summary!F147 -> 58.73 | G20: =Summary!G147 -> 31.34 | H20: =Summary!H147 -> 38.23 | I20: =Summary!I147 -> 26.98 | ... AF20: =Summary!AF147 -> 0

Sheet DTC_Data_Forecast
B1: 45809 | C1: 45810 | D1: 45811 | E1: 45812 | F1: 45813 | G1: 45814 | H1: 45815 | I1: 45816 | J1: 45817 | K1: 45818 | L1: 45819 | M1: 45820 | N1: 45821 | O1: 45822 | P1: 45823 | Q1: 45824 | R1: 45825 | S1: 45826 | T1: 45827 | U1: 45828 | V1: 45829 | W1: 45830 | X1: 45831 | Y1: 45832 | Z1: 45833 | AA1: 45834 | AB1: 45835 | AC1: 45836 | AD1: 45837 | AE1: 45838 | AF1: 45839
A2: Quantities | B2: ='DTC - P&L'!B59 -> 0 | C2: ='DTC - P&L'!C59 -> 0 | D2: ='DTC - P&L'!D59 -> 0 | E2: ='DTC - P&L'!E59 -> 0 | F2: ='DTC - P&L'!F59 -> 0 | G2: ='DTC - P&L'!G59 -> 0 | H2: ='DTC - P&L'!H59 -> 0 | I2: ='DTC - P&L'!I59 -> 0 | ... AF2: ='DTC - P&L'!AF59 -> 0
A3: Sales | B3: =Summary!B12-Summary!B26 -> 75206.646 | C3: =Summary!C12-Summary!C26 -> 117883.78 | D3: =Summary!D12-Summary!D26 -> 152220.85 | E3: =Summary!E12-Summary!E26 -> 142321.68 | F3: =Summary!F12-Summary!F26 -> 98217.24 | G3: =Summary!G12-Summary!G26 -> 91914.923 | H3: =Summary!H12-Summary!H26 -> 66930.777 | I3: =Summary!I12-Summary!I26 -> 60827.036 | ... AF3: =Summary!AF12-Summary!AF26 -> 30594.326
A5: DTC US
A6: Quantities | B6: ='DTC US&CA - P&L'!B31 -> 223 | C6: ='DTC US&CA - P&L'!C31 -> 354 | D6: ='DTC US&CA - P&L'!D31 -> 471 | E6: ='DTC US&CA - P&L'!E31 -> 442 | F6: ='DTC US&CA - P&L'!F31 -> 307 | G6: ='DTC US&CA - P&L'!G31 -> 235 | H6: ='DTC US&CA - P&L'!H31 -> 172 | I6: ='DTC US&CA - P&L'!I31 -> 151 | ... AF6: ='DTC US&CA - P&L'!AF31 -> 66
A7: Sales | B7: =Summary!B13 -> 73595.13 | C7: =Summary!C13 -> 117045.27 | D7: =Summary!D13 -> 151596.87 | E7: =Summary!E13 -> 139862.07 | F7: =Summary!F13 -> 97382.03 | G7: =Summary!G13 -> 91094.02 | H7: =Summary!H13 -> 66230.16 | I7: =Summary!I13 -> 59880.27 | ... AF7: =Summary!AF13 -> 28618.5
A9: DTC EU
A10: Quantities | B10: ='DTC EU - P&L'!B31 | C10: ='DTC EU - P&L'!C31 | D10: ='DTC EU - P&L'!D31 | E10: ='DTC EU - P&L'!E31 | F10: ='DTC EU - P&L'!F31 | G10: ='DTC EU - P&L'!G31 | H10: ='DTC EU - P&L'!H31 | I10: ='DTC EU - P&L'!I31 | ... AF10: ='DTC EU - P&L'!AF31
A11: Sales | B11: =Summary!B20 -> 1178.8734 | C11: =Summary!C20 -> 405.7888 | D11: =Summary!D20 -> 307.19612 | E11: =Summary!E20 -> 1702.1809 | F11: =Summary!F20 -> 322.5898 | G11: =Summary!G20 -> 292.25637 | H11: =Summary!H20 -> 584.5411 | I11: =Summary!I20 -> 653.1553 | ... AF11: =Summary!AF20 -> 1545.8027
A14: Spent US | B14: =Summary!B135+Summary!B138+Summary!B140+Summary!B141 -> 12872.53 | C14: =Summary!C135+Summary!C138+Summary!C140+Summary!C141 -> 26007.25 | D14: =Summary!D135+Summary!D138+Summary!D140+Summary!D141 -> 33843.71 | E14: =Summary!E135+Summary!E138+Summary!E140+Summary!E141 -> 29660.27 | F14: =Summary!F135+Summary!F138+Summary!F140+Summary!F141 -> 27931.62 | G14: =Summary!G135+Summary!G138+Summary!G140+Summary!G141 -> 26780 | H14: =Summary!H135+Summary!H138+Summary!H140+Summary!H141 -> 23159.38 | I14: =Summary!I135+Summary!I138+Summary!I140+Summary!I141 -> 16753.57 | ... AF14: =Summary!AF135+Summary!AF138+Summary!AF140+Summary!AF141 -> 4950.28
A15: Spent EU | B15: =Summary!B154 -> 0.47 | C15: =Summary!C154 -> 0 | D15: =Summary!D154 -> 1.14 | E15: =Summary!E154 -> 1 | F15: =Summary!F154 -> 0 | G15: =Summary!G154 -> 0 | H15: =Summary!H154 -> 0 | I15: =Summary!I154 -> 0.91 | ... AF15: =Summary!AF154 -> 0
A17: DTC US
A18: Quantities | B18: ='DTC US&CA - P&L'!B31+'DTC US&CA - P&L'!B36 -> 300 | C18: ='DTC US&CA - P&L'!C31+'DTC US&CA - P&L'!C36 -> 478 | D18: ='DTC US&CA - P&L'!D31+'DTC US&CA - P&L'!D36 -> 616 | E18: ='DTC US&CA - P&L'!E31+'DTC US&CA - P&L'!E36 -> 562 | F18: ='DTC US&CA - P&L'!F31+'DTC US&CA - P&L'!F36 -> 389 | G18: ='DTC US&CA - P&L'!G31+'DTC US&CA - P&L'!G36 -> 336 | H18: ='DTC US&CA - P&L'!H31+'DTC US&CA - P&L'!H36 -> 240 | I18: ='DTC US&CA - P&L'!I31+'DTC US&CA - P&L'!I36 -> 217 | ... AF18: ='DTC US&CA - P&L'!AF31+'DTC US&CA - P&L'!AF36 -> 104
A19: Sales w/o renewals | B19: =Summary!B13 -> 73595.13 | C19: =Summary!C13 -> 117045.27 | D19: =Summary!D13 -> 151596.87 | E19: =Summary!E13 -> 139862.07 | F19: =Summary!F13 -> 97382.03 | G19: =Summary!G13 -> 91094.02 | H19: =Summary!H13 -> 66230.16 | I19: =Summary!I13 -> 59880.27 | ... AF19: =Summary!AF13 -> 28618.5
A20: Sales with renewals | B20: =Summary!B13+Summary!B27 -> 86764.56 | C20: =Summary!C13+Summary!C27 -> 178074.13 | D20: =Summary!D13+Summary!D27 -> 179866.79 | E20: =Summary!E13+Summary!E27 -> 164614.81 | F20: =Summary!F13+Summary!F27 -> 137221.74 | G20: =Summary!G13+Summary!G27 -> 113105.29 | H20: =Summary!H13+Summary!H27 -> 82074.58 | I20: =Summary!I13+Summary!I27 -> 76359.62 | ... AF20: =Summary!AF13+Summary!AF27 -> 54215.33

Sheet Summary
B1: 46143 | C1: 46144 | D1: 46145 | E1: 46146 | F1: 46147 | G1: 46148 | H1: 46149 | I1: 46150 | J1: 46151 | K1: 46152 | L1: 46153 | M1: 46154 | N1: 46155 | O1: 46156 | P1: 46157 | Q1: 46158 | R1: 46159 | S1: 46160 | T1: 46161 | U1: 46162 | V1: 46163 | W1: 46164 | X1: 46165 | Y1: 46166 | Z1: 46167 | AA1: 46168 | AB1: 46169 | AC1: 46170 | AD1: 46171 | AE1: 46172 | AF1: 46173
B2: FRI | C2: SAT | D2: SUN | E2: MON | F2: TUE | G2: WED | H2: THU | I2: FRI | J2: SAT | K2: SUN | L2: MON | M2: TUE | N2: WED | O2: THU | P2: FRI | Q2: SAT | R2: SUN | S2: MON | T2: TUE | U2: WED | V2: THU | W2: FRI | X2: SAT | Y2: SUN | Z2: MON | AA2: TUE | AB2: WED | AC2: THU | AD2: FRI | AE2: SAT | AF2: SUN
A3: Notes | B3: MOTHER'S DAY SALE | M3: SPRING SALE | W3: SPECIAL OFFER (FATHER'S DAY) | AA3: SPRING SALE
E4: Price Change HBF PRO Solar (DTC/Storefront US at 09:25am CET) Old Price: RRP $339 → LP $239 → 28% OFF New Price: RRP $339 → LP $259 → 24% OFF | F4: Price Change SBF PRO Solar (DTC/Storefront EU at 12:11pm CET) Old Price: RRP $299 → LP $199 → 34% OFF New Price: RRP $299 → LP $219 → 27% OFF | G4: Renamed BB Solar back to to BB PRO Solar due to Amazon (DTC/SHOP/PDP US at 08:29am CEST) | H4: Renamed from BB PRO Solar to BB Solar due to Amazon constraints (DTC/SHOP/PDP US at 15:55pm CEST) | K4: SBF PRO Solar card HIDDEN on the Storefront (DTC/Storefront US 10:10am CEST) | L4: Retail Availability Banner Hidden (DTC/Storefront US 12:17am CEST) | M4: Mother’s Day Bundle (HBF PRO Retail) renamed to Hummingbird Bundle (DTC US 16:20pm CEST) | P4: FPM M1 Retention test turned ON (DTC US at 13.01pm UTC) | T4: Price Change HBF Bundle (HBF PRO Solar Retail) (DTC/Storefront US at 14:51pm CET) Old Price: RRP $339 → LP $259 → 24% OFF New Price: RRP $339 → LP $219 → 35% OFF | U4: Trustpilot Widget Shown (DTC/Footer US at 10:25am CEST) | W4: SKU3 V2 Price change (DTC US 09:00am CEST) - OLD:MSRP $359 LP $179 Discount 50% OFF - NEW: MSRP $349 LP $169 Discount 50% OFF | Z4: Gift Bag opted out (DTC US at 10:15AM CEST) | AA4: SKU3 V2 Price change (DTC US 09:00am CEST) - OLD: MSRP $349 LP $169 Discount 50% OFF - NEW: MSRP $339 LP $219 Discount 35% OFF | AC4: FPM M2 Retention test turned ON (DTC US at 14.11pm CEST)
F5: Show retailer banner (DTC/hp US 12:19pm CEST) | G5: SKU3 V2 Price Change (DTC US 09:20am CEST) OLD: MSRP $339 LP $169 Discount 50% OFF NEW: MSRP $378 LP $189 Discount 50% OFF | K5: Added New storefront card: Smart Bird Feeder Bundle (DTC/Storefront US 10:10am CEST) SKU: BBS4082AAA (same as GOTY Bundle bc. it has same items) ID: 833048 Price: MSRP $389 LP $199 Discount 50% OFF The PDP is turned off for this storefront card | L5: AfterPurchase Upsell Turned ON (DTC/Storefront US 13:04am CEST) | M5: SKU3 V2 card Renamed and shown on storefront (DTC US 16:20pm CEST) - OLD: Birdbuddy PRO Solar - NEW: Smart Bird Feeder | W5: After Purchase turned ON (DTC US 09:00am CEST) | AA5: Birdbuddy PRO Solar + Family premium price: - OLD: MSRP $448 LP $218.5 Discount 51% OFF - NEW: MSRP $438 LP $268.50 Discount 39% OFF
F6: Renamed BB PRO Solar to BB Solar due to Amazon (DTC/SHOP/PDP US at 19:36pm CEST) | M6: SKU3 V2 Price change (DTC US 16:20pm CEST) - OLD: MSRP $378 LP $189 Discount 50% OFF - NEW: MSRP $359 LP $179 Discount 50% OFF
A12: DTC Revenue | B12: =SUM(B13,B20,B26,B29) -> 88749.976 | C12: =SUM(C13,C20,C26,C29) -> 180837.88 | D12: =SUM(D13,D20,D26,D29) -> 181335.67 | E12: =SUM(E13,E20,E26,E29) -> 167865.39 | F12: =SUM(F13,F20,F26,F29) -> 139488.21 | G12: =SUM(G13,G20,G26,G29) -> 114657.39 | H12: =SUM(H13,H20,H26,H29) -> 83199.327 | I12: =SUM(I13,I20,I26,I29) -> 77885.256 | ... AF12: =SUM(AF13,AF20,AF26,AF29) -> 56960.976
A13: - DTC Revenue US&CA (w/o Subscriptions) | B13: =sum(B14:B19) -> 73595.13 | C13: =sum(C14:C19) -> 117045.27 | D13: =sum(D14:D19) -> 151596.87 | E13: =sum(E14:E19) -> 139862.07 | F13: =sum(F14:F19) -> 97382.03 | G13: =sum(G14:G19) -> 91094.02 | H13: =sum(H14:H19) -> 66230.16 | I13: =sum(I14:I19) -> 59880.27 | ... AF13: =sum(AF14:AF19) -> 28618.5
A14: - Hardware | B14: 55904.1 | C14: 89119.9 | D14: 113979.5 | E14: 105630.4 | F14: 72773.79 | G14: 70375.4 | H14: 50044.4 | I14: 45304.8 | J14: 45158.8 | K14: 38508 | L14: 23348 | M14: 26934 | N14: 26574.6 | O14: 361001.2 | P14: 58509.2 | Q14: 41130.1 | R14: 126157.2 | S14: 46624.4 | T14: 92972.7 | U14: 21372.7 | V14: 25308.2 | W14: 32844 | X14: 43204.36 | Y14: 51631.7 | Z14: 49357.9 | AA14: 30211.5 | AB14: 23368.2 | AC14: 15067.2 | AD14: 21131.4 | AE14: 20901 | AF14: 21928.4
A15: - Add-ons | B15: 3219.4 | C15: 5231.8 | D15: 7477.6 | E15: 6096 | F15: 4921.9 | G15: 3488.2 | H15: 3861.2 | I15: 3548.8 | J15: 3149.4 | K15: 9975.4 | L15: 5589 | M15: 3239.4 | N15: 2368.3 | O15: 19475.4 | P15: 3937.2 | Q15: 3081.4 | R15: 6862.2 | S15: 2986.8 | T15: 4486.6 | U15: 1703.4 | V15: 1571.8 | W15: 2682 | X15: 3171.87 | Y15: 3812.6 | Z15: 3965.4 | AA15: 1475.3 | AB15: 1512.6 | AC15: 1074.2 | AD15: 1286.2 | AE15: 1196.4 | AF15: 1990
A16: - Merch | B16: 0 | C16: 0 | D16: 0 | E16: 0 | F16: 0 | G16: 0 | H16: 0 | I16: 0 | J16: 0 | K16: 0 | L16: 0 | M16: 0 | N16: 0 | O16: 0 | P16: 0 | Q16: 0 | R16: 0 | S16: 0 | T16: 0 | U16: 0 | V16: 0 | W16: 0 | X16: 0 | Y16: 0 | Z16: 0 | AA16: 0 | AB16: 0 | AC16: 0 | AD16: 0 | AE16: 0 | AF16: 0
A17: - Taxes | B17: 4574.01 | C17: 7422.04 | D17: 9798.23 | E17: 9005.17 | F17: 6229.59 | G17: 5836.7 | H17: 4164.53 | I17: 3763.32 | J17: 3688.73 | K17: 3891.06 | L17: 2233.2 | M17: 2391.53 | N17: 2315.89 | O17: 29846.05 | P17: 5039.27 | Q17: 3535.73 | R17: 10602.04 | S17: 3819.09 | T17: 7713 | U17: 1893.22 | V17: 2143.34 | W17: 2745.71 | X17: 3701.84 | Y17: 4336.89 | Z17: 4166.22 | AA17: 2490.42 | AB17: 1936.98 | AC17: 1231.92 | AD17: 1649.81 | AE17: 1664.51 | AF17: 1754.62
A18: - Shipping | B18: 8038.55 | C18: 12692.82 | D18: 16363.53 | E18: 14992.57 | F18: 10382.28 | G18: 8914.96 | H18: 6540.84 | I18: 5924.02 | J18: 5831.09 | K18: 6104.58 | L18: 3468.93 | M18: 3783.78 | N18: 3759.08 | O18: 50201.87 | P18: 8074.14 | Q18: 5689.77 | R18: 17561.77 | S18: 6506.11 | T18: 12969.5 | U18: 3100.07 | V18: 3696.71 | W18: 4739.85 | X18: 6268.9 | Y18: 7553.55 | Z18: 7229.2 | AA18: 3775.99 | AB18: 2859.64 | AC18: 1889.86 | AD18: 2709.09 | AE18: 2698.06 | AF18: 2945.48
A19: - Gift Bag | B19: 1859.07 | C19: 2578.71 | D19: 3978.01 | E19: 4137.93 | F19: 3074.47 | G19: 2478.76 | H19: 1619.19 | I19: 1339.33 | J19: 1319.34 | K19: 1419.29 | L19: 839.58 | M19: 879.56 | N19: 819.59 | O19: 1199.4 | P19: 879.56 | Q19: 679.66 | R19: 999.5 | S19: 999.5 | T19: 799.6 | U19: 599.7 | V19: 899.55 | W19: 1159.42 | X19: 1336 | Y19: 1659.17 | Z19: 0 | AA19: 0 | AB19: 0 | AC19: 0 | AD19: 0 | AE19: 0 | AF19: 0
A20: - DTC Revenue EU (w/o Subscriptions) | B20: =SUM(B21:B25) -> 1178.8734 | C20: =SUM(C21:C25) -> 405.7888 | D20: =SUM(D21:D25) -> 307.19612 | E20: =SUM(E21:E25) -> 1702.1809 | F20: =SUM(F21:F25) -> 322.5898 | G20: =SUM(G21:G25) -> 292.25637 | H20: =SUM(H21:H25) -> 584.5411 | I20: =SUM(I21:I25) -> 653.1553 | ... AF20: =SUM(AF21:AF25) -> 1545.8027
A21: - Hardware | B21: ='DTC EU - P&L'!B15*B$133 -> 763.51504 | C21: ='DTC EU - P&L'!C15*C$133 -> 194.48542 | D21: ='DTC EU - P&L'!D15*D$133 -> 191.39327 | E21: ='DTC EU - P&L'!E15*E$133 -> 1150.8337 | F21: ='DTC EU - P&L'!F15*F$133 -> 210.11646 | G21: ='DTC EU - P&L'!G15*G$133 -> 216.21685 | H21: ='DTC EU - P&L'!H15*H$133 -> 424.49293 | I21: ='DTC EU - P&L'!I15*I$133 -> 217.02658 | ... AF21: ='DTC EU - P&L'!AF15*AF$133 -> 836.87562
A22: - Add-ons | B22: ='DTC EU - P&L'!B16*B$133 -> 71.903832 | C22: ='DTC EU - P&L'!C16*C$133 -> 90.751264 | D22: ='DTC EU - P&L'!D16*D$133 -> 19.079484 | E22: ='DTC EU - P&L'!E16*E$133 -> 65.6978 | F22: ='DTC EU - P&L'!F16*F$133 -> 13.542685 | G22: ='DTC EU - P&L'!G16*G$133 -> 0 | H22: ='DTC EU - P&L'!H16*H$133 -> 0 | I22: ='DTC EU - P&L'!I16*I$133 -> 264.58775 | ... AF22: ='DTC EU - P&L'!AF16*AF$133 -> 291.06032
A23: - Merch | B23: ='DTC EU - P&L'!B17*B$133 -> 0 | C23: ='DTC EU - P&L'!C17*C$133 -> 0 | D23: ='DTC EU - P&L'!D17*D$133 -> 0 | E23: ='DTC EU - P&L'!E17*E$133 -> 0 | F23: ='DTC EU - P&L'!F17*F$133 -> 0 | G23: ='DTC EU - P&L'!G17*G$133 -> 0 | H23: ='DTC EU - P&L'!H17*H$133 -> 0 | I23: ='DTC EU - P&L'!I17*I$133 -> 0 | ... AF23: ='DTC EU - P&L'!AF17*AF$133 -> 0
A24: - Taxes | B24: ='DTC EU - P&L'!B20*B$133 -> 214.46854 | C24: ='DTC EU - P&L'!C20*C$133 -> 67.776112 | D24: ='DTC EU - P&L'!D20*D$133 -> 55.654362 | E24: ='DTC EU - P&L'!E20*E$133 -> 298.60936 | F24: ='DTC EU - P&L'!F20*F$133 -> 57.96316 | G24: ='DTC EU - P&L'!G20*G$133 -> 46.667028 | H24: ='DTC EU - P&L'!H20*H$133 -> 101.41817 | I24: ='DTC EU - P&L'!I20*I$133 -> 106.67948 | ... AF24: ='DTC EU - P&L'!AF20*AF$133 -> 278.00671
A25: - Shipping | B25: ='DTC EU - P&L'!B22*B$133 -> 128.986 | C25: ='DTC EU - P&L'!C22*C$133 -> 52.776 | D25: ='DTC EU - P&L'!D22*D$133 -> 41.069 | E25: ='DTC EU - P&L'!E22*E$133 -> 187.04 | F25: ='DTC EU - P&L'!F22*F$133 -> 40.9675 | G25: ='DTC EU - P&L'!G22*G$133 -> 29.3725 | H25: ='DTC EU - P&L'!H22*H$133 -> 58.63 | I25: ='DTC EU - P&L'!I22*I$133 -> 64.8615 | ... AF25: ='DTC EU - P&L'!AF22*AF$133 -> 139.86
A26: - Yearly Premium Subscription US&CA | B26: =SUM(B27:B28) -> 13543.33 | C26: =SUM(C27:C28) -> 62954.1 | D26: =SUM(D27:D28) -> 29114.82 | E26: =SUM(E27:E28) -> 25543.71 | F26: =SUM(F27:F28) -> 41270.97 | G26: =SUM(G27:G28) -> 22742.47 | H26: =SUM(H27:H28) -> 16268.55 | I26: =SUM(I27:I28) -> 17058.22 | ... AF26: =SUM(AF27:AF28) -> 26366.65
A27: - Line Item Total | B27: 13169.43 | C27: 61028.86 | D27: 28269.92 | E27: 24752.74 | F27: 39839.71 | G27: 22011.27 | H27: 15844.42 | I27: 16479.35 | J27: 16506.05 | K27: 17164.54 | L27: 19961.72 | M27: 19177.04 | N27: 19247.53 | O27: 17306.7 | P27: 17093.98 | Q27: 15427.65 | R27: 20185.9 | S27: 17683.18 | T27: 20549.37 | U27: 23478.8 | V27: 16247.86 | W27: 22016.25 | X27: 17056.03 | Y27: 24716.25 | Z27: 27800.7 | AA27: 19684.77 | AB27: 21654.07 | AC27: 20334.41 | AD27: 21997.88 | AE27: 8967.01 | AF27: 25596.83
A28: - Taxes | B28: 373.9 | C28: 1925.24 | D28: 844.9 | E28: 790.97 | F28: 1431.26 | G28: 731.2 | H28: 424.13 | I28: 578.87 | J28: 590.87 | K28: 554.55 | L28: 634.03 | M28: 582.74 | N28: 608.02 | O28: 591.2 | P28: 583.55 | Q28: 526.64 | R28: 638.99 | S28: 611.06 | T28: 698.3 | U28: 692.15 | V28: 416.17 | W28: 717 | X28: 559.66 | Y28: 827.55 | Z28: 866.15 | AA28: 510.73 | AB28: 613.69 | AC28: 659.79 | AD28: 734.88 | AE28: 317.18 | AF28: 769.82
A29: - Yearly Premium Subscription EU | B29: =SUM(B30:B31) -> 432.6425 | C29: =SUM(C30:C31) -> 432.71629 | D29: =SUM(D30:D31) -> 316.7828 | E29: =SUM(E30:E31) -> 757.43017 | F29: =SUM(F30:F31) -> 512.62048 | G29: =SUM(G30:G31) -> 528.64625 | H29: =SUM(H30:H31) -> 116.07567 | I29: =SUM(I30:I31) -> 293.61032 | ... AF29: =SUM(AF30:AF31) -> 430.02288
A30: - Line Item Total | B30: ='DTC EU - P&L'!B18*B$133 -> 358.39346 | C30: ='DTC EU - P&L'!C18*C$133 -> 350.32709 | D30: ='DTC EU - P&L'!D18*D$133 -> 262.53652 | E30: ='DTC EU - P&L'!E18*E$133 -> 625.20458 | F30: ='DTC EU - P&L'!F18*F$133 -> 423.0304 | G30: ='DTC EU - P&L'!G18*G$133 -> 436.21687 | H30: ='DTC EU - P&L'!H18*H$133 -> 92.858194 | I30: ='DTC EU - P&L'!I18*I$133 -> 243.07732 | ... AF30: ='DTC EU - P&L'!AF18*AF$133 -> 356.89941
A31: - Taxes | B31: ='DTC EU - P&L'!B21*B$133 -> 74.249032 | C31: ='DTC EU - P&L'!C21*C$133 -> 82.3892 | D31: ='DTC EU - P&L'!D21*D$133 -> 54.246282 | E31: ='DTC EU - P&L'!E21*E$133 -> 132.22559 | F31: ='DTC EU - P&L'!F21*F$133 -> 89.59007 | G31: ='DTC EU - P&L'!G21*G$133 -> 92.429383 | H31: ='DTC EU - P&L'!H21*H$133 -> 23.21748 | I31: ='DTC EU - P&L'!I21*I$133 -> 50.533005 | ... AF31: ='DTC EU - P&L'!AF21*AF$133 -> 73.12347
A32: Amazon Revenue | B32: =sum(B33,B39) -> 41310.89 | C32: =sum(C33,C39) -> 59108.3 | D32: =sum(D33,D39) -> 106997.66 | E32: =sum(E33,E39) -> 101020.52 | F32: =sum(F33,F39) -> 90573.84 | G32: =sum(G33,G39) -> 64340.28 | H32: =sum(H33,H39) -> 59815.27 | I32: =sum(I33,I39) -> 38771.02 | ... AF32: =sum(AF33,AF39) -> 18560.69
A33: Amazon Revenue US | B33: =sum(B34:B38) -> 41264.95 | C33: =sum(C34:C38) -> 59108.3 | D33: =sum(D34:D38) -> 106923.09 | E33: =sum(E34:E38) -> 100980.97 | F33: =sum(F34:F38) -> 90308.03 | G33: =sum(G34:G38) -> 64294.29 | H33: =sum(H34:H38) -> 59341.85 | I33: =sum(I34:I38) -> 38530.94 | ... AF33: =sum(AF34:AF38) -> 18005.48
A34: - Hardware | B34: 36387 | C34: 52342 | D34: 95619 | E34: 90606 | F34: 81314 | G34: 56474 | H34: 51789.13 | I34: 33011.13 | J34: 30134 | K34: 19116 | L34: 14309.86 | M34: 15329.3 | N34: 18312.72 | O34: 23082.44 | P34: 19028.72 | Q34: 16488.58 | R34: 22271.86 | S34: 16445.86 | T34: 16124.72 | U34: 11766 | V34: 12889.86 | W34: 13119 | X34: 16307 | Y34: 13082 | Z34: 14895 | AA34: 9855 | AB34: 12046 | AC34: 10890 | AD34: 8908 | AE34: 13600 | AF34: 14505
A35: - Add-ons | B35: 2101 | C35: 2798 | D35: 4066.84 | E35: 3593 | F35: 2877 | G35: 3469 | H35: 3475.86 | I35: 2917.43 | J35: 3272 | K35: 5540 | L35: 2732.46 | M35: 2025.3 | N35: 2416.92 | O35: 1759.84 | P35: 2269.92 | Q35: 2833.38 | R35: 2521.46 | S35: 1734.46 | T35: 1687.46 | U35: 1396 | V35: 1329.46 | W35: 1802 | X35: 1453 | Y35: 2120 | Z35: 2003 | AA35: 1356 | AB35: 1376 | AC35: 1064 | AD35: 1269 | AE35: 1782 | AF35: 2287
A36: - Tax | B36: 2734.1 | C36: 3924.55 | D36: 7146.72 | E36: 6649.34 | F36: 5949.08 | G36: 4251.23 | H36: 3996.13 | I36: 2553.24 | J36: 2294.4 | K36: 1702.66 | L36: 1218.64 | M36: 1182.84 | N36: 1379.04 | O36: 1794.82 | P36: 1510.83 | Q36: 1368.97 | R36: 1816.04 | S36: 1206.35 | T36: 1239.48 | U36: 883.74 | V36: 970.43 | W36: 1030.96 | X36: 1279.14 | Y36: 1067.78 | Z36: 1241.63 | AA36: 784.27 | AB36: 982.95 | AC36: 846.84 | AD36: 669.93 | AE36: 1071.03 | AF36: 1199.32
A37: - Shipping | B37: 10.06 | C37: 15.29 | D37: 34.7 | E37: 58.46 | F37: 103.13 | G37: 45.09 | H37: 29.42 | I37: 11.08 | J37: 14.73 | K37: 30.94 | L37: 0.27 | M37: 3.41 | N37: 12.35 | O37: 12.41 | P37: 5.69 | Q37: 14.54 | R37: 10.79 | S37: 18.85 | T37: 0.41 | U37: 7.26 | V37: 11.53 | W37: 28.32 | X37: 6.79 | Y37: 0.41 | Z37: 7.35 | AA37: 11.85 | AB37: 7.45 | AC37: 0.67 | AD37: 5.47 | AE37: 16.92 | AF37: 0.34
A38: - Gift Wrap | B38: 32.79 | C38: 28.46 | D38: 55.83 | E38: 74.17 | F38: 64.82 | G38: 54.97 | H38: 51.31 | I38: 38.06 | J38: 23.79 | K38: 9.62 | L38: 9.58 | M38: 10 | N38: 35.42 | O38: 9.85 | P38: 1.23 | Q38: 10.2 | R38: 23.58 | S38: 9.34 | T38: 18.75 | U38: 17.9 | V38: 9.38 | W38: 17.46 | X38: 18.55 | Y38: 0.99 | Z38: 0.88 | AA38: 22.01 | AB38: 18.57 | AC38: 5.22 | AD38: 0.43 | AE38: 14.09 | AF38: 13.82
A39: Amazon Revenue EU | B39: ='AMAZON EU - P&L'!B32 -> 45.94 | C39: ='AMAZON EU - P&L'!C32 -> 0 | D39: ='AMAZON EU - P&L'!D32 -> 74.57 | E39: ='AMAZON EU - P&L'!E32 -> 39.55 | F39: ='AMAZON EU - P&L'!F32 -> 265.81 | G39: ='AMAZON EU - P&L'!G32 -> 45.99 | H39: ='AMAZON EU - P&L'!H32 -> 473.42 | I39: ='AMAZON EU - P&L'!I32 -> 240.08 | ... AF39: ='AMAZON EU - P&L'!AF32 -> 555.21
A40: Amazon Revenue UK | B40: ='AMAZON UK, FR, GER - P&L'!B24 -> 45.94 | C40: ='AMAZON UK, FR, GER - P&L'!C24 -> 0 | D40: ='AMAZON UK, FR, GER - P&L'!D24 -> 45.97 | E40: ='AMAZON UK, FR, GER - P&L'!E24 -> 0 | F40: ='AMAZON UK, FR, GER - P&L'!F24 -> 0 | G40: ='AMAZON UK, FR, GER - P&L'!G24 -> 45.99 | H40: ='AMAZON UK, FR, GER - P&L'!H24 -> 0 | I40: ='AMAZON UK, FR, GER - P&L'!I24 -> 0 | ... AF40: ='AMAZON UK, FR, GER - P&L'!AF24 -> 45.51
A41: Amazon Revenue FR | B41: ='AMAZON UK, FR, GER - P&L'!B300 -> 0 | C41: ='AMAZON UK, FR, GER - P&L'!C300 -> 0 | D41: ='AMAZON UK, FR, GER - P&L'!D300 -> 0 | E41: ='AMAZON UK, FR, GER - P&L'!E300 -> 39.55 | F41: ='AMAZON UK, FR, GER - P&L'!F300 -> 32.88 | G41: ='AMAZON UK, FR, GER - P&L'!G300 -> 0 | H41: ='AMAZON UK, FR, GER - P&L'!H300 -> 0 | I41: ='AMAZON UK, FR, GER - P&L'!I300 -> 0 | ... AF41: ='AMAZON UK, FR, GER - P&L'!AF300 -> 238.57
A42: Amazon Revenue GER | B42: ='AMAZON UK, FR, GER - P&L'!B576 -> 0 | C42: ='AMAZON UK, FR, GER - P&L'!C576 -> 0 | D42: ='AMAZON UK, FR, GER - P&L'!D576 -> 28.6 | E42: ='AMAZON UK, FR, GER - P&L'!E576 -> 0 | F42: ='AMAZON UK, FR, GER - P&L'!F576 -> 232.93 | G42: ='AMAZON UK, FR, GER - P&L'!G576 -> 0 | H42: ='AMAZON UK, FR, GER - P&L'!H576 -> 473.42 | I42: ='AMAZON UK, FR, GER - P&L'!I576 -> 240.08 | ... AF42: ='AMAZON UK, FR, GER - P&L'!AF576 -> 271.13
A43: - Hardware | B43: ='AMAZON EU - P&L'!B27 -> 0 | C43: ='AMAZON EU - P&L'!C27 -> 0 | D43: ='AMAZON EU - P&L'!D27 -> 0 | E43: ='AMAZON EU - P&L'!E27 -> 0 | F43: ='AMAZON EU - P&L'!F27 -> 232.93 | G43: ='AMAZON EU - P&L'!G27 -> 0 | H43: ='AMAZON EU - P&L'!H27 -> 466.69 | I43: ='AMAZON EU - P&L'!I27 -> 233.35 | ... AF43: ='AMAZON EU - P&L'!AF27 -> 463.77
A44: - Add-ons | B44: ='AMAZON EU - P&L'!B28 -> 39.38 | C44: ='AMAZON EU - P&L'!C28 -> 0 | D44: ='AMAZON EU - P&L'!D28 -> 68.01 | E44: ='AMAZON EU - P&L'!E28 -> 33.9 | F44: ='AMAZON EU - P&L'!F28 -> 30.59 | G44: ='AMAZON EU - P&L'!G28 -> 39.42 | H44: ='AMAZON EU - P&L'!H28 -> 0 | I44: ='AMAZON EU - P&L'!I28 -> 0 | ... AF44: ='AMAZON EU - P&L'!AF28 -> 72.81
A45: - Tax | B45: ='AMAZON EU - P&L'!B29 -> 6.56 | C45: ='AMAZON EU - P&L'!C29 -> 0 | D45: ='AMAZON EU - P&L'!D29 -> 6.56 | E45: ='AMAZON EU - P&L'!E29 -> 5.65 | F45: ='AMAZON EU - P&L'!F29 -> 2.29 | G45: ='AMAZON EU - P&L'!G29 -> 6.57 | H45: ='AMAZON EU - P&L'!H29 -> 6.73 | I45: ='AMAZON EU - P&L'!I29 -> 6.73 | ... AF45: ='AMAZON EU - P&L'!AF29 -> 18.63
...

Sheet DTC - P&L
A1: MAY | B1: 46143 | C1: 46144 | D1: 46145 | E1: 46146 | F1: 46147 | G1: 46148 | H1: 46149 | I1: 46150 | J1: 46151 | K1: 46152 | L1: 46153 | M1: 46154 | N1: 46155 | O1: 46156 | P1: 46157 | Q1: 46158 | R1: 46159 | S1: 46160 | T1: 46161 | U1: 46162 | V1: 46163 | W1: 46164 | X1: 46165 | Y1: 46166 | Z1: 46167 | AA1: 46168 | AB1: 46169 | AC1: 46170 | AD1: 46171 | AE1: 46172 | AF1: 46173
A2: DAY | B2: FRI | C2: SAT | D2: SUN | E2: MON | F2: TUE | G2: WED | H2: THU | I2: FRI | J2: SAT | K2: SUN | L2: MON | M2: TUE | N2: WED | O2: THU | P2: FRI | Q2: SAT | R2: SUN | S2: MON | T2: TUE | U2: WED | V2: THU | W2: FRI | X2: SAT | Y2: SUN | Z2: MON | AA2: TUE | AB2: WED | AC2: THU | AD2: FRI | AE2: SAT | AF2: SUN
A3: COMMENT
A4: Orders
A5: Meta | B5: 109 | C5: 231 | D5: 297 | E5: 281 | F5: 172 | G5: 166 | H5: 109 | I5: 100 | J5: 97 | K5: 103 | L5: 72 | M5: 72 | N5: 68 | O5: 485 | P5: 107 | Q5: 72 | R5: 145 | S5: 73 | T5: 148 | U5: 56 | V5: 42 | W5: 95 | X5: 129 | Y5: 158 | Z5: 160 | AA5: 60 | AB5: 57 | AC5: 33 | AD5: 32 | AE5: 39 | AF5: 29 | AG5: =SUM(B5:AF5) -> 3797
A6: Google | B6: 118 | C6: 146 | D6: 174 | E6: 158 | F6: 105 | G6: 90 | H6: 66 | I6: 78 | J6: 68 | K6: 67 | L6: 38 | M6: 38 | N6: 62 | O6: 132 | P6: 47 | Q6: 58 | R6: 65 | S6: 45 | T6: 47 | U6: 23 | V6: 41 | W6: 65 | X6: 69 | Y6: 81 | Z6: 90 | AA6: 31 | AB6: 31 | AC6: 30 | AD6: 40 | AE6: 55 | AF6: 56 | AG6: =SUM(B6:AF6) -> 2214
A7: TikTok | B7: 0 | C7: 0 | D7: 0 | E7: 0 | F7: 0 | G7: 0 | H7: 0 | I7: 0 | J7: 0 | K7: 0 | L7: 0 | M7: 0 | N7: 0 | O7: 0 | P7: 0 | Q7: 0 | R7: 0 | S7: 0 | T7: 0 | U7: 0 | V7: 0 | W7: 0 | X7: 0 | Y7: 0 | Z7: 0 | AA7: 0 | AB7: 0 | AC7: 0 | AD7: 0 | AE7: 0 | AF7: 0 | AG7: =SUM(B7:AF7) -> 0
A8: Bing | B8: 0 | C8: 0 | D8: 0 | E8: 0 | F8: 0 | G8: 0 | H8: 0 | I8: 0 | J8: 0 | K8: 0 | L8: 0 | M8: 0 | N8: 0 | O8: 0 | P8: 0 | Q8: 0 | R8: 0 | S8: 0 | T8: 0 | U8: 0 | V8: 0 | W8: 0 | X8: 0 | Y8: 0 | Z8: 0 | AA8: 0 | AB8: 0 | AC8: 0 | AD8: 0 | AE8: 0 | AF8: 0 | AG8: =SUM(B8:AF8) -> 0 | AH8: 0
A9: Email | B9: 0 | C9: 0 | D9: 0 | E9: 0 | F9: 0 | G9: 0 | H9: 0 | I9: 0 | J9: 0 | K9: 0 | L9: 0 | M9: 0 | N9: 0 | O9: 0 | P9: 0 | Q9: 0 | R9: 0 | S9: 0 | T9: 0 | U9: 0 | V9: 0 | W9: 0 | X9: 0 | Y9: 0 | Z9: 0 | AA9: 0 | AB9: 0 | AC9: 0 | AD9: 0 | AE9: 0 | AF9: 0 | AG9: =SUM(B9:AF9) -> 0
A10: All | B10: =SUM(B5:B9) -> 227 | C10: =SUM(C5:C9) -> 377 | D10: =SUM(D5:D9) -> 471 | E10: =SUM(E5:E9) -> 439 | F10: =SUM(F5:F9) -> 277 | G10: =SUM(G5:G9) -> 256 | H10: =SUM(H5:H9) -> 175 | I10: =SUM(I5:I9) -> 178 | ... AF10: =SUM(AF5:AF9) -> 85 | AG10: =SUM(B10:AF10) -> 6011
A14: Revenue
A15: Meta | B15: 25615.62 | C15: 56722.29 | D15: 73355.35 | E15: 71596.63 | F15: 42032.19 | G15: 44356.49 | H15: 27859.84 | I15: 26043.36 | J15: 26280.77 | K15: 24620.88 | L15: 17943.98 | M15: 16005.09 | N15: 15768.1 | O15: 115339.77 | P15: 25529 | Q15: 16794.27 | R15: 35542.96 | S15: 18103.3 | T15: 36132.27 | U15: 12698.35 | V15: 10134.97 | W15: 22778.84 | X15: 31347.84 | Y15: 35652.08 | Z15: 37810.73 | AA15: 15138.69 | AB15: 16190.51 | AC15: 7430.86 | AD15: 8026.23 | AE15: 9616.05 | AF15: 7765.19 | AG15: =SUM(B15:AF15) -> 930232.5
A16: Google | B16: 28121.71 | C16: 35894.93 | D16: 42418.39 | E16: 39691.75 | F16: 25877.86 | G16: 23228.08 | H16: 16781.96 | I16: 19509.29 | J16: 16897.91 | K16: 16563.38 | L16: 9077.8 | M16: 8711.5 | N16: 15661.29 | O16: 33314.72 | P16: 10211.6 | Q16: 13068.75 | R16: 15954.72 | S16: 11408.73 | T16: 11786.41 | U16: 4991.17 | V16: 9512.76 | W16: 14982.69 | X16: 16936.1 | Y16: 18304.71 | Z16: 21340.33 | AA16: 7438.27 | AB16: 8786.16 | AC16: 7292 | AD16: 9482.4 | AE16: 13685.34 | AF16: 14223.17 | AG16: =SUM(B16:AF16) -> 541155.88
A17: TikTok | B17: 0 | C17: 0 | D17: 0 | E17: 0 | F17: 0 | G17: 0 | H17: 0 | I17: 0 | J17: 0 | K17: 0 | L17: 0 | M17: 0 | N17: 0 | O17: 0 | P17: 0 | Q17: 0 | R17: 0 | S17: 0 | T17: 0 | U17: 0 | V17: 0 | W17: 0 | X17: 0 | Y17: 0 | Z17: 0 | AA17: 0 | AB17: 0 | AC17: 0 | AD17: 0 | AE17: 0 | AF17: 0 | AG17: =SUM(B17:AF17) -> 0
A18: Bing | B18: 0 | C18: 0 | D18: 0 | E18: 0 | F18: 0 | G18: 0 | H18: 0 | I18: 0 | J18: 0 | K18: 0 | L18: 0 | M18: 0 | N18: 0 | O18: 0 | P18: 0 | Q18: 0 | R18: 0 | S18: 0 | T18: 0 | U18: 0 | V18: 0 | W18: 0 | X18: 0 | Y18: 0 | Z18: 0 | AA18: 0 | AB18: 0 | AC18: 0 | AD18: 0 | AE18: 0 | AF18: 0 | AG18: =SUM(B18:AF18) -> 0
A19: Email | B19: 0 | C19: 0 | D19: 0 | E19: 0 | F19: 0 | G19: 0 | H19: 0 | I19: 0 | J19: 0 | K19: 0 | L19: 0 | M19: 0 | N19: 0 | O19: 0 | P19: 0 | Q19: 0 | R19: 0 | S19: 0 | T19: 0 | U19: 0 | V19: 0 | W19: 0 | X19: 0 | Y19: 0 | Z19: 0 | AA19: 0 | AB19: 0 | AC19: 0 | AD19: 0 | AE19: 0 | AF19: 0 | AG19: =SUM(B19:AF19) -> 0
A20: All | B20: =SUM(B15:B19) -> 53737.33 | C20: =SUM(C15:C19) -> 92617.22 | D20: =SUM(D15:D19) -> 115773.74 | E20: =SUM(E15:E19) -> 111288.38 | F20: =SUM(F15:F19) -> 67910.05 | G20: =SUM(G15:G19) -> 67584.57 | H20: =SUM(H15:H19) -> 44641.8 | I20: =SUM(I15:I19) -> 45552.65 | ... AF20: =SUM(AF15:AF19) -> 21988.36 | AG20: =SUM(B20:AF20) -> 1471388.4
A24: Media Cost
A25: Meta | B25: =Summary!B134 -> 9467.17 | C25: =Summary!C134 -> 21100.71 | D25: =Summary!D134 -> 29005.81 | E25: =Summary!E134 -> 26025 | F25: =Summary!F134 -> 24029.71 | G25: =Summary!G134 -> 22817.76 | H25: =Summary!H134 -> 19778.33 | I25: =Summary!I134 -> 13804.36 | ... AF25: =Summary!AF134 -> 3601.74 | AG25: =SUM(B25:AF25) -> 420259.06
A26: Google | B26: =Summary!B137 -> 3405.83 | C26: =Summary!C137 -> 4906.54 | D26: =Summary!D137 -> 4839.04 | E26: =Summary!E137 -> 3636.27 | F26: =Summary!F137 -> 3901.91 | G26: =Summary!G137 -> 3962.24 | H26: =Summary!H137 -> 3381.05 | I26: =Summary!I137 -> 2950.12 | ... AF26: =Summary!AF137 -> 1348.54 | AG26: =SUM(B26:AF26) -> 84752.31
A27: TikTok | B27: =Summary!B141 -> 0 | C27: =Summary!C141 -> 0 | D27: =Summary!D141 -> 0 | E27: =Summary!E141 -> 0 | F27: =Summary!F141 -> 0 | G27: =Summary!G141 -> 0 | H27: =Summary!H141 -> 0 | I27: =Summary!I141 -> 0 | ... AF27: =Summary!AF141 -> 0 | AG27: =SUM(B27:AF27) -> 1355.06
A28: Bing | B28: =Summary!B140 -> 0 | C28: =Summary!C140 -> 0 | D28: =Summary!D140 -> 0 | E28: =Summary!E140 -> 0 | F28: =Summary!F140 -> 0 | G28: =Summary!G140 -> 0 | H28: =Summary!H140 -> 0 | I28: =Summary!I140 -> 0 | ... AF28: =Summary!AF140 -> 0 | AG28: =SUM(B28:AF28) -> 0
A29: All | B29: =SUM(B25:B28) -> 12873 | C29: =SUM(C25:C28) -> 26007.25 | D29: =SUM(D25:D28) -> 33844.85 | E29: =SUM(E25:E28) -> 29661.27 | F29: =SUM(F25:F28) -> 27931.62 | G29: =SUM(G25:G28) -> 26780 | H29: =SUM(H25:H28) -> 23159.38 | I29: =SUM(I25:I28) -> 16754.48 | ... AF29: =SUM(AF25:AF28) -> 4950.28 | AG29: =SUM(B29:AF29) -> 506366.43
A33: Revenue
A34: Revenue Woocommerce (Platform) | B34: =Summary!B12 -> 88749.976 | C34: =Summary!C12 -> 180837.88 | D34: =Summary!D12 -> 181335.67 | E34: =Summary!E12 -> 167865.39 | F34: =Summary!F12 -> 139488.21 | G34: =Summary!G12 -> 114657.39 | H34: =Summary!H12 -> 83199.327 | I34: =Summary!I12 -> 77885.256 | ... AF34: =Summary!AF12 -> 56960.976 | AG34: =SUM(B34:AF34) -> 3147844.5
A35: Revenue w/o renewals | B35: ='DTC US&CA - P&L'!B6+'DTC EU - P&L'!B6 -> 75232.873 | C35: ='DTC US&CA - P&L'!C6+'DTC EU - P&L'!C6 -> 117808.15 | D35: ='DTC US&CA - P&L'!D6+'DTC EU - P&L'!D6 -> 152360.45 | E35: ='DTC US&CA - P&L'!E6+'DTC EU - P&L'!E6 -> 141719.12 | F35: ='DTC US&CA - P&L'!F6+'DTC EU - P&L'!F6 -> 97806.9 | G35: ='DTC US&CA - P&L'!G6+'DTC EU - P&L'!G6 -> 91646.456 | H35: ='DTC US&CA - P&L'!H6+'DTC EU - P&L'!H6 -> 67272.811 | I35: ='DTC US&CA - P&L'!I6+'DTC EU - P&L'!I6 -> 60837.855 | ... AF35: ='DTC US&CA - P&L'!AF6+'DTC EU - P&L'!AF6 -> 30514.253 | AG35: =SUM(B35:AF35) -> 2452183.5
A37: Orders
A38: Orders Woocommerce (Platform) | B38: =Summary!B89 -> 455 | C38: =Summary!C89 -> 1103 | D38: =Summary!D89 -> 926 | E38: =Summary!E89 -> 830 | F38: =Summary!F89 -> 813 | G38: =Summary!G89 -> 578 | H38: =Summary!H89 -> 420 | I38: =Summary!I89 -> 418 | ... AF38: =Summary!AF89 -> 395 | AG38: =SUM(B38:AF38) -> 16996
A39: Orders w/o renewals | B39: ='DTC US&CA - P&L'!B10+'DTC EU - P&L'!B10 -> 314 | C39: ='DTC US&CA - P&L'!C10+'DTC EU - P&L'!C10 -> 481 | D39: ='DTC US&CA - P&L'!D10+'DTC EU - P&L'!D10 -> 631 | E39: ='DTC US&CA - P&L'!E10+'DTC EU - P&L'!E10 -> 569 | F39: ='DTC US&CA - P&L'!F10+'DTC EU - P&L'!F10 -> 398 | G39: ='DTC US&CA - P&L'!G10+'DTC EU - P&L'!G10 -> 343 | H39: ='DTC US&CA - P&L'!H10+'DTC EU - P&L'!H10 -> 256 | I39: ='DTC US&CA - P&L'!I10+'DTC EU - P&L'!I10 -> 243 | ... AF39: ='DTC US&CA - P&L'!AF10+'DTC EU - P&L'!AF10 -> 125 | AG39: =SUM(B39:AF39) -> 9977
A43: Breakdown
A44: - Hardware | B44: =Summary!B14+Summary!B21 -> 56667.615 | C44: =Summary!C14+Summary!C21 -> 89314.385 | D44: =Summary!D14+Summary!D21 -> 114170.89 | E44: =Summary!E14+Summary!E21 -> 106781.23 | F44: =Summary!F14+Summary!F21 -> 72983.906 | G44: =Summary!G14+Summary!G21 -> 70591.617 | H44: =Summary!H14+Summary!H21 -> 50468.893 | I44: =Summary!I14+Summary!I21 -> 45521.827 | ... AF44: =Summary!AF14+Summary!AF21 -> 22765.276 | AG44: =SUM(B44:AF44) -> 1859965.3
A45: - Add-ons | B45: =Summary!B15+Summary!B22 -> 3291.3038 | C45: =Summary!C15+Summary!C22 -> 5322.5513 | D45: =Summary!D15+Summary!D22 -> 7496.6795 | E45: =Summary!E15+Summary!E22 -> 6161.6978 | F45: =Summary!F15+Summary!F22 -> 4935.4427 | G45: =Summary!G15+Summary!G22 -> 3488.2 | H45: =Summary!H15+Summary!H22 -> 3861.2 | I45: =Summary!I15+Summary!I22 -> 3813.3877 | ... AF45: =Summary!AF15+Summary!AF22 -> 2281.0603 | AG45: =SUM(B45:AF45) -> 130604.03
A46: - Merch | B46: =Summary!B16+Summary!B23 -> 0 | C46: =Summary!C16+Summary!C23 -> 0 | D46: =Summary!D16+Summary!D23 -> 0 | E46: =Summary!E16+Summary!E23 -> 0 | F46: =Summary!F16+Summary!F23 -> 0 | G46: =Summary!G16+Summary!G23 -> 0 | H46: =Summary!H16+Summary!H23 -> 0 | I46: =Summary!I16+Summary!I23 -> 0 | ... AF46: =Summary!AF16+Summary!AF23 -> 0 | AG46: =SUM(B46:AF46) -> 0
A47: - Yearly Pro Subscription | B47: ='DTC US&CA - P&L'!B18+Summary!B30 -> 13527.823 | C47: ='DTC US&CA - P&L'!C18+Summary!C30 -> 61379.187 | D47: ='DTC US&CA - P&L'!D18+Summary!D30 -> 28532.457 | E47: ='DTC US&CA - P&L'!E18+Summary!E30 -> 25377.945 | F47: ='DTC US&CA - P&L'!F18+Summary!F30 -> 40262.74 | G47: ='DTC US&CA - P&L'!G18+Summary!G30 -> 22447.487 | H47: ='DTC US&CA - P&L'!H18+Summary!H30 -> 15937.278 | I47: ='DTC US&CA - P&L'!I18+Summary!I30 -> 16722.427 | ... AF47: ='DTC US&CA - P&L'!AF18+Summary!AF30 -> 25953.729 | AG47: =SUM(B47:AF47) -> 677946.67
A48: - Taxes | B48: =Summary!B17+Summary!B24+Summary!B28+Summary!B31 -> 5236.6276 | C48: =Summary!C17+Summary!C24+Summary!C28+Summary!C31 -> 9497.4453 | D48: =Summary!D17+Summary!D24+Summary!D28+Summary!D31 -> 10753.031 | E48: =Summary!E17+Summary!E24+Summary!E28+Summary!E31 -> 10226.975 | F48: =Summary!F17+Summary!F24+Summary!F28+Summary!F31 -> 7808.4032 | G48: =Summary!G17+Summary!G24+Summary!G28+Summary!G31 -> 6706.9964 | H48: =Summary!H17+Summary!H24+Summary!H28+Summary!H31 -> 4713.2957 | I48: =Summary!I17+Summary!I24+Summary!I28+Summary!I31 -> 4499.4025 | ... AF48: =Summary!AF17+Summary!AF24+Summary!AF28+Summary!AF31 -> 2875.5702 | AG48: =SUM(B48:AF48) -> 182237.46
A49: - Shipping | B49: =Summary!B18+Summary!B25 -> 8167.536 | C49: =Summary!C18+Summary!C25 -> 12745.596 | D49: =Summary!D18+Summary!D25 -> 16404.599 | E49: =Summary!E18+Summary!E25 -> 15179.61 | F49: =Summary!F18+Summary!F25 -> 10423.247 | G49: =Summary!G18+Summary!G25 -> 8944.3325 | H49: =Summary!H18+Summary!H25 -> 6599.47 | I49: =Summary!I18+Summary!I25 -> 5988.8815 | ... AF49: =Summary!AF18+Summary!AF25 -> 3085.34 | AG49: =SUM(B49:AF49) -> 259537.09
A50: - Gift Bag | B50: =Summary!B19 -> 1859.07 | C50: =Summary!C19 -> 2578.71 | D50: =Summary!D19 -> 3978.01 | E50: =Summary!E19 -> 4137.93 | F50: =Summary!F19 -> 3074.47 | G50: =Summary!G19 -> 2478.76 | H50: =Summary!H19 -> 1619.19 | I50: =Summary!I19 -> 1339.33 | ... AF50: =Summary!AF19 -> 0 | AG50: =SUM(B50:AF50) -> 37553.89
A51: SUM | B51: =SUM(B44:B50) -> 88749.976 | C51: =SUM(C44:C50) -> 180837.88 | D51: =SUM(D44:D50) -> 181335.67 | E51: =SUM(E44:E50) -> 167865.39 | F51: =SUM(F44:F50) -> 139488.21 | G51: =SUM(G44:G50) -> 114657.39 | H51: =SUM(H44:H50) -> 83199.327 | I51: =SUM(I44:I50) -> 77885.256 | ... AF51: =SUM(AF44:AF50) -> 56960.976 | AG51: =SUM(B51:AF51) -> 3147844.5
A55: Units Sold (Gross) | B55: =sum(B56,B67) -> 304 | C55: =sum(C56,C67) -> 479 | D55: =sum(D56,D67) -> 617 | E55: =sum(E56,E67) -> 568 | F55: =sum(F56,F67) -> 390 | G55: =sum(G56,G67) -> 337 | H55: =sum(H56,H67) -> 242 | I55: =sum(I56,I67) -> 218 | ... AF55: =sum(AF56,AF67) -> 108 | AG55: =SUM(B55:AF55) -> 9652
A56: BB1 | B56: =sum(B60,B65) -> 304 | C56: =sum(C60,C65) -> 479 | D56: =sum(D60,D65) -> 617 | E56: =sum(E60,E65) -> 568 | F56: =sum(F60,F65) -> 390 | G56: =sum(G60,G65) -> 337 | H56: =sum(H60,H65) -> 242 | I56: =sum(I60,I65) -> 218 | ... AF56: =sum(AF60,AF65) -> 108 | AG56: =SUM(B56:AF56) -> 6702
...

Sheet DTC US&CA - P&L
A1: MAY | B1: 46143 | C1: 46144 | D1: 46145 | E1: 46146 | F1: 46147 | G1: 46148 | H1: 46149 | I1: 46150 | J1: 46151 | K1: 46152 | L1: 46153 | M1: 46154 | N1: 46155 | O1: 46156 | P1: 46157 | Q1: 46158 | R1: 46159 | S1: 46160 | T1: 46161 | U1: 46162 | V1: 46163 | W1: 46164 | X1: 46165 | Y1: 46166 | Z1: 46167 | AA1: 46168 | AB1: 46169 | AC1: 46170 | AD1: 46171 | AE1: 46172 | AF1: 46173
A2: DAY | B2: FRI | C2: SAT | D2: SUN | E2: MON | F2: TUE | G2: WED | H2: THU | I2: FRI | J2: SAT | K2: SUN | L2: MON | M2: TUE | N2: WED | O2: THU | P2: FRI | Q2: SAT | R2: SUN | S2: MON | T2: TUE | U2: WED | V2: THU | W2: FRI | X2: SAT | Y2: SUN | Z2: MON | AA2: TUE | AB2: WED | AC2: THU | AD2: FRI | AE2: SAT | AF2: SUN
A4: Revenue
A5: Revenue Woocommerce (Platform) | B5: =Summary!B13+Summary!B26 -> 87138.46 | C5: =Summary!C13+Summary!C26 -> 179999.37 | D5: =Summary!D13+Summary!D26 -> 180711.69 | E5: =Summary!E13+Summary!E26 -> 165405.78 | F5: =Summary!F13+Summary!F26 -> 138653 | G5: =Summary!G13+Summary!G26 -> 113836.49 | H5: =Summary!H13+Summary!H26 -> 82498.71 | I5: =Summary!I13+Summary!I26 -> 76938.49 | ... AF5: =Summary!AF13+Summary!AF26 -> 54985.15 | AG5: =SUM(B5:AF5) -> 3117875.4
A6: Revenue w/o renewals | B6: 74054 | C6: 117402.36 | D6: 152053.25 | E6: 140016.94 | F6: 97484.31 | G6: 91354.2 | H6: 66688.27 | I6: 60184.7 | J6: 59298.95 | K6: 60469.14 | L6: 35633.63 | M6: 37525.27 | N6: 35988.93 | O6: 461723.92 | P6: 76439.37 | Q6: 54116.66 | R6: 162182.71 | S6: 60935.9 | T6: 118941.4 | U6: 28718.59 | V6: 33672.19 | W6: 44170.98 | X6: 57682.97 | Y6: 68993.91 | Z6: 64718.72 | AA6: 37953.21 | AB6: 29677.42 | AC6: 19403.16 | AD6: 26986.47 | AE6: 26879.91 | AF6: 28968.45 | AG6: =SUM(B6:AF6) -> 2430319.9
A8: Orders
A9: Orders Woocommerce (Platform) | B9: =Summary!B90 -> 448 | C9: =Summary!C90 -> 1096 | D9: =Summary!D90 -> 921 | E9: =Summary!E90 -> 816 | F9: =Summary!F90 -> 806 | G9: =Summary!G90 -> 572 | H9: =Summary!H90 -> 417 | I9: =Summary!I90 -> 411 | ... AF9: =Summary!AF90 -> 386 | AG9: =SUM(B9:AF9) -> 16825
A10: Orders w/o renewals | B10: 311 | C10: 478 | D10: 629 | E10: 562 | F10: 396 | G10: 342 | H10: 254 | I10: 239 | J10: 230 | K10: 245 | L10: 138 | M10: 154 | N10: 150 | O10: 1910 | P10: 318 | Q10: 224 | R10: 632 | S10: 239 | T10: 485 | U10: 123 | V10: 142 | W10: 190 | X10: 244 | Y10: 302 | Z10: 284 | AA10: 132 | AB10: 112 | AC10: 82 | AD10: 104 | AE10: 111 | AF10: 120 | AG10: =SUM(B10:AF10) -> 9882
A14: Breakdown
A15: - Hardware | B15: =Summary!B14 -> 55904.1 | C15: =Summary!C14 -> 89119.9 | D15: =Summary!D14 -> 113979.5 | E15: =Summary!E14 -> 105630.4 | F15: =Summary!F14 -> 72773.79 | G15: =Summary!G14 -> 70375.4 | H15: =Summary!H14 -> 50044.4 | I15: =Summary!I14 -> 45304.8 | ... AF15: =Summary!AF14 -> 21928.4 | AG15: =SUM(B15:AF15) -> 1846377.1
A16: - Add-ons | B16: =Summary!B15 -> 3219.4 | C16: =Summary!C15 -> 5231.8 | D16: =Summary!D15 -> 7477.6 | E16: =Summary!E15 -> 6096 | F16: =Summary!F15 -> 4921.9 | G16: =Summary!G15 -> 3488.2 | H16: =Summary!H15 -> 3861.2 | I16: =Summary!I15 -> 3548.8 | ... AF16: =Summary!AF15 -> 1990 | AG16: =SUM(B16:AF16) -> 128437.77
A17: - Merch | B17: =Summary!B16 -> 0 | C17: =Summary!C16 -> 0 | D17: =Summary!D16 -> 0 | E17: =Summary!E16 -> 0 | F17: =Summary!F16 -> 0 | G17: =Summary!G16 -> 0 | H17: =Summary!H16 -> 0 | I17: =Summary!I16 -> 0 | ... AF17: =Summary!AF16 -> 0 | AG17: =SUM(B17:AF17) -> 0
A18: - Yearly Pro Subscription | B18: =Summary!B27 -> 13169.43 | C18: =Summary!C27 -> 61028.86 | D18: =Summary!D27 -> 28269.92 | E18: =Summary!E27 -> 24752.74 | F18: =Summary!F27 -> 39839.71 | G18: =Summary!G27 -> 22011.27 | H18: =Summary!H27 -> 15844.42 | I18: =Summary!I27 -> 16479.35 | ... AF18: =Summary!AF27 -> 25596.83 | AG18: =SUM(B18:AF18) -> 671250.22
A19: - Taxes | B19: =Summary!B17+Summary!B28 -> 4947.91 | C19: =Summary!C17+Summary!C28 -> 9347.28 | D19: =Summary!D17+Summary!D28 -> 10643.13 | E19: =Summary!E17+Summary!E28 -> 9796.14 | F19: =Summary!F17+Summary!F28 -> 7660.85 | G19: =Summary!G17+Summary!G28 -> 6567.9 | H19: =Summary!H17+Summary!H28 -> 4588.66 | I19: =Summary!I17+Summary!I28 -> 4342.19 | ... AF19: =Summary!AF17+Summary!AF28 -> 2524.44 | AG19: =SUM(B19:AF19) -> 176989.85
A20: - Shipping | B20: =Summary!B18 -> 8038.55 | C20: =Summary!C18 -> 12692.82 | D20: =Summary!D18 -> 16363.53 | E20: =Summary!E18 -> 14992.57 | F20: =Summary!F18 -> 10382.28 | G20: =Summary!G18 -> 8914.96 | H20: =Summary!H18 -> 6540.84 | I20: =Summary!I18 -> 5924.02 | ... AF20: =Summary!AF18 -> 2945.48 | AG20: =SUM(B20:AF20) -> 257266.59
A21: - Gift Bag | B21: =Summary!B19 -> 1859.07 | C21: =Summary!C19 -> 2578.71 | D21: =Summary!D19 -> 3978.01 | E21: =Summary!E19 -> 4137.93 | F21: =Summary!F19 -> 3074.47 | G21: =Summary!G19 -> 2478.76 | H21: =Summary!H19 -> 1619.19 | I21: =Summary!I19 -> 1339.33 | ... AF21: =Summary!AF19 -> 0 | AG21: =SUM(B21:AF21) -> 37553.89
A22: SUM | B22: =SUM(B15:B21) -> 87138.46 | C22: =SUM(C15:C21) -> 179999.37 | D22: =SUM(D15:D21) -> 180711.69 | E22: =SUM(E15:E21) -> 165405.78 | F22: =SUM(F15:F21) -> 138653 | G22: =SUM(G15:G21) -> 113836.49 | H22: =SUM(H15:H21) -> 82498.71 | I22: =SUM(I15:I21) -> 76938.49 | ... AF22: =SUM(AF15:AF21) -> 54985.15 | AG22: =SUM(B22:AF22) -> 3117875.4
A26: Units Sold (Gross) | B26: =sum(B27,B38) -> 300 | C26: =sum(C27,C38) -> 478 | D26: =sum(D27,D38) -> 616 | E26: =sum(E27,E38) -> 562 | F26: =sum(F27,F38) -> 389 | G26: =sum(G27,G38) -> 336 | H26: =sum(H27,H38) -> 240 | I26: =sum(I27,I38) -> 217 | ... AF26: =sum(AF27,AF38) -> 104 | AG26: =SUM(B26:AF26) -> 9585
A27: BB1 | B27: =sum(B31,B36) -> 300 | C27: =sum(C31,C36) -> 478 | D27: =sum(D31,D36) -> 616 | E27: =sum(E31,E36) -> 562 | F27: =sum(F31,F36) -> 389 | G27: =sum(G31,G36) -> 336 | H27: =sum(H31,H36) -> 240 | I27: =sum(I31,I36) -> 217 | ... AF27: =sum(AF31,AF36) -> 104 | AG27: =SUM(B27:AF27) -> 6635
A28: Smart Bird Feeder PRO | B28: 0 | C28: 0 | D28: 0 | E28: 0 | F28: 0 | G28: 0 | H28: 0 | I28: 0 | J28: 0 | K28: 0 | L28: 0 | M28: 0 | N28: 0 | O28: 0 | P28: 0 | Q28: 0 | R28: 0 | S28: 0 | T28: 0 | U28: 0 | V28: 0 | W28: 0 | X28: 0 | Y28: 0 | Z28: 0 | AA28: 0 | AB28: 0 | AC28: 0 | AD28: 0 | AE28: 0 | AF28: 0 | AG28: =SUM(B28:AF28) -> 0
A29: Smart Bird Feeder PRO Solar | B29: 223 | C29: 354 | D29: 471 | E29: 442 | F29: 307 | G29: 235 | H29: 172 | I29: 151 | J29: 155 | K29: 152 | L29: 79 | M29: 101 | N29: 88 | O29: 117 | P29: 91 | Q29: 79 | R29: 132 | S29: 111 | T29: 97 | U29: 73 | V29: 107 | W29: 123 | X29: 169 | Y29: 203 | Z29: 203 | AA29: 89 | AB29: 63 | AC29: 45 | AD29: 55 | AE29: 60 | AF29: 66 | AG29: =SUM(B29:AF29) -> 4813
A30: Smart Bird Feeder PRO Solar with PEX (Retail SKU) | B30: 0 | C30: 0 | D30: 0 | E30: 0 | F30: 0 | G30: 0 | H30: 0 | I30: 0 | J30: 0 | K30: 0 | L30: 0 | M30: 0 | N30: 0 | O30: 0 | P30: 0 | Q30: 0 | R30: 0 | S30: 0 | T30: 0 | U30: 0 | V30: 0 | W30: 0 | X30: 0 | Y30: 0 | Z30: 0 | AA30: 0 | AB30: 0 | AC30: 0 | AD30: 0 | AE30: 0 | AF30: 0 | AG30: =SUM(B30:AF30) -> 0
A31: SUM (BB1 SBF) | B31: =SUM(B28:B30) -> 223 | C31: =SUM(C28:C30) -> 354 | D31: =SUM(D28:D30) -> 471 | E31: =SUM(E28:E30) -> 442 | F31: =SUM(F28:F30) -> 307 | G31: =SUM(G28:G30) -> 235 | H31: =SUM(H28:H30) -> 172 | I31: =SUM(I28:I30) -> 151 | ... AF31: =SUM(AF28:AF30) -> 66 | AG31: =SUM(B31:AF31) -> 4813
A33: Smart Hummingbird Feeder PRO | B33: 0 | C33: 0 | D33: 0 | E33: 0 | F33: 0 | G33: 0 | H33: 0 | I33: 1 | J33: 0 | K33: 0 | L33: 1 | M33: 0 | N33: 0 | O33: 0 | P33: 0 | Q33: 0 | R33: 0 | S33: 0 | T33: 0 | U33: 0 | V33: 0 | W33: 0 | X33: 0 | Y33: 0 | Z33: 0 | AA33: 0 | AB33: 0 | AC33: 0 | AD33: 0 | AE33: 0 | AF33: 0 | AG33: =SUM(B33:AF33) -> 2
A34: Smart Hummingbird Feeder PRO Solar | B34: 5 | C34: 0 | D34: 0 | E34: 4 | F34: 1 | G34: 4 | H34: 0 | I34: 1 | J34: 0 | K34: 0 | L34: 0 | M34: 2 | N34: 0 | O34: 0 | P34: 0 | Q34: 0 | R34: 0 | S34: 0 | T34: 0 | U34: 0 | V34: 0 | W34: 0 | X34: 0 | Y34: 0 | Z34: 0 | AA34: 0 | AB34: 0 | AC34: 0 | AD34: 0 | AE34: 0 | AF34: 0 | AG34: =SUM(B34:AF34) -> 17
A35: Smart Hummingbird Feeder PRO Solar (Retail SKU) | B35: 72 | C35: 124 | D35: 145 | E35: 116 | F35: 81 | G35: 97 | H35: 68 | I35: 64 | J35: 62 | K35: 62 | L35: 45 | M35: 34 | N35: 25 | O35: 53 | P35: 31 | Q35: 34 | R35: 49 | S35: 28 | T35: 45 | U35: 37 | V35: 29 | W35: 53 | X35: 65 | Y35: 78 | Z35: 67 | AA35: 49 | AB35: 43 | AC35: 24 | AD35: 46 | AE35: 39 | AF35: 38 | AG35: =SUM(B35:AF35) -> 1803
A36: SUM (BB1 HBF) | B36: =SUM(B33:B35) -> 77 | C36: =SUM(C33:C35) -> 124 | D36: =SUM(D33:D35) -> 145 | E36: =SUM(E33:E35) -> 120 | F36: =SUM(F33:F35) -> 82 | G36: =SUM(G33:G35) -> 101 | H36: =SUM(H33:H35) -> 68 | I36: =SUM(I33:I35) -> 66 | ... AF36: =SUM(AF33:AF35) -> 38 | AG36: =SUM(B36:AF36) -> 1822
A38: BB2 | B38: =sum(B42,B46,B51) -> 0 | C38: =sum(C42,C46,C51) -> 0 | D38: =sum(D42,D46,D51) -> 0 | E38: =sum(E42,E46,E51) -> 0 | F38: =sum(F42,F46,F51) -> 0 | G38: =sum(G42,G46,G51) -> 0 | H38: =sum(H42,H46,H51) -> 0 | I38: =sum(I42,I46,I51) -> 0 | ... AF38: =sum(AF42,AF46,AF51) -> 0 | AG38: =SUM(B38:AF38) -> 2950
A39: Birdbuddy 2 | B39: 0 | C39: 0 | D39: 0 | E39: 0 | F39: 0 | G39: 0 | H39: 0 | I39: 0 | J39: 0 | K39: 0 | L39: 0 | M39: 0 | N39: 22 | O39: 1728 | P39: 179 | Q39: 96 | R39: 475 | S39: 102 | T39: 347 | U39: 1 | V39: 0 | W39: 0 | X39: 0 | Y39: 0 | Z39: 0 | AA39: 0 | AB39: 0 | AC39: 0 | AD39: 0 | AE39: 0 | AF39: 0 | AG39: =SUM(B39:AF39) -> 2950
A40: Birdbuddy 2 PRO | AG40: =SUM(B40:AF40) -> 0
A41: Birdbuddy 2 Retail SKU | AG41: =SUM(B41:AF41) -> 0
A42: SUM (BB2 SBF) | B42: =SUM(B39:B41) -> 0 | C42: =SUM(C39:C41) -> 0 | D42: =SUM(D39:D41) -> 0 | E42: =SUM(E39:E41) -> 0 | F42: =SUM(F39:F41) -> 0 | G42: =SUM(G39:G41) -> 0 | H42: =SUM(H39:H41) -> 0 | I42: =SUM(I39:I41) -> 0 | ... AF42: =SUM(AF39:AF41) -> 0 | AG42: =SUM(B42:AF42) -> 2950
A44: Birdbuddy 2 Nectar | AG44: =SUM(B44:AF44) -> 0
A45: Birdbuddy 2 Nectar PRO | AG45: =SUM(B45:AF45) -> 0
A46: SUM (BB2 HBF) | B46: =sum(B44:B45) -> 0 | C46: =sum(C44:C45) -> 0 | D46: =sum(D44:D45) -> 0 | E46: =sum(E44:E45) -> 0 | F46: =sum(F44:F45) -> 0 | G46: =sum(G44:G45) -> 0 | H46: =sum(H44:H45) -> 0 | I46: =sum(I44:I45) -> 0 | ... AF46: =sum(AF44:AF45) -> 0 | AG46: =SUM(B46:AF46) -> 0
A48: Birdbuddy 2 Mini non Solar | AG48: =SUM(B48:AF48) -> 0
A49: Birdbuddy 2 Mini Solar | AG49: =SUM(B49:AF49) -> 0
A50: BB2 Mini Retail SKU | AG50: =SUM(B50:AF50) -> 0
A51: SUM (BB2 MINI) | B51: =sum(B48:B50) -> 0 | C51: =sum(C48:C50) -> 0 | D51: =sum(D48:D50) -> 0 | E51: =sum(E48:E50) -> 0 | F51: =sum(F48:F50) -> 0 | G51: =sum(G48:G50) -> 0 | H51: =sum(H48:H50) -> 0 | I51: =sum(I48:I50) -> 0 | ... AF51: =sum(AF48:AF50) -> 0 | AG51: =SUM(B51:AF51) -> 0
A53: Wall Mount | B53: 0 | C53: 0 | D53: 0 | E53: 0 | F53: 0 | G53: 0 | H53: 0 | I53: 0 | J53: 0 | K53: 0 | L53: 0 | M53: 0 | N53: 0 | O53: 0 | P53: 0 | Q53: 0 | R53: 0 | S53: 0 | T53: 0 | U53: 0 | V53: 0 | W53: 0 | X53: 0 | Y53: 0 | Z53: 0 | AA53: 0 | AB53: 0 | AC53: 0 | AD53: 0 | AE53: 0 | AF53: 0 | AG53: =SUM(B53:AF53) -> 0
...

Sheet DTC EU - P&L
A1: MAY | B1: 46143 | C1: 46144 | D1: 46145 | E1: 46146 | F1: 46147 | G1: 46148 | H1: 46149 | I1: 46150 | J1: 46151 | K1: 46152 | L1: 46153 | M1: 46154 | N1: 46155 | O1: 46156 | P1: 46157 | Q1: 46158 | R1: 46159 | S1: 46160 | T1: 46161 | U1: 46162 | V1: 46163 | W1: 46164 | X1: 46165 | Y1: 46166 | Z1: 46167 | AA1: 46168 | AB1: 46169 | AC1: 46170 | AD1: 46171 | AE1: 46172 | AF1: 46173
A2: DAY | B2: FRI | C2: SAT | D2: SUN | E2: MON | F2: TUE | G2: WED | H2: THU | I2: FRI | J2: SAT | K2: SUN | L2: MON | M2: TUE | N2: WED | O2: THU | P2: FRI | Q2: SAT | R2: SUN | S2: MON | T2: TUE | U2: WED | V2: THU | W2: FRI | X2: SAT | Y2: SUN | Z2: MON | AA2: TUE | AB2: WED | AC2: THU | AD2: FRI | AE2: SAT | AF2: SUN
A4: Revenue
A5: Revenue Woocommerce (Platform) | B5: =Summary!B20+Summary!B29 -> 1611.5159 | C5: =Summary!C20+Summary!C29 -> 838.50509 | D5: =Summary!D20+Summary!D29 -> 623.97892 | E5: =Summary!E20+Summary!E29 -> 2459.6111 | F5: =Summary!F20+Summary!F29 -> 835.21028 | G5: =Summary!G20+Summary!G29 -> 820.90263 | H5: =Summary!H20+Summary!H29 -> 700.61677 | I5: =Summary!I20+Summary!I29 -> 946.76563 | ... AF5: =Summary!AF20+Summary!AF29 -> 1975.8255 | AG5: =SUM(B5:AF5) -> 29969.099
