Workbook
Name zsupermetrics_ru0GDtbZzDLHQOQtJJ6K08MvUDyyp7: #REF!
Name zsupermetrics_DQl8lUbpTRu3fayaJJi7lVfOGKjNU4: 'Data - P&L'!$A$3:$A$4
Name zsupermetrics_BioPyGBzcBsy60UCQmPcTuFReEmghI: 'Data - P&L'!$B$2:$B$3
Name zsupermetrics_refreshAll: SupermetricsQueries!$H$5
Name zsupermetrics_n3GtLgiKpTmd2pYmQNMuq6TPD0qE0b: #REF!
Name zsupermetrics_refreshAllSilent: SupermetricsQueries!$H$6
Name zsupermetrics_Mgms9p0QzysYvrIhnsKACeVBVxfIEO: #REF!
Name zsupermetrics_Mgms9p0QzysYvrIhnsKACeVBVxfIEO: 'Data - P&L'!$A$2:$A$3
Name zsupermetrics_forceRefresh: SupermetricsQueries!$H$4
Name zsupermetrics_wbYMmT0YL9bAN0yhimW0ziPFnia9Dx: #REF!
Name zsupermetrics_iNpyVy90bWCI0yUaFQpxOtzWMa6sW4: #REF!
Name zsupermetrics_xwoIpANxRm908eDp5oKTwQpEI8gvD4: #REF!
Name zsupermetrics_n3GtLgiKpTmd2pYmQNMuq6TPD0qE0b: 'Data - P&L'!$B$4:$B$5
Name rdataslayer_42b112e4e4be4305bb4c1be75e2dd549: 'Data - P&L'!$B$2:$C$3
Name zsupermetrics_9i4W4hgd80uRpQLMeX0eRnESN8gjyv: #REF!
Name zsupermetrics_5bmwtOpHUbSYmDMeuCPkrxaojTprPP: #REF!
Name rdataslayer_3753ddf3234e496aa261974a0222e193: 'Data - P&L'!$H$2:$I$2
Name zsupermetrics_SGBxROnInO9rFyh3H7j2Lldx0Bdc5v: #REF!
Name zsupermetrics_pxuhRTEmIU93xSgKclyxajD0fCZ6rF: #REF!
Name zsupermetrics_ru0GDtbZzDLHQOQtJJ6K08MvUDyyp7: 'Data - P&L'!$B$4:$B$5
Name zsupermetrics_qWp7V908pNEYMtfv8QZvSTeDnBAHOU: 'Data - P&L'!$B$5:$C$13
Name rdataslayer_4a0f150f4f2f4e4f85c890c75b7a1fa4: #REF!
Name zsupermetrics_HgZqhorObHOtZHuyJjpmyYaEPoYntx: #REF!
Name zsupermetrics_YsFuuYtr8vOdNXCCPiFJIO38NP4b2T: #REF!
Name zsupermetrics_DQl8lUbpTRu3fayaJJi7lVfOGKjNU4: #REF!
Name zsupermetrics_YVuzfmsfdurz7Ldl84Rfns8oka6LsS: #REF!
Name zsupermetrics_4VkB7ij7WO0JjKBEgvjB2GHjSy2Egm: #REF!
Name zsupermetrics_9i4W4hgd80uRpQLMeX0eRnESN8gjyv: 'Data - P&L'!$C$13
Name zsupermetrics_lx4cNai7gT6tH4j08ZRkI21Qlpjioi: #REF!
Name rdataslayer_d70e473bcafe40a3aa834ce157fb2ba3: #REF!
Name zsupermetrics_NugLlrQxlKiqhxQae8EFpITBm1pLCj: 'Data - P&L'!$B$6:$C$13
Name zsupermetrics_8xojRjNDjo2jWHGDWjFEhflhyIq3Hq: Summary!$K$8:$K$30
Name rdataslayer_3753ddf3234e496aa261974a0222e193: #REF!
Name zsupermetrics_iNpyVy90bWCI0yUaFQpxOtzWMa6sW4: 'Data - P&L'!$A$2:$A$3
Name rdataslayer_4a0f150f4f2f4e4f85c890c75b7a1fa4: 'Data - P&L'!$D$2:$E$3
Name zsupermetrics_BioPyGBzcBsy60UCQmPcTuFReEmghI: #REF!
Name zsupermetrics_qWp7V908pNEYMtfv8QZvSTeDnBAHOU: #REF!
Name zsupermetrics_8xojRjNDjo2jWHGDWjFEhflhyIq3Hq: #REF!
Name zsupermetrics_wbYMmT0YL9bAN0yhimW0ziPFnia9Dx: 'Data - P&L'!$A$2:$A$3
Name zsupermetrics_4VkB7ij7WO0JjKBEgvjB2GHjSy2Egm: 'Data - P&L'!$B$4:$C$10
Name zsupermetrics_lx4cNai7gT6tH4j08ZRkI21Qlpjioi: 'Data - P&L'!$B$4:$C$13
Name rdataslayer_42b112e4e4be4305bb4c1be75e2dd549: #REF!
Name rdataslayer_adf57e64065742daa5b4161161b1c3ca: #REF!
Name rdataslayer_adf57e64065742daa5b4161161b1c3ca: 'Data - P&L'!$B$4:$D$5
Name zsupermetrics_NugLlrQxlKiqhxQae8EFpITBm1pLCj: #REF!
Name zsupermetrics_xwoIpANxRm908eDp5oKTwQpEI8gvD4: #REF!
Name zsupermetrics_YsFuuYtr8vOdNXCCPiFJIO38NP4b2T: 'Data - P&L'!$B$4:$C$13
Name rdataslayer_d70e473bcafe40a3aa834ce157fb2ba3: 'Data - P&L'!$C$8:$D$9
Name zsupermetrics_HgZqhorObHOtZHuyJjpmyYaEPoYntx: 'Data - P&L'!$B$4:$B$5

Sheet Summary
A1: 45292 | B1: 45292 | C1: 45293 | D1: 45294 | E1: 45295 | F1: 45296 | G1: 45297 | H1: 45298 | I1: 45299 | J1: 45300 | K1: 45301 | L1: 45302 | M1: 45303 | N1: 45304 | O1: 45305 | P1: 45306 | Q1: 45307 | R1: 45308 | S1: 45309 | T1: 45310 | U1: 45311 | V1: 45312 | W1: 45313 | X1: 45314 | Y1: 45315 | Z1: 45316 | AA1: 45317 | AB1: 45318 | AC1: 45319 | AD1: 45320 | AE1: 45321 | AF1: 45322
B2: MON | C2: TUE | D2: WED | E2: THU | F2: FRI | G2: SAT | H2: SUN | I2: MON | J2: TUE | K2: WED | L2: THU | M2: FRI | N2: SAT | O2: SUN | P2: MON | Q2: TUE | R2: WED | S2: THU | T2: FRI | U2: SAT | V2: SUN | W2: MON | X2: TUE | Y2: WED | Z2: THU | AA2: FRI | AB2: SAT | AC2: SUN | AD2: MON | AE2: TUE | AF2: WED
A3: Weekend Work | B3: Peter | C3: Peter | G3: Peter | H3: Peter | N3: Peco | O3: Peco | U3: Peco | V3: Peco | AB3: Peter | AC3: Peter
A4: Notes
H5: Increased SKU4 stock by 50 | I5: 13:20 - SKU1 Amazon button, SKU2 updated to 194 stock, SKU3 back in stock with 393, SKU4 updated to 200 stock. On shop page, we show SKU3 instead of SKU4. | T5: 11:00 - SKU4 out of stock / Pro Bundle, yellow out of stock 13:27 - "20% off" promo ending / Reduced pricing for add-ons | Y5: - First order with new A/B test prices: #131667 (12:31) | AF5: - All yellow units option out of stock (15:37)
P6: Seeds Launch | Y6: Pricing A/B Test
A8: DTC Revenue | B8: 33166.99 | C8: 32204.7 | D8: 37759.59 | E8: 34093.84 | F8: 34903.7 | G8: 37601.7 | H8: 38315 | I8: 31136.13 | J8: 26907.68 | K8: 24059.75 | L8: 28780.21 | M8: 32396.98 | N8: 29630.85 | O8: 27553.58 | P8: 27869.29 | Q8: 25796.31 | R8: 32403.83 | S8: 26914.94 | T8: 27142.16 | U8: 34815.06 | V8: 18881.55 | W8: 20302.32 | X8: 22498.63 | Y8: 18260.61 | Z8: 18187.96 | AA8: 19073.76 | AB8: 20021.17 | AC8: 21449.04 | AD8: 20102.22 | AE8: 14972.58 | AF8: 17850.13
A9: - Hardware | B9: 20897.8 | C9: 21180.8 | D9: 27090.25 | E9: 24278.75 | F9: 23606.1 | G9: 25814.7 | H9: 24168.1 | I9: 21712.3 | J9: 19451.11 | K9: 17573.24 | L9: 20147.05 | M9: 24321.85 | N9: 19256.53 | O9: 17973.25 | P9: 19669.35 | Q9: 18340.13 | R9: 23673.5 | S9: 19148.68 | T9: 19822.35 | U9: 25440.05 | V9: 10620.2 | W9: 13425.9 | X9: 16754.05 | Y9: 13233.25 | Z9: 12355.35 | AA9: 12852.2 | AB9: 13490.2 | AC9: 15059.01 | AD9: 14025.8 | AE9: 10521.8 | AF9: 13440.2
A10: - Add-ons | B10: 8056.4 | C10: 7124.45 | D10: 6099.95 | E10: 5641.95 | F10: 6929.25 | G10: 7182.45 | H10: 9316.05 | I10: 5724.7 | J10: 4332.49 | K10: 3659.35 | L10: 5253.45 | M10: 4228.2 | N10: 6530.02 | O10: 5810 | P10: 4647 | Q10: 4200.82 | R10: 4763.7 | S10: 4177.27 | T10: 3701.15 | U10: 4704.8 | V10: 5101.75 | W10: 3964.65 | X10: 2996.15 | Y10: 2759.5 | Z10: 3347.65 | AA10: 3426.65 | AB10: 3644.4 | AC10: 3290.09 | AD10: 3086.35 | AE10: 2426 | AF10: 2053.65
A11: - Merch | B11: 58.14 | C11: 0 | D11: 76 | E11: 19 | F11: 44.99 | G11: 19 | H11: 130.15 | I11: 0 | J11: 58.99 | K11: 25.5 | L11: 39.99 | M11: 0 | N11: 0 | O11: 0 | P11: 39.99 | Q11: 0 | R11: 0 | S11: 0 | T11: 0 | U11: 0 | V11: 29.99 | W11: 0 | X11: 0 | Y11: 0 | Z11: 0 | AA11: 0 | AB11: 0 | AC11: 0 | AD11: 0 | AE11: 0 | AF11: 0
A12: - Seeds | B12: 0 | C12: 0 | D12: 0 | E12: 0 | F12: 0 | G12: 0 | H12: 0 | I12: 0 | J12: 0 | K12: 0 | L12: 0 | M12: 0 | N12: 0 | O12: 0 | P12: 32.8 | Q12: 91 | R12: 157.8 | S12: 297 | T12: 285.64 | U12: 272.37 | V12: 326.37 | W12: 271.72 | X12: 79.6 | Y12: 39.8 | Z12: 109.6 | AA12: 185.67 | AB12: 181.72 | AC12: 257.3 | AD12: 279.41 | AE12: 76.62 | AF12: 163.2
A13: - Taxes | B13: 1684.65 | C13: 1759.45 | D13: 2003.39 | E13: 1819.14 | F13: 1928.36 | G13: 2080.55 | H13: 1985.7 | I13: 1559.13 | J13: 1380.09 | K13: 1121.66 | L13: 1469.72 | M13: 1786.93 | N13: 1504.3 | O13: 1380.33 | P13: 1460.15 | Q13: 1348.36 | R13: 1757.83 | S13: 1417.99 | T13: 1343.02 | U13: 2054.84 | V13: 1013.24 | W13: 1121.05 | X13: 1175.83 | Y13: 939.06 | Z13: 1036.36 | AA13: 1084.24 | AB13: 1022.85 | AC13: 1131.64 | AD13: 1033.66 | AE13: 620.16 | AF13: 1017.08
A14: - Shipping | B14: 2470 | C14: 2140 | D14: 2490 | E14: 2335 | F14: 2395 | G14: 2505 | H14: 2715 | I14: 2140 | J14: 1685 | K14: 1680 | L14: 1870 | M14: 2060 | N14: 2340 | O14: 2390 | P14: 2020 | Q14: 1816 | R14: 2051 | S14: 1874 | T14: 1990 | U14: 2343 | V14: 1790 | W14: 1519 | X14: 1493 | Y14: 1289 | Z14: 1339 | AA14: 1525 | AB14: 1682 | AC14: 1711 | AD14: 1677 | AE14: 1328 | AF14: 1176
A15: Amazon Revenue | B15: =B16+B17+B18+B19+B20 -> 8259.3 | C15: =C16+C17+C18+C19+C20 -> 8509.69 | D15: =D16+D17+D18+D19+D20 -> 9959.99 | E15: =E16+E17+E18+E19+E20 -> 7222.59 | F15: =F16+F17+F18+F19+F20 -> 7395.73 | G15: =G16+G17+G18+G19+G20 -> 6262.25 | H15: =H16+H17+H18+H19+H20 -> 5480.06 | I15: =I16+I17+I18+I19+I20 -> 8883.31 | ... AF15: =AF16+AF17+AF18+AF19+AF20 -> 14667.91
A16: - Hardware | B16: 7579.26 | C16: 7878.36 | D16: 9382.76 | E16: 6797.99 | F16: 6870.37 | G16: 5854.37 | H16: 5096.37 | I16: 8203.4 | J16: 7081.24 | K16: 5634.26 | L16: 6359.39 | M16: 6559.07 | N16: 6368.68 | O16: 5184.96 | P16: 5980.28 | Q16: 4765.08 | R16: 5087.93 | S16: 6712.04 | T16: 7238.85 | U16: 11009.99 | V16: 13434.09 | W16: 13110.93 | X16: 8315.35 | Y16: 10572.52 | Z16: 6884.22 | AA16: 9832.15 | AB16: 9240.78 | AC16: 13967.45 | AD16: 15532.95 | AE16: 10092.73 | AF16: 13530.04
A17: - Add-ons | B17: 166.38 | C17: 87 | D17: 0 | E17: 0 | F17: 0 | G17: 0 | H17: 58 | I17: 116 | J17: 108.38 | K17: 0 | L17: 29 | M17: 166.38 | N17: 0 | O17: 29 | P17: 29 | Q17: 0 | R17: 87 | S17: 87 | T17: 0 | U17: 166.38 | V17: 290 | W17: 203 | X17: 232 | Y17: 261 | Z17: 232 | AA17: 261 | AB17: 435 | AC17: 754 | AD17: 406 | AE17: 448.76 | AF17: 203
A18: - Tax | B18: 503.88 | C18: 523.33 | D18: 567.45 | E18: 424.6 | F18: 520.47 | G18: 398.03 | H18: 325.29 | I18: 562.31 | J18: 476.34 | K18: 374.44 | L18: 442.43 | M18: 440.97 | N18: 434.23 | O18: 392.69 | P18: 413.92 | Q18: 341.09 | R18: 378.35 | S18: 492.53 | T18: 474.88 | U18: 805.87 | V18: 979.14 | W18: 980.73 | X18: 627.12 | Y18: 737.77 | Z18: 475.86 | AA18: 680.01 | AB18: 681.78 | AC18: 1027.38 | AD18: 1041.16 | AE18: 700.87 | AF18: 917.39
A19: - Shipping | B19: 0.5 | C19: 11.87 | D19: 0.5 | E19: 0 | F19: 0.25 | G19: 5.21 | H19: 0.25 | I19: 1 | J19: 21.15 | K19: 0.25 | L19: 1 | M19: 14.64 | N19: 0.5 | O19: 0 | P19: 6.4 | Q19: 0.75 | R19: 0 | S19: 7.74 | T19: 0 | U19: 11.83 | V19: 7.74 | W19: 0 | X19: 0.25 | Y19: 17.49 | Z19: 25.82 | AA19: 12.16 | AB19: 0 | AC19: 0.5 | AD19: 30.14 | AE19: 0.5 | AF19: 8.35
A20: - Gift Wrap | B20: 9.28 | C20: 9.13 | D20: 9.28 | E20: 0 | F20: 4.64 | G20: 4.64 | H20: 0.15 | I20: 0.6 | J20: 4.79 | K20: 0.15 | L20: 5.09 | M20: 5.09 | N20: 4.79 | O20: 0 | P20: 18.11 | Q20: 0.45 | R20: 0 | S20: 0.45 | T20: 0 | U20: 9.13 | V20: 13.92 | W20: 8.98 | X20: 18.11 | Y20: 0.3 | Z20: 27.09 | AA20: 0.15 | AB20: 0 | AC20: 13.77 | AD20: 26.59 | AE20: 0.3 | AF20: 9.13
A21: Digital Marketplaces Revenue | B21: =SUM(B26,B22) -> 0 | C21: =SUM(C26,C22) -> 0 | D21: =SUM(D26,D22) -> 0 | E21: =SUM(E26,E22) -> 0 | F21: =SUM(F26,F22) -> 0 | G21: =SUM(G26,G22) -> 0 | H21: =SUM(H26,H22) -> 0 | I21: =SUM(I26,I22) -> 0 | ... AF21: =SUM(AF26,AF22) -> 0
A22: Rachio | B22: =SUM(B23:B25) -> 0 | C22: =SUM(C23:C25) -> 0 | D22: =SUM(D23:D25) -> 0 | E22: =SUM(E23:E25) -> 0 | F22: =SUM(F23:F25) -> 0 | G22: =SUM(G23:G25) -> 0 | H22: =SUM(H23:H25) -> 0 | I22: =SUM(I23:I25) -> 0 | ... AF22: =SUM(AF23:AF25) -> 0
A23: - Hardware | B23: 0 | C23: 0 | D23: 0 | E23: 0 | F23: 0 | G23: 0 | H23: 0 | I23: 0 | J23: 0 | K23: 0 | L23: 0 | M23: 0 | N23: 0 | O23: 0 | P23: 0 | Q23: 0 | R23: 299.99 | S23: 0 | T23: 299.99 | U23: 0 | V23: 0 | W23: 0 | X23: 0 | Y23: 0 | Z23: 0 | AA23: 0 | AB23: 0 | AC23: 0 | AD23: 0 | AE23: 299.99 | AF23: 0
A24: - Tax | B24: =0.0614*B23 -> 0 | C24: =0.0614*C23 -> 0 | D24: =0.0614*D23 -> 0 | E24: =0.0614*E23 -> 0 | F24: =0.0614*F23 -> 0 | G24: =0.0614*G23 -> 0 | H24: =0.0614*H23 -> 0 | I24: =0.0614*I23 -> 0 | ... AF24: =0.0614*AF23 -> 0
A25: - Shipping | B25: 0 | C25: 0 | D25: 0 | E25: 0 | F25: 0 | G25: 0 | H25: 0 | I25: 0 | J25: 0 | K25: 0 | L25: 0 | M25: 0 | N25: 0 | O25: 0 | P25: 0 | Q25: 0 | R25: 0 | S25: 0 | T25: 0 | U25: 0 | V25: 0 | W25: 0 | X25: 0 | Y25: 0 | Z25: 0 | AA25: 0 | AB25: 0 | AC25: 0 | AD25: 0 | AE25: 0 | AF25: 0
A26: Weatherflow | B26: 0 | C26: 0 | D26: 0 | E26: 0 | F26: 0 | G26: 0 | H26: 0 | I26: 0 | J26: 0 | K26: 0 | L26: 0 | M26: 0 | N26: 0 | O26: 0 | P26: 0 | Q26: 0 | R26: 299 | S26: 0 | T26: 0 | U26: 0 | V26: 0 | W26: 0 | X26: 0 | Y26: 0 | Z26: 0 | AA26: 0 | AB26: 0 | AC26: 0 | AD26: 0 | AE26: 0 | AF26: 0
A27: - Hardware | B27: 0 | C27: 0 | D27: 0 | E27: 0 | F27: 0 | G27: 0 | H27: 0 | I27: 0 | J27: 0 | K27: 0 | L27: 0 | M27: 0 | N27: 0 | O27: 0 | P27: 0 | Q27: 0 | R27: 0 | S27: 0 | T27: 0 | U27: 0 | V27: 0 | W27: 0 | X27: 0 | Y27: 0 | Z27: 0 | AA27: 0 | AB27: 0 | AC27: 0 | AD27: 0 | AE27: 0 | AF27: 0
A28: - Tax | B28: =0.0614*B27 -> 0 | C28: =0.0614*C27 -> 0 | D28: =0.0614*D27 -> 0 | E28: =0.0614*E27 -> 0 | F28: =0.0614*F27 -> 0 | G28: =0.0614*G27 -> 0 | H28: =0.0614*H27 -> 0 | I28: =0.0614*I27 -> 0 | ... AF28: =0.0614*AF27 -> 0
A29: - Shipping | B29: 0 | C29: 0 | D29: 0 | E29: 0 | F29: 0 | G29: 0 | H29: 0 | I29: 0 | J29: 0 | K29: 0 | L29: 0 | M29: 0 | N29: 0 | O29: 0 | P29: 0 | Q29: 0 | R29: 0 | S29: 0 | T29: 0 | U29: 0 | V29: 0 | W29: 0 | X29: 0 | Y29: 0 | Z29: 0 | AA29: 0 | AB29: 0 | AC29: 0 | AD29: 0 | AE29: 0 | AF29: 0
A30: Total Revenue | B30: =SUM(B8+B15+B21) -> 41426.29 | C30: =SUM(C8+C15+C21) -> 40714.39 | D30: =SUM(D8+D15+D21) -> 47719.58 | E30: =SUM(E8+E15+E21) -> 41316.43 | F30: =SUM(F8+F15+F21) -> 42299.43 | G30: =SUM(G8+G15+G21) -> 43863.95 | H30: =SUM(H8+H15+H21) -> 43795.06 | I30: =SUM(I8+I15+I21) -> 40019.44 | ... AF30: =SUM(AF8+AF15+AF21) -> 32518.04
A32: B2B Revenue
A33: Best Buy | B33: =SUM(B34:B35) -> 2864.7186 | C33: =SUM(C34:C35) -> 0 | D33: =SUM(D34:D35) -> 4260.4596 | E33: =SUM(E34:E35) -> 2196.0366 | F33: =SUM(F34:F35) -> 237.7536 | G33: =SUM(G34:G35) -> 0 | H33: =SUM(H34:H35) -> 3968.5746 | I33: =SUM(I34:I35) -> 730.2432 | ... AF33: =SUM(AF34:AF35) -> 256.33871
A34: - Hardware | B34: 2699 | C34: 0 | D34: 4014 | E34: 2069 | F34: 224 | G34: 0 | H34: 3739 | I34: 688 | J34: 1221 | K34: 1110 | L34: 2211 | M34: 1131 | N34: 450 | O34: 750 | P34: 870 | Q34: 1350 | R34: 1860 | S34: 210 | T34: 3060 | U34: 2250 | V34: 3821.04 | W34: 2824.39 | X34: 1614.39 | Y34: 660 | Z34: 0 | AA34: 0 | AB34: 540 | AC34: 241.51 | AD34: 241.51 | AE34: 241.51 | AF34: 241.51
A35: - Tax | B35: =B34*'Data - P&L'!$U$3 -> 165.7186 | C35: =C34*'Data - P&L'!$U$3 -> 0 | D35: =D34*'Data - P&L'!$U$3 -> 246.4596 | E35: =E34*'Data - P&L'!$U$3 -> 127.0366 | F35: =F34*'Data - P&L'!$U$3 -> 13.7536 | G35: =G34*'Data - P&L'!$U$3 -> 0 | H35: =H34*'Data - P&L'!$U$3 -> 229.5746 | I35: =I34*'Data - P&L'!$U$3 -> 42.2432 | ... AF35: =AF34*'Data - P&L'!$U$3 -> 14.828714
A36: Target | B36: =sum(B37:B38) -> 254.736 | C36: =sum(C37:C38) -> 0 | D36: =sum(D37:D38) -> 241.9992 | E36: =sum(E37:E38) -> 254.736 | F36: =sum(F37:F38) -> 764.208 | G36: =sum(G37:G38) -> 254.736 | H36: =sum(H37:H38) -> 254.736 | I36: =sum(I37:I38) -> 748.287 | ... AF36: =sum(AF37:AF38) -> 0
A37: - Hardware | B37: 240 | C37: 0 | D37: 228 | E37: 240 | F37: 720 | G37: 240 | H37: 240 | I37: 705 | J37: 0 | K37: 684 | L37: 948 | M37: 894 | N37: 240 | O37: 240 | P37: 446 | Q37: 240 | R37: 463 | S37: 468 | T37: 0 | U37: 909 | V37: 252 | W37: 720 | X37: 240 | Y37: 12 | Z37: 228 | AA37: 1428 | AB37: 1198 | AC37: 195 | AD37: 0 | AE37: 1440 | AF37: 0
A38: - Tax | B38: =B37*'Data - P&L'!$U$3 -> 14.736 | C38: =C37*'Data - P&L'!$U$3 -> 0 | D38: =D37*'Data - P&L'!$U$3 -> 13.9992 | E38: =E37*'Data - P&L'!$U$3 -> 14.736 | F38: =F37*'Data - P&L'!$U$3 -> 44.208 | G38: =G37*'Data - P&L'!$U$3 -> 14.736 | H38: =H37*'Data - P&L'!$U$3 -> 14.736 | I38: =I37*'Data - P&L'!$U$3 -> 43.287 | ... AF38: =AF37*'Data - P&L'!$U$3 -> 0
A39: Total Revenue | B39: =B33+B36 -> 3119.4546 | C39: =C33+C36 -> 0 | D39: =D33+D36 -> 4502.4588 | E39: =E33+E36 -> 2450.7726 | F39: =F33+F36 -> 1001.9616 | G39: =G33+G36 -> 254.736 | H39: =H33+H36 -> 4223.3106 | I39: =I33+I36 -> 1478.5302 | ... AF39: =AF33+AF36 -> 256.33871
A41: App Revenue
A42: - Google Store | B42: ='App - P&L'!B90 -> 2765.3985 | C42: ='App - P&L'!C90 -> 1476.308 | D42: ='App - P&L'!D90 -> 1030.7135 | E42: ='App - P&L'!E90 -> 922.865 | F42: ='App - P&L'!F90 -> 1161.0445 | G42: ='App - P&L'!G90 -> 1303.5155 | H42: ='App - P&L'!H90 -> 1438.9295 | I42: ='App - P&L'!I90 -> 1317.493 | ... AF42: ='App - P&L'!AF90 -> 170.374
A43: - Apple Store | B43: ='App - P&L'!B91 -> 9876.4446 | C43: ='App - P&L'!C91 -> 5822.5217 | D43: ='App - P&L'!D91 -> 4519.4913 | E43: ='App - P&L'!E91 -> 4405.7317 | F43: ='App - P&L'!F91 -> 5186.4887 | G43: ='App - P&L'!G91 -> 6618.6471 | H43: ='App - P&L'!H91 -> 6029.4343 | I43: ='App - P&L'!I91 -> 4108.6256 | ... AF43: ='App - P&L'!AF91 -> 986.061
...

Sheet DTC - P&L
A1: JANUARY | B1: 45292 | C1: 45293 | D1: 45294 | E1: 45295 | F1: 45296 | G1: 45297 | H1: 45298 | I1: 45299 | J1: 45300 | K1: 45301 | L1: 45302 | M1: 45303 | N1: 45304 | O1: 45305 | P1: 45306 | Q1: 45307 | R1: 45308 | S1: 45309 | T1: 45310 | U1: 45311 | V1: 45312 | W1: 45313 | X1: 45314 | Y1: 45315 | Z1: 45316 | AA1: 45317 | AB1: 45318 | AC1: 45319 | AD1: 45320 | AE1: 45321 | AF1: 45322
A2: DAY | B2: MON | C2: TUE | D2: WED | E2: THU | F2: FRI | G2: SAT | H2: SUN | I2: MON | J2: TUE | K2: WED | L2: THU | M2: FRI | N2: SAT | O2: SUN | P2: MON | Q2: TUE | R2: WED | S2: THU | T2: FRI | U2: SAT | V2: SUN | W2: MON | X2: TUE | Y2: WED | Z2: THU | AA2: FRI | AB2: SAT | AC2: SUN | AD2: MON | AE2: TUE | AF2: WED
A3: COMMENT
A4: Orders
A5: Meta | B5: 46 | C5: 40 | D5: 39 | E5: 38 | F5: 40 | G5: 44 | H5: 47 | I5: 42 | J5: 32 | K5: 42 | L5: 25 | M5: 29 | N5: 30 | O5: 38 | P5: 29 | Q5: 15 | R5: 30 | S5: 29 | T5: 31 | U5: 40 | V5: 28 | W5: 27 | X5: 23 | Y5: 23 | Z5: 24 | AA5: 22 | AB5: 26 | AC5: 25 | AD5: 27 | AE5: 23 | AF5: 24 | AG5: =SUM(B5:AF5) -> 978
A6: Google | B6: 75.36 | C6: 44.92 | D6: 51.85 | E6: 52.24 | F6: 57.44 | G6: 63.57 | H6: 68.06 | I6: 42.02 | J6: 35 | K6: 36 | L6: 47.08 | M6: 39 | N6: 42 | O6: 43 | P6: 46 | Q6: 33 | R6: 51 | S6: 40 | T6: 34 | U6: 49 | V6: 42 | W6: 32 | X6: 34 | Y6: 18 | Z6: 27 | AA6: 30 | AB6: 48 | AC6: 31 | AD6: 30 | AE6: 24 | AF6: 25 | AG6: =SUM(B6:AF6) -> 1291.54
A7: TikTok | B7: 0 | C7: 0 | D7: 0 | E7: 0 | F7: 0 | G7: 0 | H7: 0 | I7: 0 | J7: 0 | K7: 0 | L7: 0 | M7: 0 | N7: 0 | O7: 0 | P7: 0 | Q7: 0 | R7: 0 | S7: 0 | T7: 0 | U7: 0 | V7: 0 | W7: 0 | X7: 0 | Y7: 0 | Z7: 0 | AA7: 0 | AB7: 0 | AC7: 0 | AD7: 0 | AE7: 0 | AF7: 0 | AG7: =SUM(B7:AF7) -> 0
A8: Bing | B8: 16 | C8: 4 | D8: 18 | E8: 16 | F8: 8 | G8: 14 | H8: 14 | I8: 14 | J8: 4 | K8: 8 | L8: 8 | M8: 16 | N8: 6 | O8: 4 | P8: 6 | Q8: 10 | R8: 14 | S8: 10 | T8: 8 | U8: 4 | V8: 10 | W8: 2 | X8: 2 | Y8: 10 | Z8: 6 | AA8: 4 | AB8: 6 | AC8: 10 | AD8: 4 | AE8: 2 | AF8: 4 | AG8: =SUM(B8:AF8) -> 262
A9: Nextdoor | B9: 0 | C9: 0 | D9: 0 | E9: 0 | F9: 0 | G9: 0 | H9: 0 | I9: 0 | J9: 0 | K9: 0 | L9: 0 | M9: 0 | N9: 0 | O9: 0 | P9: 0 | Q9: 0 | R9: 0 | S9: 0 | T9: 0 | U9: 0 | V9: 0 | W9: 0 | X9: 0 | Y9: 0 | Z9: 0 | AA9: 0 | AB9: 0 | AC9: 0 | AD9: 0 | AE9: 0 | AF9: 0 | AG9: =SUM(B9:AF9) -> 0
A10: Affiliates (Refersion) | B10: 0 | C10: 0 | D10: 0 | E10: 0 | F10: 0 | G10: 0 | H10: 0 | I10: 0 | J10: 1 | K10: 0 | L10: 1 | M10: 0 | N10: 0 | O10: 0 | P10: 0 | Q10: 0 | R10: 0 | S10: 0 | T10: 1 | U10: 0 | V10: 0 | W10: 0 | X10: 0 | Y10: 0 | AG10: =SUM(B10:AF10) -> 3
A11: Email | B11: 1 | C11: 3 | D11: 2 | E11: 2 | F11: 4 | G11: 3 | H11: 1 | I11: 1 | J11: 4 | K11: 0 | L11: 0 | M11: 0 | N11: 0 | O11: 0 | P11: 2 | Q11: 1 | R11: 0 | S11: 0 | T11: 0 | U11: 0 | V11: 0 | W11: 0 | X11: 0 | Y11: 0 | Z11: 0 | AA11: 0 | AB11: 0 | AC11: 0 | AD11: 0 | AE11: 1 | AF11: 2 | AG11: =SUM(B11:AF11) -> 27
A12: All | B12: =SUM(B5:B11) -> 138.36 | C12: =SUM(C5:C11) -> 91.92 | D12: =SUM(D5:D11) -> 110.85 | E12: =SUM(E5:E11) -> 108.24 | F12: =SUM(F5:F11) -> 109.44 | G12: =SUM(G5:G11) -> 124.57 | H12: =SUM(H5:H11) -> 130.06 | I12: =SUM(I5:I11) -> 99.02 | ... AF12: =SUM(AF5:AF11) -> 55 | AG12: =SUM(B12:AF12) -> 2561.54
A14: Revenue | X14: 3897.41 | Y14: 5024.95 | Z14: 3806.16 | AA14: 3508.79 | AB14: 4514.54 | AC14: 4610.42 | AD14: 3934.98 | AE14: 4850.18 | AF14: 5786.64
A15: Meta | B15: 7702.52 | C15: 7138.57 | D15: 6423.15 | E15: 8526.55 | F15: 8258.93 | G15: 7744.22 | H15: 7829.67 | I15: 9745.49 | J15: 8673.92 | K15: 9781.56 | L15: 5720.11 | M15: 7411.6 | N15: 6010.77 | O15: 6211.61 | P15: 5940.8639 | Q15: 2839.2095 | R15: 7473.512 | S15: 7249.34 | T15: 7038.1 | U15: 8068.47 | V15: 4105.76 | W15: 5139.4 | X15: =X14*Summary!X72 -> 4231.418 | Y15: =Y14*Summary!Y72 -> 5468.1506 | Z15: =Z14*Summary!Z72 -> 4129.303 | AA15: =AA14*Summary!AA72 -> 3811.5986 | AB15: =AB14*Summary!AB72 -> 4904.1448 | AC15: =AC14*Summary!AC72 -> 4999.0784 | AD15: =AD14*Summary!AD72 -> 4262.7638 | AE15: =AE14*Summary!AE72 -> 5259.0502 | AF15: =AF14*Summary!AF72 -> 6251.3072 | AG15: =SUM(B15:AF15) -> 198350.14
A16: Google | B16: 15176.01 | C16: 9959.28 | D16: 11082.87 | E16: 11276.45 | F16: 10964 | G16: 11756.22 | H16: 13968.19 | I16: 10252.98 | J16: 9054 | K16: 8915.82 | L16: 10439.04 | M16: 10492.28 | N16: 8424.68 | O16: 8581.54 | P16: 10279.53 | Q16: 8030.91 | R16: 13839.06 | S16: 9981.81 | T16: 9309.72 | U16: 11501.61 | V16: 7553.1 | W16: 8294.24 | X16: 8946.96 | Y16: 3117.79 | Z16: 6076.85 | AA16: 7215.22 | AB16: 10924.31 | AC16: 7074.07 | AD16: 5895.44 | AE16: 4831.05 | AF16: 5492.07 | AG16: =SUM(B16:AF16) -> 288707.1
A17: TikTok | B17: 0 | C17: 0 | D17: 0 | E17: 0 | F17: 0 | G17: 0 | H17: 0 | I17: 0 | J17: 0 | K17: 0 | L17: 0 | M17: 0 | N17: 0 | O17: 0 | P17: 0 | Q17: 0 | R17: 0 | S17: 0 | T17: 0 | U17: 0 | V17: 0 | W17: 0 | X17: 0 | Y17: 0 | Z17: 0 | AA17: 0 | AB17: 0 | AC17: 0 | AD17: 0 | AE17: 0 | AF17: 0 | AG17: =SUM(B17:AF17) -> 0
A18: Bing | B18: 2008 | C18: 502 | D18: 2259 | E18: 2008 | F18: 1004 | G18: 1757 | H18: 1757 | I18: 1757 | J18: 502 | K18: 1004 | L18: 1004 | M18: 2008 | N18: 753 | O18: 502 | P18: 753 | Q18: 1255 | R18: 1757 | S18: 1255 | T18: 1004 | U18: 502 | V18: 1255 | W18: 251 | X18: 251 | Y18: 1255 | Z18: 753 | AA18: 502 | AB18: 753 | AC18: 1255 | AD18: 502 | AE18: 251 | AF18: 502 | AG18: =SUM(B18:AF18) -> 32881
A19: Nextdoor | B19: 0 | C19: 0 | D19: 0 | E19: 0 | F19: 0 | G19: 0 | H19: 0 | I19: 0 | J19: 0 | K19: 0 | L19: 0 | M19: 0 | N19: 0 | O19: 0 | P19: 0 | Q19: 0 | R19: 0 | S19: 0 | T19: 0 | U19: 0 | V19: 0 | W19: 0 | X19: 0 | Y19: 0 | Z19: 0 | AA19: 0 | AB19: 0 | AC19: 0 | AD19: 0 | AE19: 0 | AF19: 0 | AG19: =SUM(B19:AF19) -> 0
A20: Affiliates (Refersion) | B20: 0 | C20: 0 | D20: 0 | E20: 0 | F20: 0 | G20: 0 | H20: 0 | I20: 0 | J20: 341 | K20: 0 | L20: 92 | M20: 0 | N20: 0 | O20: 0 | P20: 0 | Q20: 0 | R20: 0 | S20: 0 | T20: 394 | U20: 0 | V20: 0 | W20: 0 | X20: 0 | Y20: 0 | AG20: =SUM(B20:AF20) -> 827
A21: Email | B21: 276.11 | C21: 408 | D21: 365.4 | E21: 149.07 | F21: 427.95 | G21: 189.41 | H21: 53.05 | I21: 98 | J21: 161.95 | K21: 0 | L21: 0 | M21: 0 | N21: 0 | O21: 0 | P21: 374.7 | Q21: 50.81 | R21: 0 | S21: 0 | T21: 0 | U21: 0 | V21: 0 | W21: 0 | X21: 0 | Y21: 0 | Z21: 0 | AA21: 0 | AB21: 0 | AC21: 0 | AD21: 0 | AE21: 40.74 | AF21: 675.93 | AG21: =SUM(B21:AF21) -> 3271.12
A22: All | B22: =SUM(B15:B21) -> 25162.64 | C22: =SUM(C15:C21) -> 18007.85 | D22: =SUM(D15:D21) -> 20130.42 | E22: =SUM(E15:E21) -> 21960.07 | F22: =SUM(F15:F21) -> 20654.88 | G22: =SUM(G15:G21) -> 21446.85 | H22: =SUM(H15:H21) -> 23607.91 | I22: =SUM(I15:I21) -> 21853.47 | ... AF22: =SUM(AF15:AF21) -> 12921.307 | AG22: =SUM(B22:AF22) -> 524036.36
A24: Media Cost
A25: Meta | B25: =Summary!B73 -> 5875.9278 | C25: =Summary!C73 -> 5387.3265 | D25: =Summary!D73 -> 5162.9474 | E25: =Summary!E73 -> 5166.5229 | F25: =Summary!F73 -> 5194.2694 | G25: =Summary!G73 -> 5203.6798 | H25: =Summary!H73 -> 5447.9615 | I25: =Summary!I73 -> 5395.2728 | ... AF25: =Summary!AF73 -> 3277.2089 | AG25: =SUM(B25:AF25) -> 143999.52
A26: Google | B26: =Summary!B74 -> 2110.5 | C26: =Summary!C74 -> 2483.96 | D26: =Summary!D74 -> 2246.44 | E26: =Summary!E74 -> 2102.96 | F26: =Summary!F74 -> 1929.45 | G26: =Summary!G74 -> 1781.1 | H26: =Summary!H74 -> 1937.55 | I26: =Summary!I74 -> 1693.38 | ... AF26: =Summary!AF74 -> 1435.36 | AG26: =SUM(B26:AF26) -> 57065.75
A27: TikTok | B27: =Summary!B76 -> 0 | C27: =Summary!C76 -> 0 | D27: =Summary!D76 -> 0 | E27: =Summary!E76 -> 0 | F27: =Summary!F76 -> 0 | G27: =Summary!G76 -> 0 | H27: =Summary!H76 -> 0 | I27: =Summary!I76 -> 0 | ... AF27: =Summary!AF76 -> 0 | AG27: =SUM(B27:AF27) -> 0
A28: Bing | B28: =Summary!B75 -> 154.79 | C28: =Summary!C75 -> 206.25 | D28: =Summary!D75 -> 204.55 | E28: =Summary!E75 -> 163.92 | F28: =Summary!F75 -> 125.09 | G28: =Summary!G75 -> 91.32 | H28: =Summary!H75 -> 100.28 | I28: =Summary!I75 -> 119.37 | ... AF28: =Summary!AF75 -> 96.51 | AG28: =SUM(B28:AF28) -> 4584.27
A29: Nextdoor | B29: =Summary!B78 -> 0 | C29: =Summary!C78 -> 0 | D29: =Summary!D78 -> 0 | E29: =Summary!E78 -> 0 | F29: =Summary!F78 -> 0 | G29: =Summary!G78 -> 0 | H29: =Summary!H78 -> 0 | I29: =Summary!I78 -> 0 | ... AF29: =Summary!AF78 -> 0 | AG29: =SUM(B29:AF29) -> 0
A30: Affiliate Fee (20%) | B30: =Summary!B80 -> 0 | C30: =Summary!C80 -> 0 | D30: =Summary!D80 -> 0 | E30: =Summary!E80 -> 0 | F30: =Summary!F80 -> 0 | G30: =Summary!G80 -> 0 | H30: =Summary!H80 -> 0 | I30: =Summary!I80 -> 0 | ... AF30: =Summary!AF80 -> 0 | AG30: =SUM(B30:AF30) -> 169.97
A31: All | B31: =SUM(B25:B30) -> 8141.2178 | C31: =SUM(C25:C30) -> 8077.5365 | D31: =SUM(D25:D30) -> 7613.9374 | E31: =SUM(E25:E30) -> 7433.4029 | F31: =SUM(F25:F30) -> 7248.8094 | G31: =SUM(G25:G30) -> 7076.0998 | H31: =SUM(H25:H30) -> 7485.7915 | I31: =SUM(I25:I30) -> 7208.0228 | ... AF31: =SUM(AF25:AF30) -> 4809.0789 | AG31: =SUM(B31:AF31) -> 205819.51
A36: Revenue
A37: Revenue Woocommerce (Platform) | B37: =Summary!B8 -> 33166.99 | C37: =Summary!C8 -> 32204.7 | D37: =Summary!D8 -> 37759.59 | E37: =Summary!E8 -> 34093.84 | F37: =Summary!F8 -> 34903.7 | G37: =Summary!G8 -> 37601.7 | H37: =Summary!H8 -> 38315 | I37: =Summary!I8 -> 31136.13 | ... AF37: =Summary!AF8 -> 17850.13 | AG37: =sum(B37:AF37) -> 835052.26
A38: SUM | B38: =SUM(B37) -> 33166.99 | C38: =SUM(C37) -> 32204.7 | D38: =SUM(D37) -> 37759.59 | E38: =SUM(E37) -> 34093.84 | F38: =SUM(F37) -> 34903.7 | G38: =SUM(G37) -> 37601.7 | H38: =SUM(H37) -> 38315 | I38: =SUM(I37) -> 31136.13 | ... AF38: =SUM(AF37) -> 17850.13 | AG38: =sum(B38:AF38) -> 835052.26
A40: Orders
A41: Orders Woocommerce (Platform) | B41: =Summary!B49 -> 191 | C41: =Summary!C49 -> 158 | D41: =Summary!D49 -> 179 | E41: =Summary!E49 -> 156 | F41: =Summary!F49 -> 178 | G41: =Summary!G49 -> 187 | H41: =Summary!H49 -> 195 | I41: =Summary!I49 -> 144 | ... AF41: =Summary!AF49 -> 69 | AG41: =sum(B41:AF41) -> 3946
A42: SUM | B42: =SUM(B41) -> 191 | C42: =SUM(C41) -> 158 | D42: =SUM(D41) -> 179 | E42: =SUM(E41) -> 156 | F42: =SUM(F41) -> 178 | G42: =SUM(G41) -> 187 | H42: =SUM(H41) -> 195 | I42: =SUM(I41) -> 144 | ... AF42: =SUM(AF41) -> 69 | AG42: =sum(B42:AF42) -> 3946
A44: Breakdown
A45: - Hardware | B45: =Summary!B9 -> 20897.8 | C45: =Summary!C9 -> 21180.8 | D45: =Summary!D9 -> 27090.25 | E45: =Summary!E9 -> 24278.75 | F45: =Summary!F9 -> 23606.1 | G45: =Summary!G9 -> 25814.7 | H45: =Summary!H9 -> 24168.1 | I45: =Summary!I9 -> 21712.3 | ... AF45: =Summary!AF9 -> 13440.2 | AG45: =SUM(B45:AF45) -> 579343.85
A46: - Add-ons | B46: =Summary!B10 -> 8056.4 | C46: =Summary!C10 -> 7124.45 | D46: =Summary!D10 -> 6099.95 | E46: =Summary!E10 -> 5641.95 | F46: =Summary!F10 -> 6929.25 | G46: =Summary!G10 -> 7182.45 | H46: =Summary!H10 -> 9316.05 | I46: =Summary!I10 -> 5724.7 | ... AF46: =Summary!AF10 -> 2053.65 | AG46: =SUM(B46:AF46) -> 148180.29
A47: - Merch | B47: =Summary!B11 -> 58.14 | C47: =Summary!C11 -> 0 | D47: =Summary!D11 -> 76 | E47: =Summary!E11 -> 19 | F47: =Summary!F11 -> 44.99 | G47: =Summary!G11 -> 19 | H47: =Summary!H11 -> 130.15 | I47: =Summary!I11 -> 0 | ... AF47: =Summary!AF11 -> 0 | AG47: =SUM(B47:AF47) -> 541.74
A48: - Seeds | B48: =Summary!B12 -> 0 | C48: =Summary!C12 -> 0 | D48: =Summary!D12 -> 0 | E48: =Summary!E12 -> 0 | F48: =Summary!F12 -> 0 | G48: =Summary!G12 -> 0 | H48: =Summary!H12 -> 0 | I48: =Summary!I12 -> 0 | ... AF48: =Summary!AF12 -> 163.2 | AG48: =SUM(B48:AF48) -> 3107.62
...

Sheet App - P&L
A1: JANUARY | B1: 45292 | C1: 45293 | D1: 45294 | E1: 45295 | F1: 45296 | G1: 45297 | H1: 45298 | I1: 45299 | J1: 45300 | K1: 45301 | L1: 45302 | M1: 45303 | N1: 45304 | O1: 45305 | P1: 45306 | Q1: 45307 | R1: 45308 | S1: 45309 | T1: 45310 | U1: 45311 | V1: 45312 | W1: 45313 | X1: 45314 | Y1: 45315 | Z1: 45316 | AA1: 45317 | AB1: 45318 | AC1: 45319 | AD1: 45320 | AE1: 45321 | AF1: 45322
A2: DAY | B2: MON | C2: TUE | D2: WED | E2: THU | F2: FRI | G2: SAT | H2: SUN | I2: MON | J2: TUE | K2: WED | L2: THU | M2: FRI | N2: SAT | O2: SUN | P2: MON | Q2: TUE | R2: WED | S2: THU | T2: FRI | U2: SAT | V2: SUN | W2: MON | X2: TUE | Y2: WED | Z2: THU | AA2: FRI | AB2: SAT | AC2: SUN | AD2: MON | AE2: TUE | AF2: WED
A4: Gross Revenue
A5: Apple Store Sales | B5: 14169.892 | C5: 8386.9311 | D5: 6507.5304 | E5: 6326.8167 | F5: 7443.6982 | G5: 9494.4958 | H5: 8678.9918 | I5: 5904.7652 | J5: 4328.5 | K5: 3684.6094 | L5: 2691.1817 | M5: 3367.4772 | N5: 4641.6699 | O5: 5328.9441 | P5: 2693.87 | Q5: 1989.34 | R5: 1725.83 | S5: 2615.57 | T5: 1771.29 | U5: 4311.62 | V5: 4567.71 | W5: 3387.45 | X5: 1868.3 | Y5: 2416.36 | Z5: 2542.11 | AA5: 2283.37 | AB5: 4605.16 | AC5: 4916.1 | AD5: 2194.36 | AE5: 1762.36 | AF5: 1424.43 | AG5: =sum(B5:AF5) -> 138030.73
A6: - Yearly Subscription | B6: 13858.129 | C6: 8199.0915 | D6: 6218.966 | E6: 6121.0701 | F6: 7276.3415 | G6: 9295.2082 | H6: 8403.99 | I6: 5748.1706 | J6: 4143.8726 | K6: 3551.5034 | L6: 2531.6597 | M6: 3220.2332 | N6: 4490.2469 | O6: 5069.804 | P6: 2543.6309 | Q6: 1823.9705 | R6: 1564.27 | S6: 2511.82 | T6: 1628.07 | U6: 4191.4 | V6: 4385.96 | W6: 3212.51 | X6: 1709.61 | Y6: 2225.24 | Z6: 1991 | AA6: 1807.7395 | AB6: 4243.5984 | AC6: 4454.6102 | AD6: 1862.42 | AE6: 1442.4716 | AF6: =365.758815+779.25 -> 1145.0088 | AG6: =sum(B6:AF6) -> 130871.62
A7: - Monthly Subscription | B7: 311.76337 | C7: 187.83951 | D7: 288.56445 | E7: 205.74661 | F7: 167.35666 | G7: 199.28761 | H7: 275.00184 | I7: 156.59459 | J7: 184.63079 | K7: 133.10604 | L7: 159.52208 | M7: 147.24396 | N7: 151.42296 | O7: 259.14 | P7: 150.24 | Q7: 165.3678 | R7: 161.56 | S7: 103.75261 | T7: 143.22 | U7: 120.22 | V7: 181.75459 | W7: 174.94 | X7: 158.68726 | Y7: 191.12034 | Z7: 551.11 | AA7: 475.63121 | AB7: 361.55858 | AC7: 461.48525 | AD7: 331.94 | AE7: 319.88579 | AF7: 279.42461 | AG7: =sum(B7:AF7) -> 7159.1185
A8: Google Store Sales | B8: 3272.61 | C8: 1739.68 | D8: 1214.51 | E8: 1099.5 | F8: 1374.17 | G8: 1566.03 | H8: 1726.07 | I8: 1581.78 | J8: 652.72 | K8: 763.68 | L8: 853.43 | M8: 346.97 | N8: 745.82 | O8: 1131.99 | P8: 641.58 | Q8: 239.88 | R8: 409.43 | S8: 488.17 | T8: 448.32 | U8: 852.95 | V8: 721.04 | W8: 727.48 | X8: 485.25 | Y8: 520.18 | Z8: 227.34 | AA8: 589.11 | AB8: 781.83 | AC8: 598.87 | AD8: 295.96 | AE8: 479.07 | AF8: 214.24 | AG8: =sum(B8:AF8) -> 26789.66
A9: - Yearly Subscription | B9: 3231.08 | C9: 1682.68 | D9: 1178.79 | E9: 1050.29 | F9: 1336.04 | G9: 1525.22 | H9: 47.24 | I9: 1538.38 | J9: 587.23 | K9: 725.92 | L9: 824.84 | M9: 326.96 | N9: 726.3 | O9: 1097.3 | P9: 608.63 | Q9: 220.73 | R9: 400 | S9: 433.79 | T9: 407.04 | U9: 782.62 | V9: 685.83 | W9: 696.15 | X9: 454.24 | Y9: 501.36 | Z9: 124.58 | AA9: 539.44 | AB9: 696.48 | AC9: 503.25 | AD9: 219.75 | AE9: 416.18 | AF9: 189.41 | AG9: =sum(B9:AF9) -> 23757.75
A10: - Monthly Subscription | B10: 41.53 | C10: 57 | D10: 35.72 | E10: 49.21 | F10: 38.13 | G10: 40.81 | H10: 1678.83 | I10: 43.4 | J10: 65.49 | K10: 37.76 | L10: 28.59 | M10: 20.01 | N10: 19.52 | O10: 34.69 | P10: 32.95 | Q10: 19.15 | R10: 9.43 | S10: 54.38 | T10: 41.28 | U10: 70.33 | V10: 35.21 | W10: 31.33 | X10: 31.01 | Y10: 18.82 | Z10: 102.76 | AA10: 49.67 | AB10: 85.35 | AC10: 95.62 | AD10: 75.51 | AE10: 62.89 | AF10: 24.83 | AG10: =sum(B10:AF10) -> 3031.21
A11: SUM | B11: =sum(B5+B8) -> 17442.502 | C11: =sum(C5+C8) -> 10126.611 | D11: =sum(D5+D8) -> 7722.0404 | E11: =sum(E5+E8) -> 7426.3167 | F11: =sum(F5+F8) -> 8817.8682 | G11: =sum(G5+G8) -> 11060.526 | H11: =sum(H5+H8) -> 10405.062 | I11: =sum(I5+I8) -> 7486.5452 | ... AF11: =sum(AF5+AF8) -> 1638.67 | AG11: =sum(B11:AF11) -> 164820.39
A13: Gross Orders
A14: Apple Store Orders | B14: =sum(B15:B16) -> 417 | C14: =sum(C15:C16) -> 243 | D14: =sum(D15:D16) -> 211 | E14: =sum(E15:E16) -> 186 | F14: =sum(F15:F16) -> 210 | G14: =sum(G15:G16) -> 267 | H14: =sum(H15:H16) -> 261 | I14: =sum(I15:I16) -> 163 | ... AF14: =sum(AF15:AF16) -> 77 | AG14: =sum(B14:AF14) -> 4541
A15: - Yearly Subscription | B15: 356 | C15: 203 | D15: 149 | E15: 143 | F15: 170 | G15: 223 | H15: 204 | I15: 127 | J15: 90 | K15: 77 | L15: 57 | M15: 64 | N15: 96 | O15: 106 | P15: 56 | Q15: 41 | R15: 34 | S15: 56 | T15: 41 | U15: 97 | V15: 105 | W15: 76 | X15: 40 | Y15: 52 | Z15: 44 | AA15: 44 | AB15: 101 | AC15: 103 | AD15: 46 | AE15: 36 | AF15: 28 | AG15: =sum(B15:AF15) -> 3065
A16: - Monthly Subscription | B16: 61 | C16: 40 | D16: 62 | E16: 43 | F16: 40 | G16: 44 | H16: 57 | I16: 36 | J16: 43 | K16: 33 | L16: 34 | M16: 34 | N16: 33 | O16: 54 | P16: 33 | Q16: 41 | R16: 37 | S16: 25 | T16: 31 | U16: 26 | V16: 38 | W16: 35 | X16: 32 | Y16: 40 | Z16: 103 | AA16: 92 | AB16: 68 | AC16: 85 | AD16: 64 | AE16: 63 | AF16: 49 | AG16: =sum(B16:AF16) -> 1476
A17: Google Store Orders | B17: =sum(B18:B19) -> 80 | C17: =sum(C18:C19) -> 51 | D17: =sum(D18:D19) -> 36 | E17: =sum(E18:E19) -> 34 | F17: =sum(F18:F19) -> 35 | G17: =sum(G18:G19) -> 41 | H17: =sum(H18:H19) -> 49 | I17: =sum(I18:I19) -> 34 | ... AF17: =sum(AF18:AF19) -> 7 | AG17: =sum(B17:AF17) -> 838
A18: - Yearly Subscription | B18: 73 | C18: 40 | D18: 27 | E18: 23 | F18: 27 | G18: 32 | H18: 39 | I18: 25 | J18: 13 | K18: 16 | L18: 15 | M18: 8 | N18: 14 | O18: 22 | P18: 13 | Q18: 6 | R18: 8 | S18: 8 | T18: 9 | U18: 19 | V18: 19 | W18: 14 | X18: 9 | Y18: 11 | Z18: 3 | AA18: 13 | AB18: 16 | AC18: 10 | AD18: 4 | AE18: 9 | AF18: 3 | AG18: =sum(B18:AF18) -> 548
A19: - Monthly Subscription | B19: 7 | C19: 11 | D19: 9 | E19: 11 | F19: 8 | G19: 9 | H19: 10 | I19: 9 | J19: 13 | K19: 9 | L19: 5 | M19: 5 | N19: 5 | O19: 7 | P19: 9 | Q19: 4 | R19: 3 | S19: 12 | T19: 10 | U19: 15 | V19: 8 | W19: 7 | X19: 7 | Y19: 4 | Z19: 18 | AA19: 11 | AB19: 15 | AC19: 18 | AD19: 15 | AE19: 12 | AF19: 4 | AG19: =sum(B19:AF19) -> 290
A20: SUM | B20: =sum(B14+B17) -> 497 | C20: =sum(C14+C17) -> 294 | D20: =sum(D14+D17) -> 247 | E20: =sum(E14+E17) -> 220 | F20: =sum(F14+F17) -> 245 | G20: =sum(G14+G17) -> 308 | H20: =sum(H14+H17) -> 310 | I20: =sum(I14+I17) -> 197 | ... AF20: =sum(AF14+AF17) -> 84 | AG20: =sum(B20:AF20) -> 5379
A21: - Yearly Subscription | B21: =B15+B18 -> 429 | C21: =C15+C18 -> 243 | D21: =D15+D18 -> 176 | E21: =E15+E18 -> 166 | F21: =F15+F18 -> 197 | G21: =G15+G18 -> 255 | H21: =H15+H18 -> 243 | I21: =I15+I18 -> 152 | ... AF21: =AF15+AF18 -> 31 | AG21: =sum(B21:AF21) -> 3613
A22: - Monthly Subscription | B22: =B16+B19 -> 68 | C22: =C16+C19 -> 51 | D22: =D16+D19 -> 71 | E22: =E16+E19 -> 54 | F22: =F16+F19 -> 48 | G22: =G16+G19 -> 53 | H22: =H16+H19 -> 67 | I22: =I16+I19 -> 45 | ... AF22: =AF16+AF19 -> 53 | AG22: =sum(B22:AF22) -> 1766
A24: Refunded Revenue
A25: Apple Store Sales | B25: =sum(B26:B27) -> 59.73 | C25: =sum(C26:C27) -> 59.99 | D25: =sum(D26:D27) -> 209.9 | E25: =sum(E26:E27) -> 59.98 | F25: =sum(F26:F27) -> 89.98 | G25: =sum(G26:G27) -> 100.64 | H25: =sum(H26:H27) -> 109.65 | I25: =sum(I26:I27) -> 0 | ... AF25: =sum(AF26:AF27) -> 0 | AG25: =sum(B25:AF25) -> 1854.489
A26: - Yearly Subscription | B26: 59.73 | C26: 59.99 | D26: 209.9 | E26: 59.98 | F26: 89.98 | G26: 89.24 | H26: 100.96 | I26: 0 | J26: 149.96 | K26: 89.97 | L26: 59.98 | M26: 29.53 | N26: 59.98 | O26: 118.01 | P26: 89.32 | Q26: 184.089 | R26: 29.99 | S26: 59.99 | T26: 0 | U26: 0 | V26: 29.99 | W26: 0 | X26: 29.99 | Y26: 0 | Z26: 0 | AA26: 119.98 | AB26: 57.49 | AC26: 10.08 | AD26: 0 | AE26: 0 | AF26: 0 | AG26: =sum(B26:AF26) -> 1788.129
A27: - Monthly Subscription | B27: 0 | C27: 0 | D27: 0 | E27: 0 | F27: 0 | G27: 11.4 | H27: 8.69 | I27: 0 | J27: 3.28 | K27: 0 | L27: 0 | M27: 5.99 | N27: 4.64 | O27: 2.99 | P27: 0 | Q27: 5.99 | R27: 0 | S27: 1.55 | T27: 4.64 | U27: 0.97 | V27: 0 | W27: 0 | X27: 5.99 | Y27: 0 | Z27: 0 | AA27: 0 | AB27: 0.96 | AC27: 0 | AD27: 5.99 | AE27: 3.28 | AF27: 0 | AG27: =sum(B27:AF27) -> 66.36
A28: Google Store Sales | B28: =sum(B29:B30) -> 0 | C28: =sum(C29:C30) -> 0 | D28: =sum(D29:D30) -> 0 | E28: =sum(E29:E30) -> 29.99 | F28: =sum(F29:F30) -> 0 | G28: =sum(G29:G30) -> 0 | H28: =sum(H29:H30) -> 0 | I28: =sum(I29:I30) -> 0 | ... AF28: =sum(AF29:AF30) -> 0 | AG28: =sum(B28:AF28) -> 173
A29: - Yearly Subscription | B29: 0 | C29: 0 | D29: 0 | E29: 29.99 | F29: 0 | G29: 0 | H29: 0 | I29: 0 | J29: 0 | K29: 0 | L29: 0 | M29: 42.7 | N29: 0 | O29: 35.52 | P29: 0 | Q29: 64.79 | R29: 0 | S29: 0 | T29: 0 | U29: 0 | V29: 0 | W29: 0 | X29: 0 | Y29: 0 | Z29: 0 | AA29: 0 | AB29: 0 | AC29: 0 | AD29: 0 | AE29: 0 | AF29: 0 | AG29: =sum(B29:AF29) -> 173
A30: - Monthly Subscription | B30: 0 | C30: 0 | D30: 0 | E30: 0 | F30: 0 | G30: 0 | H30: 0 | I30: 0 | J30: 0 | K30: 0 | L30: 0 | M30: 0 | N30: 0 | O30: 0 | P30: 0 | Q30: 0 | R30: 0 | S30: 0 | T30: 0 | U30: 0 | V30: 0 | W30: 0 | X30: 0 | Y30: 0 | Z30: 0 | AA30: 0 | AB30: 0 | AC30: 0 | AD30: 0 | AE30: 0 | AF30: 0 | AG30: =sum(B30:AF30) -> 0
A31: SUM | B31: =B25+B28 -> 59.73 | C31: =C25+C28 -> 59.99 | D31: =D25+D28 -> 209.9 | E31: =E25+E28 -> 89.97 | F31: =F25+F28 -> 89.98 | G31: =G25+G28 -> 100.64 | H31: =H25+H28 -> 109.65 | I31: =I25+I28 -> 0 | ... AF31: =AF25+AF28 -> 0 | AG31: =sum(B31:AF31) -> 2027.489
A33: Refunded Orders
A34: Apple Store orders | B34: =sum(B35:B36) -> 1 | C34: =sum(C35:C36) -> 1 | D34: =sum(D35:D36) -> 5 | E34: =sum(E35:E36) -> 2 | F34: =sum(F35:F36) -> 2 | G34: =sum(G35:G36) -> 2 | H34: =sum(H35:H36) -> 2 | I34: =sum(I35:I36) -> 0 | ... AF34: =sum(AF35:AF36) -> 0 | AG34: =sum(B34:AF34) -> 44
A35: - Yearly Subscription | B35: 1 | C35: 1 | D35: 5 | E35: 2 | F35: 2 | G35: 1 | H35: 1 | I35: 0 | J35: 4 | K35: 3 | L35: 1 | M35: 0 | N35: 2 | O35: 1 | P35: 1 | Q35: 2 | R35: 1 | S35: 1 | T35: 0 | U35: 0 | V35: 1 | W35: 0 | X35: 1 | Y35: 0 | Z35: 0 | AA35: 2 | AB35: 1 | AC35: 0 | AD35: 0 | AE35: 0 | AF35: 0
A36: - Monthly Subscription | B36: 0 | C36: 0 | D36: 0 | E36: 0 | F36: 0 | G36: 1 | H36: 1 | I36: 0 | J36: 1 | K36: 0 | L36: 0 | M36: 1 | N36: 1 | O36: 1 | P36: 0 | Q36: 1 | R36: 0 | S36: 0 | T36: 0 | U36: 0 | V36: 0 | W36: 0 | X36: 1 | Y36: 0 | Z36: 0 | AA36: 0 | AB36: 0 | AC36: 0 | AD36: 1 | AE36: 1 | AF36: 0
A37: Google Store orders | B37: =sum(B38:B39) -> 0 | C37: =sum(C38:C39) -> 0 | D37: =sum(D38:D39) -> 0 | E37: =sum(E38:E39) -> 1 | F37: =sum(F38:F39) -> 0 | G37: =sum(G38:G39) -> 0 | H37: =sum(H38:H39) -> 0 | I37: =sum(I38:I39) -> 0 | ... AF37: =sum(AF38:AF39) -> 0 | AG37: =sum(B37:AF37) -> 4
A38: - Yearly Subscription | B38: 0 | C38: 0 | D38: 0 | E38: 1 | F38: 0 | G38: 0 | H38: 0 | I38: 0 | J38: 0 | K38: 0 | L38: 0 | M38: 1 | N38: 0 | O38: 1 | P38: 0 | Q38: 1 | R38: 0 | S38: 0 | T38: 0 | U38: 0 | V38: 0 | W38: 0 | X38: 0 | Y38: 0 | Z38: 0 | AA38: 0 | AB38: 0 | AC38: 0 | AD38: 0 | AE38: 0 | AF38: 0
A39: - Monthly Subscription | B39: 0 | C39: 0 | D39: 0 | E39: 0 | F39: 0 | G39: 0 | H39: 0 | I39: 0 | J39: 0 | K39: 0 | L39: 0 | M39: 0 | N39: 0 | O39: 0 | P39: 0 | Q39: 0 | R39: 0 | S39: 0 | T39: 0 | U39: 0 | V39: 0 | W39: 0 | X39: 0 | Y39: 0 | Z39: 0 | AA39: 0 | AB39: 0 | AC39: 0 | AD39: 0 | AE39: 0 | AF39: 0
A40: SUM | B40: =B34+B37 -> 1 | C40: =C34+C37 -> 1 | D40: =D34+D37 -> 5 | E40: =E34+E37 -> 3 | F40: =F34+F37 -> 2 | G40: =G34+G37 -> 2 | H40: =H34+H37 -> 2 | I40: =I34+I37 -> 0 | ... AF40: =AF34+AF37 -> 0 | AG40: =sum(B40:AF40) -> 48
A42: Net Revenue
A43: Apple Store | B43: =B5-B25 -> 14110.162 | C43: =C5-C25 -> 8326.9411 | D43: =D5-D25 -> 6297.6304 | E43: =E5-E25 -> 6266.8367 | F43: =F5-F25 -> 7353.7182 | G43: =G5-G25 -> 9393.8558 | H43: =H5-H25 -> 8569.3418 | I43: =I5-I25 -> 5904.7652 | ... AF43: =AF5-AF25 -> 1424.43 | AG43: =sum(B43:AF43) -> 136176.24
A44: - Yearly Subscription | B44: =B6-B26 -> 13798.399 | C44: =C6-C26 -> 8139.1015 | D44: =D6-D26 -> 6009.066 | E44: =E6-E26 -> 6061.0901 | F44: =F6-F26 -> 7186.3615 | G44: =G6-G26 -> 9205.9682 | H44: =H6-H26 -> 8303.03 | I44: =I6-I26 -> 5748.1706 | ... AF44: =AF6-AF26 -> 1145.0088 | AG44: =sum(B44:AF44) -> 129083.49
A45: - Monthly Subscription | B45: =B7-B27 -> 311.76337 | C45: =C7-C27 -> 187.83951 | D45: =D7-D27 -> 288.56445 | E45: =E7-E27 -> 205.74661 | F45: =F7-F27 -> 167.35666 | G45: =G7-G27 -> 187.88761 | H45: =H7-H27 -> 266.31184 | I45: =I7-I27 -> 156.59459 | ... AF45: =AF7-AF27 -> 279.42461 | AG45: =sum(B45:AF45) -> 7092.7585
...

Sheet AMAZON - P&L
A1: JANUARY | B1: 45292 | C1: 45293 | D1: 45294 | E1: 45295 | F1: 45296 | G1: 45297 | H1: 45298 | I1: 45299 | J1: 45300 | K1: 45301 | L1: 45302 | M1: 45303 | N1: 45304 | O1: 45305 | P1: 45306 | Q1: 45307 | R1: 45308 | S1: 45309 | T1: 45310 | U1: 45311 | V1: 45312 | W1: 45313 | X1: 45314 | Y1: 45315 | Z1: 45316 | AA1: 45317 | AB1: 45318 | AC1: 45319 | AD1: 45320 | AE1: 45321 | AF1: 45322
A2: DAY | B2: MON | C2: TUE | D2: WED | E2: THU | F2: FRI | G2: SAT | H2: SUN | I2: MON | J2: TUE | K2: WED | L2: THU | M2: FRI | N2: SAT | O2: SUN | P2: MON | Q2: TUE | R2: WED | S2: THU | T2: FRI | U2: SAT | V2: SUN | W2: MON | X2: TUE | Y2: WED | Z2: THU | AA2: FRI | AB2: SAT | AC2: SUN | AD2: MON | AE2: TUE | AF2: WED
A3: COMMENT
A4: Orders
A5: Amazon (market place) | B5: =Summary!B54 -> 14 | C5: =Summary!C54 -> 30 | D5: =Summary!D54 -> 34 | E5: =Summary!E54 -> 15 | F5: =Summary!F54 -> 23 | G5: =Summary!G54 -> 18 | H5: =Summary!H54 -> 22 | I5: =Summary!I54 -> 40 | ... AF5: =Summary!AF54 -> 64
A6: All | B6: =SUM(B5) -> 14 | C6: =SUM(C5) -> 30 | D6: =SUM(D5) -> 34 | E6: =SUM(E5) -> 15 | F6: =SUM(F5) -> 23 | G6: =SUM(G5) -> 18 | H6: =SUM(H5) -> 22 | I6: =SUM(I5) -> 40 | ... AF6: =SUM(AF5) -> 64 | AG6: =SUM(B6:AF6) -> 1073
A8: Revenue
A9: Amazon (market place) | B9: =Summary!B15 -> 8259.3 | C9: =Summary!C15 -> 8509.69 | D9: =Summary!D15 -> 9959.99 | E9: =Summary!E15 -> 7222.59 | F9: =Summary!F15 -> 7395.73 | G9: =Summary!G15 -> 6262.25 | H9: =Summary!H15 -> 5480.06 | I9: =Summary!I15 -> 8883.31 | ... AF9: =Summary!AF15 -> 14667.91
A10: All | B10: =SUM(B9) -> 8259.3 | C10: =SUM(C9) -> 8509.69 | D10: =SUM(D9) -> 9959.99 | E10: =SUM(E9) -> 7222.59 | F10: =SUM(F9) -> 7395.73 | G10: =SUM(G9) -> 6262.25 | H10: =SUM(H9) -> 5480.06 | I10: =SUM(I9) -> 8883.31 | ... AF10: =SUM(AF9) -> 14667.91 | AG10: =SUM(B10:AF10) -> 283546.35
A12: Media Cost
A13: Amazon Spend | B13: =Summary!B77 -> 2390.92 | C13: =Summary!C77 -> 2568.83 | D13: =Summary!D77 -> 1913.96 | E13: =Summary!E77 -> 1152.11 | F13: =Summary!F77 -> 1392.03 | G13: =Summary!G77 -> 0 | H13: =Summary!H77 -> 0 | I13: =Summary!I77 -> 341.24 | ... AF13: =Summary!AF77 -> 1754.27 | AG13: =SUM(B13:AF13) -> 37402.23
A14: Amazon Platform Fee (15 %) | B14: =B9*'Data - P&L'!$C$48 -> 1238.895 | C14: =C9*'Data - P&L'!$C$48 -> 1276.4535 | D14: =D9*'Data - P&L'!$C$48 -> 1493.9985 | E14: =E9*'Data - P&L'!$C$48 -> 1083.3885 | F14: =F9*'Data - P&L'!$C$48 -> 1109.3595 | G14: =G9*'Data - P&L'!$C$48 -> 939.3375 | H14: =H9*'Data - P&L'!$C$48 -> 822.009 | I14: =I9*'Data - P&L'!$C$48 -> 1332.4965 | ... AF14: =AF9*'Data - P&L'!$C$48 -> 2200.1865
A15: All | B15: =SUM(B13:B14) -> 3629.815 | C15: =SUM(C13:C14) -> 3845.2835 | D15: =SUM(D13:D14) -> 3407.9585 | E15: =SUM(E13:E14) -> 2235.4985 | F15: =SUM(F13:F14) -> 2501.3895 | G15: =SUM(G13:G14) -> 939.3375 | H15: =SUM(H13:H14) -> 822.009 | I15: =SUM(I13:I14) -> 1673.7365 | ... AF15: =SUM(AF13:AF14) -> 3954.4565 | AG15: =SUM(B15:AF15) -> 79934.182
A19: Amazon Orders
A20: Hardware | B20: =Summary!B16 -> 7579.26 | C20: =Summary!C16 -> 7878.36 | D20: =Summary!D16 -> 9382.76 | E20: =Summary!E16 -> 6797.99 | F20: =Summary!F16 -> 6870.37 | G20: =Summary!G16 -> 5854.37 | H20: =Summary!H16 -> 5096.37 | I20: =Summary!I16 -> 8203.4 | ... AF20: =Summary!AF16 -> 13530.04 | AG20: =SUM(B20:AF20) -> 260157.86
A21: Addons | B21: =Summary!B17 -> 166.38 | C21: =Summary!C17 -> 87 | D21: =Summary!D17 -> 0 | E21: =Summary!E17 -> 0 | F21: =Summary!F17 -> 0 | G21: =Summary!G17 -> 0 | H21: =Summary!H17 -> 58 | I21: =Summary!I17 -> 116 | ... AF21: =Summary!AF17 -> 203 | AG21: =SUM(B21:AF21) -> 4855.28
A22: Tax | B22: =Summary!B18 -> 503.88 | C22: =Summary!C18 -> 523.33 | D22: =Summary!D18 -> 567.45 | E22: =Summary!E18 -> 424.6 | F22: =Summary!F18 -> 520.47 | G22: =Summary!G18 -> 398.03 | H22: =Summary!H18 -> 325.29 | I22: =Summary!I18 -> 562.31 | ... AF22: =Summary!AF18 -> 917.39 | AG22: =SUM(B22:AF22) -> 18142.31
A23: Shipping | B23: =Summary!B19 -> 0.5 | C23: =Summary!C19 -> 11.87 | D23: =Summary!D19 -> 0.5 | E23: =Summary!E19 -> 0 | F23: =Summary!F19 -> 0.25 | G23: =Summary!G19 -> 5.21 | H23: =Summary!H19 -> 0.25 | I23: =Summary!I19 -> 1 | ... AF23: =Summary!AF19 -> 8.35 | AG23: =SUM(B23:AF23) -> 186.79
A24: Gift Wrap Price | B24: =Summary!B20 -> 9.28 | C24: =Summary!C20 -> 9.13 | D24: =Summary!D20 -> 9.28 | E24: =Summary!E20 -> 0 | F24: =Summary!F20 -> 4.64 | G24: =Summary!G20 -> 4.64 | H24: =Summary!H20 -> 0.15 | I24: =Summary!I20 -> 0.6 | ... AF24: =Summary!AF20 -> 9.13 | AG24: =SUM(B24:AF24) -> 204.11
A25: All Amazon | B25: =SUM(B20:B24) -> 8259.3 | C25: =SUM(C20:C24) -> 8509.69 | D25: =SUM(D20:D24) -> 9959.99 | E25: =SUM(E20:E24) -> 7222.59 | F25: =SUM(F20:F24) -> 7395.73 | G25: =SUM(G20:G24) -> 6262.25 | H25: =SUM(H20:H24) -> 5480.06 | I25: =SUM(I20:I24) -> 8883.31 | ... AF25: =SUM(AF20:AF24) -> 14667.91 | AG25: =SUM(B25:AF25) -> 283546.35
A27: Units Sold (Gross)
A28: SKU 1 - Blue | B28: 1 | C28: 6 | D28: 8 | E28: 5 | F28: 2 | G28: 1 | H28: 2 | I28: 4 | J28: 7 | K28: 6 | L28: 7 | M28: 15 | N28: 11 | O28: 7 | P28: 9 | Q28: 9 | R28: 8 | S28: 12 | T28: 9 | U28: 18 | V28: 15 | W28: 10 | X28: 11 | Y28: 4 | Z28: 5 | AA28: 1 | AB28: 0 | AC28: 5 | AD28: 1 | AE28: 1 | AF28: 3 | AG28: =sum(B28:AF28) -> 203
A29: SKU 2 - Yellow | B29: 1 | C29: 1 | D29: 1 | E29: 1 | F29: 2 | G29: 0 | H29: 0 | I29: 0 | J29: 1 | K29: 1 | L29: 3 | M29: 4 | N29: 5 | O29: 3 | P29: 3 | Q29: 3 | R29: 4 | S29: 3 | T29: 2 | U29: 7 | V29: 3 | W29: 3 | X29: 2 | Y29: 0 | Z29: 1 | AA29: 0 | AB29: 1 | AC29: 3 | AD29: 0 | AE29: 1 | AF29: 2 | AG29: =sum(B29:AF29) -> 61
A30: SKU 3 - Blue w/ Solar | B30: 16 | C30: 7 | D30: 2 | E30: 3 | F30: 4 | G30: 5 | H30: 3 | I30: 13 | J30: 14 | K30: 12 | L30: 13 | M30: 7 | N30: 8 | O30: 4 | P30: 10 | Q30: 6 | R30: 7 | S30: 10 | T30: 15 | U30: 1 | V30: 5 | W30: 7 | X30: 3 | Y30: 24 | Z30: 16 | AA30: 23 | AB30: 22 | AC30: 31 | AD30: 43 | AE30: 27 | AF30: 34 | AG30: =sum(B30:AF30) -> 395
A31: SKU 4 - Yellow w/ Solar | B31: 7 | C31: 12 | D31: 21 | E31: 14 | F31: 15 | G31: 13 | H31: 12 | I31: 11 | J31: 3 | K31: 1 | L31: 0 | M31: 0 | N31: 0 | O31: 5 | P31: 0 | Q31: 0 | R31: 0 | S31: 0 | T31: 0 | U31: 15 | V31: 25 | W31: 26 | X31: 14 | Y31: 8 | Z31: 2 | AA31: 9 | AB31: 8 | AC31: 9 | AD31: 8 | AE31: 5 | AF31: 7 | AG31: =sum(B31:AF31) -> 250
A32: SUM (SKU 1 - SKU 4) | B32: =SUM(B28:B31) -> 25 | C32: =SUM(C28:C31) -> 26 | D32: =SUM(D28:D31) -> 32 | E32: =SUM(E28:E31) -> 23 | F32: =SUM(F28:F31) -> 23 | G32: =SUM(G28:G31) -> 19 | H32: =SUM(H28:H31) -> 17 | I32: =SUM(I28:I31) -> 28 | ... AF32: =SUM(AF28:AF31) -> 46 | AG32: =sum(B32:AF32) -> 909
A34: Wall Mount | B34: 8 | C34: 3 | D34: 0 | E34: 0 | F34: 0 | G34: 0 | H34: 2 | I34: 4 | J34: 4 | K34: 0 | L34: 1 | M34: 6 | N34: 0 | O34: 1 | P34: 1 | Q34: 0 | R34: 3 | S34: 3 | T34: 0 | U34: 6 | V34: 10 | W34: 7 | X34: 8 | Y34: 9 | Z34: 8 | AA34: 9 | AB34: 15 | AC34: 26 | AD34: 14 | AE34: 16 | AF34: 9 | AG34: =sum(B34:AF34) -> 173
A35: Suet Ball Holder | AG35: =sum(B35:AF35) -> 0
A36: 3-in-1 Nutrition Set - Blue | AG36: =sum(B36:AF36) -> 0
A37: 3-in-1 Nutrition Set - Yellow | AG37: =sum(B37:AF37) -> 0
A38: Solar Roof Single - Blue | AG38: =sum(B38:AF38) -> 0
A39: Solar Roof Single - Yellow | AG39: =sum(B39:AF39) -> 0
A40: Perch Extender - Blue | AG40: =sum(B40:AF40) -> 0
A41: Perch Extender - Yellow | AG41: =sum(B41:AF41) -> 0
A42: SUM (Add-ons) | B42: =SUM(B34:B41) -> 8 | C42: =SUM(C34:C41) -> 3 | D42: =SUM(D34:D41) -> 0 | E42: =SUM(E34:E41) -> 0 | F42: =SUM(F34:F41) -> 0 | G42: =SUM(G34:G41) -> 0 | H42: =SUM(H34:H41) -> 2 | I42: =SUM(I34:I41) -> 4 | ... AF42: =SUM(AF34:AF41) -> 9 | AG42: =sum(B42:AF42) -> 173
A45: Units Sold by country (Gross) - Only selling in US
A46: Bird Buddy - Blue - AMAZON.US | AG46: =sum(B46:AE46) -> 0
A47: Bird Buddy - Yellow - AMAZON.US
A48: Bird Buddy with Solar Roof Blue - AMAZON.US | AB48: =AB31 -> 8 | AC48: =AC31 -> 9 | AD48: =AD31 -> 8 | AE48: =AE31 -> 5 | AG48: =sum(B48:AE48) -> 30
A49: Bird Buddy with Solar Roof Yellow - AMAZON.US
...

Sheet Digital Marketplaces - P & L
A1: JANUARY | B1: 45292 | C1: 45293 | D1: 45294 | E1: 45295 | F1: 45296 | G1: 45297 | H1: 45298 | I1: 45299 | J1: 45300 | K1: 45301 | L1: 45302 | M1: 45303 | N1: 45304 | O1: 45305 | P1: 45306 | Q1: 45307 | R1: 45308 | S1: 45309 | T1: 45310 | U1: 45311 | V1: 45312 | W1: 45313 | X1: 45314 | Y1: 45315 | Z1: 45316 | AA1: 45317 | AB1: 45318 | AC1: 45319 | AD1: 45320 | AE1: 45321 | AF1: 45322
A2: DAY | B2: MON | C2: TUE | D2: WED | E2: THU | F2: FRI | G2: SAT | H2: SUN | I2: MON | J2: TUE | K2: WED | L2: THU | M2: FRI | N2: SAT | O2: SUN | P2: MON | Q2: TUE | R2: WED | S2: THU | T2: FRI | U2: SAT | V2: SUN | W2: MON | X2: TUE | Y2: WED | Z2: THU | AA2: FRI | AB2: SAT | AC2: SUN | AD2: MON | AE2: TUE | AF2: WED
A3: Rachio (Shopify)
A4: Revenue | B4: =Summary!B22 -> 0 | C4: =Summary!C22 -> 0 | D4: =Summary!D22 -> 0 | E4: =Summary!E22 -> 0 | F4: =Summary!F22 -> 0 | G4: =Summary!G22 -> 0 | H4: =Summary!H22 -> 0 | I4: =Summary!I22 -> 0 | ... AF4: =Summary!AF22 -> 0 | AG4: =sum(B4:AF4) -> 955.22816
A5: Breakdown
A6: - Tax | B6: =Summary!B24 -> 0 | C6: =Summary!C24 -> 0 | D6: =Summary!D24 -> 0 | E6: =Summary!E24 -> 0 | F6: =Summary!F24 -> 0 | G6: =Summary!G24 -> 0 | H6: =Summary!H24 -> 0 | I6: =Summary!I24 -> 0 | ... AF6: =Summary!AF24 -> 0 | AG6: =sum(B6:AF6) -> 55.258158
A7: - Shipping | B7: =Summary!B25 -> 0 | C7: =Summary!C25 -> 0 | D7: =Summary!D25 -> 0 | E7: =Summary!E25 -> 0 | F7: =Summary!F25 -> 0 | G7: =Summary!G25 -> 0 | H7: =Summary!H25 -> 0 | I7: =Summary!I25 -> 0 | ... AF7: =Summary!AF25 -> 0 | AG7: =sum(B7:AF7) -> 0
A8: Orders | B8: =Summary!B58 -> 0 | C8: =Summary!C58 -> 0 | D8: =Summary!D58 -> 0 | E8: =Summary!E58 -> 0 | F8: =Summary!F58 -> 0 | G8: =Summary!G58 -> 0 | H8: =Summary!H58 -> 0 | I8: =Summary!I58 -> 0 | ... AF8: =Summary!AF58 -> 0 | AG8: =sum(B8:AF8) -> 3
A10: Rachio Fees (20%) | B10: =Summary!B81 -> 0 | C10: =Summary!C81 -> 0 | D10: =Summary!D81 -> 0 | E10: =Summary!E81 -> 0 | F10: =Summary!F81 -> 0 | G10: =Summary!G81 -> 0 | H10: =Summary!H81 -> 0 | I10: =Summary!I81 -> 0 | ... AF10: =Summary!AF81 -> 0 | AG10: =sum(B10:AF10) -> 191.04563
A12: Units Sold (Gross) - Rachio
A13: SKU 1 - Blue | B13: 0 | C13: 0 | D13: 0 | E13: 0 | F13: 0 | G13: 0 | H13: 0 | I13: 0 | J13: 0 | K13: 0 | L13: 0 | M13: 0 | N13: 0 | O13: 0 | P13: 0 | Q13: 0 | R13: 0 | S13: 0 | T13: 0 | U13: 0 | V13: 0 | W13: 0 | X13: 0 | Y13: 0 | Z13: 0 | AA13: 0 | AB13: 0 | AC13: 0 | AD13: 0 | AE13: 0 | AF13: 0 | AG13: =sum(B13:AF13) -> 0
A14: SKU 2 - Yellow | B14: 0 | C14: 0 | D14: 0 | E14: 0 | F14: 0 | G14: 0 | H14: 0 | I14: 0 | J14: 0 | K14: 0 | L14: 0 | M14: 0 | N14: 0 | O14: 0 | P14: 0 | Q14: 0 | R14: 0 | S14: 0 | T14: 0 | U14: 0 | V14: 0 | W14: 0 | X14: 0 | Y14: 0 | Z14: 0 | AA14: 0 | AB14: 0 | AC14: 0 | AD14: 0 | AE14: 0 | AF14: 0 | AG14: =sum(B14:AF14) -> 0
A15: SKU 3 - Blue w/ Solar | B15: 0 | C15: 0 | D15: 0 | E15: 0 | F15: 0 | G15: 0 | H15: 0 | I15: 0 | J15: 0 | K15: 0 | L15: 0 | M15: 0 | N15: 0 | O15: 0 | P15: 0 | Q15: 0 | R15: 1 | S15: 0 | T15: 1 | U15: 0 | V15: 0 | W15: 0 | X15: 0 | Y15: 0 | Z15: 0 | AA15: 0 | AB15: 0 | AC15: 0 | AD15: 0 | AE15: 1 | AF15: 0 | AG15: =sum(B15:AF15) -> 3
A16: SKU 4 - Yellow w/ Solar | B16: 0 | C16: 0 | D16: 0 | E16: 0 | F16: 0 | G16: 0 | H16: 0 | I16: 0 | J16: 0 | K16: 0 | L16: 0 | M16: 0 | N16: 0 | O16: 0 | P16: 0 | Q16: 0 | R16: 0 | S16: 0 | T16: 0 | U16: 0 | V16: 0 | W16: 0 | X16: 0 | Y16: 0 | Z16: 0 | AA16: 0 | AB16: 0 | AC16: 0 | AD16: 0 | AE16: 0 | AF16: 0 | AG16: =sum(B16:AF16) -> 0
A17: SUM (SKU 1 - SKU 4) | B17: =SUM(B13:B16) -> 0 | C17: =SUM(C13:C16) -> 0 | D17: =SUM(D13:D16) -> 0 | E17: =SUM(E13:E16) -> 0 | F17: =SUM(F13:F16) -> 0 | G17: =SUM(G13:G16) -> 0 | H17: =SUM(H13:H16) -> 0 | I17: =SUM(I13:I16) -> 0 | ... AF17: =SUM(AF13:AF16) -> 0 | AG17: =sum(B17:AF17) -> 3
A19: Wall Mount | AG19: =sum(B19:AF19) -> 0
A20: Suet Ball Holder | AG20: =sum(B20:AF20) -> 0
A21: 3-in-1 Nutrition Set - Blue | AG21: =sum(B21:AF21) -> 0
A22: 3-in-1 Nutrition Set - Yellow | AG22: =sum(B22:AF22) -> 0
A23: Solar Roof Single - Blue | AG23: =sum(B23:AF23) -> 0
A24: Solar Roof Single - Yellow | AG24: =sum(B24:AF24) -> 0
A25: Perch Extender - Blue | AG25: =sum(B25:AF25) -> 0
A26: Perch Extender - Yellow | AG26: =sum(B26:AF26) -> 0
A27: SUM (Add-ons) | B27: =SUM(B19:B26) -> 0 | C27: =SUM(C19:C26) -> 0 | D27: =SUM(D19:D26) -> 0 | E27: =SUM(E19:E26) -> 0 | F27: =SUM(F19:F26) -> 0 | G27: =SUM(G19:G26) -> 0 | H27: =SUM(H19:H26) -> 0 | I27: =SUM(I19:I26) -> 0 | ... AF27: =SUM(AF19:AF26) -> 0 | AG27: =sum(B27:AF27) -> 0
A29: Units and Revenue Cancelled & Refunds - Rachio
A31: Units Cancelled (Gross) - Rachio
A32: SKU 1 - Blue | I32: 1 | AG32: =SUM(B32:AF32) -> 1
A33: SKU 2 - Yellow | AG33: =SUM(B33:AF33) -> 0
A34: SKU 3 - Blue w/ Solar | D34: 1 | E34: 1 | L34: 2 | M34: 1 | AG34: =SUM(B34:AF34) -> 5
A35: SKU 4 - Yellow w/ Solar | AG35: =SUM(B35:AF35) -> 0
A36: SUM (SKU 1 + SKU 2) | B36: =SUM(B32:B33) -> 0 | C36: =SUM(C32:C33) -> 0 | D36: =SUM(D32:D33) -> 0 | E36: =SUM(E32:E33) -> 0 | F36: =SUM(F32:F33) -> 0 | G36: =SUM(G32:G33) -> 0 | H36: =SUM(H32:H33) -> 0 | I36: =SUM(I32:I33) -> 1 | ... AF36: =SUM(AF32:AF33) -> 0 | AG36: =SUM(B36:AF36) -> 1
A37: SUM (SKU 3 + SKU 4) | B37: =SUM(B34:B35) -> 0 | C37: =SUM(C34:C35) -> 0 | D37: =SUM(D34:D35) -> 1 | E37: =SUM(E34:E35) -> 1 | F37: =SUM(F34:F35) -> 0 | G37: =SUM(G34:G35) -> 0 | H37: =SUM(H34:H35) -> 0 | I37: =SUM(I34:I35) -> 0 | ... AF37: =SUM(AF34:AF35) -> 0 | AG37: =SUM(B37:AF37) -> 5
A39: Wall Mount | E39: 1 | I39: 1 | AG39: =SUM(B39:AF39) -> 2
A40: Suet Ball Holder | E40: 1 | I40: 1 | L40: 1 | AG40: =SUM(B40:AF40) -> 3
A41: 3-in-1 Nutrition Set - Blue | E41: 1 | I41: 1 | AG41: =SUM(B41:AF41) -> 2
A42: 3-in-1 Nutrition Set - Yellow | AG42: =SUM(B42:AF42) -> 0
A43: Solar Roof Single - Blue | I43: 1 | AG43: =SUM(B43:AF43) -> 1
A44: Solar Roof Single - Yellow | AG44: =SUM(B44:AF44) -> 0
A45: Perch Extender - Blue | AG45: =SUM(B45:AF45) -> 0
A46: Perch Extender - Yellow | AG46: =SUM(B46:AF46) -> 0
...

Sheet PP - Results
A1: 45261 | B1: 45292 | C1: 45293 | D1: 45294 | E1: 45295 | F1: 45296 | G1: 45297 | H1: 45298 | I1: 45299 | J1: 45300 | K1: 45301 | L1: 45302 | M1: 45303 | N1: 45304 | O1: 45305 | P1: 45306 | Q1: 45307 | R1: 45308 | S1: 45309 | T1: 45310 | U1: 45311 | V1: 45312 | W1: 45313 | X1: 45314 | Y1: 45315 | Z1: 45316 | AA1: 45317 | AB1: 45318 | AC1: 45319 | AD1: 45320 | AE1: 45321 | AF1: 45322
B2: MON | C2: TUE | D2: WED | E2: THU | F2: FRI | G2: SAT | H2: SUN | I2: MON | J2: TUE | K2: WED | L2: THU | M2: FRI | N2: SAT | O2: SUN | P2: MON | Q2: TUE | R2: WED | S2: THU | T2: FRI | U2: SAT | V2: SUN | W2: MON | X2: TUE | Y2: WED | Z2: THU | AA2: FRI | AB2: SAT | AC2: SUN | AD2: MON | AE2: TUE | AF2: WED
A4: Number of participants | B4: ='PP - Data'!B10 -> 114 | C4: ='PP - Data'!C10 -> 101 | D4: ='PP - Data'!D10 -> 111 | E4: ='PP - Data'!E10 -> 95 | F4: ='PP - Data'!F10 -> 116 | G4: ='PP - Data'!G10 -> 115 | H4: ='PP - Data'!H10 -> 133 | I4: ='PP - Data'!I10 -> 93 | ... AF4: ='PP - Data'!AF10 -> 34
A5: Engagement Rate | B5: =B4/Summary!B49 -> 0.59685864 | C5: =C4/Summary!C49 -> 0.63924051 | D5: =D4/Summary!D49 -> 0.62011173 | E5: =E4/Summary!E49 -> 0.60897436 | F5: =F4/Summary!F49 -> 0.65168539 | G5: =G4/Summary!G49 -> 0.61497326 | H5: =H4/Summary!H49 -> 0.68205128 | I5: =I4/Summary!I49 -> 0.64583333 | ... AF5: =AF4/Summary!AF49 -> 0.49275362
A7: Post-purchase Survey
A8: Facebook / Instagram | B8: ='PP - Data'!B12 -> 0.20175439 | C8: ='PP - Data'!C12 -> 0.25742574 | D8: ='PP - Data'!D12 -> 0.33333333 | E8: ='PP - Data'!E12 -> 0.32631579 | F8: ='PP - Data'!F12 -> 0.29310345 | G8: ='PP - Data'!G12 -> 0.29565217 | H8: ='PP - Data'!H12 -> 0.30827068 | I8: ='PP - Data'!I12 -> 0.2688172 | ... AF8: ='PP - Data'!AF12 -> 0.47058824
A9: Where on Facebook/Instagram have you heard about Bird Buddy?
A10: I saw an ad | B10: ='PP - Data'!B28 -> 0.7826087 | C10: ='PP - Data'!C28 -> 0.84615385 | D10: ='PP - Data'!D28 -> 0.59459459 | E10: ='PP - Data'!E28 -> 0.70967742 | F10: ='PP - Data'!F28 -> 0.79411765 | G10: ='PP - Data'!G28 -> 0.58823529 | H10: ='PP - Data'!H28 -> 0.75609756 | I10: ='PP - Data'!I28 -> 0.76 | ... AF10: ='PP - Data'!AF28 -> 0.875
A11: I saw a post about Bird Buddy on my friend's feed | B11: ='PP - Data'!B29 -> 0.043478261 | C11: ='PP - Data'!C29 -> 0.076923077 | D11: ='PP - Data'!D29 -> 0.21621622 | E11: ='PP - Data'!E29 -> 0.22580645 | F11: ='PP - Data'!F29 -> 0.11764706 | G11: ='PP - Data'!G29 -> 0.26470588 | H11: ='PP - Data'!H29 -> 0.12195122 | I11: ='PP - Data'!I29 -> 0.08 | ... AF11: ='PP - Data'!AF29 -> 0.0625
A12: I saw an organic post from Bird Buddy | B12: ='PP - Data'!B30 -> 0.17391304 | C12: ='PP - Data'!C30 -> 0.076923077 | D12: ='PP - Data'!D30 -> 0.18918919 | E12: ='PP - Data'!E30 -> 0.064516129 | F12: ='PP - Data'!F30 -> 0.088235294 | G12: ='PP - Data'!G30 -> 0.14705882 | H12: ='PP - Data'!H30 -> 0.12195122 | I12: ='PP - Data'!I30 -> 0.16 | ... AF12: ='PP - Data'!AF30 -> 0.0625
A13: Friends / Family | B13: ='PP - Data'!B13 -> 0.61403509 | C13: ='PP - Data'!C13 -> 0.55445545 | D13: ='PP - Data'!D13 -> 0.5045045 | E13: ='PP - Data'!E13 -> 0.50526316 | F13: ='PP - Data'!F13 -> 0.5 | G13: ='PP - Data'!G13 -> 0.54782609 | H13: ='PP - Data'!H13 -> 0.52631579 | I13: ='PP - Data'!I13 -> 0.58064516 | ... AF13: ='PP - Data'!AF13 -> 0.41176471
A14: TikTok | B14: ='PP - Data'!B14 -> 0.0087719298 | C14: ='PP - Data'!C14 -> 0.01980198 | D14: ='PP - Data'!D14 -> 0.027027027 | E14: ='PP - Data'!E14 -> 0.010526316 | F14: ='PP - Data'!F14 -> 0 | G14: ='PP - Data'!G14 -> 0.0086956522 | H14: ='PP - Data'!H14 -> 0.007518797 | I14: ='PP - Data'!I14 -> 0.010752688 | ... AF14: ='PP - Data'!AF14 -> 0
A15: TV / Radio | B15: ='PP - Data'!B15 -> 0.0087719298 | C15: ='PP - Data'!C15 -> 0.03960396 | D15: ='PP - Data'!D15 -> 0.018018018 | E15: ='PP - Data'!E15 -> 0.010526316 | F15: ='PP - Data'!F15 -> 0.051724138 | G15: ='PP - Data'!G15 -> 0.017391304 | H15: ='PP - Data'!H15 -> 0.022556391 | I15: ='PP - Data'!I15 -> 0 | ... AF15: ='PP - Data'!AF15 -> 0
A16: Blog / Article | B16: ='PP - Data'!B16 -> 0.070175439 | C16: ='PP - Data'!C16 -> 0.0099009901 | D16: ='PP - Data'!D16 -> 0.036036036 | E16: ='PP - Data'!E16 -> 0.052631579 | F16: ='PP - Data'!F16 -> 0.051724138 | G16: ='PP - Data'!G16 -> 0.052173913 | H16: ='PP - Data'!H16 -> 0.07518797 | I16: ='PP - Data'!I16 -> 0.064516129 | ... AF16: ='PP - Data'!AF16 -> 0.058823529
A17: Reddit | B17: ='PP - Data'!B17 -> 0 | C17: ='PP - Data'!C17 -> 0.0099009901 | D17: ='PP - Data'!D17 -> 0.036036036 | E17: ='PP - Data'!E17 -> 0.021052632 | F17: ='PP - Data'!F17 -> 0 | G17: ='PP - Data'!G17 -> 0 | H17: ='PP - Data'!H17 -> 0.007518797 | I17: ='PP - Data'!I17 -> 0 | ... AF17: ='PP - Data'!AF17 -> 0
A18: Google, Youtube | B18: ='PP - Data'!B18 -> 0.096491228 | C18: ='PP - Data'!C18 -> 0.10891089 | D18: ='PP - Data'!D18 -> 0.045045045 | E18: ='PP - Data'!E18 -> 0.073684211 | F18: ='PP - Data'!F18 -> 0.10344828 | G18: ='PP - Data'!G18 -> 0.069565217 | H18: ='PP - Data'!H18 -> 0.052631579 | I18: ='PP - Data'!I18 -> 0.075268817 | ... AF18: ='PP - Data'!AF18 -> 0.058823529
A19: Yahoo, Bing | B19: ='PP - Data'!B19 -> 0 | C19: ='PP - Data'!C19 -> 0 | D19: ='PP - Data'!D19 -> 0 | E19: ='PP - Data'!E19 -> 0 | F19: ='PP - Data'!F19 -> 0 | G19: ='PP - Data'!G19 -> 0.0086956522 | H19: ='PP - Data'!H19 -> 0 | I19: ='PP - Data'!I19 -> 0 | ... AF19: ='PP - Data'!AF19 -> 0
A24: Number of participants | B24: ='PP - Data'!B60 -> 115 | C24: ='PP - Data'!C60 -> 100 | D24: ='PP - Data'!D60 -> 111 | E24: ='PP - Data'!E60 -> 95 | F24: ='PP - Data'!F60 -> 117 | G24: ='PP - Data'!G60 -> 115 | H24: ='PP - Data'!H60 -> 132 | I24: ='PP - Data'!I60 -> 94 | ... AF24: ='PP - Data'!AF60 -> 34
A25: Engagement Rate | B25: =B24/Summary!B49 -> 0.60209424 | C25: =C24/Summary!C49 -> 0.63291139 | D25: =D24/Summary!D49 -> 0.62011173 | E25: =E24/Summary!E49 -> 0.60897436 | F25: =F24/Summary!F49 -> 0.65730337 | G25: =G24/Summary!G49 -> 0.61497326 | H25: =H24/Summary!H49 -> 0.67692308 | I25: =I24/Summary!I49 -> 0.65277778 | ... AF25: =AF24/Summary!AF49 -> 0.49275362
A27: Who is this for? (sub-question 3)
