Workbook
Name zsupermetrics_ru0GDtbZzDLHQOQtJJ6K08MvUDyyp7: #REF!
Name zsupermetrics_DQl8lUbpTRu3fayaJJi7lVfOGKjNU4: 'Data - P&L'!$A$3:$A$4
Name zsupermetrics_BioPyGBzcBsy60UCQmPcTuFReEmghI: 'Data - P&L'!$B$2:$B$3
Name zsupermetrics_refreshAll: SupermetricsQueries!$H$5
Name zsupermetrics_n3GtLgiKpTmd2pYmQNMuq6TPD0qE0b: #REF!
Name zsupermetrics_refreshAllSilent: SupermetricsQueries!$H$6
Name zsupermetrics_Mgms9p0QzysYvrIhnsKACeVBVxfIEO: #REF!
Name zsupermetrics_Mgms9p0QzysYvrIhnsKACeVBVxfIEO: 'Data - P&L'!$A$2:$A$3
Name zsupermetrics_forceRefresh: SupermetricsQueries!$H$4
Name zsupermetrics_wbYMmT0YL9bAN0yhimW0ziPFnia9Dx: #REF!
Name zsupermetrics_iNpyVy90bWCI0yUaFQpxOtzWMa6sW4: #REF!
Name zsupermetrics_xwoIpANxRm908eDp5oKTwQpEI8gvD4: #REF!
Name zsupermetrics_n3GtLgiKpTmd2pYmQNMuq6TPD0qE0b: 'Data - P&L'!$B$4:$B$5
Name rdataslayer_42b112e4e4be4305bb4c1be75e2dd549: 'Data - P&L'!$B$2:$C$3
Name zsupermetrics_9i4W4hgd80uRpQLMeX0eRnESN8gjyv: #REF!
Name zsupermetrics_5bmwtOpHUbSYmDMeuCPkrxaojTprPP: #REF!
Name rdataslayer_3753ddf3234e496aa261974a0222e193: 'Data - P&L'!$H$2:$I$2
Name zsupermetrics_SGBxROnInO9rFyh3H7j2Lldx0Bdc5v: #REF!
Name zsupermetrics_pxuhRTEmIU93xSgKclyxajD0fCZ6rF: #REF!
Name zsupermetrics_ru0GDtbZzDLHQOQtJJ6K08MvUDyyp7: 'Data - P&L'!$B$4:$B$5
Name zsupermetrics_qWp7V908pNEYMtfv8QZvSTeDnBAHOU: 'Data - P&L'!$B$5:$C$13
Name rdataslayer_4a0f150f4f2f4e4f85c890c75b7a1fa4: #REF!
Name zsupermetrics_8xojRjNDjo2jWHGDWjFEhflhyIq3Hq: #REF!
Name zsupermetrics_HgZqhorObHOtZHuyJjpmyYaEPoYntx: #REF!
Name zsupermetrics_YsFuuYtr8vOdNXCCPiFJIO38NP4b2T: #REF!
Name zsupermetrics_DQl8lUbpTRu3fayaJJi7lVfOGKjNU4: #REF!
Name zsupermetrics_YVuzfmsfdurz7Ldl84Rfns8oka6LsS: #REF!
Name zsupermetrics_4VkB7ij7WO0JjKBEgvjB2GHjSy2Egm: #REF!
Name zsupermetrics_9i4W4hgd80uRpQLMeX0eRnESN8gjyv: 'Data - P&L'!$C$13
Name zsupermetrics_lx4cNai7gT6tH4j08ZRkI21Qlpjioi: #REF!
Name rdataslayer_d70e473bcafe40a3aa834ce157fb2ba3: #REF!
Name zsupermetrics_NugLlrQxlKiqhxQae8EFpITBm1pLCj: 'Data - P&L'!$B$6:$C$13
Name zsupermetrics_8xojRjNDjo2jWHGDWjFEhflhyIq3Hq: Summary!$K$8:$K$48
Name zsupermetrics_FEamnpN5FsVYF0RtUTXAwunZ388Tkc: Forecast!$A$113:$C$141
Name rdataslayer_3753ddf3234e496aa261974a0222e193: #REF!
Name zsupermetrics_iNpyVy90bWCI0yUaFQpxOtzWMa6sW4: 'Data - P&L'!$A$2:$A$3
Name rdataslayer_4a0f150f4f2f4e4f85c890c75b7a1fa4: 'Data - P&L'!$D$2:$E$3
Name zsupermetrics_BioPyGBzcBsy60UCQmPcTuFReEmghI: #REF!
Name zsupermetrics_qWp7V908pNEYMtfv8QZvSTeDnBAHOU: #REF!
Name zsupermetrics_wbYMmT0YL9bAN0yhimW0ziPFnia9Dx: 'Data - P&L'!$A$2:$A$3
Name zsupermetrics_4VkB7ij7WO0JjKBEgvjB2GHjSy2Egm: 'Data - P&L'!$B$4:$C$10
Name zsupermetrics_lx4cNai7gT6tH4j08ZRkI21Qlpjioi: 'Data - P&L'!$B$4:$C$13
Name rdataslayer_42b112e4e4be4305bb4c1be75e2dd549: #REF!
Name rdataslayer_adf57e64065742daa5b4161161b1c3ca: #REF!
Name rdataslayer_adf57e64065742daa5b4161161b1c3ca: 'Data - P&L'!$B$4:$D$5
Name zsupermetrics_NugLlrQxlKiqhxQae8EFpITBm1pLCj: #REF!
Name zsupermetrics_xwoIpANxRm908eDp5oKTwQpEI8gvD4: #REF!
Name zsupermetrics_YsFuuYtr8vOdNXCCPiFJIO38NP4b2T: 'Data - P&L'!$B$4:$C$13
Name rdataslayer_d70e473bcafe40a3aa834ce157fb2ba3: 'Data - P&L'!$C$8:$D$9
Name zsupermetrics_HgZqhorObHOtZHuyJjpmyYaEPoYntx: 'Data - P&L'!$B$4:$B$5

Sheet Data_forecast_2024
B1: 45566 | C1: 45567 | D1: 45568 | E1: 45569 | F1: 45570 | G1: 45571 | H1: 45572 | I1: 45573 | J1: 45574 | K1: 45575 | L1: 45576 | M1: 45577 | N1: 45578 | O1: 45579 | P1: 45580 | Q1: 45581 | R1: 45582 | S1: 45583 | T1: 45584 | U1: 45585 | V1: 45586 | W1: 45587 | X1: 45588 | Y1: 45589 | Z1: 45590 | AA1: 45591 | AB1: 45592 | AC1: 45593 | AD1: 45594 | AE1: 45595 | AF1: 45596
A2: Quantities | B2: ='DTC - P&L'!B63+'AMAZON - P&L'!B36+'WALMART - P&L'!B19+'Digital Marketplaces - P&L'!B17+'Digital Marketplaces - P&L'!B129+'Digital Marketplaces - P&L'!B239 -> 43 | C2: ='DTC - P&L'!C63+'AMAZON - P&L'!C36+'WALMART - P&L'!C19+'Digital Marketplaces - P&L'!C17+'Digital Marketplaces - P&L'!C129+'Digital Marketplaces - P&L'!C239 -> 36 | D2: ='DTC - P&L'!D63+'AMAZON - P&L'!D36+'WALMART - P&L'!D19+'Digital Marketplaces - P&L'!D17+'Digital Marketplaces - P&L'!D129+'Digital Marketplaces - P&L'!D239 -> 40 | E2: ='DTC - P&L'!E63+'AMAZON - P&L'!E36+'WALMART - P&L'!E19+'Digital Marketplaces - P&L'!E17+'Digital Marketplaces - P&L'!E129+'Digital Marketplaces - P&L'!E239 -> 26 | F2: ='DTC - P&L'!F63+'AMAZON - P&L'!F36+'WALMART - P&L'!F19+'Digital Marketplaces - P&L'!F17+'Digital Marketplaces - P&L'!F129+'Digital Marketplaces - P&L'!F239 -> 22 | G2: ='DTC - P&L'!G63+'AMAZON - P&L'!G36+'WALMART - P&L'!G19+'Digital Marketplaces - P&L'!G17+'Digital Marketplaces - P&L'!G129+'Digital Marketplaces - P&L'!G239 -> 27 | H2: ='DTC - P&L'!H63+'AMAZON - P&L'!H36+'WALMART - P&L'!H19+'Digital Marketplaces - P&L'!H17+'Digital Marketplaces - P&L'!H129+'Digital Marketplaces - P&L'!H239 -> 28 | I2: ='DTC - P&L'!I63+'AMAZON - P&L'!I36+'WALMART - P&L'!I19+'Digital Marketplaces - P&L'!I17+'Digital Marketplaces - P&L'!I129+'Digital Marketplaces - P&L'!I239 -> 424 | ... AF2: ='DTC - P&L'!AF63+'AMAZON - P&L'!AF36+'WALMART - P&L'!AF19+'Digital Marketplaces - P&L'!AF17+'Digital Marketplaces - P&L'!AF129+'Digital Marketplaces - P&L'!AF239 -> 208
A3: Sales | B3: =Summary!B8+Summary!B25+Summary!B31+Summary!B35 -> 17178.81 | C3: =Summary!C8+Summary!C25+Summary!C31+Summary!C35 -> 12596.87 | D3: =Summary!D8+Summary!D25+Summary!D31+Summary!D35 -> 14429.86 | E3: =Summary!E8+Summary!E25+Summary!E31+Summary!E35 -> 10171.31 | F3: =Summary!F8+Summary!F25+Summary!F31+Summary!F35 -> 10354.06 | G3: =Summary!G8+Summary!G25+Summary!G31+Summary!G35 -> 10648.64 | H3: =Summary!H8+Summary!H25+Summary!H31+Summary!H35 -> 11126.65 | I3: =Summary!I8+Summary!I25+Summary!I31+Summary!I35 -> 98747.06 | ... AF3: =Summary!AF8+Summary!AF25+Summary!AF31+Summary!AF35 -> 63685.19

Sheet WALMART_Data_forecast_2024
B1: 45566 | C1: 45567 | D1: 45568 | E1: 45569 | F1: 45570 | G1: 45571 | H1: 45572 | I1: 45573 | J1: 45574 | K1: 45575 | L1: 45576 | M1: 45577 | N1: 45578 | O1: 45579 | P1: 45580 | Q1: 45581 | R1: 45582 | S1: 45583 | T1: 45584 | U1: 45585 | V1: 45586 | W1: 45587 | X1: 45588 | Y1: 45589 | Z1: 45590 | AA1: 45591 | AB1: 45592 | AC1: 45593 | AD1: 45594 | AE1: 45595 | AF1: 45596
A2: Quantities | B2: ='WALMART - P&L'!B19 -> 0 | C2: ='WALMART - P&L'!C19 -> 0 | D2: ='WALMART - P&L'!D19 -> 0 | E2: ='WALMART - P&L'!E19 -> 0 | F2: ='WALMART - P&L'!F19 -> 0 | G2: ='WALMART - P&L'!G19 -> 0 | H2: ='WALMART - P&L'!H19 -> 1 | I2: ='WALMART - P&L'!I19 -> 1 | ... AF2: ='WALMART - P&L'!AF19 -> 0
A3: Sales | B3: =Summary!B31 -> 0 | C3: =Summary!C31 -> 0 | D3: =Summary!D31 -> 0 | E3: =Summary!E31 -> 0 | F3: =Summary!F31 -> 0 | G3: =Summary!G31 -> 0 | H3: =Summary!H31 -> 321.43 | I3: =Summary!I31 -> 316.94 | ... AF3: =Summary!AF31 -> 0

Sheet COSTCO_Data_forecast_2024
B1: 45566 | C1: 45567 | D1: 45568 | E1: 45569 | F1: 45570 | G1: 45571 | H1: 45572 | I1: 45573 | J1: 45574 | K1: 45575 | L1: 45576 | M1: 45577 | N1: 45578 | O1: 45579 | P1: 45580 | Q1: 45581 | R1: 45582 | S1: 45583 | T1: 45584 | U1: 45585 | V1: 45586 | W1: 45587 | X1: 45588 | Y1: 45589 | Z1: 45590 | AA1: 45591 | AB1: 45592 | AC1: 45593 | AD1: 45594 | AE1: 45595 | AF1: 45596
A2: Quantities | B2: ='Digital Marketplaces - P&L'!B239 -> 0 | C2: ='Digital Marketplaces - P&L'!C239 -> 0 | D2: ='Digital Marketplaces - P&L'!D239 -> 0 | E2: ='Digital Marketplaces - P&L'!E239 -> 0 | F2: ='Digital Marketplaces - P&L'!F239 -> 0 | G2: ='Digital Marketplaces - P&L'!G239 -> 0 | H2: ='Digital Marketplaces - P&L'!H239 -> 0 | I2: ='Digital Marketplaces - P&L'!I239 -> 0 | ... AF2: ='Digital Marketplaces - P&L'!AF239 -> 4
A3: Sales | B3: =Summary!B44 -> 0 | C3: =Summary!C44 -> 0 | D3: =Summary!D44 -> 0 | E3: =Summary!E44 -> 0 | F3: =Summary!F44 -> 0 | G3: =Summary!G44 -> 0 | H3: =Summary!H44 -> 0 | I3: =Summary!I44 -> 0 | ... AF3: =Summary!AF44 -> 0

Sheet DM_Data_forecast_2024
B1: 45566 | C1: 45567 | D1: 45568 | E1: 45569 | F1: 45570 | G1: 45571 | H1: 45572 | I1: 45573 | J1: 45574 | K1: 45575 | L1: 45576 | M1: 45577 | N1: 45578 | O1: 45579 | P1: 45580 | Q1: 45581 | R1: 45582 | S1: 45583 | T1: 45584 | U1: 45585 | V1: 45586 | W1: 45587 | X1: 45588 | Y1: 45589 | Z1: 45590 | AA1: 45591 | AB1: 45592 | AC1: 45593 | AD1: 45594 | AE1: 45595 | AF1: 45596
A2: Quantities | B2: ='Digital Marketplaces - P&L'!B17+'Digital Marketplaces - P&L'!B129 -> 0 | C2: ='Digital Marketplaces - P&L'!C17+'Digital Marketplaces - P&L'!C129 -> 0 | D2: ='Digital Marketplaces - P&L'!D17+'Digital Marketplaces - P&L'!D129 -> 0 | E2: ='Digital Marketplaces - P&L'!E17+'Digital Marketplaces - P&L'!E129 -> 0 | F2: ='Digital Marketplaces - P&L'!F17+'Digital Marketplaces - P&L'!F129 -> 0 | G2: ='Digital Marketplaces - P&L'!G17+'Digital Marketplaces - P&L'!G129 -> 0 | H2: ='Digital Marketplaces - P&L'!H17+'Digital Marketplaces - P&L'!H129 -> 0 | I2: ='Digital Marketplaces - P&L'!I17+'Digital Marketplaces - P&L'!I129 -> 0 | ... AF2: ='Digital Marketplaces - P&L'!AF17+'Digital Marketplaces - P&L'!AF129 -> 0
A3: Sales | B3: =Summary!B36+Summary!B40 -> 0 | C3: =Summary!C36+Summary!C40 -> 0 | D3: =Summary!D36+Summary!D40 -> 0 | E3: =Summary!E36+Summary!E40 -> 0 | F3: =Summary!F36+Summary!F40 -> 0 | G3: =Summary!G36+Summary!G40 -> 0 | H3: =Summary!H36+Summary!H40 -> 0 | I3: =Summary!I36+Summary!I40 -> 0 | ... AF3: =Summary!AF36+Summary!AF40 -> 0

Sheet AMAZON_Data_forecast_2024
B1: 45566 | C1: 45567 | D1: 45568 | E1: 45569 | F1: 45570 | G1: 45571 | H1: 45572 | I1: 45573 | J1: 45574 | K1: 45575 | L1: 45576 | M1: 45577 | N1: 45578 | O1: 45579 | P1: 45580 | Q1: 45581 | R1: 45582 | S1: 45583 | T1: 45584 | U1: 45585 | V1: 45586 | W1: 45587 | X1: 45588 | Y1: 45589 | Z1: 45590 | AA1: 45591 | AB1: 45592 | AC1: 45593 | AD1: 45594 | AE1: 45595 | AF1: 45596
A2: Quantities | B2: ='AMAZON - P&L'!B36 -> 27 | C2: ='AMAZON - P&L'!C36 -> 23 | D2: ='AMAZON - P&L'!D36 -> 24 | E2: ='AMAZON - P&L'!E36 -> 16 | F2: ='AMAZON - P&L'!F36 -> 8 | G2: ='AMAZON - P&L'!G36 -> 17 | H2: ='AMAZON - P&L'!H36 -> 17 | I2: ='AMAZON - P&L'!I36 -> 412 | ... AF2: ='AMAZON - P&L'!AF36 -> 90
A3: Sales | B3: =Summary!B25 -> 7953.97 | C3: =Summary!C25 -> 6765.07 | D3: =Summary!D25 -> 7698.8 | E3: =Summary!E25 -> 5011.15 | F3: =Summary!F25 -> 2828.44 | G3: =Summary!G25 -> 5401.75 | H3: =Summary!H25 -> 5446.92 | I3: =Summary!I25 -> 93468.46 | ... AF3: =Summary!AF25 -> 22434.14

Sheet DTC_Data_forecast_2024
B1: 45566 | C1: 45567 | D1: 45568 | E1: 45569 | F1: 45570 | G1: 45571 | H1: 45572 | I1: 45573 | J1: 45574 | K1: 45575 | L1: 45576 | M1: 45577 | N1: 45578 | O1: 45579 | P1: 45580 | Q1: 45581 | R1: 45582 | S1: 45583 | T1: 45584 | U1: 45585 | V1: 45586 | W1: 45587 | X1: 45588 | Y1: 45589 | Z1: 45590 | AA1: 45591 | AB1: 45592 | AC1: 45593 | AD1: 45594 | AE1: 45595 | AF1: 45596
A2: Quantities | B2: ='DTC - P&L'!B63 -> 16 | C2: ='DTC - P&L'!C63 -> 13 | D2: ='DTC - P&L'!D63 -> 16 | E2: ='DTC - P&L'!E63 -> 10 | F2: ='DTC - P&L'!F63 -> 14 | G2: ='DTC - P&L'!G63 -> 10 | H2: ='DTC - P&L'!H63 -> 10 | I2: ='DTC - P&L'!I63 -> 11 | ... AF2: ='DTC - P&L'!AF63 -> 114
A3: Sales | B3: =Summary!B8 -> 9224.84 | C3: =Summary!C8 -> 5831.8 | D3: =Summary!D8 -> 6731.06 | E3: =Summary!E8 -> 5160.16 | F3: =Summary!F8 -> 7525.62 | G3: =Summary!G8 -> 5246.89 | H3: =Summary!H8 -> 5358.3 | I3: =Summary!I8 -> 4961.66 | ... AF3: =Summary!AF8 -> 41251.05

Sheet Summary
B1: 45566 | C1: 45567 | D1: 45568 | E1: 45569 | F1: 45570 | G1: 45571 | H1: 45572 | I1: 45573 | J1: 45574 | K1: 45575 | L1: 45576 | M1: 45577 | N1: 45578 | O1: 45579 | P1: 45580 | Q1: 45581 | R1: 45582 | S1: 45583 | T1: 45584 | U1: 45585 | V1: 45586 | W1: 45587 | X1: 45588 | Y1: 45589 | Z1: 45590 | AA1: 45591 | AB1: 45592 | AC1: 45593 | AD1: 45594 | AE1: 45595 | AF1: 45596
B2: TUE | C2: WED | D2: THU | E2: FRI | F2: SAT | G2: SUN | H2: MON | I2: TUE | J2: WED | K2: THU | L2: FRI | M2: SAT | N2: SUN | O2: MON | P2: TUE | Q2: WED | R2: THU | S2: FRI | T2: SAT | U2: SUN | V2: MON | W2: TUE | X2: WED | Y2: THU | Z2: FRI | AA2: SAT | AB2: SUN | AC2: MON | AD2: TUE | AE2: WED | AF2: THU
A4: Notes | B4: Started with popups | C4: SKU1 OOS | D4: Change of popup design | H4: Listicle Landing Page Start | I4: Prime Day MAP | K4: Canada start DTC | L4: EU test order | P4: Nature Cam PRO Launch | Q4: Accelerated spend on Meta ( 6K of "bad spend ") LP Test ( 10/30% discount split start ) EU DTC start | Z4: A/B Test (/convert & /v2) | AC4: Nature Cam PRO Launch Email #2 | AF4: A/B Test (/offer-pro)
A8: DTC Revenue | B8: =SUM(B9,B17) -> 9224.84 | C8: =SUM(C9,C17) -> 5831.8 | D8: =SUM(D9,D17) -> 6731.06 | E8: =SUM(E9,E17) -> 5160.16 | F8: =SUM(F9,F17) -> 7525.62 | G8: =SUM(G9,G17) -> 5246.89 | H8: =SUM(H9,H17) -> 5358.3 | I8: =SUM(I9,I17) -> 4961.66 | ... AF8: =SUM(AF9,AF17) -> 41251.05
A9: - DTC Revenue US&CA | B9: =sum(B10:B16) -> 9224.84 | C9: =sum(C10:C16) -> 5831.8 | D9: =sum(D10:D16) -> 6731.06 | E9: =sum(E10:E16) -> 5160.16 | F9: =sum(F10:F16) -> 7525.62 | G9: =sum(G10:G16) -> 5246.89 | H9: =sum(H10:H16) -> 5358.3 | I9: =sum(I10:I16) -> 4961.66 | ... AF9: =sum(AF10:AF16) -> 34342.97
A10: - Hardware | B10: 4811 | C10: 3876 | D10: 4654.3 | E10: 3588.1 | F10: 5412.2 | G10: 3259 | H10: 3872.1 | I10: 3757.75 | J10: 5611.3 | K10: 3465.6 | L10: 5010.15 | M10: 4547.33 | N10: 5509.5 | O10: 4655.3 | P10: 10914.08 | Q10: 8053.92 | R10: 5712.39 | S10: 5078.73 | T10: 5641.73 | U10: 2441 | V10: 4891.03 | W10: 3616.79 | X10: 7532.83 | Y10: 7031.9 | Z10: 15306.2 | AA10: 31544.15 | AB10: 29064.2 | AC10: 14646.15 | AD10: 15626.2 | AE10: 20290.15 | AF10: 25189.9
A11: - Add-ons | B11: 2000.3 | C11: 485.9 | D11: 519 | E11: 243 | F11: 409.1 | G11: 739.3 | H11: 418.9 | I11: 235.9 | J11: 1190.8 | K11: 841.5 | L11: 1078.1 | M11: 531.57 | N11: 883.2 | O11: 373 | P11: 26637.02 | Q11: 14171.58 | R11: 8502.81 | S11: 5676.69 | T11: 4650.41 | U11: 4263.22 | V11: 2624.12 | W11: 3253.65 | X11: 2763.36 | Y11: 3341.44 | Z11: 6222.2 | AA11: 5600.9 | AB11: 3983.2 | AC11: 5283.29 | AD11: 4530.45 | AE11: 4753.45 | AF11: 3108.63
A12: - Merch | B12: 0 | C12: 0 | D12: 0 | E12: 0 | F12: 0 | G12: 0 | H12: 0 | I12: 0 | J12: 514.79 | K12: 0 | L12: 0 | M12: 0 | N12: 0 | O12: 0 | P12: 0 | Q12: 0 | R12: 0 | S12: 0 | T12: 0 | U12: 0 | V12: 0 | W12: 0 | X12: 0 | Y12: 0 | Z12: 0 | AA12: 0 | AB12: 0 | AC12: 0 | AD12: 24.99 | AE12: 0 | AF12: 0
A13: - Seeds | B13: 710.7 | C13: 439.3 | D13: 555.1 | E13: 621.8 | F13: 672.7 | G13: 477.1 | H13: 344.6 | I13: 256.1 | J13: 389.5 | K13: 415.6 | L13: 400.7 | M13: 209.2 | N13: 246.3 | O13: 221.2 | P13: 620 | Q13: 423.6 | R13: 401.6 | S13: 179.3 | T13: 179.3 | U13: 296 | V13: 455.2 | W13: 233.2 | X13: 235.2 | Y13: 343.8 | Z13: 263.2 | AA13: 409.6 | AB13: 464.2 | AC13: 325.9 | AD13: 203.3 | AE13: 179.4 | AF13: 439.5
A14: - Yearly Pro Subscription | B14: 479.92 | C14: 299.95 | D14: 239.96 | E14: 0 | F14: 59.99 | G14: 59.99 | H14: 0 | I14: 59.99 | J14: 59.99 | K14: 179.97 | L14: 119.98 | M14: 239.96 | N14: 539.91 | O14: 419.93 | P14: 179.97 | Q14: 179.97 | R14: 299.95 | S14: 59.99 | T14: 239.96 | U14: 359.94 | V14: 59.99 | W14: 299.95 | X14: 299.95 | Y14: 179.97 | Z14: 239.96 | AA14: 299.95 | AB14: 299.95 | AC14: 239.96 | AD14: 59.99 | AE14: 0 | AF14: 179.97
A15: - Taxes | B15: 557.92 | C15: 353.65 | D15: 385.26 | E15: 305.76 | F15: 501.63 | G15: 334.5 | H15: 350.7 | I15: 297.71 | J15: 569.74 | K15: 361.64 | L15: 530.35 | M15: 447.54 | N15: 420.75 | O15: 411.75 | P15: 2594.41 | Q15: 1561.32 | R15: 1055.71 | S15: 784.71 | T15: 779.03 | U15: 522.03 | V15: 537.96 | W15: 446.39 | X15: 823.26 | Y15: 745.87 | Z15: 1624.01 | AA15: 2757.99 | AB15: 2514.29 | AC15: 1549.41 | AD15: 1606.93 | AE15: 1800.97 | AF15: 2207.84
A16: - Shipping | B16: 665 | C16: 377 | D16: 377.44 | E16: 401.5 | F16: 470 | G16: 377 | H16: 372 | I16: 354.21 | J16: 740.82 | K16: 429.16 | L16: 661.59 | M16: 400 | N16: 611.46 | O16: 395 | P16: 2880 | Q16: 1903.82 | R16: 1266.37 | S16: 971.54 | T16: 959.82 | U16: 565 | V16: 729.77 | W16: 742.02 | X16: 1141.61 | Y16: 1041 | Z16: 1963.37 | AA16: 3759.93 | AB16: 3343.1 | AC16: 1827.26 | AD16: 2360.23 | AE16: 2814.84 | AF16: 3217.13
A17: - DTC Revenue EU | B17: / | C17: / | D17: / | E17: / | F17: / | G17: / | H17: / | I17: / | J17: / | K17: =SUM(K18:K24) -> 599.19 | L17: / | M17: / | N17: / | O17: / | P17: / | Q17: =SUM(Q18:Q24) -> 1579.99 | R17: =SUM(R18:R24) -> 5894.45 | S17: =SUM(S18:S24) -> 3947.49 | T17: =SUM(T18:T24) -> 2042.12 | U17: =SUM(U18:U24) -> 352.15 | V17: =SUM(V18:V24) -> 1576.04 | W17: =SUM(W18:W24) -> 918.92 | X17: =SUM(X18:X24) -> 0 | ... AF17: =SUM(AF18:AF24) -> 6908.08
A18: - Hardware | K18: 439.2 | Q18: 919.49 | R18: 4182.37 | S18: 2749.13 | T18: 1423.83 | U18: 268.58 | V18: 1106.58 | W18: 661.09 | X18: 0 | Y18: 951.68 | Z18: 751.39 | AA18: 241.08 | AB18: 1360.58 | AC18: 1737.92 | AD18: 4080.63 | AE18: 3749.85 | AF18: 4759.75
A19: - Add-ons | K19: 0 | Q19: 289.11 | R19: 245.13 | S19: 208.74 | T19: 122.68 | U19: 0 | V19: 76.56 | W19: 16.81 | X19: 0 | Y19: 244.45 | Z19: 170.76 | AA19: 33.92 | AB19: 165.2 | AC19: 264.52 | AD19: 242.44 | AE19: 297.85 | AF19: 448.91
A20: - Merch | K20: 0 | Q20: 0 | R20: 0 | S20: 0 | T20: 0 | U20: 0 | V20: 0 | W20: 0 | X20: 0 | Y20: 0 | Z20: 0 | AA20: 0 | AB20: 0 | AC20: 0 | AD20: 0 | AE20: 0 | AF20: 0
A21: - Seeds | K21: 0 | Q21: 0 | R21: 0 | S21: 0 | T21: 0 | U21: 0 | V21: 0 | W21: 0 | X21: 0 | Y21: 0 | Z21: 0 | AA21: 0 | AB21: 0 | AC21: 0 | AD21: 0 | AE21: 0 | AF21: 0
A22: - Yearly Pro Subscription | K22: 0 | Q22: 0 | R22: 0 | S22: 0 | T22: 0 | U22: 0 | V22: 0 | W22: 0 | X22: 0 | Y22: 0 | Z22: 0 | AA22: 0 | AB22: 0 | AC22: 0 | AD22: 0 | AE22: 0 | AF22: 0
A23: - Taxes | K23: 83.45 | Q23: 241.08 | R23: 930.82 | S23: 636.21 | T23: 321.66 | U23: 56.4 | V23: 246.87 | W23: 160.03 | X23: 0 | Y23: 245.16 | Z23: 189.17 | AA23: 67.4 | AB23: 318.34 | AC23: 430.93 | AD23: 911.26 | AE23: 839.93 | AF23: 1100.8
A24: - Shipping | K24: 76.54 | Q24: 130.31 | R24: 536.13 | S24: 353.41 | T24: 173.95 | U24: 27.17 | V24: 146.03 | W24: 80.99 | X24: 0 | Y24: 140.75 | Z24: 91.8 | AA24: 37.8 | AB24: 183.55 | AC24: 200.08 | AD24: 535.64 | AE24: 466.94 | AF24: 598.62
A25: Amazon Revenue | B25: =B26+B27+B28+B29+B30 -> 7953.97 | C25: =C26+C27+C28+C29+C30 -> 6765.07 | D25: =D26+D27+D28+D29+D30 -> 7698.8 | E25: =E26+E27+E28+E29+E30 -> 5011.15 | F25: =F26+F27+F28+F29+F30 -> 2828.44 | G25: =G26+G27+G28+G29+G30 -> 5401.75 | H25: =H26+H27+H28+H29+H30 -> 5446.92 | I25: =I26+I27+I28+I29+I30 -> 93468.46 | ... AF25: =AF26+AF27+AF28+AF29+AF30 -> 22434.14
A26: - Hardware | B26: 7233 | C26: 6157 | D26: 6993.56 | E26: 4539.12 | F26: 2332 | G26: 4840.56 | H26: 4898.12 | I26: 86106.86 | J26: 74056.8 | K26: 23666.54 | L26: 5581.46 | M26: 5121.31 | N26: 4583.31 | O26: 5864.9 | P26: 5648.83 | Q26: 12202.86 | R26: 6977.94 | S26: 6400.65 | T26: 4855.8 | U26: 5597.88 | V26: 4804.65 | W26: 6103.23 | X26: 4677.63 | Y26: 8325.18 | Z26: 8135 | AA26: 23333.14 | AB26: 15867.14 | AC26: 12658.76 | AD26: 7984.94 | AE26: 10435 | AF26: 20447.5
A27: - Add-ons | B27: 213 | C27: 164 | D27: 222 | E27: 154 | F27: 309 | G27: 184 | H27: 203 | I27: 1207.2 | J27: 1096 | K27: 511 | L27: 162.46 | M27: 252 | N27: 375.48 | O27: 242 | P27: 144 | Q27: 146.2 | R27: 174 | S27: 193 | T27: 300 | U27: 271 | V27: 145 | W27: 220.06 | X27: 193 | Y27: 242 | Z27: 242 | AA27: 701.33 | AB27: 233 | AC27: 309 | AD27: 289 | AE27: 415 | AF27: 522
A28: - Tax | B28: 503.48 | C28: 439.58 | D28: 451.32 | E28: 296.65 | F28: 175.96 | G28: 367.96 | H28: 327.34 | I28: 6084.31 | J28: 5208.44 | K28: 1708.17 | L28: 390.58 | M28: 377.7 | N28: 356.62 | O28: 444.54 | P28: 397.33 | Q28: 899.67 | R28: 480.85 | S28: 524.3 | T28: 391.74 | U28: 389.37 | V28: 298.46 | W28: 421.24 | X28: 275.91 | Y28: 490.38 | Z28: 599.4 | AA28: 1694.46 | AB28: 1106.21 | AC28: 776.62 | AD28: 572.79 | AE28: 757.13 | AF28: 1439.98
A29: - Shipping | B29: 0 | C29: 0 | D29: 27.26 | E29: 21.04 | F29: 6.99 | G29: 0.08 | H29: 0.16 | I29: 49.97 | J29: 34.51 | K29: 0.33 | L29: 18.78 | M29: 0.08 | N29: 0.08 | O29: 0 | P29: 30.64 | Q29: 0.5 | R29: 0.75 | S29: 49.42 | T29: 0 | U29: 0.25 | V29: 0 | W29: 0.25 | X29: 0.25 | Y29: 17.19 | Z29: 0 | AA29: 13.28 | AB29: 7.74 | AC29: 12.64 | AD29: 0.33 | AE29: 0 | AF29: 14.89
A30: - Gift Wrap | B30: 4.49 | C30: 4.49 | D30: 4.66 | E30: 0.34 | F30: 4.49 | G30: 9.15 | H30: 18.3 | I30: 20.12 | J30: 37.42 | K30: 4.81 | L30: 0.17 | M30: 4.16 | N30: 4.66 | O30: 4.49 | P30: 4.64 | Q30: 0.3 | R30: 4.94 | S30: 4.49 | T30: 4.49 | U30: 0.15 | V30: 0 | W30: 0.15 | X30: 9.13 | Y30: 9.13 | Z30: 0 | AA30: 4.94 | AB30: 4.94 | AC30: 4.79 | AD30: 9.3 | AE30: 0 | AF30: 9.77
A31: Walmart Revenue | B31: =sum(B32:B34) -> 0 | C31: =sum(C32:C34) -> 0 | D31: =sum(D32:D34) -> 0 | E31: =sum(E32:E34) -> 0 | F31: =sum(F32:F34) -> 0 | G31: =sum(G32:G34) -> 0 | H31: =sum(H32:H34) -> 321.43 | I31: =sum(I32:I34) -> 316.94 | ... AF31: =sum(AF32:AF34) -> 0
A32: - Hardware | B32: 0 | C32: 0 | D32: 0 | E32: 0 | F32: 0 | G32: 0 | H32: 299 | I32: 299 | J32: 0 | K32: 0 | L32: 0 | M32: 0 | N32: 0 | O32: 0 | P32: 0 | Q32: 0 | R32: 0 | S32: 0 | T32: 0 | U32: 279 | V32: 0 | W32: 0 | X32: 0 | Y32: 0 | Z32: 0 | AA32: 239 | AB32: 0 | AC32: 0 | AD32: 239 | AE32: 0 | AF32: 0
A33: - Tax | B33: 0 | C33: 0 | D33: 0 | E33: 0 | F33: 0 | G33: 0 | H33: 22.43 | I33: 17.94 | J33: 0 | K33: 0 | L33: 0 | M33: 0 | N33: 0 | O33: 0 | P33: 0 | Q33: 0 | R33: 0 | S33: 0 | T33: 0 | U33: 19.18 | V33: 0 | W33: 0 | X33: 0 | Y33: 0 | Z33: 0 | AA33: 10.1 | AB33: 0 | AC33: 0 | AD33: 14.94 | AE33: 0 | AF33: 0
A34: - Shipping
A35: Digital Marketplaces Revenue | B35: =SUM(B40,B36) -> 0 | C35: =SUM(C40,C36) -> 0 | D35: =SUM(D40,D36) -> 0 | E35: =SUM(E40,E36) -> 0 | F35: =SUM(F40,F36) -> 0 | G35: =SUM(G40,G36) -> 0 | H35: =SUM(H40,H36) -> 0 | I35: =SUM(I40,I36) -> 0 | ... AF35: =SUM(AF40,AF36) -> 0
A36: Rachio | B36: =SUM(B37:B38) -> 0 | C36: =SUM(C37:C38) -> 0 | D36: =SUM(D37:D38) -> 0 | E36: =SUM(E37:E38) -> 0 | F36: =SUM(F37:F38) -> 0 | G36: =SUM(G37:G38) -> 0 | H36: =SUM(H37:H38) -> 0 | I36: =SUM(I37:I38) -> 0 | ... AF36: =SUM(AF37:AF38) -> 0
A37: - Hardware | B37: 0 | C37: 0 | D37: 0 | E37: 0 | F37: 0 | G37: 0 | H37: 0 | I37: 0 | J37: 0 | K37: 0 | L37: 0 | M37: 0 | N37: 0 | O37: 299.99 | P37: 0 | Q37: 0 | R37: 0 | S37: 0 | T37: 0 | U37: 0 | V37: 299.99 | W37: 0 | X37: 0 | Y37: 0 | Z37: 0 | AA37: 0 | AB37: 0 | AC37: 479.98 | AD37: 0 | AE37: 0 | AF37: 0
A38: - Tax | B38: =0.0614*B37 -> 0 | C38: =0.0614*C37 -> 0 | D38: =0.0614*D37 -> 0 | E38: =0.0614*E37 -> 0 | F38: =0.0614*F37 -> 0 | G38: =0.0614*G37 -> 0 | H38: =0.0614*H37 -> 0 | I38: =0.0614*I37 -> 0 | ... AF38: =0.0614*AF37 -> 0
A39: - Shipping
A40: Weatherflow | B40: =SUM(B41:B43) -> 0 | C40: 0 | D40: =SUM(D41:D43) -> 0 | E40: =SUM(E41:E43) -> 0 | F40: =SUM(F41:F43) -> 0 | G40: =SUM(G41:G43) -> 0 | H40: =SUM(H41:H43) -> 0 | I40: =SUM(I41:I43) -> 0 | J40: =SUM(J41:J43) -> 0 | K40: =SUM(K41:K43) -> 0 | ... AF40: =SUM(AF41:AF43) -> 0
A41: - Hardware | B41: 0 | C41: 0 | D41: 0 | E41: 0 | F41: 0 | G41: 0 | H41: 0 | I41: 0 | J41: 0 | K41: 0 | L41: 0 | M41: 0 | N41: 0 | O41: 0 | P41: 0 | Q41: 0 | R41: 0 | S41: 0 | T41: 0 | U41: 0 | V41: 0 | W41: 0 | X41: 0 | Y41: 0 | Z41: 0 | AA41: 0 | AB41: 0 | AC41: 0 | AD41: 0 | AE41: 0 | AF41: 0
A42: - Tax | B42: =0.0614*B41 -> 0 | C42: =0.0614*C41 -> 0 | D42: =0.0614*D41 -> 0 | E42: =0.0614*E41 -> 0 | F42: =0.0614*F41 -> 0 | G42: =0.0614*G41 -> 0 | H42: =0.0614*H41 -> 0 | I42: =0.0614*I41 -> 0 | ... AF42: =0.0614*AF41 -> 0
A43: - Shipping
A44: Costco | B44: =SUM(B45:B47) -> 0 | C44: =SUM(C45:C47) -> 0 | D44: =SUM(D45:D47) -> 0 | E44: =SUM(E45:E47) -> 0 | F44: =SUM(F45:F47) -> 0 | G44: =SUM(G45:G47) -> 0 | H44: =SUM(H45:H47) -> 0 | I44: =SUM(I45:I47) -> 0 | ... AF44: =SUM(AF45:AF47) -> 0
...

Sheet DTC - P&L
A1: OCTOBER | B1: 45566 | C1: 45567 | D1: 45568 | E1: 45569 | F1: 45570 | G1: 45571 | H1: 45572 | I1: 45573 | J1: 45574 | K1: 45575 | L1: 45576 | M1: 45577 | N1: 45578 | O1: 45579 | P1: 45580 | Q1: 45581 | R1: 45582 | S1: 45583 | T1: 45584 | U1: 45585 | V1: 45586 | W1: 45587 | X1: 45588 | Y1: 45589 | Z1: 45590 | AA1: 45591 | AB1: 45592 | AC1: 45593 | AD1: 45594 | AE1: 45595 | AF1: 45596
A2: DAY | B2: TUE | C2: WED | D2: THU | E2: FRI | F2: SAT | G2: SUN | H2: MON | I2: TUE | J2: WED | K2: THU | L2: FRI | M2: SAT | N2: SUN | O2: MON | P2: TUE | Q2: WED | R2: THU | S2: FRI | T2: SAT | U2: SUN | V2: MON | W2: TUE | X2: WED | Y2: THU | Z2: FRI | AA2: SAT | AB2: SUN | AC2: MON | AD2: TUE | AE2: WED | AF2: THU
A3: COMMENT
A4: Orders
A5: Meta | B5: 5 | C5: 7 | D5: 5 | E5: 6 | F5: 11 | G5: 4 | H5: 4 | I5: 7 | J5: 5 | K5: 9 | L5: 5 | M5: 3 | N5: 11 | O5: 8 | P5: 90 | Q5: 38 | R5: 26 | S5: 9 | T5: 10 | U5: 6 | V5: 6 | W5: 2 | X5: 24 | Y5: 21 | Z5: 54 | AA5: 78 | AB5: 82 | AC5: 46 | AD5: 40 | AE5: 57 | AF5: 81 | AG5: =SUM(B5:AF5) -> 760
A6: Google | B6: 5 | C6: 2 | D6: 1 | E6: 6 | F6: 2 | G6: 0 | H6: 3 | I6: 6 | J6: 3 | K6: 3 | L6: 4 | M6: 4 | N6: 2 | O6: 7 | P6: 9 | Q6: 11 | R6: 10 | S6: 8 | T6: 10 | U6: 6 | V6: 3 | W6: 15 | X6: 7 | Y6: 9 | Z6: 18 | AA6: 29 | AB6: 23 | AC6: 15 | AD6: 14 | AE6: 18 | AF6: 16 | AG6: =SUM(B6:AF6) -> 269
A7: TikTok | B7: 0 | C7: 0 | D7: 0 | E7: 0 | F7: 0 | G7: 0 | H7: 0 | I7: 0 | J7: 0 | K7: 0 | L7: 0 | M7: 0 | N7: 0 | O7: 0 | P7: 0 | Q7: 0 | R7: 0 | S7: 0 | T7: 0 | U7: 0 | V7: 0 | W7: 0 | X7: 0 | Y7: 0 | Z7: 0 | AA7: 0 | AB7: 0 | AC7: 0 | AD7: 0 | AE7: 0 | AF7: 0 | AG7: =SUM(B7:AF7) -> 0
A8: Bing | B8: 6 | C8: 2 | D8: 0 | E8: 0 | F8: 4 | G8: 2 | H8: 0 | I8: 0 | J8: 2 | K8: 0 | L8: 0 | M8: 0 | N8: 0 | O8: 0 | P8: 0 | Q8: 2 | R8: 2 | S8: 2 | T8: 14 | U8: 2 | V8: 6 | W8: 2 | X8: 0 | Y8: 0 | Z8: 4 | AA8: 18 | AB8: 8 | AC8: 10 | AD8: 12 | AE8: 12 | AF8: 4 | AG8: =SUM(B8:AF8) -> 114
A9: Email | B9: 0 | C9: 0 | D9: 0 | E9: 0 | F9: 0 | G9: 0 | H9: 0 | I9: 0 | J9: 0 | K9: 0 | L9: 0 | M9: 0 | N9: 0 | O9: 0 | P9: 0 | Q9: 0 | R9: 0 | S9: 0 | T9: 0 | U9: 0 | V9: 0 | W9: 0 | X9: 0 | Y9: 0 | Z9: 0 | AA9: 1 | AB9: 0 | AC9: 0 | AD9: 0 | AE9: 0 | AF9: 0 | AG9: =SUM(B9:AF9) -> 1
A10: Nextdoor | B10: - | C10: - | D10: - | E10: - | F10: - | G10: - | H10: - | I10: - | J10: - | K10: - | L10: - | M10: - | N10: - | O10: - | P10: - | Q10: - | R10: - | S10: - | T10: - | U10: - | V10: - | W10: - | X10: - | Y10: - | Z10: - | AA10: - | AB10: - | AC10: - | AD10: - | AE10: - | AF10: - | AG10: =SUM(B10:AF10) -> 0
A11: Affiliates (Refersion) | B11: - | C11: - | D11: - | E11: - | F11: - | G11: - | H11: - | I11: - | J11: - | K11: - | L11: - | M11: - | N11: - | O11: - | P11: - | Q11: - | R11: - | S11: - | T11: - | U11: - | V11: - | W11: - | X11: - | Y11: - | Z11: - | AA11: - | AB11: - | AC11: - | AD11: - | AE11: - | AF11: - | AG11: =SUM(B11:AF11) -> 0
A12: All | B12: =SUM(B5:B11) -> 16 | C12: =SUM(C5:C11) -> 11 | D12: =SUM(D5:D11) -> 6 | E12: =SUM(E5:E11) -> 12 | F12: =SUM(F5:F11) -> 17 | G12: =SUM(G5:G11) -> 6 | H12: =SUM(H5:H11) -> 7 | I12: =SUM(I5:I11) -> 13 | ... AF12: =SUM(AF5:AF11) -> 101 | AG12: =SUM(B12:AF12) -> 1144
A14: Revenue | B14: 1249.67 | C14: 2160.17 | D14: 1262.27 | E14: 1601.25 | F14: 4263.3 | G14: 770.99 | H14: 1212.42 | I14: 2037.42 | J14: 1855.56 | K14: 2119.42 | L14: 2091.83 | M14: 675.23 | N14: 4148.38 | O14: 1610.67 | P14: 16216.21 | Q14: 6608.06 | R14: 4413.13 | S14: 1355.13 | T14: 2593.47 | U14: 871.98 | V14: 1734.46 | W14: 229.76 | X14: 4385.9 | Y14: 3792 | Z14: 12458.26 | AA14: 21772.43 | AB14: 23101.52 | AC14: 11489.8 | AD14: 11706.73 | AE14: 15443.87 | AF14: 20854.99
A15: Meta | B15: =B14*Summary!B104 -> 1383.1348 | C15: =C14*Summary!C104 -> 2386.3398 | D15: =D14*Summary!D104 -> 1392.9149 | E15: =E14*Summary!E104 -> 1758.1725 | F15: =F14*Summary!F104 -> 4681.9561 | G15: =G14*Summary!G104 -> 845.77603 | H15: =H14*Summary!H104 -> 1330.7522 | I15: =I14*Summary!I104 -> 2237.0872 | ... AF15: =AF14*Summary!AF104 -> 22698.571 | AG15: =SUM(B15:AF15) -> 201979.57
A16: Google | B16: 1741.89 | C16: 625.91 | D16: 322.24 | E16: 1739.95 | F16: 1124.36 | G16: 0 | H16: 410.93 | I16: 1386.71 | J16: 924.96 | K16: 372.88 | L16: 688.81 | M16: 1185.66 | N16: 134.57 | O16: 2032.86 | P16: 2330.5 | Q16: 3728.37 | R16: 2872.01 | S16: 1745.14 | T16: 2768.92 | U16: 1388.49 | V16: 697.74 | W16: 2692.7 | X16: 1548.93 | Y16: 1801.58 | Z16: 4996.37 | AA16: 8857.5 | AB16: 5252.25 | AC16: 3933.33 | AD16: 3910.89 | AE16: 3802.57 | AF16: 4672.67 | AG16: =SUM(B16:AF16) -> 69691.69
A17: TikTok | B17: 0 | C17: 0 | D17: 0 | E17: 0 | F17: 0 | G17: 0 | H17: 0 | I17: 0 | J17: 0 | K17: 0 | L17: 0 | M17: 0 | N17: 0 | O17: 0 | P17: 0 | Q17: 0 | R17: 0 | S17: 0 | T17: 0 | U17: 0 | V17: 0 | W17: 0 | X17: 0 | Y17: 0 | Z17: 0 | AA17: 0 | AB17: 0 | AC17: 0 | AD17: 0 | AE17: 0 | AF17: 0 | AG17: =SUM(B17:AF17) -> 0
A18: Bing | B18: 753 | C18: 251 | D18: 0 | E18: 0 | F18: 502 | G18: 251 | H18: 0 | I18: 0 | J18: 251 | K18: 0 | L18: 0 | M18: 0 | N18: 0 | O18: 0 | P18: 0 | Q18: 251 | R18: 251 | S18: 251 | T18: 1757 | U18: 251 | V18: 753 | W18: 251 | X18: 0 | Y18: 0 | Z18: 502 | AA18: 2259 | AB18: 1004 | AC18: 1255 | AD18: 1506 | AE18: 1506 | AF18: 502 | AG18: =SUM(B18:AF18) -> 14307
A19: Email | B19: 0 | C19: 0 | D19: 0 | E19: 0 | F19: 0 | G19: 0 | H19: 0 | I19: 0 | J19: 0 | K19: 0 | L19: 0 | M19: 0 | N19: 0 | O19: 0 | P19: 0 | Q19: 0 | R19: 0 | S19: 0 | T19: 0 | U19: 0 | V19: 0 | W19: 0 | X19: 0 | Y19: 0 | Z19: 0 | AA19: 94.89 | AB19: 0 | AC19: 0 | AD19: 0 | AE19: 0 | AF19: 0 | AG19: =SUM(B19:AF19) -> 94.89
A20: Nextdoor | B20: - | C20: - | D20: - | E20: - | F20: - | G20: - | H20: - | I20: - | J20: - | K20: - | L20: - | M20: - | N20: - | O20: - | P20: - | Q20: - | R20: - | S20: - | T20: - | U20: - | V20: - | W20: - | X20: - | Y20: - | Z20: - | AA20: - | AB20: - | AC20: - | AD20: - | AE20: - | AF20: -
A21: Affiliates (Refersion) | B21: - | C21: - | D21: - | E21: - | F21: - | G21: - | H21: - | I21: - | J21: - | K21: - | L21: - | M21: - | N21: - | O21: - | P21: - | Q21: - | R21: - | S21: - | T21: - | U21: - | V21: - | W21: - | X21: - | Y21: - | Z21: - | AA21: - | AB21: - | AC21: - | AD21: - | AE21: - | AF21: -
A22: All | B22: =SUM(B15:B21) -> 3878.0248 | C22: =SUM(C15:C21) -> 3263.2498 | D22: =SUM(D15:D21) -> 1715.1549 | E22: =SUM(E15:E21) -> 3498.1225 | F22: =SUM(F15:F21) -> 6308.3161 | G22: =SUM(G15:G21) -> 1096.776 | H22: =SUM(H15:H21) -> 1741.6822 | I22: =SUM(I15:I21) -> 3623.7972 | ... AF22: =SUM(AF15:AF21) -> 27873.241 | AG22: =SUM(B22:AF22) -> 286073.15
A24: Media Cost
A25: Meta | B25: =Summary!B105 -> 1725.8554 | C25: =Summary!C105 -> 1951.7729 | D25: =Summary!D105 -> 1562.1477 | E25: =Summary!E105 -> 1759.4791 | F25: =Summary!F105 -> 1930.5368 | G25: =Summary!G105 -> 2139.6217 | H25: =Summary!H105 -> 1842.3765 | I25: =Summary!I105 -> 1731.546 | ... AF25: =Summary!AF105 -> 33389.783 | AG25: =SUM(B25:AF25) -> 232772.39
A26: Google | B26: =Summary!B108 -> 518.87 | C26: =Summary!C108 -> 512.42 | D26: =Summary!D108 -> 548.46 | E26: =Summary!E108 -> 476.27 | F26: =Summary!F108 -> 289.02 | G26: =Summary!G108 -> 399.65 | H26: =Summary!H108 -> 321.04 | I26: =Summary!I108 -> 296.38 | ... AF26: =Summary!AF108 -> 1171.76 | AG26: =SUM(B26:AF26) -> 29787.92
A27: TikTok | B27: =Summary!B112 -> 0 | C27: =Summary!C112 -> 0 | D27: =Summary!D112 -> 0 | E27: =Summary!E112 -> 0 | F27: =Summary!F112 -> 0 | G27: =Summary!G112 -> 0 | H27: =Summary!H112 -> 0 | I27: =Summary!I112 -> 60.58 | ... AF27: =Summary!AF112 -> 199.72 | AG27: =SUM(B27:AF27) -> 4479.69
A28: Bing | B28: =Summary!B111 -> 45.97 | C28: =Summary!C111 -> 49.3 | D28: =Summary!D111 -> 38.61 | E28: =Summary!E111 -> 39.19 | F28: =Summary!F111 -> 45.61 | G28: =Summary!G111 -> 15.91 | H28: =Summary!H111 -> 31.05 | I28: =Summary!I111 -> 43.16 | ... AF28: =Summary!AF111 -> 38.96 | AG28: =SUM(B28:AF28) -> 1557.75
A29: Nextdoor | B29: - | C29: - | D29: - | E29: - | F29: - | G29: - | H29: - | I29: - | J29: - | K29: - | L29: - | M29: - | N29: - | O29: - | P29: - | Q29: - | R29: - | S29: - | T29: - | U29: - | V29: - | W29: - | X29: - | Y29: - | Z29: - | AA29: - | AB29: - | AC29: - | AD29: - | AE29: - | AF29: - | AG29: =SUM(B29:AF29) -> 0
A30: Affiliate Fee (20%) | B30: - | C30: - | D30: - | E30: - | F30: - | G30: - | H30: - | I30: - | J30: - | K30: - | L30: - | M30: - | N30: - | O30: - | P30: - | Q30: - | R30: - | S30: - | T30: - | U30: - | V30: - | W30: - | X30: - | Y30: - | Z30: - | AA30: - | AB30: - | AC30: - | AD30: - | AE30: - | AF30: - | AG30: =SUM(B30:AF30) -> 0
A31: All | B31: =SUM(B25:B30) -> 2290.6954 | C31: =SUM(C25:C30) -> 2513.4929 | D31: =SUM(D25:D30) -> 2149.2177 | E31: =SUM(E25:E30) -> 2274.9391 | F31: =SUM(F25:F30) -> 2265.1668 | G31: =SUM(G25:G30) -> 2555.1817 | H31: =SUM(H25:H30) -> 2194.4665 | I31: =SUM(I25:I30) -> 2131.666 | ... AF31: =SUM(AF25:AF30) -> 34800.223 | AG31: =SUM(B31:AF31) -> 268597.75
A36: Revenue
A37: Revenue Woocommerce (Platform) | B37: =Summary!B8 -> 9224.84 | C37: =Summary!C8 -> 5831.8 | D37: =Summary!D8 -> 6731.06 | E37: =Summary!E8 -> 5160.16 | F37: =Summary!F8 -> 7525.62 | G37: =Summary!G8 -> 5246.89 | H37: =Summary!H8 -> 5358.3 | I37: =Summary!I8 -> 4961.66 | ... AF37: =Summary!AF8 -> 41251.05 | AG37: =SUM(B37:AF37) -> 522947.38
A38: SUM | B38: =SUM(B37) -> 9224.84 | C38: =SUM(C37) -> 5831.8 | D38: =SUM(D37) -> 6731.06 | E38: =SUM(E37) -> 5160.16 | F38: =SUM(F37) -> 7525.62 | G38: =SUM(G37) -> 5246.89 | H38: =SUM(H37) -> 5358.3 | I38: =SUM(I37) -> 4961.66 | ... AF38: =SUM(AF37) -> 41251.05 | AG38: =SUM(B38:AF38) -> 522947.38
A40: Orders
A41: Orders Woocommerce (Platform) | B41: =Summary!B69 -> 58 | C41: =Summary!C69 -> 36 | D41: =Summary!D69 -> 35 | E41: =Summary!E69 -> 37 | F41: =Summary!F69 -> 41 | G41: =Summary!G69 -> 39 | H41: =Summary!H69 -> 29 | I41: =Summary!I69 -> 27 | ... AF41: =Summary!AF69 -> 163 | AG41: =SUM(B41:AF41) -> 2601
A42: SUM | B42: =SUM(B41) -> 58 | C42: =SUM(C41) -> 36 | D42: =SUM(D41) -> 35 | E42: =SUM(E41) -> 37 | F42: =SUM(F41) -> 41 | G42: =SUM(G41) -> 39 | H42: =SUM(H41) -> 29 | I42: =SUM(I41) -> 27 | ... AF42: =SUM(AF41) -> 163 | AG42: =SUM(B42:AF42) -> 2601
A44: Breakdown
A45: - Hardware | B45: =Summary!B10+Summary!B18 -> 4811 | C45: =Summary!C10+Summary!C18 -> 3876 | D45: =Summary!D10+Summary!D18 -> 4654.3 | E45: =Summary!E10+Summary!E18 -> 3588.1 | F45: =Summary!F10+Summary!F18 -> 5412.2 | G45: =Summary!G10+Summary!G18 -> 3259 | H45: =Summary!H10+Summary!H18 -> 3872.1 | I45: =Summary!I10+Summary!I18 -> 3757.75 | ... AF45: =Summary!AF10+Summary!AF18 -> 29949.65 | AG45: =SUM(B45:AF45) -> 303994.13
A46: - Add-ons | B46: =Summary!B11+Summary!B19 -> 2000.3 | C46: =Summary!C11+Summary!C19 -> 485.9 | D46: =Summary!D11+Summary!D19 -> 519 | E46: =Summary!E11+Summary!E19 -> 243 | F46: =Summary!F11+Summary!F19 -> 409.1 | G46: =Summary!G11+Summary!G19 -> 739.3 | H46: =Summary!H11+Summary!H19 -> 418.9 | I46: =Summary!I11+Summary!I19 -> 235.9 | ... AF46: =Summary!AF11+Summary!AF19 -> 3557.54 | AG46: =SUM(B46:AF46) -> 122143.07
A47: - Merch | B47: =Summary!B12+Summary!B20 -> 0 | C47: =Summary!C12+Summary!C20 -> 0 | D47: =Summary!D12+Summary!D20 -> 0 | E47: =Summary!E12+Summary!E20 -> 0 | F47: =Summary!F12+Summary!F20 -> 0 | G47: =Summary!G12+Summary!G20 -> 0 | H47: =Summary!H12+Summary!H20 -> 0 | I47: =Summary!I12+Summary!I20 -> 0 | ... AF47: =Summary!AF12+Summary!AF20 -> 0 | AG47: =SUM(B47:AF47) -> 539.78
A48: - Seeds | B48: =Summary!B13+Summary!B21 -> 710.7 | C48: =Summary!C13+Summary!C21 -> 439.3 | D48: =Summary!D13+Summary!D21 -> 555.1 | E48: =Summary!E13+Summary!E21 -> 621.8 | F48: =Summary!F13+Summary!F21 -> 672.7 | G48: =Summary!G13+Summary!G21 -> 477.1 | H48: =Summary!H13+Summary!H21 -> 344.6 | I48: =Summary!I13+Summary!I21 -> 256.1 | ... AF48: =Summary!AF13+Summary!AF21 -> 439.5 | AG48: =SUM(B48:AF48) -> 11612.2
...

Sheet DTC US&CA - P&L
A1: OCTOBER | B1: 45566 | C1: 45567 | D1: 45568 | E1: 45569 | F1: 45570 | G1: 45571 | H1: 45572 | I1: 45573 | J1: 45574 | K1: 45575 | L1: 45576 | M1: 45577 | N1: 45578 | O1: 45579 | P1: 45580 | Q1: 45581 | R1: 45582 | S1: 45583 | T1: 45584 | U1: 45585 | V1: 45586 | W1: 45587 | X1: 45588 | Y1: 45589 | Z1: 45590 | AA1: 45591 | AB1: 45592 | AC1: 45593 | AD1: 45594 | AE1: 45595 | AF1: 45596
A2: DAY | B2: TUE | C2: WED | D2: THU | E2: FRI | F2: SAT | G2: SUN | H2: MON | I2: TUE | J2: WED | K2: THU | L2: FRI | M2: SAT | N2: SUN | O2: MON | P2: TUE | Q2: WED | R2: THU | S2: FRI | T2: SAT | U2: SUN | V2: MON | W2: TUE | X2: WED | Y2: THU | Z2: FRI | AA2: SAT | AB2: SUN | AC2: MON | AD2: TUE | AE2: WED | AF2: THU
A4: Revenue
A5: Revenue Woocommerce (Platform) | B5: =Summary!B9 -> 9224.84 | C5: =Summary!C9 -> 5831.8 | D5: =Summary!D9 -> 6731.06 | E5: =Summary!E9 -> 5160.16 | F5: =Summary!F9 -> 7525.62 | G5: =Summary!G9 -> 5246.89 | H5: =Summary!H9 -> 5358.3 | I5: =Summary!I9 -> 4961.66 | ... AF5: =Summary!AF9 -> 34342.97 | AG5: =SUM(B5:AF5) -> 480177.93
A6: SUM | B6: =SUM(B5) -> 9224.84 | C6: =SUM(C5) -> 5831.8 | D6: =SUM(D5) -> 6731.06 | E6: =SUM(E5) -> 5160.16 | F6: =SUM(F5) -> 7525.62 | G6: =SUM(G5) -> 5246.89 | H6: =SUM(H5) -> 5358.3 | I6: =SUM(I5) -> 4961.66 | ... AF6: =SUM(AF5) -> 34342.97 | AG6: =SUM(B6:AF6) -> 480177.93
A8: Orders
A9: Orders Woocommerce (Platform) | B9: =Summary!B70 -> 58 | C9: =Summary!C70 -> 36 | D9: =Summary!D70 -> 35 | E9: =Summary!E70 -> 37 | F9: =Summary!F70 -> 41 | G9: =Summary!G70 -> 39 | H9: =Summary!H70 -> 29 | I9: =Summary!I70 -> 27 | ... AF9: =Summary!AF70 -> 144 | AG9: =SUM(B9:AF9) -> 2464
A10: SUM | B10: =SUM(B9) -> 58 | C10: =SUM(C9) -> 36 | D10: =SUM(D9) -> 35 | E10: =SUM(E9) -> 37 | F10: =SUM(F9) -> 41 | G10: =SUM(G9) -> 39 | H10: =SUM(H9) -> 29 | I10: =SUM(I9) -> 27 | ... AF10: =SUM(AF9) -> 144 | AG10: =SUM(B10:AF10) -> 2464
A12: Breakdown
A13: - Hardware | B13: =Summary!B10 -> 4811 | C13: =Summary!C10 -> 3876 | D13: =Summary!D10 -> 4654.3 | E13: =Summary!E10 -> 3588.1 | F13: =Summary!F10 -> 5412.2 | G13: =Summary!G10 -> 3259 | H13: =Summary!H10 -> 3872.1 | I13: =Summary!I10 -> 3757.75 | ... AF13: =Summary!AF10 -> 25189.9 | AG13: =SUM(B13:AF13) -> 274610.98
A14: - Add-ons | B14: =Summary!B11 -> 2000.3 | C14: =Summary!C11 -> 485.9 | D14: =Summary!D11 -> 519 | E14: =Summary!E11 -> 243 | F14: =Summary!F11 -> 409.1 | G14: =Summary!G11 -> 739.3 | H14: =Summary!H11 -> 418.9 | I14: =Summary!I11 -> 235.9 | ... AF14: =Summary!AF11 -> 3108.63 | AG14: =SUM(B14:AF14) -> 119315.99
A15: - Merch | B15: =Summary!B12 -> 0 | C15: =Summary!C12 -> 0 | D15: =Summary!D12 -> 0 | E15: =Summary!E12 -> 0 | F15: =Summary!F12 -> 0 | G15: =Summary!G12 -> 0 | H15: =Summary!H12 -> 0 | I15: =Summary!I12 -> 0 | ... AF15: =Summary!AF12 -> 0 | AG15: =SUM(B15:AF15) -> 539.78
A16: - Seeds | B16: =Summary!B13 -> 710.7 | C16: =Summary!C13 -> 439.3 | D16: =Summary!D13 -> 555.1 | E16: =Summary!E13 -> 621.8 | F16: =Summary!F13 -> 672.7 | G16: =Summary!G13 -> 477.1 | H16: =Summary!H13 -> 344.6 | I16: =Summary!I13 -> 256.1 | ... AF16: =Summary!AF13 -> 439.5 | AG16: =SUM(B16:AF16) -> 11612.2
A17: - Yearly Pro Subscription | B17: =Summary!B14 -> 479.92 | C17: =Summary!C14 -> 299.95 | D17: =Summary!D14 -> 239.96 | E17: =Summary!E14 -> 0 | F17: =Summary!F14 -> 59.99 | G17: =Summary!G14 -> 59.99 | H17: =Summary!H14 -> 0 | I17: =Summary!I14 -> 59.99 | ... AF17: =Summary!AF14 -> 179.97 | AG17: =SUM(B17:AF17) -> 6238.96
A18: - Taxes | B18: =Summary!B15 -> 557.92 | C18: =Summary!C15 -> 353.65 | D18: =Summary!D15 -> 385.26 | E18: =Summary!E15 -> 305.76 | F18: =Summary!F15 -> 501.63 | G18: =Summary!G15 -> 334.5 | H18: =Summary!H15 -> 350.7 | I18: =Summary!I15 -> 297.71 | ... AF18: =Summary!AF15 -> 2207.84 | AG18: =SUM(B18:AF18) -> 29741.03
A19: - Shipping | B19: =Summary!B16 -> 665 | C19: =Summary!C16 -> 377 | D19: =Summary!D16 -> 377.44 | E19: =Summary!E16 -> 401.5 | F19: =Summary!F16 -> 470 | G19: =Summary!G16 -> 377 | H19: =Summary!H16 -> 372 | I19: =Summary!I16 -> 354.21 | ... AF19: =Summary!AF16 -> 3217.13 | AG19: =SUM(B19:AF19) -> 38118.99
A20: SUM | B20: =SUM(B13:B19) -> 9224.84 | C20: =SUM(C13:C19) -> 5831.8 | D20: =SUM(D13:D19) -> 6731.06 | E20: =SUM(E13:E19) -> 5160.16 | F20: =SUM(F13:F19) -> 7525.62 | G20: =SUM(G13:G19) -> 5246.89 | H20: =SUM(H13:H19) -> 5358.3 | I20: =SUM(I13:I19) -> 4961.66 | ... AF20: =SUM(AF13:AF19) -> 34342.97 | AG20: =SUM(B20:AF20) -> 480177.93
A22: Units Sold (Gross)
A23: SKU 1 - Blue | B23: 16 | C23: 6 | D23: 0 | E23: 0 | F23: 0 | G23: 0 | H23: 0 | I23: 0 | J23: 0 | K23: 0 | L23: 0 | M23: 0 | N23: 0 | O23: 0 | P23: 0 | Q23: 0 | R23: 0 | S23: 0 | T23: 0 | U23: 0 | V23: 0 | W23: 0 | X23: 0 | Y23: 1 | Z23: 2 | AA23: 14 | AB23: 11 | AC23: 5 | AD23: 13 | AE23: 7 | AF23: 17 | AG23: =SUM(B23:AF23) -> 92
A24: SKU 2 - Yellow | B24: 0 | C24: 0 | D24: 0 | E24: 0 | F24: 0 | G24: 0 | H24: 0 | I24: 0 | J24: 0 | K24: 0 | L24: 0 | M24: 0 | N24: 0 | O24: 0 | P24: 0 | Q24: 0 | R24: 0 | S24: 0 | T24: 0 | U24: 0 | V24: 0 | W24: 0 | X24: 0 | Y24: 0 | Z24: 0 | AA24: 0 | AB24: 0 | AC24: 0 | AD24: 0 | AE24: 0 | AF24: 0 | AG24: =SUM(B24:AF24) -> 0
A25: SKU 3 - Blue w/ Solar | B25: 0 | C25: 7 | D25: 16 | E25: 10 | F25: 14 | G25: 10 | H25: 10 | I25: 11 | J25: 16 | K25: 12 | L25: 11 | M25: 9 | N25: 14 | O25: 10 | P25: 3 | Q25: 3 | R25: 8 | S25: 6 | T25: 3 | U25: 4 | V25: 4 | W25: 10 | X25: 14 | Y25: 6 | Z25: 10 | AA25: 28 | AB25: 27 | AC25: 11 | AD25: 17 | AE25: 13 | AF25: 28 | AG25: =SUM(B25:AF25) -> 345
A26: SKU 4 - Yellow w/ Solar | B26: 0 | C26: 0 | D26: 0 | E26: 0 | F26: 0 | G26: 0 | H26: 0 | I26: 0 | J26: 0 | K26: 0 | L26: 0 | M26: 0 | N26: 0 | O26: 0 | P26: 0 | Q26: 0 | R26: 0 | S26: 0 | T26: 0 | U26: 0 | V26: 0 | W26: 0 | X26: 0 | Y26: 0 | Z26: 0 | AA26: 0 | AB26: 0 | AC26: 0 | AD26: 0 | AE26: 0 | AF26: 0 | AG26: =SUM(B26:AF26) -> 0
A27: SKU 1 - Blue PRO | P27: 3 | Q27: 7 | R27: 2 | S27: 2 | T27: 4 | U27: 1 | V27: 3 | W27: 1 | X27: 2 | Y27: 4 | Z27: 6 | AA27: 16 | AB27: 8 | AC27: 8 | AD27: 5 | AE27: 22 | AF27: 10 | AG27: =SUM(B27:AF27) -> 104
A28: SKU 2 - Yellow PRO | P28: 0 | Q28: 0 | R28: 0 | S28: 0 | T28: 0 | U28: 0 | V28: 0 | W28: 0 | X28: 0 | Y28: 0 | Z28: 0 | AA28: 0 | AB28: 0 | AC28: 0 | AD28: 0 | AE28: 0 | AF28: 0 | AG28: =SUM(B28:AF28) -> 0
A29: SKU 3 - Blue w/ Solar PRO | P29: 20 | Q29: 14 | R29: 7 | S29: 8 | T29: 6 | U29: 2 | V29: 9 | W29: 1 | X29: 5 | Y29: 10 | Z29: 34 | AA29: 53 | AB29: 50 | AC29: 28 | AD29: 20 | AE29: 30 | AF29: 37 | AG29: =SUM(B29:AF29) -> 334
A30: SKU 4 - Yellow w/ Solar PRO | P30: 0 | Q30: 0 | R30: 0 | S30: 0 | T30: 0 | U30: 0 | V30: 0 | W30: 0 | X30: 0 | Y30: 0 | Z30: 0 | AA30: 0 | AB30: 0 | AC30: 0 | AD30: 0 | AE30: 0 | AF30: 0 | AG30: =SUM(B30:AF30) -> 0
A31: SUM (SKU 1 - SKU 4) | B31: =SUM(B23:B30) -> 16 | C31: =SUM(C23:C30) -> 13 | D31: =SUM(D23:D30) -> 16 | E31: =SUM(E23:E30) -> 10 | F31: =SUM(F23:F30) -> 14 | G31: =SUM(G23:G30) -> 10 | H31: =SUM(H23:H30) -> 10 | I31: =SUM(I23:I30) -> 11 | ... AF31: =SUM(AF23:AF30) -> 92 | AG31: =SUM(B31:AF31) -> 875
A33: SKU 5 - HBF | B33: 1 | C33: 0 | D33: 0 | E33: 0 | F33: 2 | G33: 1 | H33: 2 | I33: 0 | J33: 2 | K33: 0 | L33: 0 | M33: 0 | N33: 1 | O33: 0 | P33: 5 | Q33: 1 | R33: 0 | S33: 0 | T33: 4 | U33: 1 | V33: 2 | W33: 1 | X33: 2 | Y33: 2 | Z33: 0 | AA33: 9 | AB33: 3 | AC33: 1 | AD33: 2 | AE33: 3 | AF33: 1 | AG33: =SUM(B33:AF33) -> 46
A34: SKU 6 - HBF w/ Solar | B34: 2 | C34: 1 | D34: 0 | E34: 2 | F34: 2 | G34: 0 | H34: 1 | I34: 2 | J34: 1 | K34: 0 | L34: 5 | M34: 6 | N34: 3 | O34: 5 | P34: 9 | Q34: 5 | R34: 5 | S34: 3 | T34: 5 | U34: 1 | V34: 1 | W34: 2 | X34: 9 | Y34: 6 | Z34: 7 | AA34: 10 | AB34: 19 | AC34: 6 | AD34: 9 | AE34: 10 | AF34: 12 | AG34: =SUM(B34:AF34) -> 149
A35: SUM (SKU 5 - SKU 6) | B35: =SUM(B33:B34) -> 3 | C35: =SUM(C33:C34) -> 1 | D35: =SUM(D33:D34) -> 0 | E35: =SUM(E33:E34) -> 2 | F35: =SUM(F33:F34) -> 4 | G35: =SUM(G33:G34) -> 1 | H35: =SUM(H33:H34) -> 3 | I35: =SUM(I33:I34) -> 2 | ... AF35: =SUM(AF33:AF34) -> 13 | AG35: =SUM(B35:AF35) -> 195
A37: Wall Mount | B37: 7 | C37: 1 | D37: 5 | E37: 2 | F37: 2 | G37: 1 | H37: 1 | I37: 2 | J37: 3 | K37: 3 | L37: 2 | M37: 2 | N37: 1 | O37: 3 | P37: 2 | Q37: 2 | R37: 1 | S37: 0 | T37: 0 | U37: 2 | V37: 4 | W37: 4 | X37: 6 | Y37: 3 | Z37: 8 | AA37: 15 | AB37: 21 | AC37: 30 | AD37: 35 | AE37: 60 | AF37: 76 | AG37: =SUM(B37:AF37) -> 304
A38: Suet Ball Holder | B38: 5 | C38: 2 | D38: 0 | E38: 2 | F38: 2 | G38: 0 | H38: 2 | I38: 2 | J38: 6 | K38: 9 | L38: 4 | M38: 5 | N38: 4 | O38: 4 | P38: 6 | Q38: 7 | R38: 5 | S38: 3 | T38: 2 | U38: 4 | V38: 4 | W38: 10 | X38: 6 | Y38: 7 | Z38: 7 | AA38: 17 | AB38: 16 | AC38: 10 | AD38: 8 | AE38: 16 | AF38: 9 | AG38: =SUM(B38:AF38) -> 184
A39: 3-in-1 Nutrition Set - Blue | B39: 3 | C39: 2 | D39: 4 | E39: 0 | F39: 1 | G39: 2 | H39: 3 | I39: 1 | J39: 9 | K39: 4 | L39: 5 | M39: 2 | N39: 4 | O39: 3 | P39: 1 | Q39: 2 | R39: 1 | S39: 0 | T39: 0 | U39: 1 | V39: 1 | W39: 5 | X39: 2 | Y39: 7 | Z39: 4 | AA39: 11 | AB39: 16 | AC39: 9 | AD39: 7 | AE39: 9 | AF39: 15 | AG39: =SUM(B39:AF39) -> 134
A40: 3-in-1 Nutrition Set - Yellow | B40: 0 | C40: 1 | D40: 0 | E40: 0 | F40: 1 | G40: 0 | H40: 0 | I40: 0 | J40: 0 | K40: 0 | L40: 0 | M40: 0 | N40: 0 | O40: 0 | P40: 0 | Q40: 0 | R40: 0 | S40: 0 | T40: 0 | U40: 0 | V40: 0 | W40: 1 | X40: 0 | Y40: 0 | Z40: 0 | AA40: 0 | AB40: 0 | AC40: 0 | AD40: 0 | AE40: 0 | AF40: 0 | AG40: =SUM(B40:AF40) -> 3
A41: Solar Roof Single - Blue | B41: 18 | C41: 5 | D41: 0 | E41: 1 | F41: 2 | G41: 4 | H41: 3 | I41: 2 | J41: 7 | K41: 4 | L41: 6 | M41: 1 | N41: 2 | O41: 1 | P41: 2 | Q41: 3 | R41: 7 | S41: 6 | T41: 3 | U41: 2 | V41: 2 | W41: 5 | X41: 3 | Y41: 3 | Z41: 1 | AA41: 11 | AB41: 1 | AC41: 2 | AD41: 8 | AE41: 7 | AF41: 5 | AG41: =SUM(B41:AF41) -> 127
A42: Solar Roof Single - Yellow | B42: 1 | C42: 0 | D42: 0 | E42: 0 | F42: 0 | G42: 2 | H42: 0 | I42: 0 | J42: 2 | K42: 1 | L42: 0 | M42: 1 | N42: 1 | O42: 1 | P42: 0 | Q42: 0 | R42: 1 | S42: 0 | T42: 1 | U42: 1 | V42: 1 | W42: 1 | X42: 0 | Y42: 2 | Z42: 0 | AA42: 1 | AB42: 1 | AC42: 1 | AD42: 1 | AE42: 2 | AF42: 2 | AG42: =SUM(B42:AF42) -> 24
A43: Perch Extender - Blue | B43: 0 | C43: 0 | D43: 0 | E43: 0 | F43: 0 | G43: 0 | H43: 0 | I43: 0 | J43: 0 | K43: 0 | L43: 1 | M43: 4 | N43: 2 | O43: 3 | P43: 8 | Q43: 6 | R43: 5 | S43: 6 | T43: 6 | U43: 4 | V43: 8 | W43: 11 | X43: 6 | Y43: 10 | Z43: 9 | AA43: 27 | AB43: 22 | AC43: 18 | AD43: 17 | AE43: 24 | AF43: 20 | AG43: =SUM(B43:AF43) -> 217
A44: Perch Extender - Yellow | B44: 3 | C44: 0 | D44: 0 | E44: 2 | F44: 1 | G44: 5 | H44: 0 | I44: 1 | J44: 0 | K44: 3 | L44: 1 | M44: 0 | N44: 1 | O44: 0 | P44: 1 | Q44: 0 | R44: 0 | S44: 1 | T44: 2 | U44: 0 | V44: 0 | W44: 0 | X44: 0 | Y44: 2 | Z44: 0 | AA44: 0 | AB44: 1 | AC44: 2 | AD44: 0 | AE44: 2 | AF44: 0 | AG44: =SUM(B44:AF44) -> 28
A45: Solar Roof (HBF) | B45: 3 | C45: 0 | D45: 1 | E45: 0 | F45: 1 | G45: 0 | H45: 0 | I45: 0 | J45: 0 | K45: 0 | L45: 1 | M45: 1 | N45: 1 | O45: 0 | P45: 1 | Q45: 2 | R45: 2 | S45: 0 | T45: 2 | U45: 0 | V45: 0 | W45: 0 | X45: 0 | Y45: 2 | Z45: 1 | AA45: 1 | AB45: 0 | AC45: 0 | AD45: 2 | AE45: 2 | AF45: 1 | AG45: =SUM(B45:AF45) -> 24
A46: Housing - only (HBF) | B46: 1 | C46: 0 | D46: 1 | E46: 0 | F46: 0 | G46: 0 | H46: 0 | I46: 0 | J46: 0 | K46: 0 | L46: 1 | M46: 0 | N46: 2 | O46: 0 | P46: 2 | Q46: 1 | R46: 2 | S46: 0 | T46: 0 | U46: 0 | V46: 0 | W46: 0 | X46: 0 | Y46: 2 | Z46: 0 | AA46: 0 | AB46: 0 | AC46: 0 | AD46: 1 | AE46: 0 | AF46: 1 | AG46: =SUM(B46:AF46) -> 14
...

Sheet DTC EU - P&L
A1: OCTOBER | B1: 45566 | C1: 45567 | D1: 45568 | E1: 45569 | F1: 45570 | G1: 45571 | H1: 45572 | I1: 45573 | J1: 45574 | K1: 45575 | L1: 45576 | M1: 45577 | N1: 45578 | O1: 45579 | P1: 45580 | Q1: 45581 | R1: 45582 | S1: 45583 | T1: 45584 | U1: 45585 | V1: 45586 | W1: 45587 | X1: 45588 | Y1: 45589 | Z1: 45590 | AA1: 45591 | AB1: 45592 | AC1: 45593 | AD1: 45594 | AE1: 45595 | AF1: 45596
A2: DAY | B2: TUE | C2: WED | D2: THU | E2: FRI | F2: SAT | G2: SUN | H2: MON | I2: TUE | J2: WED | K2: THU | L2: FRI | M2: SAT | N2: SUN | O2: MON | P2: TUE | Q2: WED | R2: THU | S2: FRI | T2: SAT | U2: SUN | V2: MON | W2: TUE | X2: WED | Y2: THU | Z2: FRI | AA2: SAT | AB2: SUN | AC2: MON | AD2: TUE | AE2: WED | AF2: THU
A4: Revenue
A5: Revenue Woocommerce (Platform) | B5: =Summary!B17 -> / | C5: =Summary!C17 -> / | D5: =Summary!D17 -> / | E5: =Summary!E17 -> / | F5: =Summary!F17 -> / | G5: =Summary!G17 -> / | H5: =Summary!H17 -> / | I5: =Summary!I17 -> / | ... AF5: =Summary!AF17 -> 6908.08 | AG5: =SUM(B5:AF5) -> 42769.45
A6: SUM | B6: =SUM(B5) -> 0 | C6: =SUM(C5) -> 0 | D6: =SUM(D5) -> 0 | E6: =SUM(E5) -> 0 | F6: =SUM(F5) -> 0 | G6: =SUM(G5) -> 0 | H6: =SUM(H5) -> 0 | I6: =SUM(I5) -> 0 | ... AF6: =SUM(AF5) -> 6908.08 | AG6: =SUM(B6:AF6) -> 42769.45
A8: Orders
A9: Orders Woocommerce (Platform) | B9: =Summary!B76 | C9: =Summary!C76 | D9: =Summary!D76 | E9: =Summary!E76 | F9: =Summary!F76 | G9: =Summary!G76 | H9: =Summary!H76 | I9: =Summary!I76 | ... AF9: =Summary!AF76 -> 19 | AG9: =SUM(B9:AF9) -> 137
A10: SUM | B10: =SUM(B9) -> 0 | C10: =SUM(C9) -> 0 | D10: =SUM(D9) -> 0 | E10: =SUM(E9) -> 0 | F10: =SUM(F9) -> 0 | G10: =SUM(G9) -> 0 | H10: =SUM(H9) -> 0 | I10: =SUM(I9) -> 0 | ... AF10: =SUM(AF9) -> 19 | AG10: =SUM(B10:AF10) -> 137
A12: Breakdown
A13: - Hardware | K13: 401.68 | Q13: 650.85 | R13: 3662.15 | S13: 2528.17 | T13: 1309.63 | U13: 247.11 | V13: 1023 | W13: 612.23 | X13: 0 | Y13: 878.99 | Z13: 695.73 | AA13: 223.2 | AB13: 1260.15 | AC13: 1606.95 | AD13: 3771.03 | AE13: 3453.22 | AF13: 4005.09 | AG13: =SUM(B13:AF13) -> 26329.18
A14: - Add-ons | K14: 0 | Q14: 266.24 | R14: 226.32 | S14: 191.96 | T14: 112.84 | U14: 0 | V14: 70.78 | W14: 15.57 | X14: 0 | Y14: 225.78 | Z14: 158.11 | AA14: 31.4 | AB14: 153.01 | AC14: 244.59 | AD14: 224.05 | AE14: 274.29 | AF14: 412.45 | AG14: =SUM(B14:AF14) -> 2607.39
A15: - Merch | K15: 0 | Q15: 0 | R15: 0 | S15: 0 | T15: 0 | U15: 0 | V15: 0 | W15: 0 | X15: 0 | Y15: 0 | Z15: 0 | AA15: 0 | AB15: 0 | AC15: 0 | AD15: 0 | AE15: 0 | AF15: 0 | AG15: =SUM(B15:AF15) -> 0
A16: - Seeds | K16: 0 | Q16: 0 | R16: 0 | S16: 0 | T16: 0 | U16: 0 | V16: 0 | W16: 0 | X16: 0 | Y16: 0 | Z16: 0 | AA16: 0 | AB16: 0 | AC16: 0 | AD16: 0 | AE16: 0 | AF16: 0 | AG16: =SUM(B16:AF16) -> 0
A17: - Yearly Pro Subscription | K17: 0 | Q17: 0 | R17: 0 | S17: 0 | T17: 0 | U17: 0 | V17: 0 | W17: 0 | X17: 0 | Y17: 0 | Z17: 0 | AA17: 0 | AB17: 0 | AC17: 0 | AD17: 0 | AE17: 0 | AF17: 0 | AG17: =SUM(B17:AF17) -> 0
A18: - Taxes | K18: 76.32 | Q18: 178.91 | R18: 819.53 | S18: 585.07 | T18: 295.86 | U18: 51.89 | V18: 228.22 | W18: 148.2 | X18: 0 | Y18: 226.43 | Z18: 175.16 | AA18: 62.4 | AB18: 294.84 | AC18: 398.46 | AD18: 842.12 | AE18: 773.49 | AF18: 941.46 | AG18: =SUM(B18:AF18) -> 6098.36
A19: - Shipping | K19: 70 | Q19: 85 | R19: 470 | S19: 325 | T19: 160 | U19: 25 | V19: 135 | W19: 75 | X19: 0 | Y19: 130 | Z19: 85 | AA19: 35 | AB19: 170 | AC19: 185 | AD19: 495 | AE19: 430 | AF19: 500 | AG19: =SUM(B19:AF19) -> 3375
A20: SUM | K20: =sum(K13:K19) -> 548 | Q20: =SUM(Q13:Q19) -> 1181 | R20: =SUM(R13:R19) -> 5178 | S20: =SUM(S13:S19) -> 3630.2 | T20: =SUM(T13:T19) -> 1878.33 | U20: =SUM(U13:U19) -> 324 | V20: =SUM(V13:V19) -> 1457 | W20: =SUM(W13:W19) -> 851 | X20: =SUM(X13:X19) -> 0 | ... AF20: =SUM(AF13:AF19) -> 5859 | AG20: =SUM(B20:AF20) -> 38409.93
A22: Units Sold (Gross)
A23: SKU 1 - Blue | K23: 2 | Q23: 0 | R23: 0 | S23: 0 | T23: 0 | U23: 0 | V23: 1 | W23: 0 | X23: 0 | Y23: 0 | Z23: 0 | AA23: 0 | AB23: 1 | AC23: 0 | AD23: 5 | AE23: 0 | AF23: 4 | AG23: =SUM(B23:AF23) -> 13
A24: SKU 2 - Yellow | K24: 0 | Q24: 0 | R24: 0 | S24: 0 | T24: 0 | U24: 0 | V24: 0 | W24: 0 | X24: 0 | Y24: 0 | Z24: 0 | AA24: 0 | AB24: 0 | AC24: 0 | AD24: 0 | AE24: 0 | AF24: 0 | AG24: =SUM(B24:AF24) -> 0
A25: SKU 3 - Blue w/ Solar | K25: 0 | Q25: 0 | R25: 0 | S25: 0 | T25: 0 | U25: 0 | V25: 0 | W25: 0 | X25: 0 | Y25: 0 | Z25: 0 | AA25: 0 | AB25: 0 | AC25: 0 | AD25: 0 | AE25: 0 | AF25: 0 | AG25: =SUM(B25:AF25) -> 0
A26: SKU 4 - Yellow w/ Solar | K26: 0 | Q26: 0 | R26: 0 | S26: 0 | T26: 0 | U26: 0 | V26: 0 | W26: 0 | X26: 0 | Y26: 0 | Z26: 0 | AA26: 0 | AB26: 0 | AC26: 0 | AD26: 0 | AE26: 0 | AF26: 0 | AG26: =SUM(B26:AF26) -> 0
A27: SKU 1 - Blue PRO | Q27: 3 | R27: 1 | S27: 3 | T27: 1 | U27: 0 | V27: 3 | W27: 2 | X27: 0 | Y27: 0 | Z27: 0 | AA27: 0 | AB27: 1 | AC27: 0 | AD27: 4 | AE27: 5 | AF27: 8 | AG27: =SUM(B27:AF27) -> 31
A28: SKU 2 - Yellow PRO | Q28: 0 | R28: 0 | S28: 0 | T28: 0 | U28: 0 | V28: 0 | W28: 0 | X28: 0 | Y28: 0 | Z28: 0 | AA28: 0 | AB28: 0 | AC28: 0 | AD28: 0 | AE28: 0 | AF28: 0 | AG28: =SUM(B28:AF28) -> 0
A29: SKU 3 - Blue w/ Solar PRO | Q29: 1 | R29: 18 | S29: 10 | T29: 5 | U29: 1 | V29: 1 | W29: 1 | X29: 0 | Y29: 4 | Z29: 3 | AA29: 1 | AB29: 4 | AC29: 7 | AD29: 10 | AE29: 11 | AF29: 10 | AG29: =SUM(B29:AF29) -> 87
A30: SKU 4 - Yellow w/ Solar PRO | Q30: 0 | R30: 0 | S30: 0 | T30: 0 | U30: 0 | V30: 0 | W30: 0 | X30: 0 | Y30: 0 | Z30: 0 | AA30: 0 | AB30: 0 | AC30: 0 | AD30: 0 | AE30: 0 | AF30: 0 | AG30: =SUM(B30:AF30) -> 0
A31: SUM (SKU 1 - SKU 4) | B31: =SUM(B23:B30) -> 0 | C31: =SUM(C23:C30) -> 0 | D31: =SUM(D23:D30) -> 0 | E31: =SUM(E23:E30) -> 0 | F31: =SUM(F23:F30) -> 0 | G31: =SUM(G23:G30) -> 0 | H31: =SUM(H23:H30) -> 0 | I31: =SUM(I23:I30) -> 0 | ... AF31: =SUM(AF23:AF30) -> 22 | AG31: =SUM(B31:AF31) -> 131
A33: SKU 5 - HBF | AG33: =SUM(B33:AF33) -> 0
A34: SKU 6 - HBF w/ Solar | AG34: =SUM(B34:AF34) -> 0
A35: SUM (SKU 5 - SKU 6) | B35: =SUM(B33:B34) -> 0 | C35: =SUM(C33:C34) -> 0 | D35: =SUM(D33:D34) -> 0 | E35: =SUM(E33:E34) -> 0 | F35: =SUM(F33:F34) -> 0 | G35: =SUM(G33:G34) -> 0 | H35: =SUM(H33:H34) -> 0 | I35: =SUM(I33:I34) -> 0 | ... AF35: =SUM(AF33:AF34) -> 0 | AG35: =SUM(B35:AF35) -> 0
A37: Wall Mount | Q37: 1 | R37: 3 | S37: 2 | T37: 0 | U37: 0 | V37: 2 | W37: 0 | X37: 0 | Y37: 3 | Z37: 2 | AA37: 1 | AB37: 1 | AC37: 3 | AD37: 0 | AE37: 3 | AF37: 9 | AG37: =SUM(B37:AF37) -> 30
A38: Suet Ball Holder | Q38: 3 | R38: 1 | S38: 2 | T38: 2 | U38: 0 | V38: 0 | W38: 1 | X38: 0 | Y38: 0 | Z38: 1 | AA38: 1 | AB38: 1 | AC38: 3 | AD38: 3 | AE38: 3 | AF38: 3 | AG38: =SUM(B38:AF38) -> 24
A39: 3-in-1 Nutrition Set - Blue | Q39: 2 | R39: 2 | S39: 2 | T39: 1 | U39: 0 | V39: 0 | W39: 0 | X39: 0 | Y39: 2 | Z39: 2 | AA39: 0 | AB39: 1 | AC39: 3 | AD39: 3 | AE39: 2 | AF39: 5 | AG39: =SUM(B39:AF39) -> 25
A40: 3-in-1 Nutrition Set - Yellow | Q40: 1 | R40: 0 | S40: 0 | T40: 0 | U40: 0 | V40: 0 | W40: 0 | X40: 0 | Y40: 0 | Z40: 0 | AA40: 0 | AB40: 0 | AC40: 0 | AD40: 0 | AE40: 0 | AF40: 0 | AG40: =SUM(B40:AF40) -> 1
A41: Solar Roof Single - Blue | Q41: 0 | R41: 0 | S41: 0 | T41: 0 | U41: 0 | V41: 0 | W41: 0 | X41: 0 | Y41: 1 | Z41: 0 | AA41: 0 | AB41: 0 | AC41: 0 | AD41: 0 | AE41: 0 | AF41: 0 | AG41: =SUM(B41:AF41) -> 1
A42: Solar Roof Single - Yellow | Q42: 0 | R42: 0 | S42: 0 | T42: 0 | U42: 0 | V42: 0 | W42: 0 | X42: 0 | Y42: 0 | Z42: 0 | AA42: 0 | AB42: 1 | AC42: 0 | AD42: 1 | AE42: 1 | AF42: 0 | AG42: =SUM(B42:AF42) -> 3
A43: Perch Extender - Blue | Q43: 3 | R43: 3 | S43: 2 | T43: 2 | U43: 0 | V43: 1 | W43: 0 | X43: 0 | Y43: 2 | Z43: 3 | AA43: 0 | AB43: 2 | AC43: 4 | AD43: 3 | AE43: 3 | AF43: 4 | AG43: =SUM(B43:AF43) -> 32
A44: Perch Extender - Yellow | Q44: 1 | R44: 0 | S44: 0 | T44: 0 | U44: 0 | V44: 0 | W44: 0 | X44: 0 | Y44: 1 | Z44: 0 | AA44: 0 | AB44: 0 | AC44: 0 | AD44: 0 | AE44: 1 | AF44: 0 | AG44: =SUM(B44:AF44) -> 3
A45: Solar Roof (HBF) | AG45: =SUM(B45:AF45) -> 0
A46: Housing - only (HBF) | AG46: =SUM(B46:AF46) -> 0
...

Sheet AMAZON - P&L
A1: OCTOBER | B1: 45566 | C1: 45567 | D1: 45568 | E1: 45569 | F1: 45570 | G1: 45571 | H1: 45572 | I1: 45573 | J1: 45574 | K1: 45575 | L1: 45576 | M1: 45577 | N1: 45578 | O1: 45579 | P1: 45580 | Q1: 45581 | R1: 45582 | S1: 45583 | T1: 45584 | U1: 45585 | V1: 45586 | W1: 45587 | X1: 45588 | Y1: 45589 | Z1: 45590 | AA1: 45591 | AB1: 45592 | AC1: 45593 | AD1: 45594 | AE1: 45595 | AF1: 45596
A2: DAY | B2: TUE | C2: WED | D2: THU | E2: FRI | F2: SAT | G2: SUN | H2: MON | I2: TUE | J2: WED | K2: THU | L2: FRI | M2: SAT | N2: SUN | O2: MON | P2: TUE | Q2: WED | R2: THU | S2: FRI | T2: SAT | U2: SUN | V2: MON | W2: TUE | X2: WED | Y2: THU | Z2: FRI | AA2: SAT | AB2: SUN | AC2: MON | AD2: TUE | AE2: WED | AF2: THU
A3: COMMENT
A4: Orders
A5: Amazon (market place) | B5: =Summary!B82 -> 40 | C5: =Summary!C82 -> 29 | D5: =Summary!D82 -> 28 | E5: =Summary!E82 -> 20 | F5: =Summary!F82 -> 20 | G5: =Summary!G82 -> 25 | H5: =Summary!H82 -> 21 | I5: =Summary!I82 -> 527 | ... AF5: =Summary!AF82 -> 101
A6: All | B6: =SUM(B5) -> 40 | C6: =SUM(C5) -> 29 | D6: =SUM(D5) -> 28 | E6: =SUM(E5) -> 20 | F6: =SUM(F5) -> 20 | G6: =SUM(G5) -> 25 | H6: =SUM(H5) -> 21 | I6: =SUM(I5) -> 527 | ... AF6: =SUM(AF5) -> 101 | AG6: =SUM(B6:AF6) -> 2002
A8: Revenue
A9: Amazon (market place) | B9: =Summary!B25 -> 7953.97 | C9: =Summary!C25 -> 6765.07 | D9: =Summary!D25 -> 7698.8 | E9: =Summary!E25 -> 5011.15 | F9: =Summary!F25 -> 2828.44 | G9: =Summary!G25 -> 5401.75 | H9: =Summary!H25 -> 5446.92 | I9: =Summary!I25 -> 93468.46 | ... AF9: =Summary!AF25 -> 22434.14
A10: All | B10: =SUM(B9) -> 7953.97 | C10: =SUM(C9) -> 6765.07 | D10: =SUM(D9) -> 7698.8 | E10: =SUM(E9) -> 5011.15 | F10: =SUM(F9) -> 2828.44 | G10: =SUM(G9) -> 5401.75 | H10: =SUM(H9) -> 5446.92 | I10: =SUM(I9) -> 93468.46 | ... AF10: =SUM(AF9) -> 22434.14 | AG10: =SUM(B10:AF10) -> 445614.21
A12: Media Cost
A13: Amazon Spend | B13: =Summary!B113 -> 3291 | C13: =Summary!C113 -> 2157 | D13: =Summary!D113 -> 1863 | E13: =Summary!E113 -> 1730 | F13: =Summary!F113 -> 2039 | G13: =Summary!G113 -> 2372 | H13: =Summary!H113 -> 2533 | I13: =Summary!I113 -> 15403 | ... AF13: =Summary!AF113 -> 4081 | AG13: =SUM(B13:AF13) -> 95556
A14: Amazon Platform Fee (15 %) | B14: =B9*'Data - P&L'!$C$48 -> 1193.0955 | C14: =C9*'Data - P&L'!$C$48 -> 1014.7605 | D14: =D9*'Data - P&L'!$C$48 -> 1154.82 | E14: =E9*'Data - P&L'!$C$48 -> 751.6725 | F14: =F9*'Data - P&L'!$C$48 -> 424.266 | G14: =G9*'Data - P&L'!$C$48 -> 810.2625 | H14: =H9*'Data - P&L'!$C$48 -> 817.038 | I14: =I9*'Data - P&L'!$C$48 -> 14020.269 | ... AF14: =AF9*'Data - P&L'!$C$48 -> 3365.121 | AG14: =SUM(B14:AF14) -> 66842.132
A15: All | B15: =SUM(B13:B14) -> 4484.0955 | C15: =SUM(C13:C14) -> 3171.7605 | D15: =SUM(D13:D14) -> 3017.82 | E15: =SUM(E13:E14) -> 2481.6725 | F15: =SUM(F13:F14) -> 2463.266 | G15: =SUM(G13:G14) -> 3182.2625 | H15: =SUM(H13:H14) -> 3350.038 | I15: =SUM(I13:I14) -> 29423.269 | ... AF15: =SUM(AF13:AF14) -> 7446.121 | AG15: =SUM(B15:AF15) -> 162398.13
A19: Amazon Orders
A20: Hardware | B20: =Summary!B26 -> 7233 | C20: =Summary!C26 -> 6157 | D20: =Summary!D26 -> 6993.56 | E20: =Summary!E26 -> 4539.12 | F20: =Summary!F26 -> 2332 | G20: =Summary!G26 -> 4840.56 | H20: =Summary!H26 -> 4898.12 | I20: =Summary!I26 -> 86106.86 | ... AF20: =Summary!AF26 -> 20447.5 | AG20: =SUM(B20:AF20) -> 406430.67
A21: Addons | B21: =Summary!B27 -> 213 | C21: =Summary!C27 -> 164 | D21: =Summary!D27 -> 222 | E21: =Summary!E27 -> 154 | F21: =Summary!F27 -> 309 | G21: =Summary!G27 -> 184 | H21: =Summary!H27 -> 203 | I21: =Summary!I27 -> 1207.2 | ... AF21: =Summary!AF27 -> 522 | AG21: =SUM(B21:AF21) -> 10034.73
A22: Tax | B22: =Summary!B28 -> 503.48 | C22: =Summary!C28 -> 439.58 | D22: =Summary!D28 -> 451.32 | E22: =Summary!E28 -> 296.65 | F22: =Summary!F28 -> 175.96 | G22: =Summary!G28 -> 367.96 | H22: =Summary!H28 -> 327.34 | I22: =Summary!I28 -> 6084.31 | ... AF22: =Summary!AF28 -> 1439.98 | AG22: =SUM(B22:AF22) -> 28648.49
A23: Shipping | B23: =Summary!B29 -> 0 | C23: =Summary!C29 -> 0 | D23: =Summary!D29 -> 27.26 | E23: =Summary!E29 -> 21.04 | F23: =Summary!F29 -> 6.99 | G23: =Summary!G29 -> 0.08 | H23: =Summary!H29 -> 0.16 | I23: =Summary!I29 -> 49.97 | ... AF23: =Summary!AF29 -> 14.89 | AG23: =SUM(B23:AF23) -> 307.41
A24: Gift Wrap Price | B24: =Summary!B30 -> 4.49 | C24: =Summary!C30 -> 4.49 | D24: =Summary!D30 -> 4.66 | E24: =Summary!E30 -> 0.34 | F24: =Summary!F30 -> 4.49 | G24: =Summary!G30 -> 9.15 | H24: =Summary!H30 -> 18.3 | I24: =Summary!I30 -> 20.12 | ... AF24: =Summary!AF30 -> 9.77 | AG24: =SUM(B24:AF24) -> 192.91
A25: All Amazon | B25: =SUM(B20:B24) -> 7953.97 | C25: =SUM(C20:C24) -> 6765.07 | D25: =SUM(D20:D24) -> 7698.8 | E25: =SUM(E20:E24) -> 5011.15 | F25: =SUM(F20:F24) -> 2828.44 | G25: =SUM(G20:G24) -> 5401.75 | H25: =SUM(H20:H24) -> 5446.92 | I25: =SUM(I20:I24) -> 93468.46 | ... AF25: =SUM(AF20:AF24) -> 22434.14 | AG25: =SUM(B25:AF25) -> 445614.21
A27: Units Sold (Gross)
