Workbook
Name zsupermetrics_ru0GDtbZzDLHQOQtJJ6K08MvUDyyp7: #REF!
Name zsupermetrics_DQl8lUbpTRu3fayaJJi7lVfOGKjNU4: 'Data - P&L'!$A$3:$A$4
Name zsupermetrics_BioPyGBzcBsy60UCQmPcTuFReEmghI: 'Data - P&L'!$B$2:$B$3
Name zsupermetrics_refreshAll: SupermetricsQueries!$H$5
Name zsupermetrics_n3GtLgiKpTmd2pYmQNMuq6TPD0qE0b: #REF!
Name zsupermetrics_refreshAllSilent: SupermetricsQueries!$H$6
Name zsupermetrics_Mgms9p0QzysYvrIhnsKACeVBVxfIEO: #REF!
Name zsupermetrics_Mgms9p0QzysYvrIhnsKACeVBVxfIEO: 'Data - P&L'!$A$2:$A$3
Name zsupermetrics_forceRefresh: SupermetricsQueries!$H$4
Name zsupermetrics_wbYMmT0YL9bAN0yhimW0ziPFnia9Dx: #REF!
Name zsupermetrics_iNpyVy90bWCI0yUaFQpxOtzWMa6sW4: #REF!
Name zsupermetrics_xwoIpANxRm908eDp5oKTwQpEI8gvD4: #REF!
Name zsupermetrics_n3GtLgiKpTmd2pYmQNMuq6TPD0qE0b: 'Data - P&L'!$B$4:$B$5
Name rdataslayer_42b112e4e4be4305bb4c1be75e2dd549: 'Data - P&L'!$B$2:$C$3
Name zsupermetrics_9i4W4hgd80uRpQLMeX0eRnESN8gjyv: #REF!
Name zsupermetrics_5bmwtOpHUbSYmDMeuCPkrxaojTprPP: #REF!
Name rdataslayer_3753ddf3234e496aa261974a0222e193: 'Data - P&L'!$H$2:$I$2
Name zsupermetrics_SGBxROnInO9rFyh3H7j2Lldx0Bdc5v: #REF!
Name zsupermetrics_pxuhRTEmIU93xSgKclyxajD0fCZ6rF: #REF!
Name zsupermetrics_ru0GDtbZzDLHQOQtJJ6K08MvUDyyp7: 'Data - P&L'!$B$4:$B$5
Name zsupermetrics_qWp7V908pNEYMtfv8QZvSTeDnBAHOU: 'Data - P&L'!$B$5:$C$13
Name rdataslayer_4a0f150f4f2f4e4f85c890c75b7a1fa4: #REF!
Name zsupermetrics_HgZqhorObHOtZHuyJjpmyYaEPoYntx: #REF!
Name zsupermetrics_YsFuuYtr8vOdNXCCPiFJIO38NP4b2T: #REF!
Name zsupermetrics_DQl8lUbpTRu3fayaJJi7lVfOGKjNU4: #REF!
Name zsupermetrics_YVuzfmsfdurz7Ldl84Rfns8oka6LsS: #REF!
Name zsupermetrics_4VkB7ij7WO0JjKBEgvjB2GHjSy2Egm: #REF!
Name zsupermetrics_9i4W4hgd80uRpQLMeX0eRnESN8gjyv: 'Data - P&L'!$C$13
Name zsupermetrics_lx4cNai7gT6tH4j08ZRkI21Qlpjioi: #REF!
Name rdataslayer_d70e473bcafe40a3aa834ce157fb2ba3: #REF!
Name zsupermetrics_NugLlrQxlKiqhxQae8EFpITBm1pLCj: 'Data - P&L'!$B$6:$C$13
Name zsupermetrics_8xojRjNDjo2jWHGDWjFEhflhyIq3Hq: Summary!$K$8:$K$31
Name zsupermetrics_FEamnpN5FsVYF0RtUTXAwunZ388Tkc: Forecast!$A$113:$C$141
Name rdataslayer_3753ddf3234e496aa261974a0222e193: #REF!
Name zsupermetrics_iNpyVy90bWCI0yUaFQpxOtzWMa6sW4: 'Data - P&L'!$A$2:$A$3
Name rdataslayer_4a0f150f4f2f4e4f85c890c75b7a1fa4: 'Data - P&L'!$D$2:$E$3
Name zsupermetrics_BioPyGBzcBsy60UCQmPcTuFReEmghI: #REF!
Name zsupermetrics_qWp7V908pNEYMtfv8QZvSTeDnBAHOU: #REF!
Name zsupermetrics_8xojRjNDjo2jWHGDWjFEhflhyIq3Hq: #REF!
Name zsupermetrics_wbYMmT0YL9bAN0yhimW0ziPFnia9Dx: 'Data - P&L'!$A$2:$A$3
Name zsupermetrics_4VkB7ij7WO0JjKBEgvjB2GHjSy2Egm: 'Data - P&L'!$B$4:$C$10
Name zsupermetrics_lx4cNai7gT6tH4j08ZRkI21Qlpjioi: 'Data - P&L'!$B$4:$C$13
Name rdataslayer_42b112e4e4be4305bb4c1be75e2dd549: #REF!
Name rdataslayer_adf57e64065742daa5b4161161b1c3ca: #REF!
Name rdataslayer_adf57e64065742daa5b4161161b1c3ca: 'Data - P&L'!$B$4:$D$5
Name zsupermetrics_NugLlrQxlKiqhxQae8EFpITBm1pLCj: #REF!
Name zsupermetrics_xwoIpANxRm908eDp5oKTwQpEI8gvD4: #REF!
Name zsupermetrics_YsFuuYtr8vOdNXCCPiFJIO38NP4b2T: 'Data - P&L'!$B$4:$C$13
Name rdataslayer_d70e473bcafe40a3aa834ce157fb2ba3: 'Data - P&L'!$C$8:$D$9
Name zsupermetrics_HgZqhorObHOtZHuyJjpmyYaEPoYntx: 'Data - P&L'!$B$4:$B$5

Sheet Summary
A1: 45352 | B1: 45352 | C1: 45353 | D1: 45354 | E1: 45355 | F1: 45356 | G1: 45357 | H1: 45358 | I1: 45359 | J1: 45360 | K1: 45361 | L1: 45362 | M1: 45363 | N1: 45364 | O1: 45365 | P1: 45366 | Q1: 45367 | R1: 45368 | S1: 45369 | T1: 45370 | U1: 45371 | V1: 45372 | W1: 45373 | X1: 45374 | Y1: 45375 | Z1: 45376 | AA1: 45377 | AB1: 45378 | AC1: 45379 | AD1: 45380 | AE1: 45381 | AF1: 45382
B2: FRI | C2: SAT | D2: SUN | E2: MON | F2: TUE | G2: WED | H2: THU | I2: FRI | J2: SAT | K2: SUN | L2: MON | M2: TUE | N2: WED | O2: THU | P2: FRI | Q2: SAT | R2: SUN | S2: MON | T2: TUE | U2: WED | V2: THU | W2: FRI | X2: SAT | Y2: SUN | Z2: MON | AA2: TUE | AB2: WED | AC2: THU | AD2: FRI | AE2: SAT | AF2: SUN
A3: Weekend Work
A4: Notes | B4: Women's Day Offer: 30% off (MAP) | T4: A/B Testing - PRO #1
B5: HBF Launch | I5: A/B Testing - Seeds #2 (First bag free & $14.90 Price) | W5: PR - WSJ
B6: A/B Testing - Seeds #1 (First bag free & $26.90 Price) | L6: HBF Price Increase HBF - $289 HBF w/ Solar - $359 | P6: Meta Advertising Stopped | T6: BestBuy - Deal of the day | Z6: Patagonia Checkout Live | AB6: HBF Shipping from June to August
A8: DTC Revenue | B8: 609995.61 | C8: 107937.13 | D8: 92285.37 | E8: 79668.99 | F8: 60001.2 | G8: 52648.98 | H8: 53600.39 | I8: 53298.97 | J8: 65507.46 | K8: 58345.32 | L8: 50106.48 | M8: 34630.63 | N8: 24539.57 | O8: 30839.36 | P8: 23481.39 | Q8: 31403.37 | R8: 24365.3 | S8: 22034.68 | T8: 18596.67 | U8: 19772.38 | V8: 21328.09 | W8: 37898.11 | X8: 30815.28 | Y8: 36859.86 | Z8: 27394.52 | AA8: 19602.23 | AB8: 19436.72 | AC8: 24112.65 | AD8: 17000.55 | AE8: 21890.63 | AF8: 18471.44
A9: - Hardware | B9: 530409.79 | C9: 88002.25 | D9: 75538.45 | E9: 64103.35 | F9: 47621.15 | G9: 40596.8 | H9: 42030.65 | I9: 42613.85 | J9: 50880.3 | K9: 45034.4 | L9: 39398.15 | M9: 26600.8 | N9: 19285.15 | O9: 24270.41 | P9: 17622.85 | Q9: 23523.2 | R9: 18560.9 | S9: 16112 | T9: 14364.78 | U9: 15242.2 | V9: 16516.9 | W9: 29456.48 | X9: 22808.32 | Y9: 27946.78 | Z9: 20592.23 | AA9: 14732.3 | AB9: 14201.2 | AC9: 17713.9 | AD9: 12605.4 | AE9: 16185.45 | AF9: 13825.11
A10: - Add-ons | B10: 9746.98 | C10: 5478.6 | D10: 4169.45 | E10: 4300.95 | F10: 3500.8 | G10: 3624.5 | H10: 3175.6 | I10: 2564.55 | J10: 4382.3 | K10: 4216.4 | L10: 3437.05 | M10: 3063.25 | N10: 1927.25 | O10: 2231.89 | P10: 2344.15 | Q10: 3365.45 | R10: 2138.25 | S10: 2508.2 | T10: 1598.74 | U10: 1579.25 | V10: 1644.9 | W10: 3179.37 | X10: 3285.08 | Y10: 3053.62 | Z10: 2515.22 | AA10: 1697.6 | AB10: 2289.2 | AC10: 2550.1 | AD10: 1848.2 | AE10: 2282.2 | AF10: 1741.99
A11: - Merch | B11: 0 | C11: 0 | D11: 0 | E11: 0 | F11: 0 | G11: 184.94 | H11: 0 | I11: 0 | J11: 0 | K11: 0 | L11: 0 | M11: 0 | N11: 0 | O11: 0 | P11: 0 | Q11: 39.99 | R11: 0 | S11: 0 | T11: 29.99 | U11: 0 | V11: 0 | W11: 0 | X11: 39.99 | Y11: 0 | Z11: 0 | AA11: 0 | AB11: 0 | AC11: 0 | AD11: 0 | AE11: 39.99 | AF11: 0
A12: - Seeds | B12: 434.04 | C12: 310.57 | D12: 225 | E12: 357.48 | F12: 360.4 | G12: 247.87 | H12: 244.33 | I12: 108.94 | J12: 213.14 | K12: 124.07 | L12: 143.4 | M12: 205.81 | N12: 146.4 | O12: 209.87 | P12: 354.81 | Q12: 160.07 | R12: 188.1 | S12: 218.9 | T12: 0 | U12: 182.47 | V12: 225 | W12: 376.6 | X12: 448.4 | Y12: 704.37 | Z12: 476 | AA12: 374.3 | AB12: 368.4 | AC12: 467.1 | AD12: 76.67 | AE12: 180.1 | AF12: 260.1
A13: - Yearly Pro Subscription | S13: 90 | T13: 58.33 | U13: 30 | V13: 0 | W13: 60 | X13: 0 | Y13: 180 | Z13: 90 | AA13: 25 | AB13: 90 | AC13: 180 | AD13: 120 | AE13: 180 | AF13: 120
A14: - Taxes | B14: 37467.8 | C14: 6623.71 | D14: 5640.47 | E14: 4787.21 | F14: 3534.85 | G14: 3154.87 | H14: 3158.81 | I14: 3131.63 | J14: 3951.72 | K14: 3605.45 | L14: 3002.88 | M14: 2120.77 | N14: 1375.77 | O14: 1877.19 | P14: 1399.58 | Q14: 1854.66 | R14: 1538.05 | S14: 1230.58 | T14: 1114.83 | U14: 1166.46 | V14: 1359.29 | W14: 2195.66 | X14: 2008.49 | Y14: 2240.09 | Z14: 1659.07 | AA14: 1266.03 | AB14: 1100.92 | AC14: 1384.55 | AD14: 1050.28 | AE14: 1340.89 | AF14: 1079.24
A15: - Shipping | B15: 31937 | C15: 7522 | D15: 6712 | E15: 6120 | F15: 4984 | G15: 4840 | H15: 4991 | I15: 4880 | J15: 6080 | K15: 5365 | L15: 4125 | M15: 2640 | N15: 1805 | O15: 2250 | P15: 1760 | Q15: 2460 | R15: 1940 | S15: 1875 | T15: 1430 | U15: 1572 | V15: 1582 | W15: 2630 | X15: 2225 | Y15: 2735 | Z15: 2062 | AA15: 1507 | AB15: 1387 | AC15: 1817 | AD15: 1300 | AE15: 1682 | AF15: 1445
A16: Amazon Revenue | B16: =B17+B18+B19+B20+B21 -> 19348.49 | C16: =C17+C18+C19+C20+C21 -> 22322.39 | D16: =D17+D18+D19+D20+D21 -> 16109.48 | E16: =E17+E18+E19+E20+E21 -> 9416.58 | F16: =F17+F18+F19+F20+F21 -> 6365.8 | G16: =G17+G18+G19+G20+G21 -> 11506.81 | H16: =H17+H18+H19+H20+H21 -> 17570.37 | I16: =I17+I18+I19+I20+I21 -> 16642.54 | ... AF16: =AF17+AF18+AF19+AF20+AF21 -> 4451.22
A17: - Hardware | B17: 16689.8 | C17: 18894.12 | D17: 13167.68 | E17: 7392.24 | F17: 4950.56 | G17: 9849 | H17: 15173.56 | I17: 14651.68 | J17: 17400.12 | K17: 19281.12 | L17: 7612.12 | M17: 7593 | N17: 8849 | O17: 10045 | P17: 11655.12 | Q17: 9624.56 | R17: 11836.56 | S17: 5440 | T17: 10463 | U17: 12247.24 | V17: 9084.56 | W17: 7771 | X17: 8962.12 | Y17: 9145 | Z17: 6631.56 | AA17: 7647.12 | AB17: 6745.24 | AC17: 6091.12 | AD17: 5679 | AE17: 5082 | AF17: 2989
A18: - Add-ons | B18: 1424.56 | C18: 1915.56 | D18: 1792.68 | E18: 1421.56 | F18: 1009 | G18: 906 | H18: 1285.56 | I18: 897 | J18: 2501.12 | K18: 1509 | L18: 1082.12 | M18: 966 | N18: 954 | O18: 999.68 | P18: 819 | Q18: 1898.24 | R18: 1582.68 | S18: 974 | T18: 850 | U18: 1110 | V18: 1075.12 | W18: 889 | X18: 1348.56 | Y18: 1547 | Z18: 1146.56 | AA18: 929 | AB18: 724 | AC18: 969.12 | AD18: 889 | AE18: 2055 | AF18: 1130
A19: - Tax | B19: 1193.49 | C19: 1464.05 | D19: 1131.65 | E19: 586.52 | F19: 392.02 | G19: 741.83 | H19: 1064.89 | I19: 1027.39 | J19: 1409.3 | K19: 1407.52 | L19: 554.12 | M19: 553.37 | N19: 641.76 | O19: 827.5 | P19: 790.79 | Q19: 881.92 | R19: 879.12 | S19: 450.62 | T19: 777.17 | U19: 818.35 | V19: 740.37 | W19: 598.37 | X19: 683.95 | Y19: 760.41 | Z19: 571.28 | AA19: 579.31 | AB19: 510.61 | AC19: 493.53 | AD19: 479.38 | AE19: 491.05 | AF19: 320.74
A20: - Shipping | B20: 26.65 | C20: 21.21 | D20: 7.47 | E20: 10.42 | F20: 0.08 | G20: 0 | H20: 29.06 | I20: 51.99 | J20: 10.3 | K20: 56.22 | L20: 0.32 | M20: 12.99 | N20: 0 | O20: 13.41 | P20: 0.16 | Q20: 0.4 | R20: 0.32 | S20: 0 | T20: 0 | U20: 44.42 | V20: 0.24 | W20: 0 | X20: 0.24 | Y20: 31.84 | Z20: 0.95 | AA20: 18.69 | AB20: 7.31 | AC20: 7.31 | AD20: 0 | AE20: 37.42 | AF20: 6.99
A21: - Gift Wrap | B21: 13.99 | C21: 27.45 | D21: 10 | E21: 5.84 | F21: 14.14 | G21: 9.98 | H21: 17.3 | I21: 14.48 | J21: 22.63 | K21: 4.83 | L21: 5.17 | M21: 4.99 | N21: 8.98 | O21: 9.49 | P21: 4.83 | Q21: 9.83 | R21: 19.14 | S21: 0 | T21: 17.96 | U21: 14.65 | V21: 5.5 | W21: 8.48 | X21: 14.48 | Y21: 29.43 | Z21: 0.34 | AA21: 9.32 | AB21: 5.17 | AC21: 9.66 | AD21: 13.47 | AE21: 0 | AF21: 4.49
A22: Digital Marketplaces Revenue | B22: =SUM(B27,B23) -> 403.31077 | C22: =SUM(C27,C23) -> 222.88339 | D22: =SUM(D27,D23) -> 0 | E22: =SUM(E27,E23) -> 0 | F22: =SUM(F27,F23) -> 0 | G22: =SUM(G27,G23) -> 222.88339 | H22: =SUM(H27,H23) -> 317.3586 | I22: =SUM(I27,I23) -> 445.76677 | ... AF22: =SUM(AF27,AF23) -> 0
A23: Rachio | B23: =SUM(B24:B25) -> 403.31077 | C23: =SUM(C24:C25) -> 222.88339 | D23: =SUM(D24:D25) -> 0 | E23: =SUM(E24:E25) -> 0 | F23: =SUM(F24:F25) -> 0 | G23: =SUM(G24:G25) -> 222.88339 | H23: =SUM(H24:H25) -> 0 | I23: =SUM(I24:I25) -> 445.76677 | ... AF23: =SUM(AF24:AF25) -> 0
A24: - Hardware | B24: 379.98 | C24: 209.99 | D24: 0 | E24: 0 | F24: 0 | G24: 209.99 | H24: 0 | I24: 419.98 | J24: 0 | K24: 1009.95 | L24: 209.99 | M24: 209.99 | N24: 0 | O24: 0 | P24: 0 | Q24: 0 | R24: 0 | S24: 0 | T24: 0 | U24: 0 | V24: 0 | W24: 0 | X24: 0 | Y24: 0 | Z24: 0 | AA24: 0 | AB24: 0 | AC24: 299.99 | AD24: 0 | AE24: 0 | AF24: 0
A25: - Tax | B25: =0.0614*B24 -> 23.330772 | C25: =0.0614*C24 -> 12.893386 | D25: =0.0614*D24 -> 0 | E25: =0.0614*E24 -> 0 | F25: =0.0614*F24 -> 0 | G25: =0.0614*G24 -> 12.893386 | H25: =0.0614*H24 -> 0 | I25: =0.0614*I24 -> 25.786772 | ... AF25: =0.0614*AF24 -> 0
A26: - Shipping
A27: Weatherflow | B27: =SUM(B28:B29) -> 0 | C27: =SUM(C28:C29) -> 0 | D27: =SUM(D28:D29) -> 0 | E27: =SUM(E28:E29) -> 0 | F27: =SUM(F28:F29) -> 0 | G27: =SUM(G28:G29) -> 0 | H27: =SUM(H28:H29) -> 317.3586 | I27: =SUM(I28:I29) -> 0 | ... AF27: =SUM(AF28:AF29) -> 0
A28: - Hardware | B28: 0 | C28: 0 | D28: 0 | E28: 0 | F28: 0 | G28: 0 | H28: 299 | I28: 0 | J28: 0 | K28: 0 | L28: 299 | M28: 0 | N28: 0 | O28: 0 | P28: 0 | Q28: 0 | R28: 0 | S28: 0 | T28: 0 | U28: 0 | V28: 0 | W28: 0 | X28: 0 | Y28: 0 | Z28: 478 | AA28: 0 | AB28: 0 | AC28: 0 | AD28: 0 | AE28: 0 | AF28: 0
A29: - Tax | B29: =0.0614*B28 -> 0 | C29: =0.0614*C28 -> 0 | D29: =0.0614*D28 -> 0 | E29: =0.0614*E28 -> 0 | F29: =0.0614*F28 -> 0 | G29: =0.0614*G28 -> 0 | H29: =0.0614*H28 -> 18.3586 | I29: =0.0614*I28 -> 0 | ... AF29: =0.0614*AF28 -> 0
A30: - Shipping
A31: Total Revenue | B31: =SUM(B8+B16+B22) -> 629747.41 | C31: =SUM(C8+C16+C22) -> 130482.4 | D31: =SUM(D8+D16+D22) -> 108394.85 | E31: =SUM(E8+E16+E22) -> 89085.57 | F31: =SUM(F8+F16+F22) -> 66367 | G31: =SUM(G8+G16+G22) -> 64378.673 | H31: =SUM(H8+H16+H22) -> 71488.119 | I31: =SUM(I8+I16+I22) -> 70387.277 | ... AF31: =SUM(AF8+AF16+AF22) -> 22922.66
A33: B2B Revenue
A34: Best Buy | B34: =iferror(sum(B35:B37),"") -> 3992.9868 | C34: =sum(C35:C37) -> 4880.3172 | D34: =sum(D35:D37) -> 0 | E34: =sum(E35:E37) -> 665.4978 | F34: =sum(F35:F37) -> 4658.4846 | G34: =sum(G35:G37) -> 3105.6564 | H34: =sum(H35:H37) -> 2440.1586 | I34: =sum(I35:I37) -> 2440.1586 | J34: =sum(J35:J37) -> 1996.4934 | ... AF34: =sum(AF35:AF37) -> 0
A35: - Hardware | B35: 3762 | C35: 4598 | D35: 0 | E35: 627 | F35: 4389 | G35: 2926 | H35: 2299 | I35: 2299 | J35: 1881 | K35: 0 | L35: 1254 | M35: 5382 | N35: 2990 | O35: 1196 | P35: 2093 | Q35: 1196 | R35: 0 | S35: 2392 | T35: 17940 | U35: 16744 | V35: 3289 | W35: 5382 | X35: 5681 | Y35: 0 | Z35: 2990 | AA35: 8073 | AB35: 6877 | AC35: 7176 | AD35: 11362 | AE35: 11661 | AF35: 0
A36: - Tax | B36: =B35*'Data - P&L'!$U$3 -> 230.9868 | C36: =C35*'Data - P&L'!$U$3 -> 282.3172 | D36: =D35*'Data - P&L'!$U$3 -> 0 | E36: =E35*'Data - P&L'!$U$3 -> 38.4978 | F36: =F35*'Data - P&L'!$U$3 -> 269.4846 | G36: =G35*'Data - P&L'!$U$3 -> 179.6564 | H36: =H35*'Data - P&L'!$U$3 -> 141.1586 | I36: =I35*'Data - P&L'!$U$3 -> 141.1586 | ... AF36: =AF35*'Data - P&L'!$U$3 -> 0
A37: - Shipping
A38: Target | B38: =sum(B39:B41) -> 361.9374 | C38: =sum(C39:C41) -> 1826.6694 | D38: =sum(D39:D41) -> 496.7352 | E38: =sum(E39:E41) -> 254.736 | F38: =sum(F39:F41) -> 254.736 | G38: =sum(G39:G41) -> 241.9992 | H38: =sum(H39:H41) -> 254.736 | I38: =sum(I39:I41) -> 507.3492 | ... AF38: =sum(AF39:AF41) -> 0
A39: - Hardware | B39: 341 | C39: 1721 | D39: 468 | E39: 240 | F39: 240 | G39: 228 | H39: 240 | I39: 478 | J39: 899 | K39: 468 | L39: 240 | M39: 641 | N39: 468 | O39: 718 | P39: 432 | Q39: 1401 | R39: 240 | S39: 472 | T39: 0 | U39: 645 | V39: 801 | W39: 2221 | X39: 3222 | Y39: 2571 | Z39: 2057 | AA39: 2685 | AB39: 2284 | AC39: 1853 | AD39: 2140 | AE39: 2716 | AF39: 0
A40: - Tax | B40: =B39*'Data - P&L'!$U$3 -> 20.9374 | C40: =C39*'Data - P&L'!$U$3 -> 105.6694 | D40: =D39*'Data - P&L'!$U$3 -> 28.7352 | E40: =E39*'Data - P&L'!$U$3 -> 14.736 | F40: =F39*'Data - P&L'!$U$3 -> 14.736 | G40: =G39*'Data - P&L'!$U$3 -> 13.9992 | H40: =H39*'Data - P&L'!$U$3 -> 14.736 | I40: =I39*'Data - P&L'!$U$3 -> 29.3492 | ... AF40: =AF39*'Data - P&L'!$U$3 -> 0
A41: - Shipping
A42: Total Revenue | B42: =B34+B38 -> 4354.9242 | C42: =C34+C38 -> 6706.9866 | D42: =D34+D38 -> 496.7352 | E42: =E34+E38 -> 920.2338 | F42: =F34+F38 -> 4913.2206 | G42: =G34+G38 -> 3347.6556 | H42: =H34+H38 -> 2694.8946 | I42: =I34+I38 -> 2947.5078 | ... AF42: =AF34+AF38 -> 0
...

Sheet DTC - P&L
A1: MARCH | B1: 45352 | C1: 45353 | D1: 45354 | E1: 45355 | F1: 45356 | G1: 45357 | H1: 45358 | I1: 45359 | J1: 45360 | K1: 45361 | L1: 45362 | M1: 45363 | N1: 45364 | O1: 45365 | P1: 45366 | Q1: 45367 | R1: 45368 | S1: 45369 | T1: 45370 | U1: 45371 | V1: 45372 | W1: 45373 | X1: 45374 | Y1: 45375 | Z1: 45376 | AA1: 45377 | AB1: 45378 | AC1: 45379 | AD1: 45380 | AE1: 45381 | AF1: 45382
A2: DAY | B2: FRI | C2: SAT | D2: SUN | E2: MON | F2: TUE | G2: WED | H2: THU | I2: FRI | J2: SAT | K2: SUN | L2: MON | M2: TUE | N2: WED | O2: THU | P2: FRI | Q2: SAT | R2: SUN | S2: MON | T2: TUE | U2: WED | V2: THU | W2: FRI | X2: SAT | Y2: SUN | Z2: MON | AA2: TUE | AB2: WED | AC2: THU | AD2: FRI | AE2: SAT | AF2: SUN
A3: COMMENT
A4: Orders
A5: Meta | B5: 458 | C5: 137 | D5: 146 | E5: 114 | F5: 84 | G5: 70 | H5: 69 | I5: 87 | J5: 86 | K5: 83 | L5: 60 | M5: 39 | N5: 27 | O5: 35 | P5: 18 | Q5: 4 | R5: 5 | S5: 3 | T5: 2 | U5: 3 | V5: 0 | W5: 0 | X5: 0 | Y5: 0 | Z5: 0 | AA5: 0 | AB5: 0 | AC5: 0 | AD5: 0 | AE5: 0 | AF5: 0 | AG5: =SUM(B5:AF5) -> 1530
A6: Google | B6: 137 | C6: 102 | D6: 89 | E6: 79 | F6: 84 | G6: 61 | H6: 49 | I6: 55 | J6: 87 | K6: 76 | L6: 50 | M6: 25 | N6: 22 | O6: 27 | P6: 38 | Q6: 40 | R6: 25 | S6: 31 | T6: 22 | U6: 26 | V6: 23 | W6: 26 | X6: 39 | Y6: 46 | Z6: 37 | AA6: 25 | AB6: 21 | AC6: 27 | AD6: 22 | AE6: 35 | AF6: 28 | AG6: =SUM(B6:AF6) -> 1454
A7: TikTok | B7: 0 | C7: 0 | D7: 0 | E7: 0 | F7: 0 | G7: 0 | H7: 0 | I7: 0 | J7: 0 | K7: 1 | L7: 2 | M7: 2 | N7: 0 | O7: 2 | P7: 0 | Q7: 0 | R7: 2 | S7: 1 | T7: 0 | U7: 1 | V7: 0 | W7: 1 | X7: 0 | Y7: 0 | Z7: 0 | AA7: 0 | AB7: 0 | AC7: 1 | AD7: 0 | AE7: 0 | AF7: 1 | AG7: =SUM(B7:AF7) -> 14
A8: Bing | B8: 40 | C8: 12 | D8: 30 | E8: 24 | F8: 14 | G8: 10 | H8: 4 | I8: 6 | J8: 20 | K8: 4 | L8: 4 | M8: 10 | N8: 8 | O8: 4 | P8: 2 | Q8: 8 | R8: 10 | S8: 0 | T8: 2 | U8: 8 | V8: 14 | W8: 20 | X8: 10 | Y8: 10 | Z8: 6 | AA8: 6 | AB8: 0 | AC8: 6 | AD8: 12 | AE8: 8 | AF8: 10 | AG8: =SUM(B8:AF8) -> 322
A9: Email | B9: 396 | C9: 72 | D9: 25 | E9: 23 | F9: 20 | G9: 12 | H9: 13 | I9: 9 | J9: 4 | K9: 0 | L9: 0 | M9: 1 | N9: 4 | O9: 2 | P9: 1 | Q9: 4 | R9: 1 | S9: 1 | T9: 0 | U9: 3 | V9: 0 | W9: 1 | X9: 4 | Y9: 2 | Z9: 1 | AA9: 0 | AB9: 2 | AC9: 2 | AD9: 2 | AE9: 2 | AF9: 1 | AG9: =SUM(B9:AF9) -> 608
A10: Nextdoor | B10: - | C10: - | D10: - | E10: - | F10: - | G10: - | H10: - | I10: - | J10: - | K10: - | L10: - | M10: - | N10: - | O10: - | P10: - | Q10: - | R10: - | S10: - | T10: - | U10: - | V10: - | W10: - | X10: - | Y10: - | Z10: - | AA10: - | AB10: - | AC10: - | AD10: - | AE10: - | AF10: - | AG10: =SUM(B10:AF10) -> 0
A11: Affiliates (Refersion) | B11: - | C11: - | D11: - | E11: - | F11: - | G11: - | H11: - | I11: - | J11: - | K11: - | L11: - | M11: - | N11: - | O11: - | P11: - | Q11: - | R11: - | S11: - | T11: - | U11: - | V11: - | W11: - | X11: - | Y11: - | Z11: - | AA11: - | AB11: - | AC11: - | AD11: - | AE11: - | AF11: - | AG11: =SUM(B11:AF11) -> 0
A12: All | B12: =SUM(B5:B11) -> 1031 | C12: =SUM(C5:C11) -> 323 | D12: =SUM(D5:D11) -> 290 | E12: =SUM(E5:E11) -> 240 | F12: =SUM(F5:F11) -> 202 | G12: =SUM(G5:G11) -> 153 | H12: =SUM(H5:H11) -> 135 | I12: =SUM(I5:I11) -> 157 | ... AF12: =SUM(AF5:AF11) -> 40 | AG12: =SUM(B12:AF12) -> 3928
A14: Revenue | B14: 130631.13 | C14: 31702.33 | D14: 36663.08 | E14: 26831.34 | F14: 18566.01 | G14: 15077.35 | H14: 16977.97 | I14: 22535.23 | J14: 19812.94 | K14: 21641.23 | L14: 16677.16 | M14: 8900.25 | N14: 7417.65 | O14: 8918.9 | P14: 5019.56 | Q14: 363.27 | R14: 1698.83 | S14: 790.14 | T14: 335.68 | U14: 337.11 | V14: 0 | W14: 0 | X14: 0 | Y14: 0 | Z14: 0 | AA14: 0 | AB14: 0 | AC14: 0 | AD14: 0 | AE14: 0 | AF14: 0
A15: Meta | B15: =B14*Summary!B76 -> 141682.52 | C15: =C14*Summary!C76 -> 34384.347 | D15: =D14*Summary!D76 -> 39753.778 | E15: =E14*Summary!E76 -> 29125.42 | F15: =F14*Summary!F76 -> 20153.404 | G15: =G14*Summary!G76 -> 16384.556 | H15: =H14*Summary!H76 -> 18590.877 | I15: =I14*Summary!I76 -> 24662.556 | ... AF15: =AF14*Summary!AF76 -> 0 | AG15: =SUM(B15:AF15) -> 425192.69
A16: Google | B16: 36240.17 | C16: 24265.81 | D16: 21831.79 | E16: 19070.15 | F16: 18701.99 | G16: 13220.28 | H16: 11961.73 | I16: 13976.93 | J16: 20899.82 | K16: 17653.64 | L16: 15254.03 | M16: 6773.81 | N16: 6500.22 | O16: 8224.43 | P16: 11274.08 | Q16: 11229.61 | R16: 7499.54 | S16: 9101.73 | T16: 7088.92 | U16: 6561.49 | V16: 6688.27 | W16: 7440.97 | X16: 12014.82 | Y16: 13776.81 | Z16: 10611.92 | AA16: 6477.18 | AB16: 6083.17 | AC16: 7892.69 | AD16: 6440.17 | AE16: 9942.06 | AF16: 8835.98 | AG16: =SUM(B16:AF16) -> 383534.21
A17: TikTok | B17: 0 | C17: 0 | D17: 0 | E17: 0 | F17: 0 | G17: 0 | H17: 0 | I17: 0 | J17: 0 | K17: 188 | L17: 697.12 | M17: 357 | N17: 0 | O17: 691.82 | P17: 0 | Q17: 0 | R17: 399.11 | S17: 292.6 | T17: 0 | U17: 27.44 | V17: 0 | W17: 51.19 | X17: 0 | Y17: 0 | Z17: 0 | AA17: 0 | AB17: 0 | AC17: 331.9 | AD17: 0 | AE17: 0 | AF17: 268 | AG17: =SUM(B17:AF17) -> 3304.18
A18: Bing | B18: 5020 | C18: 1506 | D18: 3765 | E18: 3012 | F18: 1757 | G18: 1255 | H18: 502 | I18: 753 | J18: 2510 | K18: 502 | L18: 502 | M18: 1255 | N18: 1004 | O18: 502 | P18: 251 | Q18: 1004 | R18: 1255 | S18: 0 | T18: 251 | U18: 1004 | V18: 1757 | W18: 2510 | X18: 1255 | Y18: 1255 | Z18: 753 | AA18: 753 | AB18: 0 | AC18: 753 | AD18: 1506 | AE18: 1004 | AF18: 1255 | AG18: =SUM(B18:AF18) -> 40411
A19: Email | B19: 127383.34 | C19: 22901.17 | D19: 7704.1 | E19: 6917.28 | F19: 5509.62 | G19: 3963.62 | H19: 4184.23 | I19: 2186.63 | J19: 909.46 | K19: 0 | L19: 0 | M19: 112.25 | N19: 1409.11 | O19: 449.88 | P19: 411.85 | Q19: 1484.01 | R19: 294.34 | S19: 286 | T19: 0 | U19: 1241.79 | V19: 0 | W19: 354.1 | X19: 1488.71 | Y19: 512.85 | Z19: 354.04 | AA19: 0 | AB19: 425.64 | AC19: 106.51 | AD19: 713.03 | AE19: 118.98 | AF19: 41.48 | AG19: =SUM(B19:AF19) -> 191464.02
A20: Nextdoor | B20: - | C20: - | D20: - | E20: - | F20: - | G20: - | H20: - | I20: - | J20: - | K20: - | L20: - | M20: - | N20: - | O20: - | P20: - | Q20: - | R20: - | S20: - | T20: - | U20: - | V20: - | W20: - | X20: - | Y20: - | Z20: - | AA20: - | AB20: - | AC20: - | AD20: - | AE20: - | AF20: - | AG20: =SUM(B20:AF20) -> 0
A21: Affiliates (Refersion) | B21: - | C21: - | D21: - | E21: - | F21: - | G21: - | H21: - | I21: - | J21: - | K21: - | L21: - | M21: - | N21: - | O21: - | P21: - | Q21: - | R21: - | S21: - | T21: - | U21: - | V21: - | W21: - | X21: - | Y21: - | Z21: - | AA21: - | AB21: - | AC21: - | AD21: - | AE21: - | AF21: - | AG21: =SUM(B21:AF21) -> 0
A22: All | B22: =SUM(B15:B21) -> 310326.03 | C22: =SUM(C15:C21) -> 83057.327 | D22: =SUM(D15:D21) -> 73054.668 | E22: =SUM(E15:E21) -> 58124.85 | F22: =SUM(F15:F21) -> 46122.014 | G22: =SUM(G15:G21) -> 34823.456 | H22: =SUM(H15:H21) -> 35238.837 | I22: =SUM(I15:I21) -> 41579.116 | ... AF22: =SUM(AF15:AF21) -> 10400.46 | AG22: =SUM(B22:AF22) -> 1043906.1
A24: Media Cost
A25: Meta | B25: =Summary!B77 -> 15647.524 | C25: =Summary!C77 -> 15047.035 | D25: =Summary!D77 -> 14628.606 | E25: =Summary!E77 -> 12012.697 | F25: =Summary!F77 -> 9720.1966 | G25: =Summary!G77 -> 8252.5085 | H25: =Summary!H77 -> 8148.99 | I25: =Summary!I77 -> 8881.4609 | ... AF25: =Summary!AF77 -> 0 | AG25: =SUM(B25:AF25) -> 138514.7
A26: Google | B26: =Summary!B78 -> 2913.47 | C26: =Summary!C78 -> 3307.42 | D26: =Summary!D78 -> 3859.77 | E26: =Summary!E78 -> 3297.42 | F26: =Summary!F78 -> 2896.56 | G26: =Summary!G78 -> 3013.01 | H26: =Summary!H78 -> 2993.23 | I26: =Summary!I78 -> 3067.46 | ... AF26: =Summary!AF78 -> 1712.75 | AG26: =SUM(B26:AF26) -> 78590.49
A27: TikTok | B27: =Summary!B80 -> 0 | C27: =Summary!C80 -> 0 | D27: =Summary!D80 -> 0 | E27: =Summary!E80 -> 0 | F27: =Summary!F80 -> 0 | G27: =Summary!G80 -> 0 | H27: =Summary!H80 -> 0 | I27: =Summary!I80 -> 62.08 | ... O27: =Summary!O80 -> 500.22 | P27: =Summary!P81 -> 2177.64 | Q27: =Summary!Q80 -> 493.61 | R27: =Summary!R80 -> 500.87 | S27: =Summary!S80 -> 490.48 | T27: =Summary!T80 -> 510.24 | U27: =Summary!U80 -> 501.34 | V27: =Summary!V80 -> 407.09 | W27: =Summary!W80 -> 527.79 | X27: =Summary!X80 -> 596.27 | ... AF27: =Summary!AF80 -> 251.21 | AG27: =SUM(B27:AF27) -> 12974.25
A28: Bing | B28: =Summary!B79 -> 315.68 | C28: =Summary!C79 -> 248.85 | D28: =Summary!D79 -> 243.12 | E28: =Summary!E79 -> 248.21 | F28: =Summary!F79 -> 225.84 | G28: =Summary!G79 -> 230.1 | H28: =Summary!H79 -> 312 | I28: =Summary!I79 -> 296.96 | ... AF28: =Summary!AF79 -> 152.56 | AG28: =SUM(B28:AF28) -> 6616.55
A29: Nextdoor | B29: - | C29: - | D29: - | E29: - | F29: - | G29: - | H29: - | I29: - | J29: - | K29: - | L29: - | M29: - | N29: - | O29: - | P29: - | Q29: - | R29: - | S29: - | T29: - | U29: - | V29: - | W29: - | X29: - | Y29: - | Z29: - | AA29: - | AB29: - | AC29: - | AD29: - | AE29: - | AF29: - | AG29: =SUM(B29:AF29) -> 0
A30: Affiliate Fee (20%) | B30: - | C30: - | D30: - | E30: - | F30: - | G30: - | H30: - | I30: - | J30: - | K30: - | L30: - | M30: - | N30: - | O30: - | P30: - | Q30: - | R30: - | S30: - | T30: - | U30: - | V30: - | W30: - | X30: - | Y30: - | Z30: - | AA30: - | AB30: - | AC30: - | AD30: - | AE30: - | AF30: - | AG30: =SUM(B30:AF30) -> 0
A31: All | B31: =SUM(B25:B30) -> 18876.674 | C31: =SUM(C25:C30) -> 18603.305 | D31: =SUM(D25:D30) -> 18731.496 | E31: =SUM(E25:E30) -> 15558.327 | F31: =SUM(F25:F30) -> 12842.597 | G31: =SUM(G25:G30) -> 11495.618 | H31: =SUM(H25:H30) -> 11454.22 | I31: =SUM(I25:I30) -> 12307.961 | ... AF31: =SUM(AF25:AF30) -> 2116.52 | AG31: =SUM(B31:AF31) -> 236695.99
A36: Revenue
A37: Revenue Woocommerce (Platform) | B37: =Summary!B8 -> 609995.61 | C37: =Summary!C8 -> 107937.13 | D37: =Summary!D8 -> 92285.37 | E37: =Summary!E8 -> 79668.99 | F37: =Summary!F8 -> 60001.2 | G37: =Summary!G8 -> 52648.98 | H37: =Summary!H8 -> 53600.39 | I37: =Summary!I8 -> 53298.97 | ... AF37: =Summary!AF8 -> 18471.44 | AG37: =SUM(B37:AF37) -> 1787869.3
A38: SUM | B38: =SUM(B37) -> 609995.61 | C38: =SUM(C37) -> 107937.13 | D38: =SUM(D37) -> 92285.37 | E38: =SUM(E37) -> 79668.99 | F38: =SUM(F37) -> 60001.2 | G38: =SUM(G37) -> 52648.98 | H38: =SUM(H37) -> 53600.39 | I38: =SUM(I37) -> 53298.97 | ... AF38: =SUM(AF37) -> 18471.44 | AG38: =SUM(B38:AF38) -> 1787869.3
A40: Orders
A41: Orders Woocommerce (Platform) | B41: =Summary!B52 -> 1961 | C41: =Summary!C52 -> 416 | D41: =Summary!D52 -> 347 | E41: =Summary!E52 -> 312 | F41: =Summary!F52 -> 247 | G41: =Summary!G52 -> 214 | H41: =Summary!H52 -> 208 | I41: =Summary!I52 -> 200 | ... AF41: =Summary!AF52 -> 80 | AG41: =SUM(B41:AF41) -> 6487
A42: SUM | B42: =SUM(B41) -> 1961 | C42: =SUM(C41) -> 416 | D42: =SUM(D41) -> 347 | E42: =SUM(E41) -> 312 | F42: =SUM(F41) -> 247 | G42: =SUM(G41) -> 214 | H42: =SUM(H41) -> 208 | I42: =SUM(I41) -> 200 | ... AF42: =SUM(AF41) -> 80 | AG42: =SUM(B42:AF42) -> 6487
A44: Breakdown
A45: - Hardware | B45: =Summary!B9 -> 530409.79 | C45: =Summary!C9 -> 88002.25 | D45: =Summary!D9 -> 75538.45 | E45: =Summary!E9 -> 64103.35 | F45: =Summary!F9 -> 47621.15 | G45: =Summary!G9 -> 40596.8 | H45: =Summary!H9 -> 42030.65 | I45: =Summary!I9 -> 42613.85 | ... AF45: =Summary!AF9 -> 13825.11 | AG45: =SUM(B45:AF45) -> 1448395.5
A46: - Add-ons | B46: =Summary!B10 -> 9746.98 | C46: =Summary!C10 -> 5478.6 | D46: =Summary!D10 -> 4169.45 | E46: =Summary!E10 -> 4300.95 | F46: =Summary!F10 -> 3500.8 | G46: =Summary!G10 -> 3624.5 | H46: =Summary!H10 -> 3175.6 | I46: =Summary!I10 -> 2564.55 | ... AF46: =Summary!AF10 -> 1741.99 | AG46: =SUM(B46:AF46) -> 95441.09
A47: - Merch | B47: =Summary!B11 -> 0 | C47: =Summary!C11 -> 0 | D47: =Summary!D11 -> 0 | E47: =Summary!E11 -> 0 | F47: =Summary!F11 -> 0 | G47: =Summary!G11 -> 184.94 | H47: =Summary!H11 -> 0 | I47: =Summary!I11 -> 0 | ... AF47: =Summary!AF11 -> 0 | AG47: =SUM(B47:AF47) -> 334.9
A48: - Seeds | B48: =Summary!B12 -> 434.04 | C48: =Summary!C12 -> 310.57 | D48: =Summary!D12 -> 225 | E48: =Summary!E12 -> 357.48 | F48: =Summary!F12 -> 360.4 | G48: =Summary!G12 -> 247.87 | H48: =Summary!H12 -> 244.33 | I48: =Summary!I12 -> 108.94 | ... AF48: =Summary!AF12 -> 260.1 | AG48: =SUM(B48:AF48) -> 8392.71
...

Sheet AMAZON - P&L
A1: MARCH | B1: 45352 | C1: 45353 | D1: 45354 | E1: 45355 | F1: 45356 | G1: 45357 | H1: 45358 | I1: 45359 | J1: 45360 | K1: 45361 | L1: 45362 | M1: 45363 | N1: 45364 | O1: 45365 | P1: 45366 | Q1: 45367 | R1: 45368 | S1: 45369 | T1: 45370 | U1: 45371 | V1: 45372 | W1: 45373 | X1: 45374 | Y1: 45375 | Z1: 45376 | AA1: 45377 | AB1: 45378 | AC1: 45379 | AD1: 45380 | AE1: 45381 | AF1: 45382
A2: DAY | B2: FRI | C2: SAT | D2: SUN | E2: MON | F2: TUE | G2: WED | H2: THU | I2: FRI | J2: SAT | K2: SUN | L2: MON | M2: TUE | N2: WED | O2: THU | P2: FRI | Q2: SAT | R2: SUN | S2: MON | T2: TUE | U2: WED | V2: THU | W2: FRI | X2: SAT | Y2: SUN | Z2: MON | AA2: TUE | AB2: WED | AC2: THU | AD2: FRI | AE2: SAT | AF2: SUN
A3: COMMENT
A4: Orders
A5: Amazon (market place) | B5: =Summary!B58 -> 153 | C5: =Summary!C58 -> 171 | D5: =Summary!D58 -> 147 | E5: =Summary!E58 -> 97 | F5: =Summary!F58 -> 60 | G5: =Summary!G58 -> 114 | H5: =Summary!H58 -> 121 | I5: =Summary!I58 -> 110 | ... AF5: =Summary!AF58 -> 56
A6: All | B6: =SUM(B5) -> 153 | C6: =SUM(C5) -> 171 | D6: =SUM(D5) -> 147 | E6: =SUM(E5) -> 97 | F6: =SUM(F5) -> 60 | G6: =SUM(G5) -> 114 | H6: =SUM(H5) -> 121 | I6: =SUM(I5) -> 110 | ... AF6: =SUM(AF5) -> 56 | AG6: =SUM(B6:AF6) -> 2700
A8: Revenue
A9: Amazon (market place) | B9: =Summary!B16 -> 19348.49 | C9: =Summary!C16 -> 22322.39 | D9: =Summary!D16 -> 16109.48 | E9: =Summary!E16 -> 9416.58 | F9: =Summary!F16 -> 6365.8 | G9: =Summary!G16 -> 11506.81 | H9: =Summary!H16 -> 17570.37 | I9: =Summary!I16 -> 16642.54 | ... AF9: =Summary!AF16 -> 4451.22
A10: All | B10: =SUM(B9) -> 19348.49 | C10: =SUM(C9) -> 22322.39 | D10: =SUM(D9) -> 16109.48 | E10: =SUM(E9) -> 9416.58 | F10: =SUM(F9) -> 6365.8 | G10: =SUM(G9) -> 11506.81 | H10: =SUM(H9) -> 17570.37 | I10: =SUM(I9) -> 16642.54 | ... AF10: =SUM(AF9) -> 4451.22 | AG10: =SUM(B10:AF10) -> 371798.13
A12: Media Cost
A13: Amazon Spend | B13: =Summary!B81 -> 1348.28 | C13: =Summary!C81 -> 1385.43 | D13: =Summary!D81 -> 1102.46 | E13: =Summary!E81 -> 752.89 | F13: =Summary!F81 -> 700.89 | G13: =Summary!G81 -> 2163.8 | H13: =Summary!H81 -> 3196.98 | I13: =Summary!I81 -> 2585.22 | ... AF13: =Summary!AF81 -> 430.21 | AG13: =SUM(B13:AF13) -> 50347.45
A14: Amazon Platform Fee (15 %) | B14: =B9*'Data - P&L'!$C$48 -> 2902.2735 | C14: =C9*'Data - P&L'!$C$48 -> 3348.3585 | D14: =D9*'Data - P&L'!$C$48 -> 2416.422 | E14: =E9*'Data - P&L'!$C$48 -> 1412.487 | F14: =F9*'Data - P&L'!$C$48 -> 954.87 | G14: =G9*'Data - P&L'!$C$48 -> 1726.0215 | H14: =H9*'Data - P&L'!$C$48 -> 2635.5555 | I14: =I9*'Data - P&L'!$C$48 -> 2496.381 | ... AF14: =AF9*'Data - P&L'!$C$48 -> 667.683
A15: All | B15: =SUM(B13:B14) -> 4250.5535 | C15: =SUM(C13:C14) -> 4733.7885 | D15: =SUM(D13:D14) -> 3518.882 | E15: =SUM(E13:E14) -> 2165.377 | F15: =SUM(F13:F14) -> 1655.76 | G15: =SUM(G13:G14) -> 3889.8215 | H15: =SUM(H13:H14) -> 5832.5355 | I15: =SUM(I13:I14) -> 5081.601 | ... AF15: =SUM(AF13:AF14) -> 1097.893 | AG15: =SUM(B15:AF15) -> 106117.17
A19: Amazon Orders
A20: Hardware | B20: =Summary!B17 -> 16689.8 | C20: =Summary!C17 -> 18894.12 | D20: =Summary!D17 -> 13167.68 | E20: =Summary!E17 -> 7392.24 | F20: =Summary!F17 -> 4950.56 | G20: =Summary!G17 -> 9849 | H20: =Summary!H17 -> 15173.56 | I20: =Summary!I17 -> 14651.68 | ... AF20: =Summary!AF17 -> 2989 | AG20: =SUM(B20:AF20) -> 308643.2
A21: Addons | B21: =Summary!B18 -> 1424.56 | C21: =Summary!C18 -> 1915.56 | D21: =Summary!D18 -> 1792.68 | E21: =Summary!E18 -> 1421.56 | F21: =Summary!F18 -> 1009 | G21: =Summary!G18 -> 906 | H21: =Summary!H18 -> 1285.56 | I21: =Summary!I18 -> 897 | ... AF21: =Summary!AF18 -> 1130 | AG21: =SUM(B21:AF21) -> 38600.12
A22: Tax | B22: =Summary!B19 -> 1193.49 | C22: =Summary!C19 -> 1464.05 | D22: =Summary!D19 -> 1131.65 | E22: =Summary!E19 -> 586.52 | F22: =Summary!F19 -> 392.02 | G22: =Summary!G19 -> 741.83 | H22: =Summary!H19 -> 1064.89 | I22: =Summary!I19 -> 1027.39 | ... AF22: =Summary!AF19 -> 320.74 | AG22: =SUM(B22:AF22) -> 23822.38
A23: Shipping | B23: =Summary!B20 -> 26.65 | C23: =Summary!C20 -> 21.21 | D23: =Summary!D20 -> 7.47 | E23: =Summary!E20 -> 10.42 | F23: =Summary!F20 -> 0.08 | G23: =Summary!G20 -> 0 | H23: =Summary!H20 -> 29.06 | I23: =Summary!I20 -> 51.99 | ... AF23: =Summary!AF20 -> 6.99 | AG23: =SUM(B23:AF23) -> 396.41
A24: Gift Wrap Price | B24: =Summary!B21 -> 13.99 | C24: =Summary!C21 -> 27.45 | D24: =Summary!D21 -> 10 | E24: =Summary!E21 -> 5.84 | F24: =Summary!F21 -> 14.14 | G24: =Summary!G21 -> 9.98 | H24: =Summary!H21 -> 17.3 | I24: =Summary!I21 -> 14.48 | ... AF24: =Summary!AF21 -> 4.49 | AG24: =SUM(B24:AF24) -> 336.02
A25: All Amazon | B25: =SUM(B20:B24) -> 19348.49 | C25: =SUM(C20:C24) -> 22322.39 | D25: =SUM(D20:D24) -> 16109.48 | E25: =SUM(E20:E24) -> 9416.58 | F25: =SUM(F20:F24) -> 6365.8 | G25: =SUM(G20:G24) -> 11506.81 | H25: =SUM(H20:H24) -> 17570.37 | I25: =SUM(I20:I24) -> 16642.54 | ... AF25: =SUM(AF20:AF24) -> 4451.22 | AG25: =SUM(B25:AF25) -> 371798.13
A27: Units Sold (Gross)
A28: SKU 1 - Blue | B28: 4 | C28: 6 | D28: 17 | E28: 22 | F28: 22 | G28: 16 | H28: 11 | I28: 10 | J28: 14 | K28: 15 | L28: 10 | M28: 8 | N28: 7 | O28: 7 | P28: 5 | Q28: 4 | R28: 7 | S28: 8 | T28: 10 | U28: 10 | V28: 12 | W28: 15 | X28: 15 | Y28: 22 | Z28: 19 | AA28: 12 | AB28: 12 | AC28: 18 | AD28: 10 | AE28: 5 | AF28: 5 | AG28: =SUM(B28:AF28) -> 358
A29: SKU 2 - Yellow | B29: 6 | C29: 3 | D29: 7 | E29: 8 | F29: 3 | G29: 11 | H29: 2 | I29: 4 | J29: 4 | K29: 4 | L29: 0 | M29: 0 | N29: 0 | O29: 0 | P29: 0 | Q29: 0 | R29: 0 | S29: 1 | T29: 0 | U29: 0 | V29: 1 | W29: 0 | X29: 0 | Y29: 0 | Z29: 0 | AA29: 0 | AB29: 0 | AC29: 0 | AD29: 0 | AE29: 0 | AF29: 0 | AG29: =SUM(B29:AF29) -> 54
A30: SKU 3 - Blue w/ Solar | B30: 67 | C30: 82 | D30: 40 | E30: 8 | F30: 2 | G30: 25 | H30: 60 | I30: 57 | J30: 68 | K30: 77 | L30: 24 | M30: 18 | N30: 25 | O30: 28 | P30: 38 | Q30: 29 | R30: 34 | S30: 12 | T30: 28 | U30: 32 | V30: 21 | W30: 14 | X30: 18 | Y30: 14 | Z30: 7 | AA30: 16 | AB30: 13 | AC30: 6 | AD30: 11 | AE30: 14 | AF30: 6 | AG30: =SUM(B30:AF30) -> 894
A31: SKU 4 - Yellow w/ Solar | B31: 1 | C31: 0 | D31: 1 | E31: 0 | F31: 0 | G31: 0 | H31: 1 | I31: 0 | J31: 0 | K31: 0 | L31: 1 | M31: 1 | N31: 0 | O31: 0 | P31: 0 | Q31: 0 | R31: 0 | S31: 0 | T31: 0 | U31: 1 | V31: 1 | W31: 0 | X31: 0 | Y31: 0 | Z31: 0 | AA31: 0 | AB31: 0 | AC31: 0 | AD31: 0 | AE31: 0 | AF31: 0 | AG31: =SUM(B31:AF31) -> 7
A32: SUM (SKU 1 - SKU 4) | B32: =SUM(B28:B31) -> 78 | C32: =SUM(C28:C31) -> 91 | D32: =SUM(D28:D31) -> 65 | E32: =SUM(E28:E31) -> 38 | F32: =SUM(F28:F31) -> 27 | G32: =SUM(G28:G31) -> 52 | H32: =SUM(H28:H31) -> 74 | I32: =SUM(I28:I31) -> 71 | ... AF32: =SUM(AF28:AF31) -> 11 | AG32: =SUM(B32:AF32) -> 1313
A34: Wall Mount | B34: 18 | C34: 25 | D34: 28 | E34: 19 | F34: 14 | G34: 17 | H34: 18 | I34: 11 | J34: 32 | K34: 29 | L34: 14 | M34: 10 | N34: 15 | O34: 10 | P34: 17 | Q34: 17 | R34: 15 | S34: 6 | T34: 12 | U34: 11 | V34: 15 | W34: 11 | X34: 10 | Y34: 17 | Z34: 11 | AA34: 6 | AB34: 8 | AC34: 6 | AD34: 10 | AE34: 23 | AF34: 12 | AG34: =SUM(B34:AF34) -> 467
A35: Suet Ball Holder | B35: 15 | C35: 25 | D35: 23 | E35: 15 | F35: 12 | G35: 11 | H35: 12 | I35: 15 | J35: 28 | K35: 20 | L35: 5 | M35: 10 | N35: 11 | O35: 10 | P35: 10 | Q35: 20 | R35: 15 | S35: 14 | T35: 8 | U35: 13 | V35: 13 | W35: 8 | X35: 13 | Y35: 7 | Z35: 6 | AA35: 3 | AB35: 6 | AC35: 13 | AD35: 6 | AE35: 20 | AF35: 5 | AG35: =SUM(B35:AF35) -> 392
A36: 3-in-1 Nutrition Set - Blue | B36: 5 | C36: 11 | D36: 9 | E36: 6 | F36: 10 | G36: 3 | H36: 8 | I36: 6 | J36: 11 | K36: 7 | L36: 3 | M36: 8 | N36: 2 | O36: 3 | P36: 2 | Q36: 7 | R36: 4 | S36: 7 | T36: 6 | U36: 8 | V36: 6 | W36: 7 | X36: 6 | Y36: 8 | Z36: 4 | AA36: 6 | AB36: 3 | AC36: 6 | AD36: 5 | AE36: 8 | AF36: 2 | AG36: =SUM(B36:AF36) -> 187
A37: 3-in-1 Nutrition Set - Yellow | B37: 0 | C37: 0 | D37: 0 | E37: 0 | F37: 0 | G37: 0 | H37: 0 | I37: 0 | J37: 0 | K37: 0 | L37: 0 | M37: 0 | N37: 0 | O37: 0 | P37: 0 | Q37: 0 | R37: 0 | S37: 0 | T37: 0 | U37: 0 | V37: 0 | W37: 0 | X37: 0 | Y37: 0 | Z37: 0 | AA37: 0 | AB37: 0 | AC37: 0 | AD37: 0 | AE37: 0 | AF37: 0 | AG37: =SUM(B37:AF37) -> 0
A38: Solar Roof Single - Blue | B38: 0 | C38: 0 | D38: 0 | E38: 0 | F38: 0 | G38: 0 | H38: 0 | I38: 0 | J38: 0 | K38: 0 | L38: 0 | M38: 0 | N38: 0 | O38: 0 | P38: 0 | Q38: 0 | R38: 0 | S38: 0 | T38: 0 | U38: 0 | V38: 0 | W38: 0 | X38: 0 | Y38: 0 | Z38: 0 | AA38: 0 | AB38: 0 | AC38: 0 | AD38: 0 | AE38: 0 | AF38: 0 | AG38: =SUM(B38:AF38) -> 0
A39: Solar Roof Single - Yellow | B39: 0 | C39: 0 | D39: 0 | E39: 0 | F39: 0 | G39: 0 | H39: 0 | I39: 0 | J39: 0 | K39: 0 | L39: 0 | M39: 0 | N39: 0 | O39: 0 | P39: 0 | Q39: 0 | R39: 0 | S39: 0 | T39: 0 | U39: 0 | V39: 0 | W39: 0 | X39: 0 | Y39: 0 | Z39: 0 | AA39: 0 | AB39: 0 | AC39: 0 | AD39: 0 | AE39: 0 | AF39: 0 | AG39: =SUM(B39:AF39) -> 0
A40: Perch Extender - Blue | B40: 20 | C40: 26 | D40: 35 | E40: 21 | F40: 15 | G40: 18 | H40: 14 | I40: 16 | J40: 33 | K40: 25 | L40: 11 | M40: 6 | N40: 8 | O40: 5 | P40: 2 | Q40: 8 | R40: 6 | S40: 9 | T40: 5 | U40: 8 | V40: 6 | W40: 5 | X40: 20 | Y40: 22 | Z40: 10 | AA40: 16 | AB40: 9 | AC40: 11 | AD40: 10 | AE40: 24 | AF40: 21 | AG40: =SUM(B40:AF40) -> 445
A41: Perch Extender - Yellow | B41: 0 | C41: 0 | D41: 0 | E41: 0 | F41: 0 | G41: 0 | H41: 0 | I41: 0 | J41: 0 | K41: 0 | L41: 0 | M41: 0 | N41: 0 | O41: 0 | P41: 0 | Q41: 0 | R41: 0 | S41: 0 | T41: 0 | U41: 0 | V41: 0 | W41: 0 | X41: 0 | Y41: 0 | Z41: 0 | AA41: 0 | AB41: 0 | AC41: 0 | AD41: 0 | AE41: 0 | AF41: 0 | AG41: =SUM(B41:AF41) -> 0
A42: SUM (Add-ons) | B42: =SUM(B34:B41) -> 58 | C42: =SUM(C34:C41) -> 87 | D42: =SUM(D34:D41) -> 95 | E42: =SUM(E34:E41) -> 61 | F42: =SUM(F34:F41) -> 51 | G42: =SUM(G34:G41) -> 49 | H42: =SUM(H34:H41) -> 52 | I42: =SUM(I34:I41) -> 48 | ... AF42: =SUM(AF34:AF41) -> 40 | AG42: =SUM(B42:AF42) -> 1491
A45: Units Sold by country (Gross) - Only selling in US | AG45: =SUM(B45:AF45) -> 0
A46: Bird Buddy - Blue - AMAZON.US | AG46: =SUM(B46:AF46) -> 0
A47: Bird Buddy - Yellow - AMAZON.US | AG47: =SUM(B47:AF47) -> 0
A48: Bird Buddy with Solar Roof Blue - AMAZON.US | AB48: =AB31 -> 0 | AC48: =AC31 -> 0 | AD48: =AD31 -> 0 | AE48: =AE31 -> 0 | AF48: =AF31 -> 0 | AG48: =SUM(B48:AF48) -> 0
A49: Bird Buddy with Solar Roof Yellow - AMAZON.US | AG49: =SUM(B49:AF49) -> 0
...

Sheet App - P&L
A1: MARCH | B1: 45352 | C1: 45353 | D1: 45354 | E1: 45355 | F1: 45356 | G1: 45357 | H1: 45358 | I1: 45359 | J1: 45360 | K1: 45361 | L1: 45362 | M1: 45363 | N1: 45364 | O1: 45365 | P1: 45366 | Q1: 45367 | R1: 45368 | S1: 45369 | T1: 45370 | U1: 45371 | V1: 45372 | W1: 45373 | X1: 45374 | Y1: 45375 | Z1: 45376 | AA1: 45377 | AB1: 45378 | AC1: 45379 | AD1: 45380 | AE1: 45381 | AF1: 45382
A2: DAY | B2: FRI | C2: SAT | D2: SUN | E2: MON | F2: TUE | G2: WED | H2: THU | I2: FRI | J2: SAT | K2: SUN | L2: MON | M2: TUE | N2: WED | O2: THU | P2: FRI | Q2: SAT | R2: SUN | S2: MON | T2: TUE | U2: WED | V2: THU | W2: FRI | X2: SAT | Y2: SUN | Z2: MON | AA2: TUE | AB2: WED | AC2: THU | AD2: FRI | AE2: SAT | AF2: SUN
A4: Gross Revenue
A5: Apple Store Sales | B5: 6872.9926 | C5: 5548.1791 | D5: 6728.52 | E5: 10828.22 | F5: 4542.95 | G5: 2359.11 | H5: 2377.0166 | I5: 2522.5795 | J5: 3110.92 | K5: 4379.08 | L5: 2446.622 | M5: 2536.7721 | N5: 2272.88 | O5: 2332.4713 | P5: 2029.4366 | Q5: 3555.8599 | R5: 3284.25 | S5: 2014.88 | T5: 1861.88 | U5: 1898.15 | V5: 1519.9556 | W5: 1998.4023 | X5: 2850.4083 | Y5: 3300.95 | Z5: 2373.83 | AA5: 2834.69 | AB5: 2037.67 | AC5: 1682.7447 | AD5: 2038.5427 | AE5: 2936.3707 | AF5: 3543.2198 | AG5: =SUM(B5:AF5) -> 100619.55
A6: - Yearly Subscription | B6: 6480.4932 | C6: 5249.45 | D6: 6303.7232 | E6: 10439.965 | F6: 4349.11 | G6: 2069.5 | H6: 2070.5367 | I6: 2221.0799 | J6: 2818.6286 | K6: 4065.183 | L6: 2188.3811 | M6: 2277.8533 | N6: 2070.2822 | O6: 1979.46 | P6: 1772.8024 | Q6: 3239.9422 | R6: 2971.0511 | S6: 1804.4892 | T6: 1649.59 | U6: 1678.4311 | V6: 1259.67 | W6: 1803.9661 | X6: 2467.0983 | Y6: 2854.1992 | Z6: 1558.7268 | AA6: 2071.2529 | AB6: 1526.2875 | AC6: 1204.5096 | AD6: 1617.54 | AE6: 2583.414 | AF6: 3209.8548 | AG6: =SUM(B6:AF6) -> 89856.472
A7: - Monthly Subscription | B7: 392.49935 | C7: 298.72912 | D7: 424.79334 | E7: 388.25234 | F7: 193.8388 | G7: 289.61297 | H7: 306.47985 | I7: 301.49965 | J7: 292.29241 | K7: 313.89461 | L7: 258.24085 | M7: 258.91876 | N7: 202.59739 | O7: 353.01132 | P7: 256.63424 | Q7: 315.91776 | R7: 313.1994 | S7: 210.39403 | T7: 212.29462 | U7: 219.72018 | V7: 260.28556 | W7: 194.43625 | X7: 383.31 | Y7: 446.75084 | Z7: 815.0986 | AA7: 763.43598 | AB7: 511.38712 | AC7: 478.2351 | AD7: 421.0027 | AE7: 352.9567 | AF7: 333.36507 | AG7: =SUM(B7:AF7) -> 10763.085
A8: Google Store Sales | B8: 1365.2 | C8: 1251.85 | D8: 948.07 | E8: 1423.92 | F8: 1035.76 | G8: 500.48 | H8: 444.38 | I8: 595.58 | J8: 691.69 | K8: 825.29 | L8: 513.11 | M8: 543.93 | N8: 571.93 | O8: 539.48 | P8: 609.68 | Q8: 743.21 | R8: 970.43 | S8: 476.44 | T8: 482.73 | U8: 288.1 | V8: 467.59 | W8: 169.2 | X8: 355.24 | Y8: 778.43 | Z8: 495.59 | AA8: 339.7 | AB8: 477.5 | AC8: 317.99 | AD8: 628.18 | AE8: 478.16 | AF8: 354.64 | AG8: =SUM(B8:AF8) -> 19683.48
A9: - Yearly Subscription | B9: 1320.71 | C9: 1181.63 | D9: 884.79 | E9: 1346.06 | F9: 973.33 | G9: 446.66 | H9: 384.46 | I9: 505.04 | J9: 600.22 | K9: 758.05 | L9: 471.26 | M9: 508.38 | N9: 536.89 | O9: 476.38 | P9: 542.79 | Q9: 701.27 | R9: 929.12 | S9: 412.54 | T9: 435.15 | U9: =91.84+119.98 -> 211.82 | V9: 407.88 | W9: 122.74 | X9: 283.03 | Y9: =315.01+387.93 -> 702.94 | Z9: 372.15 | AA9: 216.62 | AB9: 342.42 | AC9: 216.2 | AD9: 480.08 | AE9: 443.45 | AF9: 342.04 | AG9: =SUM(B9:AF9) -> 17556.1
A10: - Monthly Subscription | B10: 44.49 | C10: 70.22 | D10: 63.28 | E10: 77.86 | F10: 62.43 | G10: 53.82 | H10: 59.92 | I10: 90.54 | J10: 91.47 | K10: 67.24 | L10: 41.85 | M10: 35.55 | N10: 35.04 | O10: 63.1 | P10: 66.89 | Q10: 41.94 | R10: 41.31 | S10: 63.9 | T10: 47.58 | U10: 76.28 | V10: 59.71 | W10: 46.46 | X10: 72.21 | Y10: 75.49 | Z10: 123.44 | AA10: 123.08 | AB10: 135.08 | AC10: 101.68 | AD10: 148.1 | AE10: 34.71 | AF10: 12.6 | AG10: =SUM(B10:AF10) -> 2127.27
A11: SUM | B11: =sum(B5+B8) -> 8238.1926 | C11: =sum(C5+C8) -> 6800.0291 | D11: =sum(D5+D8) -> 7676.59 | E11: =sum(E5+E8) -> 12252.14 | F11: =sum(F5+F8) -> 5578.71 | G11: =sum(G5+G8) -> 2859.59 | H11: =sum(H5+H8) -> 2821.3966 | I11: =sum(I5+I8) -> 3118.1595 | ... AF11: =sum(AF5+AF8) -> 3897.8598 | AG11: =SUM(B11:AF11) -> 120303.03
A13: Gross Orders
A14: Apple Store Orders | B14: =sum(B15:B16) -> 208 | C14: =sum(C15:C16) -> 180 | D14: =sum(D15:D16) -> 238 | E14: =sum(E15:E16) -> 274 | F14: =sum(F15:F16) -> 132 | G14: =sum(G15:G16) -> 108 | H14: =sum(H15:H16) -> 115 | I14: =sum(I15:I16) -> 113 | ... AF14: =sum(AF15:AF16) -> 144 | AG14: =SUM(B14:AF14) -> 4235
A15: - Yearly Subscription | B15: 135 | C15: 122 | D15: 153 | E15: 201 | F15: 89 | G15: 51 | H15: 52 | I15: 53 | J15: 74 | K15: 107 | L15: 51 | M15: 60 | N15: 54 | O15: 54 | P15: 42 | Q15: 87 | R15: 87 | S15: 47 | T15: 41 | U15: 48 | V15: 33 | W15: 43 | X15: 57 | Y15: 76 | Z15: 42 | AA15: 48 | AB15: 39 | AC15: 34 | AD15: 49 | AE15: 67 | AF15: 86 | AG15: =SUM(B15:AF15) -> 2182
A16: - Monthly Subscription | B16: 73 | C16: 58 | D16: 85 | E16: 73 | F16: 43 | G16: 57 | H16: 63 | I16: 60 | J16: 60 | K16: 61 | L16: 50 | M16: 51 | N16: 39 | O16: 68 | P16: 50 | Q16: 63 | R16: 61 | S16: 42 | T16: 42 | U16: 42 | V16: 51 | W16: 37 | X16: 69 | Y16: 83 | Z16: 148 | AA16: 141 | AB16: 92 | AC16: 89 | AD16: 77 | AE16: 67 | AF16: 58 | AG16: =SUM(B16:AF16) -> 2053
A17: Google Store Orders | B17: =sum(B18:B19) -> 35 | C17: =sum(C18:C19) -> 39 | D17: =sum(D18:D19) -> 39 | E17: =sum(E18:E19) -> 51 | F17: =sum(F18:F19) -> 32 | G17: =sum(G18:G19) -> 20 | H17: =sum(H18:H19) -> 20 | I17: =sum(I18:I19) -> 31 | ... AF17: =sum(AF18:AF19) -> 11 | AG17: =SUM(B17:AF17) -> 818
A18: - Yearly Subscription | B18: 28 | C18: 26 | D18: 25 | E18: 34 | F18: 20 | G18: 9 | H18: 9 | I18: 14 | J18: 14 | K18: 16 | L18: 11 | M18: 14 | N18: 13 | O18: 12 | P18: 14 | Q18: 17 | R18: 24 | S18: 10 | T18: 11 | U18: 5 | V18: 10 | W18: 3 | X18: 6 | Y18: 16 | Z18: 8 | AA18: 5 | AB18: 8 | AC18: 6 | AD18: 10 | AE18: 12 | AF18: 9 | AG18: =SUM(B18:AF18) -> 419
A19: - Monthly Subscription | B19: 7 | C19: 13 | D19: 14 | E19: 17 | F19: 12 | G19: 11 | H19: 11 | I19: 17 | J19: 17 | K19: 12 | L19: 7 | M19: 7 | N19: 7 | O19: 12 | P19: 14 | Q19: 7 | R19: 7 | S19: 13 | T19: 10 | U19: 16 | V19: 12 | W19: 9 | X19: 13 | Y19: 13 | Z19: 21 | AA19: 22 | AB19: 23 | AC19: 19 | AD19: 28 | AE19: 6 | AF19: 2 | AG19: =SUM(B19:AF19) -> 399
A20: SUM | B20: =sum(B14+B17) -> 243 | C20: =sum(C14+C17) -> 219 | D20: =sum(D14+D17) -> 277 | E20: =sum(E14+E17) -> 325 | F20: =sum(F14+F17) -> 164 | G20: =sum(G14+G17) -> 128 | H20: =sum(H14+H17) -> 135 | I20: =sum(I14+I17) -> 144 | ... AF20: =sum(AF14+AF17) -> 155 | AG20: =SUM(B20:AF20) -> 5053
A21: - Yearly Subscription | B21: =B15+B18 -> 163 | C21: =C15+C18 -> 148 | D21: =D15+D18 -> 178 | E21: =E15+E18 -> 235 | F21: =F15+F18 -> 109 | G21: =G15+G18 -> 60 | H21: =H15+H18 -> 61 | I21: =I15+I18 -> 67 | ... AF21: =AF15+AF18 -> 95 | AG21: =sum(A21:AF21) -> 2601
A22: - Monthly Subscription | B22: =B16+B19 -> 80 | C22: =C16+C19 -> 71 | D22: =D16+D19 -> 99 | E22: =E16+E19 -> 90 | F22: =F16+F19 -> 55 | G22: =G16+G19 -> 68 | H22: =H16+H19 -> 74 | I22: =I16+I19 -> 77 | ... AF22: =AF16+AF19 -> 60 | AG22: =sum(B22:AF22) -> 2452
A24: Refunded Revenue
A25: Apple Store Sales | B25: =sum(B26:B27) -> 27.29 | C25: =sum(C26:C27) -> 4.97 | D25: =sum(D26:D27) -> 44.1 | E25: =sum(E26:E27) -> 1.85 | F25: =sum(F26:F27) -> 123.82 | G25: =sum(G26:G27) -> 59.99 | H25: =sum(H26:H27) -> 5.99 | I25: =sum(I26:I27) -> 0.41 | ... AF25: =sum(AF26:AF27) -> 0 | AG25: =SUM(B25:AF25) -> 875.39
A26: - Yearly Subscription | B26: 27.29 | C26: 0 | D26: 38.11 | E26: 0 | F26: 119.89 | G26: 59.99 | H26: 0 | I26: 0 | J26: 0 | K26: 29.99 | L26: 0 | M26: 0 | N26: 59.99 | O26: 20.57 | P26: 0 | Q26: 0 | R26: 0 | S26: 59.99 | T26: 23.43 | U26: 89.98 | V26: 0 | W26: 7.86 | X26: 28.35 | Y26: 29.99 | Z26: 59.99 | AA26: 89.98 | AB26: 0 | AC26: 59.98 | AD26: 0 | AE26: 0 | AF26: 0 | AG26: =SUM(B26:AF26) -> 805.38
A27: - Monthly Subscription | B27: 0 | C27: 4.97 | D27: 5.99 | E27: 1.85 | F27: 3.93 | G27: 0 | H27: 5.99 | I27: 0.41 | J27: 0 | K27: 0 | L27: 1.45 | M27: 5.61 | N27: 4.64 | O27: 0 | P27: 0 | Q27: 5.99 | R27: 0 | S27: 5.99 | T27: 0 | U27: 0 | V27: 0 | W27: 0 | X27: 0 | Y27: 0 | Z27: 5.99 | AA27: 11.21 | AB27: 0 | AC27: 5.99 | AD27: 0 | AE27: 0 | AF27: 0 | AG27: =SUM(B27:AF27) -> 70.01
A28: Google Store Sales | B28: =sum(B29:B30) -> 0 | C28: =sum(C29:C30) -> 0 | D28: =sum(D29:D30) -> 0 | E28: =sum(E29:E30) -> 0 | F28: =sum(F29:F30) -> 0 | G28: =sum(G29:G30) -> 0 | H28: =sum(H29:H30) -> 0 | I28: =sum(I29:I30) -> 0 | ... AF28: =sum(AF29:AF30) -> 0 | AG28: =SUM(B28:AF28) -> 0
A29: - Yearly Subscription | B29: 0 | C29: 0 | D29: 0 | E29: 0 | F29: 0 | G29: 0 | H29: 0 | I29: 0 | J29: 0 | K29: 0 | L29: 0 | M29: 0 | N29: 0 | O29: 0 | P29: 0 | Q29: 0 | R29: 0 | S29: 0 | T29: 0 | U29: 0 | V29: 0 | W29: 0 | X29: 0 | Y29: 0 | Z29: 0 | AA29: 0 | AB29: 0 | AC29: 0 | AD29: 0 | AE29: 0 | AF29: 0 | AG29: =SUM(B29:AF29) -> 0
A30: - Monthly Subscription | B30: 0 | C30: 0 | D30: 0 | E30: 0 | F30: 0 | G30: 0 | H30: 0 | I30: 0 | J30: 0 | K30: 0 | L30: 0 | M30: 0 | N30: 0 | O30: 0 | P30: 0 | Q30: 0 | R30: 0 | S30: 0 | T30: 0 | U30: 0 | V30: 0 | W30: 0 | X30: 0 | Y30: 0 | Z30: 0 | AA30: 0 | AB30: 0 | AC30: 0 | AD30: 0 | AE30: 0 | AF30: 0 | AG30: =SUM(B30:AF30) -> 0
A31: SUM | B31: =B25+B28 -> 27.29 | C31: =C25+C28 -> 4.97 | D31: =D25+D28 -> 44.1 | E31: =E25+E28 -> 1.85 | F31: =F25+F28 -> 123.82 | G31: =G25+G28 -> 59.99 | H31: =H25+H28 -> 5.99 | I31: =I25+I28 -> 0.41 | ... AF31: =AF25+AF28 -> 0 | AG31: =SUM(B31:AF31) -> 875.39
A33: Refunded Orders
A34: Apple Store orders | B34: =sum(B35:B36) -> 1 | C34: =sum(C35:C36) -> 1 | D34: =sum(D35:D36) -> 2 | E34: =sum(E35:E36) -> 1 | F34: =sum(F35:F36) -> 3 | G34: =sum(G35:G36) -> 1 | H34: =sum(H35:H36) -> 1 | I34: =sum(I35:I36) -> 0 | ... AF34: =sum(AF35:AF36) -> 0 | AG34: =SUM(B34:AF34) -> 29
A35: - Yearly Subscription | B35: 1 | C35: 0 | D35: 1 | E35: 0 | F35: 2 | G35: 1 | H35: 0 | I35: 0 | J35: 0 | K35: 1 | L35: 0 | M35: 0 | N35: 1 | O35: 0 | P35: 0 | Q35: 0 | R35: 0 | S35: 1 | T35: 0 | U35: 2 | V35: 0 | W35: 0 | X35: 1 | Y35: 1 | Z35: 1 | AA35: 2 | AB35: 0 | AC35: 2 | AD35: 0 | AE35: 0 | AF35: 0
A36: - Monthly Subscription | B36: 0 | C36: 1 | D36: 1 | E36: 1 | F36: 1 | G36: 0 | H36: 1 | I36: 0 | J36: 0 | K36: 0 | L36: 0 | M36: 1 | N36: 1 | O36: 0 | P36: 0 | Q36: 1 | R36: 0 | S36: 1 | T36: 0 | U36: 0 | V36: 0 | W36: 0 | X36: 0 | Y36: 0 | Z36: 1 | AA36: 1 | AB36: 0 | AC36: 1 | AD36: 0 | AE36: 0 | AF36: 0
A37: Google Store orders | B37: =sum(B38:B39) -> 0 | C37: =sum(C38:C39) -> 0 | D37: =sum(D38:D39) -> 0 | E37: =sum(E38:E39) -> 0 | F37: =sum(F38:F39) -> 0 | G37: =sum(G38:G39) -> 0 | H37: =sum(H38:H39) -> 0 | I37: =sum(I38:I39) -> 0 | ... AF37: =sum(AF38:AF39) -> 0 | AG37: =SUM(B37:AF37) -> 0
A38: - Yearly Subscription | B38: 0 | C38: 0 | D38: 0 | E38: 0 | F38: 0 | G38: 0 | H38: 0 | I38: 0 | J38: 0 | K38: 0 | L38: 0 | M38: 0 | N38: 0 | O38: 0 | P38: 0 | Q38: 0 | R38: 0 | S38: 0 | T38: 0 | U38: 0 | V38: 0 | W38: 0 | X38: 0 | Y38: 0 | Z38: 0 | AA38: 0 | AB38: 0 | AC38: 0 | AD38: 0 | AE38: 0 | AF38: 0
A39: - Monthly Subscription | B39: 0 | C39: 0 | D39: 0 | E39: 0 | F39: 0 | G39: 0 | H39: 0 | I39: 0 | J39: 0 | K39: 0 | L39: 0 | M39: 0 | N39: 0 | O39: 0 | P39: 0 | Q39: 0 | R39: 0 | S39: 0 | T39: 0 | U39: 0 | V39: 0 | W39: 0 | X39: 0 | Y39: 0 | Z39: 0 | AA39: 0 | AB39: 0 | AC39: 0 | AD39: 0 | AE39: 0 | AF39: 0
A40: SUM | B40: =B34+B37 -> 1 | C40: =C34+C37 -> 1 | D40: =D34+D37 -> 2 | E40: =E34+E37 -> 1 | F40: =F34+F37 -> 3 | G40: =G34+G37 -> 1 | H40: =H34+H37 -> 1 | I40: =I34+I37 -> 0 | ... AF40: =AF34+AF37 -> 0 | AG40: =SUM(B40:AF40) -> 29
A42: Net Revenue
A43: Apple Store | B43: =B5-B25 -> 6845.7026 | C43: =C5-C25 -> 5543.2091 | D43: =D5-D25 -> 6684.42 | E43: =E5-E25 -> 10826.37 | F43: =F5-F25 -> 4419.13 | G43: =G5-G25 -> 2299.12 | H43: =H5-H25 -> 2371.0266 | I43: =I5-I25 -> 2522.1695 | ... AF43: =AF5-AF25 -> 3543.2198 | AG43: =SUM(B43:AF43) -> 99744.164
A44: - Yearly Subscription | B44: =B6-B26 -> 6453.2032 | C44: =C6-C26 -> 5249.45 | D44: =D6-D26 -> 6265.6132 | E44: =E6-E26 -> 10439.965 | F44: =F6-F26 -> 4229.22 | G44: =G6-G26 -> 2009.51 | H44: =H6-H26 -> 2070.5367 | I44: =I6-I26 -> 2221.0799 | ... AF44: =AF6-AF26 -> 3209.8548 | AG44: =SUM(B44:AF44) -> 89051.092
A45: - Monthly Subscription | B45: =B7-B27 -> 392.49935 | C45: =C7-C27 -> 293.75912 | D45: =D7-D27 -> 418.80334 | E45: =E7-E27 -> 386.40234 | F45: =F7-F27 -> 189.9088 | G45: =G7-G27 -> 289.61297 | H45: =H7-H27 -> 300.48985 | I45: =I7-I27 -> 301.08965 | ... AF45: =AF7-AF27 -> 333.36507 | AG45: =SUM(B45:AF45) -> 10693.075
...

Sheet Digital Marketplaces - P&L
A1: MARCH | B1: 45352 | C1: 45353 | D1: 45354 | E1: 45355 | F1: 45356 | G1: 45357 | H1: 45358 | I1: 45359 | J1: 45360 | K1: 45361 | L1: 45362 | M1: 45363 | N1: 45364 | O1: 45365 | P1: 45366 | Q1: 45367 | R1: 45368 | S1: 45369 | T1: 45370 | U1: 45371 | V1: 45372 | W1: 45373 | X1: 45374 | Y1: 45375 | Z1: 45376 | AA1: 45377 | AB1: 45378 | AC1: 45379 | AD1: 45380 | AE1: 45381 | AF1: 45382
A2: DAY | B2: FRI | C2: SAT | D2: SUN | E2: MON | F2: TUE | G2: WED | H2: THU | I2: FRI | J2: SAT | K2: SUN | L2: MON | M2: TUE | N2: WED | O2: THU | P2: FRI | Q2: SAT | R2: SUN | S2: MON | T2: TUE | U2: WED | V2: THU | W2: FRI | X2: SAT | Y2: SUN | Z2: MON | AA2: TUE | AB2: WED | AC2: THU | AD2: FRI | AE2: SAT | AF2: SUN
A3: Rachio (Shopify)
A4: Revenue | B4: =Summary!B23 -> 403.31077 | C4: =Summary!C23 -> 222.88339 | D4: =Summary!D23 -> 0 | E4: =Summary!E23 -> 0 | F4: =Summary!F23 -> 0 | G4: =Summary!G23 -> 222.88339 | H4: =Summary!H23 -> 0 | I4: =Summary!I23 -> 445.76677 | ... AF4: =Summary!AF23 -> 0 | AG4: =SUM(B4:AF4) -> 3130.9814
A5: Breakdown | AG5: =SUM(B5:AF5) -> 0
A6: - Tax | B6: =Summary!B25 -> 23.330772 | C6: =Summary!C25 -> 12.893386 | D6: =Summary!D25 -> 0 | E6: =Summary!E25 -> 0 | F6: =Summary!F25 -> 0 | G6: =Summary!G25 -> 12.893386 | H6: =Summary!H25 -> 0 | I6: =Summary!I25 -> 25.786772 | ... AF6: =Summary!AF25 -> 0 | AG6: =SUM(B6:AF6) -> 181.1214
A7: - Shipping | B7: =Summary!B26 | C7: =Summary!C26 | D7: =Summary!D26 | E7: =Summary!E26 | F7: =Summary!F26 | G7: =Summary!G26 | H7: =Summary!H26 | I7: =Summary!I26 | ... AD7: =Summary!AD26 | AG7: =SUM(B7:AF7) -> 0
A8: Orders | B8: =Summary!B62 -> 2 | C8: =Summary!C62 -> 1 | D8: =Summary!D62 -> 0 | E8: =Summary!E62 -> 0 | F8: =Summary!F62 -> 0 | G8: =Summary!G62 -> 1 | H8: =Summary!H62 -> 0 | I8: =Summary!I62 -> 2 | ... AF8: =Summary!AF62 -> 0 | AG8: =SUM(B8:AF8) -> 14
A10: Rachio Fees (20%) | B10: =Summary!B85 -> 80.662154 | C10: =Summary!C85 -> 44.576677 | D10: =Summary!D85 -> 0 | E10: =Summary!E85 -> 0 | F10: =Summary!F85 -> 0 | G10: =Summary!G85 -> 44.576677 | H10: =Summary!H85 -> 0 | I10: =Summary!I85 -> 89.153354 | ... AF10: =Summary!AF85 -> 0 | AG10: =SUM(B10:AF10) -> 626.19628
A12: Units Sold (Gross) - Rachio
A13: SKU 1 - Blue | B13: 1 | C13: 0 | D13: 0 | E13: 0 | F13: 0 | G13: 0 | H13: 0 | I13: 0 | J13: 0 | K13: 1 | L13: 0 | M13: 0 | N13: 0 | O13: 0 | P13: 0 | Q13: 0 | R13: 0 | S13: 0 | T13: 0 | U13: 0 | V13: 0 | W13: 0 | X13: 0 | Y13: 0 | Z13: 0 | AA13: 0 | AB13: 0 | AC13: 0 | AD13: 0 | AE13: 0 | AF13: 0 | AG13: =SUM(B13:AF13) -> 2
A14: SKU 2 - Yellow | B14: 0 | C14: 0 | D14: 0 | E14: 0 | F14: 0 | G14: 0 | H14: 0 | I14: 0 | J14: 0 | K14: 0 | L14: 0 | M14: 0 | N14: 0 | O14: 0 | P14: 0 | Q14: 0 | R14: 0 | S14: 0 | T14: 0 | U14: 0 | V14: 0 | W14: 0 | X14: 0 | Y14: 0 | Z14: 0 | AA14: 0 | AB14: 0 | AC14: 0 | AD14: 0 | AE14: 0 | AF14: 0 | AG14: =SUM(B14:AF14) -> 0
A15: SKU 3 - Blue w/ Solar | B15: 1 | C15: 1 | D15: 0 | E15: 0 | F15: 0 | G15: 1 | H15: 0 | I15: 2 | J15: 0 | K15: 4 | L15: 2 | M15: 1 | N15: 0 | O15: 0 | P15: 0 | Q15: 0 | R15: 0 | S15: 0 | T15: 0 | U15: 0 | V15: 0 | W15: 0 | X15: 0 | Y15: 0 | Z15: 0 | AA15: 0 | AB15: 0 | AC15: 1 | AD15: 0 | AE15: 0 | AF15: 0 | AG15: =SUM(B15:AF15) -> 13
A16: SKU 4 - Yellow w/ Solar | B16: 0 | C16: 0 | D16: 0 | E16: 0 | F16: 0 | G16: 0 | H16: 0 | I16: 0 | J16: 0 | K16: 0 | L16: 0 | M16: 0 | N16: 0 | O16: 0 | P16: 0 | Q16: 0 | R16: 0 | S16: 0 | T16: 0 | U16: 0 | V16: 0 | W16: 0 | X16: 0 | Y16: 0 | Z16: 0 | AA16: 0 | AB16: 0 | AC16: 0 | AD16: 0 | AE16: 0 | AF16: 0 | AG16: =SUM(B16:AF16) -> 0
A17: SUM (SKU 1 - SKU 4) | B17: =SUM(B13:B16) -> 2 | C17: =SUM(C13:C16) -> 1 | D17: =SUM(D13:D16) -> 0 | E17: =SUM(E13:E16) -> 0 | F17: =SUM(F13:F16) -> 0 | G17: =SUM(G13:G16) -> 1 | H17: =SUM(H13:H16) -> 0 | I17: =SUM(I13:I16) -> 2 | ... AF17: =SUM(AF13:AF16) -> 0 | AG17: =SUM(B17:AF17) -> 15
A19: Wall Mount | AG19: =SUM(B19:AF19) -> 0
A20: Suet Ball Holder | AG20: =SUM(B20:AF20) -> 0
A21: 3-in-1 Nutrition Set - Blue | AG21: =SUM(B21:AF21) -> 0
A22: 3-in-1 Nutrition Set - Yellow | AG22: =SUM(B22:AF22) -> 0
A23: Solar Roof Single - Blue | AG23: =SUM(B23:AF23) -> 0
A24: Solar Roof Single - Yellow | AG24: =SUM(B24:AF24) -> 0
A25: Perch Extender - Blue | AG25: =SUM(B25:AF25) -> 0
A26: Perch Extender - Yellow | AG26: =SUM(B26:AF26) -> 0
A27: SUM (Add-ons) | B27: =SUM(B19:B26) -> 0 | C27: =SUM(C19:C26) -> 0 | D27: =SUM(D19:D26) -> 0 | E27: =SUM(E19:E26) -> 0 | F27: =SUM(F19:F26) -> 0 | G27: =SUM(G19:G26) -> 0 | H27: =SUM(H19:H26) -> 0 | I27: =SUM(I19:I26) -> 0 | ... AF27: =SUM(AF19:AF26) -> 0 | AG27: =SUM(B27:AF27) -> 0
A29: Units and Revenue Cancelled & Refunds - Rachio
A31: Units Cancelled (Gross) - Rachio
A32: SKU 1 - Blue | AG32: =SUM(B32:AF32) -> 0
A33: SKU 2 - Yellow | AG33: =SUM(B33:AF33) -> 0
A34: SKU 3 - Blue w/ Solar | AG34: =SUM(B34:AF34) -> 0
A35: SKU 4 - Yellow w/ Solar | AG35: =SUM(B35:AF35) -> 0
A36: SUM (SKU 1 + SKU 2) | B36: =SUM(B32:B33) -> 0 | C36: =SUM(C32:C33) -> 0 | D36: =SUM(D32:D33) -> 0 | E36: =SUM(E32:E33) -> 0 | F36: =SUM(F32:F33) -> 0 | G36: =SUM(G32:G33) -> 0 | H36: =SUM(H32:H33) -> 0 | I36: =SUM(I32:I33) -> 0 | ... AF36: =SUM(AF32:AF33) -> 0 | AG36: =SUM(B36:AF36) -> 0
A37: SUM (SKU 3 + SKU 4) | B37: =SUM(B34:B35) -> 0 | C37: =SUM(C34:C35) -> 0 | D37: =SUM(D34:D35) -> 0 | E37: =SUM(E34:E35) -> 0 | F37: =SUM(F34:F35) -> 0 | G37: =SUM(G34:G35) -> 0 | H37: =SUM(H34:H35) -> 0 | I37: =SUM(I34:I35) -> 0 | ... AF37: =SUM(AF34:AF35) -> 0 | AG37: =SUM(B37:AF37) -> 0
A39: Wall Mount | AG39: =SUM(B39:AF39) -> 0
A40: Suet Ball Holder | AG40: =SUM(B40:AF40) -> 0
A41: 3-in-1 Nutrition Set - Blue | AG41: =SUM(B41:AF41) -> 0
A42: 3-in-1 Nutrition Set - Yellow | AG42: =SUM(B42:AF42) -> 0
A43: Solar Roof Single - Blue | AG43: =SUM(B43:AF43) -> 0
A44: Solar Roof Single - Yellow | AG44: =SUM(B44:AF44) -> 0
A45: Perch Extender - Blue | AG45: =SUM(B45:AF45) -> 0
A46: Perch Extender - Yellow | AG46: =SUM(B46:AF46) -> 0
...

Sheet PP - Results
A1: 45352 | B1: 45352 | C1: 45353 | D1: 45354 | E1: 45355 | F1: 45356 | G1: 45357 | H1: 45358 | I1: 45359 | J1: 45360 | K1: 45361 | L1: 45362 | M1: 45363 | N1: 45364 | O1: 45365 | P1: 45366 | Q1: 45367 | R1: 45368 | S1: 45369 | T1: 45370 | U1: 45371 | V1: 45372 | W1: 45373 | X1: 45374 | Y1: 45375 | Z1: 45376 | AA1: 45377 | AB1: 45378 | AC1: 45379 | AD1: 45380 | AE1: 45381 | AF1: 45382
B2: FRI | C2: SAT | D2: SUN | E2: MON | F2: TUE | G2: WED | H2: THU | I2: FRI | J2: SAT | K2: SUN | L2: MON | M2: TUE | N2: WED | O2: THU | P2: FRI | Q2: SAT | R2: SUN | S2: MON | T2: TUE | U2: WED | V2: THU | W2: FRI | X2: SAT | Y2: SUN | Z2: MON | AA2: TUE | AB2: WED | AC2: THU | AD2: FRI | AE2: SAT | AF2: SUN
A4: Number of participants | B4: ='PP - Data'!B10 -> 1259 | C4: ='PP - Data'!C10 -> 251 | D4: ='PP - Data'!D10 -> 201 | E4: ='PP - Data'!E10 -> 184 | F4: ='PP - Data'!F10 -> 159 | G4: ='PP - Data'!G10 -> 133 | H4: ='PP - Data'!H10 -> 134 | I4: ='PP - Data'!I10 -> 117 | ... AF4: ='PP - Data'!AF10 -> 46
A5: Engagement Rate | B5: =B4/Summary!B52 -> 0.64201938 | C5: =C4/Summary!C52 -> 0.60336538 | D5: =D4/Summary!D52 -> 0.57925072 | E5: =E4/Summary!E52 -> 0.58974359 | F5: =F4/Summary!F52 -> 0.6437247 | G5: =G4/Summary!G52 -> 0.62149533 | H5: =H4/Summary!H52 -> 0.64423077 | I5: =I4/Summary!I52 -> 0.585 | ... AF5: =AF4/Summary!AF52 -> 0.575
A7: Post-purchase Survey
A8: Facebook / Instagram | B8: ='PP - Data'!B12 -> 0.24861001 | C8: ='PP - Data'!C12 -> 0.30278884 | D8: ='PP - Data'!D12 -> 0.3880597 | E8: ='PP - Data'!E12 -> 0.30434783 | F8: ='PP - Data'!F12 -> 0.28301887 | G8: ='PP - Data'!G12 -> 0.28571429 | H8: ='PP - Data'!H12 -> 0.35820896 | I8: ='PP - Data'!I12 -> 0.46153846 | ... AF8: ='PP - Data'!AF12 -> 0.15217391
A9: Where on Facebook/Instagram have you heard about Bird Buddy?
A10: I saw an ad | B10: ='PP - Data'!B28 -> 0.69009585 | C10: ='PP - Data'!C28 -> 0.72368421 | D10: ='PP - Data'!D28 -> 0.75641026 | E10: ='PP - Data'!E28 -> 0.82142857 | F10: ='PP - Data'!F28 -> 0.84444444 | G10: ='PP - Data'!G28 -> 0.78947368 | H10: ='PP - Data'!H28 -> 0.75 | I10: ='PP - Data'!I28 -> 0.83333333 | ... AF10: ='PP - Data'!AF28 -> 0.85714286
A11: I saw a post about Bird Buddy on my friend's feed | B11: ='PP - Data'!B29 -> 0.057507987 | C11: ='PP - Data'!C29 -> 0.092105263 | D11: ='PP - Data'!D29 -> 0.076923077 | E11: ='PP - Data'!E29 -> 0.071428571 | F11: ='PP - Data'!F29 -> 0.088888889 | G11: ='PP - Data'!G29 -> 0.13157895 | H11: ='PP - Data'!H29 -> 0.0625 | I11: ='PP - Data'!I29 -> 0.11111111 | ... AF11: ='PP - Data'!AF29 -> 0.14285714
A12: I saw an organic post from Bird Buddy | B12: ='PP - Data'!B30 -> 0.25239617 | C12: ='PP - Data'!C30 -> 0.18421053 | D12: ='PP - Data'!D30 -> 0.16666667 | E12: ='PP - Data'!E30 -> 0.10714286 | F12: ='PP - Data'!F30 -> 0.066666667 | G12: ='PP - Data'!G30 -> 0.078947368 | H12: ='PP - Data'!H30 -> 0.1875 | I12: ='PP - Data'!I30 -> 0.055555556 | ... AF12: ='PP - Data'!AF30 -> 0
A13: Friends / Family | B13: ='PP - Data'!B13 -> 0.52025417 | C13: ='PP - Data'!C13 -> 0.52191235 | D13: ='PP - Data'!D13 -> 0.48258706 | E13: ='PP - Data'!E13 -> 0.57065217 | F13: ='PP - Data'!F13 -> 0.52201258 | G13: ='PP - Data'!G13 -> 0.56390977 | H13: ='PP - Data'!H13 -> 0.52238806 | I13: ='PP - Data'!I13 -> 0.41880342 | ... AF13: ='PP - Data'!AF13 -> 0.69565217
A14: TikTok | B14: ='PP - Data'!B14 -> 0.0023828435 | C14: ='PP - Data'!C14 -> 0.0039840637 | D14: ='PP - Data'!D14 -> 0.0049751244 | E14: ='PP - Data'!E14 -> 0.010869565 | F14: ='PP - Data'!F14 -> 0.031446541 | G14: ='PP - Data'!G14 -> 0.022556391 | H14: ='PP - Data'!H14 -> 0.014925373 | I14: ='PP - Data'!I14 -> 0.017094017 | ... AF14: ='PP - Data'!AF14 -> 0.02173913
A15: TV / Radio | B15: ='PP - Data'!B15 -> 0.016679905 | C15: ='PP - Data'!C15 -> 0.019920319 | D15: ='PP - Data'!D15 -> 0.014925373 | E15: ='PP - Data'!E15 -> 0.016304348 | F15: ='PP - Data'!F15 -> 0.012578616 | G15: ='PP - Data'!G15 -> 0.022556391 | H15: ='PP - Data'!H15 -> 0.014925373 | I15: ='PP - Data'!I15 -> 0.017094017 | ... AF15: ='PP - Data'!AF15 -> 0
