Workbook
Name zsupermetrics_ru0GDtbZzDLHQOQtJJ6K08MvUDyyp7: #REF!
Name zsupermetrics_lx4cNai7gT6tH4j08ZRkI21Qlpjioi: #REF!
Name rdataslayer_d70e473bcafe40a3aa834ce157fb2ba3: #REF!
Name zsupermetrics_refreshAll: #REF!
Name zsupermetrics_8xojRjNDjo2jWHGDWjFEhflhyIq3Hq: #REF!
Name zsupermetrics_FEamnpN5FsVYF0RtUTXAwunZ388Tkc: #REF!
Name zsupermetrics_n3GtLgiKpTmd2pYmQNMuq6TPD0qE0b: #REF!
Name rdataslayer_3753ddf3234e496aa261974a0222e193: #REF!
Name zsupermetrics_refreshAllSilent: #REF!
Name zsupermetrics_BioPyGBzcBsy60UCQmPcTuFReEmghI: #REF!
Name zsupermetrics_qWp7V908pNEYMtfv8QZvSTeDnBAHOU: #REF!
Name zsupermetrics_Mgms9p0QzysYvrIhnsKACeVBVxfIEO: #REF!
Name zsupermetrics_forceRefresh: #REF!
Name zsupermetrics_wbYMmT0YL9bAN0yhimW0ziPFnia9Dx: #REF!
Name zsupermetrics_iNpyVy90bWCI0yUaFQpxOtzWMa6sW4: #REF!
Name zsupermetrics_9i4W4hgd80uRpQLMeX0eRnESN8gjyv: #REF!
Name zsupermetrics_5bmwtOpHUbSYmDMeuCPkrxaojTprPP: #REF!
Name rdataslayer_42b112e4e4be4305bb4c1be75e2dd549: #REF!
Name zsupermetrics_SGBxROnInO9rFyh3H7j2Lldx0Bdc5v: #REF!
Name zsupermetrics_pxuhRTEmIU93xSgKclyxajD0fCZ6rF: #REF!
Name rdataslayer_4a0f150f4f2f4e4f85c890c75b7a1fa4: #REF!
Name rdataslayer_adf57e64065742daa5b4161161b1c3ca: #REF!
Name zsupermetrics_HgZqhorObHOtZHuyJjpmyYaEPoYntx: #REF!
Name zsupermetrics_NugLlrQxlKiqhxQae8EFpITBm1pLCj: #REF!
Name zsupermetrics_xwoIpANxRm908eDp5oKTwQpEI8gvD4: #REF!
Name zsupermetrics_YsFuuYtr8vOdNXCCPiFJIO38NP4b2T: #REF!
Name zsupermetrics_DQl8lUbpTRu3fayaJJi7lVfOGKjNU4: #REF!
Name zsupermetrics_YVuzfmsfdurz7Ldl84Rfns8oka6LsS: #REF!
Name zsupermetrics_4VkB7ij7WO0JjKBEgvjB2GHjSy2Egm: #REF!

Sheet PP - Data
B1: 2021 | H1: 2022 | T1: 2023 | AF1: 2024
A2: Post-purchase Survey | B2: 44392 | C2: 44419 | D2: 44446 | E2: 44473 | F2: 44527 | G2: 44554 | H2: 44581 | I2: 44608 | J2: 44635 | K2: 44662 | L2: 44689 | M2: 44716 | N2: 44743 | O2: 44797 | P2: 44824 | Q2: 44851 | R2: 44878 | S2: 44905 | T2: 44932 | U2: 44959 | V2: 44986 | W2: 45040 | X2: 45057 | Y2: 45098 | Z2: 45113 | AA2: 45155 | AB2: 45175 | AC2: 45217 | AD2: 45246 | AE2: 45266 | AF2: 45310 | AG2: 45330 | AH2: 45357 | AI2: 45399 | AJ2: 45427 | AK2: 45448 | AL2: 45484 | AM2: 45511 | AN2: 45540 | AO2: 45573 | AP2: 45607 | AQ2: 45637 | AR2: 45664 | AS2: 45689 | AT2: 45717 | AU2: 45748 | AV2: 45778 | AW2: 45809 | AX2: 45839 | AY2: 45870 | AZ2: 45901 | BA2: 45932 | BB2: 45962 | BC2: 45992 | BD2: 46023 | BE2: 46054 | BF2: 46082 | BG2: 46113 | BH2: 46143 | BI2: 46174 | BJ2: 46204 | BK2: 46235 | BL2: 46266 | BM2: 46296 | BN2: 46327 | BO2: 46357 | BP2: Total | BQ2: %
A3: DTC Orders (wo renewals) | B3: 2330 | C3: 945 | D3: 415 | E3: 1396 | F3: 1582 | G3: 1380 | H3: 1681 | I3: 1212 | J3: 3305 | K3: 4369 | L3: 3561 | M3: 2262 | N3: 450 | O3: 485 | P3: 774 | Q3: 7298 | R3: 18144 | S3: 6148 | T3: 5443 | U3: 5311 | V3: 7268 | W3: 8490 | X3: 9520 | Y3: 4982 | Z3: 5884 | AA3: 5901 | AB3: 3889 | AC3: 7475 | AD3: 30028 | AE3: 22951 | AF3: 3946 | AG3: 7716 | AH3: 6487 | AI3: 3315 | AJ3: 4414 | AK3: 4049 | AL3: 3213 | AM3: 2306 | AN3: 1497 | AO3: 2601 | AP3: 41165 | AQ3: 39526 | AR3: 5600 | AS3: 6703 | AT3: 6999 | AU3: 9927 | AV3: 9983 | AW3: 5313 | AX3: 2483 | AY3: 2581 | AZ3: 5528 | BA3: 1276 | BB3: 41326 | BC3: 57695 | BD3: 4386 | BE3: 3366 | BF3: 7904 | BG3: 9703 | BH3: =IFERROR(__xludf.DUMMYFUNCTION("IMPORTRANGE(""1Z2ZLDM0_m0NNnV5_jRvcRNtM9Z5AZ7o_A94RnrBGQUE"",""DTC - P&L!AG39:AG39"")"),9977.0) -> 9977 | BP3: =SUM(B3:BO3) -> 485864
A4: Response rate (%) | B4: =B18/B3 -> 0.6193133 | C4: =C18/C3 -> 0.5968254 | D4: =D18/D3 -> 0.5686747 | E4: =E18/E3 -> 0.5773639 | F4: =F18/F3 -> 0.47155499 | G4: =G18/G3 -> 0.49855072 | H4: =H18/H3 -> 0.49196907 | I4: =I18/I3 -> 0.47689769 | ... BP4: =BP18/BP3 -> 0.49065376
A5: All Customers
A7: Where did you hear about Bird Buddy?
A8: Facebook / Instagram | B8: 1207 | C8: 387 | D8: 133 | E8: 335 | F8: 444 | G8: 201 | H8: 178 | I8: 399 | J8: 1047 | K8: 1489 | L8: 1218 | M8: 675 | N8: 123 | O8: 115 | P8: 216 | Q8: 1697 | R8: 3287 | S8: 658 | T8: 412 | U8: 794 | V8: 1355 | W8: 1320 | X8: 1371 | Y8: 609 | Z8: 396 | AA8: 1867 | AB8: 849 | AC8: 2104 | AD8: 9039 | AE8: 5759 | AF8: 628 | AG8: 1483 | AH8: 1085 | AI8: 433 | AJ8: =sum(AJ126,AJ168) -> 603 | AK8: =sum(AK126,AK168) -> 431 | AL8: =sum(AL126,AL168) -> 312 | AM8: =sum(AM126,AM168) -> 283 | AN8: =sum(AN126,AN168) -> 135 | AO8: =sum(AO126,AO168) -> 442 | AP8: =sum(AP126,AP168) -> 13971 | AQ8: =sum(AQ126,AQ168) -> 12822 | ... BO8: =sum(BO126,BO168) -> 0 | BP8: =SUM(B8:BO8) -> 120187 | BQ8: =iferror(BP8/$BP$18,"") -> 0.50415913
A9: Friends / Family | B9: 132 | C9: 107 | D9: 48 | E9: 69 | F9: 141 | G9: 126 | H9: 115 | I9: 62 | J9: 172 | K9: 187 | L9: 167 | M9: 100 | N9: 35 | O9: 33 | P9: 35 | Q9: 316 | R9: 1366 | S9: 966 | T9: 754 | U9: 600 | V9: 784 | W9: 917 | X9: 1030 | Y9: 650 | Z9: 573 | AA9: 1587 | AB9: 1158 | AC9: 1881 | AD9: 5146 | AE9: 4647 | AF9: 1400 | AG9: 2349 | AH9: 2170 | AI9: 1219 | AJ9: =sum(AJ127,AJ169) -> 1316 | AK9: =sum(AK127,AK169) -> 775 | AL9: =sum(AL127,AL169) -> 595 | AM9: =sum(AM127,AM169) -> 514 | AN9: =sum(AN127,AN169) -> 222 | AO9: =sum(AO127,AO169) -> 392 | AP9: =sum(AP127,AP169) -> 3782 | AQ9: =sum(AQ127,AQ169) -> 5386 | ... BO9: =sum(BO127,BO169) -> 0 | BP9: =SUM(B9:BO9) -> 78732 | BQ9: =iferror(BP9/$BP$18,"") -> 0.33026415
A10: Google, Yahoo, Bing | B10: 38 | C10: 29 | D10: 29 | E10: 33 | F10: 68 | G10: 72 | H10: 97 | I10: 41 | J10: 75 | K10: 80 | L10: 78 | M10: 48 | N10: 19 | O10: 22 | P10: 15 | Q10: 68 | R10: 174 | S10: 65 | T10: 102 | U10: 49 | V10: 73 | W10: 45 | BP10: =SUM(B10:BO10) -> 1320 | BQ10: =iferror(BP10/$BP$18,"") -> 0.0055371218
A11: Pinterest | B11: 38 | C11: 3 | D11: 7 | E11: 2 | F11: 9 | G11: 12 | H11: 4 | I11: 3 | J11: 6 | K11: 8 | L11: 6 | M11: 1 | N11: 1 | O11: 1 | P11: 2 | Q11: 12 | R11: 20 | S11: 5 | T11: 2 | U11: 4 | V11: 10 | W11: 2 | BP11: =SUM(B11:BO11) -> 158 | BQ11: =iferror(BP11/$BP$18,"") -> 0.0006627767
A12: TikTok | B12: 15 | C12: 9 | D12: 1 | E12: 4 | F12: 7 | G12: 4 | H12: 2 | I12: 4 | J12: 72 | K12: 34 | L12: 19 | M12: 41 | N12: 3 | O12: 4 | P12: 6 | Q12: 393 | R12: 1147 | S12: 99 | T12: 21 | U12: 37 | V12: 35 | W12: 100 | X12: 217 | Y12: 39 | Z12: 17 | AA12: 47 | AB12: 56 | AC12: 48 | AD12: 332 | AE12: 307 | AF12: 37 | AG12: 47 | AH12: 55 | AI12: 42 | AJ12: =sum(AJ128,AJ170) -> 70 | AK12: =sum(AK128,AK170) -> 27 | AL12: =sum(AL128,AL170) -> 5 | AM12: =sum(AM128,AM170) -> 8 | AN12: =sum(AN128,AN170) -> 4 | AO12: =sum(AO128,AO170) -> 6 | AP12: =sum(AP128,AP170) -> 241 | AQ12: =sum(AQ128,AQ170) -> 733 | ... BO12: =sum(BO128,BO170) -> 0 | BP12: =SUM(B12:BO12) -> 5980 | BQ12: =iferror(BP12/$BP$18,"") -> 0.02508484
A13: TV / Radio | B13: 11 | C13: 9 | D13: 4 | E13: 337 | F13: 31 | G13: 217 | H13: 86 | I13: 16 | J13: 17 | K13: 25 | L13: 17 | M13: 9 | N13: 13 | O13: 4 | P13: 5 | Q13: 12 | R13: 37 | S13: 42 | T13: 71 | U13: 22 | V13: 26 | W13: 281 | X13: 50 | Y13: 44 | Z13: 8 | AA13: 35 | AB13: 96 | AC13: 52 | AD13: 348 | AE13: 941 | AF13: 53 | AG13: 66 | AH13: 61 | AI13: 29 | AJ13: =sum(AJ129,AJ171) -> 44 | AK13: =sum(AK129,AK171) -> 25 | AL13: =sum(AL129,AL171) -> 12 | AM13: =sum(AM129,AM171) -> 11 | AN13: =sum(AN129,AN171) -> 6 | AO13: =sum(AO129,AO171) -> 36 | AP13: =sum(AP129,AP171) -> 221 | AQ13: =sum(AQ129,AQ171) -> 278 | ... BO13: =sum(BO129,BO171) -> 0 | BP13: =SUM(B13:BO13) -> 4891 | BQ13: =iferror(BP13/$BP$18,"") -> 0.020516714
A14: Blog / Article | B14: 2 | C14: 20 | D14: 14 | E14: 26 | F14: 46 | G14: 56 | H14: 345 | I14: 53 | J14: 166 | K14: 83 | L14: 47 | M14: 31 | N14: 22 | O14: 11 | P14: 15 | Q14: 41 | R14: 92 | S14: 53 | T14: 253 | U14: 103 | V14: 94 | W14: 113 | X14: 191 | Y14: 118 | Z14: 40 | AA14: 119 | AB14: 162 | AC14: 230 | AD14: 1230 | AE14: 868 | AF14: 144 | AG14: 236 | AH14: 245 | AI14: 231 | AJ14: =sum(AJ130,AJ172) -> 174 | AK14: =sum(AK130,AK172) -> 70 | AL14: =sum(AL130,AL172) -> 115 | AM14: =sum(AM130,AM172) -> 76 | AN14: =sum(AN130,AN172) -> 31 | AO14: =sum(AO130,AO172) -> 116 | AP14: =sum(AP130,AP172) -> 427 | AQ14: =sum(AQ130,AQ172) -> 558 | ... BO14: =sum(BO130,BO172) -> 0 | BP14: =SUM(B14:BO14) -> 10393 | BQ14: =iferror(BP14/$BP$18,"") -> 0.043596444
A15: Google / Youtube | S15: 6 | T15: 10 | U15: 9 | V15: 14 | W15: 79 | X15: 168 | Y15: 92 | Z15: 61 | AA15: 163 | AB15: 136 | AC15: 290 | AD15: 1311 | AE15: 990 | AF15: 182 | AG15: 220 | AH15: 329 | AI15: 211 | AJ15: =sum(AJ132,AJ174) -> 181 | AK15: =sum(AK132,AK174) -> 113 | AL15: =sum(AL132,AL174) -> 98 | AM15: =sum(AM132,AM174) -> 87 | AN15: =sum(AN132,AN174) -> 39 | AO15: =sum(AO132,AO174) -> 111 | AP15: =sum(AP132,AP174) -> 960 | AQ15: =sum(AQ132,AQ174) -> 1390 | ... BO15: =sum(BO132,BO174) -> 0 | BP15: =SUM(B15:BO15) -> 14365 | BQ15: =iferror(BP15/$BP$18,"") -> 0.060258147
A16: Reddit | T16: 2 | U16: 1 | V16: 1 | W16: 6 | X16: 27 | Y16: 12 | Z16: 6 | AA16: 23 | AB16: 13 | AC16: 24 | AD16: 127 | AE16: 155 | AF16: 22 | AG16: 38 | AH16: 38 | AI16: 28 | AJ16: =sum(AJ131,AJ173) -> 28 | AK16: =sum(AK131,AK173) -> 15 | AL16: =sum(AL131,AL173) -> 11 | AM16: =sum(AM131,AM173) -> 12 | AN16: =sum(AN131,AN173) -> 6 | AO16: =sum(AO131,AO173) -> 7 | AP16: =sum(AP131,AP173) -> 95 | AQ16: =sum(AQ131,AQ173) -> 176 | ... BO16: =sum(BO131,BO173) -> 0 | BP16: =SUM(B16:BO16) -> 1777 | BQ16: =iferror(BP16/$BP$18,"") -> 0.0074541405
A17: Yahoo / Bing | X17: 4 | Y17: 3 | Z17: 3 | AA17: 7 | AB17: 10 | AC17: 16 | AD17: 45 | AE17: 52 | AF17: 7 | AG17: 4 | AH17: 28 | AI17: 12 | AJ17: =sum(AJ133,AJ175) -> 7 | AK17: =sum(AK133,AK175) -> 5 | AL17: =sum(AL133,AL175) -> 1 | AM17: =sum(AM133,AM175) -> 3 | AN17: =sum(AN133,AN175) -> 0 | AO17: =sum(AO133,AO175) -> 6 | AP17: =sum(AP133,AP175) -> 35 | AQ17: =sum(AQ133,AQ175) -> 64 | ... BO17: =sum(BO133,BO175) -> 0 | BP17: =SUM(B17:BO17) -> 588 | BQ17: =iferror(BP17/$BP$18,"") -> 0.0024665361
A18: Total submissions: | B18: =SUM(B8:B17) -> 1443 | C18: =SUM(C8:C17) -> 564 | D18: =SUM(D8:D17) -> 236 | E18: =SUM(E8:E17) -> 806 | F18: =SUM(F8:F17) -> 746 | G18: =SUM(G8:G17) -> 688 | H18: =SUM(H8:H17) -> 827 | I18: =SUM(I8:I17) -> 578 | ... BO18: =SUM(BO8:BO17) -> 0 | BP18: =SUM(B18:BO18) -> 238391 | BQ18: =SUM(BQ8:BQ16) -> 0.99753346
A19: % Where did you hear about Bird Buddy?
A20: Facebook / Instagram | B20: =iferror(B8/B$18,"") -> 0.83645184 | C20: =iferror(C8/C$18,"") -> 0.68617021 | D20: =iferror(D8/D$18,"") -> 0.56355932 | E20: =iferror(E8/E$18,"") -> 0.41563275 | F20: =iferror(F8/F$18,"") -> 0.59517426 | G20: =iferror(G8/G$18,"") -> 0.29215116 | H20: =iferror(H8/H$18,"") -> 0.21523579 | I20: =iferror(I8/I$18,"") -> 0.69031142 | ... BO20: =iferror(BO8/BO$18,"")
A21: Friends / Family | B21: =iferror(B9/B$18,"") -> 0.091476091 | C21: =iferror(C9/C$18,"") -> 0.18971631 | D21: =iferror(D9/D$18,"") -> 0.20338983 | E21: =iferror(E9/E$18,"") -> 0.08560794 | F21: =iferror(F9/F$18,"") -> 0.18900804 | G21: =iferror(G9/G$18,"") -> 0.18313953 | H21: =iferror(H9/H$18,"") -> 0.13905683 | I21: =iferror(I9/I$18,"") -> 0.10726644 | ... BO21: =iferror(BO9/BO$18,"")
A22: Google, Yahoo, Bing | B22: =iferror(B10/B$18,"") -> 0.026334026 | C22: =iferror(C10/C$18,"") -> 0.05141844 | D22: =iferror(D10/D$18,"") -> 0.12288136 | E22: =iferror(E10/E$18,"") -> 0.040942928 | F22: =iferror(F10/F$18,"") -> 0.091152815 | G22: =iferror(G10/G$18,"") -> 0.10465116 | H22: =iferror(H10/H$18,"") -> 0.11729141 | I22: =iferror(I10/I$18,"") -> 0.070934256 | ... W22: =iferror(W10/W$18,"") -> 0.015717779
A23: Pinterest | B23: =iferror(B11/B$18,"") -> 0.026334026 | C23: =iferror(C11/C$18,"") -> 0.0053191489 | D23: =iferror(D11/D$18,"") -> 0.029661017 | E23: =iferror(E11/E$18,"") -> 0.0024813896 | F23: =iferror(F11/F$18,"") -> 0.012064343 | G23: =iferror(G11/G$18,"") -> 0.01744186 | H23: =iferror(H11/H$18,"") -> 0.0048367594 | I23: =iferror(I11/I$18,"") -> 0.0051903114 | ... W23: =iferror(W11/W$18,"") -> 0.00069856794
A24: TikTok | B24: =iferror(B12/B$18,"") -> 0.01039501 | C24: =iferror(C12/C$18,"") -> 0.015957447 | D24: =iferror(D12/D$18,"") -> 0.0042372881 | E24: =iferror(E12/E$18,"") -> 0.0049627792 | F24: =iferror(F12/F$18,"") -> 0.009383378 | G24: =iferror(G12/G$18,"") -> 0.0058139535 | H24: =iferror(H12/H$18,"") -> 0.0024183797 | I24: =iferror(I12/I$18,"") -> 0.0069204152 | ... BO24: =iferror(BO12/BO$18,"")
A25: TV / Radio | B25: =iferror(B13/B$18,"") -> 0.0076230076 | C25: =iferror(C13/C$18,"") -> 0.015957447 | D25: =iferror(D13/D$18,"") -> 0.016949153 | E25: =iferror(E13/E$18,"") -> 0.41811414 | F25: =iferror(F13/F$18,"") -> 0.04155496 | G25: =iferror(G13/G$18,"") -> 0.31540698 | H25: =iferror(H13/H$18,"") -> 0.10399033 | I25: =iferror(I13/I$18,"") -> 0.027681661 | ... BO25: =iferror(BO13/BO$18,"")
A26: Blog / Article | B26: =iferror(B14/B$18,"") -> 0.0013860014 | C26: =iferror(C14/C$18,"") -> 0.035460993 | D26: =iferror(D14/D$18,"") -> 0.059322034 | E26: =iferror(E14/E$18,"") -> 0.032258065 | F26: =iferror(F14/F$18,"") -> 0.061662198 | G26: =iferror(G14/G$18,"") -> 0.081395349 | H26: =iferror(H14/H$18,"") -> 0.4171705 | I26: =iferror(I14/I$18,"") -> 0.091695502 | ... BO26: =iferror(BO14/BO$18,"")
A27: Google / Youtube | S27: =iferror(S15/S$18,"") -> 0.0031678986 | T27: =iferror(T15/T$18,"") -> 0.0061462815 | U27: =iferror(U15/U$18,"") -> 0.005558987 | V27: =iferror(V15/V$18,"") -> 0.0058528428 | W27: =iferror(W15/W$18,"") -> 0.027593433 | X27: =iferror(X15/X$18,"") -> 0.054937868 | Y27: =iferror(Y15/Y$18,"") -> 0.058710913 | Z27: =iferror(Z15/Z$18,"") -> 0.055253623 | ... BO27: =iferror(BO15/BO$18,"")
A28: Reddit | T28: =iferror(T16/T$18,"") -> 0.0012292563 | U28: =iferror(U16/U$18,"") -> 0.00061766523 | V28: =iferror(V16/V$18,"") -> 0.0004180602 | W28: =iferror(W16/W$18,"") -> 0.0020957038 | X28: =iferror(X16/X$18,"") -> 0.0088293002 | Y28: =iferror(Y16/Y$18,"") -> 0.0076579451 | Z28: =iferror(Z16/Z$18,"") -> 0.0054347826 | AA28: =iferror(AA16/AA$18,"") -> 0.005977131 | ... BO28: =iferror(BO16/BO$18,"")
A29: Yahoo / Bing | X29: =iferror(X17/X$18,"") -> 0.0013080445 | Y29: =iferror(Y17/Y$18,"") -> 0.0019144863 | Z29: =iferror(Z17/Z$18,"") -> 0.0027173913 | AA29: =iferror(AA17/AA$18,"") -> 0.0018191268 | AB29: =iferror(AB17/AB$18,"") -> 0.0040322581 | AC29: =iferror(AC17/AC$18,"") -> 0.003444564 | AD29: =iferror(AD17/AD$18,"") -> 0.0025600182 | AE29: =iferror(AE17/AE$18,"") -> 0.0037903637 | ... BO29: =iferror(BO17/BO$18,"")
A32: Where on Facebook/Instagram have you heard about Bird Buddy?
A33: I saw an ad | AC33: 1304 | AD33: 7838 | AE33: 4891 | AF33: 455 | AG33: 1087 | AH33: 769 | AI33: 57 | AJ33: =sum(AJ145,AJ187) -> 451 | AK33: =sum(AK145,AK187) -> 324 | AL33: =sum(AL145,AL187) -> 223 | AM33: =sum(AM145,AM187) -> 211 | AN33: =sum(AN145,AN187) -> 106 | AO33: =sum(AO145,AO187) -> 335 | AP33: =sum(AP145,AP187) -> 12078 | AQ33: =sum(AQ145,AQ187) -> 10987 | ... BO33: =sum(BO145,BO187) -> 0 | BP33: =SUM(B33:BO33) -> 80612 | BQ33: =iferror(BP33/BP$36,"") -> 0.83470013
A34: I saw a post about Bird Buddy on my friend's feed | AC34: 103 | AD34: 496 | AE34: 386 | AF34: 90 | AG34: 198 | AH34: 97 | AI34: 17 | AJ34: =sum(AJ146,AJ188) -> 70 | AK34: =sum(AK146,AK188) -> 60 | AL34: =sum(AL146,AL188) -> 40 | AM34: =sum(AM146,AM188) -> 19 | AN34: =sum(AN146,AN188) -> 10 | AO34: =sum(AO146,AO188) -> 29 | AP34: =sum(AP146,AP188) -> 629 | AQ34: =sum(AQ146,AQ188) -> 567 | ... BO34: =sum(BO146,BO188) -> 0 | BP34: =SUM(B34:BO34) -> 5620 | BQ34: =iferror(BP34/BP$36,"") -> 0.058192512
A35: I saw an organic post from Bird Buddy | AC35: 192 | AD35: 705 | AE35: 510 | AF35: 83 | AG35: 241 | AH35: 175 | AI35: 7 | AJ35: =sum(AJ147,AJ189) -> 82 | AK35: =sum(AK147,AK189) -> 47 | AL35: =sum(AL147,AL189) -> 49 | AM35: =sum(AM147,AM189) -> 53 | AN35: =sum(AN147,AN189) -> 19 | AO35: =sum(AO147,AO189) -> 78 | AP35: =sum(AP147,AP189) -> 1264 | AQ35: =sum(AQ147,AQ189) -> 1268 | ... BO35: =sum(BO147,BO189) -> 0 | BP35: =SUM(B35:BO35) -> 10344 | BQ35: =iferror(BP35/BP$36,"") -> 0.10710736
A36: Total submissions: | AC36: =SUM(AC33:AC35) -> 1599 | AD36: =SUM(AD33:AD35) -> 9039 | AE36: =SUM(AE33:AE35) -> 5787 | AF36: =SUM(AF33:AF35) -> 628 | AG36: =SUM(AG33:AG35) -> 1526 | AH36: =SUM(AH33:AH35) -> 1041 | AI36: =SUM(AI33:AI35) -> 81 | AJ36: =SUM(AJ33:AJ35) -> 603 | ... BO36: =SUM(BO33:BO35) -> 0 | BP36: =SUM(B36:BO36) -> 96576 | BQ36: =SUM(BQ33:BQ35) -> 1
A37: % Where on Facebook/Instagram have you heard about Bird Buddy?
A38: I saw an ad | AC38: =iferror(AC33/AC$36,"") -> 0.81550969 | AD38: =iferror(AD33/AD$36,"") -> 0.86713132 | AE38: =iferror(AE33/AE$36,"") -> 0.84517021 | AF38: =iferror(AF33/AF$36,"") -> 0.72452229 | AG38: =iferror(AG33/AG$36,"") -> 0.71231979 | AH38: =iferror(AH33/AH$36,"") -> 0.73871278 | AI38: =iferror(AI33/AI$36,"") -> 0.7037037 | AJ38: =iferror(AJ33/AJ$36,"") -> 0.74792703 | ... BO38: =iferror(BO33/BO$36,"")
A39: I saw a post about Bird Buddy on my friend's feed | AC39: =iferror(AC34/AC$36,"") -> 0.06441526 | AD39: =iferror(AD34/AD$36,"") -> 0.054873327 | AE39: =iferror(AE34/AE$36,"") -> 0.066701227 | AF39: =iferror(AF34/AF$36,"") -> 0.1433121 | AG39: =iferror(AG34/AG$36,"") -> 0.12975098 | AH39: =iferror(AH34/AH$36,"") -> 0.093179635 | AI39: =iferror(AI34/AI$36,"") -> 0.20987654 | AJ39: =iferror(AJ34/AJ$36,"") -> 0.11608624 | ... BO39: =iferror(BO34/BO$36,"")
A40: I saw an organic post from Bird Buddy | AC40: =iferror(AC35/AC$36,"") -> 0.12007505 | AD40: =iferror(AD35/AD$36,"") -> 0.077995353 | AE40: =iferror(AE35/AE$36,"") -> 0.088128564 | AF40: =iferror(AF35/AF$36,"") -> 0.13216561 | AG40: =iferror(AG35/AG$36,"") -> 0.15792923 | AH40: =iferror(AH35/AH$36,"") -> 0.16810759 | AI40: =iferror(AI35/AI$36,"") -> 0.086419753 | AJ40: =iferror(AJ35/AJ$36,"") -> 0.13598673 | ... BO40: =iferror(BO35/BO$36,"")
A43: Who is this for?
A44: Just me | AD44: 581 | AE44: 1034 | AF44: 709 | AG44: 2194 | AH44: 1107 | AI44: 95 | AJ44: =sum(AJ115,AJ157) -> 430 | AK44: =sum(AK115,AK157) -> 249 | AL44: =sum(AL115,AL157) -> 323 | AM44: =sum(AM115,AM157) -> 256 | AN44: =sum(AN115,AN157) -> 120 | AO44: =sum(AO115,AO157) -> 299 | AP44: =sum(AP115,AP157) -> 1089 | AQ44: =sum(AQ115,AQ157) -> 1226 | ... BO44: =sum(BO115,BO157) -> 0 | BP44: =SUM(B44:BO44) -> 18017 | BQ44: =iferror(BP44/BP$48,"") -> 0.10101537
A45: My parents | AD45: 6391 | AE45: 10546 | AF45: 484 | AG45: 915 | AH45: 658 | AI45: 88 | AJ45: =sum(AJ116,AJ158) -> 969 | AK45: =sum(AK116,AK158) -> 477 | AL45: =sum(AL116,AL158) -> 200 | AM45: =sum(AM116,AM158) -> 181 | AN45: =sum(AN116,AN158) -> 78 | AO45: =sum(AO116,AO158) -> 174 | AP45: =sum(AP116,AP158) -> 8764 | AQ45: =sum(AQ116,AQ158) -> 10159 | ... BO45: =sum(BO116,BO158) -> 0 | BP45: =SUM(B45:BO45) -> 66021 | BQ45: =iferror(BP45/BP$48,"") -> 0.37015794
...

Sheet Overview

Sheet PP - Results %
B1: 2021 | H1: 2022 | T1: 2023 | AF1: 2024
A2: Post-purchase Survey | B2: 44392 | C2: 44419 | D2: 44446 | E2: 44473 | F2: 44527 | G2: 44554 | H2: 44581 | I2: 44608 | J2: 44635 | K2: 44662 | L2: 44689 | M2: 44716 | N2: 44743 | O2: 44797 | P2: 44824 | Q2: 44851 | R2: 44878 | S2: 44905 | T2: 44932 | U2: 44959 | V2: 44986 | W2: 45040 | X2: 45057 | Y2: 45098 | Z2: 45113 | AA2: 45155 | AB2: 45175 | AC2: 45217 | AD2: 45246 | AE2: 45266 | AF2: 45310 | AG2: 45330 | AH2: 45357 | AI2: 45399 | AJ2: 45427 | AK2: 45448 | AL2: 45484 | AM2: 45511 | AN2: 45540 | AO2: 45573 | AP2: 45607 | AQ2: 45637 | AR2: 45664 | AS2: 45692 | AT2: 45720 | AU2: 45748 | AV2: 45804 | AW2: 45832 | AX2: 45860 | AY2: 45888 | AZ2: 45916 | BA2: 45944 | BB2: 45972 | BC2: 46000 | BD2: 46028 | BE2: 46056 | BF2: 46112 | BG2: 46140 | BH2: 46168 | BI2: 46196 | BJ2: 46224 | BK2: 46252 | BL2: 46280 | BM2: 46308 | BN2: 46336 | BO2: 46357 | BP2: Total | BQ2: %
A3: All Customers
A5: % Where did you hear about Bird Buddy?
A6: Facebook / Instagram | B6: ='PP - Data'!B20 -> 0.83645184 | C6: ='PP - Data'!C20 -> 0.68617021 | D6: ='PP - Data'!D20 -> 0.56355932 | E6: ='PP - Data'!E20 -> 0.41563275 | F6: ='PP - Data'!F20 -> 0.59517426 | G6: ='PP - Data'!G20 -> 0.29215116 | H6: ='PP - Data'!H20 -> 0.21523579 | I6: ='PP - Data'!I20 -> 0.69031142 | ... BO6: ='PP - Data'!BO20
A7: Friends / Family | B7: ='PP - Data'!B21 -> 0.091476091 | C7: ='PP - Data'!C21 -> 0.18971631 | D7: ='PP - Data'!D21 -> 0.20338983 | E7: ='PP - Data'!E21 -> 0.08560794 | F7: ='PP - Data'!F21 -> 0.18900804 | G7: ='PP - Data'!G21 -> 0.18313953 | H7: ='PP - Data'!H21 -> 0.13905683 | I7: ='PP - Data'!I21 -> 0.10726644 | ... BO7: ='PP - Data'!BO21
A8: Google, Yahoo, Bing | B8: ='PP - Data'!B22 -> 0.026334026 | C8: ='PP - Data'!C22 -> 0.05141844 | D8: ='PP - Data'!D22 -> 0.12288136 | E8: ='PP - Data'!E22 -> 0.040942928 | F8: ='PP - Data'!F22 -> 0.091152815 | G8: ='PP - Data'!G22 -> 0.10465116 | H8: ='PP - Data'!H22 -> 0.11729141 | I8: ='PP - Data'!I22 -> 0.070934256 | ... BO8: ='PP - Data'!BO22
A9: Pinterest | B9: ='PP - Data'!B23 -> 0.026334026 | C9: ='PP - Data'!C23 -> 0.0053191489 | D9: ='PP - Data'!D23 -> 0.029661017 | E9: ='PP - Data'!E23 -> 0.0024813896 | F9: ='PP - Data'!F23 -> 0.012064343 | G9: ='PP - Data'!G23 -> 0.01744186 | H9: ='PP - Data'!H23 -> 0.0048367594 | I9: ='PP - Data'!I23 -> 0.0051903114 | ... BO9: ='PP - Data'!BO23
A10: TikTok | B10: ='PP - Data'!B24 -> 0.01039501 | C10: ='PP - Data'!C24 -> 0.015957447 | D10: ='PP - Data'!D24 -> 0.0042372881 | E10: ='PP - Data'!E24 -> 0.0049627792 | F10: ='PP - Data'!F24 -> 0.009383378 | G10: ='PP - Data'!G24 -> 0.0058139535 | H10: ='PP - Data'!H24 -> 0.0024183797 | I10: ='PP - Data'!I24 -> 0.0069204152 | ... BO10: ='PP - Data'!BO24
A11: TV / Radio | B11: ='PP - Data'!B25 -> 0.0076230076 | C11: ='PP - Data'!C25 -> 0.015957447 | D11: ='PP - Data'!D25 -> 0.016949153 | E11: ='PP - Data'!E25 -> 0.41811414 | F11: ='PP - Data'!F25 -> 0.04155496 | G11: ='PP - Data'!G25 -> 0.31540698 | H11: ='PP - Data'!H25 -> 0.10399033 | I11: ='PP - Data'!I25 -> 0.027681661 | ... BO11: ='PP - Data'!BO25
A12: Blog / Article | B12: ='PP - Data'!B26 -> 0.0013860014 | C12: ='PP - Data'!C26 -> 0.035460993 | D12: ='PP - Data'!D26 -> 0.059322034 | E12: ='PP - Data'!E26 -> 0.032258065 | F12: ='PP - Data'!F26 -> 0.061662198 | G12: ='PP - Data'!G26 -> 0.081395349 | H12: ='PP - Data'!H26 -> 0.4171705 | I12: ='PP - Data'!I26 -> 0.091695502 | ... AM12: ='PP - Data'!AM26 -> 0.076458753 | AO12: ='PP - Data'!AO26 -> 0.10394265 | AP12: ='PP - Data'!AP26 -> 0.021639976 | AQ12: ='PP - Data'!AQ26 -> 0.02606624 | AR12: ='PP - Data'!AR26 -> 0.052060134 | AS12: ='PP - Data'!AS26 -> 0.041500586 | AT12: ='PP - Data'!AT26 -> 0.044026501 | AU12: ='PP - Data'!AU26 -> 0.034789777 | AV12: ='PP - Data'!AV26 -> 0.038004323 | ... BO12: ='PP - Data'!BO26
A13: Google / Youtube | B13: ='PP - Data'!B27 | C13: ='PP - Data'!C27 | D13: ='PP - Data'!D27 | E13: ='PP - Data'!E27 | F13: ='PP - Data'!F27 | G13: ='PP - Data'!G27 | H13: ='PP - Data'!H27 | I13: ='PP - Data'!I27 | ... BO13: ='PP - Data'!BO27
A14: Reddit | B14: ='PP - Data'!B28 | C14: ='PP - Data'!C28 | D14: ='PP - Data'!D28 | E14: ='PP - Data'!E28 | F14: ='PP - Data'!F28 | G14: ='PP - Data'!G28 | H14: ='PP - Data'!H28 | I14: ='PP - Data'!I28 | ... BO14: ='PP - Data'!BO28
A15: Yahoo / Bing | B15: ='PP - Data'!B29 | C15: ='PP - Data'!C29 | D15: ='PP - Data'!D29 | E15: ='PP - Data'!E29 | F15: ='PP - Data'!F29 | G15: ='PP - Data'!G29 | H15: ='PP - Data'!H29 | I15: ='PP - Data'!I29 | ... BO15: ='PP - Data'!BO29
A18: % Where on Facebook/Instagram have you heard about Bird Buddy?
A19: I saw an ad | B19: ='PP - Data'!B38 | C19: ='PP - Data'!C38 | D19: ='PP - Data'!D38 | E19: ='PP - Data'!E38 | F19: ='PP - Data'!F38 | G19: ='PP - Data'!G38 | H19: ='PP - Data'!H38 | I19: ='PP - Data'!I38 | ... AA19: ='PP - Data'!AA38 | AB19: I saw an ad | AC19: ='PP - Data'!AC38 -> 0.81550969 | AD19: ='PP - Data'!AD38 -> 0.86713132 | AE19: ='PP - Data'!AE38 -> 0.84517021 | AF19: ='PP - Data'!AF38 -> 0.72452229 | AG19: ='PP - Data'!AG38 -> 0.71231979 | AH19: ='PP - Data'!AH38 -> 0.73871278 | AI19: ='PP - Data'!AI38 -> 0.7037037 | AJ19: ='PP - Data'!AJ38 -> 0.74792703 | ... BO19: ='PP - Data'!BO38
A20: I saw a post about Bird Buddy on my friend's feed | B20: ='PP - Data'!B39 | C20: ='PP - Data'!C39 | D20: ='PP - Data'!D39 | E20: ='PP - Data'!E39 | F20: ='PP - Data'!F39 | G20: ='PP - Data'!G39 | H20: ='PP - Data'!H39 | I20: ='PP - Data'!I39 | ... AA20: ='PP - Data'!AA39 | AB20: I saw a post about Bird Buddy on my friend's feed | AC20: ='PP - Data'!AC39 -> 0.06441526 | AD20: ='PP - Data'!AD39 -> 0.054873327 | AE20: ='PP - Data'!AE39 -> 0.066701227 | AF20: ='PP - Data'!AF39 -> 0.1433121 | AG20: ='PP - Data'!AG39 -> 0.12975098 | AH20: ='PP - Data'!AH39 -> 0.093179635 | AI20: ='PP - Data'!AI39 -> 0.20987654 | AJ20: ='PP - Data'!AJ39 -> 0.11608624 | ... BO20: ='PP - Data'!BO39
A21: I saw an organic post from Bird Buddy | B21: ='PP - Data'!B40 | C21: ='PP - Data'!C40 | D21: ='PP - Data'!D40 | E21: ='PP - Data'!E40 | F21: ='PP - Data'!F40 | G21: ='PP - Data'!G40 | H21: ='PP - Data'!H40 | I21: ='PP - Data'!I40 | ... AA21: ='PP - Data'!AA40 | AB21: I saw an organic post from Bird Buddy | AC21: ='PP - Data'!AC40 -> 0.12007505 | AD21: ='PP - Data'!AD40 -> 0.077995353 | AE21: ='PP - Data'!AE40 -> 0.088128564 | AF21: ='PP - Data'!AF40 -> 0.13216561 | AG21: ='PP - Data'!AG40 -> 0.15792923 | AH21: ='PP - Data'!AH40 -> 0.16810759 | AI21: ='PP - Data'!AI40 -> 0.086419753 | AJ21: ='PP - Data'!AJ40 -> 0.13598673 | ... BO21: ='PP - Data'!BO40
A24: % Who is this for?
A25: Just me | B25: ='PP - Data'!B50 | C25: ='PP - Data'!C50 | D25: ='PP - Data'!D50 | E25: ='PP - Data'!E50 | F25: ='PP - Data'!F50 | G25: ='PP - Data'!G50 | H25: ='PP - Data'!H50 | I25: ='PP - Data'!I50 | ... AB25: ='PP - Data'!AB50 | AC25: Just me | AD25: ='PP - Data'!AD50 -> 0.046719202 | AE25: ='PP - Data'!AE50 -> 0.045990304 | AF25: ='PP - Data'!AF50 -> 0.28716079 | AG25: ='PP - Data'!AG50 -> 0.31922014 | AH25: ='PP - Data'!AH50 -> 0.28663905 | AI25: ='PP - Data'!AI50 -> 0.24547804 | AJ25: ='PP - Data'!AJ50 -> 0.17022961 | AK25: ='PP - Data'!AK50 -> 0.17031464 | ... BO25: ='PP - Data'!BO50
A26: My parents | B26: ='PP - Data'!B51 | C26: ='PP - Data'!C51 | D26: ='PP - Data'!D51 | E26: ='PP - Data'!E51 | F26: ='PP - Data'!F51 | G26: ='PP - Data'!G51 | H26: ='PP - Data'!H51 | I26: ='PP - Data'!I51 | ... AB26: ='PP - Data'!AB51 | AC26: My parents | AD26: ='PP - Data'!AD51 -> 0.51391123 | AE26: ='PP - Data'!AE51 -> 0.46906552 | AF26: ='PP - Data'!AF51 -> 0.19603078 | AG26: ='PP - Data'!AG51 -> 0.13312964 | AH26: ='PP - Data'!AH51 -> 0.17037804 | AI26: ='PP - Data'!AI51 -> 0.22739018 | AJ26: ='PP - Data'!AJ51 -> 0.38361045 | AK26: ='PP - Data'!AK51 -> 0.32626539 | ... BO26: ='PP - Data'!BO51
A27: Spouse | B27: ='PP - Data'!B52 | C27: ='PP - Data'!C52 | D27: ='PP - Data'!D52 | E27: ='PP - Data'!E52 | F27: ='PP - Data'!F52 | G27: ='PP - Data'!G52 | H27: ='PP - Data'!H52 | I27: ='PP - Data'!I52 | ... AB27: ='PP - Data'!AB52 | AC27: Spouse | AD27: ='PP - Data'!AD52 -> 0.25450306 | AE27: ='PP - Data'!AE52 -> 0.29800294 | AF27: ='PP - Data'!AF52 -> 0.20534629 | AG27: ='PP - Data'!AG52 -> 0.17372326 | AH27: ='PP - Data'!AH52 -> 0.20326256 | AI27: ='PP - Data'!AI52 -> 0.2118863 | AJ27: ='PP - Data'!AJ52 -> 0.24228029 | AK27: ='PP - Data'!AK52 -> 0.24623803 | ... BO27: ='PP - Data'!BO52
A28: I will use with my family | B28: ='PP - Data'!B53 | C28: ='PP - Data'!C53 | D28: ='PP - Data'!D53 | E28: ='PP - Data'!E53 | F28: ='PP - Data'!F53 | G28: ='PP - Data'!G53 | H28: ='PP - Data'!H53 | I28: ='PP - Data'!I53 | ... AB28: ='PP - Data'!AB53 | AC28: I will use with my family | AD28: ='PP - Data'!AD53 -> 0.18486652 | AE28: ='PP - Data'!AE53 -> 0.18694124 | AF28: ='PP - Data'!AF53 -> 0.31146213 | AG28: ='PP - Data'!AG53 -> 0.37392696 | AH28: ='PP - Data'!AH53 -> 0.33972035 | AI28: ='PP - Data'!AI53 -> 0.31524548 | AJ28: ='PP - Data'!AJ53 -> 0.20387965 | AK28: ='PP - Data'!AK53 -> 0.25718194 | ... BO28: ='PP - Data'!BO53
A31: % Did you buy this for your household?
A32: Yes | B32: ='PP - Data'!B61 | C32: ='PP - Data'!C61 | D32: ='PP - Data'!D61 | E32: ='PP - Data'!E61 | F32: ='PP - Data'!F61 | G32: ='PP - Data'!G61 | H32: ='PP - Data'!H61 | I32: ='PP - Data'!I61 | ... AI32: ='PP - Data'!AI61 | AJ32: Yes | AK32: ='PP - Data'!AK61 -> 0.65178571 | AL32: ='PP - Data'!AL61 -> 0.78154917 | AM32: ='PP - Data'!AM61 -> 0.75352113 | AN32: ='PP - Data'!AN61 -> 0.73363431 | AO32: ='PP - Data'!AO61 -> 0.79749104 | AP32: ='PP - Data'!AP61 -> 0.53268802 | AQ32: ='PP - Data'!AQ61 -> 0.53230252 | AR32: ='PP - Data'!AR61 -> 0.81041203 | ... BO32: ='PP - Data'!BO61
A33: No | B33: ='PP - Data'!B62 | C33: ='PP - Data'!C62 | D33: ='PP - Data'!D62 | E33: ='PP - Data'!E62 | F33: ='PP - Data'!F62 | G33: ='PP - Data'!G62 | H33: ='PP - Data'!H62 | I33: ='PP - Data'!I62 | ... AI33: ='PP - Data'!AI62 | AJ33: No | AK33: ='PP - Data'!AK62 -> 0.34821429 | AL33: ='PP - Data'!AL62 -> 0.21845083 | AM33: ='PP - Data'!AM62 -> 0.24647887 | AN33: ='PP - Data'!AN62 -> 0.26636569 | AO33: ='PP - Data'!AO62 -> 0.20250896 | AP33: ='PP - Data'!AP62 -> 0.46731198 | AQ33: ='PP - Data'!AQ62 -> 0.46769748 | AR33: ='PP - Data'!AR62 -> 0.18958797 | ... BO33: ='PP - Data'!BO62
A35: % Did you buy this as a gift?
A36: Yes | B36: ='PP - Data'!B69 | C36: ='PP - Data'!C69 | D36: ='PP - Data'!D69 | E36: ='PP - Data'!E69 | F36: ='PP - Data'!F69 | G36: ='PP - Data'!G69 | H36: ='PP - Data'!H69 | I36: ='PP - Data'!I69 | ... AI36: ='PP - Data'!AI69 | AJ36: Yes | AK36: ='PP - Data'!AK69 -> 0.67633929 | AL36: ='PP - Data'!AL69 -> 0.46214099 | AM36: ='PP - Data'!AM69 -> 0.49698189 | AN36: ='PP - Data'!AN69 -> 0.503386 | AO36: ='PP - Data'!AO69 -> 0.48297491 | AP36: ='PP - Data'!AP69 -> 0.91399757 | AQ36: ='PP - Data'!AQ69 -> 0.90559163 | AR36: ='PP - Data'!AR69 -> 0.43930958 | ... BO36: ='PP - Data'!BO69
A37: No | B37: ='PP - Data'!B70 | C37: ='PP - Data'!C70 | D37: ='PP - Data'!D70 | E37: ='PP - Data'!E70 | F37: ='PP - Data'!F70 | G37: ='PP - Data'!G70 | H37: ='PP - Data'!H70 | I37: ='PP - Data'!I70 | ... AI37: ='PP - Data'!AI70 | AJ37: No | AK37: ='PP - Data'!AK70 -> 0.32366071 | AL37: ='PP - Data'!AL70 -> 0.53785901 | AM37: ='PP - Data'!AM70 -> 0.50301811 | AN37: ='PP - Data'!AN70 -> 0.496614 | AO37: ='PP - Data'!AO70 -> 0.51702509 | AP37: ='PP - Data'!AP70 -> 0.086002433 | AQ37: ='PP - Data'!AQ70 -> 0.094408371 | AR37: ='PP - Data'!AR70 -> 0.56069042 | ... BO37: ='PP - Data'!BO70
A39: % Are you a new or existing customer?
A40: New customer | B40: ='PP - Data'!B77 | C40: ='PP - Data'!C77 | D40: ='PP - Data'!D77 | E40: ='PP - Data'!E77 | F40: ='PP - Data'!F77 | G40: ='PP - Data'!G77 | H40: ='PP - Data'!H77 | I40: ='PP - Data'!I77 | ... AH40: ='PP - Data'!AH77 | AI40: New customer | AJ40: ='PP - Data'!AJ77 -> 0.56769596 | AK40: ='PP - Data'!AK77 -> 0.61764706 | AL40: ='PP - Data'!AL77 -> 0.45343777 | AM40: ='PP - Data'!AM77 -> 0.42655936 | AN40: ='PP - Data'!AN77 -> 0.50564334 | AO40: ='PP - Data'!AO77 -> 0.42831541 | AP40: ='PP - Data'!AP77 -> 0.91693696 | AQ40: ='PP - Data'!AQ77 -> 0.87135049 | ... BO40: ='PP - Data'!BO77
A41: Existing customer | B41: ='PP - Data'!B78 | C41: ='PP - Data'!C78 | D41: ='PP - Data'!D78 | E41: ='PP - Data'!E78 | F41: ='PP - Data'!F78 | G41: ='PP - Data'!G78 | H41: ='PP - Data'!H78 | I41: ='PP - Data'!I78 | ... AH41: ='PP - Data'!AH78 | AI41: Existing customer | AJ41: ='PP - Data'!AJ78 -> 0.43230404 | AK41: ='PP - Data'!AK78 -> 0.38235294 | AL41: ='PP - Data'!AL78 -> 0.54656223 | AM41: ='PP - Data'!AM78 -> 0.57344064 | AN41: ='PP - Data'!AN78 -> 0.49435666 | AO41: ='PP - Data'!AO78 -> 0.57168459 | AP41: ='PP - Data'!AP78 -> 0.083063045 | AQ41: ='PP - Data'!AQ78 -> 0.12864951 | ... BO41: ='PP - Data'!BO78
A43: % Will Bird Buddy be the first bird feeder in your yard?
A44: Yes | AR44: Yes | AS44: ='PP - Data'!AS85 -> 0.31632653 | AT44: ='PP - Data'!AT85 -> 0.26779226 | AU44: ='PP - Data'!AU85 -> 0.32497939 | AV44: ='PP - Data'!AV85 -> 0.35338617 | AW44: ='PP - Data'!AW85 -> 0.41780822 | AX44: ='PP - Data'!AX85 -> 0.36953456 | AY44: ='PP - Data'!AY85 -> 0.33581584 | AZ44: ='PP - Data'!AZ85 -> 0.13194851 | ... BO44: ='PP - Data'!BO85
A45: No | AR45: No | AS45: ='PP - Data'!AS86 -> 0.68367347 | AT45: ='PP - Data'!AT86 -> 0.73220774 | AU45: ='PP - Data'!AU86 -> 0.67502061 | AV45: ='PP - Data'!AV86 -> 0.64661383 | AW45: ='PP - Data'!AW86 -> 0.58219178 | AX45: ='PP - Data'!AX86 -> 0.63046544 | AY45: ='PP - Data'!AY86 -> 0.66418416 | AZ45: ='PP - Data'!AZ86 -> 0.86805149 | ... BO45: ='PP - Data'!BO86
A47: How old are you?
A48: 18-24 | AO48: 18-24 | AP48: ='PP - Data'!AP97 -> 0.024618567 | AQ48: ='PP - Data'!AQ97 -> 0.033680572 | AR48: ='PP - Data'!AR97 -> 0.014755011 | AS48: ='PP - Data'!AS97 -> 0.015943728 | AT48: ='PP - Data'!AT97 -> 0.011540928 | AU48: ='PP - Data'!AU97 -> 0.018136851 | AV48: ='PP - Data'!AV97 -> 0.023775216 | AW48: ='PP - Data'!AW97 -> 0.020547945 | ... BO48: ='PP - Data'!BO97
A49: 25-34 | AO49: 25-34 | AP49: ='PP - Data'!AP98 -> 0.14290147 | AQ49: ='PP - Data'!AQ98 -> 0.16620732 | AR49: ='PP - Data'!AR98 -> 0.077394209 | AS49: ='PP - Data'!AS98 -> 0.095427902 | AT49: ='PP - Data'!AT98 -> 0.073092541 | AU49: ='PP - Data'!AU98 -> 0.11821929 | AV49: ='PP - Data'!AV98 -> 0.1273415 | AW49: ='PP - Data'!AW98 -> 0.11904762 | ... BO49: ='PP - Data'!BO98
A50: 35-44 | AO50: 35-44 | AP50: ='PP - Data'!AP99 -> 0.26237393 | AQ50: ='PP - Data'!AQ99 -> 0.26444621 | AR50: ='PP - Data'!AR99 -> 0.17845212 | AS50: ='PP - Data'!AS99 -> 0.19109027 | AT50: ='PP - Data'!AT99 -> 0.19683693 | AU50: ='PP - Data'!AU99 -> 0.21566364 | AV50: ='PP - Data'!AV99 -> 0.24855908 | AW50: ='PP - Data'!AW99 -> 0.24200913 | ... BO50: ='PP - Data'!BO99
A51: 45-54 | AO51: 45-54 | AP51: ='PP - Data'!AP100 -> 0.27008017 | AQ51: ='PP - Data'!AQ100 -> 0.24977811 | AR51: ='PP - Data'!AR100 -> 0.22717149 | AS51: ='PP - Data'!AS100 -> 0.21617819 | AT51: ='PP - Data'!AT100 -> 0.21970507 | AU51: ='PP - Data'!AU100 -> 0.23198681 | AV51: ='PP - Data'!AV100 -> 0.25450288 | AW51: ='PP - Data'!AW100 -> 0.25081539 | ... BO51: ='PP - Data'!BO100
...

Sheet PP - Data (YEARLY)
A1: Post-purchase Survey | B1: 2021 | C1: 2022 | D1: 2023 | E1: 2024 | F1: 2025 | G1: 2026 | H1: Total | I1: %
A2: DTC Orders (wo renewals) | B2: =sum('PP - Data'!B3:G3) -> 8048 | C2: =sum('PP - Data'!H3:S3) -> 49689 | D2: =sum('PP - Data'!T3:AE3) -> 117142 | E2: =sum('PP - Data'!AF3:AQ3) -> 120235 | F2: =sum('PP - Data'!AR3:BC3) -> 155414 | G2: =sum('PP - Data'!BD3:BO3) -> 35336
A3: Response rate (%) | B3: =B17/B2 -> 0.5570328 | C3: =C17/C2 -> 0.37390569 | D3: =D17/D2 -> 0.4823206 | E3: =E17/E2 -> 0.5144675 | F3: =F17/F2 -> 0.50474217 | G3: =G17/G2 -> 0.52433779
A4: All Customers
A6: Where did you hear about Bird Buddy?
A7: Facebook / Instagram | B7: =SUM('PP - Data'!B8:G8) -> 2707 | C7: =SUM('PP - Data'!H8:S8) -> 11102 | D7: =sum('PP - Data'!T8:AE8) -> 25875 | E7: =sum('PP - Data'!AF8:AQ8) -> 32628 | F7: =sum('PP - Data'!AR8:BC8) -> 41295 | G7: =sum('PP - Data'!BD8:BO8) -> 6580 | H7: =SUM(B7:G7) -> 120187 | I7: =iferror(H7/$H$17,"") -> 0.50415913
A8: Friends / Family | B8: =SUM('PP - Data'!B9:G9) -> 623 | C8: =SUM('PP - Data'!H9:S9) -> 3554 | D8: =sum('PP - Data'!T9:AE9) -> 19727 | E8: =sum('PP - Data'!AF9:AQ9) -> 20120 | F8: =sum('PP - Data'!AR9:BC9) -> 25680 | G8: =sum('PP - Data'!BD9:BO9) -> 9028 | H8: =SUM(B8:G8) -> 78732 | I8: =iferror(H8/$H$17,"") -> 0.33026415
A9: Google, Yahoo, Bing | B9: =SUM('PP - Data'!B10:G10) -> 269 | C9: =SUM('PP - Data'!H10:S10) -> 782 | D9: =sum('PP - Data'!T10:AE10) -> 269 | H9: =SUM(B9:G9) -> 1320 | I9: =iferror(H9/$H$17,"") -> 0.0055371218
A10: Pinterest | B10: =SUM('PP - Data'!B11:G11) -> 71 | C10: =SUM('PP - Data'!H11:S11) -> 69 | D10: =sum('PP - Data'!T11:AE11) -> 18 | H10: =SUM(B10:G10) -> 158 | I10: =iferror(H10/$H$17,"") -> 0.0006627767
A11: TikTok | B11: =SUM('PP - Data'!B12:G12) -> 40 | C11: =SUM('PP - Data'!H12:S12) -> 1824 | D11: =sum('PP - Data'!T12:AE12) -> 1256 | E11: =sum('PP - Data'!AF12:AQ12) -> 1275 | F11: =sum('PP - Data'!AR12:BC12) -> 1366 | G11: =sum('PP - Data'!BD12:BO12) -> 219 | H11: =SUM(B11:G11) -> 5980 | I11: =iferror(H11/$H$17,"") -> 0.02508484
A12: TV / Radio | B12: =SUM('PP - Data'!B13:G13) -> 609 | C12: =SUM('PP - Data'!H13:S13) -> 283 | D12: =sum('PP - Data'!T13:AE13) -> 1974 | E12: =sum('PP - Data'!AF13:AQ13) -> 842 | F12: =sum('PP - Data'!AR13:BC13) -> 982 | G12: =sum('PP - Data'!BD13:BO13) -> 201 | H12: =SUM(B12:G12) -> 4891 | I12: =iferror(H12/$H$17,"") -> 0.020516714
A13: Blog / Article | B13: =SUM('PP - Data'!B14:G14) -> 164 | C13: =SUM('PP - Data'!H14:S14) -> 959 | D13: =sum('PP - Data'!T14:AE14) -> 3521 | E13: =sum('PP - Data'!AF14:AQ14) -> 2423 | F13: =sum('PP - Data'!AR14:BC14) -> 2608 | G13: =sum('PP - Data'!BD14:BO14) -> 718 | H13: =SUM(B13:G13) -> 10393 | I13: =iferror(H13/$H$17,"") -> 0.043596444
A14: Google / Youtube | C14: =SUM('PP - Data'!H15:S15) -> 6 | D14: =sum('PP - Data'!T15:AE15) -> 3323 | E14: =sum('PP - Data'!AF15:AQ15) -> 3921 | F14: =sum('PP - Data'!AR15:BC15) -> 5580 | G14: =sum('PP - Data'!BD15:BO15) -> 1535 | H14: =SUM(B14:G14) -> 14365 | I14: =iferror(H14/$H$17,"") -> 0.060258147
A15: Reddit | D15: =sum('PP - Data'!T16:AE16) -> 397 | E15: =sum('PP - Data'!AF16:AQ16) -> 476 | F15: =sum('PP - Data'!AR16:BC16) -> 715 | G15: =sum('PP - Data'!BD16:BO16) -> 189 | H15: =SUM(B15:G15) -> 1777 | I15: =iferror(H15/$H$17,"") -> 0.0074541405
A16: Yahoo / Bing | D16: =sum('PP - Data'!T17:AE17) -> 140 | E16: =sum('PP - Data'!AF17:AQ17) -> 172 | F16: =sum('PP - Data'!AR17:BC17) -> 218 | G16: =sum('PP - Data'!BD17:BO17) -> 58 | H16: =SUM(B16:G16) -> 588 | I16: =iferror(H16/$H$17,"") -> 0.0024665361
A17: Total submissions: | B17: =SUM(B7:B16) -> 4483 | C17: =SUM(C7:C16) -> 18579 | D17: =SUM(D7:D16) -> 56500 | E17: =SUM(E7:E16) -> 61857 | F17: =SUM(F7:F16) -> 78444 | G17: =SUM(G7:G16) -> 18528 | H17: =SUM(B17:G17) -> 238391 | I17: =SUM(I7:I15) -> 0.99753346
A18: % Where did you hear about Bird Buddy?
A19: Facebook / Instagram | B19: =iferror(B7/B$17,"") -> 0.60383672 | C19: =iferror(C7/C$17,"") -> 0.59755638 | D19: =iferror(D7/D$17,"") -> 0.4579646 | E19: =iferror(E7/E$17,"") -> 0.52747466 | F19: =iferror(F7/F$17,"") -> 0.5264265 | G19: =iferror(G7/G$17,"") -> 0.35513817
A20: Friends / Family | B20: =iferror(B8/B$17,"") -> 0.13896944 | C20: =iferror(C8/C$17,"") -> 0.19129124 | D20: =iferror(D8/D$17,"") -> 0.34915044 | E20: =iferror(E8/E$17,"") -> 0.32526634 | F20: =iferror(F8/F$17,"") -> 0.32736729 | G20: =iferror(G8/G$17,"") -> 0.48726252
A21: Google, Yahoo, Bing | B21: =iferror(B9/B$17,"") -> 0.060004461 | C21: =iferror(C9/C$17,"") -> 0.042090532 | D21: =iferror(D9/D$17,"") -> 0.0047610619
A22: Pinterest | B22: =iferror(B10/B$17,"") -> 0.015837609 | C22: =iferror(C10/C$17,"") -> 0.0037138705 | D22: =iferror(D10/D$17,"") -> 0.00031858407
A23: TikTok | B23: =iferror(B11/B$17,"") -> 0.0089225965 | C23: =iferror(C11/C$17,"") -> 0.098175359 | D23: =iferror(D11/D$17,"") -> 0.022230088 | E23: =iferror(E11/E$17,"") -> 0.020612057 | F23: =iferror(F11/F$17,"") -> 0.017413696 | G23: =iferror(G11/G$17,"") -> 0.011819948
A24: TV / Radio | B24: =iferror(B12/B$17,"") -> 0.13584653 | C24: =iferror(C12/C$17,"") -> 0.015232251 | D24: =iferror(D12/D$17,"") -> 0.034938053 | E24: =iferror(E12/E$17,"") -> 0.013612041 | F24: =iferror(F12/F$17,"") -> 0.012518485 | G24: =iferror(G12/G$17,"") -> 0.010848446
A25: Blog / Article | B25: =iferror(B13/B$17,"") -> 0.036582646 | C25: =iferror(C13/C$17,"") -> 0.051617418 | D25: =iferror(D13/D$17,"") -> 0.062318584 | E25: =iferror(E13/E$17,"") -> 0.039170991 | F25: =iferror(F13/F$17,"") -> 0.033246647 | G25: =iferror(G13/G$17,"") -> 0.038752159
A26: Google / Youtube | C26: =iferror(C14/C$17,"") -> 0.00032294526 | D26: =iferror(D14/D$17,"") -> 0.058814159 | E26: =iferror(E14/E$17,"") -> 0.063388137 | F26: =iferror(F14/F$17,"") -> 0.071133548 | G26: =iferror(G14/G$17,"") -> 0.082847582
A27: Reddit | D27: =iferror(D15/D$17,"") -> 0.0070265487 | E27: =iferror(E15/E$17,"") -> 0.0076951679 | F27: =iferror(F15/F$17,"") -> 0.0091147825 | G27: =iferror(G15/G$17,"") -> 0.010200777
A28: Yahoo / Bing | D28: =iferror(D16/D$17,"") -> 0.0024778761 | E28: =iferror(E16/E$17,"") -> 0.0027806069 | F28: =iferror(F16/F$17,"") -> 0.0027790526 | G28: =iferror(G16/G$17,"") -> 0.0031303972
A31: Where on Facebook/Instagram have you heard about Bird Buddy?
A32: I saw an ad | D32: =SUM('PP - Data'!AC33:AE33) -> 14033 | E32: =SUM('PP - Data'!AF33:AQ33) -> 27083 | F32: =SUM('PP - Data'!AR33:BC33) -> 34324 | G32: =SUM('PP - Data'!BD33:BO33) -> 5172 | H32: =SUM(B32:G32) -> 80612 | I32: =iferror(H32/H$35,"") -> 0.83470013
A33: I saw a post about Bird Buddy on my friend's feed | D33: =SUM('PP - Data'!AC34:AE34) -> 985 | E33: =SUM('PP - Data'!AF34:AQ34) -> 1826 | F33: =SUM('PP - Data'!AR34:BC34) -> 2303 | G33: =SUM('PP - Data'!BD34:BO34) -> 506 | H33: =SUM(B33:G33) -> 5620 | I33: =iferror(H33/H$35,"") -> 0.058192512
A34: I saw an organic post from Bird Buddy | D34: =SUM('PP - Data'!AC35:AE35) -> 1407 | E34: =SUM('PP - Data'!AF35:AQ35) -> 3366 | F34: =SUM('PP - Data'!AR35:BC35) -> 4669 | G34: =SUM('PP - Data'!BD35:BO35) -> 902 | H34: =SUM(B34:G34) -> 10344 | I34: =iferror(H34/H$35,"") -> 0.10710736
A35: Total submissions: | D35: =SUM(D32:D34) -> 16425 | E35: =SUM(E32:E34) -> 32275 | F35: =SUM(F32:F34) -> 41296 | G35: =SUM(G32:G34) -> 6580 | H35: =SUM(B35:G35) -> 96576 | I35: =SUM(I32:I34) -> 1
A36: % Where on Facebook/Instagram have you heard about Bird Buddy?
A37: I saw an ad | C37: I saw an ad | D37: =iferror(D32/D$35,"") -> 0.85436834 | E37: =iferror(E32/E$35,"") -> 0.83913246 | F37: =iferror(F32/F$35,"") -> 0.83117009 | G37: =iferror(G32/G$35,"") -> 0.78601824
A38: I saw a post about Bird Buddy on my friend's feed | C38: I saw a post about Bird Buddy on my friend's feed | D38: =iferror(D33/D$35,"") -> 0.059969559 | E38: =iferror(E33/E$35,"") -> 0.056576297 | F38: =iferror(F33/F$35,"") -> 0.055768113 | G38: =iferror(G33/G$35,"") -> 0.076899696
A39: I saw an organic post from Bird Buddy | C39: I saw an organic post from Bird Buddy | D39: =iferror(D34/D$35,"") -> 0.0856621 | E39: =iferror(E34/E$35,"") -> 0.10429125 | F39: =iferror(F34/F$35,"") -> 0.1130618 | G39: =iferror(G34/G$35,"") -> 0.13708207
A42: Who is this for?
A43: Just me | D43: =sum('PP - Data'!AD44:AE44) -> 1615 | E43: =sum('PP - Data'!AF44:AQ44) -> 8097 | F43: =sum('PP - Data'!AR44:BC44) -> 8016 | G43: =sum('PP - Data'!BD44:BO44) -> 289 | H43: =SUM(B43:G43) -> 18017 | I43: =iferror(H43/H$47,"") -> 0.10101537
A44: My parents | D44: =sum('PP - Data'!AD45:AE45) -> 16937 | E44: =sum('PP - Data'!AF45:AQ45) -> 23147 | F44: =sum('PP - Data'!AR45:BC45) -> 23227 | G44: =sum('PP - Data'!BD45:BO45) -> 2710 | H44: =SUM(B44:G44) -> 66021 | I44: =iferror(H44/H$47,"") -> 0.37015794
A45: Spouse | D45: =sum('PP - Data'!AD46:AE46) -> 9865 | E45: =sum('PP - Data'!AF46:AQ46) -> 17122 | F45: =sum('PP - Data'!AR46:BC46) -> 23861 | G45: =sum('PP - Data'!BD46:BO46) -> 4293 | H45: =SUM(B45:G45) -> 55141 | I45: =iferror(H45/H$47,"") -> 0.30915737
...

Sheet Where did you hear about Bird B

Sheet Where on FacebookInstagram have

Sheet Demographic Qs

Sheet Other Qs

Sheet New vs. Existing Costumers
