Workbook
Name zsupermetrics_qWp7V908pNEYMtfv8QZvSTeDnBAHOU: 'Business Metrics Canada'!$B$14:$C$23
Name zsupermetrics_BioPyGBzcBsy60UCQmPcTuFReEmghI: 'Business Metrics EU'!$B$5:$B$12
Name rdataslayer_3753ddf3234e496aa261974a0222e193: 'Business Metrics Canada'!$H$5:$I$5
Name zsupermetrics_ru0GDtbZzDLHQOQtJJ6K08MvUDyyp7: Formulas!$B$5:$B$6
Name zsupermetrics_qWp7V908pNEYMtfv8QZvSTeDnBAHOU: 'Business Metrics US'!$B$14:$C$23
Name zsupermetrics_HgZqhorObHOtZHuyJjpmyYaEPoYntx: 'Business Metrics US'!$B$13:$B$14
Name zsupermetrics_ru0GDtbZzDLHQOQtJJ6K08MvUDyyp7: 'Business Metrics Canada'!$B$13:$B$14
Name zsupermetrics_refreshAll: SupermetricsQueries!$H$5
Name zsupermetrics_n3GtLgiKpTmd2pYmQNMuq6TPD0qE0b: Formulas!$B$5:$B$6
Name zsupermetrics_BioPyGBzcBsy60UCQmPcTuFReEmghI: 'Business Metrics US'!$B$5:$B$12
Name rdataslayer_4a0f150f4f2f4e4f85c890c75b7a1fa4: 'Business Metrics EU'!$D$5:$E$12
Name zsupermetrics_DQl8lUbpTRu3fayaJJi7lVfOGKjNU4: 'Business Metrics US'!$A$2:$A$13
Name zsupermetrics_refreshAllSilent: SupermetricsQueries!$H$6
Name zsupermetrics_wbYMmT0YL9bAN0yhimW0ziPFnia9Dx: 'Business Metrics US'!$A$5:$A$12
Name zsupermetrics_Mgms9p0QzysYvrIhnsKACeVBVxfIEO: Formulas!$A$3:$A$4
Name zsupermetrics_ru0GDtbZzDLHQOQtJJ6K08MvUDyyp7: 'Business Metrics US'!$B$13:$B$14
Name zsupermetrics_forceRefresh: SupermetricsQueries!$H$4
Name zsupermetrics_4VkB7ij7WO0JjKBEgvjB2GHjSy2Egm: 'Business Metrics EU'!$B$13:$C$17
Name zsupermetrics_wbYMmT0YL9bAN0yhimW0ziPFnia9Dx: Formulas!$A$3:$A$4
Name zsupermetrics_iNpyVy90bWCI0yUaFQpxOtzWMa6sW4: Formulas!$A$3:$A$4
Name zsupermetrics_9i4W4hgd80uRpQLMeX0eRnESN8gjyv: Formulas!$C$14
Name zsupermetrics_9i4W4hgd80uRpQLMeX0eRnESN8gjyv: 'Business Metrics Canada'!$C$23
Name zsupermetrics_YsFuuYtr8vOdNXCCPiFJIO38NP4b2T: 'Business Metrics US'!$B$13:$C$23
Name zsupermetrics_iNpyVy90bWCI0yUaFQpxOtzWMa6sW4: 'Business Metrics Canada'!$A$5:$A$12
Name rdataslayer_adf57e64065742daa5b4161161b1c3ca: 'Business Metrics US'!$B$13:$D$14
Name zsupermetrics_xwoIpANxRm908eDp5oKTwQpEI8gvD4: 'Business Metrics US'!$A$5
Name zsupermetrics_pxuhRTEmIU93xSgKclyxajD0fCZ6rF: #REF!
Name zsupermetrics_DQl8lUbpTRu3fayaJJi7lVfOGKjNU4: 'Business Metrics Canada'!$A$2:$A$13
Name zsupermetrics_DQl8lUbpTRu3fayaJJi7lVfOGKjNU4: 'Business Metrics EU'!$A$2:$A$13
Name rdataslayer_4a0f150f4f2f4e4f85c890c75b7a1fa4: Formulas!$D$3:$E$4
Name zsupermetrics_4VkB7ij7WO0JjKBEgvjB2GHjSy2Egm: 'Business Metrics US'!$B$13:$C$17
Name rdataslayer_d70e473bcafe40a3aa834ce157fb2ba3: 'Business Metrics EU'!$C$16:$D$17
Name zsupermetrics_n3GtLgiKpTmd2pYmQNMuq6TPD0qE0b: 'Business Metrics Canada'!$B$13:$B$14
Name zsupermetrics_HgZqhorObHOtZHuyJjpmyYaEPoYntx: Formulas!$B$5:$B$6
Name zsupermetrics_YsFuuYtr8vOdNXCCPiFJIO38NP4b2T: Formulas!$B$5:$C$14
Name zsupermetrics_DQl8lUbpTRu3fayaJJi7lVfOGKjNU4: Formulas!$A$4:$A$5
Name zsupermetrics_YsFuuYtr8vOdNXCCPiFJIO38NP4b2T: 'Business Metrics Canada'!$B$13:$C$23
Name zsupermetrics_4VkB7ij7WO0JjKBEgvjB2GHjSy2Egm: Formulas!$B$5:$C$11
Name zsupermetrics_n3GtLgiKpTmd2pYmQNMuq6TPD0qE0b: 'Business Metrics US'!$B$13:$B$14
Name rdataslayer_42b112e4e4be4305bb4c1be75e2dd549: 'Business Metrics US'!$B$5:$C$12
Name zsupermetrics_lx4cNai7gT6tH4j08ZRkI21Qlpjioi: 'Business Metrics EU'!$B$13:$C$23
Name rdataslayer_3753ddf3234e496aa261974a0222e193: 'Business Metrics EU'!$H$5:$I$5
Name zsupermetrics_4VkB7ij7WO0JjKBEgvjB2GHjSy2Egm: 'Business Metrics Canada'!$B$13:$C$17
Name rdataslayer_4a0f150f4f2f4e4f85c890c75b7a1fa4: 'Business Metrics Canada'!$D$5:$E$12
Name rdataslayer_adf57e64065742daa5b4161161b1c3ca: 'Business Metrics Canada'!$B$13:$D$14
Name zsupermetrics_lx4cNai7gT6tH4j08ZRkI21Qlpjioi: Formulas!$B$5:$C$14
Name zsupermetrics_xwoIpANxRm908eDp5oKTwQpEI8gvD4: 'Business Metrics Canada'!$A$5
Name rdataslayer_d70e473bcafe40a3aa834ce157fb2ba3: Formulas!$C$9:$D$10
Name zsupermetrics_YsFuuYtr8vOdNXCCPiFJIO38NP4b2T: 'Business Metrics EU'!$B$13:$C$23
Name zsupermetrics_lx4cNai7gT6tH4j08ZRkI21Qlpjioi: 'Business Metrics Canada'!$B$13:$C$23
Name zsupermetrics_9i4W4hgd80uRpQLMeX0eRnESN8gjyv: 'Business Metrics EU'!$C$23
Name zsupermetrics_8xojRjNDjo2jWHGDWjFEhflhyIq3Hq: Sales!$K$9:$K$10
Name zsupermetrics_ru0GDtbZzDLHQOQtJJ6K08MvUDyyp7: 'Business Metrics EU'!$B$13:$B$14
Name rdataslayer_3753ddf3234e496aa261974a0222e193: Formulas!$H$3:$I$3
Name zsupermetrics_Mgms9p0QzysYvrIhnsKACeVBVxfIEO: 'Business Metrics Canada'!$A$5:$A$12
Name zsupermetrics_HgZqhorObHOtZHuyJjpmyYaEPoYntx: 'Business Metrics EU'!$B$13:$B$14
Name zsupermetrics_BioPyGBzcBsy60UCQmPcTuFReEmghI: Formulas!$B$3:$B$4
Name rdataslayer_4a0f150f4f2f4e4f85c890c75b7a1fa4: 'Business Metrics US'!$D$5:$E$12
Name zsupermetrics_iNpyVy90bWCI0yUaFQpxOtzWMa6sW4: 'Business Metrics US'!$A$5:$A$12
Name zsupermetrics_qWp7V908pNEYMtfv8QZvSTeDnBAHOU: Formulas!$B$6:$C$14

Sheet DataslayerQueries
A1: Query UUID | B1: Sheet name | C1: Range address | D1: Created | E1: Updated | F1: Last status | G1: Last refresh ID | H1: Results contain sampled data | I1: Execution time (sec) | J1: Object type | K1: Linked chart ID | L1: Data source | M1: Date range type | N1: Start date | O1: End date | P1: Compare to | Q1: Comparison value type | R1: Accounts/views | S1: Metrics | T1: Dimensions | U1: Pivot dimensions | V1: Filters | W1: Segment ID | X1: Segment dim | Y1: Sort | Z1: Max rows | AA1: Max pivot categories | AB1: Special settings | AC1: Other parameters | AD1: Result type | AE1: Language/country | AF1: Translate to | AG1: SQL | AH1: Database name | AI1: Range address (static) | AJ1: Report type | AK1: Highlight with colour | AL1: Refresh with user account | AM1: Returned data | AN1: Sort dimensions | AO1: Created by user account
A2: 42b112e4e4be4305bb4c1be75e2dd549 | B2: =IFERROR(__xludf.DUMMYFUNCTION("ARRAY_CONSTRAIN(split(CELL(""ADDRESS"",rdataslayer_42b112e4e4be4305bb4c1be75e2dd549),""!""),1,1)"),"Formulas") -> Formulas | C2: =IFERROR(__xludf.DUMMYFUNCTION("INDEX(split(CELL(""ADDRESS"",rdataslayer_42b112e4e4be4305bb4c1be75e2dd549),""!""),0,2)&"":""&address(row(rdataslayer_42b112e4e4be4305bb4c1be75e2dd549)+rows(rdataslayer_42b112e4e4be4305bb4c1be75e2dd549)-1,column(rdataslayer_42b112e4e4be4305bb4c1be75e2dd549"&")+COLUMNS(rdataslayer_42b112e4e4be4305bb4c1be75e2dd549)-1)"),"$B$3:$C$4") -> $B$3:$C$4 | D2: 44518.613 | E2: 44520.051 | F2: There is no data for the specified input | I2: 7 | J2: TABLE | L2: facebook | M2: yesterday | R2: [{"profile_id":"","name":"si_Bird buddy Inc_US &amp; CA_BirdBuddy","id":"act_273249767551281","account_name":"","advertiser_id":""}] | S2: [{"id":"spend","name":"Total Cost"}] | T2: [{"id":"date","name":"Date"}] | U2: [] | V2: [] | W2: [] | Y2: [] | Z2: 5 | AA2: 5 | AB2: {} | AC2: {} | AL2: User_Kumalic_Benjamin | AN2: [] | AO2: benjamin@mybirdbuddy.com
A3: 4a0f150f4f2f4e4f85c890c75b7a1fa4 | B3: =IFERROR(__xludf.DUMMYFUNCTION("ARRAY_CONSTRAIN(split(CELL(""ADDRESS"",rdataslayer_4a0f150f4f2f4e4f85c890c75b7a1fa4),""!""),1,1)"),"Formulas") -> Formulas | C3: =IFERROR(__xludf.DUMMYFUNCTION("INDEX(split(CELL(""ADDRESS"",rdataslayer_4a0f150f4f2f4e4f85c890c75b7a1fa4),""!""),0,2)&"":""&address(row(rdataslayer_4a0f150f4f2f4e4f85c890c75b7a1fa4)+rows(rdataslayer_4a0f150f4f2f4e4f85c890c75b7a1fa4)-1,column(rdataslayer_4a0f150f4f2f4e4f85c890c75b7a1fa4"&")+COLUMNS(rdataslayer_4a0f150f4f2f4e4f85c890c75b7a1fa4)-1)"),"$D$3:$E$4") -> $D$3:$E$4 | D3: 44518.615 | E3: 44520.051 | F3: There is no data for the specified input | I3: 7 | J3: TABLE | L3: facebook | M3: yesterday | R3: [{"account_name":"","advertiser_id":"","id":"act_273249767551281","profile_id":"","name":"si_Bird buddy Inc_US &amp; CA_BirdBuddy"}] | S3: [{"id":"spend","name":"Total Cost"}] | T3: [] | U3: [{"id":"date","name":"Date"}] | V3: [] | W3: [] | Y3: [] | Z3: 5 | AA3: 5 | AB3: {} | AC3: {} | AL3: User_Kumalic_Benjamin | AN3: [] | AO3: benjamin@mybirdbuddy.com
A4: adf57e64065742daa5b4161161b1c3ca | B4: =IFERROR(__xludf.DUMMYFUNCTION("ARRAY_CONSTRAIN(split(CELL(""ADDRESS"",rdataslayer_adf57e64065742daa5b4161161b1c3ca),""!""),1,1)"),"Formulas") -> Formulas | C4: =IFERROR(__xludf.DUMMYFUNCTION("INDEX(split(CELL(""ADDRESS"",rdataslayer_adf57e64065742daa5b4161161b1c3ca),""!""),0,2)&"":""&address(row(rdataslayer_adf57e64065742daa5b4161161b1c3ca)+rows(rdataslayer_adf57e64065742daa5b4161161b1c3ca)-1,column(rdataslayer_adf57e64065742daa5b4161161b1c3ca"&")+COLUMNS(rdataslayer_adf57e64065742daa5b4161161b1c3ca)-1)"),"$B$5:$D$6") -> $B$5:$D$6 | D4: 44518.618 | E4: 44520.051 | F4: There is no data for the specified input | I4: 18 | J4: TABLE | L4: facebook | M4: yesterday | R4: [{"name":"si_Bird buddy Inc_US &amp; CA_BirdBuddy","id":"act_273249767551281","profile_id":"","account_name":"","advertiser_id":""}] | S4: [{"id":"spend","name":"Total Cost"},{"id":"cpm","name":"CPM"}] | T4: [{"id":"date","name":"Date"}] | U4: [] | V4: [] | W4: [] | Y4: [] | Z4: 5 | AA4: 5 | AB4: {} | AC4: {} | AL4: User_Kumalic_Benjamin | AN4: [] | AO4: benjamin@mybirdbuddy.com
A5: d70e473bcafe40a3aa834ce157fb2ba3 | B5: =IFERROR(__xludf.DUMMYFUNCTION("ARRAY_CONSTRAIN(split(CELL(""ADDRESS"",rdataslayer_d70e473bcafe40a3aa834ce157fb2ba3),""!""),1,1)"),"Formulas") -> Formulas | C5: =IFERROR(__xludf.DUMMYFUNCTION("INDEX(split(CELL(""ADDRESS"",rdataslayer_d70e473bcafe40a3aa834ce157fb2ba3),""!""),0,2)&"":""&address(row(rdataslayer_d70e473bcafe40a3aa834ce157fb2ba3)+rows(rdataslayer_d70e473bcafe40a3aa834ce157fb2ba3)-1,column(rdataslayer_d70e473bcafe40a3aa834ce157fb2ba3"&")+COLUMNS(rdataslayer_d70e473bcafe40a3aa834ce157fb2ba3)-1)"),"$C$9:$D$10") -> $C$9:$D$10 | D5: 44518.619 | E5: 44520.051 | F5: There is no data for the specified input | I5: 7 | J5: TABLE | L5: facebook | M5: yesterday | R5: [{"advertiser_id":"","name":"si_Bird buddy Inc_US &amp; CA_BirdBuddy","id":"act_273249767551281","account_name":"","profile_id":""}] | S5: [{"id":"spend","name":"Total Cost"}] | T5: [{"id":"date","name":"Date"}] | U5: [] | V5: [] | W5: [] | Y5: [] | Z5: 100 | AA5: 100 | AB5: {} | AC5: {} | AL5: User_Kumalic_Benjamin | AN5: [] | AO5: benjamin@mybirdbuddy.com
A6: 3753ddf3234e496aa261974a0222e193 | B6: =IFERROR(__xludf.DUMMYFUNCTION("ARRAY_CONSTRAIN(split(CELL(""ADDRESS"",rdataslayer_3753ddf3234e496aa261974a0222e193),""!""),1,1)"),"Formulas") -> Formulas | C6: =IFERROR(__xludf.DUMMYFUNCTION("INDEX(split(CELL(""ADDRESS"",rdataslayer_3753ddf3234e496aa261974a0222e193),""!""),0,2)&"":""&address(row(rdataslayer_3753ddf3234e496aa261974a0222e193)+rows(rdataslayer_3753ddf3234e496aa261974a0222e193)-1,column(rdataslayer_3753ddf3234e496aa261974a0222e193"&")+COLUMNS(rdataslayer_3753ddf3234e496aa261974a0222e193)-1)"),"$H$3:$I$3") -> $H$3:$I$3 | D6: 44518.621 | E6: 44520.051 | F6: There is no data for the specified input | I6: 18 | J6: TABLE | L6: facebook | M6: yesterday | R6: [{"profile_id":"","account_name":"","advertiser_id":"","name":"si_Bird buddy Inc_US &amp; CA_BirdBuddy","id":"act_273249767551281"}] | S6: [{"id":"spend","name":"Total Cost"}] | T6: [] | U6: [] | V6: [] | W6: [] | Y6: [] | Z6: 100 | AA6: 100 | AB6: {"exclude_header_row":true} | AC6: {} | AL6: User_Kumalic_Benjamin | AN6: [] | AO6: benjamin@mybirdbuddy.com

Sheet Sales
B1: 44958 | C1: 44959 | D1: 44960 | E1: 44961 | F1: 44962 | G1: 44963 | H1: 44964 | I1: 44965 | J1: 44966 | K1: 44967 | L1: 44968 | M1: 44969 | N1: 44970 | O1: 44971 | P1: 44972 | Q1: 44973 | R1: 44974 | S1: 44975 | T1: 44976 | U1: 44977 | V1: 44978 | W1: 44979 | X1: 44980 | Y1: 44981 | Z1: 44982 | AA1: 44983 | AB1: 44984 | AC1: 44985
B2: WED | C2: THU | D2: FRI | E2: SAT | F2: SUN | G2: MON | H2: TUE | I2: WED | J2: THU | K2: FRI | L2: SAT | M2: SUN | N2: MON | O2: TUE | P2: WED | Q2: THU | R2: FRI | S2: SAT | T2: SUN | U2: MON | V2: TUE | W2: WED | X2: THU | Y2: FRI | Z2: SAT | AA2: SUN | AB2: MON | AC2: TUE
A3: Weekend Work | E3: Gaja | F3: Gaja | I3: Beno | L3: Beno | M3: Beno | S3: Peter | T3: Peter | Z3: Gaja | AA3: Gaja
A5: Notes | I5: Shipping rate test started at midnight | M5: PR - Wired | N5: Emai - V-day | O5: Email - V-day Follow-up | Q5: Shipping rate test ended | S5: No suet ball test started at midnight | X5: 3in1 addon rebranded and live on site | Z5: ZD Net Review (pr) | AB5: Lower Shipping Rates for US ($10 lowest) | AC5: 3-in-1 Estimated shipping changed from May to June
I6: V-day Campaign | AB6: May shipping, last April order #151301 | AC6: 3in1 Launch email & push notification
M7: V-day Listicles
A9: Shopify | B9: 43265.61 | C9: 47405.27 | D9: 42536.9 | E9: 49825.15 | F9: 46672.86 | G9: 39902.08 | H9: 42383.81 | I9: 44059.09 | J9: 43443.58 | K9: 48828.96 | L9: 56287.11 | M9: 75592.56 | N9: 59300.59 | O9: 66009.77 | P9: 52224.84 | Q9: 46314.07 | R9: 51666.67 | S9: 55998.02 | T9: 56688.25 | U9: 51457.23 | V9: 39343.14 | W9: 41783.82 | X9: 46845.64 | Y9: 45085.3 | Z9: 59458.74 | AA9: 48793.46 | AB9: 41311.93 | AC9: 52247.12
A10: Total Revenue | B10: =SUM(B9) -> 43265.61 | C10: =SUM(C9) -> 47405.27 | D10: =SUM(D9) -> 42536.9 | E10: =SUM(E9) -> 49825.15 | F10: =SUM(F9) -> 46672.86 | G10: =SUM(G9) -> 39902.08 | H10: =SUM(H9) -> 42383.81 | I10: =SUM(I9) -> 44059.09 | ... AC10: =SUM(AC9) -> 52247.12
A11: Orders | B11: 161 | C11: 177 | D11: 156 | E11: 186 | F11: 180 | G11: 159 | H11: 149 | I11: 154 | J11: 145 | K11: 172 | L11: 195 | M11: 254 | N11: 193 | O11: 213 | P11: 178 | Q11: 167 | R11: 166 | S11: 190 | T11: 210 | U11: 174 | V11: 137 | W11: 164 | X11: 258 | Y11: 173 | Z11: 222 | AA11: 180 | AB11: 151 | AC11: 440
A13: FB - US & CA | B13: 10047.82 | C13: 11002.08 | D13: 11804.85 | E13: 11510.84 | F13: 12462.41 | G13: 11937.87 | H13: 11244.56 | I13: 10884.48 | J13: 10546.13 | K13: 11980.44 | L13: 10832.96 | M13: 11875.38 | N13: 13940.01 | O13: 14855.09 | P13: 13296.67 | Q13: 13239.8 | R13: 11961.47 | S13: 14730.34 | T13: 14039.55 | U13: 13952.57 | V13: 12496.67 | W13: 13421.68 | X13: 12686.03 | Y13: 12456.87 | Z13: 13257.04 | AA13: 13626.11 | AB13: 11880.77 | AC13: 11715.75
A14: Google - WW | B14: 1859.2 | C14: 2317.88 | D14: 2390 | E14: 2840 | F14: 2701.34 | G14: 2414.2 | H14: 1834.37 | I14: 2135.55 | J14: 2271.77 | K14: 2230.43 | L14: 1763.06 | M14: 1781.33 | N14: 1579.89 | O14: 1569.51 | P14: 1600.87 | Q14: 1531.79 | R14: 1738.45 | S14: 1929.06 | T14: 2358.7 | U14: 2110.92 | V14: 1636.06 | W14: 1378.97 | X14: 1491.31 | Y14: 1289.1 | Z14: 1644.82 | AA14: 1606.44 | AB14: 1262.15 | AC14: 1222.29
A15: Bing - WW | B15: 110.91 | C15: 108.79 | D15: 97.29 | E15: 63.08 | F15: 55.51 | G15: 65.95 | H15: 77.18 | I15: 78.61 | J15: 98.72 | K15: 75.96 | L15: 45.75 | M15: 72.44 | N15: 85.22 | O15: 91.08 | P15: 80.37 | Q15: 73.65 | R15: 52.53 | S15: 87.68 | T15: 88.41 | U15: 94.7 | V15: 82.04 | W15: 88.6 | X15: 68.51 | Y15: 62.17 | Z15: 54.71 | AA15: 64.87 | AB15: 51.63 | AC15: 168.94
A16: TikTok - US & CA | C16: 286.63 | D16: 882.81 | E16: 889.48 | F16: 748.46 | G16: 935.77 | H16: 1350.45 | I16: 1050.2 | J16: 599.42 | K16: 620.22 | L16: 248.82 | M16: 763.8 | N16: 549.75 | O16: 299.74 | P16: 299.65 | Q16: 298.87 | R16: 247.56 | S16: 159.21 | T16: 0 | U16: 0 | V16: 0 | W16: 0 | X16: 0 | Y16: 0 | Z16: 0 | AA16: 0 | AB16: 0 | AC16: 0
A17: MNTN TV
A18: Affiliate Fees - US | B18: 0 | C18: 0 | D18: 0 | E18: 65.63 | F18: 0 | G18: 63.7 | H18: 0 | I18: 76.5 | J18: 0 | K18: 60.61 | L18: 0 | M18: 0 | N18: 0 | O18: 0 | P18: 0 | Q18: 0 | R18: 0 | S18: 0 | T18: 0 | U18: 70.35 | V18: 59.8 | W18: 0 | X18: 0 | Y18: 0 | Z18: 0 | AA18: 72.53 | AB18: 0 | AC18: 0
A19: Total Spend | B19: =SUM(B13:B18) -> 12017.93 | C19: =SUM(C13:C18) -> 13715.38 | D19: =SUM(D13:D18) -> 15174.95 | E19: =SUM(E13:E18) -> 15369.03 | F19: =SUM(F13:F18) -> 15967.72 | G19: =SUM(G13:G18) -> 15417.49 | H19: =SUM(H13:H18) -> 14506.56 | I19: =SUM(I13:I18) -> 14225.34 | ... AC19: =SUM(AC13:AC18) -> 13106.98
A21: ROAS | B21: =B10/B19 -> 3.6000884 | C21: =C10/C19 -> 3.4563585 | D21: =D10/D19 -> 2.8030998 | E21: =E10/E19 -> 3.241919 | F21: =F10/F19 -> 2.9229508 | G21: =G10/G19 -> 2.5881048 | H21: =H10/H19 -> 2.9216996 | I21: =I10/I19 -> 3.0972258 | ... AC21: =AC10/AC19 -> 3.9862058
A22: Spend per Unit | B22: =B19/'Detailed Report'!B140 -> 94.62937 | C22: =C19/'Detailed Report'!C140 -> 85.188696 | D22: =D19/'Detailed Report'!D140 -> 119.4878 | E22: =E19/'Detailed Report'!E140 -> 104.55122 | F22: =F19/'Detailed Report'!F140 -> 119.16209 | G22: =G19/'Detailed Report'!G140 -> 137.65616 | H22: =H19/'Detailed Report'!H140 -> 110.7371 | I22: =I19/'Detailed Report'!I140 -> 99.477902 | ... AC22: =AC19/'Detailed Report'!AC140 -> 100.05328
A23: CR | B23: 0.0111 | C23: 0.0111 | D23: 0.0103 | E23: 0.0122 | F23: 0.0111 | G23: 0.0095 | H23: 0.009 | I23: 0.0107 | J23: 0.0083 | K23: 0.0112 | L23: 0.0126 | M23: 0.014 | N23: 0.0084 | O23: 0.011 | P23: 0.0102 | Q23: 0.0098 | R23: 0.0103 | S23: 0.0093 | T23: 0.0104 | U23: 0.0084 | V23: 0.0077 | W23: 0.0087 | X23: 0.0124 | Y23: 0.0107 | Z23: 0.0136 | AA23: 0.0088 | AB23: 0.0099 | AC23: 0.0156
A24: AOV | B24: =B10/B11 -> 268.7305 | C24: =C10/C11 -> 267.82638 | D24: =D10/D11 -> 272.67244 | E24: =E10/E11 -> 267.87715 | F24: =F10/F11 -> 259.29367 | G24: =G10/G11 -> 250.95648 | H24: =H10/H11 -> 284.4551 | I24: =I10/I11 -> 286.09799 | ... AC24: =AC10/AC11 -> 118.74345
A25: fAOV | B25: 291.33 | C25: 281.42 | D25: 267.69 | E25: 262.85 | F25: 289.93 | G25: 277.55 | H25: 293.45 | I25: 303.1 | J25: 309.76 | K25: 294.97 | L25: 304.48 | M25: 310.13 | N25: 314.75 | O25: 319.25 | P25: 306.76 | Q25: 303.64 | R25: 320.7487 | S25: 302.11036 | T25: 290.91 | U25: 317.1 | V25: 283.33 | W25: 275.14 | X25: 249.17 | Y25: 295.26 | Z25: 293.72 | AA25: 292.56 | AB25: 286.63 | AC25: 193.36
A26: rAOV | B26: 96.97 | C26: 164.57 | D26: 109.19 | E26: 109.89 | F26: 121.55 | G26: 125.83 | H26: 47.49 | I26: 147.14 | J26: 170.21 | K26: 171.72 | L26: 176.55 | M26: 162.99 | N26: 234.12 | O26: 170 | P26: 238.81 | Q26: 171.17 | R26: 189.28083 | S26: 243.1924 | T26: 122.32 | U26: 130.02 | V26: 196.35 | W26: 116.11 | X26: 69.03 | Y26: 129.78 | Z26: 129.52 | AA26: 113.57 | AB26: 163.53 | AC26: 49.36
A28: Customers
A29: Returning | B29: 0.1242 | C29: 0.1356 | D29: 0.1307 | E29: 0.1702 | F29: 0.1889 | G29: 0.1824 | H29: 0.3879 | I29: 0.1234 | J29: 0.0759 | K29: 0.1279 | L29: 0.1385 | M29: 0.1024 | N29: 0.1451 | O29: 0.1733 | P29: 0.1966 | Q29: 0.2096 | R29: 0.0723 | S29: 0.1316 | T29: 0.1524 | U29: 0.1149 | V29: 0.1379 | W29: 0.128 | X29: 0.3798 | Y29: 0.2197 | Z29: 0.1577 | AA29: 0.1222 | AB29: 0.106 | AC29: 0.5182
A30: First-time | B30: =1-B29 -> 0.8758 | C30: =1-C29 -> 0.8644 | D30: =1-D29 -> 0.8693 | E30: =1-E29 -> 0.8298 | F30: =1-F29 -> 0.8111 | G30: =1-G29 -> 0.8176 | H30: =1-H29 -> 0.6121 | I30: =1-I29 -> 0.8766 | ... AC30: =1-AC29 -> 0.4818
A33: Post-purchase Survey
A34: Facebook / Instagram | B34: 0.4255 | C34: 0.3878 | D34: 0.4528 | E34: 0.4146 | F34: 0.5417 | G34: 0.4167 | H34: 0.525 | I34: 0.5106 | J34: 0.4634 | K34: 0.4884 | L34: 0.3654 | M34: 0.4167 | N34: 0.5556 | O34: 0.4727 | P34: 0.5 | Q34: 0.5405 | R34: 0.4524 | S34: 0.5918 | T34: 0.5192 | U34: 0.5273 | V34: 0.6 | W34: 0.5172 | X34: 0.3208 | Y34: 0.4872 | Z34: 0.5273 | AA34: 0.52 | AB34: 0.4722 | AC34: 0.5467
A35: Friends / Family | B35: 0.4043 | C35: 0.449 | D35: 0.4906 | E35: 0.3902 | F35: 0.3333 | G35: 0.4792 | H35: 0.425 | I35: 0.2766 | J35: 0.4146 | K35: 0.3721 | L35: 0.4808 | M35: 0.2361 | N35: 0.3333 | O35: 0.3091 | P35: 0.4286 | Q35: 0.4054 | R35: 0.4762 | S35: 0.3061 | T35: 0.2308 | U35: 0.3455 | V35: 0.325 | W35: 0.3793 | X35: 0.5472 | Y35: 0.359 | Z35: 0.4 | AA35: 0.38 | AB35: 0.4167 | AC35: 0.3333
A36: Google, Yahoo, Bing | B36: 0.0638 | C36: 0.0204 | D36: 0.0189 | E36: 0.0244 | F36: 0.0417 | G36: 0.0417 | H36: 0 | I36: 0.0638 | J36: 0.0732 | K36: 0.0233 | L36: 0.0192 | M36: 0.0278 | N36: 0.0185 | O36: 0.0364 | P36: 0.0179 | Q36: 0.027 | R36: 0 | S36: 0.0204 | T36: 0.0385 | U36: 0.0182 | V36: 0 | W36: 0.0172 | X36: 0.0377 | Y36: 0.0513 | Z36: 0.0545 | AA36: 0.06 | AB36: 0.0278 | AC36: 0.0533
A37: Pinterest | B37: 0 | C37: 0 | D37: 0 | E37: 0 | F37: 0 | G37: 0 | H37: 0 | I37: 0 | J37: 0 | K37: 0 | L37: 0.0192 | M37: 0 | N37: 0 | O37: 0 | P37: 0 | Q37: 0 | R37: 0 | S37: 0 | T37: 0 | U37: 0 | V37: 0 | W37: 0 | X37: 0.0189 | Y37: 0 | Z37: 0 | AA37: 0 | AB37: 0 | AC37: 0
A38: TikTok | B38: 0 | C38: 0.0204 | D38: 0.0189 | E38: 0.0732 | F38: 0 | G38: 0.0208 | H38: 0 | I38: 0.0426 | J38: 0.0488 | K38: 0.093 | L38: 0.0577 | M38: 0.0139 | N38: 0.0185 | O38: 0.0182 | P38: 0.0179 | Q38: 0 | R38: 0 | S38: 0 | T38: 0.0577 | U38: 0.0364 | V38: 0.05 | W38: 0.0172 | X38: 0.0189 | Y38: 0 | Z38: 0 | AA38: 0 | AB38: 0 | AC38: 0.0133
A39: TV / Radio | B39: 0.0851 | C39: 0.0204 | D39: 0.0189 | E39: 0 | F39: 0.0208 | G39: 0.0208 | H39: 0 | I39: 0 | J39: 0 | K39: 0.0233 | L39: 0.0192 | M39: 0.0139 | N39: 0 | O39: 0.0182 | P39: 0 | Q39: 0 | R39: 0 | S39: 0.0204 | T39: 0 | U39: 0.0364 | V39: 0 | W39: 0.0172 | X39: 0 | Y39: 0.0256 | Z39: 0 | AA39: 0.02 | AB39: 0.0556 | AC39: 0
A40: Blog / Article | B40: 0.0213 | C40: 0.102 | D40: 0 | E40: 0.0976 | F40: 0.0625 | G40: 0.0208 | H40: 0.05 | I40: 0.1064 | J40: 0 | K40: 0 | L40: 0.0385 | M40: 0.2917 | N40: 0.0741 | O40: 0.1455 | P40: 0.0357 | Q40: 0.027 | R40: 0.0714 | S40: 0.0612 | T40: 0.1538 | U40: 0.0364 | V40: 0.025 | W40: 0.0517 | X40: 0.0566 | Y40: 0.0769 | Z40: 0.0182 | AA40: 0.02 | AB40: 0.0278 | AC40: 0.0533
B42: 44958 | C42: Goal | D42: % of Goal
A43: Revenue | B43: =SUM(B10:AC10) -> 1394731.6 | C43: 1407000 | D43: =B43/C43 -> 0.99128043
A44: Spend | B44: =SUM(B19:AC19) -> 413120.96 | C44: 412389 | D44: =B44/C44 -> 1.0017749
A45: ROAS | B45: =B43/B44 -> 3.3760852 | C45: 3.5 | D45: =B45/C45 -> 0.96459578
A46: Spend per Unit | B46: =SUM(B19:AC19)/SUM('Detailed Report'!B140:AC140) -> 93.784554
A47: CR | B47: =AVERAGE(B23:AC23) -> 0.010582143
A48: AOV | B48: =B43/B51 -> 262.95844
...

Sheet Detailed Report
A1: FEBRUARY | B1: 44958 | C1: 44959 | D1: 44960 | E1: 44961 | F1: 44962 | G1: 44963 | H1: 44964 | I1: 44965 | J1: 44966 | K1: 44967 | L1: 44968 | M1: 44969 | N1: 44970 | O1: 44971 | P1: 44972 | Q1: 44973 | R1: 44974 | S1: 44975 | T1: 44976 | U1: 44977 | V1: 44978 | W1: 44979 | X1: 44980 | Y1: 44981 | Z1: 44982 | AA1: 44983 | AB1: 44984 | AC1: 44985
A2: DAY | B2: WED | C2: THU | D2: FRI | E2: SAT | F2: SUN | G2: MON | H2: TUE | I2: WED | J2: THU | K2: FRI | L2: SAT | M2: SUN | N2: MON | O2: TUE | P2: WED | Q2: THU | R2: FRI | S2: SAT | T2: SUN | U2: MON | V2: TUE | W2: WED | X2: THU | Y2: FRI | Z2: SAT | AA2: SUN | AB2: MON | AC2: TUE
A3: COMMENT
A4: Transactions
A5: FB (US & CA) | B5: 48 | C5: 51 | D5: 51 | E5: 55 | F5: 43 | G5: 32 | H5: 54 | I5: 44 | J5: 50 | K5: 46 | L5: 49 | M5: 54 | N5: 58 | O5: 73 | P5: 49 | Q5: 52 | R5: 54 | S5: 70 | T5: 60 | U5: 62 | V5: 41 | W5: 44 | X5: 44 | Y5: 53 | Z5: 73 | AA5: 53 | AB5: 40 | AC5: 44 | AD5: =SUM(B5:AC5) -> 1447
A6: Google | B6: 37 | C6: 29 | D6: 29 | E6: 48 | F6: 39 | G6: 29 | H6: 31 | I6: 30 | J6: 38 | K6: 49 | L6: 49 | M6: 40 | N6: 34 | O6: 38 | P6: 35 | Q6: 40 | R6: 43 | S6: 32 | T6: 65 | U6: 44 | V6: 38 | W6: 31 | X6: 39 | Y6: 35 | Z6: 55 | AA6: 36 | AB6: 39 | AC6: 31 | AD6: =SUM(B6:AC6) -> 1083
A7: TikTok | B7: 0 | C7: 0 | D7: 1 | E7: 1 | F7: 5 | G7: 0 | H7: 0 | I7: 0 | J7: 0 | K7: 0 | L7: 2 | M7: 2 | N7: 0 | O7: 4 | P7: 0 | Q7: 0 | R7: 0 | S7: 0 | T7: 1 | U7: 0 | V7: 0 | W7: 1 | X7: 0 | Y7: 0 | Z7: 0 | AA7: 0 | AB7: 0 | AC7: 0 | AD7: =SUM(B7:AC7) -> 17
A8: Bing | B8: 7 | C8: 8 | D8: 2 | E8: 1 | F8: 5 | G8: 2 | H8: 8 | I8: 5 | J8: 4 | K8: 4 | L8: 0 | M8: 5 | N8: 9 | O8: 6 | P8: 7 | Q8: 2 | R8: 2 | S8: 3 | T8: 2 | U8: 4 | V8: 5 | W8: 7 | X8: 3 | Y8: 3 | Z8: 3 | AA8: 2 | AB8: 4 | AC8: 5 | AD8: =SUM(B8:AC8) -> 118
A9: MNTN TV | AD9: =SUM(B9:AC9) -> 0
A10: Affiliates (Refersion) | B10: 0 | C10: 0 | D10: 0 | E10: 1 | F10: 0 | G10: 1 | H10: 0 | I10: 1 | J10: 0 | K10: 1 | L10: 0 | M10: 0 | N10: 0 | O10: 0 | P10: 0 | Q10: 0 | R10: 0 | S10: 0 | T10: 0 | U10: 1 | V10: 1 | W10: 0 | X10: 0 | Y10: 0 | Z10: 0 | AA10: 1 | AB10: 0 | AC10: 0 | AD10: =SUM(B10:AC10) -> 7
A11: FB (Internal Paid) | AD11: =SUM(B11:AC11) -> 0
A12: FB (EU & UK) | AD12: =SUM(B12:AC12) -> 0
A13: Email | B13: 5 | C13: 6 | D13: 4 | E13: 5 | F13: 8 | G13: 10 | H13: 4 | I13: 7 | J13: 7 | K13: 3 | L13: 3 | M13: 5 | N13: 20 | O13: 13 | P13: 26 | Q13: 15 | R13: 8 | S13: 9 | T13: 12 | U13: 5 | V13: 10 | W13: 11 | X13: 87 | Y13: 18 | Z13: 12 | AA13: 13 | AB13: 7 | AC13: 113 | AD13: =SUM(B13:AC13) -> 446
A14: All | B14: =SUM(B5:B13) -> 97 | C14: =SUM(C5:C13) -> 94 | D14: =SUM(D5:D13) -> 87 | E14: =SUM(E5:E13) -> 111 | F14: =SUM(F5:F13) -> 100 | G14: =SUM(G5:G13) -> 74 | H14: =SUM(H5:H13) -> 97 | I14: =SUM(I5:I13) -> 87 | ... AC14: =SUM(AC5:AC13) -> 193 | AD14: =SUM(B14:AC14) -> 3118
A16: Revenue
A17: FB (US & CA) | B17: 13922.96 | C17: 16049.58 | D17: 16955.63 | E17: 11510.84 | F17: 13540.22 | G17: 9279.73 | H17: 17250.48 | I17: 14657.41 | J17: 15968.67 | K17: 14684.15 | L17: 15075.68 | M17: 18597.71 | N17: 19399.95 | O17: 23848.85 | P17: 16057.58 | Q17: 16664.06 | R17: 17811.55 | S17: 22205.12 | T17: 19381.48 | U17: 21441.39 | V17: 13344.61 | W17: 14999.99 | X17: 13647.1 | Y17: 16681.21 | Z17: 23771.28 | AA17: 16770.73 | AB17: 13077.16 | AC17: 13608.39 | AD17: =SUM(B17:AC17) -> 460203.51
A18: Google | B18: 10492.85 | C18: 8041.43 | D18: 7689.34 | E18: 12227.87 | F18: 8266.85 | G18: 6762.02 | H18: 8285.29 | I18: 7890.33 | J18: 11406.8 | K18: 13508.56 | L18: 14142.51 | M18: 10834.63 | N18: 9499.21 | O18: 11127.26 | P18: 8829.56 | Q18: 9770.81 | R18: 12777.56 | S18: 8323.48 | T18: 16121.61 | U18: 12113.6 | V18: 9962.32 | W18: 8314.75 | X18: 9900.17 | Y18: 8505.2 | Z18: 14570.89 | AA18: 9419.42 | AB18: 9583.77 | AC18: 6168.44 | AD18: =SUM(B18:AC18) -> 284536.53
A19: TikTok | B19: 0 | C19: 0 | D19: 35.74 | E19: 243.32 | F19: 1703.09 | G19: 0 | H19: 0 | I19: 0 | J19: 0 | K19: 0 | L19: 551.25 | M19: 670.17 | N19: 0 | O19: 1399.28 | P19: 0 | Q19: 0 | R19: 0 | S19: 0 | T19: 370.02 | U19: 0 | V19: 0 | W19: 355.72 | X19: 0 | Y19: 0 | Z19: 0 | AA19: 0 | AB19: 0 | AC19: 0 | AD19: =SUM(B19:AC19) -> 5328.59
A20: Bing | B20: 1862 | C20: 2128 | D20: 532 | E20: 266 | F20: 1330 | G20: 532 | H20: 2128 | I20: 1330 | J20: 1064 | K20: 1064 | L20: 0 | M20: 1330 | N20: 2394 | O20: 1596 | P20: 1862 | Q20: 532 | R20: 532 | S20: 798 | T20: 532 | U20: 1064 | V20: 1330 | W20: 1862 | X20: 798 | Y20: 798 | Z20: 798 | AA20: 532 | AB20: 1064 | AC20: 1330 | AD20: =SUM(B20:AC20) -> 31388
A21: MNTN TV | AD21: =SUM(B21:AC21) -> 0
A22: Affiliates (Refersion) | B22: 0 | C22: 0 | D22: 0 | E22: 328.16 | F22: 0 | G22: 318.51 | H22: 0 | I22: 382.49 | J22: 0 | K22: 303.07 | L22: 0 | M22: 0 | N22: 0 | O22: 0 | P22: 0 | Q22: 0 | R22: 0 | S22: 0 | T22: 0 | U22: 351.75 | V22: 59.8 | W22: 0 | X22: 0 | Y22: 0 | Z22: 0 | AA22: 362.66 | AB22: 0 | AC22: 0 | AD22: =SUM(B22:AC22) -> 2106.44
A23: FB (Internal Paid) | AD23: =SUM(B23:AC23) -> 0
A24: FB (EU & UK) | AD24: =SUM(B24:AC24) -> 0
A25: Email | B25: 827.16 | C25: 827.23 | D25: 722.22 | E25: 1074.4 | F25: 1817.91 | G25: 1870.35 | H25: 760.96 | I25: 1322.62 | J25: 2252.53 | K25: 357.34 | L25: 694.58 | M25: 680.26 | N25: 5562.9 | O25: 4655.72 | P25: 7333.09 | Q25: 3382.19 | R25: 2937.43 | S25: 2224.75 | T25: 2467.69 | U25: 1670.2 | V25: 2302.53 | W25: 2703.59 | X25: 5926.46 | Y25: 2010.54 | Z25: 978.1 | AA25: 1559.76 | AB25: 1168.28 | AC25: 6780.31 | AD25: =SUM(B25:AC25) -> 66871.1
A26: All | B26: =SUM(B17:B25) -> 27104.97 | C26: =SUM(C17:C25) -> 27046.24 | D26: =SUM(D17:D25) -> 25934.93 | E26: =SUM(E17:E25) -> 25650.59 | F26: =SUM(F17:F25) -> 26658.07 | G26: =SUM(G17:G25) -> 18762.61 | H26: =SUM(H17:H25) -> 28424.73 | I26: =SUM(I17:I25) -> 25582.85 | ... AC26: =SUM(AC17:AC25) -> 27887.14 | AD26: =SUM(B26:AC26) -> 850434.17
A28: Media Cost
A29: FB Spend (US & CA) | B29: =Sales!B13 -> 10047.82 | C29: =Sales!C13 -> 11002.08 | D29: =Sales!D13 -> 11804.85 | E29: =Sales!E13 -> 11510.84 | F29: =Sales!F13 -> 12462.41 | G29: =Sales!G13 -> 11937.87 | H29: =Sales!H13 -> 11244.56 | I29: =Sales!I13 -> 10884.48 | ... AC29: =Sales!AC13 -> 11715.75 | AD29: =SUM(B29:AC29) -> 347686.24
A30: Google Spend | B30: =Sales!B14 -> 1859.2 | C30: =Sales!C14 -> 2317.88 | D30: =Sales!D14 -> 2390 | E30: =Sales!E14 -> 2840 | F30: =Sales!F14 -> 2701.34 | G30: =Sales!G14 -> 2414.2 | H30: =Sales!H14 -> 1834.37 | I30: =Sales!I14 -> 2135.55 | ... AC30: =Sales!AC14 -> 1222.29 | AD30: =SUM(B30:AC30) -> 52489.46
A31: TikTok Spend | B31: =Sales!B16 | C31: =Sales!C16 -> 286.63 | D31: =Sales!D16 -> 882.81 | E31: =Sales!E16 -> 889.48 | F31: =Sales!F16 -> 748.46 | G31: =Sales!G16 -> 935.77 | H31: =Sales!H16 -> 1350.45 | I31: =Sales!I16 -> 1050.2 | ... AC31: =Sales!AC16 -> 0 | AD31: =SUM(B31:AC31) -> 10230.84
A32: Bing Spend | B32: =Sales!B15 -> 110.91 | C32: =Sales!C15 -> 108.79 | D32: =Sales!D15 -> 97.29 | E32: =Sales!E15 -> 63.08 | F32: =Sales!F15 -> 55.51 | G32: =Sales!G15 -> 65.95 | H32: =Sales!H15 -> 77.18 | I32: =Sales!I15 -> 78.61 | ... AC32: =Sales!AC15 -> 168.94 | AD32: =SUM(B32:AC32) -> 2245.3
A33: MNTN TV | B33: =Sales!B17 | C33: =Sales!C17 | D33: =Sales!D17 | E33: =Sales!E17 | F33: =Sales!F17 | G33: =Sales!G17 | H33: =Sales!H17 | I33: =Sales!I17 | ... AC33: =Sales!AC17 | AD33: =SUM(B33:AC33) -> 0
A34: Fee 15% Purchase (Backerkit) | B34: =B21*0.15 -> 0 | C34: =C21*0.15 -> 0 | D34: =D21*0.15 -> 0 | E34: =E21*0.15 -> 0 | F34: =F21*0.15 -> 0 | G34: =G21*0.15 -> 0 | H34: =H21*0.15 -> 0 | I34: =I21*0.15 -> 0 | ... S34: =S21*0.15 -> 0 | U34: =U21*0.15 -> 0 | V34: =V21*0.15 -> 0 | W34: =W21*0.15 -> 0 | X34: =X21*0.15 -> 0 | Y34: =Y21*0.15 -> 0 | Z34: =Z21*0.15 -> 0 | AA34: =AA21*0.15 -> 0 | AB34: =AB21*0.15 -> 0 | AC34: =AC21*0.15 -> 0 | AD34: =SUM(B34:AC34) -> 0
A35: Google Management Fee | AD35: =SUM(B35:AC35) -> 0
A36: Affiliates Agency Payment (Grovia) | AD36: =SUM(B36:AC36) -> 0
A37: Affiliate Fee 20% (Grovia) | B37: =Sales!B18 -> 0 | C37: =Sales!C18 -> 0 | D37: =Sales!D18 -> 0 | E37: =Sales!E18 -> 65.63 | F37: =Sales!F18 -> 0 | G37: =Sales!G18 -> 63.7 | H37: =Sales!H18 -> 0 | I37: =Sales!I18 -> 76.5 | ... AC37: =Sales!AC18 -> 0 | AD37: =SUM(B37:AC37) -> 469.12
A38: FB Spend (Internal Paid) | AD38: =SUM(B38:AC38) -> 0
A39: FB Spend (EU & UK) | AD39: =SUM(B39:AC39) -> 0
A40: Pinterest Spend | AD40: =SUM(B40:AC40) -> 0
A41: Platform Fee (6,90%) | AD41: =SUM(B41:AC41) -> 0
A42: All | B42: =SUM(B29:B41) -> 12017.93 | C42: =SUM(C29:C41) -> 13715.38 | D42: =SUM(D29:D41) -> 15174.95 | E42: =SUM(E29:E41) -> 15369.03 | F42: =SUM(F29:F41) -> 15967.72 | G42: =SUM(G29:G41) -> 15417.49 | H42: =SUM(H29:H41) -> 14506.56 | I42: =SUM(I29:I41) -> 14225.34 | ... AC42: =SUM(AC29:AC41) -> 13106.98 | AD42: =SUM(B42:AC42) -> 413120.96
...

Sheet Formulas
B1: Business Metrics
B3: COGS | C3: Source | E3: 3PL Costs
B4: Bird Buddy | C4: 70.53 | E4: Handling Fee | F4: 1.5
B5: Bird Buddy with Solar Roof | C5: 80.08 | E5: Serial Capture | F5: 0.3
B6: Solar Roof Single | C6: 9.98 | E6: Storage | F6: 0.31
B7: Wall Mount | C7: 4.93 | E7: Other
B8: Fence Mount | C8: 6.37 | E8: Source
B9: Suet Ball Holder | C9: 1.07
B10: 3-in-1 Nutrition Set | C10: 6.08
B12: Bird Buddy Shipping | C12: Source | E12: Add-ons Shipping
B13: Inbound (NA) | C13: 18.43 | E13: Inbound (NA) | F13: 1.22
B14: Inbound (Europe) | C14: 4.98 | E14: Inbound (Europe)
B15: Inbound (ROW) | C15: 10 | E15: Inbound (ROW)
B16: Outbound (NA) | C16: 11.59 | E16: Outbound (NA)
B17: Outbound (Europe) | C17: 15 | E17: Outbound (Europe)
B18: Outbound (ROW) | C18: 20 | E18: Outbound (ROW)
B20: Marketing Averages (per unit) | E20: VAT Averages
B21: COGS | C21: =(C4*1)+(C6*F26)+(C7*F27)+(C8*F28)+(C9*F29)+(C10*F30) -> 76.263282 | E21: Europe | F21: 0.22
B22: Inbound Shipping | C22: =C13 -> 18.43 | E22: ROW | F22: 0.13
B23: Outbound Shipping | C23: =C16 -> 11.59 | E23: NA
B24: Taxes and VAT | C24: 10.89
B25: China Tax (7.5%) | C25: =C21*0.075 -> 5.7197462 | E25: Attachment Rates
B26: Duty (3.4%) | C26: =C21*0.034 -> 2.5929516 | E26: Solar Roof | F26: =('Detailed Report'!AD169)/'Detailed Report'!AD163 -> 0.074586978
B27: Processing Fee (2,97%) | C27: =Sales!B48*0.0297 -> 7.8098657 | E27: Wall Mount | F27: =('Detailed Report'!AD165)/'Detailed Report'!AD163 -> 0.41399417
B28: Transaction Fee ($0.36) | C28: =0.36 -> 0.36 | E28: Fence Mount | F28: =('Detailed Report'!AD166)/'Detailed Report'!AD163 -> 0.0021865889
B29: 3PL - Handling Fee | C29: =F4 -> 1.5 | E29: Suet Ball Holder | F29: =('Detailed Report'!AD167)/'Detailed Report'!AD163 -> 0.91836735
B30: 3PL - Serial Capture | C30: =F5 -> 0.3 | E30: Water Fountain | F30: =('Detailed Report'!AD168)/'Detailed Report'!AD163 -> 0.32094266
B31: 3PL - Storage Cost | C31: =F6 -> 0.31
B32: All | C32: =SUM(C21:C30) -> 135.45585
B34: Fees | E34: 30 Day Returns
B35: Processing Fee | C35: 0.0297 | E35: US Shipping | F35: 10
B36: Duty | C36: 0.034 | E36: EU Shipping | F36: 20
B37: China Tax | C37: 0.075 | E37: ROW Shipping | F37: 20
B38: HMF | C38: 0.00125 | E38: Money Return | F38: 0.8
B39: MPF | C39: 0.003464
B40: Solar Roof China Tax | C40: 0.25
B41: Solar Roof Duty | C41: 0.025

Sheet Business Metrics US
A1: United States
A2: Product | B2: Bird Buddy | C2: Bird Buddy with Solar Roof | D2: Solar Roof | E2: Wall Mount | F2: Suet Ball Holder | G2: 3-in-1 Nutrition Set | H2: Hummingbird Feeder | I2: Perch Extender | J2: Pole System
A3: Category | B3: Bird Feeder | C3: Bird Feeder | D3: Add-on | E3: Add-on | F3: Add-on | G3: Add-on
A5: COGS
A6: Source
A7: Owner | B7: Nick Koukourakis | C7: Nick Koukourakis | D7: Nick Koukourakis | E7: Nick Koukourakis | F7: Nick Koukourakis | G7: Nick Koukourakis
A8: Controller #1 | B8: Diana Spiewak | C8: Diana Spiewak | D8: Diana Spiewak | E8: Diana Spiewak | F8: Diana Spiewak | G8: Diana Spiewak
A9: Controller #2 | B9: Eric Malkowski | C9: Eric Malkowski | D9: Eric Malkowski | E9: Eric Malkowski | F9: Eric Malkowski | G9: Eric Malkowski
A10: Batch | B10: 150000 | C10: 150000
A11: Batch Timeline | B11: April - November | C11: April - November
A13: Chip | B13: 6.1433 | C13: 6.1433 | D13: 0 | E13: 0 | F13: 0 | G13: 0
A14: Other Component | B14: 38.23 | C14: 45.3 | D14: 6.87 | E14: 3.79 | F14: 0.82 | G14: 3.8336
A15: BOM Margin | B15: =(B13+B14)*B23 -> 15.530655 | C15: =(C13+C14)*C23 -> 18.005155 | D15: =(D13+D14)*D23 -> 2.4045 | E15: =(E13+E14)*E23 -> 1.137 | F15: =(F13+F14)*F23 -> 0.246 | G15: =(G13+G14)*G23 -> 1.15008
A16: Packaging and Accessories | B16: 8.1762 | C16: 8.1762 | D16: 0.544 | E16: 0 | F16: 0 | G16: 0.8422
A17: Package Margin | B17: =B16*B24 -> 2.45286 | C17: =C16*C24 -> 2.45286 | D17: =D16*D24 -> 0.1632 | E17: =E16*E24 -> 0 | F17: =F16*F24 -> 0 | G17: =G16*G24 -> 0.25266
A18: Total Product Cost | B18: =SUM(B13:B17) -> 70.533015 | C18: =SUM(C13:C17) -> 80.077515 | D18: =SUM(D13:D17) -> 9.9817 | E18: =SUM(E13:E17) -> 4.927 | F18: =SUM(F13:F17) -> 1.066 | G18: =SUM(G13:G17) -> 6.07854
A20: Finance fee | B20: 10 | C20: 10 | D20: 0 | E20: 0 | F20: 0 | G20: 0
A21: PPV cost component | B21: 1.88 | C21: 1.88 | D21: 0 | E21: 0 | F21: 0 | G21: 0
A23: BOM Margin (%) | B23: 0.35 | C23: 0.35 | D23: 0.35 | E23: 0.3 | F23: 0.3 | G23: 0.3
A24: Package Margin (%) | B24: 0.3 | C24: 0.3 | D24: 0.3 | E24: 0.3 | F24: 0.3 | G24: 0.3
A26: Duty Rate | B26: =sum(B13:B17)*B32 -> 0 | C26: =sum(C13:C17)*C32 -> 0 | D26: =sum(D13:D17)*D32 -> 0.2495425 | E26: =sum(E13:E17)*E32 -> 0.167518 | F26: =sum(F13:F17)*F32 -> 0.036244 | G26: =sum(G13:G17)*G32 -> 0.20667036
A27: Tarrif Rate | B27: =sum(B13:B17)*B33 -> 5.2899761 | C27: =sum(C13:C17)*C33 -> 6.0058136 | D27: =sum(D13:D17)*D33 -> 2.495425 | E27: =sum(E13:E17)*E33 -> 0.369525 | F27: =sum(F13:F17)*F33 -> 0.07995 | G27: =sum(G13:G17)*G33 -> 0.4558905
A28: HMF | B28: =SUM($B$13:$B$17)*B34 -> 0.088166269 | C28: =SUM($B$13:$B$17)*C34 -> 0.088166269 | D28: =SUM($B$13:$B$17)*D34 -> 0.088166269 | E28: =SUM($B$13:$B$17)*E34 -> 0.088166269 | F28: =SUM($B$13:$B$17)*F34 -> 0.088166269 | G28: =SUM($B$13:$B$17)*G34 -> 0.088166269
A29: MPF | B29: =SUM($B$13:$B$17)*B35 -> 0.24432636 | C29: =SUM($B$13:$B$17)*C35 -> 0.24432636 | D29: =SUM($B$13:$B$17)*D35 -> 0.24432636 | E29: =SUM($B$13:$B$17)*E35 -> 0.24432636 | F29: =SUM($B$13:$B$17)*F35 -> 0.24432636 | G29: =SUM($B$13:$B$17)*G35 -> 0.24432636
A30: Total Port Cost | B30: =SUM(B26:B29) -> 5.6224688 | C30: =SUM(C26:C29) -> 6.3383063 | D30: =SUM(D26:D29) -> 3.0774601 | E30: =SUM(E26:E29) -> 0.86953563 | F30: =SUM(F26:F29) -> 0.44868663 | G30: =SUM(G26:G29) -> 0.99505349
A32: Duty Rate (%) | B32: 0 | C32: 0 | D32: 0.025 | E32: 0.034 | F32: 0.034 | G32: 0.034
A33: Tarrif Rate (%) | B33: 0.075 | C33: 0.075 | D33: 0.25 | E33: 0.075 | F33: 0.075 | G33: 0.075
A34: HMF (%) | B34: 0.00125 | C34: 0.00125 | D34: 0.00125 | E34: 0.00125 | F34: 0.00125 | G34: 0.00125
A35: MPF (%) | B35: 0.003464 | C35: 0.003464 | D35: 0.003464 | E35: 0.003464 | F35: 0.003464 | G35: 0.003464
A37: Total Cost | B37: =B18+B20+B21+B30 -> 88.035484 | C37: =C18+C20+C21+C30 -> 98.295821 | D37: =D18+D20+D21+D30 -> 13.05916 | E37: =E18+E20+E21+E30 -> 5.7965356 | F37: =F18+F20+F21+F30 -> 1.5146866 | G37: =G18+G20+G21+G30 -> 7.0735935
A41: Inbound Shipping
A42: Source
A43: Owner | B43: Judy Stanis | C43: Judy Stanis | D43: Judy Stanis | E43: Judy Stanis | F43: Judy Stanis | G43: Judy Stanis
A44: Controller #1 | B44: Diana Spiewak | C44: Diana Spiewak | D44: Diana Spiewak | E44: Diana Spiewak | F44: Diana Spiewak | G44: Diana Spiewak
A45: Controller #2 | B45: Eric Malkowski | C45: Eric Malkowski | D45: Eric Malkowski | E45: Eric Malkowski | F45: Eric Malkowski | G45: Eric Malkowski
A46: Batch
A47: Batch Timeline
A49: Air Freight | B49: 22.88 | C49: 22.88 | D49: 3.06 | E49: 4.88 | F49: 0.75 | G49: 2.55
A50: Fast Ocean | B50: 10.56 | C50: 10.56 | D50: 1.31 | E50: 2.09 | F50: 0.32 | G50: 0.97
A51: Ocean | B51: 2.65 | C51: 2.65 | D51: 0.39 | E51: 0.58 | F51: 0.1 | G51: 0.35
...

Sheet Business Metrics Canada
A1: Canada
A2: Product | B2: Bird Buddy | C2: Bird Buddy with Solar Roof | D2: Solar Roof | E2: Wall Mount | F2: Suet Ball Holder | G2: 3-in-1 Nutrition Set | H2: Hummingbird Feeder | I2: Perch Extender | J2: Pole System
A3: Category | B3: Bird Feeder | C3: Bird Feeder | D3: Add-on | E3: Add-on | F3: Add-on | G3: Add-on
A5: COGS
A6: Source
A7: Owner | B7: Nick Koukourakis | C7: Nick Koukourakis | D7: Nick Koukourakis | E7: Nick Koukourakis | F7: Nick Koukourakis | G7: Nick Koukourakis
A8: Controller #1 | B8: Diana Spiewak | C8: Diana Spiewak | D8: Diana Spiewak | E8: Diana Spiewak | F8: Diana Spiewak | G8: Diana Spiewak
A9: Controller #2 | B9: Eric Malkowski | C9: Eric Malkowski | D9: Eric Malkowski | E9: Eric Malkowski | F9: Eric Malkowski | G9: Eric Malkowski
A10: Batch | B10: 150000 | C10: 150000
A11: Batch Timeline | B11: April - November | C11: April - November
A13: Chip | B13: 6.1433 | C13: 6.1433 | D13: 0 | E13: 0 | F13: 0 | G13: 0
A14: Other Component | B14: 38.23 | C14: 45.3 | D14: 6.87 | E14: 3.79 | F14: 0.82 | G14: 3.8336
A15: BOM Margin | B15: =(B13+B14)*B23 -> 15.530655 | C15: =(C13+C14)*C23 -> 18.005155 | D15: =(D13+D14)*D23 -> 2.4045 | E15: =(E13+E14)*E23 -> 1.137 | F15: =(F13+F14)*F23 -> 0.246 | G15: =(G13+G14)*G23 -> 1.15008
A16: Packaging and Accessories | B16: 8.1762 | C16: 8.1762 | D16: 0.544 | E16: 0 | F16: 0 | G16: 0.8422
A17: Package Margin | B17: =B16*B24 -> 2.45286 | C17: =C16*C24 -> 2.45286 | D17: =D16*D24 -> 0.1632 | E17: =E16*E24 -> 0 | F17: =F16*F24 -> 0 | G17: =G16*G24 -> 0.25266
A18: Total Product Cost | B18: =SUM(B13:B17) -> 70.533015 | C18: =SUM(C13:C17) -> 80.077515 | D18: =SUM(D13:D17) -> 9.9817 | E18: =SUM(E13:E17) -> 4.927 | F18: =SUM(F13:F17) -> 1.066 | G18: =SUM(G13:G17) -> 6.07854
A20: Finance fee | B20: 10 | C20: 10 | D20: 0 | E20: 0 | F20: 0 | G20: 0
A21: PPV cost component | B21: 1.88 | C21: 1.88 | D21: 0 | E21: 0 | F21: 0 | G21: 0
A23: BOM Margin (%) | B23: 0.35 | C23: 0.35 | D23: 0.35 | E23: 0.3 | F23: 0.3 | G23: 0.3
A24: Package Margin (%) | B24: 0.3 | C24: 0.3 | D24: 0.3 | E24: 0.3 | F24: 0.3 | G24: 0.3
A26: Duty Rate | B26: =sum(B13:B17)*B32 -> 0 | C26: =sum(C13:C17)*C32 -> 0 | D26: =sum(D13:D17)*D32 -> 0.2495425 | E26: =sum(E13:E17)*E32 -> 0.167518 | F26: =sum(F13:F17)*F32 -> 0.036244 | G26: =sum(G13:G17)*G32 -> 0.20667036
A27: Tarrif Rate | B27: =sum(B13:B17)*B33 -> 5.2899761 | C27: =sum(C13:C17)*C33 -> 6.0058136 | D27: =sum(D13:D17)*D33 -> 2.495425 | E27: =sum(E13:E17)*E33 -> 0.369525 | F27: =sum(F13:F17)*F33 -> 0.07995 | G27: =sum(G13:G17)*G33 -> 0.4558905
A28: HMF | B28: =SUM($B$13:$B$17)*B34 -> 0.088166269 | C28: =SUM($B$13:$B$17)*C34 -> 0.088166269 | D28: =SUM($B$13:$B$17)*D34 -> 0.088166269 | E28: =SUM($B$13:$B$17)*E34 -> 0.088166269 | F28: =SUM($B$13:$B$17)*F34 -> 0.088166269 | G28: =SUM($B$13:$B$17)*G34 -> 0.088166269
A29: MPF | B29: =SUM($B$13:$B$17)*B35 -> 0.24432636 | C29: =SUM($B$13:$B$17)*C35 -> 0.24432636 | D29: =SUM($B$13:$B$17)*D35 -> 0.24432636 | E29: =SUM($B$13:$B$17)*E35 -> 0.24432636 | F29: =SUM($B$13:$B$17)*F35 -> 0.24432636 | G29: =SUM($B$13:$B$17)*G35 -> 0.24432636
A30: Total Port Cost | B30: =SUM(B26:B29) -> 5.6224688 | C30: =SUM(C26:C29) -> 6.3383063 | D30: =SUM(D26:D29) -> 3.0774601 | E30: =SUM(E26:E29) -> 0.86953563 | F30: =SUM(F26:F29) -> 0.44868663 | G30: =SUM(G26:G29) -> 0.99505349
A32: Duty Rate (%) | B32: 0 | C32: 0 | D32: 0.025 | E32: 0.034 | F32: 0.034 | G32: 0.034
A33: Tarrif Rate (%) | B33: 0.075 | C33: 0.075 | D33: 0.25 | E33: 0.075 | F33: 0.075 | G33: 0.075
A34: HMF (%) | B34: 0.00125 | C34: 0.00125 | D34: 0.00125 | E34: 0.00125 | F34: 0.00125 | G34: 0.00125
A35: MPF (%) | B35: 0.003464 | C35: 0.003464 | D35: 0.003464 | E35: 0.003464 | F35: 0.003464 | G35: 0.003464
A37: Total Cost | B37: =B18+B20+B21+B30 -> 88.035484 | C37: =C18+C20+C21+C30 -> 98.295821 | D37: =D18+D20+D21+D30 -> 13.05916 | E37: =E18+E20+E21+E30 -> 5.7965356 | F37: =F18+F20+F21+F30 -> 1.5146866 | G37: =G18+G20+G21+G30 -> 7.0735935
A41: Inbound Shipping
A42: Source
A43: Owner | B43: Judy Stanis | C43: Judy Stanis | D43: Judy Stanis | E43: Judy Stanis | F43: Judy Stanis | G43: Judy Stanis
A44: Controller #1 | B44: Diana Spiewak | C44: Diana Spiewak | D44: Diana Spiewak | E44: Diana Spiewak | F44: Diana Spiewak | G44: Diana Spiewak
A45: Controller #2 | B45: Eric Malkowski | C45: Eric Malkowski | D45: Eric Malkowski | E45: Eric Malkowski | F45: Eric Malkowski | G45: Eric Malkowski
A46: Batch
A47: Batch Timeline
A49: Air Freight | B49: 22.88 | C49: 22.88 | D49: 3.06 | E49: 4.88 | F49: 0.75 | G49: 2.55
A50: Fast Ocean | B50: 10.56 | C50: 10.56 | D50: 1.31 | E50: 2.09 | F50: 0.32 | G50: 0.97
A51: Ocean | B51: 2.65 | C51: 2.65 | D51: 0.39 | E51: 0.58 | F51: 0.1 | G51: 0.35
...

Sheet Business Metrics EU
A1: Europe
A2: Product | B2: Bird Buddy | C2: Bird Buddy with Solar Roof | D2: Solar Roof | E2: Wall Mount | F2: Suet Ball Holder | G2: 3-in-1 Nutrition Set | H2: Hummingbird Feeder | I2: Perch Extender | J2: Pole System
A3: Category | B3: Bird Feeder | C3: Bird Feeder | D3: Add-on | E3: Add-on | F3: Add-on | G3: Add-on
A5: COGS
A6: Source
A7: Owner | B7: Nick Koukourakis | C7: Nick Koukourakis | D7: Nick Koukourakis | E7: Nick Koukourakis | F7: Nick Koukourakis | G7: Nick Koukourakis
A8: Controller #1 | B8: Diana Spiewak | C8: Diana Spiewak | D8: Diana Spiewak | E8: Diana Spiewak | F8: Diana Spiewak | G8: Diana Spiewak
A9: Controller #2 | B9: Eric Malkowski | C9: Eric Malkowski | D9: Eric Malkowski | E9: Eric Malkowski | F9: Eric Malkowski | G9: Eric Malkowski
A10: Batch | B10: 150000 | C10: 150000
A11: Batch Timeline | B11: April - November | C11: April - November
A13: Chip | B13: 6.1433 | C13: 6.1433 | D13: 0 | E13: 0 | F13: 0 | G13: 0
A14: Other Component | B14: 38.23 | C14: 45.3 | D14: 6.87 | E14: 3.79 | F14: 0.82 | G14: 4.91
A15: BOM Margin | B15: =(B13+B14)*B23 -> 15.530655 | C15: =(C13+C14)*C23 -> 18.005155 | D15: =(D13+D14)*D23 -> 2.4045 | E15: =(E13+E14)*E23 -> 1.137 | F15: =(F13+F14)*F23 -> 0.246 | G15: =(G13+G14)*G23 -> 1.473
A16: Packaging and Accessories | B16: 8.1762 | C16: 8.1762 | D16: 0.544 | E16: 0 | F16: 0 | G16: 0.78
A17: Package Margin | B17: =B16*B24 -> 2.45286 | C17: =C16*C24 -> 2.45286 | D17: =D16*D24 -> 0.1632 | E17: =E16*E24 -> 0 | F17: =F16*F24 -> 0 | G17: =G16*G24 -> 0.234
A18: Total Product Cost | B18: =SUM(B13:B17) -> 70.533015 | C18: =SUM(C13:C17) -> 80.077515 | D18: =SUM(D13:D17) -> 9.9817 | E18: =SUM(E13:E17) -> 4.927 | F18: =SUM(F13:F17) -> 1.066 | G18: =SUM(G13:G17) -> 7.397
A20: Finance fee | B20: 10 | C20: 10 | D20: 0 | E20: 0 | F20: 0 | G20: 0
A21: PPV cost component | B21: 1.88 | C21: 1.88 | D21: 0 | E21: 0 | F21: 0 | G21: 0
A23: BOM Margin (%) | B23: 0.35 | C23: 0.35 | D23: 0.35 | E23: 0.3 | F23: 0.3 | G23: 0.3
A24: Package Margin (%) | B24: 0.3 | C24: 0.3 | D24: 0.3 | E24: 0.3 | F24: 0.3 | G24: 0.3
A26: Duty Rate | B26: =sum(B13:B17)*B32 -> 0 | C26: =sum(C13:C17)*C32 -> 0 | D26: =sum(D13:D17)*D32 -> 0.2495425 | E26: =sum(E13:E17)*E32 -> 0.167518 | F26: =sum(F13:F17)*F32 -> 0.036244 | G26: =sum(G13:G17)*G32 -> 0.251498
A27: Tarrif Rate | B27: =sum(B13:B17)*B33 -> 5.2899761 | C27: =sum(C13:C17)*C33 -> 6.0058136 | D27: =sum(D13:D17)*D33 -> 2.495425 | E27: =sum(E13:E17)*E33 -> 0.369525 | F27: =sum(F13:F17)*F33 -> 0.07995 | G27: =sum(G13:G17)*G33 -> 0.554775
A28: HMF | B28: =SUM($B$13:$B$17)*B34 -> 0.088166269 | C28: =SUM($B$13:$B$17)*C34 -> 0.088166269 | D28: =SUM($B$13:$B$17)*D34 -> 0.088166269 | E28: =SUM($B$13:$B$17)*E34 -> 0.088166269 | F28: =SUM($B$13:$B$17)*F34 -> 0.088166269 | G28: =SUM($B$13:$B$17)*G34 -> 0.088166269
A29: MPF | B29: =SUM($B$13:$B$17)*B35 -> 0.24432636 | C29: =SUM($B$13:$B$17)*C35 -> 0.24432636 | D29: =SUM($B$13:$B$17)*D35 -> 0.24432636 | E29: =SUM($B$13:$B$17)*E35 -> 0.24432636 | F29: =SUM($B$13:$B$17)*F35 -> 0.24432636 | G29: =SUM($B$13:$B$17)*G35 -> 0.24432636
A30: Total Port Cost | B30: =SUM(B26:B29) -> 5.6224688 | C30: =SUM(C26:C29) -> 6.3383063 | D30: =SUM(D26:D29) -> 3.0774601 | E30: =SUM(E26:E29) -> 0.86953563 | F30: =SUM(F26:F29) -> 0.44868663 | G30: =SUM(G26:G29) -> 1.1387656
A32: Duty Rate (%) | B32: 0 | C32: 0 | D32: 0.025 | E32: 0.034 | F32: 0.034 | G32: 0.034
A33: Tarrif Rate (%) | B33: 0.075 | C33: 0.075 | D33: 0.25 | E33: 0.075 | F33: 0.075 | G33: 0.075
A34: HMF (%) | B34: 0.00125 | C34: 0.00125 | D34: 0.00125 | E34: 0.00125 | F34: 0.00125 | G34: 0.00125
A35: MPF (%) | B35: 0.003464 | C35: 0.003464 | D35: 0.003464 | E35: 0.003464 | F35: 0.003464 | G35: 0.003464
A37: Total Cost | B37: =B18+B20+B21+B30 -> 88.035484 | C37: =C18+C20+C21+C30 -> 98.295821 | D37: =D18+D20+D21+D30 -> 13.05916 | E37: =E18+E20+E21+E30 -> 5.7965356 | F37: =F18+F20+F21+F30 -> 1.5146866 | G37: =G18+G20+G21+G30 -> 8.5357656
A41: Inbound Shipping
A42: Source
A43: Owner | B43: Judy Stanis | C43: Judy Stanis | D43: Judy Stanis | E43: Judy Stanis | F43: Judy Stanis | G43: Judy Stanis
A44: Controller #1 | B44: Diana Spiewak | C44: Diana Spiewak | D44: Diana Spiewak | E44: Diana Spiewak | F44: Diana Spiewak | G44: Diana Spiewak
A45: Controller #2 | B45: Eric Malkowski | C45: Eric Malkowski | D45: Eric Malkowski | E45: Eric Malkowski | F45: Eric Malkowski | G45: Eric Malkowski
A46: Batch
A47: Batch Timeline
A49: Air Freight | B49: 22.88 | C49: 22.88 | D49: 3.06 | E49: 4.88 | F49: 0.75 | G49: 2.55
A50: Fast Ocean | B50: 10.56 | C50: 10.56 | D50: 1.31 | E50: 2.09 | F50: 0.32 | G50: 0.97
A51: Ocean | B51: 2.65 | C51: 2.65 | D51: 0.39 | E51: 0.58 | F51: 0.1 | G51: 0.35
...

Sheet SupermetricsQueries
A1: Supermetrics Queries
A3: All the queries created by Supermetrics are stored here, each in its own row.
H4: 16406162
A5: On this sheet you can:
A6: 1. Modify the parameters of a query. Any changes will be visible when you run a refresh.
A8: 2. Remove a query by deleting its row | H8: Europe/Paris
A10: 3. Add new queries: type a range address and query parameters, leave the query ID empty. The query will be added when you run a refresh. (Of course, it's much easier to use the sidebar to add new queries.)
A13: Queries are stored with the authentication of the original user that created the query. If you want to transfer a query to the currently active Google Sheets user, delete its query ID from column A and run a refresh. For complete instructions on transferring queries, see https://support.supermetrics.com/support/solutions/articles/19000050074-how-can-i-transfer-queries-from-one-user-to-another-
A16: Don't delete or rename this sheet. If you delete or rename it, your existing queries can no longer be refreshed. Hiding the sheet is OK. Also, don't delete any rows above row 21.
A19: Query ID | D19: Sheet name | E19: Range address | G19: Created | H19: Updated | I19: Last status | J19: Last refresh ID | K19: Results contain sampled data | L19: Execution time (sec) | M19: Object type | N19: Linked chart ID | O19: Data source | Q19: Date range type | R19: Start date | S19: End date | T19: Compare to | U19: Comparison value type | W19: Accounts/views | X19: Metrics | Y19: Dimensions | Z19: Pivot dimensions | AA19: Filters | AB19: Segment ID | AC19: Sort | AD19: Max rows | AE19: Max pivot categories | AF19: Special settings | AG19: Other parameters | AJ19: Result type | AK19: Language/country | AL19: Translate to | AN19: SQL | AO19: Database name | AP19: Range address (static) | AQ19: Report type | AT19: Highlight with colour | AU19: Refresh with user account | AV19: Returned data
A20: paramsID | C20: ssID | D20: sheetName | E20: rangeAddress | G20: created | H20: updated | I20: lastStatus | J20: lastqueryID | K20: sampled | L20: runtime_sec | M20: objType | N20: linkedChartID | O20: dataSource | Q20: dateRangeType | R20: startDateString | S20: endDateString | T20: comp | U20: cvt | W20: profiles | X20: metrics | Y20: dimensions | Z20: sd | AA20: filterArr | AB20: segment | AC20: sort | AD20: maxResults | AE20: maxCategories | AF20: specialSettings | AG20: otherParams | AJ20: sds_result_type | AK20: sds_lang | AL20: sds_tolang | AN20: sql | AO20: db_name | AP20: rangeAddressStatic | AQ20: rt | AR20: scopeMZ | AS20: sortMZ | AT20: condform | AU20: authUser | AV20: metaDataToUser
A21: pxuhRTEmIU93xSgKclyxajD0fCZ6rF | D21: =IFERROR(__xludf.DUMMYFUNCTION("ARRAY_CONSTRAIN(split(CELL(""ADDRESS"",zsupermetrics_pxuhRTEmIU93xSgKclyxajD0fCZ6rF),""!""),1,1)"),"#REF!") -> #REF! | E21: =CELL("ADDRESS",zsupermetrics_pxuhRTEmIU93xSgKclyxajD0fCZ6rF)&":"&address(row(zsupermetrics_pxuhRTEmIU93xSgKclyxajD0fCZ6rF)+rows(zsupermetrics_pxuhRTEmIU93xSgKclyxajD0fCZ6rF)-1,column(zsupermetrics_pxuhRTEmIU93xSgKclyxajD0fCZ6rF)+COLUMNS(zsupermetrics_pxuhRTEmIU93xSgKclyxajD0fCZ6rF)-1) -> #REF! | G21: 44557.697 | H21: 44557.839 | I21: Created successfully | K21: FALSE | L21: 4 | M21: TABLE | O21: SHP | Q21: thismonth | W21: ["gid://shopify/Shop/55807180983`Bird Buddy"] | X21: ["gross_sales","returns","shipping","tax","total_sales","sm_order_count"] | Y21: [] | Z21: ["date"] | AA21: [] | AB21: [] | AD21: 10000 | AE21: 50 | AF21: ["METRICS_IN_ROWS","MULTILEVEL_COL_HEADERS"] | AG21: {} | AP21: Shopify 1'!A1:AB7 | AU21: gid://shopify/Shop/55807180983
