Workbook
Name rdataslayer_d70e473bcafe40a3aa834ce157fb2ba3: 'Business Metrics Canada'!$C$16:$D$17
Name zsupermetrics_xwoIpANxRm908eDp5oKTwQpEI8gvD4: 'Business Metrics US'!$A$5
Name zsupermetrics_ru0GDtbZzDLHQOQtJJ6K08MvUDyyp7: Formulas!$B$5:$B$6
Name zsupermetrics_iNpyVy90bWCI0yUaFQpxOtzWMa6sW4: 'Business Metrics US'!$A$5:$A$12
Name zsupermetrics_NugLlrQxlKiqhxQae8EFpITBm1pLCj: 'Business Metrics Canada'!$B$15:$C$23
Name rdataslayer_4a0f150f4f2f4e4f85c890c75b7a1fa4: 'Business Metrics Canada'!$D$5:$E$12
Name zsupermetrics_refreshAll: SupermetricsQueries!$H$5
Name zsupermetrics_DQl8lUbpTRu3fayaJJi7lVfOGKjNU4: 'Business Metrics Canada'!$A$2:$A$13
Name zsupermetrics_n3GtLgiKpTmd2pYmQNMuq6TPD0qE0b: Formulas!$B$5:$B$6
Name zsupermetrics_9i4W4hgd80uRpQLMeX0eRnESN8gjyv: 'Business Metrics US'!$C$23
Name zsupermetrics_qWp7V908pNEYMtfv8QZvSTeDnBAHOU: 'Business Metrics Canada'!$B$14:$C$23
Name zsupermetrics_refreshAllSilent: SupermetricsQueries!$H$6
Name zsupermetrics_Mgms9p0QzysYvrIhnsKACeVBVxfIEO: Formulas!$A$3:$A$4
Name rdataslayer_4a0f150f4f2f4e4f85c890c75b7a1fa4: 'Business Metrics US'!$D$5:$E$12
Name zsupermetrics_lx4cNai7gT6tH4j08ZRkI21Qlpjioi: 'Business Metrics Canada'!$B$13:$C$23
Name zsupermetrics_forceRefresh: SupermetricsQueries!$H$4
Name zsupermetrics_wbYMmT0YL9bAN0yhimW0ziPFnia9Dx: Formulas!$A$3:$A$4
Name zsupermetrics_iNpyVy90bWCI0yUaFQpxOtzWMa6sW4: Formulas!$A$3:$A$4
Name zsupermetrics_xwoIpANxRm908eDp5oKTwQpEI8gvD4: 'Business Metrics Canada'!$A$5
Name rdataslayer_3753ddf3234e496aa261974a0222e193: 'Business Metrics US'!$H$5:$I$5
Name zsupermetrics_4VkB7ij7WO0JjKBEgvjB2GHjSy2Egm: 'Business Metrics Canada'!$B$13:$C$17
Name zsupermetrics_wbYMmT0YL9bAN0yhimW0ziPFnia9Dx: 'Business Metrics Canada'!$A$5:$A$12
Name zsupermetrics_9i4W4hgd80uRpQLMeX0eRnESN8gjyv: Formulas!$C$14
Name zsupermetrics_YsFuuYtr8vOdNXCCPiFJIO38NP4b2T: 'Business Metrics US'!$B$13:$C$23
Name rdataslayer_adf57e64065742daa5b4161161b1c3ca: 'Business Metrics Canada'!$B$13:$D$14
Name zsupermetrics_9i4W4hgd80uRpQLMeX0eRnESN8gjyv: 'Business Metrics Canada'!$C$23
Name zsupermetrics_4VkB7ij7WO0JjKBEgvjB2GHjSy2Egm: 'Business Metrics US'!$B$13:$C$17
Name zsupermetrics_pxuhRTEmIU93xSgKclyxajD0fCZ6rF: #REF!
Name zsupermetrics_wbYMmT0YL9bAN0yhimW0ziPFnia9Dx: 'Business Metrics US'!$A$5:$A$12
Name rdataslayer_4a0f150f4f2f4e4f85c890c75b7a1fa4: Formulas!$D$3:$E$4
Name zsupermetrics_iNpyVy90bWCI0yUaFQpxOtzWMa6sW4: 'Business Metrics Canada'!$A$5:$A$12
Name zsupermetrics_HgZqhorObHOtZHuyJjpmyYaEPoYntx: Formulas!$B$5:$B$6
Name zsupermetrics_YsFuuYtr8vOdNXCCPiFJIO38NP4b2T: Formulas!$B$5:$C$14
Name zsupermetrics_DQl8lUbpTRu3fayaJJi7lVfOGKjNU4: Formulas!$A$4:$A$5
Name zsupermetrics_4VkB7ij7WO0JjKBEgvjB2GHjSy2Egm: Formulas!$B$5:$C$11
Name zsupermetrics_Mgms9p0QzysYvrIhnsKACeVBVxfIEO: 'Business Metrics US'!$A$5:$A$12
Name zsupermetrics_lx4cNai7gT6tH4j08ZRkI21Qlpjioi: Formulas!$B$5:$C$14
Name zsupermetrics_BioPyGBzcBsy60UCQmPcTuFReEmghI: 'Business Metrics US'!$B$5:$B$12
Name zsupermetrics_qWp7V908pNEYMtfv8QZvSTeDnBAHOU: 'Business Metrics US'!$B$14:$C$23
Name rdataslayer_adf57e64065742daa5b4161161b1c3ca: 'Business Metrics US'!$B$13:$D$14
Name rdataslayer_d70e473bcafe40a3aa834ce157fb2ba3: Formulas!$C$9:$D$10
Name zsupermetrics_8xojRjNDjo2jWHGDWjFEhflhyIq3Hq: Sales!$K$8:$K$9
Name rdataslayer_42b112e4e4be4305bb4c1be75e2dd549: 'Business Metrics Canada'!$B$5:$C$12
Name rdataslayer_d70e473bcafe40a3aa834ce157fb2ba3: 'Business Metrics US'!$C$16:$D$17
Name rdataslayer_3753ddf3234e496aa261974a0222e193: Formulas!$H$3:$I$3
Name zsupermetrics_BioPyGBzcBsy60UCQmPcTuFReEmghI: 'Business Metrics Canada'!$B$5:$B$12
Name zsupermetrics_DQl8lUbpTRu3fayaJJi7lVfOGKjNU4: 'Business Metrics US'!$A$2:$A$13
Name zsupermetrics_HgZqhorObHOtZHuyJjpmyYaEPoYntx: 'Business Metrics US'!$B$13:$B$14
Name zsupermetrics_BioPyGBzcBsy60UCQmPcTuFReEmghI: Formulas!$B$3:$B$4
Name zsupermetrics_qWp7V908pNEYMtfv8QZvSTeDnBAHOU: Formulas!$B$6:$C$14
Name zsupermetrics_NugLlrQxlKiqhxQae8EFpITBm1pLCj: 'Business Metrics US'!$B$15:$C$23
Name rdataslayer_3753ddf3234e496aa261974a0222e193: 'Business Metrics Canada'!$H$5:$I$5
Name zsupermetrics_n3GtLgiKpTmd2pYmQNMuq6TPD0qE0b: 'Business Metrics US'!$B$13:$B$14
Name rdataslayer_42b112e4e4be4305bb4c1be75e2dd549: 'Business Metrics US'!$B$5:$C$12
Name zsupermetrics_lx4cNai7gT6tH4j08ZRkI21Qlpjioi: 'Business Metrics US'!$B$13:$C$23
Name rdataslayer_42b112e4e4be4305bb4c1be75e2dd549: Formulas!$B$3:$C$4
Name zsupermetrics_n3GtLgiKpTmd2pYmQNMuq6TPD0qE0b: 'Business Metrics Canada'!$B$13:$B$14
Name rdataslayer_adf57e64065742daa5b4161161b1c3ca: Formulas!$B$5:$D$6
Name zsupermetrics_ru0GDtbZzDLHQOQtJJ6K08MvUDyyp7: 'Business Metrics Canada'!$B$13:$B$14
Name zsupermetrics_HgZqhorObHOtZHuyJjpmyYaEPoYntx: 'Business Metrics Canada'!$B$13:$B$14

Sheet DataslayerQueries
A1: Query UUID | B1: Sheet name | C1: Range address | D1: Created | E1: Updated | F1: Last status | G1: Last refresh ID | H1: Results contain sampled data | I1: Execution time (sec) | J1: Object type | K1: Linked chart ID | L1: Data source | M1: Date range type | N1: Start date | O1: End date | P1: Compare to | Q1: Comparison value type | R1: Accounts/views | S1: Metrics | T1: Dimensions | U1: Pivot dimensions | V1: Filters | W1: Segment ID | X1: Segment dim | Y1: Sort | Z1: Max rows | AA1: Max pivot categories | AB1: Special settings | AC1: Other parameters | AD1: Result type | AE1: Language/country | AF1: Translate to | AG1: SQL | AH1: Database name | AI1: Range address (static) | AJ1: Report type | AK1: Highlight with colour | AL1: Refresh with user account | AM1: Returned data | AN1: Sort dimensions | AO1: Created by user account
A2: 42b112e4e4be4305bb4c1be75e2dd549 | B2: =IFERROR(__xludf.DUMMYFUNCTION("ARRAY_CONSTRAIN(split(CELL(""ADDRESS"",rdataslayer_42b112e4e4be4305bb4c1be75e2dd549),""!""),1,1)"),"Formulas") -> Formulas | C2: =IFERROR(__xludf.DUMMYFUNCTION("INDEX(split(CELL(""ADDRESS"",rdataslayer_42b112e4e4be4305bb4c1be75e2dd549),""!""),0,2)&"":""&address(row(rdataslayer_42b112e4e4be4305bb4c1be75e2dd549)+rows(rdataslayer_42b112e4e4be4305bb4c1be75e2dd549)-1,column(rdataslayer_42b112e4e4be4305bb4c1be75e2dd549"&")+COLUMNS(rdataslayer_42b112e4e4be4305bb4c1be75e2dd549)-1)"),"$B$3:$C$4") -> $B$3:$C$4 | D2: 44518.613 | E2: 44520.051 | F2: There is no data for the specified input | I2: 7 | J2: TABLE | L2: facebook | M2: yesterday | R2: [{"profile_id":"","name":"si_Bird buddy Inc_US &amp; CA_BirdBuddy","id":"act_273249767551281","account_name":"","advertiser_id":""}] | S2: [{"id":"spend","name":"Total Cost"}] | T2: [{"id":"date","name":"Date"}] | U2: [] | V2: [] | W2: [] | Y2: [] | Z2: 5 | AA2: 5 | AB2: {} | AC2: {} | AL2: User_Kumalic_Benjamin | AN2: [] | AO2: benjamin@mybirdbuddy.com
A3: 4a0f150f4f2f4e4f85c890c75b7a1fa4 | B3: =IFERROR(__xludf.DUMMYFUNCTION("ARRAY_CONSTRAIN(split(CELL(""ADDRESS"",rdataslayer_4a0f150f4f2f4e4f85c890c75b7a1fa4),""!""),1,1)"),"Formulas") -> Formulas | C3: =IFERROR(__xludf.DUMMYFUNCTION("INDEX(split(CELL(""ADDRESS"",rdataslayer_4a0f150f4f2f4e4f85c890c75b7a1fa4),""!""),0,2)&"":""&address(row(rdataslayer_4a0f150f4f2f4e4f85c890c75b7a1fa4)+rows(rdataslayer_4a0f150f4f2f4e4f85c890c75b7a1fa4)-1,column(rdataslayer_4a0f150f4f2f4e4f85c890c75b7a1fa4"&")+COLUMNS(rdataslayer_4a0f150f4f2f4e4f85c890c75b7a1fa4)-1)"),"$D$3:$E$4") -> $D$3:$E$4 | D3: 44518.615 | E3: 44520.051 | F3: There is no data for the specified input | I3: 7 | J3: TABLE | L3: facebook | M3: yesterday | R3: [{"account_name":"","advertiser_id":"","id":"act_273249767551281","profile_id":"","name":"si_Bird buddy Inc_US &amp; CA_BirdBuddy"}] | S3: [{"id":"spend","name":"Total Cost"}] | T3: [] | U3: [{"id":"date","name":"Date"}] | V3: [] | W3: [] | Y3: [] | Z3: 5 | AA3: 5 | AB3: {} | AC3: {} | AL3: User_Kumalic_Benjamin | AN3: [] | AO3: benjamin@mybirdbuddy.com
A4: adf57e64065742daa5b4161161b1c3ca | B4: =IFERROR(__xludf.DUMMYFUNCTION("ARRAY_CONSTRAIN(split(CELL(""ADDRESS"",rdataslayer_adf57e64065742daa5b4161161b1c3ca),""!""),1,1)"),"Formulas") -> Formulas | C4: =IFERROR(__xludf.DUMMYFUNCTION("INDEX(split(CELL(""ADDRESS"",rdataslayer_adf57e64065742daa5b4161161b1c3ca),""!""),0,2)&"":""&address(row(rdataslayer_adf57e64065742daa5b4161161b1c3ca)+rows(rdataslayer_adf57e64065742daa5b4161161b1c3ca)-1,column(rdataslayer_adf57e64065742daa5b4161161b1c3ca"&")+COLUMNS(rdataslayer_adf57e64065742daa5b4161161b1c3ca)-1)"),"$B$5:$D$6") -> $B$5:$D$6 | D4: 44518.618 | E4: 44520.051 | F4: There is no data for the specified input | I4: 18 | J4: TABLE | L4: facebook | M4: yesterday | R4: [{"name":"si_Bird buddy Inc_US &amp; CA_BirdBuddy","id":"act_273249767551281","profile_id":"","account_name":"","advertiser_id":""}] | S4: [{"id":"spend","name":"Total Cost"},{"id":"cpm","name":"CPM"}] | T4: [{"id":"date","name":"Date"}] | U4: [] | V4: [] | W4: [] | Y4: [] | Z4: 5 | AA4: 5 | AB4: {} | AC4: {} | AL4: User_Kumalic_Benjamin | AN4: [] | AO4: benjamin@mybirdbuddy.com
A5: d70e473bcafe40a3aa834ce157fb2ba3 | B5: =IFERROR(__xludf.DUMMYFUNCTION("ARRAY_CONSTRAIN(split(CELL(""ADDRESS"",rdataslayer_d70e473bcafe40a3aa834ce157fb2ba3),""!""),1,1)"),"Formulas") -> Formulas | C5: =IFERROR(__xludf.DUMMYFUNCTION("INDEX(split(CELL(""ADDRESS"",rdataslayer_d70e473bcafe40a3aa834ce157fb2ba3),""!""),0,2)&"":""&address(row(rdataslayer_d70e473bcafe40a3aa834ce157fb2ba3)+rows(rdataslayer_d70e473bcafe40a3aa834ce157fb2ba3)-1,column(rdataslayer_d70e473bcafe40a3aa834ce157fb2ba3"&")+COLUMNS(rdataslayer_d70e473bcafe40a3aa834ce157fb2ba3)-1)"),"$C$9:$D$10") -> $C$9:$D$10 | D5: 44518.619 | E5: 44520.051 | F5: There is no data for the specified input | I5: 7 | J5: TABLE | L5: facebook | M5: yesterday | R5: [{"advertiser_id":"","name":"si_Bird buddy Inc_US &amp; CA_BirdBuddy","id":"act_273249767551281","account_name":"","profile_id":""}] | S5: [{"id":"spend","name":"Total Cost"}] | T5: [{"id":"date","name":"Date"}] | U5: [] | V5: [] | W5: [] | Y5: [] | Z5: 100 | AA5: 100 | AB5: {} | AC5: {} | AL5: User_Kumalic_Benjamin | AN5: [] | AO5: benjamin@mybirdbuddy.com
A6: 3753ddf3234e496aa261974a0222e193 | B6: =IFERROR(__xludf.DUMMYFUNCTION("ARRAY_CONSTRAIN(split(CELL(""ADDRESS"",rdataslayer_3753ddf3234e496aa261974a0222e193),""!""),1,1)"),"Formulas") -> Formulas | C6: =IFERROR(__xludf.DUMMYFUNCTION("INDEX(split(CELL(""ADDRESS"",rdataslayer_3753ddf3234e496aa261974a0222e193),""!""),0,2)&"":""&address(row(rdataslayer_3753ddf3234e496aa261974a0222e193)+rows(rdataslayer_3753ddf3234e496aa261974a0222e193)-1,column(rdataslayer_3753ddf3234e496aa261974a0222e193"&")+COLUMNS(rdataslayer_3753ddf3234e496aa261974a0222e193)-1)"),"$H$3:$I$3") -> $H$3:$I$3 | D6: 44518.621 | E6: 44520.051 | F6: There is no data for the specified input | I6: 18 | J6: TABLE | L6: facebook | M6: yesterday | R6: [{"profile_id":"","account_name":"","advertiser_id":"","name":"si_Bird buddy Inc_US &amp; CA_BirdBuddy","id":"act_273249767551281"}] | S6: [{"id":"spend","name":"Total Cost"}] | T6: [] | U6: [] | V6: [] | W6: [] | Y6: [] | Z6: 100 | AA6: 100 | AB6: {"exclude_header_row":true} | AC6: {} | AL6: User_Kumalic_Benjamin | AN6: [] | AO6: benjamin@mybirdbuddy.com

Sheet Sales
A1: 45078 | B1: 45078 | C1: 45079 | D1: 45080 | E1: 45081 | F1: 45082 | G1: 45083 | H1: 45084 | I1: 45085 | J1: 45086 | K1: 45087 | L1: 45088 | M1: 45089 | N1: 45090 | O1: 45091 | P1: 45092 | Q1: 45093 | R1: 45094 | S1: 45095 | T1: 45096 | U1: 45097 | V1: 45098 | W1: 45099 | X1: 45100 | Y1: 45101 | Z1: 45102 | AA1: 45103 | AB1: 45104 | AC1: 45105 | AD1: 45106 | AE1: 45107
B2: THU | C2: FRI | D2: SAT | E2: SUN | F2: MON | G2: TUE | H2: WED | I2: THU | J2: FRI | K2: SAT | L2: SUN | M2: MON | N2: TUE | O2: WED | P2: THU | Q2: FRI | R2: SAT | S2: SUN | T2: MON | U2: TUE | V2: WED | W2: THU | X2: FRI | Y2: SAT | Z2: SUN | AA2: MON | AB2: TUE | AC2: WED | AD2: THU | AE2: FRI
A3: Weekend Work | D3: Peco | E3: Peco | K3: Gaja | L3: Gaja | R3: Peco | S3: Peco | Y3: Peco | Z3: Peco
O4: Fathers Day | AE4: Summer Sales
M5: Shipping Now Test | U5: Payment providers stop working | AB5: WooCommerce switch at 18:24, last Shopify order #183523
A8: Shopify | B8: 37285.47 | C8: 46599.75 | D8: 46367.55 | E8: 40297.62 | F8: 41509.4 | G8: 41342.95 | H8: 38115.1 | I8: 54242.89 | J8: 49227.15 | K8: 42538.3 | L8: 43625.02 | M8: 51022.38 | N8: 60134.96 | O8: 62926.35 | P8: 65481.78 | Q8: 57018.23 | R8: 69211.15 | S8: 94472.61 | T8: 63754.21 | U8: 27186.32 | V8: 14833.39 | W8: 15136.45 | X8: 18667.99 | Y8: 23460.16 | Z8: 44629.89 | AA8: 31036.14 | AB8: 28402.03 | AC8: 19037.19 | AD8: 21890.55 | AE8: 26087.44
A9: Total Revenue | B9: =SUM(B8) -> 37285.47 | C9: =SUM(C8) -> 46599.75 | D9: =SUM(D8) -> 46367.55 | E9: =SUM(E8) -> 40297.62 | F9: =SUM(F8) -> 41509.4 | G9: =SUM(G8) -> 41342.95 | H9: =SUM(H8) -> 38115.1 | I9: =SUM(I8) -> 54242.89 | ... AE9: =SUM(AE8) -> 26087.44
A10: Orders | B10: 143 | C10: 152 | D10: 183 | E10: 156 | F10: 153 | G10: 165 | H10: 150 | I10: 205 | J10: 189 | K10: 166 | L10: 167 | M10: 227 | N10: 231 | O10: 238 | P10: 258 | Q10: 222 | R10: 263 | S10: 378 | T10: 245 | U10: 110 | V10: 66 | W10: 57 | X10: 89 | Y10: 90 | Z10: 175 | AA10: 110 | AB10: =69+42 -> 111 | AC10: 79 | AD10: 97 | AE10: 107
A12: FB - US & CA | B12: 5819.35 | C12: 6351.79 | D12: 6995.09 | E12: 6480.56 | F12: 5823.01 | G12: 5934.08 | H12: 5813 | I12: 5781.36 | J12: 5734.34 | K12: 5529.15 | L12: 6108.87 | M12: 6044.18 | N12: 5477.22 | O12: 5473.72 | P12: 7942.82 | Q12: 10262.5 | R12: 11301.08 | S12: 11986.12 | T12: 11892.42 | U12: 6768.77 | V12: 0 | W12: 0 | X12: 1604.81 | Y12: 1595.97 | Z12: 2982.76 | AA12: 4321 | AB12: 3388.35 | AC12: 2990.92 | AD12: 4398.82 | AE12: 5398.79
A13: Google - WW | B13: 6834.34 | C13: 10214.61 | D13: 9297.35 | E13: 7824.73 | F13: 7747.63 | G13: 7082.13 | H13: 8111.48 | I13: 7959.23 | J13: 8775.49 | K13: 12799.76 | L13: 14428.68 | M13: 14510.17 | N13: 13329.58 | O13: 11868.87 | P13: 8491.53 | Q13: 8350.94 | R13: 8945.22 | S13: 9485.66 | T13: 8248.1 | U13: 7251.03 | V13: 4471.26 | W13: 0 | X13: 340.43 | Y13: 2834.24 | Z13: 3962.71 | AA13: 3345.79 | AB13: 3573.3 | AC13: 3314.72 | AD13: 2934.13 | AE13: 2905.43
A14: Bing - WW | B14: 259.98 | C14: 273.58 | D14: 257.11 | E14: 262.79 | F14: 187.4 | G14: 235.08 | H14: 262.2 | I14: 257.03 | J14: 0 | K14: 0 | L14: 219.13 | M14: 253.88 | N14: 259.97 | O14: 259.17 | P14: 266.81 | Q14: 259.99 | R14: 266.7 | S14: 261.75 | T14: 264.9 | U14: 221.94 | V14: 0 | W14: 0 | X14: 0 | Y14: 0 | Z14: 0 | AA14: 0 | AB14: 0 | AC14: 0 | AD14: 0 | AE14: 0
A15: TikTok - US & CA | B15: 319.5 | C15: 167.28 | D15: 165.57 | E15: 167.6 | F15: 78.15 | G15: 0 | H15: 0 | I15: 0 | J15: 0 | K15: 0 | L15: 0 | M15: 0 | N15: 0 | O15: 0 | P15: 0 | Q15: 206.92 | R15: 396.46 | S15: 396.41 | T15: 400 | U15: 239.31 | V15: 125.08 | W15: 0 | X15: 0 | Y15: 0 | Z15: 0 | AA15: 0 | AB15: 0 | AC15: 0 | AD15: 0 | AE15: 0
A16: MNTN TV
A17: Affiliate Fees - US | B17: 0 | C17: 58.44 | D17: 212.47 | E17: 0 | F17: 205.69 | G17: 200.16 | H17: 16.88 | I17: 0 | J17: 137.31 | K17: 150.23 | L17: 267.68 | M17: 76.11 | N17: 305.87 | O17: 295.93 | P17: 290.62 | Q17: 0 | R17: 325.96 | S17: 376.14 | T17: 283.3 | U17: =68.32+39.97+64.84 -> 173.13 | V17: 0 | W17: =55.91+80.49+44.41+74.99 -> 255.8 | X17: =64.39+25.04 -> 89.43 | Y17: =65+59.22 -> 124.22 | Z17: =65.45+91.69+16.88+71.71 -> 245.73 | AA17: 62.62 | AB17: 56.04 | AC17: 0 | AD17: 0 | AE17: 0
A18: Total Spend | B18: =SUM(B12:B17) -> 13233.17 | C18: =SUM(C12:C17) -> 17065.7 | D18: =SUM(D12:D17) -> 16927.59 | E18: =SUM(E12:E17) -> 14735.68 | F18: =SUM(F12:F17) -> 14041.88 | G18: =SUM(G12:G17) -> 13451.45 | H18: =SUM(H12:H17) -> 14203.56 | I18: =SUM(I12:I17) -> 13997.62 | ... AE18: =SUM(AE12:AE17) -> 8304.22
A20: ROAS | B20: =B9/B18 -> 2.8175766 | C20: =C9/C18 -> 2.7306088 | D20: =D9/D18 -> 2.7391702 | E20: =E9/E18 -> 2.734697 | F20: =F9/F18 -> 2.9561141 | G20: =G9/G18 -> 3.0734939 | H20: =H9/H18 -> 2.6834892 | I20: =I9/I18 -> 3.8751509 | ... AE20: =AE9/AE18 -> 3.1414678
A21: Spend per Unit | B21: =B18/'Detailed Report'!B141 -> 101.79362 | C21: =C18/'Detailed Report'!C141 -> 130.27252 | D21: =D18/'Detailed Report'!D141 -> 109.21026 | E21: =E18/'Detailed Report'!E141 -> 109.96776 | F21: =F18/'Detailed Report'!F141 -> 101.75275 | G21: =G18/'Detailed Report'!G141 -> 92.768621 | H21: =H18/'Detailed Report'!H141 -> 110.96531 | I21: =I18/'Detailed Report'!I141 -> 76.489727 | ... AE21: =AE18/'Detailed Report'!AE141 -> 96.560698
A22: CR | B22: 0.012 | C22: 0.0107 | D22: 0.0128 | E22: 0.0115 | F22: 0.0113 | G22: 0.0138 | H22: 0.0134 | I22: 0.0191 | J22: 0.0111 | K22: 0.0054 | L22: 0.0038 | M22: 0.0041 | N22: 0.0063 | O22: 0.0062 | P22: 0.01 | Q22: 0.0063 | R22: 0.0102 | S22: 0.0153 | T22: 0.0099 | U22: 0.0054 | V22: 0.0038 | W22: 0.0092 | X22: 0.0064 | Y22: 0.0076 | Z22: 0.0194 | AA22: 0.0119 | AB22: 0.0191 | AC22: 0.0126 | AD22: 0.013 | AE22: 0.0145
A23: AOV | B23: =B9/B10 -> 260.73755 | C23: =C9/C10 -> 306.5773 | D23: =D9/D10 -> 253.37459 | E23: =E9/E10 -> 258.31808 | F23: =F9/F10 -> 271.30327 | G23: =G9/G10 -> 250.56333 | H23: =H9/H10 -> 254.10067 | I23: =I9/I10 -> 264.59946 | ... AE23: =AE9/AE10 -> 243.80785
A24: fAOV | B24: 286.28 | C24: 273.55 | D24: 269.42 | E24: 267.89 | F24: 271.92 | G24: 267.31 | H24: 268.35 | I24: 274.9 | J24: 242.44 | K24: 243.98 | L24: 273.44 | M24: 255.8 | N24: 267.49 | O24: 269.69 | P24: 259.7 | Q24: 271.62 | R24: 269.63 | S24: 263.53 | T24: 264.16 | U24: 272.25 | V24: 232.74 | W24: 251.67 | X24: 256.27 | Y24: 285.45 | Z24: 276.36 | AA24: 291.36 | AB24: 256.11 | AC24: 240.17 | AD24: 228.03 | AE24: 244.17
A25: rAOV | B25: 146.01 | C25: 173.06 | D25: 140.15 | E25: 165.78 | F25: 255.19 | G25: 148.41 | H25: 124.59 | I25: 196.7 | J25: 141.4 | K25: 120.7 | L25: 153.45 | M25: 112.46 | N25: 187.72 | O25: 227.9 | P25: 196.63 | Q25: 151.21 | R25: 188.59 | S25: 128.2 | T25: 238.21 | U25: 124.48 | V25: 188.8 | W25: 102.28 | X25: 79.73 | Y25: 157.82 | Z25: 154.06 | AA25: 220.38 | AB25: 194.52 | AC25: 24 | AD25: 0 | AE25: 0
A27: Customers
A28: Returning | B28: 0.169 | C28: 0.1467 | D28: 0.1111 | E28: 0.0774 | F28: 0.1699 | G28: 0.1227 | H28: 0.0872 | I28: 0.1317 | J28: 0.0794 | K28: 0.1205 | L28: 0.1018 | M28: 0.1883 | N28: 0.0913 | O28: 0.1646 | P28: 0.0778 | Q28: 0.1131 | R28: 0.0798 | S28: 0.1005 | T28: 0.1107 | U28: 0.1389 | V28: 0.1818 | W28: 0.0877 | X28: 0.25 | Y28: 0.1477 | Z28: 0.1782 | AA28: 0.1009 | AB28: 0.1014 | AC28: 0.0127 | AD28: 0 | AE28: 0
A29: First-time | B29: =1-B28 -> 0.831 | C29: =1-C28 -> 0.8533 | D29: =1-D28 -> 0.8889 | E29: =1-E28 -> 0.9226 | F29: =1-F28 -> 0.8301 | G29: =1-G28 -> 0.8773 | H29: =1-H28 -> 0.9128 | I29: =1-I28 -> 0.8683 | ... AE29: =1-AE28 -> 1
A32: Post-purchase Survey
A33: Facebook / Instagram | B33: 0.3125 | C33: 0.4894 | D33: 0.4154 | E33: 0.3793 | F33: 0.463 | G33: 0.3684 | H33: 0.4043 | I33: 0.4407 | J33: 0.4308 | K33: 0.4348 | L33: 0.3958 | M33: 0.4512 | N33: 0.3571 | O33: 0.4625 | P33: 0.4521 | Q33: 0.3385 | R33: 0.4545 | S33: 0.405 | T33: 0.4304 | U33: 0.4324 | V33: 0.35 | W33: 0.16 | X33: 0.2973 | Y33: 0.2727 | Z33: 0.2118 | AA33: 0.2549 | AB33: 0.3793 | AC33: 0 | AD33: 0 | AE33: 0
A34: Friends / Family | B34: 0.5208 | C34: 0.383 | D34: 0.3538 | E34: 0.4138 | F34: 0.3519 | G34: 0.4035 | H34: 0.4043 | I34: 0.4068 | J34: 0.4308 | K34: 0.4565 | L34: 0.4167 | M34: 0.4512 | N34: 0.5 | O34: 0.425 | P34: 0.411 | Q34: 0.5231 | R34: 0.3182 | S34: 0.3471 | T34: 0.3418 | U34: 0.4054 | V34: 0.45 | W34: 0.52 | X34: 0.5676 | Y34: 0.5152 | Z34: 0.4118 | AA34: 0.3333 | AB34: 0.3793 | AC34: 0 | AD34: 0 | AE34: 0
A35: Google, Youtube | B35: 0.0833 | C35: 0.0213 | D35: 0.0308 | E35: 0.0172 | F35: 0.0926 | G35: 0.1404 | H35: 0.0851 | I35: 0.0678 | J35: 0.0462 | K35: 0.0435 | L35: 0.0417 | M35: 0.061 | N35: 0.0893 | O35: 0.05 | P35: 0.0274 | Q35: 0 | R35: 0.0909 | S35: 0.0661 | T35: 0.038 | U35: 0.0811 | V35: 0 | W35: 0.12 | X35: 0.0541 | Y35: 0.0909 | Z35: 0.0824 | AA35: 0.0392 | AB35: 0.0345 | AC35: 0 | AD35: 0 | AE35: 0
A36: Yahoo, Bing | B36: 0.0208 | C36: 0 | D36: 0 | E36: 0.0172 | F36: 0 | G36: 0 | H36: 0.0213 | I36: 0 | J36: 0 | K36: 0 | L36: 0 | M36: 0 | N36: 0 | O36: 0 | P36: 0 | Q36: 0 | R36: 0 | S36: 0 | T36: 0 | U36: 0 | V36: 0.05 | W36: 0 | X36: 0 | Y36: 0 | Z36: 0 | AA36: 0 | AB36: 0 | AC36: 0 | AD36: 0 | AE36: 0
A37: TikTok | B37: 0.0208 | C37: 0 | D37: 0 | E37: 0.0172 | F37: 0 | G37: 0.0351 | H37: 0.0426 | I37: 0.0169 | J37: 0.0308 | K37: 0.0217 | L37: 0.0625 | M37: 0.0122 | N37: 0 | O37: 0.025 | P37: 0.0137 | Q37: 0.0615 | R37: 0.0455 | S37: 0.0496 | T37: 0.0127 | U37: 0.0541 | V37: 0.05 | W37: 0.04 | X37: 0 | Y37: 0 | Z37: 0 | AA37: 0.0196 | AB37: 0.069 | AC37: 0 | AD37: 0 | AE37: 0
A38: TV / Radio | B38: 0 | C38: 0 | D38: 0.1692 | E38: 0.1207 | F38: 0.037 | G38: 0.0351 | H38: 0 | I38: 0 | J38: 0.0154 | K38: 0 | L38: 0 | M38: 0.0122 | N38: 0.0536 | O38: 0.0125 | P38: 0.0137 | Q38: 0.0154 | R38: 0.0152 | S38: 0.0331 | T38: 0.0127 | U38: 0 | V38: 0 | W38: 0 | X38: 0 | Y38: 0.0303 | Z38: 0.0235 | AA38: 0.0392 | AB38: 0.0345 | AC38: 0 | AD38: 0 | AE38: 0
A39: Blog / Article | B39: 0.0208 | C39: 0.0638 | D39: 0.0154 | E39: 0.0345 | F39: 0.0556 | G39: 0.0175 | H39: 0.0426 | I39: 0.0678 | J39: 0.0462 | K39: 0.0217 | L39: 0.0625 | M39: 0.0122 | N39: 0 | O39: 0.025 | P39: 0.0822 | Q39: 0.0462 | R39: 0.0606 | S39: 0.0992 | T39: 0.1519 | U39: 0.027 | V39: 0.1 | W39: 0.16 | X39: 0.0811 | Y39: 0.0909 | Z39: 0.2706 | AA39: 0.2745 | AB39: 0.069 | AC39: 0 | AD39: 0 | AE39: 0
A40: Reddit | B40: 0.0208 | C40: 0.0426 | D40: 0.0154 | E40: 0 | F40: 0 | G40: 0 | H40: 0 | I40: 0 | J40: 0 | K40: 0.0217 | L40: 0.0208 | M40: 0 | N40: 0 | O40: 0 | P40: 0 | Q40: 0.0154 | R40: 0.0152 | S40: 0 | T40: 0.0127 | U40: 0 | V40: 0 | W40: 0 | X40: 0 | Y40: 0 | Z40: 0 | AA40: 0.0392 | AB40: 0.0345 | AC40: 0 | AD40: 0 | AE40: 0
B42: 45078 | C42: Goal | D42: % of Goal
A43: Revenue | B43: =SUM(B9:AE9) -> 1275540.4 | C43: 2000000 | D43: =B43/C43 -> 0.63777021
A44: Spend | B44: =SUM(B18:AE18) -> 400840.84 | C44: 666000 | D44: =B44/C44 -> 0.60186312
A45: ROAS | B45: =B43/B44 -> 3.1821618 | C45: 3 | D45: =B45/C45 -> 1.0607206
A46: Spend per Unit | B46: =SUM(B18:AE18)/SUM('Detailed Report'!B141:AE141) -> 93.045692
A47: CR | B47: =AVERAGE(B22:AE22) -> 0.010536667
A48: AOV | B48: =B43/B51 -> 256.02979
...

Sheet Detailed Report
A1: JUNE | B1: 45078 | C1: 45079 | D1: 45080 | E1: 45081 | F1: 45082 | G1: 45083 | H1: 45084 | I1: 45085 | J1: 45086 | K1: 45087 | L1: 45088 | M1: 45089 | N1: 45090 | O1: 45091 | P1: 45092 | Q1: 45093 | R1: 45094 | S1: 45095 | T1: 45096 | U1: 45097 | V1: 45098 | W1: 45099 | X1: 45100 | Y1: 45101 | Z1: 45102 | AA1: 45103 | AB1: 45104 | AC1: 45105 | AD1: 45106 | AE1: 45107
A2: DAY | B2: THU | C2: FRI | D2: SAT | E2: SUN | F2: MON | G2: TUE | H2: WED | I2: THU | J2: FRI | K2: SAT | L2: SUN | M2: MON | N2: TUE | O2: WED | P2: THU | Q2: FRI | R2: SAT | S2: SUN | T2: MON | U2: TUE | V2: WED | W2: THU | X2: FRI | Y2: SAT | Z2: SUN | AA2: MON | AB2: TUE | AC2: WED | AD2: THU | AE2: FRI
A3: COMMENT
A4: Transactions
A5: FB (US & CA) | B5: 13 | C5: 14 | D5: 17 | E5: 14 | F5: 18 | G5: 15 | H5: 21 | I5: 32 | J5: 30 | K5: 23 | L5: 30 | M5: 36 | N5: 23 | O5: 26 | P5: 37 | Q5: 33 | R5: 51 | S5: 61 | T5: 50 | U5: 16 | V5: 0 | W5: 1 | X5: 5 | Y5: 2 | Z5: 12 | AA5: 13 | AB5: 14 | AF5: =SUM(B5:AE5) -> 607
A6: Google | B6: 69 | C6: 74 | D6: 83 | E6: 88 | F6: 67 | G6: 70 | H6: 70 | I6: 94 | J6: 40 | K6: 43 | L6: 74 | M6: 110 | N6: 110 | O6: 132 | P6: 120 | Q6: 112 | R6: 127 | S6: 187 | T6: 96 | U6: 49 | V6: 26 | W6: 8 | X6: 20 | Y6: 33 | Z6: 60 | AA6: 52 | AB6: 26 | AF6: =SUM(B6:AE6) -> 2040
A7: TikTok | B7: 0 | C7: 0 | D7: 0 | E7: 0 | F7: 0 | G7: 0 | H7: 0 | I7: 0 | J7: 1 | K7: 0 | L7: 0 | M7: 0 | N7: 0 | O7: 0 | P7: 0 | Q7: 1 | R7: 2 | S7: 1 | T7: 0 | U7: 1 | V7: 0 | W7: 0 | X7: 0 | Y7: 0 | Z7: 0 | AA7: 0 | AB7: 0 | AF7: =SUM(B7:AE7) -> 6
A8: Bing | B8: 8 | C8: 2 | D8: 5 | E8: 7 | F8: 3 | G8: 12 | H8: 3 | I8: 10 | J8: 8 | K8: 4 | L8: 8 | M8: 7 | N8: 7 | O8: 9 | P8: 7 | Q8: 7 | R8: 11 | S8: 7 | T8: 7 | U8: 4 | V8: 4 | W8: 1 | X8: 0 | Y8: 1 | Z8: 3 | AA8: 0 | AB8: 0 | AF8: =SUM(B8:AE8) -> 145
A9: MNTN TV
A10: Affiliates (Refersion) | B10: 0 | C10: 1 | D10: 3 | E10: 0 | F10: 3 | G10: 3 | H10: 1 | I10: 0 | J10: 2 | K10: 2 | L10: 4 | M10: 2 | N10: 4 | O10: 5 | P10: 5 | Q10: 0 | R10: 5 | S10: 6 | T10: 4 | U10: 3 | V10: 0 | W10: 4 | X10: 2 | Y10: 2 | Z10: 4 | AA10: 1 | AB10: 1
A11: FB (Internal Paid) | AF11: =SUM(B11:AE11) -> 0
A12: FB (EU & UK) | AF12: =SUM(B12:AE12) -> 0
A13: Email | B13: 7 | C13: 12 | D13: 5 | E13: 7 | F13: 15 | G13: 8 | H13: 5 | I13: 9 | J13: 8 | K13: 8 | L13: 9 | M13: 25 | N13: 14 | O13: 24 | P13: 15 | Q13: 13 | R13: 12 | S13: 9 | T13: 11 | U13: 12 | V13: 9 | W13: 4 | X13: 12 | Y13: 6 | Z13: 17 | AA13: 11 | AB13: 5 | AC13: 0 | AF13: =SUM(B13:AE13) -> 292
A14: All | B14: =SUM(B5:B13) -> 97 | C14: =SUM(C5:C13) -> 103 | D14: =SUM(D5:D13) -> 113 | E14: =SUM(E5:E13) -> 116 | F14: =SUM(F5:F13) -> 106 | G14: =SUM(G5:G13) -> 108 | H14: =SUM(H5:H13) -> 100 | I14: =SUM(I5:I13) -> 145 | ... AE14: =SUM(AE5:AE13) -> 0 | AF14: =SUM(B14:AE14) -> 3157
A16: Revenue
A17: FB (US & CA) | B17: 3294.85 | C17: 4118.4 | D17: 4524.34 | E17: 4243.17 | F17: 4803.88 | G17: 3933.64 | H17: 6685.47 | I17: 8736.05 | J17: 8807.3 | K17: 6640.61 | L17: 8227.08 | M17: 9676.52 | N17: 6002.61 | O17: 7076.8 | P17: 9216.81 | Q17: 9731.68 | R17: 13752.62 | S17: 16145.05 | T17: 13978.94 | U17: 4301.62 | V17: 0 | W17: 229.38 | X17: 1159.16 | Y17: 564.56 | Z17: 3563.53 | AA17: 3515.69 | AB17: 3910.35 | AC17: 0 | AF17: =SUM(B17:AE17) -> 166840.11
A18: Google | B18: 18415.6 | C18: 20483.25 | D18: 21036.07 | E18: 22253.35 | F18: 15981.54 | G18: 17517.93 | H18: 16988.56 | I18: 24280 | J18: 9973.73 | K18: 10765.09 | L18: 18770.4 | M18: 25343.21 | N18: 28010.8 | O18: 34899.1 | P18: 31011.07 | Q18: 29470.1 | R18: 34610.55 | S18: 45898.07 | T18: 22540.7 | U18: 11885.77 | V18: 5551.29 | W18: 2080.54 | X18: 4147.16 | Y18: 9029.57 | Z18: 14360.95 | AA18: 13933.84 | AB18: 6205 | AC18: 0 | AF18: =SUM(B18:AE18) -> 515443.24
A19: TikTok | B19: 0 | C19: 0 | D19: 0 | E19: 0 | F19: 0 | G19: 0 | H19: 0 | I19: 0 | J19: 324.21 | K19: 0 | L19: 0 | M19: 0 | N19: 0 | O19: 0 | P19: 0 | Q19: 199.85 | R19: 557.82 | S19: 252.23 | T19: 0 | U19: 254.66 | V19: 0 | W19: 0 | X19: 0 | Y19: 0 | Z19: 0 | AA19: 0 | AB19: 0 | AC19: 0 | AF19: =SUM(B19:AE19) -> 1588.77
A20: Bing | B20: 2058.32 | C20: 495.26 | D20: 1494.25 | E20: 1471.87 | F20: 834.81 | G20: 2850.58 | H20: 748.12 | I20: 2498.22 | J20: 2291.4 | K20: 1197.61 | L20: 2075.9 | M20: 1628.04 | N20: 1188.56 | O20: 2244.35 | P20: 1830.03 | Q20: 1376.61 | R20: 2901.37 | S20: 1354.88 | T20: 1581.82 | U20: 1044.93 | V20: 797.51 | W20: 39 | X20: 0 | Y20: 264.29 | Z20: 804.07 | AA20: 0 | AB20: 0 | AC20: 0 | AF20: =SUM(B20:AE20) -> 35071.8
A21: MNTN TV
A22: Affiliates (Refersion) | B22: 0 | C22: 292.21 | D22: 0 | E22: 0 | F22: 1028.47 | G22: 861.02 | H22: 84.38 | I22: 0 | J22: 549.25 | K22: 656.17 | L22: 1191.62 | M22: 380.54 | N22: 1223.44 | O22: 1282.92 | P22: 1261.52 | Q22: 0 | R22: 1412.07 | S22: 1610.08 | T22: 1183.66 | U22: =273.29+199.85+324.21 -> 797.35 | V22: 0 | W22: =223.63+321.94+222.07+299.94 -> 1067.58 | X22: =321.94+125.19 -> 447.13 | Y22: =324.98+296.08 -> 621.06 | Z22: =327.25+366.76+84.38+286.82 -> 1065.21 | AA22: 250.49 | AB22: 224.16 | AC22: 0
A23: FB (Internal Paid) | AF23: =SUM(B23:AE23) -> 0
A24: FB (EU & UK) | AF24: =SUM(B24:AE24) -> 0
A25: Email | B25: 614.21 | C25: 1866.32 | D25: 1061.11 | E25: 1626.6 | F25: 2162.44 | G25: 1269.3 | H25: 842.13 | I25: 1971.81 | J25: 1668.28 | K25: 1266.91 | L25: 2066.5 | M25: 4117.38 | N25: 3156.41 | O25: 4830.22 | P25: 3679.37 | Q25: 2566.29 | R25: 2915.62 | S25: 1746.61 | T25: 4013.65 | U25: 2259.81 | V25: 1433.41 | W25: 618 | X25: 1282.03 | Y25: 1154.01 | Z25: 4045.13 | AA25: 2949.81 | AB25: 1054.17 | AC25: 0 | AF25: =SUM(B25:AE25) -> 58237.53
A26: All | B26: =SUM(B17:B25) -> 24382.98 | C26: =SUM(C17:C25) -> 27255.44 | D26: =SUM(D17:D25) -> 28115.77 | E26: =SUM(E17:E25) -> 29594.99 | F26: =SUM(F17:F25) -> 24811.14 | G26: =SUM(G17:G25) -> 26432.47 | H26: =SUM(H17:H25) -> 25348.66 | I26: =SUM(I17:I25) -> 37486.08 | ... AE26: =SUM(AE17:AE25) -> 0 | AF26: =SUM(B26:AE26) -> 794671.78
A28: Media Cost
A29: FB Spend (US & CA) | B29: =Sales!B12 -> 5819.35 | C29: =Sales!C12 -> 6351.79 | D29: =Sales!D12 -> 6995.09 | E29: =Sales!E12 -> 6480.56 | F29: =Sales!F12 -> 5823.01 | G29: =Sales!G12 -> 5934.08 | H29: =Sales!H12 -> 5813 | I29: =Sales!I12 -> 5781.36 | ... AE29: =Sales!AE12 -> 5398.79 | AF29: =SUM(B29:AE29) -> 170200.85
A30: Google Spend | B30: =Sales!B13 -> 6834.34 | C30: =Sales!C13 -> 10214.61 | D30: =Sales!D13 -> 9297.35 | E30: =Sales!E13 -> 7824.73 | F30: =Sales!F13 -> 7747.63 | G30: =Sales!G13 -> 7082.13 | H30: =Sales!H13 -> 8111.48 | I30: =Sales!I13 -> 7959.23 | ... AE30: =Sales!AE13 -> 2905.43 | AF30: =SUM(B30:AE30) -> 219238.54
A31: TikTok Spend | B31: =Sales!B15 -> 319.5 | C31: =Sales!C15 -> 167.28 | D31: =Sales!D15 -> 165.57 | E31: =Sales!E15 -> 167.6 | F31: =Sales!F15 -> 78.15 | G31: =Sales!G15 -> 0 | H31: =Sales!H15 -> 0 | I31: =Sales!I15 -> 0 | ... AE31: =Sales!AE15 -> 0 | AF31: =SUM(B31:AE31) -> 2662.28
A32: Bing Spend | B32: =Sales!B14 -> 259.98 | C32: =Sales!C14 -> 273.58 | D32: =Sales!D14 -> 257.11 | E32: =Sales!E14 -> 262.79 | F32: =Sales!F14 -> 187.4 | G32: =Sales!G14 -> 235.08 | H32: =Sales!H14 -> 262.2 | I32: =Sales!I14 -> 257.03 | ... AE32: =Sales!AE14 -> 0 | AF32: =SUM(B32:AE32) -> 4529.41
A33: MNTN TV | B33: =Sales!B16 | C33: =Sales!C16 | D33: =Sales!D16 | E33: =Sales!E16 | F33: =Sales!F16 | G33: =Sales!G16 | H33: =Sales!H16 | I33: =Sales!I16 | ... AE33: =Sales!AE16 | AF33: =SUM(B33:AE33) -> 0
A34: Fee 15% Purchase (Backerkit) | B34: =B21*0.15 -> 0 | C34: =C21*0.15 -> 0 | D34: =D21*0.15 -> 0 | E34: =E21*0.15 -> 0 | F34: =F21*0.15 -> 0 | G34: =G21*0.15 -> 0 | H34: =H21*0.15 -> 0 | I34: =I21*0.15 -> 0 | ... S34: =S21*0.15 -> 0 | U34: =U21*0.15 -> 0 | V34: =V21*0.15 -> 0 | W34: =W21*0.15 -> 0 | X34: =X21*0.15 -> 0 | Y34: =Y21*0.15 -> 0 | Z34: =Z21*0.15 -> 0 | AA34: =AA21*0.15 -> 0 | AB34: =AB21*0.15 -> 0 | AC34: =AC21*0.15 -> 0 | AF34: =SUM(B34:AE34) -> 0
A35: Google Management Fee | AF35: =SUM(B35:AE35) -> 0
A36: Affiliates Agency Payment (Grovia) | AF36: =SUM(B36:AE36) -> 0
A37: Affiliate Fee 20% (Grovia) | B37: =Sales!B17 -> 0 | C37: =Sales!C17 -> 58.44 | D37: =Sales!D17 -> 212.47 | E37: =Sales!E17 -> 0 | F37: =Sales!F17 -> 205.69 | G37: =Sales!G17 -> 200.16 | H37: =Sales!H17 -> 16.88 | I37: =Sales!I17 -> 0 | K37: =Sales!K17 -> 150.23 | L37: =Sales!L17 -> 267.68 | M37: =Sales!M17 -> 76.11 | N37: =Sales!N17 -> 305.87 | O37: =Sales!O17 -> 295.93 | P37: =Sales!P17 -> 290.62 | Q37: =Sales!Q17 -> 0 | R37: =Sales!R17 -> 325.96 | ... AE37: =Sales!AE17 -> 0 | AF37: =SUM(B37:AE37) -> 4072.45
A38: FB Spend (Internal Paid) | AF38: =SUM(B38:AE38) -> 0
A39: FB Spend (EU & UK) | AF39: =SUM(B39:AE39) -> 0
A40: Pinterest Spend | AF40: =SUM(B40:AE40) -> 0
A41: Platform Fee (6,90%) | AF41: =SUM(B41:AE41) -> 0
A42: All | B42: =SUM(B29:B41) -> 13233.17 | C42: =SUM(C29:C41) -> 17065.7 | D42: =SUM(D29:D41) -> 16927.59 | E42: =SUM(E29:E41) -> 14735.68 | F42: =SUM(F29:F41) -> 14041.88 | G42: =SUM(G29:G41) -> 13451.45 | H42: =SUM(H29:H41) -> 14203.56 | I42: =SUM(I29:I41) -> 13997.62 | ... AE42: =SUM(AE29:AE41) -> 8304.22 | AF42: =SUM(B42:AE42) -> 400703.53
...

Sheet Formulas
B1: Business Metrics
B3: COGS | C3: Source | E3: 3PL Costs
B4: Bird Buddy | C4: 70.53 | E4: Handling Fee | F4: 1.5
B5: Bird Buddy with Solar Roof | C5: 80.08 | E5: Serial Capture | F5: 0.3
B6: Solar Roof Single | C6: 9.98 | E6: Storage | F6: 0.31
B7: Wall Mount | C7: 4.93 | E7: Other
B8: Fence Mount | C8: 6.37 | E8: Source
B9: Suet Ball Holder | C9: 1.07
B10: 3-in-1 Nutrition Set | C10: 6.08
B12: Bird Buddy Shipping | C12: Source | E12: Add-ons Shipping
B13: Inbound (NA) | C13: 18.43 | E13: Inbound (NA) | F13: 2.81
B14: Inbound (Europe) | C14: 4.98 | E14: Inbound (Europe)
B15: Inbound (ROW) | C15: 10 | E15: Inbound (ROW)
B16: Outbound (NA) | C16: 11.59 | E16: Outbound (NA) | F16: 6.16
B17: Outbound (Europe) | C17: 15 | E17: Outbound (Europe)
B18: Outbound (ROW) | C18: 20 | E18: Outbound (ROW)
B20: Marketing Averages (per unit) | E20: VAT Averages
B21: COGS | C21: =(C4*1)+(C6*F26)+(C7*F27)+(C8*F28)+(C9*F29)+(C10*F30) -> 74.085618 | E21: Europe | F21: 0.22
B22: Inbound Shipping | C22: =C13 -> 18.43 | E22: ROW | F22: 0.13
B23: Outbound Shipping | C23: =C16 -> 11.59 | E23: NA
B24: Taxes and VAT | C24: 10.89
B25: China Tax (7.5%) | C25: =C21*0.075 -> 5.5564214 | E25: Attachment Rates
B26: Duty (3.4%) | C26: =C21*0.034 -> 2.518911 | E26: Solar Roof | F26: =('Detailed Report'!AF170)/'Detailed Report'!AF164 -> 0.077832512
B27: Processing Fee (2,97%) | C27: =Sales!B48*0.0297 -> 7.6040848 | E27: Wall Mount | F27: =('Detailed Report'!AF166)/'Detailed Report'!AF164 -> 0.31182266
B28: Transaction Fee ($0.36) | C28: =0.36 -> 0.36 | E28: Fence Mount | F28: =('Detailed Report'!AF167)/'Detailed Report'!AF164 -> 0
B29: 3PL - Handling Fee | C29: =F4 -> 1.5 | E29: Suet Ball Holder | F29: =('Detailed Report'!AF168)/'Detailed Report'!AF164 -> 0.17364532
B30: 3PL - Serial Capture | C30: =F5 -> 0.3 | E30: 3-in-1 | F30: =('Detailed Report'!AF169)/'Detailed Report'!AF164 -> 0.17364532
B31: 3PL - Storage Cost | C31: =F6 -> 0.31
B32: All | C32: =SUM(C21:C30) -> 132.83504
B34: Fees | E34: 30 Day Returns
B35: Processing Fee | C35: 0.0297 | E35: US Shipping | F35: 10
B36: Duty | C36: 0.034 | E36: EU Shipping | F36: 20
B37: China Tax | C37: 0.075 | E37: ROW Shipping | F37: 20
B38: HMF | C38: 0.00125 | E38: Money Return | F38: 0.8
B39: MPF | C39: 0.003464
B40: Solar Roof China Tax | C40: 0.25
B41: Solar Roof Duty | C41: 0.025

Sheet SupermetricsQueries
A1: Supermetrics Queries
A3: All the queries created by Supermetrics are stored here, each in its own row.
H4: 16406162
A5: On this sheet you can:
A6: 1. Modify the parameters of a query. Any changes will be visible when you run a refresh.
A8: 2. Remove a query by deleting its row | H8: Europe/Paris
A10: 3. Add new queries: type a range address and query parameters, leave the query ID empty. The query will be added when you run a refresh. (Of course, it's much easier to use the sidebar to add new queries.)
A13: Queries are stored with the authentication of the original user that created the query. If you want to transfer a query to the currently active Google Sheets user, delete its query ID from column A and run a refresh. For complete instructions on transferring queries, see https://support.supermetrics.com/support/solutions/articles/19000050074-how-can-i-transfer-queries-from-one-user-to-another-
A16: Don't delete or rename this sheet. If you delete or rename it, your existing queries can no longer be refreshed. Hiding the sheet is OK. Also, don't delete any rows above row 21.
A19: Query ID | D19: Sheet name | E19: Range address | G19: Created | H19: Updated | I19: Last status | J19: Last refresh ID | K19: Results contain sampled data | L19: Execution time (sec) | M19: Object type | N19: Linked chart ID | O19: Data source | Q19: Date range type | R19: Start date | S19: End date | T19: Compare to | U19: Comparison value type | W19: Accounts/views | X19: Metrics | Y19: Dimensions | Z19: Pivot dimensions | AA19: Filters | AB19: Segment ID | AC19: Sort | AD19: Max rows | AE19: Max pivot categories | AF19: Special settings | AG19: Other parameters | AJ19: Result type | AK19: Language/country | AL19: Translate to | AN19: SQL | AO19: Database name | AP19: Range address (static) | AQ19: Report type | AT19: Highlight with colour | AU19: Refresh with user account | AV19: Returned data
A20: paramsID | C20: ssID | D20: sheetName | E20: rangeAddress | G20: created | H20: updated | I20: lastStatus | J20: lastqueryID | K20: sampled | L20: runtime_sec | M20: objType | N20: linkedChartID | O20: dataSource | Q20: dateRangeType | R20: startDateString | S20: endDateString | T20: comp | U20: cvt | W20: profiles | X20: metrics | Y20: dimensions | Z20: sd | AA20: filterArr | AB20: segment | AC20: sort | AD20: maxResults | AE20: maxCategories | AF20: specialSettings | AG20: otherParams | AJ20: sds_result_type | AK20: sds_lang | AL20: sds_tolang | AN20: sql | AO20: db_name | AP20: rangeAddressStatic | AQ20: rt | AR20: scopeMZ | AS20: sortMZ | AT20: condform | AU20: authUser | AV20: metaDataToUser
A21: pxuhRTEmIU93xSgKclyxajD0fCZ6rF | D21: =IFERROR(__xludf.DUMMYFUNCTION("ARRAY_CONSTRAIN(split(CELL(""ADDRESS"",zsupermetrics_pxuhRTEmIU93xSgKclyxajD0fCZ6rF),""!""),1,1)"),"#REF!") -> #REF! | E21: =CELL("ADDRESS",zsupermetrics_pxuhRTEmIU93xSgKclyxajD0fCZ6rF)&":"&address(row(zsupermetrics_pxuhRTEmIU93xSgKclyxajD0fCZ6rF)+rows(zsupermetrics_pxuhRTEmIU93xSgKclyxajD0fCZ6rF)-1,column(zsupermetrics_pxuhRTEmIU93xSgKclyxajD0fCZ6rF)+COLUMNS(zsupermetrics_pxuhRTEmIU93xSgKclyxajD0fCZ6rF)-1) -> #REF! | G21: 44557.697 | H21: 44557.839 | I21: Created successfully | K21: FALSE | L21: 4 | M21: TABLE | O21: SHP | Q21: thismonth | W21: ["gid://shopify/Shop/55807180983`Bird Buddy"] | X21: ["gross_sales","returns","shipping","tax","total_sales","sm_order_count"] | Y21: [] | Z21: ["date"] | AA21: [] | AB21: [] | AD21: 10000 | AE21: 50 | AF21: ["METRICS_IN_ROWS","MULTILEVEL_COL_HEADERS"] | AG21: {} | AP21: Shopify 1'!A1:AB7 | AU21: gid://shopify/Shop/55807180983

Sheet Business Metrics US
A1: United States
A2: Product | B2: Bird Buddy | C2: Bird Buddy with Solar Roof | D2: Solar Roof | E2: Wall Mount | F2: Suet Ball Holder | G2: 3-in-1 Nutrition Set | H2: Hummingbird Feeder | I2: Perch Extender | J2: Pole System
A3: Category | B3: Bird Feeder | C3: Bird Feeder | D3: Add-on | E3: Add-on | F3: Add-on | G3: Add-on
A5: COGS
A6: Source
A7: Owner | B7: Nick Koukourakis | C7: Nick Koukourakis | D7: Nick Koukourakis | E7: Nick Koukourakis | F7: Nick Koukourakis | G7: Nick Koukourakis
A8: Controller #1 | B8: Diana Spiewak | C8: Diana Spiewak | D8: Diana Spiewak | E8: Diana Spiewak | F8: Diana Spiewak | G8: Diana Spiewak
A9: Controller #2 | B9: Eric Malkowski | C9: Eric Malkowski | D9: Eric Malkowski | E9: Eric Malkowski | F9: Eric Malkowski | G9: Eric Malkowski
A10: Batch | B10: 150000 | C10: 150000
A11: Batch Timeline | B11: April - November | C11: April - November
A13: Chip | B13: 6.1433 | C13: 6.1433 | D13: 0 | E13: 0 | F13: 0 | G13: 0
A14: Other Component | B14: 38.23 | C14: 45.3 | D14: 6.87 | E14: 3.79 | F14: 0.82 | G14: 3.8336
A15: BOM Margin | B15: =(B13+B14)*B23 -> 15.530655 | C15: =(C13+C14)*C23 -> 18.005155 | D15: =(D13+D14)*D23 -> 2.4045 | E15: =(E13+E14)*E23 -> 1.137 | F15: =(F13+F14)*F23 -> 0.246 | G15: =(G13+G14)*G23 -> 1.15008
A16: Packaging and Accessories | B16: 8.1762 | C16: 8.1762 | D16: 0.544 | E16: 0 | F16: 0 | G16: 0.8422
A17: Package Margin | B17: =B16*B24 -> 2.45286 | C17: =C16*C24 -> 2.45286 | D17: =D16*D24 -> 0.1632 | E17: =E16*E24 -> 0 | F17: =F16*F24 -> 0 | G17: =G16*G24 -> 0.25266
A18: Total Product Cost | B18: =SUM(B13:B17) -> 70.533015 | C18: =SUM(C13:C17) -> 80.077515 | D18: =SUM(D13:D17) -> 9.9817 | E18: =SUM(E13:E17) -> 4.927 | F18: =SUM(F13:F17) -> 1.066 | G18: =SUM(G13:G17) -> 6.07854
A20: Finance fee | B20: 10 | C20: 10 | D20: 0 | E20: 0 | F20: 0 | G20: 0
A21: PPV cost component | B21: 1.88 | C21: 1.88 | D21: 0 | E21: 0 | F21: 0 | G21: 0
A23: BOM Margin (%) | B23: 0.35 | C23: 0.35 | D23: 0.35 | E23: 0.3 | F23: 0.3 | G23: 0.3
A24: Package Margin (%) | B24: 0.3 | C24: 0.3 | D24: 0.3 | E24: 0.3 | F24: 0.3 | G24: 0.3
A26: Duty Rate | B26: =sum(B13:B17)*B32 -> 0 | C26: =sum(C13:C17)*C32 -> 0 | D26: =sum(D13:D17)*D32 -> 0.2495425 | E26: =sum(E13:E17)*E32 -> 0.167518 | F26: =sum(F13:F17)*F32 -> 0.036244 | G26: =sum(G13:G17)*G32 -> 0.20667036
A27: Tarrif Rate | B27: =sum(B13:B17)*B33 -> 5.2899761 | C27: =sum(C13:C17)*C33 -> 6.0058136 | D27: =sum(D13:D17)*D33 -> 2.495425 | E27: =sum(E13:E17)*E33 -> 0.369525 | F27: =sum(F13:F17)*F33 -> 0.07995 | G27: =sum(G13:G17)*G33 -> 0.4558905
A28: HMF | B28: =SUM($B$13:$B$17)*B34 -> 0.088166269 | C28: =SUM($B$13:$B$17)*C34 -> 0.088166269 | D28: =SUM($B$13:$B$17)*D34 -> 0.088166269 | E28: =SUM($B$13:$B$17)*E34 -> 0.088166269 | F28: =SUM($B$13:$B$17)*F34 -> 0.088166269 | G28: =SUM($B$13:$B$17)*G34 -> 0.088166269
A29: MPF | B29: =SUM($B$13:$B$17)*B35 -> 0.24432636 | C29: =SUM($B$13:$B$17)*C35 -> 0.24432636 | D29: =SUM($B$13:$B$17)*D35 -> 0.24432636 | E29: =SUM($B$13:$B$17)*E35 -> 0.24432636 | F29: =SUM($B$13:$B$17)*F35 -> 0.24432636 | G29: =SUM($B$13:$B$17)*G35 -> 0.24432636
A30: Total Port Cost | B30: =SUM(B26:B29) -> 5.6224688 | C30: =SUM(C26:C29) -> 6.3383063 | D30: =SUM(D26:D29) -> 3.0774601 | E30: =SUM(E26:E29) -> 0.86953563 | F30: =SUM(F26:F29) -> 0.44868663 | G30: =SUM(G26:G29) -> 0.99505349
A32: Duty Rate (%) | B32: 0 | C32: 0 | D32: 0.025 | E32: 0.034 | F32: 0.034 | G32: 0.034
A33: Tarrif Rate (%) | B33: 0.075 | C33: 0.075 | D33: 0.25 | E33: 0.075 | F33: 0.075 | G33: 0.075
A34: HMF (%) | B34: 0.00125 | C34: 0.00125 | D34: 0.00125 | E34: 0.00125 | F34: 0.00125 | G34: 0.00125
A35: MPF (%) | B35: 0.003464 | C35: 0.003464 | D35: 0.003464 | E35: 0.003464 | F35: 0.003464 | G35: 0.003464
A37: Total Cost | B37: =B18+B20+B21+B30 -> 88.035484 | C37: =C18+C20+C21+C30 -> 98.295821 | D37: =D18+D20+D21+D30 -> 13.05916 | E37: =E18+E20+E21+E30 -> 5.7965356 | F37: =F18+F20+F21+F30 -> 1.5146866 | G37: =G18+G20+G21+G30 -> 7.0735935
A41: Inbound Shipping
A42: Source
A43: Owner | B43: Judy Stanis | C43: Judy Stanis | D43: Judy Stanis | E43: Judy Stanis | F43: Judy Stanis | G43: Judy Stanis
A44: Controller #1 | B44: Diana Spiewak | C44: Diana Spiewak | D44: Diana Spiewak | E44: Diana Spiewak | F44: Diana Spiewak | G44: Diana Spiewak
A45: Controller #2 | B45: Eric Malkowski | C45: Eric Malkowski | D45: Eric Malkowski | E45: Eric Malkowski | F45: Eric Malkowski | G45: Eric Malkowski
A46: Batch
A47: Batch Timeline
A49: Air Freight | B49: 22.88 | C49: 22.88 | D49: 3.06 | E49: 4.88 | F49: 0.75 | G49: 2.55
A50: Fast Ocean | B50: 10.56 | C50: 10.56 | D50: 1.31 | E50: 2.09 | F50: 0.32 | G50: 0.97
A51: Ocean | B51: 2.65 | C51: 2.65 | D51: 0.39 | E51: 0.58 | F51: 0.1 | G51: 0.35
...

Sheet Business Metrics Canada
A1: Canada
A2: Product | B2: Bird Buddy | C2: Bird Buddy with Solar Roof | D2: Solar Roof | E2: Wall Mount | F2: Suet Ball Holder | G2: 3-in-1 Nutrition Set | H2: Hummingbird Feeder | I2: Perch Extender | J2: Pole System
A3: Category | B3: Bird Feeder | C3: Bird Feeder | D3: Add-on | E3: Add-on | F3: Add-on | G3: Add-on
A5: COGS
A6: Source
A7: Owner | B7: Nick Koukourakis | C7: Nick Koukourakis | D7: Nick Koukourakis | E7: Nick Koukourakis | F7: Nick Koukourakis | G7: Nick Koukourakis
A8: Controller #1 | B8: Diana Spiewak | C8: Diana Spiewak | D8: Diana Spiewak | E8: Diana Spiewak | F8: Diana Spiewak | G8: Diana Spiewak
A9: Controller #2 | B9: Eric Malkowski | C9: Eric Malkowski | D9: Eric Malkowski | E9: Eric Malkowski | F9: Eric Malkowski | G9: Eric Malkowski
A10: Batch | B10: 150000 | C10: 150000
A11: Batch Timeline | B11: April - November | C11: April - November
A13: Chip | B13: 6.1433 | C13: 6.1433 | D13: 0 | E13: 0 | F13: 0 | G13: 0
A14: Other Component | B14: 38.23 | C14: 45.3 | D14: 6.87 | E14: 3.79 | F14: 0.82 | G14: 3.8336
A15: BOM Margin | B15: =(B13+B14)*B23 -> 15.530655 | C15: =(C13+C14)*C23 -> 18.005155 | D15: =(D13+D14)*D23 -> 2.4045 | E15: =(E13+E14)*E23 -> 1.137 | F15: =(F13+F14)*F23 -> 0.246 | G15: =(G13+G14)*G23 -> 1.15008
A16: Packaging and Accessories | B16: 8.1762 | C16: 8.1762 | D16: 0.544 | E16: 0 | F16: 0 | G16: 0.8422
A17: Package Margin | B17: =B16*B24 -> 2.45286 | C17: =C16*C24 -> 2.45286 | D17: =D16*D24 -> 0.1632 | E17: =E16*E24 -> 0 | F17: =F16*F24 -> 0 | G17: =G16*G24 -> 0.25266
A18: Total Product Cost | B18: =SUM(B13:B17) -> 70.533015 | C18: =SUM(C13:C17) -> 80.077515 | D18: =SUM(D13:D17) -> 9.9817 | E18: =SUM(E13:E17) -> 4.927 | F18: =SUM(F13:F17) -> 1.066 | G18: =SUM(G13:G17) -> 6.07854
A20: Finance fee | B20: 10 | C20: 10 | D20: 0 | E20: 0 | F20: 0 | G20: 0
A21: PPV cost component | B21: 1.88 | C21: 1.88 | D21: 0 | E21: 0 | F21: 0 | G21: 0
A23: BOM Margin (%) | B23: 0.35 | C23: 0.35 | D23: 0.35 | E23: 0.3 | F23: 0.3 | G23: 0.3
A24: Package Margin (%) | B24: 0.3 | C24: 0.3 | D24: 0.3 | E24: 0.3 | F24: 0.3 | G24: 0.3
A26: Duty Rate | B26: =sum(B13:B17)*B32 -> 0 | C26: =sum(C13:C17)*C32 -> 0 | D26: =sum(D13:D17)*D32 -> 0.2495425 | E26: =sum(E13:E17)*E32 -> 0.167518 | F26: =sum(F13:F17)*F32 -> 0.036244 | G26: =sum(G13:G17)*G32 -> 0.20667036
A27: Tarrif Rate | B27: =sum(B13:B17)*B33 -> 5.2899761 | C27: =sum(C13:C17)*C33 -> 6.0058136 | D27: =sum(D13:D17)*D33 -> 2.495425 | E27: =sum(E13:E17)*E33 -> 0.369525 | F27: =sum(F13:F17)*F33 -> 0.07995 | G27: =sum(G13:G17)*G33 -> 0.4558905
A28: HMF | B28: =SUM($B$13:$B$17)*B34 -> 0.088166269 | C28: =SUM($B$13:$B$17)*C34 -> 0.088166269 | D28: =SUM($B$13:$B$17)*D34 -> 0.088166269 | E28: =SUM($B$13:$B$17)*E34 -> 0.088166269 | F28: =SUM($B$13:$B$17)*F34 -> 0.088166269 | G28: =SUM($B$13:$B$17)*G34 -> 0.088166269
A29: MPF | B29: =SUM($B$13:$B$17)*B35 -> 0.24432636 | C29: =SUM($B$13:$B$17)*C35 -> 0.24432636 | D29: =SUM($B$13:$B$17)*D35 -> 0.24432636 | E29: =SUM($B$13:$B$17)*E35 -> 0.24432636 | F29: =SUM($B$13:$B$17)*F35 -> 0.24432636 | G29: =SUM($B$13:$B$17)*G35 -> 0.24432636
A30: Total Port Cost | B30: =SUM(B26:B29) -> 5.6224688 | C30: =SUM(C26:C29) -> 6.3383063 | D30: =SUM(D26:D29) -> 3.0774601 | E30: =SUM(E26:E29) -> 0.86953563 | F30: =SUM(F26:F29) -> 0.44868663 | G30: =SUM(G26:G29) -> 0.99505349
A32: Duty Rate (%) | B32: 0 | C32: 0 | D32: 0.025 | E32: 0.034 | F32: 0.034 | G32: 0.034
A33: Tarrif Rate (%) | B33: 0.075 | C33: 0.075 | D33: 0.25 | E33: 0.075 | F33: 0.075 | G33: 0.075
A34: HMF (%) | B34: 0.00125 | C34: 0.00125 | D34: 0.00125 | E34: 0.00125 | F34: 0.00125 | G34: 0.00125
A35: MPF (%) | B35: 0.003464 | C35: 0.003464 | D35: 0.003464 | E35: 0.003464 | F35: 0.003464 | G35: 0.003464
A37: Total Cost | B37: =B18+B20+B21+B30 -> 88.035484 | C37: =C18+C20+C21+C30 -> 98.295821 | D37: =D18+D20+D21+D30 -> 13.05916 | E37: =E18+E20+E21+E30 -> 5.7965356 | F37: =F18+F20+F21+F30 -> 1.5146866 | G37: =G18+G20+G21+G30 -> 7.0735935
A41: Inbound Shipping
A42: Source
A43: Owner | B43: Judy Stanis | C43: Judy Stanis | D43: Judy Stanis | E43: Judy Stanis | F43: Judy Stanis | G43: Judy Stanis
A44: Controller #1 | B44: Diana Spiewak | C44: Diana Spiewak | D44: Diana Spiewak | E44: Diana Spiewak | F44: Diana Spiewak | G44: Diana Spiewak
A45: Controller #2 | B45: Eric Malkowski | C45: Eric Malkowski | D45: Eric Malkowski | E45: Eric Malkowski | F45: Eric Malkowski | G45: Eric Malkowski
A46: Batch
A47: Batch Timeline
A49: Air Freight | B49: 22.88 | C49: 22.88 | D49: 3.06 | E49: 4.88 | F49: 0.75 | G49: 2.55
A50: Fast Ocean | B50: 10.56 | C50: 10.56 | D50: 1.31 | E50: 2.09 | F50: 0.32 | G50: 0.97
A51: Ocean | B51: 2.65 | C51: 2.65 | D51: 0.39 | E51: 0.58 | F51: 0.1 | G51: 0.35
...
