Workbook
Name rdataslayer_d70e473bcafe40a3aa834ce157fb2ba3: 'Business Metrics Canada'!$C$16:$D$17
Name zsupermetrics_xwoIpANxRm908eDp5oKTwQpEI8gvD4: 'Business Metrics US'!$A$5
Name zsupermetrics_ru0GDtbZzDLHQOQtJJ6K08MvUDyyp7: 'OLD Formulas'!$B$5:$B$6
Name zsupermetrics_iNpyVy90bWCI0yUaFQpxOtzWMa6sW4: 'Business Metrics US'!$A$5:$A$12
Name zsupermetrics_DQl8lUbpTRu3fayaJJi7lVfOGKjNU4: 'ECOMMERCE Formulas'!$A$3:$A$4
Name zsupermetrics_NugLlrQxlKiqhxQae8EFpITBm1pLCj: 'Business Metrics Canada'!$B$15:$C$23
Name rdataslayer_4a0f150f4f2f4e4f85c890c75b7a1fa4: 'Business Metrics Canada'!$D$5:$E$12
Name zsupermetrics_BioPyGBzcBsy60UCQmPcTuFReEmghI: 'ECOMMERCE Formulas'!$B$2:$B$3
Name zsupermetrics_refreshAll: SupermetricsQueries!$H$5
Name zsupermetrics_DQl8lUbpTRu3fayaJJi7lVfOGKjNU4: 'Business Metrics Canada'!$A$2:$A$13
Name zsupermetrics_n3GtLgiKpTmd2pYmQNMuq6TPD0qE0b: 'OLD Formulas'!$B$5:$B$6
Name zsupermetrics_9i4W4hgd80uRpQLMeX0eRnESN8gjyv: 'Business Metrics US'!$C$23
Name zsupermetrics_qWp7V908pNEYMtfv8QZvSTeDnBAHOU: 'Business Metrics Canada'!$B$14:$C$23
Name zsupermetrics_refreshAllSilent: SupermetricsQueries!$H$6
Name zsupermetrics_Mgms9p0QzysYvrIhnsKACeVBVxfIEO: 'OLD Formulas'!$A$3:$A$4
Name rdataslayer_4a0f150f4f2f4e4f85c890c75b7a1fa4: 'Business Metrics US'!$D$5:$E$12
Name zsupermetrics_lx4cNai7gT6tH4j08ZRkI21Qlpjioi: 'Business Metrics Canada'!$B$13:$C$23
Name zsupermetrics_Mgms9p0QzysYvrIhnsKACeVBVxfIEO: 'ECOMMERCE Formulas'!$A$2:$A$3
Name zsupermetrics_forceRefresh: SupermetricsQueries!$H$4
Name zsupermetrics_wbYMmT0YL9bAN0yhimW0ziPFnia9Dx: 'OLD Formulas'!$A$3:$A$4
Name zsupermetrics_iNpyVy90bWCI0yUaFQpxOtzWMa6sW4: 'OLD Formulas'!$A$3:$A$4
Name zsupermetrics_xwoIpANxRm908eDp5oKTwQpEI8gvD4: 'Business Metrics Canada'!$A$5
Name zsupermetrics_xwoIpANxRm908eDp5oKTwQpEI8gvD4: #REF!
Name rdataslayer_3753ddf3234e496aa261974a0222e193: 'Business Metrics US'!$H$5:$I$5
Name zsupermetrics_4VkB7ij7WO0JjKBEgvjB2GHjSy2Egm: 'Business Metrics Canada'!$B$13:$C$17
Name zsupermetrics_n3GtLgiKpTmd2pYmQNMuq6TPD0qE0b: 'ECOMMERCE Formulas'!$B$4:$B$5
Name rdataslayer_42b112e4e4be4305bb4c1be75e2dd549: 'ECOMMERCE Formulas'!$B$2:$C$3
Name zsupermetrics_wbYMmT0YL9bAN0yhimW0ziPFnia9Dx: 'Business Metrics Canada'!$A$5:$A$12
Name zsupermetrics_9i4W4hgd80uRpQLMeX0eRnESN8gjyv: 'OLD Formulas'!$C$14
Name zsupermetrics_YsFuuYtr8vOdNXCCPiFJIO38NP4b2T: 'Business Metrics US'!$B$13:$C$23
Name zsupermetrics_5bmwtOpHUbSYmDMeuCPkrxaojTprPP: #REF!
Name rdataslayer_adf57e64065742daa5b4161161b1c3ca: 'Business Metrics Canada'!$B$13:$D$14
Name zsupermetrics_9i4W4hgd80uRpQLMeX0eRnESN8gjyv: 'Business Metrics Canada'!$C$23
Name rdataslayer_3753ddf3234e496aa261974a0222e193: 'ECOMMERCE Formulas'!$H$2:$I$2
Name zsupermetrics_4VkB7ij7WO0JjKBEgvjB2GHjSy2Egm: 'Business Metrics US'!$B$13:$C$17
Name zsupermetrics_SGBxROnInO9rFyh3H7j2Lldx0Bdc5v: #REF!
Name zsupermetrics_pxuhRTEmIU93xSgKclyxajD0fCZ6rF: #REF!
Name zsupermetrics_ru0GDtbZzDLHQOQtJJ6K08MvUDyyp7: 'ECOMMERCE Formulas'!$B$4:$B$5
Name zsupermetrics_qWp7V908pNEYMtfv8QZvSTeDnBAHOU: 'ECOMMERCE Formulas'!$B$5:$C$13
Name zsupermetrics_wbYMmT0YL9bAN0yhimW0ziPFnia9Dx: 'Business Metrics US'!$A$5:$A$12
Name rdataslayer_4a0f150f4f2f4e4f85c890c75b7a1fa4: 'OLD Formulas'!$D$3:$E$4
Name zsupermetrics_iNpyVy90bWCI0yUaFQpxOtzWMa6sW4: 'Business Metrics Canada'!$A$5:$A$12
Name zsupermetrics_HgZqhorObHOtZHuyJjpmyYaEPoYntx: 'OLD Formulas'!$B$5:$B$6
Name zsupermetrics_YsFuuYtr8vOdNXCCPiFJIO38NP4b2T: 'OLD Formulas'!$B$5:$C$14
Name zsupermetrics_DQl8lUbpTRu3fayaJJi7lVfOGKjNU4: 'OLD Formulas'!$A$4:$A$5
Name zsupermetrics_YVuzfmsfdurz7Ldl84Rfns8oka6LsS: #REF!
Name zsupermetrics_4VkB7ij7WO0JjKBEgvjB2GHjSy2Egm: 'OLD Formulas'!$B$5:$C$11
Name zsupermetrics_9i4W4hgd80uRpQLMeX0eRnESN8gjyv: 'ECOMMERCE Formulas'!$C$13
Name zsupermetrics_Mgms9p0QzysYvrIhnsKACeVBVxfIEO: 'Business Metrics US'!$A$5:$A$12
Name zsupermetrics_lx4cNai7gT6tH4j08ZRkI21Qlpjioi: 'OLD Formulas'!$B$5:$C$14
Name zsupermetrics_BioPyGBzcBsy60UCQmPcTuFReEmghI: 'Business Metrics US'!$B$5:$B$12
Name zsupermetrics_qWp7V908pNEYMtfv8QZvSTeDnBAHOU: 'Business Metrics US'!$B$14:$C$23
Name rdataslayer_adf57e64065742daa5b4161161b1c3ca: 'Business Metrics US'!$B$13:$D$14
Name rdataslayer_d70e473bcafe40a3aa834ce157fb2ba3: 'OLD Formulas'!$C$9:$D$10
Name zsupermetrics_NugLlrQxlKiqhxQae8EFpITBm1pLCj: 'ECOMMERCE Formulas'!$B$6:$C$13
Name zsupermetrics_8xojRjNDjo2jWHGDWjFEhflhyIq3Hq: 'OLD Sales'!$K$8:$K$14
Name rdataslayer_42b112e4e4be4305bb4c1be75e2dd549: 'Business Metrics Canada'!$B$5:$C$12
Name rdataslayer_d70e473bcafe40a3aa834ce157fb2ba3: 'Business Metrics US'!$C$16:$D$17
Name rdataslayer_3753ddf3234e496aa261974a0222e193: 'OLD Formulas'!$H$3:$I$3
Name zsupermetrics_BioPyGBzcBsy60UCQmPcTuFReEmghI: 'Business Metrics Canada'!$B$5:$B$12

Sheet DataslayerQueries
A1: Query UUID | B1: Sheet name | C1: Range address | D1: Created | E1: Updated | F1: Last status | G1: Last refresh ID | H1: Results contain sampled data | I1: Execution time (sec) | J1: Object type | K1: Linked chart ID | L1: Data source | M1: Date range type | N1: Start date | O1: End date | P1: Compare to | Q1: Comparison value type | R1: Accounts/views | S1: Metrics | T1: Dimensions | U1: Pivot dimensions | V1: Filters | W1: Segment ID | X1: Segment dim | Y1: Sort | Z1: Max rows | AA1: Max pivot categories | AB1: Special settings | AC1: Other parameters | AD1: Result type | AE1: Language/country | AF1: Translate to | AG1: SQL | AH1: Database name | AI1: Range address (static) | AJ1: Report type | AK1: Highlight with colour | AL1: Refresh with user account | AM1: Returned data | AN1: Sort dimensions | AO1: Created by user account
A2: 42b112e4e4be4305bb4c1be75e2dd549 | B2: =IFERROR(__xludf.DUMMYFUNCTION("ARRAY_CONSTRAIN(split(CELL(""ADDRESS"",rdataslayer_42b112e4e4be4305bb4c1be75e2dd549),""!""),1,1)"),"[OLD] Formulas'") -> [OLD] Formulas' | C2: =IFERROR(__xludf.DUMMYFUNCTION("INDEX(split(CELL(""ADDRESS"",rdataslayer_42b112e4e4be4305bb4c1be75e2dd549),""!""),0,2)&"":""&address(row(rdataslayer_42b112e4e4be4305bb4c1be75e2dd549)+rows(rdataslayer_42b112e4e4be4305bb4c1be75e2dd549)-1,column(rdataslayer_42b112e4e4be4305bb4c1be75e2dd549"&")+COLUMNS(rdataslayer_42b112e4e4be4305bb4c1be75e2dd549)-1)"),"$B$3:$C$4") -> $B$3:$C$4 | D2: 44518.613 | E2: 44520.051 | F2: There is no data for the specified input | I2: 7 | J2: TABLE | L2: facebook | M2: yesterday | R2: [{"profile_id":"","name":"si_Bird buddy Inc_US &amp; CA_BirdBuddy","id":"act_273249767551281","account_name":"","advertiser_id":""}] | S2: [{"id":"spend","name":"Total Cost"}] | T2: [{"id":"date","name":"Date"}] | U2: [] | V2: [] | W2: [] | Y2: [] | Z2: 5 | AA2: 5 | AB2: {} | AC2: {} | AL2: User_Kumalic_Benjamin | AN2: [] | AO2: benjamin@mybirdbuddy.com
A3: 4a0f150f4f2f4e4f85c890c75b7a1fa4 | B3: =IFERROR(__xludf.DUMMYFUNCTION("ARRAY_CONSTRAIN(split(CELL(""ADDRESS"",rdataslayer_4a0f150f4f2f4e4f85c890c75b7a1fa4),""!""),1,1)"),"[OLD] Formulas'") -> [OLD] Formulas' | C3: =IFERROR(__xludf.DUMMYFUNCTION("INDEX(split(CELL(""ADDRESS"",rdataslayer_4a0f150f4f2f4e4f85c890c75b7a1fa4),""!""),0,2)&"":""&address(row(rdataslayer_4a0f150f4f2f4e4f85c890c75b7a1fa4)+rows(rdataslayer_4a0f150f4f2f4e4f85c890c75b7a1fa4)-1,column(rdataslayer_4a0f150f4f2f4e4f85c890c75b7a1fa4"&")+COLUMNS(rdataslayer_4a0f150f4f2f4e4f85c890c75b7a1fa4)-1)"),"$D$3:$E$4") -> $D$3:$E$4 | D3: 44518.615 | E3: 44520.051 | F3: There is no data for the specified input | I3: 7 | J3: TABLE | L3: facebook | M3: yesterday | R3: [{"account_name":"","advertiser_id":"","id":"act_273249767551281","profile_id":"","name":"si_Bird buddy Inc_US &amp; CA_BirdBuddy"}] | S3: [{"id":"spend","name":"Total Cost"}] | T3: [] | U3: [{"id":"date","name":"Date"}] | V3: [] | W3: [] | Y3: [] | Z3: 5 | AA3: 5 | AB3: {} | AC3: {} | AL3: User_Kumalic_Benjamin | AN3: [] | AO3: benjamin@mybirdbuddy.com
A4: adf57e64065742daa5b4161161b1c3ca | B4: =IFERROR(__xludf.DUMMYFUNCTION("ARRAY_CONSTRAIN(split(CELL(""ADDRESS"",rdataslayer_adf57e64065742daa5b4161161b1c3ca),""!""),1,1)"),"[OLD] Formulas'") -> [OLD] Formulas' | C4: =IFERROR(__xludf.DUMMYFUNCTION("INDEX(split(CELL(""ADDRESS"",rdataslayer_adf57e64065742daa5b4161161b1c3ca),""!""),0,2)&"":""&address(row(rdataslayer_adf57e64065742daa5b4161161b1c3ca)+rows(rdataslayer_adf57e64065742daa5b4161161b1c3ca)-1,column(rdataslayer_adf57e64065742daa5b4161161b1c3ca"&")+COLUMNS(rdataslayer_adf57e64065742daa5b4161161b1c3ca)-1)"),"$B$5:$D$6") -> $B$5:$D$6 | D4: 44518.618 | E4: 44520.051 | F4: There is no data for the specified input | I4: 18 | J4: TABLE | L4: facebook | M4: yesterday | R4: [{"name":"si_Bird buddy Inc_US &amp; CA_BirdBuddy","id":"act_273249767551281","profile_id":"","account_name":"","advertiser_id":""}] | S4: [{"id":"spend","name":"Total Cost"},{"id":"cpm","name":"CPM"}] | T4: [{"id":"date","name":"Date"}] | U4: [] | V4: [] | W4: [] | Y4: [] | Z4: 5 | AA4: 5 | AB4: {} | AC4: {} | AL4: User_Kumalic_Benjamin | AN4: [] | AO4: benjamin@mybirdbuddy.com
A5: d70e473bcafe40a3aa834ce157fb2ba3 | B5: =IFERROR(__xludf.DUMMYFUNCTION("ARRAY_CONSTRAIN(split(CELL(""ADDRESS"",rdataslayer_d70e473bcafe40a3aa834ce157fb2ba3),""!""),1,1)"),"[OLD] Formulas'") -> [OLD] Formulas' | C5: =IFERROR(__xludf.DUMMYFUNCTION("INDEX(split(CELL(""ADDRESS"",rdataslayer_d70e473bcafe40a3aa834ce157fb2ba3),""!""),0,2)&"":""&address(row(rdataslayer_d70e473bcafe40a3aa834ce157fb2ba3)+rows(rdataslayer_d70e473bcafe40a3aa834ce157fb2ba3)-1,column(rdataslayer_d70e473bcafe40a3aa834ce157fb2ba3"&")+COLUMNS(rdataslayer_d70e473bcafe40a3aa834ce157fb2ba3)-1)"),"$C$9:$D$10") -> $C$9:$D$10 | D5: 44518.619 | E5: 44520.051 | F5: There is no data for the specified input | I5: 7 | J5: TABLE | L5: facebook | M5: yesterday | R5: [{"advertiser_id":"","name":"si_Bird buddy Inc_US &amp; CA_BirdBuddy","id":"act_273249767551281","account_name":"","profile_id":""}] | S5: [{"id":"spend","name":"Total Cost"}] | T5: [{"id":"date","name":"Date"}] | U5: [] | V5: [] | W5: [] | Y5: [] | Z5: 100 | AA5: 100 | AB5: {} | AC5: {} | AL5: User_Kumalic_Benjamin | AN5: [] | AO5: benjamin@mybirdbuddy.com
A6: 3753ddf3234e496aa261974a0222e193 | B6: =IFERROR(__xludf.DUMMYFUNCTION("ARRAY_CONSTRAIN(split(CELL(""ADDRESS"",rdataslayer_3753ddf3234e496aa261974a0222e193),""!""),1,1)"),"[OLD] Formulas'") -> [OLD] Formulas' | C6: =IFERROR(__xludf.DUMMYFUNCTION("INDEX(split(CELL(""ADDRESS"",rdataslayer_3753ddf3234e496aa261974a0222e193),""!""),0,2)&"":""&address(row(rdataslayer_3753ddf3234e496aa261974a0222e193)+rows(rdataslayer_3753ddf3234e496aa261974a0222e193)-1,column(rdataslayer_3753ddf3234e496aa261974a0222e193"&")+COLUMNS(rdataslayer_3753ddf3234e496aa261974a0222e193)-1)"),"$H$3:$I$3") -> $H$3:$I$3 | D6: 44518.621 | E6: 44520.051 | F6: There is no data for the specified input | I6: 18 | J6: TABLE | L6: facebook | M6: yesterday | R6: [{"profile_id":"","account_name":"","advertiser_id":"","name":"si_Bird buddy Inc_US &amp; CA_BirdBuddy","id":"act_273249767551281"}] | S6: [{"id":"spend","name":"Total Cost"}] | T6: [] | U6: [] | V6: [] | W6: [] | Y6: [] | Z6: 100 | AA6: 100 | AB6: {"exclude_header_row":true} | AC6: {} | AL6: User_Kumalic_Benjamin | AN6: [] | AO6: benjamin@mybirdbuddy.com

Sheet Summary
A1: 45108 | B1: 45108 | C1: 45109 | D1: 45110 | E1: 45111 | F1: 45112 | G1: 45113 | H1: 45114 | I1: 45115 | J1: 45116 | K1: 45117 | L1: 45118 | M1: 45119 | N1: 45120 | O1: 45121 | P1: 45122 | Q1: 45123 | R1: 45124 | S1: 45125 | T1: 45126 | U1: 45127 | V1: 45128 | W1: 45129 | X1: 45130 | Y1: 45131 | Z1: 45132 | AA1: 45133 | AB1: 45134 | AC1: 45135 | AD1: 45136 | AE1: 45137 | AF1: 45138
B2: SAT | C2: SUN | D2: MON | E2: TUE | F2: WED | G2: THU | H2: FRI | I2: SAT | J2: SUN | K2: MON | L2: TUE | M2: WED | N2: THU | O2: FRI | P2: SAT | Q2: SUN | R2: MON | S2: TUE | T2: WED | U2: THU | V2: FRI | W2: SAT | X2: SUN | Y2: MON | Z2: TUE | AA2: WED | AB2: THU | AC2: FRI | AD2: SAT | AE2: SUN | AF2: MON
A3: Weekend Work | B3: Peter | C3: Peter | I3: Peter | J3: Peter | P3: Peco | Q3: Peco | W3: Peco | X3: Peco | AD3: Peter | AE3: Peter
B4: Summer Sale | Z4: Friendship Day
G5: Check comments in this cell | H5: Check comments in this cell | K5: Switch to BB yellow AND blue 10% off | N5: Communication changed from next day shipping to now shipping | R5: Website caching problem / Site down for 8 hours | V5: SBF (Blue) - out of stock | Y5: One page checkout live from 3pm | Z5: Friendship Day starts at 18:00 CET | AC5: SBF (Blue) Back in stock
N6: In-Stock Sale Email | O6: In-Stock Sale Push Notification | R6: In-Stock Sale Follow-up Email | AA6: Switching FB strategy to separate MOF & BOF
A8: DTC Revenue | B8: =sum(B9:B12) -> 45643.43 | C8: =sum(C9:C12) -> 45073.44 | D8: =sum(D9:D12) -> 38928.55 | E8: =sum(E9:E12) -> 42623.92 | F8: =sum(F9:F12) -> 41052.98 | G8: =sum(G9:G12) -> 44139.05 | H8: =sum(H9:H12) -> 46442.05 | I8: =sum(I9:I12) -> 54824.78 | ... AF8: =sum(AF9:AF12) -> 36477.99
A9: - Hardware | B9: 36339.3 | C9: 35421 | D9: 31591.8 | E9: 34100.4 | F9: 33472.26 | G9: 35821.56 | H9: 38210.4 | I9: 43742.46 | J9: 41422.2 | K9: 39284.96 | L9: 40703.3 | M9: 41234.16 | N9: 63104.9 | O9: 56976.1 | P9: 47668.1 | Q9: 49046.66 | R9: 26941 | S9: 48103.1 | T9: 35159.9 | U9: 39792.4 | V9: 36372.6 | W9: 36633.8 | X9: 30906.36 | Y9: 26358.4 | Z9: 27558.89 | AA9: 25640.36 | AB9: 28999.96 | AC9: 26447.16 | AD9: 25269.66 | AE9: 25398.43 | AF9: 29808.2
A10: - Add-ons | B10: 3989.9 | C10: 4273 | D10: 2907 | E10: 3694 | F10: 2903.84 | G10: 3373.34 | H10: 3094 | I10: 4878.34 | J10: 4884.2 | K10: 4714.34 | L10: 3192 | M10: 3191.34 | N10: 6532 | O10: 5318.7 | P10: 5447.5 | Q10: 4774.34 | R10: 2782.5 | S10: 4742 | T10: 3127.5 | U10: 4219 | V10: 3698 | W10: 3777.5 | X10: 4035.84 | Y10: 2513 | Z10: 2883.51 | AA10: 2296.84 | AB10: 2151.84 | AC10: 2146.84 | AD10: 2833.34 | AE10: 2899.17 | AF10: 2702.4
A11: - Taxes | B11: 2609.23 | C11: 2794.44 | D11: 2179.75 | E11: 2264.52 | F11: 2326.88 | G11: 2594.15 | H11: 2622.65 | I11: 3158.98 | J11: 2956.54 | K11: 2753.74 | L11: 2970.74 | M11: 2809.39 | N11: 4513.51 | O11: 4143.08 | P11: 3461.03 | Q11: 3387.67 | R11: 1939.38 | S11: 3498.68 | T11: 2561.62 | U11: 2827.76 | V11: 2666.73 | W11: 2596.99 | X11: 2267.02 | Y11: 1868.93 | Z11: 1873.95 | AA11: 1777.49 | AB11: 1878.56 | AC11: 1670.07 | AD11: 1808.81 | AE11: 1886.17 | AF11: 1967.39
A12: - Shipping | B12: 2705 | C12: 2585 | D12: 2250 | E12: 2565 | F12: 2350 | G12: 2350 | H12: 2515 | I12: 3045 | J12: 2980 | K12: 2970 | L12: 2580 | M12: 2695 | N12: 4355 | O12: 3935 | P12: 3460 | Q12: 3550 | R12: 1955 | S12: 3210 | T12: 2460 | U12: 2680 | V12: 2580 | W12: 2460 | X12: 2305 | Y12: 1840 | Z12: 1875 | AA12: 1745 | AB12: 1820 | AC12: 1945 | AD12: 1750 | AE12: 1850 | AF12: 2000
A13: Total Revenue | B13: =SUM(B8) -> 45643.43 | C13: =SUM(C8) -> 45073.44 | D13: =SUM(D8) -> 38928.55 | E13: =SUM(E8) -> 42623.92 | F13: =SUM(F8) -> 41052.98 | G13: =SUM(G8) -> 44139.05 | H13: =SUM(H8) -> 46442.05 | I13: =SUM(I8) -> 54824.78 | ... AF13: =SUM(AF8) -> 36477.99
A15: DTC Orders | B15: 196 | C15: 181 | D15: 159 | E15: 187 | F15: 174 | G15: 186 | H15: 197 | I15: 239 | J15: 221 | K15: 219 | L15: 210 | M15: 200 | N15: 333 | O15: 294 | P15: 255 | Q15: 256 | R15: 153 | S15: 240 | T15: 177 | U15: 200 | V15: 192 | W15: 191 | X15: 173 | Y15: 130 | Z15: 135 | AA15: 119 | AB15: 130 | AC15: 133 | AD15: 131 | AE15: 132 | AF15: 141
A16: - Hardware (units sold) | B16: 151 | C16: 149 | D16: 134 | E16: 146 | F16: 147 | G16: 154 | H16: 170 | I16: 189 | J16: 178 | K16: 174 | L16: 181 | M16: 182 | N16: 287 | O16: 263 | P16: 217 | Q16: 222 | R16: 122 | S16: 213 | T16: 154 | U16: 171 | V16: 154 | W16: 146 | X16: 125 | Y16: 104 | Z16: 112 | AA16: 106 | AB16: 119 | AC16: 112 | AD16: 103 | AE16: 106 | AF16: 122
A17: - Add-ons (units sold) | B17: 134 | C17: 150 | D17: 94 | E17: 122 | F17: 104 | G17: 109 | H17: 101 | I17: 167 | J17: 160 | K17: 154 | L17: 118 | M17: 114 | N17: 221 | O17: 183 | P17: 197 | Q17: 176 | R17: 93 | S17: 170 | T17: 120 | U17: 145 | V17: 132 | W17: 135 | X17: 138 | Y17: 92 | Z17: 95 | AA17: 83 | AB17: 80 | AC17: 75 | AD17: 90 | AE17: 99 | AF17: 98
A18: Total Orders | B18: =SUM(B15) -> 196 | C18: =SUM(C15) -> 181 | D18: =SUM(D15) -> 159 | E18: =SUM(E15) -> 187 | F18: =SUM(F15) -> 174 | G18: =SUM(G15) -> 186 | H18: =SUM(H15) -> 197 | I18: =SUM(I15) -> 239 | ... AF18: =SUM(AF15) -> 141
A20: Meta Spend EUR | B20: 6812.23 | C20: 8920.58 | D20: 10641.93 | E20: =12542.67 -> 12542.67 | F20: =12229.74 -> 12229.74 | G20: =12058.01 -> 12058.01 | H20: =12244.54 -> 12244.54 | I20: =12582.44 -> 12582.44 | J20: =15187 -> 15187 | K20: =14931.46 -> 14931.46 | L20: =13178.9 -> 13178.9 | M20: 8654.11 | N20: 8564.89 | O20: 11789.45 | P20: 15747.93 | Q20: 18280.91 | R20: 13347.97 | S20: 13146.6 | T20: 14341.92 | U20: 14801 | V20: 14841.48 | W20: 15111.05 | X20: 15762.12 | Y20: 10132.76 | Z20: 8367.72 | AA20: 8856.5 | AB20: 6682.97 | AC20: 6077.66 | AD20: 6139.65 | AE20: 7096.91 | AF20: 7025.38
A21: Currency rate
A22: Meta Spend | B22: =IFERROR(__xludf.DUMMYFUNCTION("GOOGLEFINANCE(""CURRENCY:EURUSD"")*B20"),7810.5282453499985) -> 7810.5282 | C22: =IFERROR(__xludf.DUMMYFUNCTION("GOOGLEFINANCE(""CURRENCY:EURUSD"")*C20"),10227.8463961) -> 10227.846 | D22: =IFERROR(__xludf.DUMMYFUNCTION("GOOGLEFINANCE(""CURRENCY:EURUSD"")*D20"),12201.45163185) -> 12201.452 | E22: =IFERROR(__xludf.DUMMYFUNCTION("GOOGLEFINANCE(""CURRENCY:EURUSD"")*E20"),14380.73557515) -> 14380.736 | F22: =IFERROR(__xludf.DUMMYFUNCTION("GOOGLEFINANCE(""CURRENCY:EURUSD"")*F20"),14021.947248299999) -> 14021.947 | G22: =IFERROR(__xludf.DUMMYFUNCTION("GOOGLEFINANCE(""CURRENCY:EURUSD"")*G20"),13825.05107545) -> 13825.051 | H22: =IFERROR(__xludf.DUMMYFUNCTION("GOOGLEFINANCE(""CURRENCY:EURUSD"")*H20"),14038.9161143) -> 14038.916 | I22: =IFERROR(__xludf.DUMMYFUNCTION("GOOGLEFINANCE(""CURRENCY:EURUSD"")*I20"),14426.3336698) -> 14426.334 | J22: =IFERROR(__xludf.DUMMYFUNCTION("GOOGLEFINANCE(""CURRENCY:EURUSD"")*J20"),17412.578915) -> 17412.579 | K22: =IFERROR(__xludf.DUMMYFUNCTION("GOOGLEFINANCE(""CURRENCY:EURUSD"")*K20"),17119.590805699998) -> 17119.591 | L22: =IFERROR(__xludf.DUMMYFUNCTION("GOOGLEFINANCE(""CURRENCY:EURUSD"")*L20"),15110.201900499998) -> 15110.202 | M22: =IFERROR(__xludf.DUMMYFUNCTION("GOOGLEFINANCE(""CURRENCY:EURUSD"")*M20"),9922.32654995) -> 9922.3265 | N22: =IFERROR(__xludf.DUMMYFUNCTION("GOOGLEFINANCE(""CURRENCY:EURUSD"")*N20"),9820.03180505) -> 9820.0318 | O22: =IFERROR(__xludf.DUMMYFUNCTION("GOOGLEFINANCE(""CURRENCY:EURUSD"")*O20"),13517.13495025) -> 13517.135 | P22: =IFERROR(__xludf.DUMMYFUNCTION("GOOGLEFINANCE(""CURRENCY:EURUSD"")*P20"),18055.71040185) -> 18055.71 | Q22: =IFERROR(__xludf.DUMMYFUNCTION("GOOGLEFINANCE(""CURRENCY:EURUSD"")*Q20"),20959.885955949998) -> 20959.886 | R22: =IFERROR(__xludf.DUMMYFUNCTION("GOOGLEFINANCE(""CURRENCY:EURUSD"")*R20"),15304.048263649998) -> 15304.048 | S22: =IFERROR(__xludf.DUMMYFUNCTION("GOOGLEFINANCE(""CURRENCY:EURUSD"")*S20"),15073.168496999999) -> 15073.168 | T22: =IFERROR(__xludf.DUMMYFUNCTION("GOOGLEFINANCE(""CURRENCY:EURUSD"")*T20"),16443.6566664) -> 16443.657 | U22: =IFERROR(__xludf.DUMMYFUNCTION("GOOGLEFINANCE(""CURRENCY:EURUSD"")*U20"),16970.012544999998) -> 16970.013 | V22: =IFERROR(__xludf.DUMMYFUNCTION("GOOGLEFINANCE(""CURRENCY:EURUSD"")*V20"),17016.4246866) -> 17016.425 | W22: =IFERROR(__xludf.DUMMYFUNCTION("GOOGLEFINANCE(""CURRENCY:EURUSD"")*W20"),17325.49882225) -> 17325.499 | X22: =IFERROR(__xludf.DUMMYFUNCTION("GOOGLEFINANCE(""CURRENCY:EURUSD"")*X20"),18071.9798754) -> 18071.98 | Y22: =IFERROR(__xludf.DUMMYFUNCTION("GOOGLEFINANCE(""CURRENCY:EURUSD"")*Y20"),11617.6653142) -> 11617.665 | Z22: =IFERROR(__xludf.DUMMYFUNCTION("GOOGLEFINANCE(""CURRENCY:EURUSD"")*Z20"),9593.967527399998) -> 9593.9675 | AA22: =IFERROR(__xludf.DUMMYFUNCTION("GOOGLEFINANCE(""CURRENCY:EURUSD"")*AA20"),10154.375792499999) -> 10154.376 | AB22: =IFERROR(__xludf.DUMMYFUNCTION("GOOGLEFINANCE(""CURRENCY:EURUSD"")*AB20"),7662.32583865) -> 7662.3258 | AC22: =IFERROR(__xludf.DUMMYFUNCTION("GOOGLEFINANCE(""CURRENCY:EURUSD"")*AC20"),6968.310684699999) -> 6968.3107 | AD22: =IFERROR(__xludf.DUMMYFUNCTION("GOOGLEFINANCE(""CURRENCY:EURUSD"")*AD20"),7039.385009249999) -> 7039.385 | AE22: =IFERROR(__xludf.DUMMYFUNCTION("GOOGLEFINANCE(""CURRENCY:EURUSD"")*AE20"),8136.92667595) -> 8136.9267 | AF22: =IFERROR(__xludf.DUMMYFUNCTION("GOOGLEFINANCE(""CURRENCY:EURUSD"")*AF20"),8054.9143121) -> 8054.9143
A23: Google Spend | B23: 3497.11 | C23: 3319.47 | D23: 3105.73 | E23: 3164.17 | F23: 2743.6 | G23: 3026.1 | H23: 3130.09 | I23: 3395.52 | J23: 3789.66 | K23: 3114.09 | L23: 3480.59 | M23: 3371.41 | N23: 3892.08 | O23: 4289.26 | P23: 5070.66 | Q23: 5352.91 | R23: 4266.18 | S23: 5866.88 | T23: 3965.4 | U23: 3445.26 | V23: 4409.06 | W23: 6178.13 | X23: 7918.68 | Y23: 7299.64 | Z23: 6903.82 | AA23: 5757.83 | AB23: 6501.5 | AC23: 6675.18 | AD23: 5629.81 | AE23: 3929.84 | AF23: 2235.27
A24: Bing Spend | B24: 244.51 | C24: 259.8 | D24: 259.73 | E24: 251.56 | F24: 260.93 | G24: 252.96 | H24: 250.94 | I24: 249.85 | J24: 248.72 | K24: 245.95 | L24: 250.54 | M24: 247.66 | N24: 82.36 | O24: 0 | P24: 0 | Q24: 0 | R24: 0 | S24: 0 | T24: 130.29 | U24: 247.33 | V24: 241.87 | W24: 267.6 | X24: 247.2 | Y24: 239.41 | Z24: 253.25 | AA24: 281.69 | AB24: 262.48 | AC24: 301.09 | AD24: 283.72 | AE24: 289.28 | AF24: 296.9
A25: TikTok Spend | B25: 0 | C25: 0 | D25: 0 | E25: 0 | F25: 0 | G25: 0 | H25: 0 | I25: 0 | J25: 0 | K25: 0 | L25: 0 | M25: 0 | N25: 0 | O25: 0 | P25: 0 | Q25: 0 | R25: 0 | S25: 0 | T25: 0 | U25: 0 | V25: 0 | W25: 0 | X25: 0 | Y25: 0 | Z25: 0 | AA25: 0 | AB25: 0 | AC25: 0 | AD25: 0 | AE25: 0 | AF25: 0
A26: Nextdoor Spend | B26: 0 | C26: 0 | D26: 0 | E26: 0 | F26: 0 | G26: 0 | H26: 0 | I26: 0 | J26: 0 | K26: 0 | L26: 0 | M26: 0 | N26: 0 | O26: 0 | P26: 0 | Q26: 0 | R26: 0 | S26: 0 | T26: 0 | U26: 0 | V26: 0 | W26: 0 | X26: 0 | Y26: 0 | Z26: 0 | AA26: 0 | AB26: 0 | AC26: 0 | AD26: 0 | AE26: 0 | AF26: 0
A27: Affiliate Fees | B27: 0 | C27: 0 | D27: 0 | E27: 0 | F27: 0 | G27: 0 | H27: 0 | I27: 0 | J27: 0 | K27: 0 | L27: 0 | M27: 0 | N27: 0 | O27: 0 | P27: 0 | Q27: 0 | R27: 0 | S27: 156.16 | T27: 131.12 | U27: 215.27 | V27: 264.81 | W27: 122.94 | X27: 187.67 | Y27: 229.7 | Z27: 157.02 | AA27: 108.61 | AB27: 196.05 | AC27: 49.05 | AD27: 0 | AE27: 136.42 | AF27: 0
A28: Total DTC Spend | B28: =B22+B23+B24+B25+B26+B27 -> 11552.148 | C28: =C22+C23+C24+C25+C26+C27 -> 13807.116 | D28: =D22+D23+D24+D25+D26+D27 -> 15566.912 | E28: =E22+E23+E24+E25+E26+E27 -> 17796.466 | F28: =F22+F23+F24+F25+F26+F27 -> 17026.477 | G28: =G22+G23+G24+G25+G26+G27 -> 17104.111 | H28: =H22+H23+H24+H25+H26+H27 -> 17419.946 | I28: =I22+I23+I24+I25+I26+I27 -> 18071.704 | ... AF28: =AF22+AF23+AF24+AF25+AF26+AF27 -> 10587.084
A29: Total Spend | B29: =SUM(B22:B27) -> 11552.148 | C29: =SUM(C22:C27) -> 13807.116 | D29: =SUM(D22:D27) -> 15566.912 | E29: =SUM(E22:E27) -> 17796.466 | F29: =SUM(F22:F27) -> 17026.477 | G29: =SUM(G22:G27) -> 17104.111 | H29: =SUM(H22:H27) -> 17419.946 | I29: =SUM(I22:I27) -> 18071.704 | ... AF29: =SUM(AF22:AF27) -> 10587.084
A31: Blended ROAS | B31: =B13/B29 -> 3.9510772 | C31: =C13/C29 -> 3.2645079 | D31: =D13/D29 -> 2.500724 | E31: =E13/E29 -> 2.3950778 | F31: =F13/F29 -> 2.4111259 | G31: =G13/G29 -> 2.5806106 | H31: =H13/H29 -> 2.6660272 | I31: =I13/I29 -> 3.0337361 | ... AF31: =AF13/AF29 -> 3.445518
A32: wROAS | B32: =B8/B28 -> 3.9510772 | C32: =C8/C28 -> 3.2645079 | D32: =D8/D28 -> 2.500724 | E32: =E8/E28 -> 2.3950778 | F32: =F8/F28 -> 2.4111259 | G32: =G8/G28 -> 2.5806106 | H32: =H8/H28 -> 2.6660272 | I32: =I8/I28 -> 3.0337361 | ... AF32: =AF8/AF28 -> 3.445518
A34: Blended Spend per Unit | B34: =B29/'DTC - P&L'!B57 -> 76.504293 | C34: =C29/'DTC - P&L'!C57 -> 92.665211 | D34: =D29/'DTC - P&L'!D57 -> 116.17098 | E34: =E29/'DTC - P&L'!E57 -> 121.8936 | F34: =F29/'DTC - P&L'!F57 -> 115.82638 | G34: =G29/'DTC - P&L'!G57 -> 111.06566 | H34: =H29/'DTC - P&L'!H57 -> 102.47027 | I34: =I29/'DTC - P&L'!I57 -> 95.61748 | ... AF34: =AF29/'DTC - P&L'!AF57 -> 86.77938
A35: Web Spend per Unit | B35: =B28/'DTC - P&L'!B57 -> 76.504293 | C35: =C28/'DTC - P&L'!C57 -> 92.665211 | D35: =D28/'DTC - P&L'!D57 -> 116.17098 | E35: =E28/'DTC - P&L'!E57 -> 121.8936 | F35: =F28/'DTC - P&L'!F57 -> 115.82638 | G35: =G28/'DTC - P&L'!G57 -> 111.06566 | H35: =H28/'DTC - P&L'!H57 -> 102.47027 | I35: =I28/'DTC - P&L'!I57 -> 95.61748 | ... AF35: =AF28/'DTC - P&L'!AF57 -> 86.77938
A37: Web CR | B37: 0.0202 | C37: 0.0166 | D37: 0.0147 | E37: 0.0172 | F37: 0.0173 | G37: 0.0182 | H37: 0.018 | I37: 0.0213 | J37: 0.0175 | K37: 0.0189 | L37: 0.0184 | M37: 0.0227 | N37: 0.0302 | O37: 0.0177 | P37: 0.0204 | Q37: 0.0194 | R37: 0.0147 | S37: 0.0229 | T37: 0.0182 | U37: 0.0219 | V37: 0.0189 | W37: 0.0176 | X37: 0.0159 | Y37: 0.015 | Z37: 0.0165 | AA37: 0.0153 | AB37: 0.0168 | AC37: 0.0173 | AD37: 0.0182 | AE37: 0.0179 | AF37: 0.0221
A38: Web AOV | B38: =B8/B15 -> 232.87464 | C38: =C8/C15 -> 249.02453 | D38: =D8/D15 -> 244.83365 | E38: =E8/E15 -> 227.9354 | F38: =F8/F15 -> 235.93667 | G38: =G8/G15 -> 237.30672 | H38: =H8/H15 -> 235.74645 | I38: =I8/I15 -> 229.39238 | ... AF38: =AF8/AF15 -> 258.70915
A39: fAOV | B39: 232.87 | C39: 250.12 | D39: 245.84 | E39: 228.12 | F39: 233.8 | G39: 237.07 | H39: 235.75 | I39: 229.1 | J39: 236.39 | K39: 226.93 | L39: 236.28 | M39: 249.32 | N39: 236.82 | O39: 239.27 | P39: 237.04 | Q39: 239.26 | R39: 224.56 | S39: 249.17 | T39: 251.88 | U39: 247.08 | V39: 238.35 | W39: 239.44 | X39: 231.27 | Y39: 262.63 | Z39: 252.93 | AA39: 267.26 | AB39: 270.84 | AC39: 244.41 | AD39: 249.79 | AE39: 247.92 | AF39: 264.04
A40: rAOV | B40: 0 | C40: 150.77 | D40: 86.4 | E40: 210.85 | F40: 320.38 | G40: 251.65 | H40: 0 | I40: 246.79 | J40: 0 | K40: 235.68 | L40: 64.09 | M40: 282.07 | N40: 177.61 | O40: 267.23 | P40: 156.3 | Q40: 177.77 | R40: 76.55 | S40: 218.32 | T40: 69.85 | U40: 298.57 | V40: 164.13 | W40: 151.25 | X40: 160.39 | Y40: 89.17 | Z40: 275.82 | AA40: 152.47 | AB40: 151.33 | AC40: 145.32 | AD40: 73.05 | AE40: 109.48 | AF40: 113.61
A42: Customers
A43: Returning | B43: 1 | C43: 0.011 | D43: 0.006 | E43: 0.011 | F43: 0.012 | G43: 0.016 | H43: 0 | I43: 0.017 | J43: 0 | K43: 0.014 | L43: 0.005 | M43: 0.01 | N43: 0.018 | O43: 0.004 | P43: 0.028 | Q43: 0.032 | R43: 0.034 | S43: 0.034 | T43: 0.034 | U43: 0.01 | V43: 0.032 | W43: 0.016 | X43: 0.041 | Y43: 0.071 | Z43: 0.015 | AA43: 0.025 | AB43: 0.023 | AC43: 0.015 | AD43: 0.047 | AE43: 0.038 | AF43: 0.036
A44: First-time | B44: =1-B43 -> 0 | C44: =1-C43 -> 0.989 | D44: =1-D43 -> 0.994 | E44: =1-E43 -> 0.989 | F44: =1-F43 -> 0.988 | G44: =1-G43 -> 0.984 | H44: =1-H43 -> 1 | I44: =1-I43 -> 0.983 | ... AF44: =1-AF43 -> 0.964
B46: 45108 | C46: Goal | D46: % of Goal
A47: Revenue | B47: =SUM(B13:AF13) -> 1411507.8 | C47: 1200000 | D47: =B47/C47 -> 1.1762565
A48: Spend | B48: =SUM(B29:AF29) -> 555410.3 | C48: =C47/C49 -> 300000 | D48: =B48/C48 -> 1.8513677
...

Sheet DTC - P&L
A1: JULY | B1: 45108 | C1: 45109 | D1: 45110 | E1: 45111 | F1: 45112 | G1: 45113 | H1: 45114 | I1: 45115 | J1: 45116 | K1: 45117 | L1: 45118 | M1: 45119 | N1: 45120 | O1: 45121 | P1: 45122 | Q1: 45123 | R1: 45124 | S1: 45125 | T1: 45126 | U1: 45127 | V1: 45128 | W1: 45129 | X1: 45130 | Y1: 45131 | Z1: 45132 | AA1: 45133 | AB1: 45134 | AC1: 45135 | AD1: 45136 | AE1: 45137 | AF1: 45138
A2: DAY | B2: SAT | C2: SUN | D2: MON | E2: TUE | F2: WED | G2: THU | H2: FRI | I2: SAT | J2: SUN | K2: MON | L2: TUE | M2: WED | N2: THU | O2: FRI | P2: SAT | Q2: SUN | R2: MON | S2: TUE | T2: WED | U2: THU | V2: FRI | W2: SAT | X2: SUN | Y2: MON | Z2: TUE | AA2: WED | AB2: THU | AC2: FRI | AD2: SAT | AE2: SUN | AF2: MON
A3: COMMENT
A4: Orders
A5: Meta | B5: 52 | C5: 93 | D5: 64 | E5: 95 | F5: 81 | G5: 102 | H5: 101 | I5: 140 | J5: 113 | K5: 120 | L5: 107 | M5: 80 | N5: 140 | O5: 146 | P5: 114 | Q5: 118 | R5: 66 | S5: 96 | T5: 91 | U5: 104 | V5: 90 | W5: 89 | X5: 93 | Y5: 60 | Z5: 51 | AA5: 37 | AB5: 50 | AC5: 43 | AD5: 39 | AE5: 30 | AF5: 41 | AG5: =SUM(B5:AF5) -> 2646
A6: Google | B6: 78 | C6: 85 | D6: 66 | E6: 73 | F6: 67 | G6: 80 | H6: 86 | I6: 102 | J6: 95 | K6: 111 | L6: 91 | M6: 117 | N6: 94 | O6: 98 | P6: 84 | Q6: 86 | R6: 88 | S6: 130 | T6: 98 | U6: 150 | V6: 153 | W6: 140 | X6: 174 | Y6: 113 | Z6: 116 | AA6: 115 | AB6: 119 | AC6: 139 | AD6: 101 | AE6: 115 | AF6: 72 | AG6: =SUM(B6:AF6) -> 3236
A7: TikTok | B7: 0 | C7: 0 | D7: 0 | E7: 0 | F7: 0 | G7: 0 | H7: 0 | I7: 0 | J7: 0 | K7: 0 | L7: 0 | M7: 0 | N7: 0 | O7: 0 | P7: 0 | Q7: 0 | R7: 0 | S7: 0 | T7: 0 | U7: 0 | V7: 0 | W7: 0 | X7: 0 | Y7: 0 | Z7: 0 | AA7: 0 | AB7: 0 | AC7: 0 | AD7: 0 | AE7: 0 | AF7: 0 | AG7: 0
A8: Bing | B8: 0 | C8: 0 | D8: 0 | E8: 0 | F8: 0 | G8: 0 | H8: 0 | I8: 0 | J8: 0 | K8: 0 | L8: 0 | M8: 0 | N8: 0 | O8: 0 | P8: 0 | Q8: 0 | R8: 0 | S8: 0 | T8: 0 | U8: 0 | V8: 0 | W8: 0 | X8: 0 | Y8: 0 | Z8: 0 | AA8: 0 | AB8: 0 | AC8: 0 | AD8: 0 | AE8: 0 | AF8: 0 | AG8: =SUM(B8:AF8) -> 0
A9: Nextdoor | B9: 0 | C9: 0 | D9: 0 | E9: 0 | F9: 0 | G9: 0 | H9: 0 | I9: 0 | J9: 0 | K9: 0 | L9: 0 | M9: 0 | N9: 0 | O9: 0 | P9: 0 | Q9: 0 | R9: 0 | S9: 0 | T9: 0 | U9: 0 | V9: 0 | W9: 0 | X9: 0 | Y9: 0 | Z9: 0 | AA9: 0 | AB9: 0 | AC9: 0 | AD9: 0 | AE9: 0 | AF9: 0 | AG9: =SUM(B9:AF9) -> 0
A10: Affiliates (Refersion) | B10: 0 | C10: 0 | D10: 0 | E10: 0 | F10: 0 | G10: 0 | H10: 0 | I10: 0 | J10: 0 | K10: 0 | L10: 0 | M10: 0 | N10: 0 | O10: 0 | P10: 0 | Q10: 0 | R10: 0 | S10: 4 | T10: 3 | U10: 3 | V10: 4 | W10: 2 | X10: 3 | Y10: 5 | Z10: 3 | AA10: 2 | AB10: 3 | AC10: 1 | AD10: 0 | AE10: 4 | AF10: 0 | AG10: 37
A11: Email | B11: 4 | C11: 6 | D11: 3 | E11: 2 | F11: 1 | G11: 1 | H11: 0 | I11: 1 | J11: 2 | K11: 3 | L11: 1 | M11: 2 | N11: 94 | O11: 76 | P11: 25 | Q11: 17 | R11: 29 | S11: 38 | T11: 2 | U11: 4 | V11: 3 | W11: 2 | X11: 6 | Y11: 2 | Z11: 1 | AA11: 0 | AB11: 4 | AC11: 4 | AD11: 1 | AE11: 4 | AF11: 4 | AG11: =SUM(B11:AF11) -> 342
A12: All | B12: =SUM(B5:B11) -> 134 | C12: =SUM(C5:C11) -> 184 | D12: =SUM(D5:D11) -> 133 | E12: =SUM(E5:E11) -> 170 | F12: =SUM(F5:F11) -> 149 | G12: =SUM(G5:G11) -> 183 | H12: =SUM(H5:H11) -> 187 | I12: =SUM(I5:I11) -> 243 | ... AF12: =SUM(AF5:AF11) -> 117 | AG12: =SUM(B12:AF12) -> 6261
A14: Revenue | B14: 12675.01 | C14: 24381.02 | D14: 15128.23 | E14: 21258.9 | F14: 19092.71 | G14: 22290.99 | H14: 22384.22 | I14: 31413.49 | J14: 26123.96 | K14: 27325.69 | L14: 23733.94 | M14: 18438.07 | N14: 33573.93 | O14: 33415.06 | P14: 24031.07 | Q14: 25557.35 | R14: 13441.3 | S14: 21801.24 | T14: 20575.78 | U14: 25635.85 | V14: 19910.12 | W14: 21315.94 | X14: 20426.44 | Y14: 13358.97 | Z14: 12504.83 | AA14: 8226.96 | AB14: 12250.88 | AC14: 9252.93 | AD14: 9205.01 | AE14: 6970.93 | AF14: 10140.6
A15: Meta | B15: =IFERROR(__xludf.DUMMYFUNCTION("GOOGLEFINANCE(""CURRENCY:EURUSD"")*B14"),14532.46934045) -> 14532.469 | C15: =IFERROR(__xludf.DUMMYFUNCTION("GOOGLEFINANCE(""CURRENCY:EURUSD"")*C14"),27953.9365759) -> 27953.937 | D15: =IFERROR(__xludf.DUMMYFUNCTION("GOOGLEFINANCE(""CURRENCY:EURUSD"")*D14"),17345.19646535) -> 17345.196 | E15: =IFERROR(__xludf.DUMMYFUNCTION("GOOGLEFINANCE(""CURRENCY:EURUSD"")*E14"),24374.2855005) -> 24374.286 | F15: =IFERROR(__xludf.DUMMYFUNCTION("GOOGLEFINANCE(""CURRENCY:EURUSD"")*F14"),21890.65118695) -> 21890.651 | G15: =IFERROR(__xludf.DUMMYFUNCTION("GOOGLEFINANCE(""CURRENCY:EURUSD"")*G14"),25557.62312955) -> 25557.623 | H15: =IFERROR(__xludf.DUMMYFUNCTION("GOOGLEFINANCE(""CURRENCY:EURUSD"")*H14"),25664.5155199) -> 25664.516 | I15: =IFERROR(__xludf.DUMMYFUNCTION("GOOGLEFINANCE(""CURRENCY:EURUSD"")*I14"),36016.979892049996) -> 36016.98 | J15: =IFERROR(__xludf.DUMMYFUNCTION("GOOGLEFINANCE(""CURRENCY:EURUSD"")*J14"),29952.295718199995) -> 29952.296 | K15: =IFERROR(__xludf.DUMMYFUNCTION("GOOGLEFINANCE(""CURRENCY:EURUSD"")*K14"),31330.133241049996) -> 31330.133 | L15: =IFERROR(__xludf.DUMMYFUNCTION("GOOGLEFINANCE(""CURRENCY:EURUSD"")*L14"),27212.030237299998) -> 27212.03 | M15: =IFERROR(__xludf.DUMMYFUNCTION("GOOGLEFINANCE(""CURRENCY:EURUSD"")*M14"),21140.07696815) -> 21140.077 | N15: =IFERROR(__xludf.DUMMYFUNCTION("GOOGLEFINANCE(""CURRENCY:EURUSD"")*N14"),38494.02157185) -> 38494.022 | O15: =IFERROR(__xludf.DUMMYFUNCTION("GOOGLEFINANCE(""CURRENCY:EURUSD"")*O14"),38311.8699677) -> 38311.87 | P15: =IFERROR(__xludf.DUMMYFUNCTION("GOOGLEFINANCE(""CURRENCY:EURUSD"")*P14"),27552.703153149996) -> 27552.703 | Q15: =IFERROR(__xludf.DUMMYFUNCTION("GOOGLEFINANCE(""CURRENCY:EURUSD"")*Q14"),29302.651855749995) -> 29302.652 | R15: =IFERROR(__xludf.DUMMYFUNCTION("GOOGLEFINANCE(""CURRENCY:EURUSD"")*R14"),15411.055308499997) -> 15411.055 | S15: =IFERROR(__xludf.DUMMYFUNCTION("GOOGLEFINANCE(""CURRENCY:EURUSD"")*S14"),24996.1027158) -> 24996.103 | T15: =IFERROR(__xludf.DUMMYFUNCTION("GOOGLEFINANCE(""CURRENCY:EURUSD"")*T14"),23591.0576801) -> 23591.058 | U15: =IFERROR(__xludf.DUMMYFUNCTION("GOOGLEFINANCE(""CURRENCY:EURUSD"")*U14"),29392.655638249995) -> 29392.656 | V15: =IFERROR(__xludf.DUMMYFUNCTION("GOOGLEFINANCE(""CURRENCY:EURUSD"")*V14"),22827.848535399997) -> 22827.849 | W15: =IFERROR(__xludf.DUMMYFUNCTION("GOOGLEFINANCE(""CURRENCY:EURUSD"")*W14"),24439.684427299995) -> 24439.684 | X15: =IFERROR(__xludf.DUMMYFUNCTION("GOOGLEFINANCE(""CURRENCY:EURUSD"")*X14"),23419.8326498) -> 23419.833 | Y15: =IFERROR(__xludf.DUMMYFUNCTION("GOOGLEFINANCE(""CURRENCY:EURUSD"")*Y14"),15316.660258649998) -> 15316.66 | Z15: =IFERROR(__xludf.DUMMYFUNCTION("GOOGLEFINANCE(""CURRENCY:EURUSD"")*Z14"),14337.35031235) -> 14337.35 | AA15: =IFERROR(__xludf.DUMMYFUNCTION("GOOGLEFINANCE(""CURRENCY:EURUSD"")*AA14"),9432.579853199999) -> 9432.5799 | AB15: =IFERROR(__xludf.DUMMYFUNCTION("GOOGLEFINANCE(""CURRENCY:EURUSD"")*AB14"),14046.185209599998) -> 14046.185 | AC15: =IFERROR(__xludf.DUMMYFUNCTION("GOOGLEFINANCE(""CURRENCY:EURUSD"")*AC14"),10608.90062685) -> 10608.901 | AD15: =IFERROR(__xludf.DUMMYFUNCTION("GOOGLEFINANCE(""CURRENCY:EURUSD"")*AD14"),10553.95819045) -> 10553.958 | AE15: =IFERROR(__xludf.DUMMYFUNCTION("GOOGLEFINANCE(""CURRENCY:EURUSD"")*AE14"),7992.48493685) -> 7992.4849 | AF15: =IFERROR(__xludf.DUMMYFUNCTION("GOOGLEFINANCE(""CURRENCY:EURUSD"")*AF14"),11626.654226999999) -> 11626.654 | AG15: =SUM(B15:AF15) -> 694624.45
A16: Google | B16: 17677.42 | C16: 19491.64 | D16: 16155.61 | E16: 16190.97 | F16: 14253.45 | G16: 18950.64 | H16: 17552.74 | I16: 21202.65 | J16: 22383.36 | K16: 24365.38 | L16: 21103.84 | M16: 27826.14 | N16: 21588.42 | O16: 22876.85 | P16: 18232.01 | Q16: 19035.3 | R16: 19745.03 | S16: 29990.59 | T16: 25696.34 | U16: 35243.03 | V16: 35780.89 | W16: 30440.01 | X16: 41113.74 | Y16: 29308.52 | Z16: 31396.99 | AA16: 28641.3 | AB16: 29733.18 | AC16: 34539.75 | AD16: 24300.69 | AE16: 28836.64 | AF16: 16758.04 | AG16: =SUM(B16:AF16) -> 760411.16
A17: TikTok | B17: 0 | C17: 0 | D17: 0 | E17: 0 | F17: 0 | G17: 0 | H17: 0 | I17: 0 | J17: 0 | K17: 0 | L17: 0 | M17: 0 | N17: 0 | O17: 0 | P17: 0 | Q17: 0 | R17: 0 | S17: 0 | T17: 0 | U17: 0 | V17: 0 | W17: 0 | X17: 0 | Y17: 0 | Z17: 0 | AA17: 0 | AB17: 0 | AC17: 0 | AD17: 0 | AE17: 0 | AF17: 0 | AG17: 0
A18: Bing | B18: 0 | C18: 0 | D18: 0 | E18: 0 | F18: 0 | G18: 0 | H18: 0 | I18: 0 | J18: 0 | K18: 0 | L18: 0 | M18: 0 | N18: 0 | O18: 0 | P18: 0 | Q18: 0 | R18: 0 | S18: 0 | T18: 0 | U18: 0 | V18: 0 | W18: 0 | X18: 0 | Y18: 0 | Z18: 0 | AA18: 0 | AB18: 0 | AC18: 0 | AD18: 0 | AE18: 0 | AF18: 0 | AG18: =SUM(B18:AF18) -> 0
A19: Nextdoor | B19: 0 | C19: 0 | D19: 0 | E19: 0 | F19: 0 | G19: 0 | H19: 0 | I19: 0 | J19: 0 | K19: 0 | L19: 0 | M19: 0 | N19: 0 | O19: 0 | P19: 0 | Q19: 0 | R19: 0 | S19: 0 | T19: 0 | U19: 0 | V19: 0 | W19: 0 | X19: 0 | Y19: 0 | Z19: 0 | AA19: 0 | AB19: 0 | AC19: 0 | AD19: 0 | AE19: 0 | AF19: 0 | AG19: =SUM(B19:AF19) -> 0
A20: Affiliates (Refersion) | B20: 0 | C20: 0 | D20: 0 | E20: 0 | F20: 0 | G20: 0 | H20: 0 | I20: 0 | J20: 0 | K20: 0 | L20: 0 | M20: 0 | N20: 0 | O20: 0 | P20: 0 | Q20: 0 | R20: 0 | S20: 780.81 | T20: 541.79 | U20: 925.45 | V20: 1184.57 | W20: 531.95 | X20: 938.33 | Y20: 1148.46 | Z20: 785.1 | AA20: 543.06 | AB20: 908.25 | AC20: 245.27 | AD20: 0 | AE20: 682.12 | AF20: 0 | AG20: 9215.16
A21: Email | B21: 815.46 | C21: 1741.69 | D21: 729.81 | E21: 509.74 | F21: 204.7 | G21: 266.63 | H21: 0 | I21: 30.74 | J21: 425.14 | K21: 543.68 | L21: 63 | M21: 348.11 | N21: 21081.09 | O21: 19052.55 | P21: 6531.28 | Q21: 3775.83 | R21: 6515.75 | S21: 7669.01 | T21: 238.68 | U21: 825.72 | V21: 465.42 | W21: 309.71 | X21: 1222.39 | Y21: 351.79 | Z21: 24.84 | AA21: 0 | AB21: 1047.31 | AC21: 576.18 | AD21: 124.94 | AE21: 646.42 | AF21: 1000.93 | AG21: =SUM(B21:AF21) -> 77138.54
A22: All | B22: =SUM(B15:B21) -> 33025.349 | C22: =SUM(C15:C21) -> 49187.267 | D22: =SUM(D15:D21) -> 34230.616 | E22: =SUM(E15:E21) -> 41074.995 | F22: =SUM(F15:F21) -> 36348.801 | G22: =SUM(G15:G21) -> 44774.893 | H22: =SUM(H15:H21) -> 43217.256 | I22: =SUM(I15:I21) -> 57250.37 | ... AF22: =SUM(AF15:AF21) -> 29385.624 | AG22: =SUM(B22:AF22) -> 1541389.3
A24: Media Cost
A25: Meta | B25: =Summary!B22 -> 7810.5282 | C25: =Summary!C22 -> 10227.846 | D25: =Summary!D22 -> 12201.452 | E25: =Summary!E22 -> 14380.736 | F25: =Summary!F22 -> 14021.947 | G25: =Summary!G22 -> 13825.051 | H25: =Summary!H22 -> 14038.916 | I25: =Summary!I22 -> 14426.334 | ... AF25: =Summary!AF22 -> 8054.9143 | AG25: =SUM(B25:AF25) -> 408282.93
A26: Google | B26: =Summary!B23 -> 3497.11 | C26: =Summary!C23 -> 3319.47 | D26: =Summary!D23 -> 3105.73 | E26: =Summary!E23 -> 3164.17 | F26: =Summary!F23 -> 2743.6 | G26: =Summary!G23 -> 3026.1 | H26: =Summary!H23 -> 3130.09 | I26: =Summary!I23 -> 3395.52 | ... AF26: =Summary!AF23 -> 2235.27 | AG26: =SUM(B26:AF26) -> 138724.93
A27: TikTok | B27: =Summary!B25 -> 0 | C27: =Summary!C25 -> 0 | D27: =Summary!D25 -> 0 | E27: =Summary!E25 -> 0 | F27: =Summary!F25 -> 0 | G27: =Summary!G25 -> 0 | H27: =Summary!H25 -> 0 | I27: =Summary!I25 -> 0 | ... AF27: =Summary!AF25 -> 0 | AG27: =SUM(B27:AF27) -> 0
A28: Bing | B28: =Summary!B24 -> 244.51 | C28: =Summary!C24 -> 259.8 | D28: =Summary!D24 -> 259.73 | E28: =Summary!E24 -> 251.56 | F28: =Summary!F24 -> 260.93 | G28: =Summary!G24 -> 252.96 | H28: =Summary!H24 -> 250.94 | I28: =Summary!I24 -> 249.85 | ... AF28: =Summary!AF24 -> 296.9 | AG28: =SUM(B28:AF28) -> 6447.62
A29: Nextdoor | B29: =Summary!B26 -> 0 | C29: =Summary!C26 -> 0 | D29: =Summary!D26 -> 0 | E29: =Summary!E26 -> 0 | F29: =Summary!F26 -> 0 | G29: =Summary!G26 -> 0 | H29: =Summary!H26 -> 0 | I29: =Summary!I26 -> 0 | ... AF29: =Summary!AF26 -> 0 | AG29: =SUM(B29:AF29) -> 0
A30: Affiliate Fee (20%) | B30: =Summary!B27 -> 0 | C30: =Summary!C27 -> 0 | D30: =Summary!D27 -> 0 | E30: =Summary!E27 -> 0 | F30: =Summary!F27 -> 0 | G30: =Summary!G27 -> 0 | H30: =Summary!H27 -> 0 | I30: =Summary!I27 -> 0 | ... AF30: =Summary!AF27 -> 0 | AG30: =SUM(B30:AF30) -> 1954.82
A31: All | B31: =SUM(B25:B30) -> 11552.148 | C31: =SUM(C25:C30) -> 13807.116 | D31: =SUM(D25:D30) -> 15566.912 | E31: =SUM(E25:E30) -> 17796.466 | F31: =SUM(F25:F30) -> 17026.477 | G31: =SUM(G25:G30) -> 17104.111 | H31: =SUM(H25:H30) -> 17419.946 | I31: =SUM(I25:I30) -> 18071.704 | ... AF31: =SUM(AF25:AF30) -> 10587.084 | AG31: =SUM(B31:AF31) -> 555410.3
A36: Revenue
A37: Revenue Woocommerce (Platform) | B37: =Summary!B8 -> 45643.43 | C37: =Summary!C8 -> 45073.44 | D37: =Summary!D8 -> 38928.55 | E37: =Summary!E8 -> 42623.92 | F37: =Summary!F8 -> 41052.98 | G37: =Summary!G8 -> 44139.05 | H37: =Summary!H8 -> 46442.05 | I37: =Summary!I8 -> 54824.78 | ... AF37: =Summary!AF8 -> 36477.99 | AG37: =sum(B37:AF37) -> 1411507.8
A38: SUM | B38: =SUM(B37) -> 45643.43 | C38: =SUM(C37) -> 45073.44 | D38: =SUM(D37) -> 38928.55 | E38: =SUM(E37) -> 42623.92 | F38: =SUM(F37) -> 41052.98 | G38: =SUM(G37) -> 44139.05 | H38: =SUM(H37) -> 46442.05 | I38: =SUM(I37) -> 54824.78 | ... AF38: =SUM(AF37) -> 36477.99 | AG38: =sum(B38:AF38) -> 1411507.8
A40: Orders
A41: Orders Woocommerce (Platform) | B41: =Summary!B15 -> 196 | C41: =Summary!C15 -> 181 | D41: =Summary!D15 -> 159 | E41: =Summary!E15 -> 187 | F41: =Summary!F15 -> 174 | G41: =Summary!G15 -> 186 | H41: =Summary!H15 -> 197 | I41: =Summary!I15 -> 239 | ... AF41: =Summary!AF15 -> 141 | AG41: =sum(B41:AF41) -> 5884
A42: SUM | B42: =SUM(B41) -> 196 | C42: =SUM(C41) -> 181 | D42: =SUM(D41) -> 159 | E42: =SUM(E41) -> 187 | F42: =SUM(F41) -> 174 | G42: =SUM(G41) -> 186 | H42: =SUM(H41) -> 197 | I42: =SUM(I41) -> 239 | ... AF42: =SUM(AF41) -> 141 | AG42: =sum(B42:AF42) -> 5884
A44: Breakdown
A45: - Hardware | B45: =Summary!B9 -> 36339.3 | C45: =Summary!C9 -> 35421 | D45: =Summary!D9 -> 31591.8 | E45: =Summary!E9 -> 34100.4 | F45: =Summary!F9 -> 33472.26 | G45: =Summary!G9 -> 35821.56 | H45: =Summary!H9 -> 38210.4 | I45: =Summary!I9 -> 43742.46 | ... AF45: =Summary!AF9 -> 29808.2 | AG45: =SUM(B45:AF45) -> 1137529.8
A46: - Add-ons | B46: =Summary!B10 -> 3989.9 | C46: =Summary!C10 -> 4273 | D46: =Summary!D10 -> 2907 | E46: =Summary!E10 -> 3694 | F46: =Summary!F10 -> 2903.84 | G46: =Summary!G10 -> 3373.34 | H46: =Summary!H10 -> 3094 | I46: =Summary!I10 -> 4878.34 | ... AF46: =Summary!AF10 -> 2702.4 | AG46: =SUM(B46:AF46) -> 113977.12
A47: - Merch
A48: - Taxes | B48: =Summary!B11 -> 2609.23 | C48: =Summary!C11 -> 2794.44 | D48: =Summary!D11 -> 2179.75 | E48: =Summary!E11 -> 2264.52 | F48: =Summary!F11 -> 2326.88 | G48: =Summary!G11 -> 2594.15 | H48: =Summary!H11 -> 2622.65 | I48: =Summary!I11 -> 3158.98 | ... AF48: =Summary!AF11 -> 1967.39 | AG48: =SUM(B48:AF48) -> 80635.85
...

Sheet DATA - P&L
B1: Business Metrics
A2: Source | B2: COGS | E2: Attachment Rates | H2: Marketing Averages (per first-time order) | K2: Fees | N2: VAT Averages | Q2: 30 Day Returns | T2: Digital Market Places & B2B
B3: Bird Buddy | C3: 86.9 | D3: 86.9 | E3: Solar Roof | F3: =(('DTC - P&L'!AG83+'DTC - P&L'!AG84)/'DTC - P&L'!AG77) -> 0.11074516 | H3: COGS | I3: =(C3*F9)+(C4*F8)+(C5*F3)+(C6*F4)+(C7*F5)+(C8*F6)+(C9*F7)+(C10*F10) -> 99.26282 | J3: =(D3*F9)+(D4*F8)+(D5*F3)+(D6*F4)+(D7*F5)+(D8*F6)+(D9*F7) -> 99.26282 | K3: Stripe Processing Fee | L3: 0.029 | N3: Europe | O3: 0.22 | Q3: US Shipping | R3: 15 | T3: Average % tax | U3: 0.0614 | V3: Source
B4: Bird Buddy with Solar Roof | C4: 97.61 | D4: 97.61 | E4: Wall Mount | F4: =('DTC - P&L'!AG79/'DTC - P&L'!AG77) -> 0.32770688 | H4: Inbound Shipping | I4: =C38+('DTC - P&L'!AG87/'DTC - P&L'!AG77)*D38 -> 13.076362 | K4: Duty | L4: 0.034 | N4: ROW | O4: 0.13 | Q4: EU Shipping | R4: 40
B5: Solar Roof Single | C5: 13.44 | D5: 13.44 | E5: Fence Mount | F5: 0 | H5: Outbound Shipping | I5: =C34+('DTC - P&L'!AG87/'DTC - P&L'!AG77)*D34 -> 16.814081 | K5: China Tax | L5: 0.075 | N5: NA | Q5: ROW Shipping | R5: 20
B6: Wall Mount | C6: 5.49 | D6: 5.49 | E6: Suet Ball Holder | F6: =('DTC - P&L'!AG80)/'DTC - P&L'!AG77 -> 0.16694113 | H6: Taxes and VAT | I6: 16.81 | K6: HMF | L6: 0.00125 | Q6: Money Return | R6: 1
B7: Fence Mount | C7: 6.37 | E7: 3-in-1 | F7: =('DTC - P&L'!AG81+'DTC - P&L'!AG82)/'DTC - P&L'!AG77 -> 0.1864965 | H7: China Tax (7.5%) | I7: 0 | K7: MPF | L7: 0.003464
B8: Suet Ball Holder | C8: 1.19 | D8: 1.19 | E8: Bird Buddy w/ Solar | F8: =('DTC - P&L'!AG75+'DTC - P&L'!AG76)/'DTC - P&L'!AG77 -> 0.71284479 | H8: Duty (3.4%) | I8: 0 | K8: Solar Roof China Tax | L8: 0.075
B9: 3-in-1 Nutrition Set | C9: 6.66 | D9: 6.66 | E9: Bird Buddy | F9: =1-F8 -> 0.28715521 | H9: Processing Fee (2,90%) | I9: =Summary!B52*L3 -> 6.9915358 | K9: Solar Roof Duty | L9: 0.025
B10: Perch Extender | C10: 6 | E10: Perch Extender | F10: =('DTC - P&L'!AG85+'DTC - P&L'!AG86)/'DTC - P&L'!AG77 -> 0 | H10: Transaction Fee ($0.30) | I10: =0.3 -> 0.3 | K10: Chargeback Fee (Stripe) | L10: 15
B11: Avg. Merch Cost | C11: 3.94 | E11: OTHER 2 | H11: OTHER 1
B12: Avg. Merch Cost without Calendar | C12: 14.79 | E12: OTHER 3 | H12: OTHER 2 | K12: Stripe | L12: 0.95
B13: SBF Housing | E13: OTHER 4 | H13: OTHER 3 | K13: Affirm | L13: 0.05
B14: SBF Camera | E14: OTHER 5 | H14: OTHER 4 | K14: Affirm processing fee | L14: 0.0579
H15: All | I15: =SUM(I3:I14) -> 153.2548 | K15: Affirm transaction fee | L15: 0.3
B22: Outbound shipping | C22: Bird buddy | D22: Add-ons | E22: Merch
A23: *w/o CA weight | B23: Outbound (NA) | C23: 11.94 | D23: 6.155 | E23: 5.4 | H23: App Advertising
B24: Outbound (Europe) | C24: 11.94 | D24: 6.16 | H24: Meta Share to Apple Store | I24: 0.8
B25: Outbound (ROW) | C25: 11.94 | D25: 6.16 | H25: Meta Share to Google Store | I25: 0.2
A26: Source | B26: 3PL Costs | C26: 0 | D26: 0
B27: Handling Fee
B28: Serial Capture | C28: 0.1 | D28: 0
B29: Storage | C29: 0.31 | D29: 0.31
B30: Supplies cost | C30: 0 | D30: 0
B31: Pick charge | C31: 0.35 | D31: 0.35
B32: Pollybag cost | C32: 0 | D32: 0
B33: Carton cost | C33: 1.65 | D33: 0.71
B34: Total outbound (NA) | C34: =C26+C23-C27 -> 11.94 | D34: =D26+D23-D27 -> 6.155
B35: Total outbound (Europe) | C35: 15.06 | D35: =D27+D24-D28 -> 6.16
B36: Total outbound (ROW) | C36: 20
A37: Source | B37: Inbound shipping | C37: Bird buddy | D37: Add-ons
B38: Inbound (NA) | C38: 11.94 | D38: 1.435
B39: Inbound (Europe) | C39: 11.94 | D39: 1.44
B40: Inbound (ROW) | C40: 11.94 | D40: 1.44
B42: AMAZON Logistics | C42: Bird buddy | D42: Add-ons
A43: https://docs.google.com/spreadsheets/d/1Dn0q7h1bHxXdG0N9KpcqzFo0tWUWYXOrRX7yxv3G1E0/edit#gid=1264242332 | B43: Inbound | C43: 11.94 | D43: 1.435
A44: =sum(C43:C44) -> 12.18 | B44: Storage Fee | C44: 0.24 | D44: 0.24
A45: =C46 -> 12.94 | B45: AMAZON Fees | C45: Bird buddy
A46: =sum(F43:F45) -> 0 | B46: FBA fee for units | C46: 12.94
B47: FBA fee for addons | C47: 5.7
...

Sheet OLD Sales
A1: 45108 | B1: 45108 | C1: 45109 | D1: 45110 | E1: 45111 | F1: 45112 | G1: 45113 | H1: 45114 | I1: 45115 | J1: 45116 | K1: 45117 | L1: 45118 | M1: 45119 | N1: 45120 | O1: 45121 | P1: 45122 | Q1: 45123 | R1: 45124 | S1: 45125 | T1: 45126 | U1: 45127 | V1: 45128 | W1: 45129 | X1: 45130 | Y1: 45131 | Z1: 45132 | AA1: 45133 | AB1: 45134 | AC1: 45135 | AD1: 45136 | AE1: 45137 | AF1: 45138
B2: SAT | C2: SUN | D2: MON | E2: TUE | F2: WED | G2: THU | H2: FRI | I2: SAT | J2: SUN | K2: MON | L2: TUE | M2: WED | N2: THU | O2: FRI | P2: SAT | Q2: SUN | R2: MON | S2: TUE | T2: WED | U2: THU | V2: FRI | W2: SAT | X2: SUN | Y2: MON | Z2: TUE | AA2: WED | AB2: THU | AC2: FRI | AD2: SAT | AE2: SUN | AF2: MON
A3: Weekend Work | B3: Peter | C3: Peter | I3: Peter | J3: Peter | P3: Peco | Q3: Peco | W3: Peco | X3: Peco | AD3: Peter | AE3: Peter
B4: Summer Sale | Z4: Friendship Day
G5: Check comments in this cell | H5: Check comments in this cell | K5: Switch to BB yellow AND blue 10% off | N5: Communication changed from next day shipping to now shipping | R5: Website caching problem / Site down for 8 hours | V5: SBF (Blue) - out of stock | Y5: One page checkout live from 3pm | Z5: Friendship Day starts at 18:00 CET | AC5: SBF (Blue) Back in stock
N6: In-Stock Sale Email | O6: In-Stock Sale Push Notification | R6: In-Stock Sale Follow-up Email | AA6: Switching FB strategy to separate MOF & BOF
A8: WordPress | B8: 49127.2 | C8: 44359.94 | D8: 41176.95 | E8: 43682.34 | F8: 40447.23 | G8: 43380.21 | H8: 47720.49 | I8: 53389.16 | J8: 55427.36 | K8: 45887.67 | L8: 51043.74 | M8: 51340.77 | N8: 80153.53 | O8: 68572.56 | P8: 60624.25 | Q8: 59856.53 | R8: 32044.25 | S8: 60316.3 | T8: 43139.27 | U8: 47288.79 | V8: 48826.1 | W8: 41957.56 | X8: 40174.12 | Y8: 31487.95 | Z8: 36143.33 | AA8: 30366.88 | AB8: 34701.54 | AC8: 30849.69 | AD8: 32381.7 | AE8: 31165.57 | AF8: 34474.77
A9: - Hardware | B9: 38838.3 | C9: 35153 | D9: 33448.8 | E9: 34820.96 | F9: 33275.8 | G9: 35142.66 | H9: 39129.4 | I9: 42610.16 | J9: 43820 | K9: 36440.66 | L9: 41884.4 | M9: 42312.66 | N9: 64361.4 | O9: 55693.9 | P9: 47887.4 | Q9: 48508.86 | R9: 25786.1 | S9: 48734.4 | T9: 35136.7 | U9: 37751.3 | V9: 39691.9 | W9: 33371.7 | X9: 31170.36 | Y9: 25637.3 | Z9: 29158.29 | AA9: 24819.62 | AB9: 29034.5 | AC9: 25107.36 | AD9: 25791.26 | AE9: 24811.43 | AF9: 28199.2
A10: - Add-ons | B10: 4520.9 | C10: 3973 | D10: 3041 | E10: 3854.34 | F10: 2602.5 | G10: 3407.34 | H10: 3307 | I10: 4744.34 | J10: 5288.2 | K10: 4194.34 | L10: 3421 | M10: 3348.34 | N10: 6765 | O10: 4947.7 | P10: 5754.5 | Q10: 4532.34 | R10: 2548.5 | S10: 4762 | T10: 3096.5 | U10: 4190 | V10: 3601 | W10: 3856.5 | X10: 4290.84 | Y10: 2311 | Z10: 3009.51 | AA10: 2200.18 | AB10: 1970.5 | AC10: 2210.84 | AD10: 2940.34 | AE10: 2794.17 | AF10: 2493.4
A11: - Merch | B11: 0 | C11: 0 | D11: 0 | E11: 0 | F11: 0 | G11: 0 | H11: 0 | I11: 0 | J11: 0 | K11: 0 | L11: 0 | M11: 0 | N11: 0 | O11: 0 | P11: 0 | Q11: 0 | R11: 0 | S11: 0 | T11: 0 | U11: 0 | V11: 0 | W11: 0 | X11: 0 | Y11: 0 | Z11: 0 | AA11: 0 | AB11: 0 | AC11: 0 | AD11: 0 | AE11: 0 | AF11: 0
A12: - Taxes | B12: 2823 | C12: 2733.94 | D12: 2277.15 | E12: 2382.04 | F12: 2343.93 | G12: 2470.21 | H12: 2749.09 | I12: 2999.66 | J12: 3139.16 | K12: 2572.67 | L12: 3033.34 | M12: 2959.77 | N12: 4577.13 | O12: 4045.96 | P12: 3397.35 | Q12: 3395.33 | R12: 1884.65 | S12: 3534.9 | T12: 2551.07 | U12: 2717.49 | V12: 2883.2 | W12: 2349.36 | X12: 2317.92 | Y12: 1784.65 | Z12: 2015.53 | AA12: 1682.08 | AB12: 1861.54 | AC12: 1651.49 | AD12: 1830.1 | AE12: 1799.97 | AF12: 1872.17
A13: - Shipping | B13: 2945 | C13: 2500 | D13: 2410 | E13: 2625 | F13: 2225 | G13: 2360 | H13: 2535 | I13: 3035 | J13: 3180 | K13: 2680 | L13: 2705 | M13: 2720 | N13: 4450 | O13: 3885 | P13: 3585 | Q13: 3420 | R13: 1825 | S13: 3285 | T13: 2355 | U13: 2630 | V13: 2650 | W13: 2380 | X13: 2395 | Y13: 1755 | Z13: 1960 | AA13: 1665 | AB13: 1835 | AC13: 1880 | AD13: 1820 | AE13: 1760 | AF13: 1910
A14: Total Revenue | B14: =SUM(B9:B13) -> 49127.2 | C14: =SUM(C9:C13) -> 44359.94 | D14: =SUM(D9:D13) -> 41176.95 | E14: =SUM(E9:E13) -> 43682.34 | F14: =SUM(F9:F13) -> 40447.23 | G14: =SUM(G9:G13) -> 43380.21 | H14: =SUM(H9:H13) -> 47720.49 | I14: =SUM(I9:I13) -> 53389.16 | ... AF14: =SUM(AF9:AF13) -> 34474.77
A15: Orders | B15: 173 | C15: 181 | D15: 159 | E15: 184 | F15: 171 | G15: 187 | H15: 193 | I15: 236 | J15: 216 | K15: 214 | L15: 204 | M15: 198 | N15: 326 | O15: 288 | P15: 252 | Q15: 249 | R15: 147 | S15: 234 | T15: 172 | U15: 198 | V15: 188 | W15: 187 | X15: 171 | Y15: 126 | Z15: 129 | AA15: 114 | AB15: 128 | AC15: 130 | AD15: 126 | AE15: 128 | AF15: 131
A16: - Hardware (units sold) | B16: 161 | C16: 142 | D16: 139 | E16: 147 | F16: 144 | G16: 153 | H16: 167 | I16: 179 | J16: 186 | K16: 162 | L16: 186 | M16: 182 | N16: 289 | O16: 248 | P16: 213 | Q16: 216 | R16: 112 | S16: 206 | T16: 151 | U16: 159 | V16: 164 | W16: 130 | X16: 124 | Y16: 98 | Z16: 118 | AA16: 98 | AB16: 114 | AC16: 103 | AD16: 103 | AE16: 96 | AF16: 113
A17: - Add-ons (units sold) | B17: 146 | C17: 132 | D17: 97 | E17: 127 | F17: 89 | G17: 108 | H17: 106 | I17: 159 | J17: 163 | K17: 134 | L17: 116 | M17: 112 | N17: 217 | O17: 172 | P17: 201 | Q17: 165 | R17: 88 | S17: 159 | T17: 105 | U17: 138 | V17: 128 | W17: 133 | X17: 139 | Y17: 87 | Z17: 96 | AA17: 80 | AB17: 74 | AC17: 73 | AD17: 93 | AE17: 91 | AF17: 85
A18: - Merch (units sold) | B18: 0 | C18: 0 | D18: 0 | E18: 0 | F18: 0 | G18: 0 | H18: 0 | I18: 0 | J18: 0 | K18: 0 | L18: 0 | M18: 0 | N18: 0 | O18: 0 | P18: 0 | Q18: 0 | R18: 0 | S18: 0 | T18: 0 | U18: 0 | V18: 0 | W18: 0 | X18: 0 | Y18: 0 | Z18: 0 | AA18: 0 | AB18: 0 | AC18: 0 | AD18: 0 | AE18: 0 | AF18: 0
A19: =sum(14:14) -> 1411507.8
A20: FB - US & CA | B20: 7590.32 | C20: 9939.48 | D20: 11857.85 | E20: 13975.77 | F20: 13627.08 | G20: 13435.73 | H20: 13643.57 | I20: 14020.82 | J20: 16923.12 | K20: 16638.37 | L20: 14685.47 | M20: 9643.71 | N20: 9544.29 | O20: 13137.58 | P20: 17548.71 | Q20: 20371.34 | R20: 14875.41 | S20: 14651 | T20: 15983.11 | U20: 16495.31 | V20: 16540.43 | W20: 16840.85 | X20: 17566.45 | Y20: 11293.8 | Z20: 9326.51 | AA20: 9853.2 | AB20: 7316.48 | AC20: 6685.51 | AD20: 6692.13 | AE20: 7810.96 | AF20: 7705.29
A21: Google - WW | B21: 3493.03 | C21: 3318.69 | D21: 3105.04 | E21: 3164.26 | F21: 2740.55 | G21: 3020.34 | H21: 3129.51 | I21: 3393.25 | J21: 3789.9 | K21: 3108.44 | L21: 3475.99 | M21: 3368.31 | N21: 3891.75 | O21: 4289.75 | P21: 4978.18 | Q21: 5350.38 | R21: 4262.94 | S21: 5867.41 | T21: 3955.4 | U21: 3443.43 | V21: 4404.04 | W21: 6179.63 | X21: 7876.81 | Y21: 6931.42 | Z21: 6903.19 | AA21: 5631.54 | AB21: 6483.21 | AC21: 6665.27 | AD21: 5627.76 | AE21: 3929.84 | AF21: 2235.27
A22: Bing - WW | B22: 244.51 | C22: 259.8 | D22: 259.73 | E22: 251.56 | F22: 260.93 | G22: 252.96 | H22: 250.94 | I22: 249.85 | J22: 248.72 | K22: 245.95 | L22: 250.54 | M22: 247.66 | N22: 82.36 | O22: 0 | P22: 0 | Q22: 0 | R22: 0 | S22: 0 | T22: 130.29 | U22: 247.33 | V22: 241.87 | W22: 267.6 | X22: 243.5 | Y22: 239.41 | Z22: 253.25 | AA22: 274.45 | AB22: 262.48 | AC22: 301.09 | AD22: 283.72 | AE22: 289.28 | AF22: 296.9
A23: TikTok - US & CA | B23: 0 | C23: 0 | D23: 0 | E23: 0 | F23: 0 | G23: 0 | H23: 0 | I23: 0 | J23: 0 | K23: 0 | L23: 0 | M23: 0 | N23: 0 | O23: 0 | P23: 0 | Q23: 0 | R23: 0 | S23: 0 | T23: 0 | U23: 0 | V23: 0 | W23: 0 | X23: 0 | Y23: 0 | Z23: 0 | AA23: 0 | AB23: 0 | AC23: 0 | AD23: 0 | AE23: 0
A24: MNTN TV
A25: Affiliate Fees - US | B25: 0 | C25: 0 | D25: 0 | E25: 0 | F25: 0 | G25: 0 | H25: 0 | I25: 0 | J25: 0 | K25: 0 | L25: 0 | M25: 0 | N25: 0 | O25: 0 | P25: 0 | Q25: 0 | R25: 0 | S25: 156.16 | T25: 131.12 | U25: 215.27 | V25: 264.81 | W25: 122.94 | X25: 187.67 | Y25: 229.7 | Z25: 157.02 | AA25: 108.61 | AB25: 196.05 | AC25: 49.05 | AD25: 0 | AE25: 136.42 | AF25: 0
A26: Total Spend | B26: =SUM(B20:B25) -> 11327.86 | C26: =SUM(C20:C25) -> 13517.97 | D26: =SUM(D20:D25) -> 15222.62 | E26: =SUM(E20:E25) -> 17391.59 | F26: =SUM(F20:F25) -> 16628.56 | G26: =SUM(G20:G25) -> 16709.03 | H26: =SUM(H20:H25) -> 17024.02 | I26: =SUM(I20:I25) -> 17663.92 | ... AF26: =SUM(AF20:AF25) -> 10237.46
A27: =sum(26:26) -> 542625.68
A28: ROAS | B28: =B14/B26 -> 4.3368474 | C28: =C14/C26 -> 3.2815534 | D28: =D14/D26 -> 2.7049844 | E28: =E14/E26 -> 2.5116933 | F28: =F14/F26 -> 2.4323952 | G28: =G14/G26 -> 2.5962135 | H28: =H14/H26 -> 2.803127 | I28: =I14/I26 -> 3.0224978 | ... AF28: =AF14/AF26 -> 3.3675121
A29: CAC | B29: =B26/B15 -> 65.47896 | C29: =C26/C15 -> 74.684917 | D29: =D26/D15 -> 95.739748 | E29: =E26/E15 -> 94.519511 | F29: =F26/F15 -> 97.243041 | G29: =G26/G15 -> 89.353102 | H29: =H26/H15 -> 88.207358 | I29: =I26/I15 -> 74.847119 | ... AF29: =AF26/AF15 -> 78.14855
A30: CR | B30: 0.0145 | C30: 0.0134 | D30: 0.0122 | E30: 0.0141 | F30: 0.0138 | G30: 0.0142 | H30: 0.0145 | I30: 0.018 | J30: 0.0145 | K30: 0.0152 | L30: 0.0167 | M30: 0.0175 | N30: 0.0229 | O30: 0.0149 | P30: 0.0227 | Q30: 0.0159 | R30: 0.0124 | S30: 0.0213 | T30: 0.0175 | U30: 0.022 | V30: 0.0153 | W30: 0.0155 | X30: 0.0139 | Y30: 0.0125 | Z30: 0.0138 | AA30: 0.0115 | AB30: 0.0139 | AC30: 0.0154 | AD30: 0.0159 | AE30: 0.0143 | AF30: 0.017
A31: AOV | B31: =B14/B15 -> 283.97225 | C31: =C14/C15 -> 245.08254 | D31: =D14/D15 -> 258.97453 | E31: =E14/E15 -> 237.40402 | F31: =F14/F15 -> 236.53351 | G31: =G14/G15 -> 231.97973 | H31: =H14/H15 -> 247.25642 | I31: =I14/I15 -> 226.22525 | ... AF31: =AF14/AF15 -> 263.16618
A32: fAOV | B32: 230 | C32: 250 | D32: 246.65 | E32: 202.04 | F32: 207.45 | G32: 209.04 | H32: 238 | I32: 232 | J32: 209.7 | K32: 204.43 | L32: 210.2 | M32: 219.24 | N32: 210.16 | O32: 211.85 | P32: 211.62 | Q32: 212.28 | R32: 199.44 | S32: 218.72 | T32: 223.74 | U32: 219.67 | V32: 211.86 | W32: 209.25 | X32: 204.42 | Y32: 235.35 | Z32: 223.39 | AA32: 239.8 | AB32: 244.19 | AC32: 247 | AD32: 251 | AE32: 220.65 | AF32: 238.88
A33: rAOV | B33: 218 | C33: 242 | D33: 182.5 | E33: 208.07 | F33: 226.03 | G33: 236.7 | H33: 222 | I33: 199 | J33: 124.55 | K33: 111.81 | L33: 116.24 | M33: 203.05 | N33: 159.26 | O33: 203.1 | P33: 138.28 | Q33: 146.12 | R33: 82.14 | S33: 226.82 | T33: 50.38 | U33: 221.05 | V33: 116.11 | W33: 163.28 | X33: 142.14 | Y33: 83.5 | Z33: 246 | AA33: 65 | AB33: 45.5 | AC33: 155 | AD33: 37 | AE33: 116.29 | AF33: 98.33
A35: Customers
A36: Returning | B36: 0.006 | C36: 0.0226 | D36: 0.0127 | E36: 0.0163 | F36: 0.0234 | G36: 0.0321 | H36: 0.0105 | I36: 0.0044 | J36: 0.0093 | K36: 0.0421 | L36: 0.0245 | M36: 0.0101 | N36: 0.0245 | O36: 0.0347 | P36: 0.0476 | Q36: 0.0522 | R36: 0.0544 | S36: 0.0427 | T36: 0.0465 | U36: 0.0303 | V36: 0.0532 | W36: 0.0214 | X36: 0.0409 | Y36: 0.0952 | Z36: 0.0155 | AA36: 0.0175 | AB36: 0.0156 | AC36: 0.0079 | AD36: 0.0084 | AE36: 0.0547 | AF36: 0.0458
A37: First-time | B37: =1-B36 -> 0.994 | C37: =1-C36 -> 0.9774 | D37: =1-D36 -> 0.9873 | E37: =1-E36 -> 0.9837 | F37: =1-F36 -> 0.9766 | G37: =1-G36 -> 0.9679 | H37: =1-H36 -> 0.9895 | I37: =1-I36 -> 0.9956 | ... AF37: =1-AF36 -> 0.9542
A40: Post-purchase Survey
A41: Facebook / Instagram | B41: / | C41: / | D41: / | E41: / | F41: / | G41: / | H41: / | I41: / | J41: / | K41: / | L41: / | M41: / | N41: 0.4214 | O41: 0 | P41: 0 | Q41: 0 | R41: 0 | S41: 0 | T41: 0 | U41: ='OLD Formulas'!N16 -> 0.32 | V41: ='OLD Formulas'!O16 -> 0.39285714 | W41: ='OLD Formulas'!P16 -> 0.42741935 | X41: ='OLD Formulas'!Q16 -> 0.42741935 | Y41: ='OLD Formulas'!R16 -> 0.4109589 | Z41: ='OLD Formulas'!S16 -> 0.29032258 | AA41: ='OLD Formulas'!T16 -> 0.37142857 | AB41: ='OLD Formulas'!U16 -> 0.31506849 | ... AF41: ='OLD Formulas'!Y16 -> 0.31111111
A42: Friends / Family | B42: / | C42: / | D42: / | E42: / | F42: / | G42: / | H42: / | I42: / | J42: / | K42: / | L42: / | M42: / | N42: 0.5157 | O42: 0 | P42: 0 | Q42: 0 | R42: 0 | S42: 0 | T42: 0 | U42: ='OLD Formulas'!N17 -> 0.56 | V42: ='OLD Formulas'!O17 -> 0.51785714 | W42: ='OLD Formulas'!P17 -> 0.48387097 | X42: ='OLD Formulas'!Q17 -> 0.4516129 | Y42: ='OLD Formulas'!R17 -> 0.42465753 | Z42: ='OLD Formulas'!S17 -> 0.59139785 | AA42: ='OLD Formulas'!T17 -> 0.48571429 | AB42: ='OLD Formulas'!U17 -> 0.53424658 | ... AF42: ='OLD Formulas'!Y17 -> 0.58888889
A43: TikTok | B43: / | C43: / | D43: / | E43: / | F43: / | G43: / | H43: / | I43: / | J43: / | K43: / | L43: / | M43: / | N43: 0.0126 | O43: 0 | P43: 0 | Q43: 0 | R43: 0 | S43: 0 | T43: 0 | U43: ='OLD Formulas'!N18 -> 0 | V43: ='OLD Formulas'!O18 -> 0 | W43: ='OLD Formulas'!P18 -> 0.0080645161 | X43: ='OLD Formulas'!Q18 -> 0.0080645161 | Y43: ='OLD Formulas'!R18 -> 0.02739726 | Z43: ='OLD Formulas'!S18 -> 0.032258065 | AA43: ='OLD Formulas'!T18 -> 0.042857143 | AB43: ='OLD Formulas'!U18 -> 0.04109589 | ... AF43: ='OLD Formulas'!Y18 -> 0.033333333
A44: TV / Radio | B44: / | C44: / | D44: / | E44: / | F44: / | G44: / | H44: / | I44: / | J44: / | K44: / | L44: / | M44: / | N44: 0 | O44: 0 | P44: 0 | Q44: 0 | R44: 0 | S44: 0 | T44: 0 | U44: ='OLD Formulas'!N19 -> 0.026666667 | V44: ='OLD Formulas'!O19 -> 0 | W44: ='OLD Formulas'!P19 -> 0.0080645161 | X44: ='OLD Formulas'!Q19 -> 0.016129032 | Y44: ='OLD Formulas'!R19 -> 0 | Z44: ='OLD Formulas'!S19 -> 0 | AA44: ='OLD Formulas'!T19 -> 0.014285714 | AB44: ='OLD Formulas'!U19 -> 0.01369863 | ... AF44: ='OLD Formulas'!Y19 -> 0.011111111
...

Sheet OLD Detailed Report
A1: JULY | B1: 45108 | C1: 45109 | D1: 45110 | E1: 45111 | F1: 45112 | G1: 45113 | H1: 45114 | I1: 45115 | J1: 45116 | K1: 45117 | L1: 45118 | M1: 45119 | N1: 45120 | O1: 45121 | P1: 45122 | Q1: 45123 | R1: 45124 | S1: 45125 | T1: 45126 | U1: 45127 | V1: 45128 | W1: 45129 | X1: 45130 | Y1: 45131 | Z1: 45132 | AA1: 45133 | AB1: 45134 | AC1: 45135 | AD1: 45136 | AE1: 45137 | AF1: 45138
A2: DAY | B2: SAT | C2: SUN | D2: MON | E2: TUE | F2: WED | G2: THU | H2: FRI | I2: SAT | J2: SUN | K2: MON | L2: TUE | M2: WED | N2: THU | O2: FRI | P2: SAT | Q2: SUN | R2: MON | S2: TUE | T2: WED | U2: THU | V2: FRI | W2: SAT | X2: SUN | Y2: MON | Z2: TUE | AA2: WED | AB2: THU | AC2: FRI | AD2: SAT | AE2: SUN | AF2: MON
A3: COMMENT
A4: Transactions
A5: FB (US & CA) | B5: 29 | C5: 56 | D5: 31 | E5: 59 | F5: 47 | G5: 60 | H5: 64 | I5: 89 | J5: 75 | K5: 62 | L5: 51 | M5: 42 | N5: 53 | O5: 73 | P5: 68 | Q5: 67 | R5: 28 | S5: 48 | T5: 53 | U5: 64 | V5: 60 | W5: 65 | X5: 65 | Y5: 30 | Z5: 31 | AA5: 12 | AB5: 27 | AC5: 21 | AD5: 21 | AE5: 18 | AF5: 24 | AG5: =SUM(B5:AF5) -> 1493
A6: Google | B6: 55 | C6: 62 | D6: 52 | E6: 62 | F6: 59 | G6: 59 | H6: 62 | I6: 79 | J6: 67 | K6: 80 | L6: 78 | M6: 77 | N6: 84 | O6: 63 | P6: 69 | Q6: 65 | R6: 42 | S6: 63 | T6: 66 | U6: 66 | V6: 58 | W6: 57 | X6: 65 | Y6: 45 | Z6: 40 | AA6: 49 | AB6: 46 | AC6: 53 | AD6: 39 | AE6: 51 | AF6: 36 | AG6: =SUM(B6:AF6) -> 1849
