Workbook
Name rdataslayer_d70e473bcafe40a3aa834ce157fb2ba3: 'Business Metrics Canada'!$C$16:$D$17
Name zsupermetrics_xwoIpANxRm908eDp5oKTwQpEI8gvD4: 'Business Metrics US'!$A$5
Name zsupermetrics_ru0GDtbZzDLHQOQtJJ6K08MvUDyyp7: #REF!
Name zsupermetrics_iNpyVy90bWCI0yUaFQpxOtzWMa6sW4: 'Business Metrics US'!$A$5:$A$12
Name zsupermetrics_DQl8lUbpTRu3fayaJJi7lVfOGKjNU4: 'OLD Formulas'!$A$3:$A$4
Name zsupermetrics_NugLlrQxlKiqhxQae8EFpITBm1pLCj: 'Business Metrics Canada'!$B$15:$C$23
Name rdataslayer_4a0f150f4f2f4e4f85c890c75b7a1fa4: 'Business Metrics Canada'!$D$5:$E$12
Name zsupermetrics_BioPyGBzcBsy60UCQmPcTuFReEmghI: 'OLD Formulas'!$B$2:$B$3
Name zsupermetrics_refreshAll: SupermetricsQueries!$H$5
Name zsupermetrics_DQl8lUbpTRu3fayaJJi7lVfOGKjNU4: 'Business Metrics Canada'!$A$2:$A$13
Name zsupermetrics_n3GtLgiKpTmd2pYmQNMuq6TPD0qE0b: #REF!
Name zsupermetrics_9i4W4hgd80uRpQLMeX0eRnESN8gjyv: 'Business Metrics US'!$C$23
Name zsupermetrics_qWp7V908pNEYMtfv8QZvSTeDnBAHOU: 'Business Metrics Canada'!$B$14:$C$23
Name zsupermetrics_refreshAllSilent: SupermetricsQueries!$H$6
Name zsupermetrics_Mgms9p0QzysYvrIhnsKACeVBVxfIEO: #REF!
Name rdataslayer_4a0f150f4f2f4e4f85c890c75b7a1fa4: 'Business Metrics US'!$D$5:$E$12
Name zsupermetrics_lx4cNai7gT6tH4j08ZRkI21Qlpjioi: 'Business Metrics Canada'!$B$13:$C$23
Name zsupermetrics_Mgms9p0QzysYvrIhnsKACeVBVxfIEO: 'OLD Formulas'!$A$2:$A$3
Name zsupermetrics_forceRefresh: SupermetricsQueries!$H$4
Name zsupermetrics_wbYMmT0YL9bAN0yhimW0ziPFnia9Dx: #REF!
Name zsupermetrics_iNpyVy90bWCI0yUaFQpxOtzWMa6sW4: #REF!
Name zsupermetrics_xwoIpANxRm908eDp5oKTwQpEI8gvD4: 'Business Metrics Canada'!$A$5
Name zsupermetrics_xwoIpANxRm908eDp5oKTwQpEI8gvD4: #REF!
Name rdataslayer_3753ddf3234e496aa261974a0222e193: 'Business Metrics US'!$H$5:$I$5
Name zsupermetrics_4VkB7ij7WO0JjKBEgvjB2GHjSy2Egm: 'Business Metrics Canada'!$B$13:$C$17
Name zsupermetrics_n3GtLgiKpTmd2pYmQNMuq6TPD0qE0b: 'OLD Formulas'!$B$4:$B$5
Name rdataslayer_42b112e4e4be4305bb4c1be75e2dd549: 'OLD Formulas'!$B$2:$C$3
Name zsupermetrics_wbYMmT0YL9bAN0yhimW0ziPFnia9Dx: 'Business Metrics Canada'!$A$5:$A$12
Name zsupermetrics_9i4W4hgd80uRpQLMeX0eRnESN8gjyv: #REF!
Name zsupermetrics_YsFuuYtr8vOdNXCCPiFJIO38NP4b2T: 'Business Metrics US'!$B$13:$C$23
Name zsupermetrics_5bmwtOpHUbSYmDMeuCPkrxaojTprPP: #REF!
Name rdataslayer_adf57e64065742daa5b4161161b1c3ca: 'Business Metrics Canada'!$B$13:$D$14
Name zsupermetrics_9i4W4hgd80uRpQLMeX0eRnESN8gjyv: 'Business Metrics Canada'!$C$23
Name rdataslayer_3753ddf3234e496aa261974a0222e193: 'OLD Formulas'!$H$2:$I$2
Name zsupermetrics_4VkB7ij7WO0JjKBEgvjB2GHjSy2Egm: 'Business Metrics US'!$B$13:$C$17
Name zsupermetrics_SGBxROnInO9rFyh3H7j2Lldx0Bdc5v: #REF!
Name zsupermetrics_pxuhRTEmIU93xSgKclyxajD0fCZ6rF: #REF!
Name zsupermetrics_ru0GDtbZzDLHQOQtJJ6K08MvUDyyp7: 'OLD Formulas'!$B$4:$B$5
Name zsupermetrics_qWp7V908pNEYMtfv8QZvSTeDnBAHOU: 'OLD Formulas'!$B$5:$C$13
Name zsupermetrics_wbYMmT0YL9bAN0yhimW0ziPFnia9Dx: 'Business Metrics US'!$A$5:$A$12
Name rdataslayer_4a0f150f4f2f4e4f85c890c75b7a1fa4: #REF!
Name zsupermetrics_iNpyVy90bWCI0yUaFQpxOtzWMa6sW4: 'Business Metrics Canada'!$A$5:$A$12
Name zsupermetrics_HgZqhorObHOtZHuyJjpmyYaEPoYntx: #REF!
Name zsupermetrics_YsFuuYtr8vOdNXCCPiFJIO38NP4b2T: #REF!
Name zsupermetrics_DQl8lUbpTRu3fayaJJi7lVfOGKjNU4: #REF!
Name zsupermetrics_YVuzfmsfdurz7Ldl84Rfns8oka6LsS: #REF!
Name zsupermetrics_4VkB7ij7WO0JjKBEgvjB2GHjSy2Egm: #REF!
Name zsupermetrics_9i4W4hgd80uRpQLMeX0eRnESN8gjyv: 'OLD Formulas'!$C$13
Name zsupermetrics_Mgms9p0QzysYvrIhnsKACeVBVxfIEO: 'Business Metrics US'!$A$5:$A$12
Name zsupermetrics_lx4cNai7gT6tH4j08ZRkI21Qlpjioi: #REF!
Name zsupermetrics_BioPyGBzcBsy60UCQmPcTuFReEmghI: 'Business Metrics US'!$B$5:$B$12
Name zsupermetrics_qWp7V908pNEYMtfv8QZvSTeDnBAHOU: 'Business Metrics US'!$B$14:$C$23
Name rdataslayer_adf57e64065742daa5b4161161b1c3ca: 'Business Metrics US'!$B$13:$D$14
Name rdataslayer_d70e473bcafe40a3aa834ce157fb2ba3: #REF!
Name zsupermetrics_NugLlrQxlKiqhxQae8EFpITBm1pLCj: 'OLD Formulas'!$B$6:$C$13
Name zsupermetrics_8xojRjNDjo2jWHGDWjFEhflhyIq3Hq: 'OLD Sales'!$K$8:$K$23
Name rdataslayer_42b112e4e4be4305bb4c1be75e2dd549: 'Business Metrics Canada'!$B$5:$C$12
Name rdataslayer_d70e473bcafe40a3aa834ce157fb2ba3: 'Business Metrics US'!$C$16:$D$17
Name rdataslayer_3753ddf3234e496aa261974a0222e193: #REF!
Name zsupermetrics_BioPyGBzcBsy60UCQmPcTuFReEmghI: 'Business Metrics Canada'!$B$5:$B$12

Sheet DataslayerQueries
A1: Query UUID | B1: Sheet name | C1: Range address | D1: Created | E1: Updated | F1: Last status | G1: Last refresh ID | H1: Results contain sampled data | I1: Execution time (sec) | J1: Object type | K1: Linked chart ID | L1: Data source | M1: Date range type | N1: Start date | O1: End date | P1: Compare to | Q1: Comparison value type | R1: Accounts/views | S1: Metrics | T1: Dimensions | U1: Pivot dimensions | V1: Filters | W1: Segment ID | X1: Segment dim | Y1: Sort | Z1: Max rows | AA1: Max pivot categories | AB1: Special settings | AC1: Other parameters | AD1: Result type | AE1: Language/country | AF1: Translate to | AG1: SQL | AH1: Database name | AI1: Range address (static) | AJ1: Report type | AK1: Highlight with colour | AL1: Refresh with user account | AM1: Returned data | AN1: Sort dimensions | AO1: Created by user account
A2: 42b112e4e4be4305bb4c1be75e2dd549 | B2: =IFERROR(__xludf.DUMMYFUNCTION("ARRAY_CONSTRAIN(split(CELL(""ADDRESS"",rdataslayer_42b112e4e4be4305bb4c1be75e2dd549),""!""),1,1)"),"#REF!") -> #REF! | C2: =IFERROR(__xludf.DUMMYFUNCTION("INDEX(split(CELL(""ADDRESS"",rdataslayer_42b112e4e4be4305bb4c1be75e2dd549),""!""),0,2)&"":""&address(row(rdataslayer_42b112e4e4be4305bb4c1be75e2dd549)+rows(rdataslayer_42b112e4e4be4305bb4c1be75e2dd549)-1,column(rdataslayer_42b112e4e4be4305bb4c1be75e2dd549"&")+COLUMNS(rdataslayer_42b112e4e4be4305bb4c1be75e2dd549)-1)"),"#REF!") -> #REF! | D2: 44518.613 | E2: 44520.051 | F2: There is no data for the specified input | I2: 7 | J2: TABLE | L2: facebook | M2: yesterday | R2: [{"profile_id":"","name":"si_Bird buddy Inc_US &amp; CA_BirdBuddy","id":"act_273249767551281","account_name":"","advertiser_id":""}] | S2: [{"id":"spend","name":"Total Cost"}] | T2: [{"id":"date","name":"Date"}] | U2: [] | V2: [] | W2: [] | Y2: [] | Z2: 5 | AA2: 5 | AB2: {} | AC2: {} | AL2: User_Kumalic_Benjamin | AN2: [] | AO2: benjamin@mybirdbuddy.com
A3: 4a0f150f4f2f4e4f85c890c75b7a1fa4 | B3: =IFERROR(__xludf.DUMMYFUNCTION("ARRAY_CONSTRAIN(split(CELL(""ADDRESS"",rdataslayer_4a0f150f4f2f4e4f85c890c75b7a1fa4),""!""),1,1)"),"#REF!") -> #REF! | C3: =IFERROR(__xludf.DUMMYFUNCTION("INDEX(split(CELL(""ADDRESS"",rdataslayer_4a0f150f4f2f4e4f85c890c75b7a1fa4),""!""),0,2)&"":""&address(row(rdataslayer_4a0f150f4f2f4e4f85c890c75b7a1fa4)+rows(rdataslayer_4a0f150f4f2f4e4f85c890c75b7a1fa4)-1,column(rdataslayer_4a0f150f4f2f4e4f85c890c75b7a1fa4"&")+COLUMNS(rdataslayer_4a0f150f4f2f4e4f85c890c75b7a1fa4)-1)"),"#REF!") -> #REF! | D3: 44518.615 | E3: 44520.051 | F3: There is no data for the specified input | I3: 7 | J3: TABLE | L3: facebook | M3: yesterday | R3: [{"account_name":"","advertiser_id":"","id":"act_273249767551281","profile_id":"","name":"si_Bird buddy Inc_US &amp; CA_BirdBuddy"}] | S3: [{"id":"spend","name":"Total Cost"}] | T3: [] | U3: [{"id":"date","name":"Date"}] | V3: [] | W3: [] | Y3: [] | Z3: 5 | AA3: 5 | AB3: {} | AC3: {} | AL3: User_Kumalic_Benjamin | AN3: [] | AO3: benjamin@mybirdbuddy.com
A4: adf57e64065742daa5b4161161b1c3ca | B4: =IFERROR(__xludf.DUMMYFUNCTION("ARRAY_CONSTRAIN(split(CELL(""ADDRESS"",rdataslayer_adf57e64065742daa5b4161161b1c3ca),""!""),1,1)"),"#REF!") -> #REF! | C4: =IFERROR(__xludf.DUMMYFUNCTION("INDEX(split(CELL(""ADDRESS"",rdataslayer_adf57e64065742daa5b4161161b1c3ca),""!""),0,2)&"":""&address(row(rdataslayer_adf57e64065742daa5b4161161b1c3ca)+rows(rdataslayer_adf57e64065742daa5b4161161b1c3ca)-1,column(rdataslayer_adf57e64065742daa5b4161161b1c3ca"&")+COLUMNS(rdataslayer_adf57e64065742daa5b4161161b1c3ca)-1)"),"#REF!") -> #REF! | D4: 44518.618 | E4: 44520.051 | F4: There is no data for the specified input | I4: 18 | J4: TABLE | L4: facebook | M4: yesterday | R4: [{"name":"si_Bird buddy Inc_US &amp; CA_BirdBuddy","id":"act_273249767551281","profile_id":"","account_name":"","advertiser_id":""}] | S4: [{"id":"spend","name":"Total Cost"},{"id":"cpm","name":"CPM"}] | T4: [{"id":"date","name":"Date"}] | U4: [] | V4: [] | W4: [] | Y4: [] | Z4: 5 | AA4: 5 | AB4: {} | AC4: {} | AL4: User_Kumalic_Benjamin | AN4: [] | AO4: benjamin@mybirdbuddy.com
A5: d70e473bcafe40a3aa834ce157fb2ba3 | B5: =IFERROR(__xludf.DUMMYFUNCTION("ARRAY_CONSTRAIN(split(CELL(""ADDRESS"",rdataslayer_d70e473bcafe40a3aa834ce157fb2ba3),""!""),1,1)"),"#REF!") -> #REF! | C5: =IFERROR(__xludf.DUMMYFUNCTION("INDEX(split(CELL(""ADDRESS"",rdataslayer_d70e473bcafe40a3aa834ce157fb2ba3),""!""),0,2)&"":""&address(row(rdataslayer_d70e473bcafe40a3aa834ce157fb2ba3)+rows(rdataslayer_d70e473bcafe40a3aa834ce157fb2ba3)-1,column(rdataslayer_d70e473bcafe40a3aa834ce157fb2ba3"&")+COLUMNS(rdataslayer_d70e473bcafe40a3aa834ce157fb2ba3)-1)"),"#REF!") -> #REF! | D5: 44518.619 | E5: 44520.051 | F5: There is no data for the specified input | I5: 7 | J5: TABLE | L5: facebook | M5: yesterday | R5: [{"advertiser_id":"","name":"si_Bird buddy Inc_US &amp; CA_BirdBuddy","id":"act_273249767551281","account_name":"","profile_id":""}] | S5: [{"id":"spend","name":"Total Cost"}] | T5: [{"id":"date","name":"Date"}] | U5: [] | V5: [] | W5: [] | Y5: [] | Z5: 100 | AA5: 100 | AB5: {} | AC5: {} | AL5: User_Kumalic_Benjamin | AN5: [] | AO5: benjamin@mybirdbuddy.com
A6: 3753ddf3234e496aa261974a0222e193 | B6: =IFERROR(__xludf.DUMMYFUNCTION("ARRAY_CONSTRAIN(split(CELL(""ADDRESS"",rdataslayer_3753ddf3234e496aa261974a0222e193),""!""),1,1)"),"#REF!") -> #REF! | C6: =IFERROR(__xludf.DUMMYFUNCTION("INDEX(split(CELL(""ADDRESS"",rdataslayer_3753ddf3234e496aa261974a0222e193),""!""),0,2)&"":""&address(row(rdataslayer_3753ddf3234e496aa261974a0222e193)+rows(rdataslayer_3753ddf3234e496aa261974a0222e193)-1,column(rdataslayer_3753ddf3234e496aa261974a0222e193"&")+COLUMNS(rdataslayer_3753ddf3234e496aa261974a0222e193)-1)"),"#REF!") -> #REF! | D6: 44518.621 | E6: 44520.051 | F6: There is no data for the specified input | I6: 18 | J6: TABLE | L6: facebook | M6: yesterday | R6: [{"profile_id":"","account_name":"","advertiser_id":"","name":"si_Bird buddy Inc_US &amp; CA_BirdBuddy","id":"act_273249767551281"}] | S6: [{"id":"spend","name":"Total Cost"}] | T6: [] | U6: [] | V6: [] | W6: [] | Y6: [] | Z6: 100 | AA6: 100 | AB6: {"exclude_header_row":true} | AC6: {} | AL6: User_Kumalic_Benjamin | AN6: [] | AO6: benjamin@mybirdbuddy.com

Sheet Summary
A1: 45170 | B1: 45170 | C1: 45171 | D1: 45172 | E1: 45173 | F1: 45174 | G1: 45175 | H1: 45176 | I1: 45177 | J1: 45178 | K1: 45179 | L1: 45180 | M1: 45181 | N1: 45182 | O1: 45183 | P1: 45184 | Q1: 45185 | R1: 45186 | S1: 45187 | T1: 45188 | U1: 45189 | V1: 45190 | W1: 45191 | X1: 45192 | Y1: 45193 | Z1: 45194 | AA1: 45195 | AB1: 45196 | AC1: 45197 | AD1: 45198 | AE1: 45199
B2: FRI | C2: SAT | D2: SUN | E2: MON | F2: TUE | G2: WED | H2: THU | I2: FRI | J2: SAT | K2: SUN | L2: MON | M2: TUE | N2: WED | O2: THU | P2: FRI | Q2: SAT | R2: SUN | S2: MON | T2: TUE | U2: WED | V2: THU | W2: FRI | X2: SAT | Y2: SUN | Z2: MON | AA2: TUE | AB2: WED | AC2: THU | AD2: FRI | AE2: SAT
A3: Weekend Work | C3: Peco | D3: Peco | J3: Peco | K3: Peco | Q3: Peter | R3: Peter | X3: Peter | Y3: Peter | AE3: Peco
A4: Notes | S4: PRO Subscription Launch | X4: SKU3 ABC Test - Testing availability
B5: Labor Day | N5: 10% off Sitewide | S5: Keynote
G6: IGG Launch | S6: Perch Extender Launch | AB6: Existing users email sent at 15:35
A8: DTC Revenue | B8: =sum(B9:B14) -> 16813.33 | C8: =sum(C9:C14) -> 24584.7 | D8: =sum(D9:D14) -> 29900.76 | E8: =sum(E9:E14) -> 36334.28 | F8: =sum(F9:F14) -> 33865.73 | G8: =sum(G9:G14) -> 26222.32 | H8: =sum(H9:H14) -> 19010.62 | I8: =sum(I9:I14) -> 14263.81 | ... AE8: =sum(AE9:AE14) -> 24655.64
A9: - Hardware | B9: 13722.1 | C9: 19550.7 | D9: 23435.2 | E9: 29484.65 | F9: 27664 | G9: 20990.5 | H9: 15207.5 | I9: 11768 | J9: 14587.8 | K9: 18895.35 | L9: 16210 | M9: 14428.3 | N9: 14116.6 | O9: 16589.5 | P9: 17022.8 | Q9: 15507.9 | R9: 16466.4 | S9: 19896.36 | T9: 17790.86 | U9: 15609.46 | V9: 15125.66 | W9: 14080.46 | X9: 14631.43 | Y9: 17414.66 | Z9: 17603 | AA9: 12051.38 | AB9: 21870.44 | AC9: 15951.41 | AD9: 17981.86 | AE9: 19255.96
A10: - Add-ons | B10: 1072.8 | C10: 1944.6 | D10: 2730.2 | E10: 2310.6 | F10: 2146.4 | G10: 2010 | H10: 1468.7 | I10: 941 | J10: 1121.5 | K10: 1949.4 | L10: 2023.5 | M10: 1254 | N10: 1044 | O10: 1530.2 | P10: 1517.4 | Q10: 1717.1 | R10: 1458 | S10: 22114.94 | T10: 11299.34 | U10: 5629.34 | V10: 4905.34 | W10: 3952.34 | X10: 4079.17 | Y10: 4446.34 | Z10: 3484 | AA10: 2812.7 | AB10: 3183.5 | AC10: 3209.84 | AD10: 3033.54 | AE10: 2396.19
A11: - Merch
A12: - Seeds
A13: - Taxes | B13: 868.43 | C13: 1259.4 | D13: 1585.36 | E13: 1889.03 | F13: 1815.33 | G13: 1391.82 | H13: 1024.42 | I13: 584.81 | J13: 1032.12 | K13: 1238.66 | L13: 1152.7 | M13: 933.13 | N13: 850.02 | O13: 1041.8 | P13: 1073.31 | Q13: 1026.42 | R13: 1169.32 | S13: 2713 | T13: 1702.35 | U13: 1234.72 | V13: 1184.78 | W13: 1095.42 | X13: 1040.12 | Y13: 1309.75 | Z13: 1109.86 | AA13: 881.17 | AB13: 1570.77 | AC13: 1125.82 | AD13: 1271.39 | AE13: 1353.49
A14: - Shipping | B14: 1150 | C14: 1830 | D14: 2150 | E14: 2650 | F14: 2240 | G14: 1830 | H14: 1310 | I14: 970 | J14: 965 | K14: 1485 | L14: 1360 | M14: 990 | N14: 1100 | O14: 1425 | P14: 1470 | Q14: 1265 | R14: 1215 | S14: 7925 | T14: 4445 | U14: 2485 | V14: 2110 | W14: 1895 | X14: 1900 | Y14: 2120 | Z14: 2150 | AA14: 1440 | AB14: 1785 | AC14: 1740 | AD14: 1520 | AE14: 1650
A15: Amazon Revenue | B15: =B16+B17+B18+B19+B20 -> 3281.76 | C15: =C16+C17+C18+C19+C20 -> 3000.84 | D15: =D16+D17+D18+D19+D20 -> 4785.04 | E15: =E16+E17+E18+E19+E20 -> 6287.08 | F15: =F16+F17+F18+F19+F20 -> 5999.8 | G15: =G16+G17+G18+G19+G20 -> 5360.55 | H15: =H16+H17+H18+H19+H20 -> 3848.96 | I15: =I16+I17+I18+I19+I20 -> 2985.94 | ... AE15: =AE16+AE17+AE18+AE19+AE20 -> 7779.39
A16: - Hardware | B16: 3069 | C16: 2790 | D16: 4464 | E16: 5859 | F16: 5580 | G16: 5022 | H16: 3627 | I16: 2790 | J16: 7254 | K16: 6138 | L16: 6138 | M16: 7533 | N16: 7533 | O16: 8649 | P16: 4185 | Q16: 5859 | R16: 5022 | S16: 6975 | T16: 13671 | U16: 8928 | V16: 8649 | W16: 11160 | X16: 5580 | Y16: 10881 | Z16: 8928 | AA16: 10044 | AB16: 9207 | AC16: 11439 | AD16: 10323 | AE16: 7254
A17: - Add-ons | B17: 0 | C17: 0 | D17: 0 | E17: 0 | F17: 0 | G17: 0 | H17: 0 | I17: 0 | J17: 0 | K17: 0 | L17: 0 | M17: 0 | N17: 0 | O17: 0 | P17: 0 | Q17: 0 | R17: 0 | S17: 0 | T17: 0 | U17: 0 | V17: 0 | W17: 0 | X17: 0 | Y17: 0 | Z17: 0 | AA17: 0 | AB17: 0 | AC17: 0 | AD17: 0 | AE17: 0
A18: - Tax | B18: 205.77 | C18: 210.38 | D18: 302.63 | E18: 423.13 | F18: 410.82 | G18: 328.65 | H18: 221.96 | I18: 195.94 | J18: 524.61 | K18: 451.31 | L18: 392.02 | M18: 499.26 | N18: 554.7 | O18: 583.53 | P18: 320.37 | Q18: 382.52 | R18: 342.06 | S18: 506.38 | T18: 989.01 | U18: 581.41 | V18: 602.81 | W18: 795.33 | X18: 424.74 | Y18: 795.77 | Z18: 629.32 | AA18: 699.27 | AB18: 608.52 | AC18: 823.17 | AD18: 705.3 | AE18: 520.9
A19: - Shipping | B19: 6.99 | C19: 0.29 | D19: 13.75 | E19: 0.29 | F19: 0 | G19: 0.58 | H19: 0 | I19: 0 | J19: 0.29 | K19: 0 | L19: 6.99 | M19: 6.15 | N19: 11.79 | O19: 7.28 | P19: 0 | Q19: 0 | R19: 0 | S19: 0 | T19: 0.58 | U19: 6.99 | V19: 0 | W19: 0.29 | X19: 4.48 | Y19: 0.29 | Z19: 0 | AA19: 0 | AB19: 1.45 | AC19: 7.28 | AD19: 0.58 | AE19: 0
A20: - Gift Wrap | B20: 0 | C20: 0.17 | D20: 4.66 | E20: 4.66 | F20: 8.98 | G20: 9.32 | H20: 0 | I20: 0 | J20: 0.17 | K20: 4.49 | L20: 4.49 | M20: 13.98 | N20: 13.47 | O20: 9.15 | P20: 8.98 | Q20: 0 | R20: 8.98 | S20: 0 | T20: 4.83 | U20: 4.49 | V20: 0 | W20: 4.66 | X20: 4.49 | Y20: 9.15 | Z20: 0 | AA20: 0 | AB20: 5.34 | AC20: 9.15 | AD20: 9.32 | AE20: 4.49
A21: Digital Marketplaces Revenue | B21: =SUM(B26,B22) -> 0 | C21: =SUM(C26,C22) -> 0 | D21: =SUM(D26,D22) -> 0 | E21: =SUM(E26,E22) -> 0 | F21: =SUM(F26,F22) -> 0 | G21: =SUM(G26,G22) -> 0 | H21: =SUM(H26,H22) -> 0 | I21: =SUM(I26,I22) -> 0 | ... AE21: =SUM(AE26,AE22) -> 1039
A22: Rachio | B22: =SUM(B23:B25) -> 0 | C22: =SUM(C23:C25) -> 0 | D22: =SUM(D23:D25) -> 0 | E22: =SUM(E23:E25) -> 0 | F22: =SUM(F23:F25) -> 0 | G22: =SUM(G23:G25) -> 0 | H22: =SUM(H23:H25) -> 0 | I22: =SUM(I23:I25) -> 0 | ... AB22: =SUM(AB23:AB25) -> 0 | AC22: 8188.24 | AD22: 5806.09 | AE22: 1039
A23: - Hardware
A24: - Tax
A25: - Shipping | B25: 0 | C25: 0 | D25: 0 | E25: 0 | F25: 0 | G25: 0 | H25: 0 | I25: 0 | J25: 0 | K25: 0 | L25: 0 | M25: 0 | N25: 0 | O25: 0 | P25: 0 | Q25: 0 | R25: 0 | S25: 0 | T25: 0 | U25: 0 | V25: 0 | W25: 0 | X25: 0 | Y25: 0 | Z25: 0 | AA25: 0 | AB25: 0 | AC25: 0 | AD25: 0 | AE25: 0
A26: Weatherflow | B26: =SUM(B27:B29) -> 0 | C26: =SUM(C27:C29) -> 0 | D26: =SUM(D27:D29) -> 0 | E26: =SUM(E27:E29) -> 0 | F26: =SUM(F27:F29) -> 0 | G26: =SUM(G27:G29) -> 0 | H26: =SUM(H27:H29) -> 0 | I26: =SUM(I27:I29) -> 0 | ... AE26: =SUM(AE27:AE29) -> 0
A27: - Hardware | B27: 0 | C27: 0 | D27: 0 | E27: 0 | F27: 0 | G27: 0 | H27: 0 | I27: 0 | J27: 0 | K27: 0 | L27: 0 | M27: 0 | N27: 0 | O27: 0 | P27: 0 | Q27: 0 | R27: 0 | S27: 0 | T27: 0 | U27: 0 | V27: 0 | W27: 0 | X27: 0 | Y27: 0 | Z27: 0 | AA27: 0 | AB27: 0 | AC27: 0 | AD27: 0 | AE27: 0
A28: - Tax
A29: - Shipping
A30: IndieGoGo | B30: 0 | C30: 0 | D30: 0 | E30: 0 | F30: 0 | G30: 1402 | H30: 1770 | I30: 4010 | J30: 4732 | K30: 3202 | L30: 5231 | M30: 5261 | N30: 2388 | O30: 2038 | P30: 2542 | Q30: 5190 | R30: 1034 | S30: 1367 | T30: 2658 | U30: 1459 | V30: 418 | W30: 0 | X30: 298 | Y30: 298 | Z30: 0 | AA30: 298 | AB30: 992 | AC30: 0 | AD30: 324 | AE30: 1034
A31: - Hardware | B31: 0 | C31: 0 | D31: 0 | E31: 0 | F31: 0 | G31: 770 | H31: 1267 | I31: 3815 | J31: 3721 | K31: 2718 | L31: 4687 | M31: 4529 | N31: 2268 | O31: 1933 | P31: 2039 | Q31: 4965 | R31: 974 | S31: 1317 | T31: 1856 | U31: 1389 | V31: 403 | W31: 0 | X31: 283 | Y31: 283 | Z31: 0 | AA31: 283 | AB31: 967 | AC31: 0 | AD31: 309 | AE31: 974
A32: - Add-ons | B32: 0 | C32: 0 | D32: 0 | E32: 0 | F32: 0 | G32: 567 | H32: 408 | I32: 0 | J32: 786 | K32: 299 | L32: 299 | M32: 487 | N32: 0 | O32: 0 | P32: 378 | Q32: 0 | R32: 0 | S32: 0 | T32: 677 | U32: 0 | V32: 0 | W32: 0 | X32: 0 | Y32: 0 | Z32: 0 | AA32: 0 | AB32: 0 | AC32: 0 | AD32: 0 | AE32: 0
A33: - Taxes | B33: 0 | C33: 0 | D33: 0 | E33: 0 | F33: 0 | G33: 0 | H33: 0 | I33: 0 | J33: 0 | K33: 0 | L33: 0 | M33: 0 | N33: 0 | O33: 0 | P33: 0 | Q33: 0 | R33: 0 | S33: 0 | T33: 0 | U33: 0 | V33: 0 | W33: 0 | X33: 0 | Y33: 0 | Z33: 0 | AA33: 0 | AB33: 0 | AC33: 0 | AD33: 0 | AE33: 0
A34: - Shipping | B34: 0 | C34: 0 | D34: 0 | E34: 0 | F34: 0 | G34: 65 | H34: 95 | I34: 195 | J34: 225 | K34: 185 | L34: 245 | M34: 245 | N34: 120 | O34: 105 | P34: 125 | Q34: 225 | R34: 60 | S34: 50 | T34: 125 | U34: 70 | V34: 15 | W34: 0 | X34: 15 | Y34: 15 | Z34: 0 | AA34: 15 | AB34: 25 | AC34: 0 | AD34: 15 | AE34: 60
A35: Total Revenue | B35: =SUM(B8+B15+B21+B30) -> 20095.09 | C35: =SUM(C8+C15+C21+C30) -> 27585.54 | D35: =SUM(D8+D15+D21+D30) -> 34685.8 | E35: =SUM(E8+E15+E21+E30) -> 42621.36 | F35: =SUM(F8+F15+F21+F30) -> 39865.53 | G35: =SUM(G8+G15+G21+G30) -> 32984.87 | H35: =SUM(H8+H15+H21+H30) -> 24629.58 | I35: =SUM(I8+I15+I21+I30) -> 21259.75 | ... AE35: =SUM(AE8+AE15+AE21+AE30) -> 34508.03
A37: App Revenue
A38: - Google Store | B38: ='App - P&L'!B90 -> 0 | C38: ='App - P&L'!C90 -> 0 | D38: ='App - P&L'!D90 -> 0 | E38: ='App - P&L'!E90 -> 0 | F38: ='App - P&L'!F90 -> 0 | G38: ='App - P&L'!G90 -> 2.3605 | H38: ='App - P&L'!H90 -> 2.352 | I38: ='App - P&L'!I90 -> 0 | ... AE38: ='App - P&L'!AE90 -> 2312.095
A39: - Apple Store | B39: ='App - P&L'!B91 -> 0 | C39: ='App - P&L'!C91 -> 0 | D39: ='App - P&L'!D91 -> 0 | E39: ='App - P&L'!E91 -> 0 | F39: ='App - P&L'!F91 -> 0 | G39: ='App - P&L'!G91 -> 0 | H39: ='App - P&L'!H91 -> 0 | I39: ='App - P&L'!I91 -> 0 | ... AE39: ='App - P&L'!AE91 -> 3232.2861
A40: - Comission | B40: ='App - P&L'!B67 -> 0 | C40: ='App - P&L'!C67 -> 0 | D40: ='App - P&L'!D67 -> 0 | E40: ='App - P&L'!E67 -> 0 | F40: ='App - P&L'!F67 -> 0 | G40: ='App - P&L'!G67 -> 0.5295 | H40: ='App - P&L'!H67 -> 0.528 | I40: ='App - P&L'!I67 -> 0 | ... AE40: ='App - P&L'!AE67 -> 1871.4476
A41: - Tax | B41: ='App - P&L'!B68 -> 0 | C41: ='App - P&L'!C68 -> 0 | D41: ='App - P&L'!D68 -> 0 | E41: ='App - P&L'!E68 -> 0 | F41: ='App - P&L'!F68 -> 0 | G41: ='App - P&L'!G68 -> 0.64 | H41: ='App - P&L'!H68 -> 0.64 | I41: ='App - P&L'!I68 -> 0 | ... AE41: ='App - P&L'!AE68 -> 253.18
A42: Total Revenue | B42: =sum(B38:B41) -> 0 | C42: =sum(C38:C41) -> 0 | D42: =sum(D38:D41) -> 0 | E42: =sum(E38:E41) -> 0 | F42: =sum(F38:F41) -> 0 | G42: =sum(G38:G41) -> 3.53 | H42: =sum(H38:H41) -> 3.52 | I42: =sum(I38:I41) -> 0 | ... AE42: =sum(AE38:AE41) -> 7669.0088
...

Sheet DTC - P&L
A1: SEPTEMBER | B1: 45170 | C1: 45171 | D1: 45172 | E1: 45173 | F1: 45174 | G1: 45175 | H1: 45176 | I1: 45177 | J1: 45178 | K1: 45179 | L1: 45180 | M1: 45181 | N1: 45182 | O1: 45183 | P1: 45184 | Q1: 45185 | R1: 45186 | S1: 45187 | T1: 45188 | U1: 45189 | V1: 45190 | W1: 45191 | X1: 45192 | Y1: 45193 | Z1: 45194 | AA1: 45195 | AB1: 45196 | AC1: 45197 | AD1: 45198 | AE1: 45199
A2: DAY | B2: FRI | C2: SAT | D2: SUN | E2: MON | F2: TUE | G2: WED | H2: THU | I2: FRI | J2: SAT | K2: SUN | L2: MON | M2: TUE | N2: WED | O2: THU | P2: FRI | Q2: SAT | R2: SUN | S2: MON | T2: TUE | U2: WED | V2: THU | W2: FRI | X2: SAT | Y2: SUN | Z2: MON | AA2: TUE | AB2: WED | AC2: THU | AD2: FRI | AE2: SAT
A3: COMMENT
A4: Orders
A5: Meta | B5: 30 | C5: 37 | D5: 55 | E5: 64 | F5: 74 | G5: 60 | H5: 30 | I5: 25 | J5: 37 | K5: 46 | L5: 65 | M5: 47 | N5: 34 | O5: 38 | P5: 56 | Q5: 49 | R5: 34 | S5: 151 | T5: 103 | U5: 73 | V5: 46 | W5: 34 | X5: 38 | Y5: 43 | Z5: 33 | AA5: 27 | AB5: 28 | AC5: 29 | AD5: 31 | AE5: 36 | AF5: =SUM(B5:AE5) -> 1453
A6: Google | B6: 33 | C6: 43 | D6: 59 | E6: 58 | F6: 53 | G6: 46 | H6: 22 | I6: 22 | J6: 38 | K6: 40 | L6: 26 | M6: 34 | N6: 24 | O6: 28 | P6: 35 | Q6: 33 | R6: 38 | S6: 88 | T6: 73 | U6: 43 | V6: 41 | W6: 42 | X6: 47 | Y6: 38 | Z6: 33 | AA6: 33 | AB6: 32 | AC6: 33 | AD6: 32 | AE6: 45 | AF6: =SUM(B6:AE6) -> 1212
A7: TikTok | B7: 0 | C7: 0 | D7: 0 | E7: 0 | F7: 0 | G7: 0 | H7: 0 | I7: 0 | J7: 0 | K7: 0 | L7: 0 | M7: 0 | N7: 0 | O7: 0 | P7: 0 | Q7: 0 | R7: 0 | S7: 0 | T7: 0 | U7: 0 | V7: 0 | W7: 0 | X7: 0 | Y7: 0 | Z7: 0 | AA7: 0 | AB7: 0 | AC7: 0 | AD7: 0 | AE7: 0 | AF7: 0
A8: Bing | B8: 0 | C8: 2 | D8: 0 | E8: 0 | F8: 0 | G8: 0 | H8: 0 | I8: 0 | J8: 0 | K8: 0 | L8: 0 | M8: 0 | N8: 0 | O8: 0 | P8: 0 | Q8: 0 | R8: 0 | S8: 0 | T8: 0 | U8: 0 | V8: 0 | W8: 0 | X8: 0 | Y8: 22 | Z8: 6 | AA8: 2 | AB8: 0 | AC8: 4 | AD8: 4 | AE8: 6 | AF8: =SUM(B8:AE8) -> 46
A9: Nextdoor | B9: 0 | C9: 0 | D9: 0 | E9: 0 | F9: 0 | G9: 0 | H9: 0 | I9: 0 | J9: 0 | K9: 0 | L9: 0 | M9: 0 | N9: 0 | O9: 0 | P9: 0 | Q9: 0 | R9: 0 | S9: 0 | T9: 0 | U9: 0 | V9: 0 | W9: 0 | X9: 0 | Y9: 0 | Z9: 0 | AA9: 0 | AB9: 0 | AC9: 0 | AD9: 0 | AE9: 0 | AF9: 0
A10: Affiliates (Refersion) | B10: 0 | C10: 0 | D10: 0 | E10: 1 | F10: 2 | G10: 1 | H10: 0 | I10: 0 | J10: 0 | K10: 2 | L10: 0 | M10: 0 | N10: 0 | O10: 2 | P10: 1 | Q10: 2 | R10: 1 | S10: 1 | T10: 1 | U10: 1 | V10: 0 | W10: 1 | X10: 0 | Y10: 1 | Z10: 0 | AA10: 0 | AB10: 0 | AC10: 0 | AD10: 0 | AE10: 0 | AF10: 17
A11: Email | B11: 1 | C11: 1 | D11: 1 | E11: 2 | F11: 2 | G11: 1 | H11: 0 | I11: 2 | J11: 0 | K11: 1 | L11: 2 | M11: 0 | N11: 0 | O11: 1 | P11: 1 | Q11: 0 | R11: 1 | S11: 289 | T11: 87 | U11: 26 | V11: 25 | W11: 21 | X11: 19 | Y11: 13 | Z11: 8 | AA11: 7 | AB11: 30 | AC11: 17 | AD11: 10 | AE11: 4 | AF11: =SUM(B11:AE11) -> 572
A12: All | B12: =SUM(B5:B11) -> 64 | C12: =SUM(C5:C11) -> 83 | D12: =SUM(D5:D11) -> 115 | E12: =SUM(E5:E11) -> 125 | F12: =SUM(F5:F11) -> 131 | G12: =SUM(G5:G11) -> 108 | H12: =SUM(H5:H11) -> 52 | I12: =SUM(I5:I11) -> 49 | ... AE12: =SUM(AE5:AE11) -> 91 | AF12: =SUM(B12:AE12) -> 3300
A14: Revenue | B14: 6093.17 | C14: 7548.12 | D14: 12070.55 | E14: 14020.42 | F14: 15836.42 | G14: 10672.44 | H14: 6908.16 | I14: 6192.65 | J14: 8844.93 | K14: 12091.33 | L14: 16674.1 | M14: 13103.66 | N14: 9013.67 | O14: 8206.73 | P14: 13576.03 | Q14: 11601.77 | R14: 8073.45 | S14: 15805.2 | T14: 12819.7 | U14: 11558.54 | V14: 7521.11 | W14: 6317.87 | X14: 8096.65 | Y14: 9209.38 | Z14: 7333.24 | AA14: 5704 | AB14: 5914.6 | AC14: 6436.66 | AD14: 7919.38 | AE14: 9068.7
A15: Meta | B15: =B14*Summary!B63 -> 6573.3118 | C15: =C14*Summary!C63 -> 8142.9119 | D15: =D14*Summary!D63 -> 13003.604 | E15: =E14*Summary!E63 -> 15135.043 | F15: =F14*Summary!F63 -> 16986.144 | G15: =G14*Summary!G63 -> 11448.326 | H15: =H14*Summary!H63 -> 7391.7312 | I15: =I14*Summary!I63 -> 6630.4704 | ... AE15: =AE14*Summary!AE63 -> 9594.6846 | AF15: =SUM(B15:AE15) -> 307799.04
A16: Google | B16: 5686.76 | C16: 7591.09 | D16: 10836.18 | E16: 10459.89 | F16: 11145.3 | G16: 8833.63 | H16: 4455.65 | I16: 4929.52 | J16: 8377.98 | K16: 8034.35 | L16: 4735.4 | M16: 8170.46 | N16: 4528.93 | O16: 5890.99 | P16: 5996.7 | Q16: 6054.73 | R16: 7230.17 | S16: 11758.69 | T16: 11983.88 | U16: 7147.16 | V16: 7394.44 | W16: 6893.83 | X16: 9346.26 | Y16: 8085.14 | Z16: 6676.5 | AA16: 6657.14 | AB16: 6547.23 | AC16: 6488.04 | AD16: 6111.93 | AE16: 11198.87 | AF16: =SUM(B16:AE16) -> 229246.84
A17: TikTok | B17: 0 | C17: 0 | D17: 0 | E17: 0 | F17: 0 | G17: 0 | H17: 0 | I17: 0 | J17: 0 | K17: 0 | L17: 0 | M17: 0 | N17: 0 | O17: 0 | P17: 0 | Q17: 0 | R17: 0 | S17: 0 | T17: 0 | U17: 0 | V17: 0 | W17: 0 | X17: 0 | Y17: 0 | Z17: 0 | AA17: 0 | AB17: 0 | AC17: 0 | AD17: 0 | AE17: 0 | AF17: =SUM(B17:AE17) -> 0
A18: Bing | B18: 0 | C18: 251 | D18: 0 | E18: 0 | F18: 0 | G18: 0 | H18: 0 | I18: 0 | J18: 0 | K18: 0 | L18: 0 | M18: 0 | N18: 0 | O18: 0 | P18: 0 | Q18: 0 | R18: 0 | S18: 0 | T18: 0 | U18: 0 | V18: 0 | W18: 0 | X18: 0 | Y18: 2761 | Z18: 753 | AA18: 251 | AB18: 0 | AC18: 502 | AD18: 502 | AE18: 753 | AF18: =SUM(B18:AE18) -> 5773
A19: Nextdoor | B19: 0 | C19: 0 | D19: 0 | E19: 0 | F19: 0 | G19: 0 | H19: 0 | I19: 0 | J19: 0 | K19: 0 | L19: 0 | M19: 0 | N19: 0 | O19: 0 | P19: 0 | Q19: 0 | R19: 0 | S19: 0 | T19: 0 | U19: 0 | V19: 0 | W19: 0 | X19: 0 | Y19: 0 | Z19: 0 | AA19: 0 | AB19: 0 | AC19: 0 | AD19: 0 | AE19: 0 | AF19: =SUM(B19:AE19) -> 0
A20: Affiliates (Refersion) | B20: 0 | C20: 0 | D20: 0 | E20: 191.22 | F20: 500.33 | G20: 250.2 | H20: 0 | I20: 0 | J20: 0 | K20: 656.14 | L20: 0 | M20: 0 | N20: 0 | O20: 558.43 | P20: 266.62 | Q20: 299.58 | R20: 268.11 | S20: 77.38 | T20: 295.24 | U20: 285.19 | V20: 0 | W20: 285.82 | X20: 0 | Y20: 134.53 | Z20: 0 | AA20: 0 | AB20: 0 | AC20: 0 | AD20: 0 | AE20: 0 | AF20: 4068.79
A21: Email | B21: 31.54 | C21: 194.2 | D21: 325.4 | E21: 299.73 | F21: 758.64 | G21: 30.22 | H21: 0 | I21: 284.54 | J21: 0 | K21: 277.14 | L21: 272.9 | M21: 0 | N21: 0 | O21: 360.23 | P21: 62.95 | Q21: 0 | R21: 276.01 | S21: 17465.79 | T21: 4691.16 | U21: 1885.65 | V21: 2249.89 | W21: 2177.45 | X21: 912.06 | Y21: 712.15 | Z21: 731.4 | AA21: 720.45 | AB21: 8391.12 | AC21: 3445.83 | AD21: 2534.36 | AE21: 1006.28 | AF21: =SUM(B21:AE21) -> 50097.09
A22: All | B22: =SUM(B15:B21) -> 12291.612 | C22: =SUM(C15:C21) -> 16179.202 | D22: =SUM(D15:D21) -> 24165.184 | E22: =SUM(E15:E21) -> 26085.883 | F22: =SUM(F15:F21) -> 29390.414 | G22: =SUM(G15:G21) -> 20562.376 | H22: =SUM(H15:H21) -> 11847.381 | I22: =SUM(I15:I21) -> 11844.53 | ... AE22: =SUM(AE15:AE21) -> 22552.835 | AF22: =SUM(B22:AE22) -> 596984.76
A24: Media Cost
A25: Meta | B25: =Summary!B65 -> 4940.4078 | C25: =Summary!C65 -> 4538.0801 | D25: =Summary!D65 -> 6292.9294 | E25: =Summary!E65 -> 7164.6631 | F25: =Summary!F65 -> 9564.4493 | G25: =Summary!G65 -> 9981.8489 | H25: =Summary!H65 -> 4150.0806 | I25: =Summary!I65 -> 1979.8849 | ... AE25: =Summary!AE65 -> 5308.5044 | AF25: =SUM(B25:AE25) -> 152533.05
A26: Google | B26: =Summary!B66 -> 1210.79 | C26: =Summary!C66 -> 1399.9 | D26: =Summary!D66 -> 1709.65 | E26: =Summary!E66 -> 1315.99 | F26: =Summary!F66 -> 1354.7 | G26: =Summary!G66 -> 1334.04 | H26: =Summary!H66 -> 1388.13 | I26: =Summary!I66 -> 1350.77 | ... AE26: =Summary!AE66 -> 2141.16 | AF26: =SUM(B26:AE26) -> 56634.05
A27: TikTok | B27: =Summary!B68 -> 0 | C27: =Summary!C68 -> 0 | D27: =Summary!D68 -> 0 | E27: =Summary!E68 -> 0 | F27: =Summary!F68 -> 0 | G27: =Summary!G68 -> 0 | H27: =Summary!H68 -> 0 | I27: =Summary!I68 -> 0 | ... AE27: =Summary!AE68 -> 0 | AF27: =SUM(B27:AE27) -> 217.52
A28: Bing | B28: =Summary!B67 -> 183.94 | C28: =Summary!C67 -> 172.98 | D28: =Summary!D67 -> 228.88 | E28: =Summary!E67 -> 223.48 | F28: =Summary!F67 -> 230.68 | G28: =Summary!G67 -> 227.63 | H28: =Summary!H67 -> 224.23 | I28: =Summary!I67 -> 191.43 | ... AE28: =Summary!AE67 -> 464.33 | AF28: =SUM(B28:AE28) -> 6220.52
A29: Nextdoor | B29: =Summary!B70 -> 0 | C29: =Summary!C70 -> 0 | D29: =Summary!D70 -> 0 | E29: =Summary!E70 -> 0 | F29: =Summary!F70 -> 0 | G29: =Summary!G70 -> 0 | H29: =Summary!H70 -> 0 | I29: =Summary!I70 -> 0 | ... AE29: =Summary!AE70 -> 0 | AF29: =SUM(B29:AE29) -> 7245.47
A30: Affiliate Fee (20%) | B30: =Summary!B72 -> 0 | C30: =Summary!C72 -> 0 | D30: =Summary!D72 -> 0 | E30: =Summary!E72 -> 47.81 | F30: =Summary!F72 -> 113.06 | G30: =Summary!G72 -> 62.55 | H30: =Summary!H72 -> 0 | I30: =Summary!I72 -> 0 | ... AE30: =Summary!AE72 -> 0 | AF30: =SUM(B30:AE30) -> 895.31
A31: All | B31: =SUM(B25:B30) -> 6335.1378 | C31: =SUM(C25:C30) -> 6110.9601 | D31: =SUM(D25:D30) -> 8231.4594 | E31: =SUM(E25:E30) -> 8751.9431 | F31: =SUM(F25:F30) -> 11262.889 | G31: =SUM(G25:G30) -> 11606.069 | H31: =SUM(H25:H30) -> 5762.4406 | I31: =SUM(I25:I30) -> 3522.0849 | ... AE31: =SUM(AE25:AE30) -> 7913.9944 | AF31: =SUM(B31:AE31) -> 223745.92
A36: Revenue
A37: Revenue Woocommerce (Platform) | B37: =Summary!B8 -> 16813.33 | C37: =Summary!C8 -> 24584.7 | D37: =Summary!D8 -> 29900.76 | E37: =Summary!E8 -> 36334.28 | F37: =Summary!F8 -> 33865.73 | G37: =Summary!G8 -> 26222.32 | H37: =Summary!H8 -> 19010.62 | I37: =Summary!I8 -> 14263.81 | ... AE37: =Summary!AE8 -> 24655.64 | AF37: =sum(B37:AE37) -> 723794.94
A38: SUM | B38: =SUM(B37) -> 16813.33 | C38: =SUM(C37) -> 24584.7 | D38: =SUM(D37) -> 29900.76 | E38: =SUM(E37) -> 36334.28 | F38: =SUM(F37) -> 33865.73 | G38: =SUM(G37) -> 26222.32 | H38: =SUM(H37) -> 19010.62 | I38: =SUM(I37) -> 14263.81 | ... AE38: =SUM(AE37) -> 24655.64 | AF38: =sum(B38:AE38) -> 723794.94
A40: Orders
A41: Orders Woocommerce (Platform) | B41: =Summary!B44 -> 80 | C41: =Summary!C44 -> 113 | D41: =Summary!D44 -> 139 | E41: =Summary!E44 -> 168 | F41: =Summary!F44 -> 153 | G41: =Summary!G44 -> 125 | H41: =Summary!H44 -> 81 | I41: =Summary!I44 -> 53 | ... AE41: =Summary!AE44 -> 103 | AF41: =sum(B41:AE41) -> 3889
A42: SUM | B42: =SUM(B41) -> 80 | C42: =SUM(C41) -> 113 | D42: =SUM(D41) -> 139 | E42: =SUM(E41) -> 168 | F42: =SUM(F41) -> 153 | G42: =SUM(G41) -> 125 | H42: =SUM(H41) -> 81 | I42: =SUM(I41) -> 53 | ... AE42: =SUM(AE41) -> 103 | AF42: =sum(B42:AE42) -> 3889
A44: Breakdown
A45: - Hardware | B45: =Summary!B9 -> 13722.1 | C45: =Summary!C9 -> 19550.7 | D45: =Summary!D9 -> 23435.2 | E45: =Summary!E9 -> 29484.65 | F45: =Summary!F9 -> 27664 | G45: =Summary!G9 -> 20990.5 | H45: =Summary!H9 -> 15207.5 | I45: =Summary!I9 -> 11768 | ... AE45: =Summary!AE9 -> 19255.96 | AF45: =SUM(B45:AE45) -> 524910.24
A46: - Add-ons | B46: =Summary!B10 -> 1072.8 | C46: =Summary!C10 -> 1944.6 | D46: =Summary!D10 -> 2730.2 | E46: =Summary!E10 -> 2310.6 | F46: =Summary!F10 -> 2146.4 | G46: =Summary!G10 -> 2010 | H46: =Summary!H10 -> 1468.7 | I46: =Summary!I10 -> 941 | ... AE46: =Summary!AE10 -> 2396.19 | AF46: =SUM(B46:AE46) -> 102785.98
A47: - Merch | B47: =Summary!B11 | C47: =Summary!C11 | D47: =Summary!D11 | E47: =Summary!E11 | F47: =Summary!F11 | G47: =Summary!G11 | H47: =Summary!H11 | I47: =Summary!I11 | ... AE47: =Summary!AE11
A48: - Taxes | B48: =Summary!B13 -> 868.43 | C48: =Summary!C13 -> 1259.4 | D48: =Summary!D13 -> 1585.36 | E48: =Summary!E13 -> 1889.03 | F48: =Summary!F13 -> 1815.33 | G48: =Summary!G13 -> 1391.82 | H48: =Summary!H13 -> 1024.42 | I48: =Summary!I13 -> 584.81 | ... AE48: =Summary!AE13 -> 1353.49 | AF48: =SUM(B48:AE48) -> 37528.72
...

Sheet AMAZON - P&L
A1: JANUARY | B1: 45170 | C1: 45171 | D1: 45172 | E1: 45173 | F1: 45174 | G1: 45175 | H1: 45176 | I1: 45177 | J1: 45178 | K1: 45179 | L1: 45180 | M1: 45181 | N1: 45182 | O1: 45183 | P1: 45184 | Q1: 45185 | R1: 45186 | S1: 45187 | T1: 45188 | U1: 45189 | V1: 45190 | W1: 45191 | X1: 45192 | Y1: 45193 | Z1: 45194 | AA1: 45195 | AB1: 45196 | AC1: 45197 | AD1: 45198 | AE1: 45199
A2: DAY | B2: FRI | C2: SAT | D2: SUN | E2: MON | F2: TUE | G2: WED | H2: THU | I2: FRI | J2: SAT | K2: SUN | L2: MON | M2: TUE | N2: WED | O2: THU | P2: FRI | Q2: SAT | R2: SUN | S2: MON | T2: TUE | U2: WED | V2: THU | W2: FRI | X2: SAT | Y2: SUN | Z2: MON | AA2: TUE | AB2: WED | AC2: THU | AD2: FRI | AE2: SAT
A3: COMMENT
A4: Orders
A5: Amazon (market place) | B5: =Summary!B47 -> 14 | C5: =Summary!C47 -> 8 | D5: =Summary!D47 -> 20 | E5: =Summary!E47 -> 24 | F5: =Summary!F47 -> 16 | G5: =Summary!G47 -> 21 | H5: =Summary!H47 -> 12 | I5: =Summary!I47 -> 11 | ... AE5: =Summary!AE47 -> 30
A6: All | B6: =SUM(B5) -> 14 | C6: =SUM(C5) -> 8 | D6: =SUM(D5) -> 20 | E6: =SUM(E5) -> 24 | F6: =SUM(F5) -> 16 | G6: =SUM(G5) -> 21 | H6: =SUM(H5) -> 12 | I6: =SUM(I5) -> 11 | ... AE6: =SUM(AE5) -> 30 | AF6: =SUM(B6:AE6) -> 772
A8: Revenue
A9: Amazon (market place) | B9: =Summary!B15 -> 3281.76 | C9: =Summary!C15 -> 3000.84 | D9: =Summary!D15 -> 4785.04 | E9: =Summary!E15 -> 6287.08 | F9: =Summary!F15 -> 5999.8 | G9: =Summary!G15 -> 5360.55 | H9: =Summary!H15 -> 3848.96 | I9: =Summary!I15 -> 2985.94 | ... AE9: =Summary!AE15 -> 7779.39
A10: All | B10: =SUM(B9) -> 3281.76 | C10: =SUM(C9) -> 3000.84 | D10: =SUM(D9) -> 4785.04 | E10: =SUM(E9) -> 6287.08 | F10: =SUM(F9) -> 5999.8 | G10: =SUM(G9) -> 5360.55 | H10: =SUM(H9) -> 3848.96 | I10: =SUM(I9) -> 2985.94 | ... AE10: =SUM(AE9) -> 7779.39 | AF10: =SUM(B10:AE10) -> 229806.35
A12: Media Cost
A13: Amazon Spend | B13: =Summary!B69 -> 1276.67 | C13: =Summary!C69 -> 1876.55 | D13: =Summary!D69 -> 2182.61 | E13: =Summary!E69 -> 1886.24 | F13: =Summary!F69 -> 1401.31 | G13: =Summary!G69 -> 1491.07 | H13: =Summary!H69 -> 1448.93 | I13: =Summary!I69 -> 1479.75 | ... AE13: =Summary!AE69 -> 3932.81 | AF13: =sum(B13:AE13) -> 61343.57
A14: Amazon Platform Fee (15 %) | B14: =B9*'DATA - P&L'!$C$48 -> 492.264 | C14: =C9*'DATA - P&L'!$C$48 -> 450.126 | D14: =D9*'DATA - P&L'!$C$48 -> 717.756 | E14: =E9*'DATA - P&L'!$C$48 -> 943.062 | F14: =F9*'DATA - P&L'!$C$48 -> 899.97 | G14: =G9*'DATA - P&L'!$C$48 -> 804.0825 | H14: =H9*'DATA - P&L'!$C$48 -> 577.344 | I14: =I9*'DATA - P&L'!$C$48 -> 447.891 | ... AE14: =AE9*'DATA - P&L'!$C$48 -> 1166.9085
A15: All | B15: =SUM(B13:B14) -> 1768.934 | C15: =SUM(C13:C14) -> 2326.676 | D15: =SUM(D13:D14) -> 2900.366 | E15: =SUM(E13:E14) -> 2829.302 | F15: =SUM(F13:F14) -> 2301.28 | G15: =SUM(G13:G14) -> 2295.1525 | H15: =SUM(H13:H14) -> 2026.274 | I15: =SUM(I13:I14) -> 1927.641 | ... AE15: =SUM(AE13:AE14) -> 5099.7185 | AF15: =SUM(B15:AE15) -> 95814.523
A19: Amazon Orders
A20: Hardware | B20: =Summary!B16 -> 3069 | C20: =Summary!C16 -> 2790 | D20: =Summary!D16 -> 4464 | E20: =Summary!E16 -> 5859 | F20: =Summary!F16 -> 5580 | G20: =Summary!G16 -> 5022 | H20: =Summary!H16 -> 3627 | I20: =Summary!I16 -> 2790 | ... AE20: =Summary!AE16 -> 7254 | AF20: =SUM(B20:AE20) -> 214551
A21: Addons | B21: =Summary!B17 -> 0 | C21: =Summary!C17 -> 0 | D21: =Summary!D17 -> 0 | E21: =Summary!E17 -> 0 | F21: =Summary!F17 -> 0 | G21: =Summary!G17 -> 0 | H21: =Summary!H17 -> 0 | I21: =Summary!I17 -> 0 | ... AE21: =Summary!AE17 -> 0 | AF21: =SUM(B21:AE21) -> 0
A22: Tax | B22: =Summary!B18 -> 205.77 | C22: =Summary!C18 -> 210.38 | D22: =Summary!D18 -> 302.63 | E22: =Summary!E18 -> 423.13 | F22: =Summary!F18 -> 410.82 | G22: =Summary!G18 -> 328.65 | H22: =Summary!H18 -> 221.96 | I22: =Summary!I18 -> 195.94 | ... AE22: =Summary!AE18 -> 520.9 | AF22: =SUM(B22:AE22) -> 15031.59
A23: Shipping | B23: =Summary!B19 -> 6.99 | C23: =Summary!C19 -> 0.29 | D23: =Summary!D19 -> 13.75 | E23: =Summary!E19 -> 0.29 | F23: =Summary!F19 -> 0 | G23: =Summary!G19 -> 0.58 | H23: =Summary!H19 -> 0 | I23: =Summary!I19 -> 0 | ... AE23: =Summary!AE19 -> 0 | AF23: =SUM(B23:AE23) -> 76.34
A24: Gift Wrap Price | B24: =Summary!B20 -> 0 | C24: =Summary!C20 -> 0.17 | D24: =Summary!D20 -> 4.66 | E24: =Summary!E20 -> 4.66 | F24: =Summary!F20 -> 8.98 | G24: =Summary!G20 -> 9.32 | H24: =Summary!H20 -> 0 | I24: =Summary!I20 -> 0 | ... AE24: =Summary!AE20 -> 4.49 | AF24: =SUM(B24:AE24) -> 147.42
A25: All Amazon | B25: =SUM(B20:B24) -> 3281.76 | C25: =SUM(C20:C24) -> 3000.84 | D25: =SUM(D20:D24) -> 4785.04 | E25: =SUM(E20:E24) -> 6287.08 | F25: =SUM(F20:F24) -> 5999.8 | G25: =SUM(G20:G24) -> 5360.55 | H25: =SUM(H20:H24) -> 3848.96 | I25: =SUM(I20:I24) -> 2985.94 | ... AE25: =SUM(AE20:AE24) -> 7779.39 | AF25: =SUM(B25:AE25) -> 229806.35
A27: Units Sold (Gross)
A28: SKU 1 - Blue | AF28: =sum(B28:AE28) -> 0
A29: SKU 2 - Yellow | AF29: =sum(B29:AE29) -> 0
A30: SKU 3 - Blue w/ Solar | B30: 11 | C30: 10 | D30: 17 | E30: 22 | F30: 21 | G30: 18 | H30: 13 | I30: 10 | J30: 26 | K30: 22 | L30: 22 | M30: 27 | N30: 27 | O30: 31 | P30: 15 | Q30: 21 | R30: 18 | S30: 25 | T30: 49 | U30: 32 | V30: 31 | W30: 41 | X30: 21 | Y30: 39 | Z30: 32 | AA30: 36 | AB30: 34 | AC30: 41 | AD30: 37 | AE30: 32 | AF30: =sum(B30:AE30) -> 781
A31: SKU 4 - Yellow w/ Solar | AF31: =sum(B31:AE31) -> 0
A32: SUM (SKU 1 - SKU 4) | B32: =sum(B28:B31) -> 11 | C32: =sum(C28:C31) -> 10 | D32: =sum(D28:D31) -> 17 | E32: =sum(E28:E31) -> 22 | F32: =sum(F28:F31) -> 21 | G32: =sum(G28:G31) -> 18 | H32: =sum(H28:H31) -> 13 | I32: =sum(I28:I31) -> 10 | ... AE32: =sum(AE28:AE31) -> 32 | AF32: =sum(B32:AE32) -> 781
A34: Wall Mount | AF34: =sum(B34:AE34) -> 0
A35: Suet Ball Holder | AF35: =sum(B35:AE35) -> 0
A36: 3-in-1 Nutrition Set - Blue | AF36: =sum(B36:AE36) -> 0
A37: 3-in-1 Nutrition Set - Yellow | AF37: =sum(B37:AE37) -> 0
A38: Solar Roof Single - Blue | AF38: =sum(B38:AE38) -> 0
A39: Solar Roof Single - Yellow | AF39: =sum(B39:AE39) -> 0
A40: Perch Extender - Blue | AF40: =sum(B40:AE40) -> 0
A41: Perch Extender - Yellow | AF41: =sum(B41:AE41) -> 0
A42: SUM (Add-ons) | B42: =SUM(B34:B41) -> 0 | C42: =SUM(C34:C41) -> 0 | D42: =SUM(D34:D41) -> 0 | E42: =SUM(E34:E41) -> 0 | F42: =SUM(F34:F41) -> 0 | G42: =SUM(G34:G41) -> 0 | H42: =SUM(H34:H41) -> 0 | I42: =SUM(I34:I41) -> 0 | ... AE42: =SUM(AE34:AE41) -> 0 | AF42: =sum(B42:AE42) -> 0
A45: Units Sold by country (Gross) - Only selling in US
A46: Bird Buddy - Blue - AMAZON.US | AF46: =sum(B46:AE46) -> 0
A47: Bird Buddy - Yellow - AMAZON.US
A48: Bird Buddy with Solar Roof Blue - AMAZON.US | AB48: =AB31 | AC48: =AC31 | AD48: =AD31 | AE48: =AE31 | AF48: =sum(B48:AE48) -> 0
A49: Bird Buddy with Solar Roof Yellow - AMAZON.US
...

Sheet App - P&L
A1: SEPTEMBER | B1: 45170 | C1: 45171 | D1: 45172 | E1: 45173 | F1: 45174 | G1: 45175 | H1: 45176 | I1: 45177 | J1: 45178 | K1: 45179 | L1: 45180 | M1: 45181 | N1: 45182 | O1: 45183 | P1: 45184 | Q1: 45185 | R1: 45186 | S1: 45187 | T1: 45188 | U1: 45189 | V1: 45190 | W1: 45191 | X1: 45192 | Y1: 45193 | Z1: 45194 | AA1: 45195 | AB1: 45196 | AC1: 45197 | AD1: 45198 | AE1: 45199
A2: DAY | B2: FRI | C2: SAT | D2: SUN | E2: MON | F2: TUE | G2: WED | H2: THU | I2: FRI | J2: SAT | K2: SUN | L2: MON | M2: TUE | N2: WED | O2: THU | P2: FRI | Q2: SAT | R2: SUN | S2: MON | T2: TUE | U2: WED | V2: THU | W2: FRI | X2: SAT | Y2: SUN | Z2: MON | AA2: TUE | AB2: WED | AC2: THU | AD2: FRI | AE2: SAT
A4: Gross Revenue
A5: Apple Store Sales | B5: 0 | C5: 0 | D5: 0 | E5: 0 | F5: 0 | G5: 0 | H5: 0 | I5: 0 | J5: 0 | K5: 0 | L5: 0 | M5: 0 | N5: 0 | O5: 0 | P5: 0 | Q5: 0 | R5: 0 | S5: 5748.6935 | T5: 6580.5519 | U5: 4058.2307 | V5: 3177.1625 | W5: 2122.4201 | X5: 2216.3139 | Y5: 2009.1927 | Z5: 1405.2564 | AA5: 1441.6047 | AB5: 965.97582 | AC5: 1057.4882 | AD5: 5026.6341 | AE5: 4807.3088 | AF5: =sum(B5:AE5) -> 40616.833
A6: - Yearly Subscription | B6: 0 | C6: 0 | D6: 0 | E6: 0 | F6: 0 | G6: 0 | H6: 0 | I6: 0 | J6: 0 | K6: 0 | L6: 0 | M6: 0 | N6: 0 | O6: 0 | P6: 0 | Q6: 0 | R6: 0 | S6: 5748.6935 | T6: 6580.5519 | U6: 4058.2307 | V6: 3177.1625 | W6: 2122.4201 | X6: 2216.3139 | Y6: 2009.1927 | Z6: 1361.2228 | AA6: 1348.0112 | AB6: 934.39645 | AC6: 1026.3088 | AD6: 5005.441 | AE6: 4783.1257 | AF6: =sum(B6:AE6) -> 40371.071
A7: - Monthly Subscription | B7: 0 | C7: 0 | D7: 0 | E7: 0 | F7: 0 | G7: 0 | H7: 0 | I7: 0 | J7: 0 | K7: 0 | L7: 0 | M7: 0 | N7: 0 | O7: 0 | P7: 0 | Q7: 0 | R7: 0 | S7: 0 | T7: 0 | U7: 0 | V7: 0 | W7: 0 | X7: 0 | Y7: 0 | Z7: 44.033621 | AA7: 93.59341 | AB7: 31.579364 | AC7: 31.179341 | AD7: 21.19312 | AE7: 24.18312 | AF7: =sum(B7:AE7) -> 245.76198
A8: Google Store Sales | B8: 0 | C8: 0 | D8: 0 | E8: 0 | F8: 0 | G8: 3.53 | H8: 3.52 | I8: 0 | J8: 0 | K8: 0 | L8: 0 | M8: 0 | N8: 0 | O8: 0 | P8: 35.16 | Q8: 15.99 | R8: 35.15 | S8: 2612.31 | T8: 1993.73 | U8: 1418.95 | V8: 1165.15 | W8: 829.06 | X8: 745.44 | Y8: 626.12 | Z8: 497.57 | AA8: 589.46 | AB8: 457.86 | AC8: 360.17 | AD8: 2072.5 | AE8: 2861.7 | AF8: =sum(B8:AE8) -> 16323.37
A9: - Yearly Subscription | B9: 0 | C9: 0 | D9: 0 | E9: 0 | F9: 0 | G9: 0 | H9: 0 | I9: 0 | J9: 0 | K9: 0 | L9: 0 | M9: 0 | N9: 0 | O9: 0 | P9: 31.97 | Q9: 15.99 | R9: 31.96 | S9: 2602.74 | T9: 1993.73 | U9: 1412.75 | V9: 1165.15 | W9: 829.06 | X9: 745.44 | Y9: 626.12 | Z9: 491.4 | AA9: 570.4 | AB9: 448.25 | AC9: 353.64 | AD9: 2066.35 | AE9: 2852.07 | AF9: =sum(B9:AE9) -> 16237.02
A10: - Monthly Subscription | B10: 0 | C10: 0 | D10: 0 | E10: 0 | F10: 0 | G10: 3.53 | H10: 3.52 | I10: 0 | J10: 0 | K10: 0 | L10: 0 | M10: 0 | N10: 0 | O10: 0 | P10: 3.19 | Q10: 0 | R10: 3.19 | S10: 9.57 | T10: 0 | U10: 6.2 | V10: 0 | W10: 0 | X10: 0 | Y10: 0 | Z10: 6.17 | AA10: 19.06 | AB10: 9.61 | AC10: 6.53 | AD10: 6.15 | AE10: 9.63 | AF10: =sum(B10:AE10) -> 86.35
A11: SUM | B11: =sum(B5+B8) -> 0 | C11: =sum(C5+C8) -> 0 | D11: =sum(D5+D8) -> 0 | E11: =sum(E5+E8) -> 0 | F11: =sum(F5+F8) -> 0 | G11: =sum(G5+G8) -> 3.53 | H11: =sum(H5+H8) -> 3.52 | I11: =sum(I5+I8) -> 0 | ... AE11: =sum(AE5+AE8) -> 7669.0088 | AF11: =sum(B11:AE11) -> 56940.203
A13: Gross Orders
A14: Apple Store Orders | B14: =sum(B15:B16) -> 0 | C14: =sum(C15:C16) -> 0 | D14: =sum(D15:D16) -> 0 | E14: =sum(E15:E16) -> 0 | F14: =sum(F15:F16) -> 0 | G14: =sum(G15:G16) -> 0 | H14: =sum(H15:H16) -> 0 | I14: =sum(I15:I16) -> 0 | ... AE14: =sum(AE15:AE16) -> 319 | AF14: =sum(B14:AE14) -> 2719
A15: - Yearly Subscription | B15: 0 | C15: 0 | D15: 0 | E15: 0 | F15: 0 | G15: 0 | H15: 0 | I15: 0 | J15: 0 | K15: 0 | L15: 0 | M15: 0 | N15: 0 | O15: 0 | P15: 0 | Q15: 0 | R15: 0 | S15: 372 | T15: 431 | U15: 265 | V15: 207 | W15: 141 | X15: 145 | Y15: 132 | Z15: 89 | AA15: 86 | AB15: 62 | AC15: 67 | AD15: 331 | AE15: 311 | AF15: =sum(B15:AE15) -> 2639
A16: - Monthly Subscription | B16: 0 | C16: 0 | D16: 0 | E16: 0 | F16: 0 | G16: 0 | H16: 0 | I16: 0 | J16: 0 | K16: 0 | L16: 0 | M16: 0 | N16: 0 | O16: 0 | P16: 0 | Q16: 0 | R16: 0 | S16: 0 | T16: 0 | U16: 0 | V16: 0 | W16: 0 | X16: 0 | Y16: 0 | Z16: 14 | AA16: 31 | AB16: 10 | AC16: 10 | AD16: 7 | AE16: 8 | AF16: =sum(B16:AE16) -> 80
A17: Google Store Orders | B17: =sum(B18:B19) -> 0 | C17: =sum(C18:C19) -> 0 | D17: =sum(D18:D19) -> 0 | E17: =sum(E18:E19) -> 0 | F17: =sum(F18:F19) -> 0 | G17: =sum(G18:G19) -> 1 | H17: =sum(H18:H19) -> 1 | I17: =sum(I18:I19) -> 0 | ... AE17: =sum(AE18:AE19) -> 182 | AF17: =sum(B17:AE17) -> 1069
A18: - Yearly Subscription | B18: 0 | C18: 0 | D18: 0 | E18: 0 | F18: 0 | G18: 0 | H18: 0 | I18: 0 | J18: 0 | K18: 0 | L18: 0 | M18: 0 | N18: 0 | O18: 0 | P18: 1 | Q18: 1 | R18: 1 | S18: 145 | T18: 157 | U18: 98 | V18: 74 | W18: 56 | X18: 46 | Y18: 39 | Z18: 31 | AA18: 35 | AB18: 28 | AC18: 22 | AD18: 129 | AE18: 179 | AF18: =sum(B18:AE18) -> 1042
A19: - Monthly Subscription | B19: 0 | C19: 0 | D19: 0 | E19: 0 | F19: 0 | G19: 1 | H19: 1 | I19: 0 | J19: 0 | K19: 0 | L19: 0 | M19: 0 | N19: 0 | O19: 0 | P19: 1 | Q19: 0 | R19: 1 | S19: 3 | T19: 0 | U19: 2 | V19: 0 | W19: 0 | X19: 0 | Y19: 0 | Z19: 2 | AA19: 6 | AB19: 3 | AC19: 2 | AD19: 2 | AE19: 3 | AF19: =sum(B19:AE19) -> 27
A20: SUM | B20: =sum(B14+B17) -> 0 | C20: =sum(C14+C17) -> 0 | D20: =sum(D14+D17) -> 0 | E20: =sum(E14+E17) -> 0 | F20: =sum(F14+F17) -> 0 | G20: =sum(G14+G17) -> 1 | H20: =sum(H14+H17) -> 1 | I20: =sum(I14+I17) -> 0 | ... AE20: =sum(AE14+AE17) -> 501 | AF20: =sum(B20:AE20) -> 3788
A21: - Yearly Subscription | B21: =B15+B18 -> 0 | C21: =C15+C18 -> 0 | D21: =D15+D18 -> 0 | E21: =E15+E18 -> 0 | F21: =F15+F18 -> 0 | G21: =G15+G18 -> 0 | H21: =H15+H18 -> 0 | I21: =I15+I18 -> 0 | ... AE21: =AE15+AE18 -> 490 | AF21: =sum(B21:AE21) -> 3681
A22: - Monthly Subscription | B22: =B16+B19 -> 0 | C22: =C16+C19 -> 0 | D22: =D16+D19 -> 0 | E22: =E16+E19 -> 0 | F22: =F16+F19 -> 0 | G22: =G16+G19 -> 1 | H22: =H16+H19 -> 1 | I22: =I16+I19 -> 0 | ... AE22: =AE16+AE19 -> 11 | AF22: =sum(B22:AE22) -> 107
A24: Refunded Revenue
A25: Apple Store Sales | B25: =sum(B26:B27) -> 0 | C25: =sum(C26:C27) -> 0 | D25: =sum(D26:D27) -> 0 | E25: =sum(E26:E27) -> 0 | F25: =sum(F26:F27) -> 0 | G25: =sum(G26:G27) -> 0 | H25: =sum(H26:H27) -> 0 | I25: =sum(I26:I27) -> 0 | ... AE25: =sum(AE26:AE27) -> 14.99 | AF25: =sum(B25:AE25) -> 88.17
A26: - Yearly Subscription | B26: 0 | C26: 0 | D26: 0 | E26: 0 | F26: 0 | G26: 0 | H26: 0 | I26: 0 | J26: 0 | K26: 0 | L26: 0 | M26: 0 | N26: 0 | O26: 0 | P26: 0 | Q26: 0 | R26: 0 | S26: 0 | T26: 14.99 | U26: 0 | V26: 0 | W26: 29.72 | X26: 0 | Y26: 0 | Z26: 0 | AA26: 0 | AB26: 28.47 | AC26: 0 | AD26: 0 | AE26: 14.99 | AF26: =sum(B26:AE26) -> 88.17
A27: - Monthly Subscription | B27: 0 | C27: 0 | D27: 0 | E27: 0 | F27: 0 | G27: 0 | H27: 0 | I27: 0 | J27: 0 | K27: 0 | L27: 0 | M27: 0 | N27: 0 | O27: 0 | P27: 0 | Q27: 0 | R27: 0 | S27: 0 | T27: 0 | U27: 0 | V27: 0 | W27: 0 | X27: 0 | Y27: 0 | Z27: 0 | AA27: 0 | AB27: 0 | AC27: 0 | AD27: 0 | AE27: 0 | AF27: =sum(B27:AE27) -> 0
A28: Google Store Sales | B28: =sum(B29:B30) -> 0 | C28: =sum(C29:C30) -> 0 | D28: =sum(D29:D30) -> 0 | E28: =sum(E29:E30) -> 0 | F28: =sum(F29:F30) -> 0 | G28: =sum(G29:G30) -> 0 | H28: =sum(H29:H30) -> 0 | I28: =sum(I29:I30) -> 0 | ... AE28: =sum(AE29:AE30) -> 0 | AF28: =sum(B28:AE28) -> 359.76
A29: - Yearly Subscription | B29: 0 | C29: 0 | D29: 0 | E29: 0 | F29: 0 | G29: 0 | H29: 0 | I29: 0 | J29: 0 | K29: 0 | L29: 0 | M29: 0 | N29: 0 | O29: 0 | P29: 0 | Q29: 14.99 | R29: 0 | S29: 0 | T29: =21*14.99 -> 314.79 | U29: 0 | V29: 14.99 | W29: 14.99 | X29: 0 | Y29: 0 | Z29: 0 | AA29: 0 | AB29: 0 | AC29: 0 | AD29: 0 | AE29: 0 | AF29: =sum(B29:AE29) -> 359.76
A30: - Monthly Subscription | B30: 0 | C30: 0 | D30: 0 | E30: 0 | F30: 0 | G30: 0 | H30: 0 | I30: 0 | J30: 0 | K30: 0 | L30: 0 | M30: 0 | N30: 0 | O30: 0 | P30: 0 | Q30: 0 | R30: 0 | S30: 0 | T30: 0 | U30: 0 | V30: 0 | W30: 0 | X30: 0 | Y30: 0 | Z30: 0 | AA30: 0 | AB30: 0 | AC30: 0 | AD30: 0 | AE30: 0 | AF30: =sum(B30:AE30) -> 0
A31: SUM | B31: =B25+B28 -> 0 | C31: =C25+C28 -> 0 | D31: =D25+D28 -> 0 | E31: =E25+E28 -> 0 | F31: =F25+F28 -> 0 | G31: =G25+G28 -> 0 | H31: =H25+H28 -> 0 | I31: =I25+I28 -> 0 | ... AE31: =AE25+AE28 -> 14.99 | AF31: =sum(B31:AE31) -> 447.93
A33: Refunded Orders
A34: Apple Store orders | B34: =sum(B35:B36) -> 0 | C34: =sum(C35:C36) -> 0 | D34: =sum(D35:D36) -> 0 | E34: =sum(E35:E36) -> 0 | F34: =sum(F35:F36) -> 0 | G34: =sum(G35:G36) -> 0 | H34: =sum(H35:H36) -> 0 | I34: =sum(I35:I36) -> 0 | ... AE34: =sum(AE35:AE36) -> 1 | AF34: =sum(B34:AE34) -> 5
A35: - Yearly Subscription | B35: 0 | C35: 0 | D35: 0 | E35: 0 | F35: 0 | G35: 0 | H35: 0 | I35: 0 | J35: 0 | K35: 0 | L35: 0 | M35: 0 | N35: 0 | O35: 0 | P35: 0 | Q35: 0 | R35: 0 | S35: 0 | T35: 1 | U35: 0 | V35: 0 | W35: 2 | X35: 0 | Y35: 0 | Z35: 0 | AA35: 0 | AB35: 1 | AC35: 0 | AD35: 0 | AE35: 1
A36: - Monthly Subscription | B36: 0 | C36: 0 | D36: 0 | E36: 0 | F36: 0 | G36: 0 | H36: 0 | I36: 0 | J36: 0 | K36: 0 | L36: 0 | M36: 0 | N36: 0 | O36: 0 | P36: 0 | Q36: 0 | R36: 0 | S36: 0 | T36: 0 | U36: 0 | V36: 0 | W36: 0 | X36: 0 | Y36: 0 | Z36: 0 | AA36: 0 | AB36: 0 | AC36: 0 | AD36: 0 | AE36: 0
A37: Google Store orders | B37: =sum(B38:B39) -> 0 | C37: =sum(C38:C39) -> 0 | D37: =sum(D38:D39) -> 0 | E37: =sum(E38:E39) -> 0 | F37: =sum(F38:F39) -> 0 | G37: =sum(G38:G39) -> 0 | H37: =sum(H38:H39) -> 0 | I37: =sum(I38:I39) -> 0 | ... AE37: =sum(AE38:AE39) -> 0 | AF37: =sum(B37:AE37) -> 24
A38: - Yearly Subscription | B38: 0 | C38: 0 | D38: 0 | E38: 0 | F38: 0 | G38: 0 | H38: 0 | I38: 0 | J38: 0 | K38: 0 | L38: 0 | M38: 0 | N38: 0 | O38: 0 | P38: 0 | Q38: 1 | R38: 0 | S38: 0 | T38: 21 | U38: 0 | V38: 1 | W38: 1 | X38: 0 | Y38: 0 | Z38: 0 | AA38: 0 | AB38: 0 | AC38: 0 | AD38: 0 | AE38: 0
A39: - Monthly Subscription | B39: 0 | C39: 0 | D39: 0 | E39: 0 | F39: 0 | G39: 0 | H39: 0 | I39: 0 | J39: 0 | K39: 0 | L39: 0 | M39: 0 | N39: 0 | O39: 0 | P39: 0 | Q39: 0 | R39: 0 | S39: 0 | T39: 0 | U39: 0 | V39: 0 | W39: 0 | X39: 0 | Y39: 0 | Z39: 0 | AA39: 0 | AB39: 0 | AC39: 0 | AD39: 0 | AE39: 0
A40: SUM | B40: =B34+B37 -> 0 | C40: =C34+C37 -> 0 | D40: =D34+D37 -> 0 | E40: =E34+E37 -> 0 | F40: =F34+F37 -> 0 | G40: =G34+G37 -> 0 | H40: =H34+H37 -> 0 | I40: =I34+I37 -> 0 | ... AE40: =AE34+AE37 -> 1 | AF40: =sum(B40:AE40) -> 29
A42: Net Revenue
A43: Apple Store | B43: =B5-B25 -> 0 | C43: =C5-C25 -> 0 | D43: =D5-D25 -> 0 | E43: =E5-E25 -> 0 | F43: =F5-F25 -> 0 | G43: =G5-G25 -> 0 | H43: =H5-H25 -> 0 | I43: =I5-I25 -> 0 | ... AE43: =AE5-AE25 -> 4792.3188 | AF43: =sum(B43:AE43) -> 40528.663
A44: - Yearly Subscription | B44: =B6-B26 -> 0 | C44: =C6-C26 -> 0 | D44: =D6-D26 -> 0 | E44: =E6-E26 -> 0 | F44: =F6-F26 -> 0 | G44: =G6-G26 -> 0 | H44: =H6-H26 -> 0 | I44: =I6-I26 -> 0 | ... AE44: =AE6-AE26 -> 4768.1357 | AF44: =sum(B44:AE44) -> 40282.901
A45: - Monthly Subscription | B45: =B7-B27 -> 0 | C45: =C7-C27 -> 0 | D45: =D7-D27 -> 0 | E45: =E7-E27 -> 0 | F45: =F7-F27 -> 0 | G45: =G7-G27 -> 0 | H45: =H7-H27 -> 0 | I45: =I7-I27 -> 0 | ... AE45: =AE7-AE27 -> 24.18312 | AF45: =sum(B45:AE45) -> 245.76198
...

Sheet Digital Marketplaces
A1: SEPTEMBER | B1: 45170 | C1: 45171 | D1: 45172 | E1: 45173 | F1: 45174 | G1: 45175 | H1: 45176 | I1: 45177 | J1: 45178 | K1: 45179 | L1: 45180 | M1: 45181 | N1: 45182 | O1: 45183 | P1: 45184 | Q1: 45185 | R1: 45186 | S1: 45187 | T1: 45188 | U1: 45189 | V1: 45190 | W1: 45191 | X1: 45192 | Y1: 45193 | Z1: 45194 | AA1: 45195 | AB1: 45196 | AC1: 45197 | AD1: 45198 | AE1: 45199
A2: DAY | B2: MON | C2: TUE | D2: WED | E2: THU | F2: FRI | G2: SAT | H2: SUN | I2: MON | J2: TUE | K2: WED | L2: THU | M2: FRI | N2: SAT | O2: SUN | P2: MON | Q2: TUE | R2: WED | S2: THU | T2: FRI | U2: SAT | V2: SUN | W2: MON | X2: TUE | Y2: WED | Z2: THU | AA2: FRI | AB2: SAT | AC2: SUN | AD2: MON | AE2: TUE
A3: Rachio (Shopify)
A4: Revenue | B4: =Summary!B22 -> 0 | C4: =Summary!C22 -> 0 | D4: =Summary!D22 -> 0 | E4: =Summary!E22 -> 0 | F4: =Summary!F22 -> 0 | G4: =Summary!G22 -> 0 | H4: =Summary!H22 -> 0 | I4: =Summary!I22 -> 0 | ... AE4: =Summary!AE22 -> 1039 | AF4: =sum(B4:AE4) -> 15033.33
A5: Breakdown
A6: - Tax | B6: =Summary!B24 | C6: =Summary!C24 | D6: =Summary!D24 | E6: =Summary!E24 | F6: =Summary!F24 | G6: =Summary!G24 | H6: =Summary!H24 | I6: =Summary!I24 | ... AE6: =Summary!AE24 | AF6: =sum(B6:AE6) -> 0
A7: - Shipping | B7: =Summary!B25 -> 0 | C7: =Summary!C25 -> 0 | D7: =Summary!D25 -> 0 | E7: =Summary!E25 -> 0 | F7: =Summary!F25 -> 0 | G7: =Summary!G25 -> 0 | H7: =Summary!H25 -> 0 | I7: =Summary!I25 -> 0 | ... AE7: =Summary!AE25 -> 0 | AF7: =sum(B7:AE7) -> 0
A8: Orders | B8: =Summary!B51 | C8: =Summary!C51 | D8: =Summary!D51 | E8: =Summary!E51 | F8: =Summary!F51 | G8: =Summary!G51 | H8: =Summary!H51 | I8: =Summary!I51 | ... AE8: =Summary!AE51 -> 5 | AF8: =sum(B8:AE8) -> 69
A10: Rachio Fees (20%) | B10: =Summary!B73 -> 0 | C10: =Summary!C73 -> 0 | D10: =Summary!D73 -> 0 | E10: =Summary!E73 -> 0 | F10: =Summary!F73 -> 0 | G10: =Summary!G73 -> 0 | H10: =Summary!H73 -> 0 | I10: =Summary!I73 -> 0 | ... AE10: =Summary!AE73 -> 207.8 | AF10: =sum(B10:AE10) -> 3006.666
A12: Units Sold (Gross) - Rachio
A13: SKU 1 - Blue | AC13: 7 | AD13: 9 | AE13: 0 | AF13: =sum(B13:AE13) -> 16
A14: SKU 2 - Yellow | AC14: 4 | AD14: 3 | AE14: 1 | AF14: =sum(B14:AE14) -> 8
A15: SKU 3 - Blue w/ Solar | AC15: 19 | AD15: 12 | AE15: 3 | AF15: =sum(B15:AE15) -> 34
A16: SKU 4 - Yellow w/ Solar | AC16: 5 | AD16: 3 | AE16: 1 | AF16: =sum(B16:AE16) -> 9
A17: SUM (SKU 1 - SKU 4) | B17: =SUM(B13:B16) -> 0 | C17: =SUM(C13:C16) -> 0 | D17: =SUM(D13:D16) -> 0 | E17: =SUM(E13:E16) -> 0 | F17: =SUM(F13:F16) -> 0 | G17: =SUM(G13:G16) -> 0 | H17: =SUM(H13:H16) -> 0 | I17: =SUM(I13:I16) -> 0 | ... AE17: =SUM(AE13:AE16) -> 5 | AF17: =sum(B17:AE17) -> 67
A19: Wall Mount | AC19: 0 | AD19: 0 | AE19: 0 | AF19: =sum(B19:AE19) -> 0
A20: Suet Ball Holder | AC20: 0 | AD20: 0 | AE20: 0 | AF20: =sum(B20:AE20) -> 0
A21: 3-in-1 Nutrition Set - Blue | AC21: 0 | AD21: 0 | AE21: 0 | AF21: =sum(B21:AE21) -> 0
A22: 3-in-1 Nutrition Set - Yellow | AC22: 0 | AD22: 0 | AE22: 0 | AF22: =sum(B22:AE22) -> 0
A23: Solar Roof Single - Blue | AC23: 0 | AD23: 0 | AE23: 0 | AF23: =sum(B23:AE23) -> 0
A24: Solar Roof Single - Yellow | AC24: 0 | AD24: 0 | AE24: 0 | AF24: =sum(B24:AE24) -> 0
A25: Perch Extender - Blue | AC25: 0 | AD25: 0 | AE25: 0 | AF25: =sum(B25:AE25) -> 0
A26: Perch Extender - Yellow | AC26: 0 | AD26: 0 | AE26: 0 | AF26: =sum(B26:AE26) -> 0
A27: SUM (Add-ons) | B27: =SUM(B19:B26) -> 0 | C27: =SUM(C19:C26) -> 0 | D27: =SUM(D19:D26) -> 0 | E27: =SUM(E19:E26) -> 0 | F27: =SUM(F19:F26) -> 0 | G27: =SUM(G19:G26) -> 0 | H27: =SUM(H19:H26) -> 0 | I27: =SUM(I19:I26) -> 0 | ... AE27: =SUM(AE19:AE26) -> 0 | AF27: =sum(B27:AE27) -> 0
A29: Units and Revenue Cancelled & Refunds - Rachio
A31: Units Cancelled (Gross) - Rachio
A32: SKU 1 - Blue | AF32: =SUM(B32:AE32) -> 0
A33: SKU 2 - Yellow | AF33: =SUM(B33:AE33) -> 0
A34: SKU 3 - Blue w/ Solar | AF34: =SUM(B34:AE34) -> 0
A35: SKU 4 - Yellow w/ Solar | AF35: =SUM(B35:AE35) -> 0
A36: SUM (SKU 1 + SKU 2) | B36: =SUM(B32:B33) -> 0 | C36: =SUM(C32:C33) -> 0 | D36: =SUM(D32:D33) -> 0 | E36: =SUM(E32:E33) -> 0 | F36: =SUM(F32:F33) -> 0 | G36: =SUM(G32:G33) -> 0 | H36: =SUM(H32:H33) -> 0 | I36: =SUM(I32:I33) -> 0 | ... AE36: =SUM(AE32:AE33) -> 0 | AF36: =SUM(B36:AE36) -> 0
A37: SUM (SKU 3 + SKU 4) | B37: =SUM(B34:B35) -> 0 | C37: =SUM(C34:C35) -> 0 | D37: =SUM(D34:D35) -> 0 | E37: =SUM(E34:E35) -> 0 | F37: =SUM(F34:F35) -> 0 | G37: =SUM(G34:G35) -> 0 | H37: =SUM(H34:H35) -> 0 | I37: =SUM(I34:I35) -> 0 | ... AE37: =SUM(AE34:AE35) -> 0 | AF37: =SUM(B37:AE37) -> 0
A39: Wall Mount | AF39: =SUM(B39:AE39) -> 0
A40: Suet Ball Holder | AF40: =SUM(B40:AE40) -> 0
A41: 3-in-1 Nutrition Set - Blue | AF41: =SUM(B41:AE41) -> 0
A42: 3-in-1 Nutrition Set - Yellow | AF42: =SUM(B42:AE42) -> 0
A43: Solar Roof Single - Blue | AF43: =SUM(B43:AE43) -> 0
A44: Solar Roof Single - Yellow | AF44: =SUM(B44:AE44) -> 0
A45: Perch Extender - Blue | AF45: =SUM(B45:AE45) -> 0
A46: Perch Extender - Yellow | AF46: =SUM(B46:AE46) -> 0
...

Sheet DATA - P&L
B1: Business Metrics
A2: Source | B2: COGS | E2: Attachment Rates | H2: Marketing Averages (per first-time order) | K2: Fees | N2: VAT Averages | Q2: 30 Day Returns | T2: Digital Market Places & B2B
B3: Bird Buddy | C3: 86.9 | D3: 86.9 | E3: Solar Roof | F3: =(('DTC - P&L'!AF83+'DTC - P&L'!AF84)/'DTC - P&L'!AF77) -> 0.079075966 | H3: COGS | I3: =(C3*F9)+(C4*F8)+(C5*F3)+(C6*F4)+(C7*F5)+(C8*F6)+(C9*F7)+(C10*F10) -> 102.96659 | J3: =(D3*F9)+(D4*F8)+(D5*F3)+(D6*F4)+(D7*F5)+(D8*F6)+(D9*F7) -> 99.381519 | K3: Stripe Processing Fee | L3: 0.029 | N3: Europe | O3: 0.22 | Q3: US Shipping | R3: 15 | T3: Average % tax | U3: 0.0614 | V3: Source
B4: Bird Buddy with Solar Roof | C4: 97.61 | D4: 97.61 | E4: Wall Mount | F4: =('DTC - P&L'!AF79/'DTC - P&L'!AF77) -> 0.33540649 | H4: Inbound Shipping | I4: =C38+('DTC - P&L'!AF87/'DTC - P&L'!AF77)*D38 -> 14.122143 | K4: Duty | L4: 0.034 | N4: ROW | O4: 0.13 | Q4: EU Shipping | R4: 40
B5: Solar Roof Single | C5: 13.44 | D5: 13.44 | E5: Fence Mount | F5: 0 | H5: Outbound Shipping | I5: =C34+('DTC - P&L'!AF87/'DTC - P&L'!AF77)*D34 -> 21.299647 | K5: China Tax | L5: 0.075 | N5: NA | Q5: ROW Shipping | R5: 20
B6: Wall Mount | C6: 5.49 | D6: 5.49 | E6: Suet Ball Holder | F6: =('DTC - P&L'!AF80)/'DTC - P&L'!AF77 -> 0.23056419 | H6: Taxes and VAT | I6: 16.81 | K6: HMF | L6: 0.00125 | Q6: Money Return | R6: 1
B7: Fence Mount | C7: 6.37 | E7: 3-in-1 | F7: =('DTC - P&L'!AF81+'DTC - P&L'!AF82)/'DTC - P&L'!AF77 -> 0.27809862 | H7: China Tax (7.5%) | I7: 0 | K7: MPF | L7: 0.003464
B8: Suet Ball Holder | C8: 1.19 | D8: 1.19 | E8: Bird Buddy w/ Solar | F8: =('DTC - P&L'!AF75+'DTC - P&L'!AF76)/'DTC - P&L'!AF77 -> 0.6956908 | H8: Duty (3.4%) | I8: 0 | K8: Solar Roof China Tax | L8: 0.075
B9: 3-in-1 Nutrition Set | C9: 6.66 | D9: 6.66 | E9: Bird Buddy | F9: =1-F8 -> 0.3043092 | H9: Processing Fee (2,90%) | I9: =Summary!B109*L3 -> 6.1513277 | K9: Solar Roof Duty | L9: 0.025
B10: Perch Extender | C10: 6 | E10: Perch Extender | F10: =('DTC - P&L'!AF85+'DTC - P&L'!AF86)/'DTC - P&L'!AF77 -> 0.59751222 | H10: Transaction Fee ($0.30) | I10: =0.3 -> 0.3 | K10: Chargeback Fee (Stripe) | L10: 15
B11: Avg. Merch Cost | C11: 3.94 | E11: OTHER 2 | H11: OTHER 1
B12: Avg. Merch Cost without Calendar | C12: 14.79 | E12: OTHER 3 | H12: OTHER 2 | K12: Stripe | L12: 0.95
B13: SBF Housing | E13: OTHER 4 | H13: OTHER 3 | K13: Affirm | L13: 0.05
B14: SBF Camera | E14: OTHER 5 | H14: OTHER 4 | K14: Affirm processing fee | L14: 0.0579
H15: All | I15: =SUM(I3:I14) -> 161.64971 | K15: Affirm transaction fee | L15: 0.3
B22: Outbound shipping | C22: Bird buddy | D22: Add-ons | E22: Merch
A23: *w/o CA weight | B23: Outbound (NA) | C23: 11.94 | D23: 6.155 | E23: 5.4 | H23: App Advertising
B24: Outbound (Europe) | C24: 11.94 | D24: 6.16 | H24: Meta Share to Apple Store | I24: 0.8
B25: Outbound (ROW) | C25: 11.94 | D25: 6.16 | H25: Meta Share to Google Store | I25: 0.2
A26: Source | B26: 3PL Costs | C26: 0 | D26: 0
B27: Handling Fee
B28: Serial Capture | C28: 0.1 | D28: 0
B29: Storage | C29: 0.31 | D29: 0.31
B30: Supplies cost | C30: 0 | D30: 0
B31: Pick charge | C31: 0.35 | D31: 0.35
B32: Pollybag cost | C32: 0 | D32: 0
B33: Carton cost | C33: 1.65 | D33: 0.71
B34: Total outbound (NA) | C34: =C26+C23-C27 -> 11.94 | D34: =D26+D23-D27 -> 6.155
B35: Total outbound (Europe) | C35: 15.06 | D35: =D27+D24-D28 -> 6.16
B36: Total outbound (ROW) | C36: 20
A37: Source | B37: Inbound shipping | C37: Bird buddy | D37: Add-ons
B38: Inbound (NA) | C38: 11.94 | D38: 1.435
B39: Inbound (Europe) | C39: 11.94 | D39: 1.44
B40: Inbound (ROW) | C40: 11.94 | D40: 1.44
B42: AMAZON Logistics | C42: Bird buddy | D42: Add-ons
A43: https://docs.google.com/spreadsheets/d/1Dn0q7h1bHxXdG0N9KpcqzFo0tWUWYXOrRX7yxv3G1E0/edit#gid=1264242332 | B43: Inbound | C43: 11.94 | D43: 1.435
A44: =sum(C43:C44) -> 12.18 | B44: Storage Fee | C44: 0.24 | D44: 0.24
A45: =C46 -> 12.94 | B45: AMAZON Fees | C45: Bird buddy
A46: =sum(F43:F45) -> 0 | B46: FBA fee for units | C46: 12.94
B47: FBA fee for addons | C47: 5.7
...

Sheet OLD Sales
A1: 45170 | B1: 45170 | C1: 45171 | D1: 45172 | E1: 45173 | F1: 45174 | G1: 45175 | H1: 45176 | I1: 45177 | J1: 45178 | K1: 45179 | L1: 45180 | M1: 45181 | N1: 45182 | O1: 45183 | P1: 45184 | Q1: 45185 | R1: 45186 | S1: 45187 | T1: 45188 | U1: 45189 | V1: 45190 | W1: 45191 | X1: 45192 | Y1: 45193 | Z1: 45194 | AA1: 45195 | AB1: 45196 | AC1: 45197 | AD1: 45198 | AE1: 45199
B2: FRI | C2: SAT | D2: SUN | E2: MON | F2: TUE | G2: WED | H2: THU | I2: FRI | J2: SAT | K2: SUN | L2: MON | M2: TUE | N2: WED | O2: THU | P2: FRI | Q2: SAT | R2: SUN | S2: MON | T2: TUE | U2: WED | V2: THU | W2: FRI | X2: SAT | Y2: SUN | Z2: MON | AA2: TUE | AB2: WED | AC2: THU | AD2: FRI | AE2: SAT
A3: Weekend Work | C3: Peco | D3: Peco | J3: Peco | K3: Peco | Q3: Peter | R3: Peter | X3: Peter | Y3: Peter | AE3: Peco
S4: PRO Subscription Launch | X4: SKU3 ABC Test - Testing availability
B5: Labor Day | N5: 10% off Sitewide | S5: Keynote
