Workbook
Name rdataslayer_d70e473bcafe40a3aa834ce157fb2ba3: 'Business Metrics Canada'!$C$16:$D$17
Name zsupermetrics_xwoIpANxRm908eDp5oKTwQpEI8gvD4: 'Business Metrics US'!$A$5
Name zsupermetrics_ru0GDtbZzDLHQOQtJJ6K08MvUDyyp7: #REF!
Name zsupermetrics_iNpyVy90bWCI0yUaFQpxOtzWMa6sW4: 'Business Metrics US'!$A$5:$A$12
Name zsupermetrics_DQl8lUbpTRu3fayaJJi7lVfOGKjNU4: 'OLD Formulas'!$A$3:$A$4
Name zsupermetrics_NugLlrQxlKiqhxQae8EFpITBm1pLCj: 'Business Metrics Canada'!$B$15:$C$23
Name rdataslayer_4a0f150f4f2f4e4f85c890c75b7a1fa4: 'Business Metrics Canada'!$D$5:$E$12
Name zsupermetrics_BioPyGBzcBsy60UCQmPcTuFReEmghI: 'OLD Formulas'!$B$2:$B$3
Name zsupermetrics_refreshAll: SupermetricsQueries!$H$5
Name zsupermetrics_DQl8lUbpTRu3fayaJJi7lVfOGKjNU4: 'Business Metrics Canada'!$A$2:$A$13
Name zsupermetrics_n3GtLgiKpTmd2pYmQNMuq6TPD0qE0b: #REF!
Name zsupermetrics_9i4W4hgd80uRpQLMeX0eRnESN8gjyv: 'Business Metrics US'!$C$23
Name zsupermetrics_qWp7V908pNEYMtfv8QZvSTeDnBAHOU: 'Business Metrics Canada'!$B$14:$C$23
Name zsupermetrics_refreshAllSilent: SupermetricsQueries!$H$6
Name zsupermetrics_Mgms9p0QzysYvrIhnsKACeVBVxfIEO: #REF!
Name rdataslayer_4a0f150f4f2f4e4f85c890c75b7a1fa4: 'Business Metrics US'!$D$5:$E$12
Name zsupermetrics_lx4cNai7gT6tH4j08ZRkI21Qlpjioi: 'Business Metrics Canada'!$B$13:$C$23
Name zsupermetrics_Mgms9p0QzysYvrIhnsKACeVBVxfIEO: 'OLD Formulas'!$A$2:$A$3
Name zsupermetrics_forceRefresh: SupermetricsQueries!$H$4
Name zsupermetrics_wbYMmT0YL9bAN0yhimW0ziPFnia9Dx: #REF!
Name zsupermetrics_iNpyVy90bWCI0yUaFQpxOtzWMa6sW4: #REF!
Name zsupermetrics_xwoIpANxRm908eDp5oKTwQpEI8gvD4: 'Business Metrics Canada'!$A$5
Name zsupermetrics_xwoIpANxRm908eDp5oKTwQpEI8gvD4: #REF!
Name rdataslayer_3753ddf3234e496aa261974a0222e193: 'Business Metrics US'!$H$5:$I$5
Name zsupermetrics_4VkB7ij7WO0JjKBEgvjB2GHjSy2Egm: 'Business Metrics Canada'!$B$13:$C$17
Name zsupermetrics_n3GtLgiKpTmd2pYmQNMuq6TPD0qE0b: 'OLD Formulas'!$B$4:$B$5
Name rdataslayer_42b112e4e4be4305bb4c1be75e2dd549: 'OLD Formulas'!$B$2:$C$3
Name zsupermetrics_wbYMmT0YL9bAN0yhimW0ziPFnia9Dx: 'Business Metrics Canada'!$A$5:$A$12
Name zsupermetrics_9i4W4hgd80uRpQLMeX0eRnESN8gjyv: #REF!
Name zsupermetrics_YsFuuYtr8vOdNXCCPiFJIO38NP4b2T: 'Business Metrics US'!$B$13:$C$23
Name zsupermetrics_5bmwtOpHUbSYmDMeuCPkrxaojTprPP: #REF!
Name rdataslayer_adf57e64065742daa5b4161161b1c3ca: 'Business Metrics Canada'!$B$13:$D$14
Name zsupermetrics_9i4W4hgd80uRpQLMeX0eRnESN8gjyv: 'Business Metrics Canada'!$C$23
Name rdataslayer_3753ddf3234e496aa261974a0222e193: 'OLD Formulas'!$H$2:$I$2
Name zsupermetrics_4VkB7ij7WO0JjKBEgvjB2GHjSy2Egm: 'Business Metrics US'!$B$13:$C$17
Name zsupermetrics_SGBxROnInO9rFyh3H7j2Lldx0Bdc5v: #REF!
Name zsupermetrics_pxuhRTEmIU93xSgKclyxajD0fCZ6rF: #REF!
Name zsupermetrics_ru0GDtbZzDLHQOQtJJ6K08MvUDyyp7: 'OLD Formulas'!$B$4:$B$5
Name zsupermetrics_qWp7V908pNEYMtfv8QZvSTeDnBAHOU: 'OLD Formulas'!$B$5:$C$13
Name zsupermetrics_wbYMmT0YL9bAN0yhimW0ziPFnia9Dx: 'Business Metrics US'!$A$5:$A$12
Name rdataslayer_4a0f150f4f2f4e4f85c890c75b7a1fa4: #REF!
Name zsupermetrics_iNpyVy90bWCI0yUaFQpxOtzWMa6sW4: 'Business Metrics Canada'!$A$5:$A$12
Name zsupermetrics_HgZqhorObHOtZHuyJjpmyYaEPoYntx: #REF!
Name zsupermetrics_YsFuuYtr8vOdNXCCPiFJIO38NP4b2T: #REF!
Name zsupermetrics_DQl8lUbpTRu3fayaJJi7lVfOGKjNU4: #REF!
Name zsupermetrics_YVuzfmsfdurz7Ldl84Rfns8oka6LsS: #REF!
Name zsupermetrics_4VkB7ij7WO0JjKBEgvjB2GHjSy2Egm: #REF!
Name zsupermetrics_9i4W4hgd80uRpQLMeX0eRnESN8gjyv: 'OLD Formulas'!$C$13
Name zsupermetrics_Mgms9p0QzysYvrIhnsKACeVBVxfIEO: 'Business Metrics US'!$A$5:$A$12
Name zsupermetrics_lx4cNai7gT6tH4j08ZRkI21Qlpjioi: #REF!
Name zsupermetrics_BioPyGBzcBsy60UCQmPcTuFReEmghI: 'Business Metrics US'!$B$5:$B$12
Name zsupermetrics_qWp7V908pNEYMtfv8QZvSTeDnBAHOU: 'Business Metrics US'!$B$14:$C$23
Name rdataslayer_adf57e64065742daa5b4161161b1c3ca: 'Business Metrics US'!$B$13:$D$14
Name rdataslayer_d70e473bcafe40a3aa834ce157fb2ba3: #REF!
Name zsupermetrics_NugLlrQxlKiqhxQae8EFpITBm1pLCj: 'OLD Formulas'!$B$6:$C$13
Name zsupermetrics_8xojRjNDjo2jWHGDWjFEhflhyIq3Hq: 'Sales OLD'!$K$8:$K$26
Name rdataslayer_42b112e4e4be4305bb4c1be75e2dd549: 'Business Metrics Canada'!$B$5:$C$12
Name rdataslayer_d70e473bcafe40a3aa834ce157fb2ba3: 'Business Metrics US'!$C$16:$D$17
Name rdataslayer_3753ddf3234e496aa261974a0222e193: #REF!
Name zsupermetrics_BioPyGBzcBsy60UCQmPcTuFReEmghI: 'Business Metrics Canada'!$B$5:$B$12

Sheet DataslayerQueries
A1: Query UUID | B1: Sheet name | C1: Range address | D1: Created | E1: Updated | F1: Last status | G1: Last refresh ID | H1: Results contain sampled data | I1: Execution time (sec) | J1: Object type | K1: Linked chart ID | L1: Data source | M1: Date range type | N1: Start date | O1: End date | P1: Compare to | Q1: Comparison value type | R1: Accounts/views | S1: Metrics | T1: Dimensions | U1: Pivot dimensions | V1: Filters | W1: Segment ID | X1: Segment dim | Y1: Sort | Z1: Max rows | AA1: Max pivot categories | AB1: Special settings | AC1: Other parameters | AD1: Result type | AE1: Language/country | AF1: Translate to | AG1: SQL | AH1: Database name | AI1: Range address (static) | AJ1: Report type | AK1: Highlight with colour | AL1: Refresh with user account | AM1: Returned data | AN1: Sort dimensions | AO1: Created by user account
A2: 42b112e4e4be4305bb4c1be75e2dd549 | B2: =IFERROR(__xludf.DUMMYFUNCTION("ARRAY_CONSTRAIN(split(CELL(""ADDRESS"",rdataslayer_42b112e4e4be4305bb4c1be75e2dd549),""!""),1,1)"),"#REF!") -> #REF! | C2: =IFERROR(__xludf.DUMMYFUNCTION("INDEX(split(CELL(""ADDRESS"",rdataslayer_42b112e4e4be4305bb4c1be75e2dd549),""!""),0,2)&"":""&address(row(rdataslayer_42b112e4e4be4305bb4c1be75e2dd549)+rows(rdataslayer_42b112e4e4be4305bb4c1be75e2dd549)-1,column(rdataslayer_42b112e4e4be4305bb4c1be75e2dd549"&")+COLUMNS(rdataslayer_42b112e4e4be4305bb4c1be75e2dd549)-1)"),"#REF!") -> #REF! | D2: 44518.613 | E2: 44520.051 | F2: There is no data for the specified input | I2: 7 | J2: TABLE | L2: facebook | M2: yesterday | R2: [{"profile_id":"","name":"si_Bird buddy Inc_US &amp; CA_BirdBuddy","id":"act_273249767551281","account_name":"","advertiser_id":""}] | S2: [{"id":"spend","name":"Total Cost"}] | T2: [{"id":"date","name":"Date"}] | U2: [] | V2: [] | W2: [] | Y2: [] | Z2: 5 | AA2: 5 | AB2: {} | AC2: {} | AL2: User_Kumalic_Benjamin | AN2: [] | AO2: benjamin@mybirdbuddy.com
A3: 4a0f150f4f2f4e4f85c890c75b7a1fa4 | B3: =IFERROR(__xludf.DUMMYFUNCTION("ARRAY_CONSTRAIN(split(CELL(""ADDRESS"",rdataslayer_4a0f150f4f2f4e4f85c890c75b7a1fa4),""!""),1,1)"),"#REF!") -> #REF! | C3: =IFERROR(__xludf.DUMMYFUNCTION("INDEX(split(CELL(""ADDRESS"",rdataslayer_4a0f150f4f2f4e4f85c890c75b7a1fa4),""!""),0,2)&"":""&address(row(rdataslayer_4a0f150f4f2f4e4f85c890c75b7a1fa4)+rows(rdataslayer_4a0f150f4f2f4e4f85c890c75b7a1fa4)-1,column(rdataslayer_4a0f150f4f2f4e4f85c890c75b7a1fa4"&")+COLUMNS(rdataslayer_4a0f150f4f2f4e4f85c890c75b7a1fa4)-1)"),"#REF!") -> #REF! | D3: 44518.615 | E3: 44520.051 | F3: There is no data for the specified input | I3: 7 | J3: TABLE | L3: facebook | M3: yesterday | R3: [{"account_name":"","advertiser_id":"","id":"act_273249767551281","profile_id":"","name":"si_Bird buddy Inc_US &amp; CA_BirdBuddy"}] | S3: [{"id":"spend","name":"Total Cost"}] | T3: [] | U3: [{"id":"date","name":"Date"}] | V3: [] | W3: [] | Y3: [] | Z3: 5 | AA3: 5 | AB3: {} | AC3: {} | AL3: User_Kumalic_Benjamin | AN3: [] | AO3: benjamin@mybirdbuddy.com
A4: adf57e64065742daa5b4161161b1c3ca | B4: =IFERROR(__xludf.DUMMYFUNCTION("ARRAY_CONSTRAIN(split(CELL(""ADDRESS"",rdataslayer_adf57e64065742daa5b4161161b1c3ca),""!""),1,1)"),"#REF!") -> #REF! | C4: =IFERROR(__xludf.DUMMYFUNCTION("INDEX(split(CELL(""ADDRESS"",rdataslayer_adf57e64065742daa5b4161161b1c3ca),""!""),0,2)&"":""&address(row(rdataslayer_adf57e64065742daa5b4161161b1c3ca)+rows(rdataslayer_adf57e64065742daa5b4161161b1c3ca)-1,column(rdataslayer_adf57e64065742daa5b4161161b1c3ca"&")+COLUMNS(rdataslayer_adf57e64065742daa5b4161161b1c3ca)-1)"),"#REF!") -> #REF! | D4: 44518.618 | E4: 44520.051 | F4: There is no data for the specified input | I4: 18 | J4: TABLE | L4: facebook | M4: yesterday | R4: [{"name":"si_Bird buddy Inc_US &amp; CA_BirdBuddy","id":"act_273249767551281","profile_id":"","account_name":"","advertiser_id":""}] | S4: [{"id":"spend","name":"Total Cost"},{"id":"cpm","name":"CPM"}] | T4: [{"id":"date","name":"Date"}] | U4: [] | V4: [] | W4: [] | Y4: [] | Z4: 5 | AA4: 5 | AB4: {} | AC4: {} | AL4: User_Kumalic_Benjamin | AN4: [] | AO4: benjamin@mybirdbuddy.com
A5: d70e473bcafe40a3aa834ce157fb2ba3 | B5: =IFERROR(__xludf.DUMMYFUNCTION("ARRAY_CONSTRAIN(split(CELL(""ADDRESS"",rdataslayer_d70e473bcafe40a3aa834ce157fb2ba3),""!""),1,1)"),"#REF!") -> #REF! | C5: =IFERROR(__xludf.DUMMYFUNCTION("INDEX(split(CELL(""ADDRESS"",rdataslayer_d70e473bcafe40a3aa834ce157fb2ba3),""!""),0,2)&"":""&address(row(rdataslayer_d70e473bcafe40a3aa834ce157fb2ba3)+rows(rdataslayer_d70e473bcafe40a3aa834ce157fb2ba3)-1,column(rdataslayer_d70e473bcafe40a3aa834ce157fb2ba3"&")+COLUMNS(rdataslayer_d70e473bcafe40a3aa834ce157fb2ba3)-1)"),"#REF!") -> #REF! | D5: 44518.619 | E5: 44520.051 | F5: There is no data for the specified input | I5: 7 | J5: TABLE | L5: facebook | M5: yesterday | R5: [{"advertiser_id":"","name":"si_Bird buddy Inc_US &amp; CA_BirdBuddy","id":"act_273249767551281","account_name":"","profile_id":""}] | S5: [{"id":"spend","name":"Total Cost"}] | T5: [{"id":"date","name":"Date"}] | U5: [] | V5: [] | W5: [] | Y5: [] | Z5: 100 | AA5: 100 | AB5: {} | AC5: {} | AL5: User_Kumalic_Benjamin | AN5: [] | AO5: benjamin@mybirdbuddy.com
A6: 3753ddf3234e496aa261974a0222e193 | B6: =IFERROR(__xludf.DUMMYFUNCTION("ARRAY_CONSTRAIN(split(CELL(""ADDRESS"",rdataslayer_3753ddf3234e496aa261974a0222e193),""!""),1,1)"),"#REF!") -> #REF! | C6: =IFERROR(__xludf.DUMMYFUNCTION("INDEX(split(CELL(""ADDRESS"",rdataslayer_3753ddf3234e496aa261974a0222e193),""!""),0,2)&"":""&address(row(rdataslayer_3753ddf3234e496aa261974a0222e193)+rows(rdataslayer_3753ddf3234e496aa261974a0222e193)-1,column(rdataslayer_3753ddf3234e496aa261974a0222e193"&")+COLUMNS(rdataslayer_3753ddf3234e496aa261974a0222e193)-1)"),"#REF!") -> #REF! | D6: 44518.621 | E6: 44520.051 | F6: There is no data for the specified input | I6: 18 | J6: TABLE | L6: facebook | M6: yesterday | R6: [{"profile_id":"","account_name":"","advertiser_id":"","name":"si_Bird buddy Inc_US &amp; CA_BirdBuddy","id":"act_273249767551281"}] | S6: [{"id":"spend","name":"Total Cost"}] | T6: [] | U6: [] | V6: [] | W6: [] | Y6: [] | Z6: 100 | AA6: 100 | AB6: {"exclude_header_row":true} | AC6: {} | AL6: User_Kumalic_Benjamin | AN6: [] | AO6: benjamin@mybirdbuddy.com

Sheet Summary
A1: 45231 | B1: 45231 | C1: 45232 | D1: 45233 | E1: 45234 | F1: 45235 | G1: 45236 | H1: 45237 | I1: 45238 | J1: 45239 | K1: 45240 | L1: 45241 | M1: 45242 | N1: 45243 | O1: 45244 | P1: 45245 | Q1: 45246 | R1: 45247 | S1: 45248 | T1: 45249 | U1: 45250 | V1: 45251 | W1: 45252 | X1: 45253 | Y1: 45254 | Z1: 45255 | AA1: 45256 | AB1: 45257 | AC1: 45258 | AD1: 45259 | AE1: 45260
B2: WED | C2: THU | D2: FRI | E2: SAT | F2: SUN | G2: MON | H2: TUE | I2: WED | J2: THU | K2: FRI | L2: SAT | M2: SUN | N2: MON | O2: TUE | P2: WED | Q2: THU | R2: FRI | S2: SAT | T2: SUN | U2: MON | V2: TUE | W2: WED | X2: THU | Y2: FRI | Z2: SAT | AA2: SUN | AB2: MON | AC2: TUE | AD2: WED | AE2: THU
A3: Weekend Work | B3: Peco | E3: Peco | F3: Peco | L3: Peter | M3: Peter | S3: Peco | T3: Peco | Z3: Peco | AA3: Peco
A4: Notes | B4: Halloween Sale - MAP | Y4: Accounts hacked
C5: 3in1 Launch | H5: Early Black Friday - MAP | K5: Black Friday Lowest Price Ever communication
I6: BB US Unit Shipping $15 | J6: Merch Launch | L6: Published in WSJ | W6: BF Email | Y6: D-Day | Z6: Fresh ad account | AA6: Main ad account restored | AB6: Amazon out of stock | AC6: Full Pricing is back at 14.00
A8: DTC Revenue | B8: 105288.85 | C8: 114299.05 | D8: 112607.15 | E8: 122040.63 | F8: 137885.87 | G8: 130202.04 | H8: 119604.06 | I8: 123367.12 | J8: 132758.96 | K8: 129650.69 | L8: 170840.54 | M8: 167598.98 | N8: 144526.94 | O8: 150855.82 | P8: 138667.14 | Q8: 128700 | R8: 137223.22 | S8: 174001.55 | T8: 184464.08 | U8: 194400.84 | V8: 198063.87 | W8: 290518.02 | X8: 350215.16 | Y8: 952032.29 | Z8: 589382.83 | AA8: 442601.05 | AB8: 679709.11 | AC8: 479681.85 | AD8: 104651.11 | AE8: 94859.28
A9: - Hardware | B9: 85464.76 | C9: 88820.66 | D9: 90446.48 | E9: 97964.77 | F9: 112993.92 | G9: 106383.84 | H9: 97516.45 | I9: 97998.57 | J9: 105495.71 | K9: 103305.74 | L9: 135481.65 | M9: 130709.47 | N9: 104808.29 | O9: 120021.9 | P9: 110332.61 | Q9: 101442.48 | R9: 109297.97 | S9: 139757.95 | T9: 148816.8 | U9: 155473.12 | V9: 159649.26 | W9: 232257.49 | X9: 279269.34 | Y9: 768682.68 | Z9: 480538.29 | AA9: 355864.59 | AB9: 554099.5 | AC9: 394641.7 | AD9: 85839.83 | AE9: 76648.21
A10: - Add-ons | B10: 6707.54 | C10: 10578.54 | D10: 9279.32 | E10: 10715.53 | F10: 9847.38 | G10: 9498.36 | H10: 9096.2 | I10: 10900.63 | J10: 10081.86 | K10: 9833.36 | L10: 14204.65 | M10: 15202.53 | N10: 17902.76 | O10: 11276.86 | P10: 10034.39 | Q10: 10184.52 | R10: 9958.2 | S10: 11848.7 | T10: 12208.7 | U10: 14372.88 | V10: 13573.49 | W10: 22112.66 | X10: 26913.89 | Y10: 64135.85 | Z10: 34635.81 | AA10: 31300.7 | AB10: 40412.44 | AC10: 25503.7 | AD10: 7747.32 | AE10: 7659.93
A11: - Merch | B11: 0 | C11: 0 | D11: 0 | E11: 0 | F11: 0 | G11: 0 | H11: 0 | I11: 0 | J11: 552.01 | K11: 356.89 | L11: 281.81 | M11: 164.95 | N11: 0 | O11: 681.63 | P11: 662.92 | Q11: 844.78 | R11: 636.28 | S11: 271.98 | T11: 215.97 | U11: 185.98 | V11: 275.99 | W11: 406.99 | X11: 415.66 | Y11: 911.63 | Z11: 605.98 | AA11: 275.01 | AB11: 776.95 | AC11: 788.98 | AD11: 172.99 | AE11: 114
A12: - Seeds
A13: - Taxes | B13: 5816.55 | C13: 6484.85 | D13: 6121.35 | E13: 7055.33 | F13: 7974.57 | G13: 7404.84 | H13: 6681.41 | I13: 6882.92 | J13: 7181.38 | K13: 7019.7 | L13: 9404.43 | M13: 9065.03 | N13: 8205.89 | O13: 8084.43 | P13: 7629.22 | Q13: 6860.22 | R13: 7425.77 | S13: 9037.92 | T13: 9827.61 | U13: 10093.86 | V13: 10475.13 | W13: 14995.88 | X13: 18816.27 | Y13: 53419.13 | Z13: 33357.75 | AA13: 23750.75 | AB13: 38985.22 | AC13: 27392.47 | AD13: 5705.97 | AE13: 5427.14
A14: - Shipping | B14: 7300 | C14: 8415 | D14: 6760 | E14: 6305 | F14: 7070 | G14: 6915 | H14: 6310 | I14: 7585 | J14: 9448 | K14: 9135 | L14: 11468 | M14: 12457 | N14: 13610 | O14: 10791 | P14: 10008 | Q14: 9368 | R14: 9905 | S14: 13085 | T14: 13395 | U14: 14275 | V14: 14090 | W14: 20745 | X14: 24800 | Y14: 64883 | Z14: 40245 | AA14: 31410 | AB14: 45435 | AC14: 31355 | AD14: 5185 | AE14: 5010
A15: Amazon Revenue | B15: =SUM(B16:B20) -> 9998.64 | C15: =SUM(C16:C20) -> 10453.96 | D15: =SUM(D16:D20) -> 16043.42 | E15: =SUM(E16:E20) -> 15088.14 | F15: =SUM(F16:F20) -> 19511.77 | G15: =SUM(G16:G20) -> 15164.18 | H15: =SUM(H16:H20) -> 12460.48 | I15: =SUM(I16:I20) -> 14308.41 | ... AE15: =SUM(AE16:AE20) -> 540.1
A16: - Hardware | B16: 9193 | C16: 9677.76 | D16: 14877.86 | E16: 14028.38 | F16: 18099.43 | G16: 14185 | H16: 11584.43 | I16: 13067.81 | J16: 20859.28 | K16: 27638.76 | L16: 36779.09 | M16: 34737.14 | N16: 34577.9 | O16: 36524.81 | P16: 36879.17 | Q16: 43135.38 | R16: 47392.32 | S16: 55557.25 | T16: 38666.59 | U16: 90083.38 | V16: 99805.68 | W16: 114068.3 | X16: 149568.42 | Y16: 594889.04 | Z16: 365780.37 | AA16: 231202.98 | AB16: 72457.99 | AC16: 0 | AD16: 0 | AE16: 478
A17: - Add-ons | B17: 144 | C17: 72 | D17: 117.6 | E17: 96 | F17: 142.8 | G17: 96 | H17: 94.8 | I17: 262.8 | J17: 216 | K17: 120 | L17: 214.8 | M17: 240 | N17: 120 | O17: 214.8 | P17: 192 | Q17: 576 | R17: 502.8 | S17: 696 | T17: 605.9 | U17: 863.7 | V17: 976.59 | W17: 815.5 | X17: 1287.9 | Y17: 3856.09 | Z17: 1296 | AA17: 192 | AB17: 48 | AC17: 0 | AD17: 40 | AE17: 29
A18: - Tax | B18: 649.85 | C18: 696.41 | D18: 1038.18 | E18: 947.39 | F18: 1262.15 | G18: 869.71 | H18: 771.81 | I18: 963.53 | J18: 1442.59 | K18: 1915.06 | L18: 2629.44 | M18: 2388.49 | N18: 2399.04 | O18: 2510.61 | P18: 2616.64 | Q18: 3063.65 | R18: 3338.55 | S18: 3872.14 | T18: 2750.01 | U18: 6355.92 | V18: 7181.12 | W18: 7881.51 | X18: 10502.78 | Y18: 42104.68 | Z18: 25752.03 | AA18: 16557.32 | AB18: 5150.32 | AC18: 0 | AD18: 3.71 | AE18: 33.1
A19: - Shipping | B19: 11.79 | C19: 7.49 | D19: 0.5 | E19: 7.24 | F19: 2.75 | G19: 0 | H19: 0.31 | I19: 0.5 | J19: 24.14 | K19: 14.16 | L19: 2 | M19: 21.16 | N19: 25.45 | O19: 0.5 | P19: 37.43 | Q19: 5.51 | R19: 5.39 | S19: 28.49 | T19: 61.6 | U19: 52.57 | V19: 175.38 | W19: 87.25 | X19: 155.77 | Y19: 416.82 | Z19: 134.4 | AA19: 127.92 | AB19: 1301.75 | AC19: 0 | AD19: 15 | AE19: 0
A20: - Gift Wrap | B20: 0 | C20: 0.3 | D20: 9.28 | E20: 9.13 | F20: 4.64 | G20: 13.47 | H20: 9.13 | I20: 13.77 | J20: 18.86 | K20: 18.26 | L20: 14.67 | M20: 31.88 | N20: 14.22 | O20: 9.28 | P20: 9.88 | Q20: 18.86 | R20: 44.55 | S20: 27.24 | T20: 9.28 | U20: 95.34 | V20: 67.75 | W20: 64.36 | X20: 123.33 | Y20: 384.47 | Z20: 357.37 | AA20: 200.71 | AB20: 19.61 | AC20: 0 | AD20: 0 | AE20: 0
A21: Digital Marketplaces Revenue | B21: =SUM(B30,B26,B22) -> 619.2186 | C21: =SUM(C30,C26,C22) -> 1017 | D21: =SUM(D30,D26,D22) -> 566 | E21: =SUM(E30,E26,E22) -> 22212.501 | F21: =SUM(F30,F26,F22) -> 12330.909 | G21: =SUM(G30,G26,G22) -> 48255.884 | H21: =SUM(H30,H26,H22) -> 6842.2291 | I21: =SUM(I30,I26,I22) -> 1682.7254 | ... AE21: =SUM(AE30,AE26,AE22) -> 1378.5442
A22: Rachio | B22: =sum(B23:B24) -> 211.2186 | C22: =sum(C23:C24) -> 0 | D22: =sum(D23:D24) -> 0 | E22: =sum(E23:E24) -> 21715.501 | F22: =sum(F23:F24) -> 10825.909 | G22: =sum(G23:G24) -> 47060.884 | H22: =sum(H23:H24) -> 6559.2291 | I22: =sum(I23:I24) -> 254.72539 | ... AE22: =sum(AE23:AE24) -> 891.54416
A23: - Hardware | B23: 199 | C23: 0 | D23: 0 | E23: 20459.3 | F23: 10199.65 | G23: 44338.5 | H23: 6179.79 | I23: 239.99 | J23: 2639.91 | K23: 899.97 | L23: 899.97 | M23: 1199.96 | N23: 1199.96 | O23: 299.99 | P23: 1979.93 | Q23: 10439.65 | R23: 1739.94 | S23: 2099.93 | T23: 2099.93 | U23: 2339.92 | V23: 2399.92 | W23: 2399.92 | X23: 4379.85 | Y23: 5219.82 | Z23: 839.97 | AA23: 15179.48 | AB23: 25679.13 | AC23: 9779.67 | AD23: 1139.96 | AE23: 839.97
A24: - Tax | B24: =B23*'Data - P&L'!$U$3 -> 12.2186 | C24: =C23*'Data - P&L'!$U$3 -> 0 | D24: =D23*'Data - P&L'!$U$3 -> 0 | E24: =E23*'Data - P&L'!$U$3 -> 1256.201 | F24: =F23*'Data - P&L'!$U$3 -> 626.25851 | G24: =G23*'Data - P&L'!$U$3 -> 2722.3839 | H24: =H23*'Data - P&L'!$U$3 -> 379.43911 | I24: =I23*'Data - P&L'!$U$3 -> 14.735386 | ... AE24: =AE23*'Data - P&L'!$U$3 -> 51.574158
A25: - Shipping
A26: Weatherflow
A27: - Hardware
A28: - Tax
A29: - Shipping
A30: IndieGoGo | B30: =sum(B31:B34) -> 408 | C30: =sum(C31:C34) -> 1017 | D30: =sum(D31:D34) -> 566 | E30: =sum(E31:E34) -> 497 | F30: =sum(F31:F34) -> 1505 | G30: =sum(G31:G34) -> 1195 | H30: =sum(H31:H34) -> 283 | I30: =sum(I31:I34) -> 1428 | ... AE30: =sum(AE31:AE34) -> 487
A31: - Hardware | B31: 378 | C31: 698 | D31: 378 | E31: 0 | F31: 1187 | G31: 887 | H31: 189 | I31: 1353 | J31: 199 | K31: 0 | L31: 887 | M31: 378 | N31: 189 | O31: 378 | P31: 189 | Q31: 189 | R31: 0 | S31: 0 | T31: 388 | U31: 688 | V31: 0 | W31: 766 | X31: 0 | Y31: 1444 | Z31: 1794 | AA31: 756 | AB31: 378 | AC31: 0 | AD31: 189 | AE31: 378
A32: - Add-ons | B32: 0 | C32: 269 | D32: 158 | E32: 467 | F32: 253 | G32: 253 | H32: 79 | I32: 0 | J32: 95 | K32: 0 | L32: 253 | M32: 79 | N32: 79 | O32: 79 | P32: 0 | Q32: 79 | R32: 0 | S32: 0 | T32: 0 | U32: 253 | V32: 0 | W32: 253 | X32: 0 | Y32: 332 | Z32: 190 | AA32: 237 | AB32: 158 | AC32: 358 | AD32: 0 | AE32: 79
A33: - Taxes | B33: 0 | C33: 0 | D33: 0 | E33: 0 | F33: 0 | G33: 0 | H33: 0 | I33: 0 | J33: 0 | K33: 0 | L33: 0 | M33: 0 | N33: 0 | O33: 0 | P33: 0 | Q33: 0 | R33: 0 | S33: 0 | T33: 0 | U33: 0 | V33: 0 | W33: 0 | X33: 0 | Y33: 0 | Z33: 0 | AA33: 0 | AB33: 0 | AC33: 0 | AD33: 0 | AE33: 0
A34: - Shipping | B34: 30 | C34: 50 | D34: 30 | E34: 30 | F34: 65 | G34: 55 | H34: 15 | I34: 75 | J34: 25 | K34: 0 | L34: 55 | M34: 30 | N34: 15 | O34: 30 | P34: 15 | Q34: 15 | R34: 0 | S34: 0 | T34: 30 | U34: 50 | V34: 0 | W34: 60 | X34: 0 | Y34: 100 | Z34: 120 | AA34: 60 | AB34: 30 | AC34: 20 | AD34: 15 | AE34: 30
A35: Total Revenue | B35: =SUM(B8+B15+B21+B30) -> 116314.71 | C35: =SUM(C8+C15+C21+C30) -> 126787.01 | D35: =SUM(D8+D15+D21+D30) -> 129782.57 | E35: =SUM(E8+E15+E21+E30) -> 159838.27 | F35: =SUM(F8+F15+F21+F30) -> 171233.55 | G35: =SUM(G8+G15+G21+G30) -> 194817.1 | H35: =SUM(H8+H15+H21+H30) -> 139189.77 | I35: =SUM(I8+I15+I21+I30) -> 140786.26 | ... AE35: =SUM(AE8+AE15+AE21+AE30) -> 97264.924
A37: B2B Revenue
A38: Best Buy | G38: =SUM(G39:G40) -> 509.472 | H38: =SUM(H39:H40) -> 445.788 | I38: =SUM(I39:I40) -> 222.894 | J38: =SUM(J39:J40) -> 1337.364 | K38: =SUM(K39:K40) -> 7578.396 | L38: =SUM(L39:L40) -> 5572.35 | M38: =SUM(M39:M40) -> 7348.0722 | N38: =SUM(N39:N40) -> 4457.88 | ... AE38: =SUM(AE39:AE40) -> 57949.256
A39: - Hardware | G39: 480 | H39: 420 | I39: 210 | J39: 1260 | K39: 7140 | L39: 5250 | M39: 6923 | N39: 4200 | O39: 5450 | P39: 3150 | Q39: 1470 | R39: 4410 | S39: 2520 | T39: 6720 | U39: 4830 | V39: 3360 | W39: 7980 | X39: 11339 | Y39: 32758 | Z39: 10500 | AA39: 10500 | AB39: 60477 | AC39: 42208 | AD39: 43258 | AE39: 54597
A40: - Tax | G40: =G39*'Data - P&L'!$U$3 -> 29.472 | H40: =H39*'Data - P&L'!$U$3 -> 25.788 | I40: =I39*'Data - P&L'!$U$3 -> 12.894 | J40: =J39*'Data - P&L'!$U$3 -> 77.364 | K40: =K39*'Data - P&L'!$U$3 -> 438.396 | L40: =L39*'Data - P&L'!$U$3 -> 322.35 | M40: =M39*'Data - P&L'!$U$3 -> 425.0722 | N40: =N39*'Data - P&L'!$U$3 -> 257.88 | ... AE40: =AE39*'Data - P&L'!$U$3 -> 3352.2558
A41: Target
A42: - Hardware
...

Sheet DTC - P&L
A1: November | B1: 45231 | C1: 45232 | D1: 45233 | E1: 45234 | F1: 45235 | G1: 45236 | H1: 45237 | I1: 45238 | J1: 45239 | K1: 45240 | L1: 45241 | M1: 45242 | N1: 45243 | O1: 45244 | P1: 45245 | Q1: 45246 | R1: 45247 | S1: 45248 | T1: 45249 | U1: 45250 | V1: 45251 | W1: 45252 | X1: 45253 | Y1: 45254 | Z1: 45255 | AA1: 45256 | AB1: 45257 | AC1: 45258 | AD1: 45259 | AE1: 45260
A2: DAY | B2: WED | C2: THU | D2: FRI | E2: SAT | F2: SUN | G2: MON | H2: TUE | I2: WED | J2: THU | K2: FRI | L2: SAT | M2: SUN | N2: MON | O2: TUE | P2: WED | Q2: THU | R2: FRI | S2: SAT | T2: SUN | U2: MON | V2: TUE | W2: WED | X2: THU | Y2: FRI | Z2: SAT | AA2: SUN | AB2: MON | AC2: TUE | AD2: WED | AE2: THU
A3: COMMENT
A4: Orders
A5: Meta | B5: 305 | C5: 329 | D5: 325 | E5: 321 | F5: 377 | G5: 353 | H5: 314 | I5: 292 | J5: 329 | K5: 340 | L5: 315 | M5: 344 | N5: 250 | O5: 324 | P5: 313 | Q5: 316 | R5: 314 | S5: 407 | T5: 403 | U5: 472 | V5: 447 | W5: 591 | X5: 825 | Y5: 2373 | Z5: 1476 | AA5: 1134 | AB5: 1693 | AC5: 1202 | AD5: 190 | AE5: 116 | AF5: =SUM(B5:AE5) -> 16790
A6: Google | B6: 129.23 | C6: 136.54 | D6: 142.32 | E6: 169.04 | F6: 192.21 | G6: 213.75 | H6: 212.27 | I6: 193.51 | J6: 199.67 | K6: 227.59 | L6: 228.33 | M6: 229.89 | N6: 226.72 | O6: 237.61 | P6: 222.03 | Q6: 228.18 | R6: 260.86 | S6: 289.41 | T6: 366.37 | U6: 364.71 | V6: 362.56 | W6: 339.91 | X6: 579.91 | Y6: 1249 | Z6: 914 | AA6: 686.99 | AB6: 1015 | AC6: 747 | AD6: 137.75 | AE6: 133.61 | AF6: =SUM(B6:AE6) -> 10635.97
A7: TikTok | B7: 0 | C7: 0 | D7: 0 | E7: 0 | F7: 0 | G7: 0 | H7: 0 | I7: 0 | J7: 0 | K7: 0 | L7: 0 | M7: 0 | N7: 0 | O7: 0 | P7: 0 | Q7: 2 | R7: 0 | S7: 0 | T7: 0 | U7: 0 | V7: 0 | W7: 0 | X7: 0 | Y7: 0 | Z7: 0 | AA7: 0 | AB7: 0 | AC7: 0 | AD7: 0 | AE7: 0 | AF7: =SUM(B7:AE7) -> 2
A8: Bing | B8: 24 | C8: 30 | D8: 24 | E8: 22 | F8: 20 | G8: 34 | H8: 26 | I8: 38 | J8: 20 | K8: 24 | L8: 40 | M8: 44 | N8: 26 | O8: 44 | P8: 28 | Q8: 30 | R8: 36 | S8: 22 | T8: 44 | U8: 34 | V8: 40 | W8: 46 | X8: 48 | Y8: 74 | Z8: 42 | AA8: 36 | AB8: 50 | AC8: 100 | AD8: 16 | AE8: 16 | AF8: =SUM(B8:AE8) -> 1078
A9: Nextdoor | B9: 0 | C9: 0 | D9: 0 | E9: 0 | F9: 0 | G9: 0 | H9: 0 | I9: 0 | J9: 0 | K9: 0 | L9: 0 | M9: 0 | N9: 0 | O9: 0 | P9: 0 | Q9: 0 | R9: 0 | S9: 1 | T9: 1 | U9: 1 | V9: 1 | W9: 0 | X9: 0 | Y9: 0 | Z9: 0 | AA9: 1 | AB9: 4 | AC9: 0 | AD9: 0 | AE9: 0 | AF9: =SUM(B9:AE9) -> 9
A10: Affiliates (Refersion) | B10: 3 | C10: 1 | D10: 0 | E10: 2 | F10: 3 | G10: 1 | H10: 1 | I10: 0 | J10: 0 | K10: 2 | L10: 0 | M10: 5 | N10: 2 | O10: 2 | P10: 2 | Q10: 0 | R10: 2 | S10: 0 | T10: 0 | U10: 0 | V10: 1 | W10: 2 | X10: 4 | Y10: 3 | Z10: 3 | AA10: 2 | AB10: 9 | AC10: 8 | AD10: 1 | AE10: 1 | AF10: =SUM(B10:AE10) -> 60
A11: Email | B11: 5 | C11: 57 | D11: 23 | E11: 6 | F11: 7 | G11: 5 | H11: 11 | I11: 11 | J11: 23 | K11: 14 | L11: 5 | M11: 9 | N11: 8 | O11: 19 | P11: 18 | Q11: 19 | R11: 8 | S11: 7 | T11: 7 | U11: 4 | V11: 2 | W11: 191 | X11: 122 | Y11: 169 | Z11: 71 | AA11: 38 | AB11: 50 | AC11: 23 | AD11: 4 | AE11: 5 | AF11: =SUM(B11:AE11) -> 941
A12: All | B12: =SUM(B5:B11) -> 466.23 | C12: =SUM(C5:C11) -> 553.54 | D12: =SUM(D5:D11) -> 514.32 | E12: =SUM(E5:E11) -> 520.04 | F12: =SUM(F5:F11) -> 599.21 | G12: =SUM(G5:G11) -> 606.75 | H12: =SUM(H5:H11) -> 564.27 | I12: =SUM(I5:I11) -> 534.51 | ... AE12: =SUM(AE5:AE11) -> 271.61 | AF12: =SUM(B12:AE12) -> 29515.97
A14: Revenue | B14: 68732.42 | C14: 72150.16 | D14: 67654.24 | E14: 69524.68 | F14: 81040.74 | G14: 75727.42 | H14: 68450.74 | I14: 64261.29 | J14: 73757.33 | K14: 75181.43 | L14: 70884.65 | M14: 75544.9 | N14: 56206.3 | O14: 72316.09 | P14: 68561.95 | Q14: 68209.11 | R14: 67866.49 | S14: 89177.45 | T14: 89930.01 | U14: 106844.96 | V14: 99421.9 | W14: 130742.44 | X14: 183129.98 | Y14: 523574.65 | Z14: 320375.62 | AA14: 248293.09 | AB14: 373074.03 | AC14: 269078.11 | AD14: 52640.01 | AE14: 31699.42
A15: Meta | B15: =B14*Summary!B80 -> 72753.267 | C15: =C14*Summary!C80 -> 76594.61 | D15: =D14*Summary!D80 -> 72633.592 | E15: =E14*Summary!E80 -> 74641.696 | F15: =F14*Summary!F80 -> 86972.922 | G15: =G14*Summary!G80 -> 81172.221 | H15: =H14*Summary!H80 -> 73221.757 | I15: =I14*Summary!I80 -> 68823.842 | ... AE15: =AE14*Summary!AE80 -> 34536.518 | AF15: =SUM(B15:AE15) -> 4039600.1
A16: Google | B16: 30567.62 | C16: 32350.72 | D16: 33008.87 | E16: 39166.38 | F16: 42455.97 | G16: 48146.77 | H16: 49995.64 | I16: 46378.54 | J16: 46596.26 | K16: 50876.02 | L16: 55535.62 | M16: 54435.13 | N16: 50517.39 | O16: 55244.61 | P16: 51370.39 | Q16: 54607.17 | R16: 61927.38 | S16: 68490.91 | T16: 88024.45 | U16: 86295.03 | V16: 87700.65 | W16: 78603.95 | X16: 139593.46 | Y16: 299835.52 | Z16: 212440.76 | AA16: 164154.9 | AB16: 249887.71 | AC16: 185591.19 | AD16: 40320.29 | AE16: 40781.03 | AF16: =SUM(B16:AE16) -> 2544900.3
A17: TikTok | B17: 0 | C17: 0 | D17: 0 | E17: 0 | F17: 0 | G17: 0 | H17: 0 | I17: 0 | J17: 0 | K17: 0 | L17: 0 | M17: 0 | N17: 0 | O17: 0 | P17: 0 | Q17: 244 | R17: 0 | S17: 0 | T17: 0 | U17: 0 | V17: 0 | W17: 0 | X17: 0 | Y17: 0 | Z17: 0 | AA17: 0 | AB17: 0 | AC17: 0 | AD17: 0 | AE17: 0 | AF17: =SUM(B17:AE17) -> 244
A18: Bing | B18: 3012 | C18: 3765 | D18: 3012 | E18: 2761 | F18: 2510 | G18: 4267 | H18: 3263 | I18: 4769 | J18: 2510 | K18: 3012 | L18: 5020 | M18: 5522 | N18: 3263 | O18: 5522 | P18: 3514 | Q18: 3765 | R18: 4518 | S18: 2761 | T18: 5522 | U18: 4267 | V18: 5020 | W18: 5773 | X18: 6024 | Y18: 9287 | Z18: 5271 | AA18: 4518 | AB18: 6275 | AC18: 12550 | AD18: 2008 | AE18: 2008 | AF18: =SUM(B18:AE18) -> 135289
A19: Nextdoor | B19: 0 | C19: 0 | D19: 0 | E19: 0 | F19: 0 | G19: 0 | H19: 0 | I19: 0 | J19: 0 | K19: 0 | L19: 0 | M19: 0 | N19: 0 | O19: 0 | P19: 0 | Q19: 0 | R19: 0 | S19: 324 | T19: 184 | U19: 261.98 | V19: 202.59 | W19: 0 | X19: 0 | Y19: 0 | Z19: 0 | AA19: 468.73 | AB19: 1161.06 | AC19: 0 | AD19: 0 | AE19: 0 | AF19: =SUM(B19:AE19) -> 2602.36
A20: Affiliates (Refersion) | B20: 813.55 | C20: 244 | D20: 0 | E20: 578.65 | F20: 606.54 | G20: 315.46 | H20: 433 | I20: 0 | J20: 0 | K20: 445.76 | L20: 0 | M20: 1624.44 | N20: 438.73 | O20: 503.23 | P20: 276.37 | Q20: 0 | R20: 526.56 | S20: 0 | T20: 0 | U20: 0 | V20: 161.91 | W20: 476 | X20: 1214.94 | Y20: 472.95 | Z20: 615.78 | AA20: 469.78 | AB20: 2370.19 | AC20: 1830.85 | AD20: 343 | AE20: 68 | AF20: =SUM(B20:AE20) -> 14829.69
A21: Email | B21: 559.03 | C21: 3667.35 | D21: 1510.38 | E21: 559.68 | F21: 337.61 | G21: 590.49 | H21: 1434.31 | I21: 2811.6 | J21: 3069.32 | K21: 1285.84 | L21: 1164.2 | M21: 1089.11 | N21: 1259.65 | O21: 2842.65 | P21: 1750.29 | Q21: 1606.27 | R21: 312.69 | S21: 531.27 | T21: 1296.07 | U21: 368.47 | V21: 347.32 | W21: 43912.02 | X21: 28303.35 | Y21: 40391.88 | Z21: 15727.28 | AA21: 8244.38 | AB21: 9907.34 | AC21: 4302.47 | AD21: 793.51 | AE21: 284.09 | AF21: =SUM(B21:AE21) -> 180259.92
A22: All | B22: =SUM(B15:B21) -> 107705.47 | C22: =SUM(C15:C21) -> 116621.68 | D22: =SUM(D15:D21) -> 110164.84 | E22: =SUM(E15:E21) -> 117707.41 | F22: =SUM(F15:F21) -> 132883.04 | G22: =SUM(G15:G21) -> 134491.94 | H22: =SUM(H15:H21) -> 128347.71 | I22: =SUM(I15:I21) -> 122782.98 | ... AE22: =SUM(AE15:AE21) -> 77677.638 | AF22: =SUM(B22:AE22) -> 6917725.4
A24: Media Cost
A25: Meta | B25: =Summary!B81 -> 32434.536 | C25: =Summary!C81 -> 29070.716 | D25: =Summary!D81 -> 31545.288 | E25: =Summary!E81 -> 28085.666 | F25: =Summary!F81 -> 28087.694 | G25: =Summary!G81 -> 29676.677 | H25: =Summary!H81 -> 25760.505 | I25: =Summary!I81 -> 32668.713 | ... AE25: =Summary!AE81 -> 13572.196 | AF25: =SUM(B25:AE25) -> 1476268
A26: Google | B26: =Summary!B82 -> 4770.48 | C26: =Summary!C82 -> 5351.07 | D26: =Summary!D82 -> 6050.06 | E26: =Summary!E82 -> 7040.29 | F26: =Summary!F82 -> 8856.02 | G26: =Summary!G82 -> 8610.7 | H26: =Summary!H82 -> 7930.14 | I26: =Summary!I82 -> 8941.43 | ... AE26: =Summary!AE82 -> 5438.57 | AF26: =SUM(B26:AE26) -> 310638.05
A27: TikTok | B27: =Summary!B84 -> 0 | C27: =Summary!C84 -> 0 | D27: =Summary!D84 -> 0 | E27: =Summary!E84 -> 0 | F27: =Summary!F84 -> 0 | G27: =Summary!G84 -> 0 | H27: =Summary!H84 -> 0 | I27: =Summary!I84 -> 0 | ... AE27: =Summary!AE84 -> 0 | AF27: =SUM(B27:AE27) -> 748.65
A28: Bing | B28: =Summary!B83 -> 239.79 | C28: =Summary!C83 -> 254.86 | D28: =Summary!D83 -> 278.94 | E28: =Summary!E83 -> 309.46 | F28: =Summary!F83 -> 254.73 | G28: =Summary!G83 -> 398.68 | H28: =Summary!H83 -> 376.76 | I28: =Summary!I83 -> 415.9 | ... AE28: =Summary!AE83 -> 348.29 | AF28: =SUM(B28:AE28) -> 12497.09
A29: Nextdoor | B29: =Summary!B86 -> 0 | C29: =Summary!C86 -> 0 | D29: =Summary!D86 -> 0 | E29: =Summary!E86 -> 0 | F29: =Summary!F86 -> 0 | G29: =Summary!G86 -> 0 | H29: =Summary!H86 -> 0 | I29: =Summary!I86 -> 0 | ... AE29: =Summary!AE86 -> 0 | AF29: =SUM(B29:AE29) -> 4003.63
A30: Affiliate Fee (20%) | B30: =Summary!B88 -> 162.71 | C30: =Summary!C88 -> 61 | D30: =Summary!D88 -> 0 | E30: =Summary!E88 -> 4255.588 | F30: =Summary!F88 -> 2292.936 | G30: =Summary!G88 -> 63.09 | H30: =Summary!H88 -> 86.6 | I30: =Summary!I88 -> 0 | ... AE30: =Summary!AE88 -> 13.6 | AF30: =SUM(B30:AE30) -> 9391.734
A31: All | B31: =SUM(B25:B30) -> 37607.516 | C31: =SUM(C25:C30) -> 34737.646 | D31: =SUM(D25:D30) -> 37874.288 | E31: =SUM(E25:E30) -> 39691.004 | F31: =SUM(F25:F30) -> 39491.38 | G31: =SUM(G25:G30) -> 38749.147 | H31: =SUM(H25:H30) -> 34154.005 | I31: =SUM(I25:I30) -> 42026.043 | ... AE31: =SUM(AE25:AE30) -> 19372.656 | AF31: =SUM(B31:AE31) -> 1813547.2
A36: Revenue
A37: Revenue Woocommerce (Platform) | B37: =Summary!B8 -> 105288.85 | C37: =Summary!C8 -> 114299.05 | D37: =Summary!D8 -> 112607.15 | E37: =Summary!E8 -> 122040.63 | F37: =Summary!F8 -> 137885.87 | G37: =Summary!G8 -> 130202.04 | H37: =Summary!H8 -> 119604.06 | I37: =Summary!I8 -> 123367.12 | ... AE37: =Summary!AE8 -> 94859.28 | AF37: =sum(B37:AE37) -> 7000698.1
A38: SUM | B38: =SUM(B37) -> 105288.85 | C38: =SUM(C37) -> 114299.05 | D38: =SUM(D37) -> 112607.15 | E38: =SUM(E37) -> 122040.63 | F38: =SUM(F37) -> 137885.87 | G38: =SUM(G37) -> 130202.04 | H38: =SUM(H37) -> 119604.06 | I38: =SUM(I37) -> 123367.12 | ... AE38: =SUM(AE37) -> 94859.28 | AF38: =sum(B38:AE38) -> 7000698.1
A40: Orders
A41: Orders Woocommerce (Platform) | B41: =Summary!B54 -> 456 | C41: =Summary!C54 -> 542 | D41: =Summary!D54 -> 522 | E41: =Summary!E54 -> 542 | F41: =Summary!F54 -> 614 | G41: =Summary!G54 -> 588 | H41: =Summary!H54 -> 526 | I41: =Summary!I54 -> 538 | ... AE41: =Summary!AE54 -> 320 | AF41: =sum(B41:AE41) -> 30028
A42: SUM | B42: =SUM(B41) -> 456 | C42: =SUM(C41) -> 542 | D42: =SUM(D41) -> 522 | E42: =SUM(E41) -> 542 | F42: =SUM(F41) -> 614 | G42: =SUM(G41) -> 588 | H42: =SUM(H41) -> 526 | I42: =SUM(I41) -> 538 | ... AE42: =SUM(AE41) -> 320 | AF42: =sum(B42:AE42) -> 30028
A44: Breakdown
A45: - Hardware | B45: =Summary!B9 -> 85464.76 | C45: =Summary!C9 -> 88820.66 | D45: =Summary!D9 -> 90446.48 | E45: =Summary!E9 -> 97964.77 | F45: =Summary!F9 -> 112993.92 | G45: =Summary!G9 -> 106383.84 | H45: =Summary!H9 -> 97516.45 | I45: =Summary!I9 -> 97998.57 | ... AE45: =Summary!AE9 -> 76648.21 | AF45: =SUM(B45:AE45) -> 5630024
A46: - Add-ons | B46: =Summary!B10 -> 6707.54 | C46: =Summary!C10 -> 10578.54 | D46: =Summary!D10 -> 9279.32 | E46: =Summary!E10 -> 10715.53 | F46: =Summary!F10 -> 9847.38 | G46: =Summary!G10 -> 9498.36 | H46: =Summary!H10 -> 9096.2 | I46: =Summary!I10 -> 10900.63 | ... AE46: =Summary!AE10 -> 7659.93 | AF46: =SUM(B46:AE46) -> 497728.7
A47: - Merch | B47: =Summary!B11 -> 0 | C47: =Summary!C11 -> 0 | D47: =Summary!D11 -> 0 | E47: =Summary!E11 -> 0 | F47: =Summary!F11 -> 0 | G47: =Summary!G11 -> 0 | H47: =Summary!H11 -> 0 | I47: =Summary!I11 -> 0 | ... AE47: =Summary!AE11 -> 114 | AF47: =SUM(B47:AE47) -> 9599.38
A48: - Taxes | B48: =Summary!B13 -> 5816.55 | C48: =Summary!C13 -> 6484.85 | D48: =Summary!D13 -> 6121.35 | E48: =Summary!E13 -> 7055.33 | F48: =Summary!F13 -> 7974.57 | G48: =Summary!G13 -> 7404.84 | H48: =Summary!H13 -> 6681.41 | I48: =Summary!I13 -> 6882.92 | ... AE48: =Summary!AE13 -> 5427.14 | AF48: =SUM(B48:AE48) -> 386582.99
...

Sheet AMAZON - P&L
A1: November | B1: 45231 | C1: 45232 | D1: 45233 | E1: 45234 | F1: 45235 | G1: 45236 | H1: 45237 | I1: 45238 | J1: 45239 | K1: 45240 | L1: 45241 | M1: 45242 | N1: 45243 | O1: 45244 | P1: 45245 | Q1: 45246 | R1: 45247 | S1: 45248 | T1: 45249 | U1: 45250 | V1: 45251 | W1: 45252 | X1: 45253 | Y1: 45254 | Z1: 45255 | AA1: 45256 | AB1: 45257 | AC1: 45258 | AD1: 45259 | AE1: 45260
A2: DAY | B2: WED | C2: THU | D2: FRI | E2: SAT | F2: SUN | G2: MON | H2: TUE | I2: WED | J2: THU | K2: FRI | L2: SAT | M2: SUN | N2: MON | O2: TUE | P2: WED | Q2: THU | R2: FRI | S2: SAT | T2: SUN | U2: MON | V2: TUE | W2: WED | X2: THU | Y2: FRI | Z2: SAT | AA2: SUN | AB2: MON | AC2: TUE | AD2: WED | AE2: THU
A3: COMMENT
A4: Orders
A5: Amazon (market place) | B5: =Summary!B59 -> 42 | C5: =Summary!C59 -> 40 | D5: =Summary!D59 -> 61 | E5: =Summary!E59 -> 58 | F5: =Summary!F59 -> 74 | G5: =Summary!G59 -> 56 | H5: =Summary!H59 -> 50 | I5: =Summary!I59 -> 65 | ... AE5: =Summary!AE59 -> 3
A6: All | B6: =SUM(B5) -> 42 | C6: =SUM(C5) -> 40 | D6: =SUM(D5) -> 61 | E6: =SUM(E5) -> 58 | F6: =SUM(F5) -> 74 | G6: =SUM(G5) -> 56 | H6: =SUM(H5) -> 50 | I6: =SUM(I5) -> 65 | ... AE6: =SUM(AE5) -> 3 | AF6: =SUM(B6:AE6) -> 10840
A8: Revenue
A9: Amazon (market place) | B9: =Summary!B15 -> 9998.64 | C9: =Summary!C15 -> 10453.96 | D9: =Summary!D15 -> 16043.42 | E9: =Summary!E15 -> 15088.14 | F9: =Summary!F15 -> 19511.77 | G9: =Summary!G15 -> 15164.18 | H9: =Summary!H15 -> 12460.48 | I9: =Summary!I15 -> 14308.41 | ... AE9: =Summary!AE15 -> 540.1
A10: All | B10: =SUM(B9) -> 9998.64 | C10: =SUM(C9) -> 10453.96 | D10: =SUM(D9) -> 16043.42 | E10: =SUM(E9) -> 15088.14 | F10: =SUM(F9) -> 19511.77 | G10: =SUM(G9) -> 15164.18 | H10: =SUM(H9) -> 12460.48 | I10: =SUM(I9) -> 14308.41 | ... AE10: =SUM(AE9) -> 540.1 | AF10: =SUM(B10:AE10) -> 2411885.2
A12: Media Cost
A13: Amazon Spend | B13: =Summary!B85 -> 3233.72 | C13: =Summary!C85 -> 3207.21 | D13: =Summary!D85 -> 3213.69 | E13: =Summary!E85 -> 4807.14 | F13: =Summary!F85 -> 5368.78 | G13: =Summary!G85 -> 3970.36 | H13: =Summary!H85 -> 3978.92 | I13: =Summary!I85 -> 2768.25 | ... AE13: =Summary!AE85 -> 433.94 | AF13: =SUM(B13:AE13) -> 343549.87
A14: Amazon Platform Fee (15 %) | B14: =B9*'Data - P&L'!$C$48 -> 1499.796 | C14: =C9*'Data - P&L'!$C$48 -> 1568.094 | D14: =D9*'Data - P&L'!$C$48 -> 2406.513 | E14: =E9*'Data - P&L'!$C$48 -> 2263.221 | F14: =F9*'Data - P&L'!$C$48 -> 2926.7655 | G14: =G9*'Data - P&L'!$C$48 -> 2274.627 | H14: =H9*'Data - P&L'!$C$48 -> 1869.072 | I14: =I9*'Data - P&L'!$C$48 -> 2146.2615 | ... AE14: =AE9*'Data - P&L'!$C$48 -> 81.015 | AF14: =SUM(B14:AE14) -> 361782.79
A15: All | B15: =SUM(B13:B14) -> 4733.516 | C15: =SUM(C13:C14) -> 4775.304 | D15: =SUM(D13:D14) -> 5620.203 | E15: =SUM(E13:E14) -> 7070.361 | F15: =SUM(F13:F14) -> 8295.5455 | G15: =SUM(G13:G14) -> 6244.987 | H15: =SUM(H13:H14) -> 5847.992 | I15: =SUM(I13:I14) -> 4914.5115 | ... AE15: =SUM(AE13:AE14) -> 514.955 | AF15: =SUM(B15:AE15) -> 705332.66
A19: Amazon Orders
A20: Hardware | B20: =Summary!B16 -> 9193 | C20: =Summary!C16 -> 9677.76 | D20: =Summary!D16 -> 14877.86 | E20: =Summary!E16 -> 14028.38 | F20: =Summary!F16 -> 18099.43 | G20: =Summary!G16 -> 14185 | H20: =Summary!H16 -> 11584.43 | I20: =Summary!I16 -> 13067.81 | ... AE20: =Summary!AE16 -> 478 | AF20: =SUM(B20:AE20) -> 2235795.5
A21: Addons | B21: =Summary!B17 -> 144 | C21: =Summary!C17 -> 72 | D21: =Summary!D17 -> 117.6 | E21: =Summary!E17 -> 96 | F21: =Summary!F17 -> 142.8 | G21: =Summary!G17 -> 96 | H21: =Summary!H17 -> 94.8 | I21: =Summary!I17 -> 262.8 | ... AE21: =Summary!AE17 -> 29 | AF21: =SUM(B21:AE21) -> 14129.08
A22: Tax | B22: =Summary!B18 -> 649.85 | C22: =Summary!C18 -> 696.41 | D22: =Summary!D18 -> 1038.18 | E22: =Summary!E18 -> 947.39 | F22: =Summary!F18 -> 1262.15 | G22: =Summary!G18 -> 869.71 | H22: =Summary!H18 -> 771.81 | I22: =Summary!I18 -> 963.53 | ... AE22: =Summary!AE18 -> 33.1 | AF22: =SUM(B22:AE22) -> 157647.74
A23: Shipping | B23: =Summary!B19 -> 11.79 | C23: =Summary!C19 -> 7.49 | D23: =Summary!D19 -> 0.5 | E23: =Summary!E19 -> 7.24 | F23: =Summary!F19 -> 2.75 | G23: =Summary!G19 -> 0 | H23: =Summary!H19 -> 0.31 | I23: =Summary!I19 -> 0.5 | ... AE23: =Summary!AE19 -> 0 | AF23: =SUM(B23:AE23) -> 2723.27
A24: Gift Wrap Price | B24: =Summary!B20 -> 0 | C24: =Summary!C20 -> 0.3 | D24: =Summary!D20 -> 9.28 | E24: =Summary!E20 -> 9.13 | F24: =Summary!F20 -> 4.64 | G24: =Summary!G20 -> 13.47 | H24: =Summary!H20 -> 9.13 | I24: =Summary!I20 -> 13.77 | ... AE24: =Summary!AE20 -> 0 | AF24: =SUM(B24:AE24) -> 1589.64
A25: All Amazon | B25: =SUM(B20:B24) -> 9998.64 | C25: =SUM(C20:C24) -> 10453.96 | D25: =SUM(D20:D24) -> 16043.42 | E25: =SUM(E20:E24) -> 15088.14 | F25: =SUM(F20:F24) -> 19511.77 | G25: =SUM(G20:G24) -> 15164.18 | H25: =SUM(H20:H24) -> 12460.48 | I25: =SUM(I20:I24) -> 14308.41 | ... AE25: =SUM(AE20:AE24) -> 540.1 | AF25: =SUM(B25:AE25) -> 2411885.2
A27: Units Sold (Gross)
A28: SKU 1 - Blue | B28: 10 | C28: 5 | D28: 7 | E28: 4 | F28: 6 | G28: 8 | H28: 10 | I28: 20 | J28: 24 | K28: 17 | L28: 19 | M28: 11 | N28: 20 | O28: 21 | P28: 24 | Q28: 17 | R28: 17 | S28: 15 | T28: 39 | U28: 0 | V28: 2 | W28: 1 | X28: 2 | Y28: 0 | Z28: 0 | AA28: 0 | AB28: 0 | AC28: 0 | AD28: 0 | AE28: 2 | AF28: =sum(B28:AE28) -> 301
A29: SKU 2 - Yellow | B29: 0 | C29: 0 | D29: 0 | E29: 0 | F29: 0 | G29: 3 | H29: 1 | I29: 4 | J29: 3 | K29: 2 | L29: 3 | M29: 2 | N29: 4 | O29: 1 | P29: 0 | Q29: 0 | R29: 0 | S29: 0 | T29: 0 | U29: 0 | V29: 0 | W29: 0 | X29: 0 | Y29: 1 | Z29: 0 | AA29: 0 | AB29: 0 | AC29: 0 | AD29: 0 | AE29: 0 | AF29: =sum(B29:AE29) -> 24
A30: SKU 3 - Blue w/ Solar | B30: 27 | C30: 31 | D30: 50 | E30: 49 | F30: 58 | G30: 42 | H30: 33 | I30: 25 | J30: 56 | K30: 100 | L30: 137 | M30: 140 | N30: 127 | O30: 136 | P30: 143 | Q30: 181 | R30: 201 | S30: 232 | T30: 140 | U30: 430 | V30: 473 | W30: 545 | X30: 713 | Y30: 2841 | Z30: 1752 | AA30: 1107 | AB30: 347 | AC30: 0 | AD30: 0 | AE30: 0 | AF30: =sum(B30:AE30) -> 10116
A31: SKU 4 - Yellow w/ Solar | B31: 0 | C31: 1 | D31: 0 | E31: 1 | F31: 4 | G31: 2 | H31: 2 | I31: 9 | J31: 13 | K31: 7 | L31: 6 | M31: 7 | N31: 4 | O31: 7 | P31: 10 | Q31: 9 | R31: 10 | S31: 19 | T31: 1 | U31: 1 | V31: 2 | W31: 0 | X31: 2 | Y31: 6 | Z31: 0 | AA31: 0 | AB31: 0 | AC31: 0 | AD31: 0 | AE31: 0 | AF31: =sum(B31:AE31) -> 123
A32: SUM (SKU 1 - SKU 4) | B32: =SUM(B28:B31) -> 37 | C32: =SUM(C28:C31) -> 37 | D32: =SUM(D28:D31) -> 57 | E32: =SUM(E28:E31) -> 54 | F32: =SUM(F28:F31) -> 68 | G32: =SUM(G28:G31) -> 55 | H32: =SUM(H28:H31) -> 46 | I32: =SUM(I28:I31) -> 58 | ... AE32: =SUM(AE28:AE31) -> 2 | AF32: =sum(B32:AE32) -> 10564
A34: Wall Mount | B34: 6 | C34: 3 | D34: 5 | E34: 4 | F34: 6 | G34: 4 | H34: 4 | I34: 11 | J34: 9 | K34: 7 | L34: 9 | M34: 11 | N34: 6 | O34: 9 | P34: 8 | Q34: 24 | R34: 21 | S34: 29 | T34: 28 | U34: 36 | V34: 41 | W34: 35 | X34: 53 | Y34: 162 | Z34: 54 | AA34: 8 | AB34: 2 | AC34: 0 | AD34: 0 | AE34: 1 | AF34: 0
A35: Suet Ball Holder | AF35: =sum(B35:AE35) -> 0
A36: 3-in-1 Nutrition Set - Blue | AF36: =sum(B36:AE36) -> 0
A37: 3-in-1 Nutrition Set - Yellow | AF37: =sum(B37:AE37) -> 0
A38: Solar Roof Single - Blue | AF38: =sum(B38:AE38) -> 0
A39: Solar Roof Single - Yellow | AF39: =sum(B39:AE39) -> 0
A40: Perch Extender - Blue | AF40: =sum(B40:AE40) -> 0
A41: Perch Extender - Yellow | B41: 0 | C41: 0 | D41: 0 | E41: 0 | F41: 0 | G41: 0 | H41: 0 | I41: 0 | J41: 0 | K41: 0 | L41: 0 | M41: 0 | N41: 0 | O41: 0 | P41: 0 | Q41: 0 | R41: 0 | S41: 0 | T41: 0 | U41: 0 | V41: 0 | W41: 0 | X41: 1 | Y41: 0 | Z41: 0 | AA41: 0 | AB41: 0 | AC41: 0 | AD41: 1 | AE41: 0 | AF41: 0
A42: SUM (Add-ons) | B42: =SUM(B34:B41) -> 6 | C42: =SUM(C34:C41) -> 3 | D42: =SUM(D34:D41) -> 5 | E42: =SUM(E34:E41) -> 4 | F42: =SUM(F34:F41) -> 6 | G42: =SUM(G34:G41) -> 4 | H42: =SUM(H34:H41) -> 4 | I42: =SUM(I34:I41) -> 11 | ... AE42: =SUM(AE34:AE41) -> 1 | AF42: =sum(B42:AE42) -> 598
A45: Units Sold by country (Gross) - Only selling in US
A46: Bird Buddy - Blue - AMAZON.US | AF46: =sum(B46:AE46) -> 0
A47: Bird Buddy - Yellow - AMAZON.US
A48: Bird Buddy with Solar Roof Blue - AMAZON.US | AF48: =sum(B48:AE48) -> 0
A49: Bird Buddy with Solar Roof Yellow - AMAZON.US
...

Sheet App - P&L
A1: NOVEMBER | B1: 45231 | C1: 45232 | D1: 45233 | E1: 45234 | F1: 45235 | G1: 45236 | H1: 45237 | I1: 45238 | J1: 45239 | K1: 45240 | L1: 45241 | M1: 45242 | N1: 45243 | O1: 45244 | P1: 45245 | Q1: 45246 | R1: 45247 | S1: 45248 | T1: 45249 | U1: 45250 | V1: 45251 | W1: 45252 | X1: 45253 | Y1: 45254 | Z1: 45255 | AA1: 45256 | AB1: 45257 | AC1: 45258 | AD1: 45259 | AE1: 45260
A2: DAY | B2: WED | C2: THU | D2: FRI | E2: SAT | F2: SUN | G2: MON | H2: TUE | I2: WED | J2: THU | K2: FRI | L2: SAT | M2: SUN | N2: MON | O2: TUE | P2: WED | Q2: THU | R2: FRI | S2: SAT | T2: SUN | U2: MON | V2: TUE | W2: WED | X2: THU | Y2: FRI | Z2: SAT | AA2: SUN | AB2: MON | AC2: TUE | AD2: WED | AE2: THU
A4: Gross Revenue
A5: Apple Store Sales | B5: 486.89744 | C5: 814.04465 | D5: 739.74443 | E5: 1715.1806 | F5: 1559.7076 | G5: 1055.1993 | H5: 788.2665 | I5: 1004.4706 | J5: 1076.0191 | K5: 1253.7324 | L5: 1647.7231 | M5: 2182.4651 | N5: 848.16916 | O5: 892.46262 | P5: 1067.8864 | Q5: 1037.3426 | R5: 1258.7803 | S5: 1452.8909 | T5: 1760.0101 | U5: 985.97595 | V5: 930.86499 | W5: 588.94055 | X5: 924.14745 | Y5: 1197.6415 | Z5: 1576.0659 | AA5: 1841.4662 | AB5: 921.08585 | AC5: 1026.6748 | AD5: 1109.9303 | AE5: 1514.4123 | AF5: =sum(B5:AE5) -> 35258.198
A6: - Yearly Subscription | B6: 456.09649 | C6: 785.98649 | D6: 699.59172 | E6: 1669.5203 | F6: 1502.0491 | G6: 1006.3345 | H6: 730.33077 | I6: 941.1917 | J6: 1022.9289 | K6: 1214.4833 | L6: 1611.8431 | M6: 2137.5178 | N6: 814.63337 | O6: 846.10787 | P6: 1037.8235 | Q6: 993.87106 | R6: 1231.2245 | S6: 1416.685 | T6: 1726.3203 | U6: 970.71563 | V6: 905.98221 | W6: 546.03638 | X6: 897.23745 | Y6: 1148.8178 | Z6: 1493.5112 | AA6: 1742.6503 | AB6: 872.7233 | AC6: 963.15938 | AD6: 1063.9545 | AE6: 1438.3516 | AF6: =sum(B6:AE6) -> 33887.679
A7: - Monthly Subscription | B7: 30.800946 | C7: 28.05816 | D7: 40.15271 | E7: 45.66029 | F7: 57.658456 | G7: 48.864826 | H7: 57.935735 | I7: 63.278865 | J7: 53.090217 | K7: 39.249014 | L7: 35.88 | M7: 44.947262 | N7: 33.535796 | O7: 46.354749 | P7: 30.062955 | Q7: 43.47153 | R7: 27.555796 | S7: 36.20591 | T7: 33.689825 | U7: 15.26033 | V7: 24.88278 | W7: 42.904179 | X7: 26.91 | Y7: 48.823752 | Z7: 82.554635 | AA7: 98.815893 | AB7: 48.362546 | AC7: 63.515386 | AD7: 45.975735 | AE7: 76.0607 | AF7: =sum(B7:AE7) -> 1370.519
A8: Google Store Sales | B8: 99.62 | C8: 165.88 | D8: 71.14 | E8: 412.73 | F8: 297.94 | G8: 81.15 | H8: 179.72 | I8: 322.51 | J8: 341.54 | K8: 289.96 | L8: 415.35 | M8: 386.59 | N8: 356.13 | O8: 365.22 | P8: 263.21 | Q8: 164.08 | R8: 294.83 | S8: 396.25 | T8: 549.52 | U8: 239.29 | V8: 334.46 | W8: 167.9 | X8: 168.91 | Y8: 328.28 | Z8: 487.35 | AA8: 786.74 | AB8: 397.36 | AC8: 209.04 | AD8: 368.19 | AE8: 193.16 | AF8: =sum(B8:AE8) -> 9134.05
A9: - Yearly Subscription | B9: 93.42 | C9: 159.9 | D9: 64.79 | E9: 389.8 | F9: 291.53 | G9: 62.22 | H9: 160.91 | I9: 296.17 | J9: 328.93 | K9: 286.97 | L9: 408.98 | M9: 376.89 | N9: 346.46 | O9: 358.99 | P9: 249.44 | Q9: 161.09 | R9: 291.59 | S9: 380.3 | T9: 537.08 | U9: 223.5 | V9: 318.29 | W9: 158.44 | X9: 159.28 | Y9: 318.65 | Z9: 474.41 | AA9: 770.79 | AB9: 387.58 | AC9: 189.81 | AD9: 345.83 | AE9: 183.53 | AF9: =sum(B9:AE9) -> 8775.57
A10: - Monthly Subscription | B10: 6.2 | C10: 5.98 | D10: 6.35 | E10: 22.93 | F10: 6.41 | G10: 18.93 | H10: 18.81 | I10: 26.34 | J10: 12.61 | K10: 2.99 | L10: 6.37 | M10: 9.7 | N10: 9.67 | O10: 6.23 | P10: 13.77 | Q10: 2.99 | R10: 3.24 | S10: 15.95 | T10: 12.44 | U10: 15.79 | V10: 16.17 | W10: 9.46 | X10: 9.63 | Y10: 9.63 | Z10: 12.94 | AA10: 15.95 | AB10: 9.78 | AC10: 19.23 | AD10: 22.36 | AE10: 9.63 | AF10: =sum(B10:AE10) -> 358.48
A11: SUM | B11: =sum(B5+B8) -> 586.51744 | C11: =sum(C5+C8) -> 979.92465 | D11: =sum(D5+D8) -> 810.88444 | E11: =sum(E5+E8) -> 2127.9106 | F11: =sum(F5+F8) -> 1857.6476 | G11: =sum(G5+G8) -> 1136.3493 | H11: =sum(H5+H8) -> 967.9865 | I11: =sum(I5+I8) -> 1326.9806 | ... AE11: =sum(AE5+AE8) -> 1707.5723 | AF11: =sum(B11:AE11) -> 44392.248
A13: Gross Orders
A14: Apple Store Orders | B14: =sum(B15:B16) -> 25 | C14: =sum(C15:C16) -> 35 | D14: =sum(D15:D16) -> 36 | E14: =sum(E15:E16) -> 70 | F14: =sum(F15:F16) -> 70 | G14: =sum(G15:G16) -> 49 | H14: =sum(H15:H16) -> 43 | I14: =sum(I15:I16) -> 52 | ... AE14: =sum(AE15:AE16) -> 74 | AF14: =sum(B14:AE14) -> 1574
A15: - Yearly Subscription | B15: 15 | C15: 26 | D15: 23 | E15: 55 | F15: 51 | G15: 33 | H15: 24 | I15: 31 | J15: 34 | K15: 40 | L15: 53 | M15: 72 | N15: 27 | O15: 28 | P15: 34 | Q15: 33 | R15: 41 | S15: 47 | T15: 57 | U15: 32 | V15: 30 | W15: 18 | X15: 30 | Y15: 38 | Z15: 49 | AA15: 58 | AB15: 29 | AC15: 32 | AD15: 35 | AE15: 49 | AF15: =sum(B15:AE15) -> 1124
A16: - Monthly Subscription | B16: 10 | C16: 9 | D16: 13 | E16: 15 | F16: 19 | G16: 16 | H16: 19 | I16: 21 | J16: 17 | K16: 13 | L16: 12 | M16: 15 | N16: 11 | O16: 15 | P16: 10 | Q16: 14 | R16: 9 | S16: 12 | T16: 11 | U16: 5 | V16: 8 | W16: 14 | X16: 9 | Y16: 16 | Z16: 27 | AA16: 33 | AB16: 16 | AC16: 21 | AD16: 15 | AE16: 25 | AF16: =sum(B16:AE16) -> 450
A17: Google Store Orders | B17: =sum(B18:B19) -> 5 | C17: =sum(C18:C19) -> 7 | D17: =sum(D18:D19) -> 4 | E17: =sum(E18:E19) -> 19 | F17: =sum(F18:F19) -> 11 | G17: =sum(G18:G19) -> 8 | H17: =sum(H18:H19) -> 11 | I17: =sum(I18:I19) -> 17 | ... AE17: =sum(AE18:AE19) -> 9 | AF17: =sum(B17:AE17) -> 389
A18: - Yearly Subscription | B18: 3 | C18: 5 | D18: 2 | E18: 12 | F18: 9 | G18: 2 | H18: 5 | I18: 9 | J18: 10 | K18: 9 | L18: 13 | M18: 12 | N18: 11 | O18: 11 | P18: 8 | Q18: 7 | R18: 9 | S18: 12 | T18: 17 | U18: 7 | V18: 10 | W18: 5 | X18: 5 | Y18: 10 | Z18: 15 | AA18: 24 | AB18: 12 | AC18: 6 | AD18: 11 | AE18: 6 | AF18: =sum(B18:AE18) -> 277
A19: - Monthly Subscription | B19: 2 | C19: 2 | D19: 2 | E19: 7 | F19: 2 | G19: 6 | H19: 6 | I19: 8 | J19: 4 | K19: 1 | L19: 2 | M19: 3 | N19: 3 | O19: 2 | P19: 4 | Q19: 1 | R19: 1 | S19: 5 | T19: 4 | U19: 5 | V19: 5 | W19: 3 | X19: 3 | Y19: 3 | Z19: 4 | AA19: 5 | AB19: 3 | AC19: 6 | AD19: 7 | AE19: 3 | AF19: =sum(B19:AE19) -> 112
A20: SUM | B20: =sum(B14+B17) -> 30 | C20: =sum(C14+C17) -> 42 | D20: =sum(D14+D17) -> 40 | E20: =sum(E14+E17) -> 89 | F20: =sum(F14+F17) -> 81 | G20: =sum(G14+G17) -> 57 | H20: =sum(H14+H17) -> 54 | I20: =sum(I14+I17) -> 69 | ... AE20: =sum(AE14+AE17) -> 83 | AF20: =sum(B20:AE20) -> 1963
A21: - Yearly Subscription | B21: =B15+B18 -> 18 | C21: =C15+C18 -> 31 | D21: =D15+D18 -> 25 | E21: =E15+E18 -> 67 | F21: =F15+F18 -> 60 | G21: =G15+G18 -> 35 | H21: =H15+H18 -> 29 | I21: =I15+I18 -> 40 | ... AE21: =AE15+AE18 -> 55 | AF21: =sum(B21:AE21) -> 1401
A22: - Monthly Subscription | B22: =B16+B19 -> 12 | C22: =C16+C19 -> 11 | D22: =D16+D19 -> 15 | E22: =E16+E19 -> 22 | F22: =F16+F19 -> 21 | G22: =G16+G19 -> 22 | H22: =H16+H19 -> 25 | I22: =I16+I19 -> 29 | ... AE22: =AE16+AE19 -> 28 | AF22: =sum(B22:AE22) -> 562
A24: Refunded Revenue
A25: Apple Store Sales | B25: =sum(B26:B27) -> 0 | C25: =sum(C26:C27) -> 0 | D25: =sum(D26:D27) -> 0 | E25: =sum(E26:E27) -> 0 | F25: =sum(F26:F27) -> 14.99 | G25: =sum(G26:G27) -> 0 | H25: =sum(H26:H27) -> 0 | I25: =sum(I26:I27) -> 0 | ... AE25: =sum(AE26:AE27) -> 31.624 | AF25: =sum(B25:AE25) -> 76.604
A26: - Yearly Subscription | B26: 0 | C26: 0 | D26: 0 | E26: 0 | F26: 14.99 | G26: 0 | H26: 0 | I26: 0 | J26: 0 | K26: 0 | L26: 0 | M26: 29.99 | N26: 0 | O26: 0 | P26: 0 | Q26: 0 | R26: 0 | S26: 0 | T26: 0 | U26: 0 | V26: 0 | W26: 0 | X26: 0 | Y26: 0 | Z26: 0 | AA26: 0 | AB26: 0 | AC26: 0 | AD26: 0 | AE26: 31.624 | AF26: =sum(B26:AE26) -> 76.604
A27: - Monthly Subscription | B27: 0 | C27: 0 | D27: 0 | E27: 0 | F27: 0 | G27: 0 | H27: 0 | I27: 0 | J27: 0 | K27: 0 | L27: 0 | M27: 0 | N27: 0 | O27: 0 | P27: 0 | Q27: 0 | R27: 0 | S27: 0 | T27: 0 | U27: 0 | V27: 0 | W27: 0 | X27: 0 | Y27: 0 | Z27: 0 | AA27: 0 | AB27: 0 | AC27: 0 | AD27: 0 | AE27: 0 | AF27: =sum(B27:AE27) -> 0
A28: Google Store Sales | B28: =sum(B29:B30) -> 0 | C28: =sum(C29:C30) -> 0 | D28: =sum(D29:D30) -> 0 | E28: =sum(E29:E30) -> 0 | F28: =sum(F29:F30) -> 0 | G28: =sum(G29:G30) -> 0 | H28: =sum(H29:H30) -> 0 | I28: =sum(I29:I30) -> 0 | ... AE28: =sum(AE29:AE30) -> 0 | AF28: =sum(B28:AE28) -> 29.99
A29: - Yearly Subscription | B29: 0 | C29: 0 | D29: 0 | E29: 0 | F29: 0 | G29: 0 | H29: 0 | I29: 0 | J29: 0 | K29: 0 | L29: 0 | M29: 0 | N29: 0 | O29: 0 | P29: 0 | Q29: 29.99 | R29: 0 | S29: 0 | T29: 0 | U29: 0 | V29: 0 | W29: 0 | X29: 0 | Y29: 0 | Z29: 0 | AA29: 0 | AB29: 0 | AC29: 0 | AD29: 0 | AE29: 0 | AF29: =sum(B29:AE29) -> 29.99
A30: - Monthly Subscription | B30: 0 | C30: 0 | D30: 0 | E30: 0 | F30: 0 | G30: 0 | H30: 0 | I30: 0 | J30: 0 | K30: 0 | L30: 0 | M30: 0 | N30: 0 | O30: 0 | P30: 0 | Q30: 0 | R30: 0 | S30: 0 | T30: 0 | U30: 0 | V30: 0 | W30: 0 | X30: 0 | Y30: 0 | Z30: 0 | AA30: 0 | AB30: 0 | AC30: 0 | AD30: 0 | AE30: 0 | AF30: =sum(B30:AE30) -> 0
A31: SUM | B31: =B25+B28 -> 0 | C31: =C25+C28 -> 0 | D31: =D25+D28 -> 0 | E31: =E25+E28 -> 0 | F31: =F25+F28 -> 14.99 | G31: =G25+G28 -> 0 | H31: =H25+H28 -> 0 | I31: =I25+I28 -> 0 | ... AE31: =AE25+AE28 -> 31.624 | AF31: =sum(B31:AE31) -> 106.594
A33: Refunded Orders
A34: Apple Store orders | B34: =sum(B35:B36) -> 0 | C34: =sum(C35:C36) -> 0 | D34: =sum(D35:D36) -> 0 | E34: =sum(E35:E36) -> 0 | F34: =sum(F35:F36) -> 1 | G34: =sum(G35:G36) -> 0 | H34: =sum(H35:H36) -> 0 | I34: =sum(I35:I36) -> 0 | ... AE34: =sum(AE35:AE36) -> 1 | AF34: =sum(B34:AE34) -> 3
A35: - Yearly Subscription | B35: 0 | C35: 0 | D35: 0 | E35: 0 | F35: 1 | G35: 0 | H35: 0 | I35: 0 | J35: 0 | K35: 0 | L35: 0 | M35: 1 | N35: 0 | O35: 0 | P35: 0 | Q35: 0 | R35: 0 | S35: 0 | T35: 0 | U35: 0 | V35: 0 | W35: 0 | X35: 0 | Y35: 0 | Z35: 0 | AA35: 0 | AB35: 0 | AC35: 0 | AD35: 0 | AE35: 1
A36: - Monthly Subscription | B36: 0 | C36: 0 | D36: 0 | E36: 0 | F36: 0 | G36: 0 | H36: 0 | I36: 0 | J36: 0 | K36: 0 | L36: 0 | M36: 0 | N36: 0 | O36: 0 | P36: 0 | Q36: 0 | R36: 0 | S36: 0 | T36: 0 | U36: 0 | V36: 0 | W36: 0 | X36: 0 | Y36: 0 | Z36: 0 | AA36: 0 | AB36: 0 | AC36: 0 | AD36: 0 | AE36: 0
A37: Google Store orders | B37: =sum(B38:B39) -> 0 | C37: =sum(C38:C39) -> 0 | D37: =sum(D38:D39) -> 0 | E37: =sum(E38:E39) -> 0 | F37: =sum(F38:F39) -> 0 | G37: =sum(G38:G39) -> 0 | H37: =sum(H38:H39) -> 0 | I37: =sum(I38:I39) -> 0 | ... AE37: =sum(AE38:AE39) -> 0 | AF37: =sum(B37:AE37) -> 2
A38: - Yearly Subscription | B38: 0 | C38: 0 | D38: 0 | E38: 0 | F38: 0 | G38: 0 | H38: 0 | I38: 0 | J38: 0 | K38: 0 | L38: 0 | M38: 0 | N38: 0 | O38: 0 | P38: 0 | Q38: 2 | R38: 0 | S38: 0 | T38: 0 | U38: 0 | V38: 0 | W38: 0 | X38: 0 | Y38: 0 | Z38: 0 | AA38: 0 | AB38: 0 | AC38: 0 | AD38: 0 | AE38: 0
A39: - Monthly Subscription | B39: 0 | C39: 0 | D39: 0 | E39: 0 | F39: 0 | G39: 0 | H39: 0 | I39: 0 | J39: 0 | K39: 0 | L39: 0 | M39: 0 | N39: 0 | O39: 0 | P39: 0 | Q39: 0 | R39: 0 | S39: 0 | T39: 0 | U39: 0 | V39: 0 | W39: 0 | X39: 0 | Y39: 0 | Z39: 0 | AA39: 0 | AB39: 0 | AC39: 0 | AD39: 0 | AE39: 0
A40: SUM | B40: =B34+B37 -> 0 | C40: =C34+C37 -> 0 | D40: =D34+D37 -> 0 | E40: =E34+E37 -> 0 | F40: =F34+F37 -> 1 | G40: =G34+G37 -> 0 | H40: =H34+H37 -> 0 | I40: =I34+I37 -> 0 | ... AE40: =AE34+AE37 -> 1 | AF40: =sum(B40:AE40) -> 5
A42: Net Revenue
A43: Apple Store | B43: =B5-B25 -> 486.89744 | C43: =C5-C25 -> 814.04465 | D43: =D5-D25 -> 739.74443 | E43: =E5-E25 -> 1715.1806 | F43: =F5-F25 -> 1544.7176 | G43: =G5-G25 -> 1055.1993 | H43: =H5-H25 -> 788.2665 | I43: =I5-I25 -> 1004.4706 | ... AE43: =AE5-AE25 -> 1482.7883 | AF43: =sum(B43:AE43) -> 35181.594
A44: - Yearly Subscription | B44: =B6-B26 -> 456.09649 | C44: =C6-C26 -> 785.98649 | D44: =D6-D26 -> 699.59172 | E44: =E6-E26 -> 1669.5203 | F44: =F6-F26 -> 1487.0591 | G44: =G6-G26 -> 1006.3345 | H44: =H6-H26 -> 730.33077 | I44: =I6-I26 -> 941.1917 | ... AE44: =AE6-AE26 -> 1406.7276 | AF44: =sum(B44:AE44) -> 33811.075
A45: - Monthly Subscription | B45: =B7-B27 -> 30.800946 | C45: =C7-C27 -> 28.05816 | D45: =D7-D27 -> 40.15271 | E45: =E7-E27 -> 45.66029 | F45: =F7-F27 -> 57.658456 | G45: =G7-G27 -> 48.864826 | H45: =H7-H27 -> 57.935735 | I45: =I7-I27 -> 63.278865 | ... AE45: =AE7-AE27 -> 76.0607 | AF45: =sum(B45:AE45) -> 1370.519
...

Sheet Digital Marketplaces
A1: NOVEMBER | B1: 45231 | C1: 45232 | D1: 45233 | E1: 45234 | F1: 45235 | G1: 45236 | H1: 45237 | I1: 45238 | J1: 45239 | K1: 45240 | L1: 45241 | M1: 45242 | N1: 45243 | O1: 45244 | P1: 45245 | Q1: 45246 | R1: 45247 | S1: 45248 | T1: 45249 | U1: 45250 | V1: 45251 | W1: 45252 | X1: 45253 | Y1: 45254 | Z1: 45255 | AA1: 45256 | AB1: 45257 | AC1: 45258 | AD1: 45259 | AE1: 45321
A2: DAY | B2: MON | C2: TUE | D2: WED | E2: THU | F2: FRI | G2: SAT | H2: SUN | I2: MON | J2: TUE | K2: WED | L2: THU | M2: FRI | N2: SAT | O2: SUN | P2: MON | Q2: TUE | R2: WED | S2: THU | T2: FRI | U2: SAT | V2: SUN | W2: MON | X2: TUE | Y2: WED | Z2: THU | AA2: FRI | AB2: SAT | AC2: SUN | AD2: MON | AE2: TUE
A3: Rachio (Shopify)
A4: Revenue | B4: =Summary!B22 -> 211.2186 | C4: =Summary!C22 -> 0 | D4: =Summary!D22 -> 0 | E4: =Summary!E22 -> 21715.501 | F4: =Summary!F22 -> 10825.909 | G4: =Summary!G22 -> 47060.884 | H4: =Summary!H22 -> 6559.2291 | I4: =Summary!I22 -> 254.72539 | ... AE4: =Summary!AE22 -> 891.54416 | AF4: =sum(B4:AE4) -> 188200
A5: Breakdown
A6: - Tax | B6: =Summary!B24 -> 12.2186 | C6: =Summary!C24 -> 0 | D6: =Summary!D24 -> 0 | E6: =Summary!E24 -> 1256.201 | F6: =Summary!F24 -> 626.25851 | G6: =Summary!G24 -> 2722.3839 | H6: =Summary!H24 -> 379.43911 | I6: =Summary!I24 -> 14.735386 | ... AE6: =Summary!AE24 -> 51.574158 | AF6: =sum(B6:AE6) -> 10887.017
A7: - Shipping | B7: =Summary!B25 | C7: =Summary!C25 | D7: =Summary!D25 | E7: =Summary!E25 | F7: =Summary!F25 | G7: =Summary!G25 | H7: =Summary!H25 | I7: =Summary!I25 | ... AE7: =Summary!AE25 | AF7: =sum(B7:AE7) -> 0
A8: Orders | B8: =Summary!B58 | C8: =Summary!C58 | D8: =Summary!D58 | E8: =Summary!E58 | F8: =Summary!F58 | G8: =Summary!G58 | H8: =Summary!H58 | I8: =Summary!I58 | ... AE8: =Summary!AE58 | AF8: =sum(B8:AE8) -> 0
A10: Rachio Fees (20%) | B10: =Summary!B89 -> 42.24372 | C10: =Summary!C89 -> 0 | D10: =Summary!D89 -> 0 | E10: =Summary!E89 -> 4343.1002 | F10: =Summary!F89 -> 2165.1817 | G10: =Summary!G89 -> 9412.1768 | H10: =Summary!H89 -> 1311.8458 | I10: =Summary!I89 -> 50.945077 | ... AE10: =Summary!AE89 -> 178.30883
A12: Units Sold (Gross) - Rachio
A13: SKU 1 - Blue | B13: 1 | C13: 0 | D13: 0 | E13: 7 | F13: 5 | G13: 6 | H13: 2 | I13: 1 | J13: 1 | K13: 0 | L13: 0 | M13: 0 | N13: 0 | O13: 0 | P13: 2 | Q13: 1 | R13: 0 | S13: 0 | T13: 0 | U13: 1 | V13: 0 | W13: 0 | X13: 2 | Y13: 2 | Z13: 1 | AA13: 4 | AB13: 5 | AC13: 1 | AD13: 1 | AE13: 1 | AF13: =sum(B13:AE13) -> 44
A14: SKU 2 - Yellow | B14: 0 | C14: 0 | D14: 0 | E14: 3 | F14: 0 | G14: 5 | H14: 0 | I14: 0 | J14: 0 | K14: 0 | L14: 0 | M14: 0 | N14: 0 | O14: 0 | P14: 0 | Q14: 0 | R14: 1 | S14: 0 | T14: 0 | U14: 0 | V14: 0 | W14: 0 | X14: 0 | Y14: 1 | Z14: 0 | AA14: 3 | AB14: 2 | AC14: 1 | AD14: 0 | AE14: 0 | AF14: =sum(B14:AE14) -> 16
A15: SKU 3 - Blue w/ Solar | B15: 0 | C15: 0 | D15: 0 | E15: 43 | F15: 23 | G15: 101 | H15: 13 | I15: 0 | J15: 9 | K15: 3 | L15: 2 | M15: 2 | N15: 1 | O15: 1 | P15: 2 | Q15: 27 | R15: 4 | S15: 5 | T15: 6 | U15: 6 | V15: 5 | W15: 5 | X15: 13 | Y15: 14 | Z15: 2 | AA15: 32 | AB15: 61 | AC15: 23 | AD15: 1 | AE15: 2 | AF15: =sum(B15:AE15) -> 406
A16: SKU 4 - Yellow w/ Solar | B16: 0 | C16: 0 | D16: 0 | E16: 18 | F16: 8 | G16: 38 | H16: 6 | I16: 0 | J16: 1 | K16: 0 | L16: 1 | M16: 2 | N16: 3 | O16: 0 | P16: 3 | Q16: 7 | R16: 1 | S16: 2 | T16: 1 | U16: 1 | V16: 3 | W16: 3 | X16: 2 | Y16: 2 | Z16: 0 | AA16: 14 | AB16: 19 | AC16: 8 | AD16: 2 | AE16: 0 | AF16: =sum(B16:AE16) -> 145
A17: SUM (SKU 1 - SKU 4) | B17: =SUM(B13:B16) -> 1 | C17: =SUM(C13:C16) -> 0 | D17: =SUM(D13:D16) -> 0 | E17: =SUM(E13:E16) -> 71 | F17: =SUM(F13:F16) -> 36 | G17: =SUM(G13:G16) -> 150 | H17: =SUM(H13:H16) -> 21 | I17: =SUM(I13:I16) -> 1 | ... AE17: =SUM(AE13:AE16) -> 3 | AF17: =sum(B17:AE17) -> 611
A19: Wall Mount | B19: 0 | C19: 0 | D19: 0 | E19: 0 | F19: 0 | G19: 0 | H19: 0 | I19: 0 | J19: 0 | K19: 0 | L19: 0 | M19: 0 | N19: 0 | O19: 0 | P19: 0 | Q19: 0 | R19: 0 | S19: 0 | T19: 0 | U19: 0 | V19: 0 | W19: 0 | X19: 0 | Y19: 0 | Z19: 0 | AA19: 0 | AB19: 0 | AC19: 0 | AD19: 0 | AE19: 0 | AF19: =sum(B19:AE19) -> 0
A20: Suet Ball Holder | B20: 0 | C20: 0 | D20: 0 | E20: 0 | F20: 0 | G20: 0 | H20: 0 | I20: 0 | J20: 0 | K20: 0 | L20: 0 | M20: 0 | N20: 0 | O20: 0 | P20: 0 | Q20: 0 | R20: 0 | S20: 0 | T20: 0 | U20: 0 | V20: 0 | W20: 0 | X20: 0 | Y20: 0 | Z20: 0 | AA20: 0 | AB20: 0 | AC20: 0 | AD20: 0 | AE20: 0 | AF20: =sum(B20:AE20) -> 0
A21: 3-in-1 Nutrition Set - Blue | B21: 0 | C21: 0 | D21: 0 | E21: 0 | F21: 0 | G21: 0 | H21: 0 | I21: 0 | J21: 0 | K21: 0 | L21: 0 | M21: 0 | N21: 0 | O21: 0 | P21: 0 | Q21: 0 | R21: 0 | S21: 0 | T21: 0 | U21: 0 | V21: 0 | W21: 0 | X21: 0 | Y21: 0 | Z21: 0 | AA21: 0 | AB21: 0 | AC21: 0 | AD21: 0 | AE21: 0 | AF21: =sum(B21:AE21) -> 0
A22: 3-in-1 Nutrition Set - Yellow | B22: 0 | C22: 0 | D22: 0 | E22: 0 | F22: 0 | G22: 0 | H22: 0 | I22: 0 | J22: 0 | K22: 0 | L22: 0 | M22: 0 | N22: 0 | O22: 0 | P22: 0 | Q22: 0 | R22: 0 | S22: 0 | T22: 0 | U22: 0 | V22: 0 | W22: 0 | X22: 0 | Y22: 0 | Z22: 0 | AA22: 0 | AB22: 0 | AC22: 0 | AD22: 0 | AE22: 0 | AF22: =sum(B22:AE22) -> 0
A23: Solar Roof Single - Blue | B23: 0 | C23: 0 | D23: 0 | E23: 0 | F23: 0 | G23: 0 | H23: 0 | I23: 0 | J23: 0 | K23: 0 | L23: 0 | M23: 0 | N23: 0 | O23: 0 | P23: 0 | Q23: 0 | R23: 0 | S23: 0 | T23: 0 | U23: 0 | V23: 0 | W23: 0 | X23: 0 | Y23: 0 | Z23: 0 | AA23: 0 | AB23: 0 | AC23: 0 | AD23: 0 | AE23: 0 | AF23: =sum(B23:AE23) -> 0
A24: Solar Roof Single - Yellow | B24: 0 | C24: 0 | D24: 0 | E24: 0 | F24: 0 | G24: 0 | H24: 0 | I24: 0 | J24: 0 | K24: 0 | L24: 0 | M24: 0 | N24: 0 | O24: 0 | P24: 0 | Q24: 0 | R24: 0 | S24: 0 | T24: 0 | U24: 0 | V24: 0 | W24: 0 | X24: 0 | Y24: 0 | Z24: 0 | AA24: 0 | AB24: 0 | AC24: 0 | AD24: 0 | AE24: 0 | AF24: =sum(B24:AE24) -> 0
A25: Perch Extender - Blue | B25: 0 | C25: 0 | D25: 0 | E25: 0 | F25: 0 | G25: 0 | H25: 0 | I25: 0 | J25: 0 | K25: 0 | L25: 0 | M25: 0 | N25: 0 | O25: 0 | P25: 0 | Q25: 0 | R25: 0 | S25: 0 | T25: 0 | U25: 0 | V25: 0 | W25: 0 | X25: 0 | Y25: 0 | Z25: 0 | AA25: 0 | AB25: 0 | AC25: 0 | AD25: 0 | AE25: 0 | AF25: =sum(B25:AE25) -> 0
