Workbook
Name zsupermetrics_ru0GDtbZzDLHQOQtJJ6K08MvUDyyp7: #REF!
Name zsupermetrics_DQl8lUbpTRu3fayaJJi7lVfOGKjNU4: 'OLD Data - P&L'!$A$3:$A$4
Name zsupermetrics_BioPyGBzcBsy60UCQmPcTuFReEmghI: 'OLD Data - P&L'!$B$2:$B$3
Name zsupermetrics_refreshAll: SupermetricsQueries!$H$5
Name zsupermetrics_n3GtLgiKpTmd2pYmQNMuq6TPD0qE0b: #REF!
Name zsupermetrics_refreshAllSilent: SupermetricsQueries!$H$6
Name zsupermetrics_Mgms9p0QzysYvrIhnsKACeVBVxfIEO: #REF!
Name zsupermetrics_Mgms9p0QzysYvrIhnsKACeVBVxfIEO: 'OLD Data - P&L'!$A$2:$A$3
Name zsupermetrics_forceRefresh: SupermetricsQueries!$H$4
Name zsupermetrics_wbYMmT0YL9bAN0yhimW0ziPFnia9Dx: #REF!
Name zsupermetrics_iNpyVy90bWCI0yUaFQpxOtzWMa6sW4: #REF!
Name zsupermetrics_xwoIpANxRm908eDp5oKTwQpEI8gvD4: #REF!
Name zsupermetrics_n3GtLgiKpTmd2pYmQNMuq6TPD0qE0b: 'OLD Data - P&L'!$B$4:$B$5
Name rdataslayer_42b112e4e4be4305bb4c1be75e2dd549: 'OLD Data - P&L'!$B$2:$C$3
Name zsupermetrics_9i4W4hgd80uRpQLMeX0eRnESN8gjyv: #REF!
Name zsupermetrics_5bmwtOpHUbSYmDMeuCPkrxaojTprPP: #REF!
Name rdataslayer_3753ddf3234e496aa261974a0222e193: 'OLD Data - P&L'!$H$2:$I$2
Name zsupermetrics_SGBxROnInO9rFyh3H7j2Lldx0Bdc5v: #REF!
Name zsupermetrics_pxuhRTEmIU93xSgKclyxajD0fCZ6rF: #REF!
Name zsupermetrics_ru0GDtbZzDLHQOQtJJ6K08MvUDyyp7: 'OLD Data - P&L'!$B$4:$B$5
Name zsupermetrics_qWp7V908pNEYMtfv8QZvSTeDnBAHOU: 'OLD Data - P&L'!$B$5:$C$13
Name rdataslayer_4a0f150f4f2f4e4f85c890c75b7a1fa4: #REF!
Name zsupermetrics_HgZqhorObHOtZHuyJjpmyYaEPoYntx: #REF!
Name zsupermetrics_YsFuuYtr8vOdNXCCPiFJIO38NP4b2T: #REF!
Name zsupermetrics_DQl8lUbpTRu3fayaJJi7lVfOGKjNU4: #REF!
Name zsupermetrics_YVuzfmsfdurz7Ldl84Rfns8oka6LsS: #REF!
Name zsupermetrics_4VkB7ij7WO0JjKBEgvjB2GHjSy2Egm: #REF!
Name zsupermetrics_9i4W4hgd80uRpQLMeX0eRnESN8gjyv: 'OLD Data - P&L'!$C$13
Name zsupermetrics_lx4cNai7gT6tH4j08ZRkI21Qlpjioi: #REF!
Name rdataslayer_d70e473bcafe40a3aa834ce157fb2ba3: #REF!
Name zsupermetrics_NugLlrQxlKiqhxQae8EFpITBm1pLCj: 'OLD Data - P&L'!$B$6:$C$13
Name zsupermetrics_8xojRjNDjo2jWHGDWjFEhflhyIq3Hq: 'OLD Summary'!$K$8:$K$24
Name rdataslayer_3753ddf3234e496aa261974a0222e193: #REF!
Name zsupermetrics_iNpyVy90bWCI0yUaFQpxOtzWMa6sW4: 'OLD Data - P&L'!$A$2:$A$3
Name rdataslayer_4a0f150f4f2f4e4f85c890c75b7a1fa4: 'OLD Data - P&L'!$D$2:$E$3
Name zsupermetrics_BioPyGBzcBsy60UCQmPcTuFReEmghI: #REF!
Name zsupermetrics_qWp7V908pNEYMtfv8QZvSTeDnBAHOU: #REF!
Name zsupermetrics_8xojRjNDjo2jWHGDWjFEhflhyIq3Hq: #REF!
Name zsupermetrics_wbYMmT0YL9bAN0yhimW0ziPFnia9Dx: 'OLD Data - P&L'!$A$2:$A$3
Name zsupermetrics_4VkB7ij7WO0JjKBEgvjB2GHjSy2Egm: 'OLD Data - P&L'!$B$4:$C$10
Name zsupermetrics_lx4cNai7gT6tH4j08ZRkI21Qlpjioi: 'OLD Data - P&L'!$B$4:$C$13
Name rdataslayer_42b112e4e4be4305bb4c1be75e2dd549: #REF!
Name rdataslayer_adf57e64065742daa5b4161161b1c3ca: #REF!
Name rdataslayer_adf57e64065742daa5b4161161b1c3ca: 'OLD Data - P&L'!$B$4:$D$5
Name zsupermetrics_NugLlrQxlKiqhxQae8EFpITBm1pLCj: #REF!
Name zsupermetrics_xwoIpANxRm908eDp5oKTwQpEI8gvD4: #REF!
Name zsupermetrics_YsFuuYtr8vOdNXCCPiFJIO38NP4b2T: 'OLD Data - P&L'!$B$4:$C$13
Name rdataslayer_d70e473bcafe40a3aa834ce157fb2ba3: 'OLD Data - P&L'!$C$8:$D$9
Name zsupermetrics_HgZqhorObHOtZHuyJjpmyYaEPoYntx: 'OLD Data - P&L'!$B$4:$B$5

Sheet Summary
A1: 45261 | B1: 45261 | C1: 45262 | D1: 45263 | E1: 45264 | F1: 45265 | G1: 45266 | H1: 45267 | I1: 45268 | J1: 45269 | K1: 45270 | L1: 45271 | M1: 45272 | N1: 45273 | O1: 45274 | P1: 45275 | Q1: 45276 | R1: 45277 | S1: 45278 | T1: 45279 | U1: 45280 | V1: 45281 | W1: 45282 | X1: 45283 | Y1: 45284 | Z1: 45285 | AA1: 45286 | AB1: 45287 | AC1: 45288 | AD1: 45289 | AE1: 45290 | AF1: 45291
B2: FRI | C2: SAT | D2: SUN | E2: MON | F2: TUE | G2: WED | H2: THU | I2: FRI | J2: SAT | K2: SUN | L2: MON | M2: TUE | N2: WED | O2: THU | P2: FRI | Q2: SAT | R2: SUN | S2: MON | T2: TUE | U2: WED | V2: THU | W2: FRI | X2: SAT | Y2: SUN | Z2: MON | AA2: TUE | AB2: WED | AC2: THU | AD2: FRI | AE2: SAT | AF2: SUN
A3: Weekend Work | C3: Peco | D3: Peco | J3: Peco | K3: Peco | P3: Peco | Q3: Peco | R3: Peco | X3: Peco | Y3: Peco | Z3: Peco | AA3: Peco | AD3: Peter | AE3: Peter | AF3: Peter
A4: Notes | B4: Christmas Sale (-20%)
F5: 10:29 Yellow preferred version & blue version +$10 | H5: 10.30 Blue version additional +$10 & SKU 1+SKU 5 combination active | I5: Blue version additional $20 from 17:47 | K5: Featured on CBS Sunday Morning | L5: Blue BB out of stock at 14:25 SKU 3 live at 10:15 / Christmas Email Offer | N5: 16:05 changed US & Canada to expedited shipping, order #119304 16:06 +$20 on Bird Buddy Yellow units | O5: 9:23 - SKU3 & Pro Bundle Blue out of Stock 14:22 Pricing change on Yellow BBs (original prices, Wall Mount & 3-in-1 increase by $10), only pro bundle -20% 15:40 Amazon button on Smart bird feeder with solar roof | P5: 13:20 SKU2 +$10 ($249) SKU4 +$10 ($309) Solar Roof +$10 ($99) Wall Mount +$10 (49) Pro bundle $327 (20% off) Shipping US +$10 ($45) Add-on Shop - Yellow default | U5: 16:32 - SKU2 - $10 down ($239), SKU4 $10 down ($299), Pro bundle ($317) | V5: 14:12 - Blue & Yellow Pro Bundle $329 (added Suet Ball Holder, and +$1 per item for Wall Mount and 3-in-1), Suet Ball Holder back in stock for $24. Wall Mount price down to $39 (-$10). | AD5: 11:35 - Yellow Pro added perch extender (price goes up for $31 to $360), perch extended is back on stock | AE5: Twitter traffic spike
L6: SKU3 price increased to $349 at 11.00
A8: DTC Revenue | B8: 182179.74 | C8: 239359.12 | D8: 309347.58 | E8: 305578.38 | F8: 298114.36 | G8: 324866.09 | H8: 330539.93 | I8: 353516.62 | J8: 360109.93 | K8: 544223.4 | L8: 507957.88 | M8: 441290.61 | N8: 378497.6 | O8: 289096.22 | P8: 234608.6 | Q8: 195884.99 | R8: 135037.9 | S8: 152636.6 | T8: 143733.9 | U8: 111010.22 | V8: 53985.74 | W8: 45371.98 | X8: 32430.01 | Y8: 28394.59 | Z8: 46187.9 | AA8: 38487.01 | AB8: 31524.34 | AC8: 31682.88 | AD8: 35924.11 | AE8: 45927.46 | AF8: 44158.82
A9: - Hardware | B9: 148896.28 | C9: 196722.13 | D9: 255328.76 | E9: 254086.11 | F9: 245877.15 | G9: 268135.33 | H9: 267062.57 | I9: 283105.87 | J9: 287226.6 | K9: 431622.54 | L9: 410276.54 | M9: 363565.77 | N9: 306167.33 | O9: 229526.48 | P9: 185579.36 | Q9: 151020.91 | R9: 104311.3 | S9: 119135.96 | T9: 111973.84 | U9: 89333.68 | V9: 44585.65 | W9: 36770.85 | X9: 26184.13 | Y9: 21720.95 | Z9: 30855.55 | AA9: 22390.5 | AB9: 19166.75 | AC9: 19296.05 | AD9: 20772.9 | AE9: 30281.55 | AF9: 29212.93
A10: - Add-ons | B10: 12027.92 | C10: 14248.12 | D10: 17773.14 | E10: 15874.79 | F10: 15079.85 | G10: 17998.27 | H10: 24577.23 | I10: 29469.5 | J10: 30723.45 | K10: 49963.65 | L10: 37955.26 | M10: 25861.27 | N10: 20871.96 | O10: 11810.97 | P10: 8711.89 | Q10: 9843.64 | R10: 6337.85 | S10: 6090.44 | T10: 5671.06 | U10: 5104.32 | V10: 3339.05 | W10: 3379.65 | X10: 2646.87 | Y10: 3345.6 | Z10: 9404.45 | AA10: 10875.1 | AB10: 8185.4 | AC10: 8230.9 | AD10: 10525.15 | AE10: 9954.55 | AF10: 9678.87
A11: - Merch | B11: 161 | C11: 238.99 | D11: 255.97 | E11: 49.89 | F11: 1934.95 | G11: 539.98 | H11: 335.15 | I11: 635.5 | J11: 642.95 | K11: 689.48 | L11: 825.94 | M11: 686.08 | N11: 608.47 | O11: 358.15 | P11: 434.98 | Q11: 285 | R11: 187.15 | S11: 304 | T11: 152.99 | U11: 298.97 | V11: 76 | W11: 86.99 | X11: 57 | Y11: 35.15 | Z11: 139.99 | AA11: 114 | AB11: 47 | AC11: 38 | AD11: 57 | AE11: 38 | AF11: 55.99
A12: - Taxes | B12: 10324.54 | C12: 13474.88 | D12: 17959.71 | E12: 17167.59 | F12: 16904.41 | G12: 18912.51 | H12: 19444.98 | I12: 20395.75 | J12: 21341.93 | K12: 32117.73 | L12: 28913.14 | M12: 25567.49 | N12: 21859.84 | O12: 16620.62 | P12: 13332.37 | Q12: 11155.44 | R12: 7731.6 | S12: 8521.2 | T12: 8206.01 | U12: 6368.25 | V12: 3160.04 | W12: 2684.49 | X12: 1517.01 | Y12: 1492.89 | Z12: 2357.91 | AA12: 1977.41 | AB12: 1750.19 | AC12: 1757.93 | AD12: 1869.06 | AE12: 2428.36 | AF12: 2431.03
A13: - Shipping | B13: 10770 | C13: 14675 | D13: 18030 | E13: 18400 | F13: 18318 | G13: 19280 | H13: 19120 | I13: 19910 | J13: 20175 | K13: 29830 | L13: 29987 | M13: 25610 | N13: 28990 | O13: 30780 | P13: 26550 | Q13: 23580 | R13: 16470 | S13: 18585 | T13: 17730 | U13: 9905 | V13: 2825 | W13: 2450 | X13: 2025 | Y13: 1800 | Z13: 3430 | AA13: 3130 | AB13: 2375 | AC13: 2360 | AD13: 2700 | AE13: 3225 | AF13: 2780
A14: Amazon Revenue | B14: =SUM(B15:B19) -> 253.34 | C14: =SUM(C15:C19) -> 0 | D14: =SUM(D15:D19) -> 239 | E14: =SUM(E15:E19) -> 316.94 | F14: =SUM(F15:F19) -> 0 | G14: =SUM(G15:G19) -> 0 | H14: =SUM(H15:H19) -> 252.15 | I14: =SUM(I15:I19) -> 0 | ... AF14: =SUM(AF15:AF19) -> 10388.6
A15: - Hardware | B15: 239 | C15: 0 | D15: 239 | E15: 299 | F15: 0 | G15: 0 | H15: 239 | I15: 0 | J15: 2980.24 | K15: 16437.68 | L15: 1625 | M15: 1600.12 | N15: 3068.56 | O15: 12871.26 | P15: 28791.72 | Q15: 79480.27 | R15: 235448.23 | S15: 189522.92 | T15: 173616.13 | U15: 73448.75 | V15: 59661.41 | W15: 49452.96 | X15: 45309.13 | Y15: 27065.29 | Z15: 17551.03 | AA15: 17695.82 | AB15: 7410.12 | AC15: 9221.68 | AD15: 6276.56 | AE15: 10357.68 | AF15: 9586.55
A16: - Add-ons | B16: 0 | C16: 0 | D16: 0 | E16: 0 | F16: 0 | G16: 0 | H16: 0 | I16: 0 | J16: 87 | K16: 29 | L16: 0 | M16: 29 | N16: 0 | O16: 0 | P16: 116 | Q16: 348 | R16: 1508 | S16: 1218 | T16: 1305 | U16: 783 | V16: 406 | W16: 493 | X16: 667 | Y16: 551 | Z16: 2146 | AA16: 2610 | AB16: 1943 | AC16: 812 | AD16: 29 | AE16: 58 | AF16: 87
A17: - Tax | B17: 14.34 | C17: 0 | D17: 0 | E17: 17.94 | F17: 0 | G17: 0 | H17: 13.15 | I17: 0 | J17: 202.17 | K17: 1189.4 | L17: 105.88 | M17: 114.74 | N17: 184.35 | O17: 838.71 | P17: 2028.05 | Q17: 5562.66 | R17: 16741.34 | S17: 13366.17 | T17: 12080.12 | U17: 5095.44 | V17: 4217.98 | W17: 3680.14 | X17: 3107.29 | Y17: 1949.06 | Z17: 1224.05 | AA17: 1412.66 | AB17: 655.22 | AC17: 688.12 | AD17: 426.66 | AE17: 703.83 | AF17: 710.31
A18: - Shipping | B18: 0 | C18: 0 | D18: 0 | E18: 0 | F18: 0 | G18: 0 | H18: 0 | I18: 0 | J18: 0.32 | K18: 7.23 | L18: 0 | M18: 0.16 | N18: 14.06 | O18: 7.23 | P18: 7.23 | Q18: 61.39 | R18: 100.18 | S18: 135.52 | T18: 91.67 | U18: 10.58 | V18: 26.32 | W18: 26.56 | X18: 51.68 | Y18: 14.14 | Z18: 7.98 | AA18: 10.07 | AB18: 13.68 | AC18: 0.24 | AD18: 7.07 | AE18: 0.24 | AF18: 0.08
A19: - Gift Wrap | B19: 0 | C19: 0 | D19: 0 | E19: 0 | F19: 0 | G19: 0 | H19: 0 | I19: 0 | J19: 14.15 | K19: 27.45 | L19: 0 | M19: 0.34 | N19: 0.17 | O19: 5 | P19: 13.98 | Q19: 68.54 | R19: 325.34 | S19: 210.47 | T19: 229.44 | U19: 70.75 | V19: 65.41 | W19: 108.46 | X19: 81.52 | Y19: 40.75 | Z19: 36.88 | AA19: 18.79 | AB19: 4.83 | AC19: 0.51 | AD19: 4.66 | AE19: 9.49 | AF19: 4.66
A20: Digital Marketplaces Revenue | B20: =SUM(B25,B21) -> 955.22816 | C20: =SUM(C25,C21) -> 318.40939 | D20: =SUM(D25,D21) -> 636.81877 | E20: =SUM(E25,E21) -> 318.40939 | F20: =SUM(F25,F21) -> 318.40939 | G20: =SUM(G25,G21) -> 0 | H20: =SUM(H25,H21) -> 1183.461 | I20: =SUM(I25,I21) -> 4929.1098 | ... AF20: =SUM(AF25,AF21) -> 0
A21: Rachio | B21: =SUM(B22:B24) -> 955.22816 | C21: =SUM(C22:C24) -> 318.40939 | D21: =SUM(D22:D24) -> 636.81877 | E21: =SUM(E22:E24) -> 318.40939 | F21: =SUM(F22:F24) -> 318.40939 | G21: =SUM(G22:G24) -> 0 | H21: =SUM(H22:H24) -> 0 | I21: =SUM(I22:I24) -> 955.22816 | ... AF21: =SUM(AF22:AF24) -> 0
A22: - Hardware | B22: 899.97 | C22: 299.99 | D22: 599.98 | E22: 299.99 | F22: 299.99 | G22: 0 | H22: 0 | I22: 899.97 | J22: 839.97 | K22: 839.97 | L22: 1199.96 | M22: 24719.17 | N22: 7619.74 | O22: 0 | P22: 0 | Q22: 899.97 | R22: 299.99 | S22: 599.98 | T22: 599.98 | U22: 0 | V22: 0 | W22: 0 | X22: 0 | Y22: 0 | Z22: 0 | AA22: 0 | AB22: 0 | AC22: 0 | AD22: 0 | AE22: 0 | AF22: 0
A23: - Tax | B23: =0.0614*B22 -> 55.258158 | C23: =0.0614*C22 -> 18.419386 | D23: =0.0614*D22 -> 36.838772 | E23: =0.0614*E22 -> 18.419386 | F23: =0.0614*F22 -> 18.419386 | G23: =0.0614*G22 -> 0 | H23: =0.0614*H22 -> 0 | I23: =0.0614*I22 -> 55.258158 | ... AF23: =0.0614*AF22 -> 0
A24: - Shipping | B24: 0 | C24: 0 | D24: 0 | E24: 0 | F24: 0 | G24: 0 | H24: 0 | I24: 0 | J24: 0 | K24: 0 | L24: 0 | M24: 0 | N24: 0 | O24: 0 | P24: 0 | Q24: 0 | R24: 0 | S24: 0 | T24: 0 | U24: 0 | V24: 0 | W24: 0 | X24: 0 | Y24: 0 | Z24: 0 | AA24: 0 | AB24: 0 | AC24: 0 | AD24: 0 | AE24: 0 | AF24: 0
A25: Weatherflow | H25: =SUM(H26:H28) -> 1183.461 | I25: =SUM(I26:I28) -> 3973.8816 | J25: =SUM(J26:J28) -> 0 | K25: =SUM(K26:K28) -> 211.2186 | L25: =SUM(L26:L28) -> 211.2186 | M25: =SUM(M26:M28) -> 1183.461 | N25: =SUM(N26:N28) -> 676.1118 | O25: =SUM(O26:O28) -> 0 | ... AF25: =SUM(AF26:AF28) -> 0
A26: - Hardware | H26: 1115 | I26: 3744 | J26: 0 | K26: 199 | L26: 199 | M26: 1115 | N26: 637 | O26: 0 | P26: 0 | Q26: 0 | R26: 239 | S26: 0 | T26: 0 | U26: 0 | V26: 0 | W26: 0 | X26: 0 | Y26: 0 | Z26: 0 | AA26: 0 | AB26: 0 | AC26: 0 | AD26: 0 | AE26: 0 | AF26: 0
A27: - Tax | H27: =0.0614*H26 -> 68.461 | I27: =0.0614*I26 -> 229.8816 | J27: =0.0614*J26 -> 0 | K27: =0.0614*K26 -> 12.2186 | L27: =0.0614*L26 -> 12.2186 | M27: =0.0614*M26 -> 68.461 | N27: =0.0614*N26 -> 39.1118 | O27: =0.0614*O26 -> 0 | ... AF27: =0.0614*AF26 -> 0
A28: - Shipping | H28: 0 | I28: 0 | J28: 0 | K28: 0 | L28: 0 | M28: 0 | N28: 0 | O28: 0 | P28: 0 | Q28: 0 | R28: 0 | S28: 0 | T28: 0 | U28: 0 | V28: 0 | W28: 0 | X28: 0 | Y28: 0 | Z28: 0 | AA28: 0 | AB28: 0 | AC28: 0 | AD28: 0 | AE28: 0 | AF28: 0
A29: IndieGoGo | B29: =sum(B30:B33) -> 691 | C29: =sum(C30:C33) -> 1185 | D29: =sum(D30:D33) -> 487 | E29: =sum(E30:E33) -> 418 | F29: =sum(F30:F33) -> 283 | G29: =sum(G30:G33) -> 1257 | H29: =sum(H30:H33) -> 204 | I29: =sum(I30:I33) -> 309 | ... AF29: =sum(AF30:AF33) -> 0
A30: - Hardware | B30: 567 | C30: 499 | D30: 378 | E30: 388 | F30: 189 | G30: 945 | H30: 189 | I30: 199 | J30: 189 | K30: 955 | L30: 955 | M30: 0 | N30: 199 | O30: 698 | P30: 0 | Q30: 688 | R30: 0 | S30: 0 | T30: 378 | U30: 0 | V30: 378 | W30: 189 | X30: 1376 | Y30: 0 | Z30: 189 | AA30: 1076 | AB30: 378 | AC30: 1885 | AD30: 0 | AE30: 1255 | AF30: 0
A31: - Add-ons | B31: 79 | C31: 641 | D31: 79 | E31: 0 | F31: 79 | G31: 237 | H31: 0 | I31: 95 | J31: 79 | K31: 0 | L31: 95 | M31: 0 | N31: 0 | O31: 174 | P31: 0 | Q31: 253 | R31: 0 | S31: 279 | T31: 79 | U31: 0 | V31: 158 | W31: 79 | X31: 706 | Y31: 0 | Z31: 79 | AA31: 253 | AB31: 79 | AC31: 617 | AD31: 0 | AE31: 490 | AF31: 0
A32: - Taxes | B32: 0 | C32: 0 | D32: 0 | E32: 0 | F32: 0 | G32: 0 | H32: 0 | I32: 0 | J32: 0 | K32: 0 | L32: 0 | M32: 0 | N32: 0 | O32: 0 | P32: 0 | Q32: 0 | R32: 0 | S32: 0 | T32: 0 | U32: 0 | V32: 0 | W32: 0 | X32: 0 | Y32: 0 | Z32: 0 | AA32: 0 | AB32: 0 | AC32: 0 | AD32: 0 | AE32: 0 | AF32: 0
A33: - Shipping | B33: 45 | C33: 45 | D33: 30 | E33: 30 | F33: 15 | G33: 75 | H33: 15 | I33: 15 | J33: 15 | K33: 95 | L33: 75 | M33: 0 | N33: 15 | O33: 40 | P33: 0 | Q33: 40 | R33: 0 | S33: 20 | T33: 30 | U33: 0 | V33: 30 | W33: 15 | X33: 100 | Y33: 0 | Z33: 15 | AA33: 70 | AB33: 30 | AC33: 105 | AD33: 0 | AE33: 85 | AF33: 0
A34: Total Revenue | B34: =SUM(B8+B14+B20+B29) -> 184079.31 | C34: =SUM(C8+C14+C20+C29) -> 240862.53 | D34: =SUM(D8+D14+D20+D29) -> 310710.4 | E34: =SUM(E8+E14+E20+E29) -> 306631.73 | F34: =SUM(F8+F14+F20+F29) -> 298715.77 | G34: =SUM(G8+G14+G20+G29) -> 326123.09 | H34: =SUM(H8+H14+H20+H29) -> 332179.54 | I34: =SUM(I8+I14+I20+I29) -> 358754.73 | ... AF34: =SUM(AF8+AF14+AF20+AF29) -> 54547.42
A36: B2B Revenue
A37: Best Buy | B37: =SUM(B38:B39) -> 21396.763 | C37: =SUM(C38:C39) -> 24580.963 | D37: =SUM(D38:D39) -> 36712.765 | E37: =SUM(E38:E39) -> 31395.151 | F37: =SUM(F38:F39) -> 35439.085 | G37: =SUM(G38:G39) -> 40246.165 | H37: =SUM(H38:H39) -> 38463.013 | I37: =SUM(I38:I39) -> 43812.469 | ... AF37: =SUM(AF38:AF39) -> 4107.618
A38: - Hardwere | B38: 20159 | C38: 23159 | D38: 34589 | E38: 29579 | F38: 33389 | G38: 37918 | H38: 36238 | I38: 41278 | J38: 47308 | K38: 89948 | L38: 82077 | M38: 79197 | N38: 52271 | O38: 43490 | P38: 55159 | Q38: 62788 | R38: 37190 | S38: 8713 | T38: 7020 | U38: 3720 | V38: 5250 | W38: 2760 | X38: 2640 | Y38: 3570 | Z38: 1620 | AA38: 0 | AB38: 1560 | AC38: 0 | AD38: 1890 | AE38: 0 | AF38: 3870
A39: - Tax | B39: =B38*'Data - P&L'!$U$3 -> 1237.7626 | C39: =C38*'Data - P&L'!$U$3 -> 1421.9626 | D39: =D38*'Data - P&L'!$U$3 -> 2123.7646 | E39: =E38*'Data - P&L'!$U$3 -> 1816.1506 | F39: =F38*'Data - P&L'!$U$3 -> 2050.0846 | G39: =G38*'Data - P&L'!$U$3 -> 2328.1652 | H39: =H38*'Data - P&L'!$U$3 -> 2225.0132 | I39: =I38*'Data - P&L'!$U$3 -> 2534.4692 | ... AF39: =AF38*'Data - P&L'!$U$3 -> 237.618
A40: Total Revenue | B40: =B37 -> 21396.763 | C40: =C37 -> 24580.963 | D40: =D37 -> 36712.765 | E40: =E37 -> 31395.151 | F40: =F37 -> 35439.085 | G40: =G37 -> 40246.165 | H40: =H37 -> 38463.013 | I40: =I37 -> 43812.469 | ... AF40: =AF37 -> 4107.618
A42: App Revenue
A43: - Google Store | B43: ='APP - P&L'!B90 -> 181.381 | C43: ='APP - P&L'!C90 -> 255.6225 | D43: ='APP - P&L'!D90 -> 292.136 | E43: ='APP - P&L'!E90 -> 70.9675 | F43: ='APP - P&L'!F90 -> 170.7475 | G43: ='APP - P&L'!G90 -> 203.15 | H43: ='APP - P&L'!H90 -> 231.9495 | I43: ='APP - P&L'!I90 -> 333.66 | ... AF43: ='APP - P&L'!AF90 -> 1708.84
...

Sheet DTC - P&L
A1: DECEMBER | B1: 45261 | C1: 45262 | D1: 45263 | E1: 45264 | F1: 45265 | G1: 45266 | H1: 45267 | I1: 45268 | J1: 45269 | K1: 45270 | L1: 45271 | M1: 45272 | N1: 45273 | O1: 45274 | P1: 45275 | Q1: 45276 | R1: 45277 | S1: 45278 | T1: 45279 | U1: 45280 | V1: 45281 | W1: 45282 | X1: 45283 | Y1: 45284 | Z1: 45285 | AA1: 45286 | AB1: 45287 | AC1: 45288 | AD1: 45289 | AE1: 45290 | AF1: 45291
A2: DAY | B2: FRI | C2: SAT | D2: SUN | E2: MON | F2: TUE | G2: WED | H2: THU | I2: FRI | J2: SAT | K2: SUN | L2: MON | M2: TUE | N2: WED | O2: THU | P2: FRI | Q2: SAT | R2: SUN | S2: MON | T2: TUE | U2: WED | V2: THU | W2: FRI | X2: SAT | Y2: SUN | Z2: MON | AA2: TUE | AB2: WED | AC2: THU | AD2: FRI | AE2: SAT | AF2: SUN
A3: COMMENT
A4: Orders
A5: Meta | B5: 291 | C5: 406 | D5: 638 | E5: 655 | F5: 639 | G5: 678 | H5: 718 | I5: 715 | J5: 674 | K5: 800 | L5: 927 | M5: 802 | N5: 680 | O5: 386 | P5: 317 | Q5: 236 | R5: 152 | S5: 199 | T5: 171 | U5: 152 | V5: 81 | W5: 59 | X5: 34 | Y5: 35 | Z5: 49 | AA5: 67 | AB5: 59 | AC5: 60 | AD5: 61 | AE5: 48 | AF5: 57 | AG5: =SUM(B5:AF5) -> 10846
A6: Google | B6: 233 | C6: 327 | D6: 378 | E6: 427 | F6: 461 | G6: 504 | H6: 642 | I6: 598 | J6: 611 | K6: 923 | L6: 880 | M6: 708 | N6: 620 | O6: 432 | P6: 344 | Q6: 303 | R6: 204 | S6: 221 | T6: 194 | U6: 146 | V6: 80 | W6: 75 | X6: 77 | Y6: 76 | Z6: 146 | AA6: 122 | AB6: 95 | AC6: 84 | AD6: 83 | AE6: 75 | AF6: 94 | AG6: =SUM(B6:AF6) -> 10163
A7: TikTok | B7: 0 | C7: 0 | D7: 0 | E7: 0 | F7: 0 | G7: 0 | H7: 0 | I7: 0 | J7: 0 | K7: 0 | L7: 0 | M7: 0 | N7: 0 | O7: 0 | P7: 0 | Q7: 0 | R7: 0 | S7: 0 | T7: 0 | U7: 0 | V7: 0 | W7: 0 | X7: 0 | Y7: 0 | Z7: 0 | AA7: 0 | AB7: 0 | AC7: 0 | AD7: 0 | AE7: 0 | AF7: 0 | AG7: =SUM(B7:AF7) -> 0
A8: Bing | B8: 34 | C8: 82 | D8: 60 | E8: 56 | F8: 60 | G8: 114 | H8: 84 | I8: 48 | J8: 42 | K8: 74 | L8: 104 | M8: 98 | N8: 112 | O8: 66 | P8: 58 | Q8: 22 | R8: 18 | S8: 30 | T8: 38 | U8: 22 | V8: 22 | W8: 6 | X8: 4 | Y8: 2 | Z8: 24 | AA8: 24 | AB8: 4 | AC8: 6 | AD8: 14 | AE8: 26 | AF8: 30 | AG8: =SUM(B8:AF8) -> 1384
A9: Nextdoor | B9: 0 | C9: 0 | D9: 0 | E9: 0 | F9: 0 | G9: 0 | H9: 0 | I9: 0 | J9: 0 | K9: 0 | L9: 0 | M9: 0 | N9: 0 | O9: 0 | P9: 0 | Q9: 0 | R9: 0 | S9: 0 | T9: 0 | U9: 0 | V9: 0 | W9: 0 | X9: 0 | Y9: 0 | Z9: 0 | AA9: 0 | AB9: 0 | AC9: 0 | AD9: 0 | AE9: 0 | AF9: 0 | AG9: =SUM(B9:AF9) -> 0
A10: Affiliates (Refersion) | B10: 0 | C10: 0 | D10: 1 | E10: 2 | F10: 1 | G10: 0 | H10: 0 | I10: 0 | J10: 0 | K10: 1 | L10: 0 | M10: 2 | N10: 1 | O10: 1 | P10: 0 | Q10: 2 | R10: 0 | S10: 0 | T10: 1 | U10: 0 | V10: 0 | W10: 0 | X10: 0 | Y10: 0 | Z10: 0 | AA10: 0 | AB10: 0 | AC10: 1 | AD10: 0 | AE10: 0 | AF10: 1 | AG10: =SUM(B10:AF10) -> 14
A11: Email | B11: 20 | C11: 13 | D11: 7 | E11: 8 | F11: 80 | G11: 27 | H11: 5 | I11: 9 | J11: 4 | K11: 0 | L11: 50 | M11: 34 | N11: 22 | O11: 13 | P11: 7 | Q11: 9 | R11: 7 | S11: 4 | T11: 3 | U11: 2 | V11: 0 | W11: 0 | X11: 0 | Y11: 1 | Z11: 0 | AA11: 4 | AB11: 4 | AC11: 3 | AD11: 2 | AE11: 1 | AF11: 4 | AG11: =SUM(B11:AF11) -> 343
A12: All | B12: =SUM(B5:B11) -> 578 | C12: =SUM(C5:C11) -> 828 | D12: =SUM(D5:D11) -> 1084 | E12: =SUM(E5:E11) -> 1148 | F12: =SUM(F5:F11) -> 1241 | G12: =SUM(G5:G11) -> 1323 | H12: =SUM(H5:H11) -> 1449 | I12: =SUM(I5:I11) -> 1370 | ... AF12: =SUM(AF5:AF11) -> 186 | AG12: =SUM(B12:AF12) -> 22750
A14: Revenue
A15: Meta | B15: 81056.24 | C15: 110015.82 | D15: 172277.91 | E15: 176517.15 | F15: 172438.66 | G15: 186215.27 | H15: 201234.58 | I15: 195070.22 | J15: 192468.85 | K15: 225532.2 | L15: 261140.55 | M15: 221820.29 | N15: 196094.06 | O15: 121879.9 | P15: 107909.7 | Q15: 80499.91 | R15: 51068.984 | S15: 66232.198 | T15: 58229.613 | U15: 47539.611 | V15: 23548.263 | W15: 16465.432 | X15: 9273.1188 | Y15: 8708.3697 | Z15: 8925.7332 | AA15: 9984.6099 | AB15: 9897.2378 | AC15: 9618.2902 | AD15: 9410.3864 | AE15: 7548.0626 | AF15: 10744.301 | AG15: =SUM(B15:AF15) -> 3049365.5
A16: Google | B16: 62206.06 | C16: 85549.22 | D16: 100052.64 | E16: 111654.98 | F16: 122346 | G16: 132441.63 | H16: 165865.86 | I16: 167384.69 | J16: 167920.56 | K16: 252823.78 | L16: 237174.61 | M16: 192957.91 | N16: 176065.38 | O16: 136962.91 | P16: 113652.55 | Q16: 102290.09 | R16: 65183.65 | S16: 71115.64 | T16: 64605.62 | U16: 43130.73 | V16: 23208.51 | W16: 19398.87 | X16: 19951.31 | Y16: 18464.11 | Z16: 27526.43 | AA16: 20208.31 | AB16: 15603.75 | AC16: 13883.39 | AD16: 13080.78 | AE16: 14160.02 | AF16: 20822.54 | AG16: =SUM(B16:AF16) -> 2777692.5
A17: TikTok | B17: 0 | C17: 0 | D17: 0 | E17: 0 | F17: 0 | G17: 0 | H17: 0 | I17: 0 | J17: 0 | K17: 0 | L17: 0 | M17: 0 | N17: 0 | O17: 0 | P17: 0 | Q17: 0 | R17: 0 | S17: 0 | T17: 0 | U17: 0 | V17: 0 | W17: 0 | X17: 0 | Y17: 0 | Z17: 0 | AA17: 0 | AB17: 0 | AC17: 0 | AD17: 0 | AE17: 0 | AF17: 0 | AG17: =SUM(B17:AF17) -> 0
A18: Bing | B18: 4267 | C18: 10291 | D18: 7530 | E18: 7028 | F18: 7530 | G18: 14307 | H18: 10542 | I18: 6024 | J18: 5271 | K18: 9287 | L18: 13052 | M18: 12299 | N18: 14056 | O18: 8283 | P18: 7279 | Q18: 2761 | R18: 2259 | S18: 3765 | T18: 4769 | U18: 2761 | V18: 2761 | W18: 753 | X18: 502 | Y18: 251 | Z18: 3012 | AA18: 3012 | AB18: 502 | AC18: 753 | AD18: 1757 | AE18: 3263 | AF18: 3765 | AG18: =SUM(B18:AF18) -> 173692
A19: Nextdoor | B19: 0 | C19: 0 | D19: 0 | E19: 0 | F19: 0 | G19: 0 | H19: 0 | I19: 0 | J19: 0 | K19: 0 | L19: 0 | M19: 0 | N19: 0 | O19: 0 | P19: 0 | Q19: 0 | R19: 0 | S19: 0 | T19: 0 | U19: 0 | V19: 0 | W19: 0 | X19: 0 | Y19: 0 | Z19: 0 | AA19: 0 | AB19: 0 | AC19: 0 | AD19: 0 | AE19: 0 | AF19: 0 | AG19: =SUM(B19:AF19) -> 0
A20: Affiliates (Refersion) | B20: 0 | C20: 0 | D20: 278 | E20: 497.72 | F20: 179.85 | G20: 0 | H20: 0 | I20: 0 | J20: 0 | K20: 230.34 | L20: 0 | M20: 549.92 | N20: 370 | O20: 274 | P20: 0 | Q20: 318.59 | R20: 0 | S20: 0 | T20: 288.31 | U20: 0 | V20: 0 | W20: 0 | X20: 0 | Y20: 0 | Z20: 0 | AA20: 0 | AB20: 0 | AC20: 324.14 | AD20: 0 | AE20: 0 | AF20: 375.41 | AG20: =SUM(B20:AF20) -> 3686.28
A21: Email | B21: 5460.24 | C21: 2667.72 | D21: 2101.12 | E21: 2466.51 | F21: 6838.53 | G21: 3498.22 | H21: 414.78 | I21: 1629.87 | J21: 1009.77 | K21: 0 | L21: 11648.98 | M21: 7357.52 | N21: 4119.13 | O21: 3745.99 | P21: 1274.38 | Q21: 2124.21 | R21: 1629.29 | S21: 1381.18 | T21: 1565.55 | U21: 296.74 | V21: 0 | W21: 0 | X21: 0 | Y21: 341.09 | Z21: 0 | AA21: 439.63 | AB21: 238.92 | AC21: 241.74 | AD21: 487.06 | AE21: 133.29 | AF21: 575.49 | AG21: =SUM(B21:AF21) -> 63686.95
A22: All | B22: =SUM(B15:B21) -> 152989.54 | C22: =SUM(C15:C21) -> 208523.76 | D22: =SUM(D15:D21) -> 282239.67 | E22: =SUM(E15:E21) -> 298164.36 | F22: =SUM(F15:F21) -> 309333.04 | G22: =SUM(G15:G21) -> 336462.12 | H22: =SUM(H15:H21) -> 378057.22 | I22: =SUM(I15:I21) -> 370108.78 | ... AF22: =SUM(AF15:AF21) -> 36282.741 | AG22: =SUM(B22:AF22) -> 6068123.3
A24: Media Cost
A25: Meta | B25: =Summary!B74 -> 21772.841 | C25: =Summary!C74 -> 31642.26 | D25: =Summary!D74 -> 53297.918 | E25: =Summary!E74 -> 64412.413 | F25: =Summary!F74 -> 57917.224 | G25: =Summary!G74 -> 61406.531 | H25: =Summary!H74 -> 68789.323 | I25: =Summary!I74 -> 59937.281 | ... AF25: =Summary!AF74 -> 5934.1944 | AG25: =SUM(B25:AF25) -> 1035696.4
A26: Google | B26: =Summary!B75 -> 5447.08 | C26: =Summary!C75 -> 5717.82 | D26: =Summary!D75 -> 5853.85 | E26: =Summary!E75 -> 6168.03 | F26: =Summary!F75 -> 7765.18 | G26: =Summary!G75 -> 12389.76 | H26: =Summary!H75 -> 15878.71 | I26: =Summary!I75 -> 20488.81 | ... AF26: =Summary!AF75 -> 2034.48 | AG26: =SUM(B26:AF26) -> 290838.42
A27: TikTok | B27: =Summary!B77 -> 0 | C27: =Summary!C77 -> 0 | D27: =Summary!D77 -> 0 | E27: =Summary!E77 -> 0 | F27: =Summary!F77 -> 0 | G27: =Summary!G77 -> 0 | H27: =Summary!H77 -> 0 | I27: =Summary!I77 -> 0 | ... AF27: =Summary!AF77 -> 0 | AG27: =SUM(B27:AF27) -> 8186.54
A28: Bing | B28: =Summary!B76 -> 315.1 | C28: =Summary!C76 -> 267.21 | D28: =Summary!D76 -> 293.77 | E28: =Summary!E76 -> 311.83 | F28: =Summary!F76 -> 307.19 | G28: =Summary!G76 -> 1080.36 | H28: =Summary!H76 -> 1061.59 | I28: =Summary!I76 -> 1086.12 | ... AF28: =Summary!AF76 -> 181.91 | AG28: =SUM(B28:AF28) -> 22766.24
A29: Nextdoor | B29: =Summary!B79 -> 0 | C29: =Summary!C79 -> 0 | D29: =Summary!D79 -> 0 | E29: =Summary!E79 -> 0 | F29: =Summary!F79 -> 0 | G29: =Summary!G79 -> 0 | H29: =Summary!H79 -> 0 | I29: =Summary!I79 -> 0 | ... AF29: =Summary!AF79 -> 0 | AG29: =SUM(B29:AF29) -> 0
A30: Affiliate Fee (20%) | B30: =Summary!B81 -> 0 | C30: =Summary!C81 -> 0 | D30: =Summary!D81 -> 69.5 | E30: =Summary!E81 -> 110.85 | F30: =Summary!F81 -> 35.97 | G30: =Summary!G81 -> 0 | H30: =Summary!H81 -> 0 | I30: =Summary!I81 -> 0 | ... AF30: =Summary!AF81 -> 93.85 | AG30: =SUM(B30:AF30) -> 840.87
A31: All | B31: =SUM(B25:B30) -> 27535.021 | C31: =SUM(C25:C30) -> 37627.29 | D31: =SUM(D25:D30) -> 59515.038 | E31: =SUM(E25:E30) -> 71003.123 | F31: =SUM(F25:F30) -> 66025.564 | G31: =SUM(G25:G30) -> 74876.651 | H31: =SUM(H25:H30) -> 85729.623 | I31: =SUM(I25:I30) -> 81512.211 | ... AF31: =SUM(AF25:AF30) -> 8244.4344 | AG31: =SUM(B31:AF31) -> 1358328.5
A36: Revenue
A37: Revenue Woocommerce (Platform) | B37: =Summary!B8 -> 182179.74 | C37: =Summary!C8 -> 239359.12 | D37: =Summary!D8 -> 309347.58 | E37: =Summary!E8 -> 305578.38 | F37: =Summary!F8 -> 298114.36 | G37: =Summary!G8 -> 324866.09 | H37: =Summary!H8 -> 330539.93 | I37: =Summary!I8 -> 353516.62 | ... AE37: =Summary!AE8 -> 45927.46 | AF37: 44158.82 | AG37: =sum(B37:AF37) -> 6271664.5
A38: SUM | B38: =SUM(B37) -> 182179.74 | C38: =SUM(C37) -> 239359.12 | D38: =SUM(D37) -> 309347.58 | E38: =SUM(E37) -> 305578.38 | F38: =SUM(F37) -> 298114.36 | G38: =SUM(G37) -> 324866.09 | H38: =SUM(H37) -> 330539.93 | I38: =SUM(I37) -> 353516.62 | ... AF38: =SUM(AF37) -> 44158.82 | AG38: =sum(B38:AF38) -> 6271664.5
A40: Orders
A41: Orders Woocommerce (Platform) | B41: =Summary!B49 -> 671 | C41: =Summary!C49 -> 904 | D41: =Summary!D49 -> 1163 | E41: =Summary!E49 -> 1145 | F41: =Summary!F49 -> 1191 | G41: =Summary!G49 -> 1233 | H41: =Summary!H49 -> 1221 | I41: =Summary!I49 -> 1297 | ... AE41: =Summary!AE49 -> 238 | AF41: 203 | AG41: =sum(B41:AF41) -> 22951
A42: SUM | B42: =SUM(B41) -> 671 | C42: =SUM(C41) -> 904 | D42: =SUM(D41) -> 1163 | E42: =SUM(E41) -> 1145 | F42: =SUM(F41) -> 1191 | G42: =SUM(G41) -> 1233 | H42: =SUM(H41) -> 1221 | I42: =SUM(I41) -> 1297 | ... AF42: =SUM(AF41) -> 203 | AG42: =sum(B42:AF42) -> 22951
A44: Breakdown
A45: - Hardware | B45: =Summary!B9 -> 148896.28 | C45: =Summary!C9 -> 196722.13 | D45: =Summary!D9 -> 255328.76 | E45: =Summary!E9 -> 254086.11 | F45: =Summary!F9 -> 245877.15 | G45: =Summary!G9 -> 268135.33 | H45: =Summary!H9 -> 267062.57 | I45: =Summary!I9 -> 283105.87 | ... AF45: =Summary!AF9 -> 29212.93 | AG45: =SUM(B45:AF45) -> 5010192.3
A46: - Add-ons | B46: =Summary!B10 -> 12027.92 | C46: =Summary!C10 -> 14248.12 | D46: =Summary!D10 -> 17773.14 | E46: =Summary!E10 -> 15874.79 | F46: =Summary!F10 -> 15079.85 | G46: =Summary!G10 -> 17998.27 | H46: =Summary!H10 -> 24577.23 | I46: =Summary!I10 -> 29469.5 | ... AF46: =Summary!AF10 -> 9678.87 | AG46: =SUM(B46:AF46) -> 445560.17
A47: - Merch | B47: =Summary!B11 -> 161 | C47: =Summary!C11 -> 238.99 | D47: =Summary!D11 -> 255.97 | E47: =Summary!E11 -> 49.89 | F47: =Summary!F11 -> 1934.95 | G47: =Summary!G11 -> 539.98 | H47: =Summary!H11 -> 335.15 | I47: =Summary!I11 -> 635.5 | ... AF47: =Summary!AF11 -> 55.99 | AG47: =SUM(B47:AF47) -> 10370.71
A48: - Taxes | B48: =Summary!B12 -> 10324.54 | C48: =Summary!C12 -> 13474.88 | D48: =Summary!D12 -> 17959.71 | E48: =Summary!E12 -> 17167.59 | F48: =Summary!F12 -> 16904.41 | G48: =Summary!G12 -> 18912.51 | H48: =Summary!H12 -> 19444.98 | I48: =Summary!I12 -> 20395.75 | ... AF48: =Summary!AF12 -> 2431.03 | AG48: =SUM(B48:AF48) -> 359746.31
...

Sheet AMAZON - P&L
A1: DECEMBER | B1: 45261 | C1: 45262 | D1: 45263 | E1: 45264 | F1: 45265 | G1: 45266 | H1: 45267 | I1: 45268 | J1: 45269 | K1: 45270 | L1: 45271 | M1: 45272 | N1: 45273 | O1: 45274 | P1: 45275 | Q1: 45276 | R1: 45277 | S1: 45278 | T1: 45279 | U1: 45280 | V1: 45281 | W1: 45282 | X1: 45283 | Y1: 45284 | Z1: 45285 | AA1: 45286 | AB1: 45287 | AC1: 45288 | AD1: 45289 | AE1: 45290 | AF1: 45291
A2: DAY | B2: FRI | C2: SAT | D2: SUN | E2: MON | F2: TUE | G2: WED | H2: THU | I2: FRI | J2: SAT | K2: SUN | L2: MON | M2: TUE | N2: WED | O2: THU | P2: FRI | Q2: SAT | R2: SUN | S2: MON | T2: TUE | U2: WED | V2: THU | W2: FRI | X2: SAT | Y2: SUN | Z2: MON | AA2: TUE | AB2: WED | AC2: THU | AD2: FRI | AE2: SAT | AF2: SUN
A3: COMMENT
A4: Orders
A5: Amazon (market place) | B5: =Summary!B53 -> 1 | C5: =Summary!C53 -> 0 | D5: =Summary!D53 -> 1 | E5: =Summary!E53 -> 1 | F5: =Summary!F53 -> 0 | G5: =Summary!G53 -> 0 | H5: =Summary!H53 -> 1 | I5: =Summary!I53 -> 0 | ... AF5: =Summary!AF53 -> 38
A6: All | B6: =SUM(B5) -> 1 | C6: =SUM(C5) -> 0 | D6: =SUM(D5) -> 1 | E6: =SUM(E5) -> 1 | F6: =SUM(F5) -> 0 | G6: =SUM(G5) -> 0 | H6: =SUM(H5) -> 1 | I6: =SUM(I5) -> 0 | ... AF6: =SUM(AF5) -> 38 | AG6: =SUM(B6:AF6) -> 4118
A8: Revenue
A9: Amazon (market place) | B9: =Summary!B14 -> 253.34 | C9: =Summary!C14 -> 0 | D9: =Summary!D14 -> 239 | E9: =Summary!E14 -> 316.94 | F9: =Summary!F14 -> 0 | G9: =Summary!G14 -> 0 | H9: =Summary!H14 -> 252.15 | I9: =Summary!I14 -> 0 | ... AF9: =Summary!AF14 -> 10388.6
A10: All | B10: =SUM(B9) -> 253.34 | C10: =SUM(C9) -> 0 | D10: =SUM(D9) -> 239 | E10: =SUM(E9) -> 316.94 | F10: =SUM(F9) -> 0 | G10: =SUM(G9) -> 0 | H10: =SUM(H9) -> 252.15 | I10: =SUM(I9) -> 0 | ... AF10: =SUM(AF9) -> 10388.6 | AG10: =SUM(B10:AF10) -> 1172985.1
A12: Media Cost
A13: Amazon Spend | B13: =Summary!B78 -> 0 | C13: =Summary!C78 -> 0 | D13: =Summary!D78 -> 688.15 | E13: =Summary!E78 -> 0 | F13: =Summary!F78 -> 0.41 | G13: =Summary!G78 -> 495.44 | H13: =Summary!H78 -> 0 | I13: =Summary!I78 -> 777.19 | ... AF13: =Summary!AF78 -> 2262.4 | AG13: =SUM(C13:AF13) -> 201173.89
A14: Amazon Platform Fee (15 %) | B14: =B9*'Data - P&L'!$C$48 -> 38.001 | C14: =C9*'Data - P&L'!$C$48 -> 0 | D14: =D9*'Data - P&L'!$C$48 -> 35.85 | E14: =E9*'Data - P&L'!$C$48 -> 47.541 | F14: =F9*'Data - P&L'!$C$48 -> 0 | G14: =G9*'Data - P&L'!$C$48 -> 0 | H14: =H9*'Data - P&L'!$C$48 -> 37.8225 | I14: =I9*'Data - P&L'!$C$48 -> 0 | ... AF14: =AF9*'Data - P&L'!$C$48 -> 1558.29 | AG14: =SUM(C14:AF14) -> 175909.77
A15: All | B15: =SUM(B13:B14) -> 38.001 | C15: =SUM(C13:C14) -> 0 | D15: =SUM(D13:D14) -> 724 | E15: =SUM(E13:E14) -> 47.541 | F15: =SUM(F13:F14) -> 0.41 | G15: =SUM(G13:G14) -> 495.44 | H15: =SUM(H13:H14) -> 37.8225 | I15: =SUM(I13:I14) -> 777.19 | ... AF15: =SUM(AF13:AF14) -> 3820.69 | AG15: =SUM(B15:AF15) -> 377121.66
A19: Amazon Orders
A20: Hardware | B20: =Summary!B15 -> 239 | C20: =Summary!C15 -> 0 | D20: =Summary!D15 -> 239 | E20: =Summary!E15 -> 299 | F20: =Summary!F15 -> 0 | G20: =Summary!G15 -> 0 | H20: =Summary!H15 -> 239 | I20: =Summary!I15 -> 0 | ... AF20: =Summary!AF15 -> 9586.55 | AG20: =SUM(B20:AF20) -> 1079495.1
A21: Addons | B21: =Summary!B16 -> 0 | C21: =Summary!C16 -> 0 | D21: =Summary!D16 -> 0 | E21: =Summary!E16 -> 0 | F21: =Summary!F16 -> 0 | G21: =Summary!G16 -> 0 | H21: =Summary!H16 -> 0 | I21: =Summary!I16 -> 0 | ... AF21: =Summary!AF16 -> 87 | AG21: =SUM(B21:AF21) -> 15225
A22: Tax | B22: =Summary!B17 -> 14.34 | C22: =Summary!C17 -> 0 | D22: =Summary!D17 -> 0 | E22: =Summary!E17 -> 17.94 | F22: =Summary!F17 -> 0 | G22: =Summary!G17 -> 0 | H22: =Summary!H17 -> 13.15 | I22: =Summary!I17 -> 0 | ... AF22: =Summary!AF17 -> 710.31 | AG22: =SUM(B22:AF22) -> 76329.78
A23: Shipping | B23: =Summary!B18 -> 0 | C23: =Summary!C18 -> 0 | D23: =Summary!D18 -> 0 | E23: =Summary!E18 -> 0 | F23: =Summary!F18 -> 0 | G23: =Summary!G18 -> 0 | H23: =Summary!H18 -> 0 | I23: =Summary!I18 -> 0 | ... AF23: =Summary!AF18 -> 0.08 | AG23: =SUM(B23:AF23) -> 593.63
A24: Gift Wrap Price | B24: =Summary!B19 -> 0 | C24: =Summary!C19 -> 0 | D24: =Summary!D19 -> 0 | E24: =Summary!E19 -> 0 | F24: =Summary!F19 -> 0 | G24: =Summary!G19 -> 0 | H24: =Summary!H19 -> 0 | I24: =Summary!I19 -> 0 | ... AF24: =Summary!AF19 -> 4.66 | AG24: =SUM(B24:AF24) -> 1341.59
A25: All Amazon | B25: =SUM(B20:B24) -> 253.34 | C25: =SUM(C20:C24) -> 0 | D25: =SUM(D20:D24) -> 239 | E25: =SUM(E20:E24) -> 316.94 | F25: =SUM(F20:F24) -> 0 | G25: =SUM(G20:G24) -> 0 | H25: =SUM(H20:H24) -> 252.15 | I25: =SUM(I20:I24) -> 0 | ... AF25: =SUM(AF20:AF24) -> 10388.6 | AG25: =SUM(B25:AF25) -> 1172985.1
A27: Units Sold (Gross)
A28: SKU 1 - Blue | B28: 2 | C28: 0 | D28: 1 | E28: 0 | F28: 0 | G28: 0 | H28: 1 | I28: 0 | J28: 0 | K28: 0 | L28: 1 | M28: 2 | N28: 1 | O28: 1 | P28: 0 | Q28: 0 | R28: 0 | S28: 0 | T28: 0 | U28: 0 | V28: 0 | W28: 1 | X28: 1 | Y28: 0 | Z28: 11 | AA28: 1 | AB28: 3 | AC28: 1 | AD28: 0 | AE28: 5 | AF28: 4 | AG28: =sum(B28:AF28) -> 36
A29: SKU 2 - Yellow | B29: 1 | C29: 0 | D29: 0 | E29: 0 | F29: 0 | G29: 0 | H29: 0 | I29: 0 | J29: 0 | K29: 0 | L29: 0 | M29: 0 | N29: 0 | O29: 0 | P29: 0 | Q29: 0 | R29: 0 | S29: 0 | T29: 0 | U29: 0 | V29: 0 | W29: 0 | X29: 2 | Y29: 4 | Z29: 8 | AA29: 0 | AB29: 0 | AC29: 1 | AD29: 0 | AE29: 0 | AF29: 0 | AG29: =sum(B29:AF29) -> 16
A30: SKU 3 - Blue w/ Solar | B30: 1 | C30: 0 | D30: 0 | E30: 0 | F30: 0 | G30: 0 | H30: 0 | I30: 0 | J30: 10 | K30: 53 | L30: 4 | M30: 3 | N30: 8 | O30: 42 | P30: 96 | Q30: 265 | R30: 785 | S30: 632 | T30: 579 | U30: 245 | V30: 199 | W30: 164 | X30: 146 | Y30: 83 | Z30: 29 | AA30: 37 | AB30: 6 | AC30: 9 | AD30: 6 | AE30: 14 | AF30: 5 | AG30: =sum(B30:AF30) -> 3421
A31: SKU 4 - Yellow w/ Solar | B31: 2 | C31: 0 | D31: 0 | E31: 1 | F31: 0 | G31: 0 | H31: 0 | I31: 0 | J31: 0 | K31: 2 | L31: 0 | M31: 0 | N31: 0 | O31: 0 | P31: 0 | Q31: 0 | R31: 0 | S31: 0 | T31: 0 | U31: 0 | V31: 0 | W31: 0 | X31: 2 | Y31: 5 | Z31: 35 | AA31: 21 | AB31: 16 | AC31: 20 | AD31: 15 | AE31: 16 | AF31: 18 | AG31: =sum(B31:AF31) -> 153
A32: SUM (SKU 1 - SKU 4) | B32: =SUM(B28:B31) -> 6 | C32: =SUM(C28:C31) -> 0 | D32: =SUM(D28:D31) -> 1 | E32: =SUM(E28:E31) -> 1 | F32: =SUM(F28:F31) -> 0 | G32: =SUM(G28:G31) -> 0 | H32: =SUM(H28:H31) -> 1 | I32: =SUM(I28:I31) -> 0 | ... AF32: =SUM(AF28:AF31) -> 27 | AG32: =sum(B32:AF32) -> 3626
A34: Wall Mount | B34: 0 | C34: 0 | D34: 0 | E34: 0 | F34: 0 | G34: 0 | H34: 0 | I34: 0 | J34: 3 | K34: 1 | L34: 0 | M34: 1 | N34: 0 | O34: 0 | P34: 4 | Q34: 12 | R34: 52 | S34: 43 | T34: 45 | U34: 28 | V34: 14 | W34: 18 | X34: 23 | Y34: 19 | Z34: 75 | AA34: 90 | AB34: 68 | AC34: 28 | AD34: 1 | AE34: 2 | AF34: 3 | AG34: =sum(B34:AF34) -> 530
A35: Suet Ball Holder | B35: 0 | C35: 0 | D35: 0 | E35: 0 | F35: 0 | G35: 0 | H35: 0 | I35: 0 | J35: 0 | K35: 0 | L35: 0 | M35: 0 | N35: 0 | O35: 0 | P35: 0 | Q35: 0 | R35: 0 | S35: 0 | T35: 0 | U35: 0 | V35: 0 | W35: 0 | X35: 0 | Y35: 0 | Z35: 0 | AA35: 0 | AB35: 0 | AC35: 0 | AD35: 0 | AE35: 0 | AF35: 0 | AG35: =sum(B35:AF35) -> 0
A36: 3-in-1 Nutrition Set - Blue | B36: 0 | C36: 0 | D36: 0 | E36: 0 | F36: 0 | G36: 0 | H36: 0 | I36: 0 | J36: 0 | K36: 0 | L36: 0 | M36: 0 | N36: 0 | O36: 0 | P36: 0 | Q36: 0 | R36: 0 | S36: 0 | T36: 0 | U36: 0 | V36: 0 | W36: 0 | X36: 0 | Y36: 0 | Z36: 0 | AA36: 0 | AB36: 0 | AC36: 0 | AD36: 0 | AE36: 0 | AF36: 0 | AG36: =sum(B36:AF36) -> 0
A37: 3-in-1 Nutrition Set - Yellow | B37: 0 | C37: 0 | D37: 0 | E37: 0 | F37: 0 | G37: 0 | H37: 0 | I37: 0 | J37: 0 | K37: 0 | L37: 0 | M37: 0 | N37: 0 | O37: 0 | P37: 0 | Q37: 0 | R37: 0 | S37: 0 | T37: 0 | U37: 0 | V37: 0 | W37: 0 | X37: 0 | Y37: 0 | Z37: 0 | AA37: 0 | AB37: 0 | AC37: 0 | AD37: 0 | AE37: 0 | AF37: 0 | AG37: =sum(B37:AF37) -> 0
A38: Solar Roof Single - Blue | B38: 0 | C38: 0 | D38: 0 | E38: 0 | F38: 0 | G38: 0 | H38: 0 | I38: 0 | J38: 0 | K38: 0 | L38: 0 | M38: 0 | N38: 0 | O38: 0 | P38: 0 | Q38: 0 | R38: 0 | S38: 0 | T38: 0 | U38: 0 | V38: 0 | W38: 0 | X38: 0 | Y38: 0 | Z38: 0 | AA38: 0 | AB38: 0 | AC38: 0 | AD38: 0 | AE38: 0 | AF38: 0 | AG38: =sum(B38:AF38) -> 0
A39: Solar Roof Single - Yellow | B39: 0 | C39: 0 | D39: 0 | E39: 0 | F39: 0 | G39: 0 | H39: 0 | I39: 0 | J39: 0 | K39: 0 | L39: 0 | M39: 0 | N39: 0 | O39: 0 | P39: 0 | Q39: 0 | R39: 0 | S39: 0 | T39: 0 | U39: 0 | V39: 0 | W39: 0 | X39: 0 | Y39: 0 | Z39: 0 | AA39: 0 | AB39: 0 | AC39: 0 | AD39: 0 | AE39: 0 | AF39: 0 | AG39: =sum(B39:AF39) -> 0
A40: Perch Extender - Blue | B40: 0 | C40: 0 | D40: 0 | E40: 0 | F40: 0 | G40: 0 | H40: 0 | I40: 0 | J40: 0 | K40: 0 | L40: 0 | M40: 0 | N40: 0 | O40: 0 | P40: 0 | Q40: 0 | R40: 0 | S40: 0 | T40: 0 | U40: 0 | V40: 0 | W40: 0 | X40: 0 | Y40: 0 | Z40: 0 | AA40: 0 | AB40: 0 | AC40: 0 | AD40: 0 | AE40: 0 | AF40: 0 | AG40: =sum(B40:AF40) -> 0
A41: Perch Extender - Yellow | B41: 0 | C41: 0 | D41: 0 | E41: 0 | F41: 0 | G41: 0 | H41: 0 | I41: 0 | J41: 0 | K41: 0 | L41: 0 | M41: 0 | N41: 0 | O41: 0 | P41: 0 | Q41: 0 | R41: 0 | S41: 0 | T41: 0 | U41: 0 | V41: 0 | W41: 0 | X41: 0 | Y41: 0 | Z41: 0 | AA41: 0 | AB41: 0 | AC41: 0 | AD41: 0 | AE41: 0 | AF41: 0 | AG41: =sum(B41:AF41) -> 0
A42: SUM (Add-ons) | B42: =SUM(B34:B41) -> 0 | C42: =SUM(C34:C41) -> 0 | D42: =SUM(D34:D41) -> 0 | E42: =SUM(E34:E41) -> 0 | F42: =SUM(F34:F41) -> 0 | G42: =SUM(G34:G41) -> 0 | H42: =SUM(H34:H41) -> 0 | I42: =SUM(I34:I41) -> 0 | ... AF42: =SUM(AF34:AF41) -> 3 | AG42: =sum(B42:AF42) -> 530
A45: Units Sold by country (Gross) - Only selling in US
A46: Bird Buddy - Blue - AMAZON.US | AG46: =sum(B46:AE46) -> 0
A47: Bird Buddy - Yellow - AMAZON.US
A48: Bird Buddy with Solar Roof Blue - AMAZON.US | AG48: =sum(B48:AE48) -> 0
A49: Bird Buddy with Solar Roof Yellow - AMAZON.US
...

Sheet APP - P&L
A1: JANUARY | B1: 45292 | C1: 45293 | D1: 45294 | E1: 45295 | F1: 45296 | G1: 45297 | H1: 45298 | I1: 45299 | J1: 45300 | K1: 45301 | L1: 45302 | M1: 45303 | N1: 45304 | O1: 45305 | P1: 45306 | Q1: 45307 | R1: 45308 | S1: 45309 | T1: 45310 | U1: 45311 | V1: 45312 | W1: 45313 | X1: 45314 | Y1: 45315 | Z1: 45316 | AA1: 45317 | AB1: 45318 | AC1: 45319 | AD1: 45320 | AE1: 45321 | AF1: 45322
A2: DAY | B2: MON | C2: TUE | D2: WED | E2: THU | F2: FRI | G2: SAT | H2: SUN | I2: MON | J2: TUE | K2: WED | L2: THU | M2: FRI | N2: SAT | O2: SUN | P2: MON | Q2: TUE | R2: WED | S2: THU | T2: FRI | U2: SAT | V2: SUN | W2: MON | X2: TUE | Y2: WED | Z2: THU | AA2: FRI | AB2: SAT | AC2: SUN | AD2: MON | AE2: TUE | AF2: WED
A4: Gross Revenue
A5: Apple Store Sales | B5: 1720.7904 | C5: 2353.8949 | D5: 1773.2926 | E5: 1307.9704 | F5: 1056.7641 | G5: 1277.0296 | H5: 1259.3559 | I5: 1574.9166 | J5: 1734.4595 | K5: 2173.4351 | L5: 1176.7082 | M5: 1091.9338 | N5: 727.3789 | O5: 811.4365 | P5: 1130.3281 | Q5: 1919.8968 | R5: 2114.2114 | S5: 988.26562 | T5: 1360.8294 | U5: 1019.9931 | V5: 1925.9781 | W5: 2626.1175 | X5: 4620.4567 | Y5: 6211.0456 | Z5: 28980.079 | AA5: 27313.591 | AB5: 16002.782 | AC5: 11862.606 | AD5: 9379.4322 | AE5: 12039.757 | AF5: 10508.22 | AG5: =sum(B5:AF5) -> 160042.96
A6: - Yearly Subscription | B6: 1663.2904 | C6: 2282.8949 | D6: 1673.6926 | E6: 1251.9704 | F6: 973.56415 | G6: 1213.1296 | H6: 1192.7559 | I6: 1481.4166 | J6: 1645.9595 | K6: 2100.8551 | L6: 1134.5082 | M6: 1037.5338 | N6: 681.7789 | O6: 743.2365 | P6: 1075.9281 | Q6: 1829.1968 | R6: 2056.0114 | S6: 919.96562 | T6: 1311.9294 | U6: 971.69311 | V6: 1873.6781 | W6: 2500.6107 | X6: 4521.6667 | Y6: 6051.0375 | Z6: 28390.318 | AA6: 26794.486 | AB6: 15707.053 | AC6: 11443.908 | AD6: 9051.8635 | AE6: 11647.461 | AF6: 10241.118 | AG6: =sum(B6:AF6) -> 155464.51
A7: - Monthly Subscription | B7: 57.5 | C7: 71 | D7: 99.6 | E7: 56 | F7: 83.2 | G7: 63.9 | H7: 66.6 | I7: 93.5 | J7: 88.5 | K7: 72.58 | L7: 42.2 | M7: 54.4 | N7: 45.6 | O7: 68.2 | P7: 54.4 | Q7: 90.7 | R7: 58.2 | S7: 68.3 | T7: 48.9 | U7: 48.3 | V7: 52.3 | W7: 125.50679 | X7: 98.79 | Y7: 160.00807 | Z7: 589.76137 | AA7: 519.10445 | AB7: 295.72895 | AC7: 418.69729 | AD7: 327.56865 | AE7: 392.2967 | AF7: 267.1023 | AG7: =sum(B7:AF7) -> 4578.4446
A8: Google Store Sales | B8: 226.46 | C8: 302.25 | D8: 344.36 | E8: 84.95 | F8: 214.95 | G8: 239 | H8: 301.87 | I8: 400.4 | J8: 482.7 | K8: 611.61 | L8: 198.6 | M8: 215.75 | N8: 206.18 | O8: 195.25 | P8: 286.06 | Q8: 490.95 | R8: 462.87 | S8: 213.81 | T8: 124.15 | U8: 126.07 | V8: 446.93 | W8: 592.91 | X8: 1256.13 | Y8: 1838.25 | Z8: 6047.3 | AA8: 5987.74 | AB8: 3149.93 | AC8: 1656.09 | AD8: 1829.01 | AE8: 2162.23 | AF8: 2010.4 | AG8: =sum(B8:AF8) -> 32705.16
A9: - Yearly Subscription | B9: 223.25 | C9: 286.02 | D9: 321.98 | E9: 61.63 | F9: 202.04 | G9: 219.93 | H9: 286.02 | I9: 380.36 | J9: 460.36 | K9: 596.03 | L9: 195.43 | M9: 202.72 | N9: 193.25 | O9: 185.85 | P9: 259.61 | Q9: 477.26 | R9: 453.43 | S9: 191.31 | T9: 95.83 | U9: 100.45 | V9: 414.42 | W9: 571.04 | X9: 1240.06 | Y9: 1809.59 | Z9: 5950.84 | AA9: 5937.4 | AB9: 3076.93 | AC9: 1574.65 | AD9: 1755.72 | AE9: 2089.9 | AF9: 1979.17 | AG9: =sum(B9:AF9) -> 31792.48
A10: - Monthly Subscription | B10: 3.21 | C10: 16.23 | D10: 22.38 | E10: 23.32 | F10: 12.91 | G10: 19.07 | H10: 15.85 | I10: 20.04 | J10: 22.34 | K10: 15.58 | L10: 3.17 | M10: 13.03 | N10: 12.93 | O10: 9.4 | P10: 26.45 | Q10: 13.69 | R10: 9.44 | S10: 22.5 | T10: 28.32 | U10: 25.62 | V10: 32.51 | W10: 21.87 | X10: 16.07 | Y10: 28.66 | Z10: 96.46 | AA10: 50.34 | AB10: 73 | AC10: 81.44 | AD10: 73.29 | AE10: 72.33 | AF10: 31.23 | AG10: =sum(B10:AF10) -> 912.68
A11: SUM | B11: =sum(B5+B8) -> 1947.2504 | C11: =sum(C5+C8) -> 2656.1449 | D11: =sum(D5+D8) -> 2117.6526 | E11: =sum(E5+E8) -> 1392.9204 | F11: =sum(F5+F8) -> 1271.7141 | G11: =sum(G5+G8) -> 1516.0296 | H11: =sum(H5+H8) -> 1561.2259 | I11: =sum(I5+I8) -> 1975.3166 | ... AF11: =sum(AF5+AF8) -> 12518.62 | AG11: =sum(B11:AF11) -> 192748.12
A13: Gross Orders
A14: Apple Store Orders | B14: =sum(B15:B16) -> 75 | C14: =sum(C15:C16) -> 99 | D14: =sum(D15:D16) -> 87 | E14: =sum(E15:E16) -> 59 | F14: =sum(F15:F16) -> 60 | G14: =sum(G15:G16) -> 61 | H14: =sum(H15:H16) -> 62 | I14: =sum(I15:I16) -> 78 | ... AF14: =sum(AF15:AF16) -> 360 | AG14: =sum(B14:AF14) -> 6161
A15: - Yearly Subscription | B15: 56 | C15: 76 | D15: 55 | E15: 41 | F15: 33 | G15: 40 | H15: 40 | I15: 48 | J15: 56 | K15: 69 | L15: 37 | M15: 34 | N15: 22 | O15: 24 | P15: 35 | Q15: 61 | R15: 68 | S15: 30 | T15: 43 | U15: 32 | V15: 62 | W15: 84 | X15: 150 | Y15: 200 | Z15: 941 | AA15: 891 | AB15: 522 | AC15: 381 | AD15: 289 | AE15: 365 | AF15: 313 | AG15: =sum(B15:AF15) -> 5098
A16: - Monthly Subscription | B16: 19 | C16: 23 | D16: 32 | E16: 18 | F16: 27 | G16: 21 | H16: 22 | I16: 30 | J16: 28 | K16: 24 | L16: 14 | M16: 18 | N16: 15 | O16: 22 | P16: 18 | Q16: 29 | R16: 19 | S16: 22 | T16: 16 | U16: 16 | V16: 17 | W16: 27 | X16: 21 | Y16: 35 | Z16: 110 | AA16: 101 | AB16: 57 | AC16: 79 | AD16: 62 | AE16: 74 | AF16: 47 | AG16: =sum(B16:AF16) -> 1063
A17: Google Store Orders | B17: =sum(B18:B19) -> 8 | C17: =sum(C18:C19) -> 14 | D17: =sum(D18:D19) -> 17 | E17: =sum(E18:E19) -> 9 | F17: =sum(F18:F19) -> 10 | G17: =sum(G18:G19) -> 13 | H17: =sum(H18:H19) -> 14 | I17: =sum(I18:I19) -> 18 | ... AF17: =sum(AF18:AF19) -> 63 | AG17: =sum(B17:AF17) -> 1200
A18: - Yearly Subscription | B18: 7 | C18: 9 | D18: 10 | E18: 2 | F18: 6 | G18: 7 | H18: 9 | I18: 12 | J18: 14 | K18: 19 | L18: 6 | M18: 6 | N18: 6 | O18: 6 | P18: 8 | Q18: 15 | R18: 14 | S18: 6 | T18: 3 | U18: 3 | V18: 13 | W18: 18 | X18: 38 | Y18: 55 | Z18: 187 | AA18: 187 | AB18: 97 | AC18: 49 | AD18: 52 | AE18: 62 | AF18: 58 | AG18: =sum(B18:AF18) -> 984
A19: - Monthly Subscription | B19: 1 | C19: 5 | D19: 7 | E19: 7 | F19: 4 | G19: 6 | H19: 5 | I19: 6 | J19: 7 | K19: 5 | L19: 1 | M19: 4 | N19: 4 | O19: 3 | P19: 8 | Q19: 4 | R19: 3 | S19: 7 | T19: 9 | U19: 8 | V19: 8 | W19: 5 | X19: 4 | Y19: 6 | Z19: 17 | AA19: 10 | AB19: 13 | AC19: 16 | AD19: 15 | AE19: 13 | AF19: 5 | AG19: =sum(B19:AF19) -> 216
A20: SUM | B20: =sum(B14+B17) -> 83 | C20: =sum(C14+C17) -> 113 | D20: =sum(D14+D17) -> 104 | E20: =sum(E14+E17) -> 68 | F20: =sum(F14+F17) -> 70 | G20: =sum(G14+G17) -> 74 | H20: =sum(H14+H17) -> 76 | I20: =sum(I14+I17) -> 96 | ... AF20: =sum(AF14+AF17) -> 423 | AG20: =sum(B20:AF20) -> 7361
A21: - Yearly Subscription | B21: =B15+B18 -> 63 | C21: =C15+C18 -> 85 | D21: =D15+D18 -> 65 | E21: =E15+E18 -> 43 | F21: =F15+F18 -> 39 | G21: =G15+G18 -> 47 | H21: =H15+H18 -> 49 | I21: =I15+I18 -> 60 | ... AF21: =AF15+AF18 -> 371 | AG21: =sum(B21:AF21) -> 6082
A22: - Monthly Subscription | B22: =B16+B19 -> 20 | C22: =C16+C19 -> 28 | D22: =D16+D19 -> 39 | E22: =E16+E19 -> 25 | F22: =F16+F19 -> 31 | G22: =G16+G19 -> 27 | H22: =H16+H19 -> 27 | I22: =I16+I19 -> 36 | ... AF22: =AF16+AF19 -> 52 | AG22: =sum(B22:AF22) -> 1279
A24: Refunded Revenue
A25: Apple Store Sales | B25: =sum(B26:B27) -> 29.99 | C25: =sum(C26:C27) -> 29.99 | D25: =sum(D26:D27) -> 0 | E25: =sum(E26:E27) -> 0 | F25: =sum(F26:F27) -> 29.99 | G25: =sum(G26:G27) -> 0 | H25: =sum(H26:H27) -> 29.99 | I25: =sum(I26:I27) -> 0 | ... AF25: =sum(AF26:AF27) -> 29.99 | AG25: =sum(B25:AF25) -> 431.93
A26: - Yearly Subscription | B26: 29.99 | C26: 29.99 | D26: 0 | E26: 0 | F26: 29.99 | G26: 0 | H26: 29.99 | I26: 0 | J26: 59.98 | K26: 0 | L26: 0 | M26: 0 | N26: 0 | O26: 0 | P26: 0 | Q26: 36.16 | R26: 0 | S26: 0 | T26: 0 | U26: 0 | V26: 0 | W26: 29.99 | X26: 0 | Y26: 0 | Z26: 0 | AA26: 29.99 | AB26: 59.9 | AC26: 29.99 | AD26: 29.99 | AE26: 0 | AF26: 29.99 | AG26: =sum(B26:AF26) -> 425.95
A27: - Monthly Subscription | B27: 0 | C27: 0 | D27: 0 | E27: 0 | F27: 0 | G27: 0 | H27: 0 | I27: 0 | J27: 0 | K27: 5.98 | L27: 0 | M27: 0 | N27: 0 | O27: 0 | P27: 0 | Q27: 0 | R27: 0 | S27: 0 | T27: 0 | U27: 0 | V27: 0 | W27: 0 | X27: 0 | Y27: 0 | Z27: 0 | AA27: 0 | AB27: 0 | AC27: 0 | AD27: 0 | AE27: 0 | AF27: 0 | AG27: =sum(B27:AF27) -> 5.98
A28: Google Store Sales | B28: =sum(B29:B30) -> 0 | C28: =sum(C29:C30) -> 0 | D28: =sum(D29:D30) -> 0 | E28: =sum(E29:E30) -> 0 | F28: =sum(F29:F30) -> 0 | G28: =sum(G29:G30) -> 0 | H28: =sum(H29:H30) -> 0 | I28: =sum(I29:I30) -> 0 | ... AF28: =sum(AF29:AF30) -> 0 | AG28: =sum(B28:AF28) -> 0
A29: - Yearly Subscription | B29: 0 | C29: 0 | D29: 0 | E29: 0 | F29: 0 | G29: 0 | H29: 0 | I29: 0 | J29: 0 | K29: 0 | L29: 0 | M29: 0 | N29: 0 | O29: 0 | P29: 0 | Q29: 0 | R29: 0 | S29: 0 | T29: 0 | U29: 0 | V29: 0 | W29: 0 | X29: 0 | Y29: 0 | Z29: 0 | AA29: 0 | AB29: 0 | AC29: 0 | AD29: 0 | AE29: 0 | AF29: 0 | AG29: =sum(B29:AF29) -> 0
A30: - Monthly Subscription | B30: 0 | C30: 0 | D30: 0 | E30: 0 | F30: 0 | G30: 0 | H30: 0 | I30: 0 | J30: 0 | K30: 0 | L30: 0 | M30: 0 | N30: 0 | O30: 0 | P30: 0 | Q30: 0 | R30: 0 | S30: 0 | T30: 0 | U30: 0 | V30: 0 | W30: 0 | X30: 0 | Y30: 0 | Z30: 0 | AA30: 0 | AB30: 0 | AC30: 0 | AD30: 0 | AE30: 0 | AF30: 0 | AG30: =sum(B30:AF30) -> 0
A31: SUM | B31: =B25+B28 -> 29.99 | C31: =C25+C28 -> 29.99 | D31: =D25+D28 -> 0 | E31: =E25+E28 -> 0 | F31: =F25+F28 -> 29.99 | G31: =G25+G28 -> 0 | H31: =H25+H28 -> 29.99 | I31: =I25+I28 -> 0 | ... AF31: =AF25+AF28 -> 29.99 | AG31: =sum(B31:AF31) -> 431.93
A33: Refunded Orders
A34: Apple Store orders | B34: =sum(B35:B36) -> 1 | C34: =sum(C35:C36) -> 1 | D34: =sum(D35:D36) -> 0 | E34: =sum(E35:E36) -> 0 | F34: =sum(F35:F36) -> 1 | G34: =sum(G35:G36) -> 0 | H34: =sum(H35:H36) -> 1 | I34: =sum(I35:I36) -> 0 | ... AF34: =sum(AF35:AF36) -> 1 | AG34: =sum(B34:AF34) -> 17
A35: - Yearly Subscription | B35: 1 | C35: 1 | D35: 0 | E35: 0 | F35: 1 | G35: 0 | H35: 1 | I35: 0 | J35: 2 | K35: 0 | L35: 0 | M35: 0 | N35: 0 | O35: 0 | P35: 0 | Q35: 2 | R35: 0 | S35: 0 | T35: 0 | U35: 0 | V35: 0 | W35: 1 | X35: 0 | Y35: 0 | Z35: 0 | AA35: 1 | AB35: 2 | AC35: 1 | AD35: 1 | AE35: 0 | AF35: 1
A36: - Monthly Subscription | B36: 0 | C36: 0 | D36: 0 | E36: 0 | F36: 0 | G36: 0 | H36: 0 | I36: 0 | J36: 0 | K36: 2 | L36: 0 | M36: 0 | N36: 0 | O36: 0 | P36: 0 | Q36: 0 | R36: 0 | S36: 0 | T36: 0 | U36: 0 | V36: 0 | W36: 0 | X36: 0 | Y36: 0 | Z36: 0 | AA36: 0 | AB36: 0 | AC36: 0 | AD36: 0 | AE36: 0 | AF36: 0
A37: Google Store orders | B37: =sum(B38:B39) -> 0 | C37: =sum(C38:C39) -> 0 | D37: =sum(D38:D39) -> 0 | E37: =sum(E38:E39) -> 0 | F37: =sum(F38:F39) -> 0 | G37: =sum(G38:G39) -> 0 | H37: =sum(H38:H39) -> 0 | I37: =sum(I38:I39) -> 0 | ... AF37: =sum(AF38:AF39) -> 0 | AG37: =sum(B37:AF37) -> 0
A38: - Yearly Subscription | B38: 0 | C38: 0 | D38: 0 | E38: 0 | F38: 0 | G38: 0 | H38: 0 | I38: 0 | J38: 0 | K38: 0 | L38: 0 | M38: 0 | N38: 0 | O38: 0 | P38: 0 | Q38: 0 | R38: 0 | S38: 0 | T38: 0 | U38: 0 | V38: 0 | W38: 0 | X38: 0 | Y38: 0 | Z38: 0 | AA38: 0 | AB38: 0 | AC38: 0 | AD38: 0 | AE38: 0 | AF38: 0
A39: - Monthly Subscription | B39: 0 | C39: 0 | D39: 0 | E39: 0 | F39: 0 | G39: 0 | H39: 0 | I39: 0 | J39: 0 | K39: 0 | L39: 0 | M39: 0 | N39: 0 | O39: 0 | P39: 0 | Q39: 0 | R39: 0 | S39: 0 | T39: 0 | U39: 0 | V39: 0 | W39: 0 | X39: 0 | Y39: 0 | Z39: 0 | AA39: 0 | AB39: 0 | AC39: 0 | AD39: 0 | AE39: 0 | AF39: 0
A40: SUM | B40: =B34+B37 -> 1 | C40: =C34+C37 -> 1 | D40: =D34+D37 -> 0 | E40: =E34+E37 -> 0 | F40: =F34+F37 -> 1 | G40: =G34+G37 -> 0 | H40: =H34+H37 -> 1 | I40: =I34+I37 -> 0 | ... AF40: =AF34+AF37 -> 1 | AG40: =sum(B40:AF40) -> 17
A42: Net Revenue
A43: Apple Store | B43: =B5-B25 -> 1690.8004 | C43: =C5-C25 -> 2323.9049 | D43: =D5-D25 -> 1773.2926 | E43: =E5-E25 -> 1307.9704 | F43: =F5-F25 -> 1026.7741 | G43: =G5-G25 -> 1277.0296 | H43: =H5-H25 -> 1229.3659 | I43: =I5-I25 -> 1574.9166 | ... AF43: =AF5-AF25 -> 10478.23 | AG43: =sum(B43:AF43) -> 159611.03
A44: - Yearly Subscription | B44: =B6-B26 -> 1633.3004 | C44: =C6-C26 -> 2252.9049 | D44: =D6-D26 -> 1673.6926 | E44: =E6-E26 -> 1251.9704 | F44: =F6-F26 -> 943.57415 | G44: =G6-G26 -> 1213.1296 | H44: =H6-H26 -> 1162.7659 | I44: =I6-I26 -> 1481.4166 | ... AF44: =AF6-AF26 -> 10211.128 | AG44: =sum(B44:AF44) -> 155038.56
A45: - Monthly Subscription | B45: =B7-B27 -> 57.5 | C45: =C7-C27 -> 71 | D45: =D7-D27 -> 99.6 | E45: =E7-E27 -> 56 | F45: =F7-F27 -> 83.2 | G45: =G7-G27 -> 63.9 | H45: =H7-H27 -> 66.6 | I45: =I7-I27 -> 93.5 | ... AF45: =AF7-AF27 -> 267.1023 | AG45: =sum(B45:AF45) -> 4572.4646
...

Sheet Digital Marketplaces
A1: DECEMBER | B1: 45261 | C1: 45262 | D1: 45263 | E1: 45264 | F1: 45265 | G1: 45266 | H1: 45267 | I1: 45268 | J1: 45269 | K1: 45270 | L1: 45271 | M1: 45272 | N1: 45273 | O1: 45274 | P1: 45275 | Q1: 45276 | R1: 45277 | S1: 45278 | T1: 45279 | U1: 45280 | V1: 45281 | W1: 45282 | X1: 45283 | Y1: 45284 | Z1: 45285 | AA1: 45286 | AB1: 45287 | AC1: 45288 | AD1: 45289 | AE1: 45290 | AF1: 45291
A2: DAY | B2: FRI | C2: SAT | D2: SUN | E2: MON | F2: TUE | G2: WED | H2: THU | I2: FRI | J2: SAT | K2: SUN | L2: MON | M2: TUE | N2: WED | O2: THU | P2: FRI | Q2: SAT | R2: SUN | S2: MON | T2: TUE | U2: WED | V2: THU | W2: FRI | X2: SAT | Y2: SUN | Z2: MON | AA2: TUE | AB2: WED | AC2: THU | AD2: FRI | AE2: SAT | AF2: SUN
A3: Rachio (Shopify)
A4: Revenue | B4: =Summary!B21 -> 955.22816 | C4: =Summary!C21 -> 318.40939 | D4: =Summary!D21 -> 636.81877 | E4: =Summary!E21 -> 318.40939 | F4: =Summary!F21 -> 318.40939 | G4: =Summary!G21 -> 0 | H4: =Summary!H21 -> 0 | I4: =Summary!I21 -> 955.22816 | ... AF4: =Summary!AF21 -> 0 | AG4: =sum(B4:AF4) -> 43431.023
A5: Breakdown
A6: - Tax | B6: =Summary!B23 -> 55.258158 | C6: =Summary!C23 -> 18.419386 | D6: =Summary!D23 -> 36.838772 | E6: =Summary!E23 -> 18.419386 | F6: =Summary!F23 -> 18.419386 | G6: =Summary!G23 -> 0 | H6: =Summary!H23 -> 0 | I6: =Summary!I23 -> 55.258158 | ... AF6: =Summary!AF23 -> 0 | AG6: =sum(B6:AF6) -> 2512.4033
A7: - Shipping | AG7: =sum(B7:AF7) -> 0
A8: Orders | B8: =Summary!B57 -> 4 | C8: =Summary!C57 -> 1 | D8: =Summary!D57 -> 2 | E8: =Summary!E57 -> 1 | F8: =Summary!F57 -> 1 | G8: =Summary!G57 -> 0 | H8: =Summary!H57 -> 0 | I8: =Summary!I57 -> 3 | ... AF8: =Summary!AF57 -> 0 | AG8: =sum(B8:AF8) -> 143
A10: Rachio Fees (20%) | B10: =Summary!B82 -> 191.04563 | C10: =Summary!C82 -> 63.681877 | D10: =Summary!D82 -> 127.36375 | E10: =Summary!E82 -> 63.681877 | F10: =Summary!F82 -> 63.681877 | G10: =Summary!G82 -> 0 | H10: =Summary!H82 -> 0 | I10: =Summary!I82 -> 191.04563 | ... AF10: =Summary!AF82 -> 0 | AG10: =sum(B10:AF10) -> 8686.2047
A12: Units Sold (Gross) - Rachio
A13: SKU 1 - Blue | B13: 0 | C13: 0 | D13: 0 | E13: 0 | F13: 0 | G13: 0 | H13: 0 | I13: 0 | J13: 0 | K13: 1 | L13: 0 | M13: 2 | N13: 2 | O13: 0 | P13: 0 | Q13: 0 | R13: 0 | S13: 0 | T13: 0 | U13: 0 | V13: 0 | W13: 0 | X13: 0 | Y13: 0 | Z13: 0 | AA13: 0 | AB13: 0 | AC13: 0 | AD13: 0 | AE13: 0 | AF13: 0 | AG13: =sum(B13:AF13) -> 5
A14: SKU 2 - Yellow | B14: 0 | C14: 0 | D14: 0 | E14: 0 | F14: 0 | G14: 0 | H14: 0 | I14: 0 | J14: 1 | K14: 0 | L14: 0 | M14: 1 | N14: 1 | O14: 0 | P14: 0 | Q14: 0 | R14: 0 | S14: 0 | T14: 0 | U14: 0 | V14: 0 | W14: 0 | X14: 0 | Y14: 0 | Z14: 0 | AA14: 0 | AB14: 0 | AC14: 0 | AD14: 0 | AE14: 0 | AF14: 0 | AG14: =sum(B14:AF14) -> 3
A15: SKU 3 - Blue w/ Solar | B15: 3 | C15: 0 | D15: 2 | E15: 1 | F15: 1 | G15: 0 | H15: 0 | I15: 2 | J15: 2 | K15: 2 | L15: 4 | M15: 64 | N15: 14 | O15: 0 | P15: 0 | Q15: 3 | R15: 1 | S15: 0 | T15: 2 | U15: 0 | V15: 0 | W15: 0 | X15: 0 | Y15: 0 | Z15: 0 | AA15: 0 | AB15: 0 | AC15: 0 | AD15: 0 | AE15: 0 | AF15: 0 | AG15: =sum(B15:AF15) -> 101
A16: SKU 4 - Yellow w/ Solar | B16: 3 | C16: 1 | D16: 0 | E16: 0 | F16: 0 | G16: 0 | H16: 0 | I16: 1 | J16: 0 | K16: 0 | L16: 0 | M16: 20 | N16: 9 | O16: 0 | P16: 0 | Q16: 0 | R16: 1 | S16: 2 | T16: 0 | U16: 0 | V16: 0 | W16: 0 | X16: 0 | Y16: 0 | Z16: 0 | AA16: 0 | AB16: 0 | AC16: 0 | AD16: 0 | AE16: 0 | AF16: 0 | AG16: =sum(B16:AF16) -> 37
A17: SUM (SKU 1 - SKU 4) | B17: =SUM(B13:B16) -> 6 | C17: =SUM(C13:C16) -> 1 | D17: =SUM(D13:D16) -> 2 | E17: =SUM(E13:E16) -> 1 | F17: =SUM(F13:F16) -> 1 | G17: =SUM(G13:G16) -> 0 | H17: =SUM(H13:H16) -> 0 | I17: =SUM(I13:I16) -> 3 | ... AF17: =SUM(AF13:AF16) -> 0 | AG17: =sum(B17:AF17) -> 146
A19: Wall Mount | B19: 0 | C19: 0 | D19: 0 | E19: 0 | F19: 0 | G19: 0 | H19: 0 | I19: 0 | J19: 0 | K19: 0 | L19: 0 | M19: 0 | N19: 0 | O19: 0 | P19: 0 | Q19: 0 | R19: 0 | S19: 0 | T19: 0 | U19: 0 | V19: 0 | W19: 0 | X19: 0 | Y19: 0 | Z19: 0 | AA19: 0 | AB19: 0 | AC19: 0 | AD19: 0 | AE19: 0 | AF19: 0 | AG19: =sum(B19:AF19) -> 0
A20: Suet Ball Holder | B20: 0 | C20: 0 | D20: 0 | E20: 0 | F20: 0 | G20: 0 | H20: 0 | I20: 0 | J20: 0 | K20: 0 | L20: 0 | M20: 0 | N20: 0 | O20: 0 | P20: 0 | Q20: 0 | R20: 0 | S20: 0 | T20: 0 | U20: 0 | V20: 0 | W20: 0 | X20: 0 | Y20: 0 | Z20: 0 | AA20: 0 | AB20: 0 | AC20: 0 | AD20: 0 | AE20: 0 | AF20: 0 | AG20: =sum(B20:AF20) -> 0
A21: 3-in-1 Nutrition Set - Blue | B21: 0 | C21: 0 | D21: 0 | E21: 0 | F21: 0 | G21: 0 | H21: 0 | I21: 0 | J21: 0 | K21: 0 | L21: 0 | M21: 0 | N21: 0 | O21: 0 | P21: 0 | Q21: 0 | R21: 0 | S21: 0 | T21: 0 | U21: 0 | V21: 0 | W21: 0 | X21: 0 | Y21: 0 | Z21: 0 | AA21: 0 | AB21: 0 | AC21: 0 | AD21: 0 | AE21: 0 | AF21: 0 | AG21: =sum(B21:AF21) -> 0
A22: 3-in-1 Nutrition Set - Yellow | B22: 0 | C22: 0 | D22: 0 | E22: 0 | F22: 0 | G22: 0 | H22: 0 | I22: 0 | J22: 0 | K22: 0 | L22: 0 | M22: 0 | N22: 0 | O22: 0 | P22: 0 | Q22: 0 | R22: 0 | S22: 0 | T22: 0 | U22: 0 | V22: 0 | W22: 0 | X22: 0 | Y22: 0 | Z22: 0 | AA22: 0 | AB22: 0 | AC22: 0 | AD22: 0 | AE22: 0 | AF22: 0 | AG22: =sum(B22:AF22) -> 0
A23: Solar Roof Single - Blue | B23: 0 | C23: 0 | D23: 0 | E23: 0 | F23: 0 | G23: 0 | H23: 0 | I23: 0 | J23: 0 | K23: 0 | L23: 0 | M23: 0 | N23: 0 | O23: 0 | P23: 0 | Q23: 0 | R23: 0 | S23: 0 | T23: 0 | U23: 0 | V23: 0 | W23: 0 | X23: 0 | Y23: 0 | Z23: 0 | AA23: 0 | AB23: 0 | AC23: 0 | AD23: 0 | AE23: 0 | AF23: 0 | AG23: =sum(B23:AF23) -> 0
A24: Solar Roof Single - Yellow | B24: 0 | C24: 0 | D24: 0 | E24: 0 | F24: 0 | G24: 0 | H24: 0 | I24: 0 | J24: 0 | K24: 0 | L24: 0 | M24: 0 | N24: 0 | O24: 0 | P24: 0 | Q24: 0 | R24: 0 | S24: 0 | T24: 0 | U24: 0 | V24: 0 | W24: 0 | X24: 0 | Y24: 0 | Z24: 0 | AA24: 0 | AB24: 0 | AC24: 0 | AD24: 0 | AE24: 0 | AF24: 0 | AG24: =sum(B24:AF24) -> 0
A25: Perch Extender - Blue | B25: 0 | C25: 0 | D25: 0 | E25: 0 | F25: 0 | G25: 0 | H25: 0 | I25: 0 | J25: 0 | K25: 0 | L25: 0 | M25: 0 | N25: 0 | O25: 0 | P25: 0 | Q25: 0 | R25: 0 | S25: 0 | T25: 0 | U25: 0 | V25: 0 | W25: 0 | X25: 0 | Y25: 0 | Z25: 0 | AA25: 0 | AB25: 0 | AC25: 0 | AD25: 0 | AE25: 0 | AF25: 0 | AG25: =sum(B25:AF25) -> 0
A26: Perch Extender - Yellow | B26: 0 | C26: 0 | D26: 0 | E26: 0 | F26: 0 | G26: 0 | H26: 0 | I26: 0 | J26: 0 | K26: 0 | L26: 0 | M26: 0 | N26: 0 | O26: 0 | P26: 0 | Q26: 0 | R26: 0 | S26: 0 | T26: 0 | U26: 0 | V26: 0 | W26: 0 | X26: 0 | Y26: 0 | Z26: 0 | AA26: 0 | AB26: 0 | AC26: 0 | AD26: 0 | AE26: 0 | AF26: 0 | AG26: =sum(B26:AF26) -> 0
A27: SUM (Add-ons) | B27: =SUM(B19:B26) -> 0 | C27: =SUM(C19:C26) -> 0 | D27: =SUM(D19:D26) -> 0 | E27: =SUM(E19:E26) -> 0 | F27: =SUM(F19:F26) -> 0 | G27: =SUM(G19:G26) -> 0 | H27: =SUM(H19:H26) -> 0 | I27: =SUM(I19:I26) -> 0 | ... AF27: =SUM(AF19:AF26) -> 0 | AG27: =sum(B27:AF27) -> 0
A29: Units and Revenue Cancelled & Refunds - Rachio
A31: Units Cancelled (Gross) - Rachio
A32: SKU 1 - Blue | AG32: =SUM(B32:AF32) -> 0
A33: SKU 2 - Yellow | AG33: =SUM(B33:AF33) -> 0
A34: SKU 3 - Blue w/ Solar | G34: 1 | AG34: =SUM(B34:AF34) -> 1
A35: SKU 4 - Yellow w/ Solar | AG35: =SUM(B35:AF35) -> 0
A36: SUM (SKU 1 + SKU 2) | B36: =SUM(B32:B33) -> 0 | C36: =SUM(C32:C33) -> 0 | D36: =SUM(D32:D33) -> 0 | E36: =SUM(E32:E33) -> 0 | F36: =SUM(F32:F33) -> 0 | G36: =SUM(G32:G33) -> 0 | H36: =SUM(H32:H33) -> 0 | I36: =SUM(I32:I33) -> 0 | ... AF36: =SUM(AF32:AF33) -> 0 | AG36: =SUM(B36:AF36) -> 0
A37: SUM (SKU 3 + SKU 4) | B37: =SUM(B34:B35) -> 0 | C37: =SUM(C34:C35) -> 0 | D37: =SUM(D34:D35) -> 0 | E37: =SUM(E34:E35) -> 0 | F37: =SUM(F34:F35) -> 0 | G37: =SUM(G34:G35) -> 1 | H37: =SUM(H34:H35) -> 0 | I37: =SUM(I34:I35) -> 0 | ... AF37: =SUM(AF34:AF35) -> 0 | AG37: =SUM(B37:AF37) -> 1
A39: Wall Mount | AG39: =SUM(B39:AF39) -> 0
A40: Suet Ball Holder | AG40: =SUM(B40:AF40) -> 0
A41: 3-in-1 Nutrition Set - Blue | AG41: =SUM(B41:AF41) -> 0
A42: 3-in-1 Nutrition Set - Yellow | AG42: =SUM(B42:AF42) -> 0
A43: Solar Roof Single - Blue | AG43: =SUM(B43:AF43) -> 0
A44: Solar Roof Single - Yellow | AG44: =SUM(B44:AF44) -> 0
A45: Perch Extender - Blue | AG45: =SUM(B45:AF45) -> 0
A46: Perch Extender - Yellow | AG46: =SUM(B46:AF46) -> 0
...

Sheet Data - P&L
B1: Business Metrics
A2: Source | B2: COGS | E2: Attachment Rates | H2: Marketing Averages (per first-time order) | K2: Fees | N2: VAT Averages | Q2: 30 Day Returns | T2: Digital Market Places & B2B
B3: Bird Buddy | C3: 86.9 | D3: 86.9 | E3: Solar Roof | F3: =(('DTC - P&L'!AG83+'DTC - P&L'!AG84)/'DTC - P&L'!AG77) -> 0.093977434 | H3: COGS | I3: =(C3*F9)+(C4*F8)+(C5*F3)+(C6*F4)+(C7*F5)+(C8*F6)+(C9*F7)+(C10*F10) -> 98.747507 | J3: =(D3*F9)+(D4*F8)+(D5*F3)+(D6*F4)+(D7*F5)+(D8*F6)+(D9*F7) -> 97.496396 | K3: Stripe Processing Fee | L3: 0.029 | N3: Europe | O3: 0.22 | Q3: US Shipping | R3: 15 | T3: Average % tax | U3: 0.0614
B4: Bird Buddy with Solar Roof | C4: 97.61 | D4: 97.61 | E4: Wall Mount | F4: =('DTC - P&L'!AG79/'DTC - P&L'!AG77) -> 0.25399306 | H4: Inbound Shipping | I4: =C38+('DTC - P&L'!AG87/'DTC - P&L'!AG77)*D38 -> 12.999515 | K4: Duty | L4: 0.034 | N4: ROW | O4: 0.13 | Q4: EU Shipping | R4: 40
B5: Solar Roof Single | C5: 13.44 | D5: 13.44 | E5: Fence Mount | F5: 0 | H5: Outbound Shipping | I5: =C34+('DTC - P&L'!AG87/'DTC - P&L'!AG77)*D34 -> 60.187683 | K5: China Tax | L5: 0.075 | N5: NA | Q5: ROW Shipping | R5: 20
B6: Wall Mount | C6: 5.49 | D6: 5.49 | E6: Suet Ball Holder | F6: =('DTC - P&L'!AG80)/'DTC - P&L'!AG77 -> 0.024031651 | H6: Taxes and VAT | I6: 16.81 | K6: HMF | L6: 0.00125 | Q6: Money Return | R6: 1
